Workbook

Sheet IT Working sheet 
A1: S.No | B1: Policy Number | E1: Policy Issuance Date | F1: Customer Name | G1: Contact Number | H1: VehicleNumber | I1: Make | J1: Model | K1: Value | L1: Up Front Charges | M1: Rates | N1: Sales Date | O1: Gross Cont | P1: Net Cont | Q1: Gross Cont (Fresh *2) | R1: Deferred Commission | S1: Commission % | T1: Agency | U1: Tagging | V1: Commission Status | W1: Custodian Name | X1: Category | Y1: Channel | Z1: Sub Channel
A2: 1 | B2: KHI/HO/D/MO/PC COMP/P/110102/06/2025 | E2: 45827 | F2: Zain ul abidin | G2: 0300 2348932 | H2: BVB-723 | I2: ALTO VXR | J2: 2021 | K2: 2500000 | L2: 37500 | M2: 0.015 | N2: 45827 | O2: 31897 | P2: 37500 | Q2: =O2*2 -> 63794 | R2: 573 | S2: 0 | T2: 09000870/Digital sales - DA | U2: FRE | W2: Hamna Ali | X2: Comprehensive | Y2: Other | Z2: Other
A3: 2 | B3: KHI/HO/D/MO/PC COMP/P/110104/06/2025 | E3: 45827 | F3: Zain ul abidin | G3: 0300 2348932 | H3: BTY-041 | I3: ALTO VXR | J3: 2021 | K3: 2500000 | L3: 37500 | M3: 0.015 | N3: 45827 | O3: 31897 | P3: 37500 | Q3: =O3*2 -> 63794 | R3: 563 | S3: 0 | T3: 09000870/Digital sales - DA | U3: FRE | W3: Hamna Ali | X3: Comprehensive | Y3: Other | Z3: Other
A4: 3 | B4: KHI/HO/D/MO/PC COMP/P/110238/06/2025 | E4: 45834 | F4: Zain ul abidin | G4: 0300 2348932 | H4: BWX-068 | I4: ALTO VXR | J4: 2022 | K4: 2500000 | L4: 37500 | M4: 0.015 | N4: 45834 | O4: 31897 | P4: 37500 | Q4: =O4*2 -> 63794 | R4: 563 | S4: 0 | T4: 09000870/Digital sales - DA | U4: FRE | W4: Hamna Ali | X4: Comprehensive | Y4: Other | Z4: Other
A5: 4 | B5: KHI/HO/D/MO/PC COMP/P/110441/07/2025 | C5: =VLOOKUP('IT Working sheet '!B5,'09000210'!B:C,2,0) -> 040000200398 | D5: ="Update ins_assorted_clients set commission_amount = '"&R5&"' where assorted_code = '"&C5&"' and agency_code = '09000870';" -> Update ins_assorted_clients set commission_amount = '563' where assorted_code = '040000200398' and agency_code = '09000870'; | E5: 45846 | F5: Mohammad Tariq Deen | G5: 0333-3618220 | H5: BYT-442 | I5: EK Wagon | J5: 2023 | K5: 2500000 | L5: 35000 | M5: 0.014 | N5: 45846 | O5: 29742 | P5: 35000 | Q5: 29742 | R5: 563 | S5: 0 | T5: 09000870/Digital sales - DA | U5: REN | W5: Hamna Ali | X5: Comprehensive | Y5: Retail Renewal | Z5: Retail Renewal (July-2025)
A6: 5 | B6: LHR/LHR/D/MO/PC COMP/P/110475/07/2025 | C6: =VLOOKUP('IT Working sheet '!B6,'09000210'!B:C,2,0) -> 040000200465 | D6: ="Update ins_assorted_clients set commission_amount = '"&R6&"' where assorted_code = '"&C6&"' and agency_code = '09000870';" -> Update ins_assorted_clients set commission_amount = '563' where assorted_code = '040000200465' and agency_code = '09000870'; | E6: 45847 | F6: Shoaib Nazir | G6: 0307-9379517 | H6: RIC 19 450 | I6: ALTO VXR | J6: 2019 | K6: 2300000 | L6: 46000 | M6: 0.02 | N6: 45847 | O6: 39299 | P6: 46000 | Q6: 39299 | R6: 563 | S6: 0 | T6: 09000870/Digital sales - DA | U6: REN | W6: Hamna Ali | X6: Comprehensive | Y6: Retail Renewal | Z6: Retail Renewal (July-2025)
A7: 6 | B7: LHR/LHR/D/MO/PC COMP/P/110352/07/2025 | C7: =VLOOKUP('IT Working sheet '!B7,'09000210'!B:C,2,0) -> 040000200132 | D7: ="Update ins_assorted_clients set commission_amount = '"&R7&"' where assorted_code = '"&C7&"' and agency_code = '09000870';" -> Update ins_assorted_clients set commission_amount = '563' where assorted_code = '040000200132' and agency_code = '09000870'; | E7: 45841 | F7: Rasul Bakhsh Siraj | G7: 0320-4800112 | H7: LE-18-8813 | I7: CITY 1.5 ASPIRE | J7: 2017 | K7: 3300000 | L7: 49500 | M7: 0.015 | N7: 45841 | O7: 42291 | P7: 49500 | Q7: 42291 | R7: 563 | S7: 0 | T7: 09000870/Digital sales - DA | U7: REN | W7: Hamna Ali | X7: Comprehensive | Y7: Retail Renewal | Z7: Retail Renewal (July-2025)
A8: 7 | B8: KHI/HO/D/MO/PC COMP/P/110480/07/2025 | C8: =VLOOKUP('IT Working sheet '!B8,'09000210'!B:C,2,0) -> 040000200474 | D8: ="Update ins_assorted_clients set commission_amount = '"&R8&"' where assorted_code = '"&C8&"' and agency_code = '09000870';" -> Update ins_assorted_clients set commission_amount = '563' where assorted_code = '040000200474' and agency_code = '09000870'; | E8: 45848 | F8: Mukhtar Ahmed | G8: 0333-2286698 | H8: BXF-950 | I8: SAGA | J8: 2022 | K8: 2519200 | L8: 50384 | M8: 0.02 | N8: 45848 | O8: 43003 | P8: 50384 | Q8: 43003 | R8: 563 | S8: 0 | T8: 09000870/Digital sales - DA | U8: REN | W8: Hamna Ali | X8: Comprehensive | Y8: Retail Renewal | Z8: Retail Renewal (July-2025)
A9: 8 | B9: KHI/HO/D/MO/PC COMP/P/110452/07/2025 | C9: =VLOOKUP('IT Working sheet '!B9,'09000210'!B:C,2,0) -> 040000200415 | D9: ="Update ins_assorted_clients set commission_amount = '"&R9&"' where assorted_code = '"&C9&"' and agency_code = '09000870';" -> Update ins_assorted_clients set commission_amount = '563' where assorted_code = '040000200415' and agency_code = '09000870'; | E9: 45846 | F9: Nida Hussain | G9: 0321-2029596 | I9: DAYZ | J9: 2022 | K9: 3500000 | L9: 52500 | M9: 0.015 | N9: 45846 | O9: 44828 | P9: 52500 | Q9: 44828 | R9: 563 | S9: 0 | T9: 09000870/Digital sales - DA | U9: REN | W9: Hamna Ali | X9: Comprehensive | Y9: Retail Renewal | Z9: Retail Renewal (June-2025)
A10: 9 | B10: KHI/HO/D/MO/PC COMP/P/110537/07/2025 | C10: =VLOOKUP('IT Working sheet '!B10,'09000210'!B:C,2,0) -> 040000200563 | D10: ="Update ins_assorted_clients set commission_amount = '"&R10&"' where assorted_code = '"&C10&"' and agency_code = '09000870';" -> Update ins_assorted_clients set commission_amount = '563' where assorted_code = '040000200563' and agency_code = '09000870'; | E10: 45852 | F10: Muhammad Asif | G10: 0336-0001977 | H10: CAC-708 | I10: ALTO VXL AGS | J10: 2024 | K10: 3045000 | L10: 53288 | M10: 0.0175 | N10: 45852 | O10: 45507 | P10: 53288 | Q10: 45507 | R10: 563 | S10: 0 | T10: 09000870/Digital sales - DA | U10: REN | W10: Hamna Ali | X10: Comprehensive | Y10: Retail Renewal | Z10: Retail Renewal (July-2025)
A11: 10 | B11: KHI/HO/D/MO/PC COMP/P/110478/07/2025 | C11: =VLOOKUP('IT Working sheet '!B11,'09000210'!B:C,2,0) -> 040000200469 | D11: ="Update ins_assorted_clients set commission_amount = '"&R11&"' where assorted_code = '"&C11&"' and agency_code = '09000870';" -> Update ins_assorted_clients set commission_amount = '563' where assorted_code = '040000200469' and agency_code = '09000870'; | E11: 45847 | F11: Sameer Ul Haq | G11: 0323-2035147 | H11: BXE-201 | I11: YARIS CVT | J11: 2022 | K11: 4000000 | L11: 60000 | M11: 0.015 | N11: 45847 | O11: 51293 | P11: 60000 | Q11: 51293 | R11: 563 | S11: 0 | T11: 09000870/Digital sales - DA | U11: REN | W11: Hamna Ali | X11: Comprehensive | Y11: Retail Renewal | Z11: Retail Renewal (July-2025)
A12: 11 | B12: KHI/HO/D/MO/PC COMP/P/110449/07/2025 | C12: =VLOOKUP('IT Working sheet '!B12,'09000210'!B:C,2,0) -> 040000200409 | D12: ="Update ins_assorted_clients set commission_amount = '"&R12&"' where assorted_code = '"&C12&"' and agency_code = '09000870';" -> Update ins_assorted_clients set commission_amount = '563' where assorted_code = '040000200409' and agency_code = '09000870'; | E12: 45846 | F12: Tariq Altaf | G12: 0321-2587658 | H12: BP-0274 | I12: RAIZE | J12: 2021 | K12: 6000000 | L12: 84000 | M12: 0.014 | N12: 45846 | O12: 71983 | P12: 84000 | Q12: 71983 | R12: 563 | S12: 0 | T12: 09000870/Digital sales - DA | U12: REN | W12: Hamna Ali | X12: Comprehensive | Y12: Retail Renewal | Z12: Retail Renewal (July-2025)
A13: 12 | B13: KHI/HO/D/MO/PC COMP/P/110540/07/2025 | C13: =VLOOKUP('IT Working sheet '!B13,'09000210'!B:C,2,0) -> 040000200568 | D13: ="Update ins_assorted_clients set commission_amount = '"&R13&"' where assorted_code = '"&C13&"' and agency_code = '09000870';" -> Update ins_assorted_clients set commission_amount = '563' where assorted_code = '040000200568' and agency_code = '09000870'; | E13: 45852 | F13: Topline Securities Limited | G13: 0331-3219274 | H13: BK-1720 | I13: SPORTAGE | J13: 2022 | K13: 6000000 | L13: 90000 | M13: 0.015 | N13: 45852 | O13: 77155 | P13: 90000 | Q13: 77155 | R13: 563 | S13: 0 | T13: 09000870/Digital sales - DA | U13: REN | W13: Hamna Ali | X13: Comprehensive | Y13: Retail Renewal | Z13: Retail Renewal (July-2025)
A14: 13 | B14: KHI/HO/D/MO/PC COMP/P/110512/07/2025 | C14: =VLOOKUP('IT Working sheet '!B14,'09000210'!B:C,2,0) -> 040000200522 | D14: ="Update ins_assorted_clients set commission_amount = '"&R14&"' where assorted_code = '"&C14&"' and agency_code = '09000870';" -> Update ins_assorted_clients set commission_amount = '563' where assorted_code = '040000200522' and agency_code = '09000870'; | E14: 45849 | F14: Sheikh Mansoor Ali Masood | G14: 0300-8271290 | H14: BM-7300 | I14: PROTON X70 EXECUTIVE AWD | J14: .. | K14: 6500000 | L14: 110500 | M14: 0.017 | N14: 45849 | O14: 94828 | P14: 110500 | Q14: 94828 | R14: 563 | S14: 0 | T14: 09000870/Digital sales - DA | U14: REN | W14: Hamna Ali | X14: Comprehensive | Y14: Retail Renewal | Z14: Retail Renewal (July-2025)
A15: 14 | B15: KHI/HO/D/MO/PC COMP/P/110516/07/2025 | C15: =VLOOKUP('IT Working sheet '!B15,'09000210'!B:C,2,0) -> #N/A | E15: 45849 | F15: Muhammad Yaseen Baloch | G15: 0300-2025750 | H15: BVT-719 | I15: ALTO VXL AGS | J15: 2022 | K15: 3000000 | L15: 51000 | M15: 0.017 | N15: 45849 | O15: 43535 | P15: 51000 | Q15: 43535 | R15: 563 | S15: 0 | T15: 09000870/Digital sales - DA | U15: REN | W15: Hamna Ali | X15: Comprehensive | Y15: Other | Z15: Other
A16: 15 | B16: LHR/LHR/D/MO/PC COMP/P/110338/07/2025 | C16: =VLOOKUP('IT Working sheet '!B16,'09000210'!B:C,2,0) -> 040000200105 | D16: ="Update ins_assorted_clients set commission_amount = '"&R16&"' where assorted_code = '"&C16&"' and agency_code = '09000870';" -> Update ins_assorted_clients set commission_amount = '563' where assorted_code = '040000200105' and agency_code = '09000870'; | E16: 45840 | F16: Muhammad Ammad Sohail Bhopal | G16: 0333-4352333 | H16: BDW-457 | I16: SANTA FE AWD | J16: 2024 | K16: 14780000 | L16: 206920 | M16: 0.014 | N16: 45840 | O16: 176838 | P16: 206920 | Q16: 176838 | R16: 563 | S16: 0 | T16: 09000870/Digital sales - DA | U16: REN | W16: Hamna Ali | X16: Comprehensive | Y16: Retail Renewal | Z16: Retail Renewal (July-2025)
A17: 16 | B17: KHI/HO/D/MO/PC COMP/P/110240/06/2025 | E17: 45835 | F17: Roshna Razzaq | G17: 0331-9747508 | H17: ABQ-082 | I17: PICANTO A/T | J17: 2021 | K17: 3200000 | L17: 48000 | M17: 0.015 | N17: 45835 | O17: 40949 | P17: 48000 | Q17: 40949 | R17: 563 | S17: 0 | T17: 09000870/Digital sales - DA | U17: REN | W17: Hamna Ali | X17: Comprehensive | Y17: Retail Renewal | Z17: Retail Renewal (June-2025)
A18: 17 | B18: LHR/LHR/D/MO/PC COMP/P/109750/06/2025 | E18: 45810 | F18: Zulfiqar Ali | G18: 0322-4081828 | H18: ADC-197 | I18: WAGON R VXL | J18: 2021 | K18: 2800000 | L18: 55720 | M18: 0.0199 | N18: 45809 | O18: 47607 | P18: 55720 | Q18: 47607 | R18: 563 | S18: 0 | T18: 09000870/Digital sales - DA | U18: REN | W18: Hamna Ali | X18: Comprehensive | Y18: Retail Renewal | Z18: Retail Renewal (June-2025)
A19: 18 | B19: LHR/LHR/D/MO/PC COMP/P/110250/06/2025 | E19: 45835 | F19: Tariq Mehmood | G19: 0334-5282712 | H19: AED-513 | I19: BRV I-VTEC | J19: 2024 | K19: 3700000 | L19: 62900 | M19: 0.017 | N19: 45824 | O19: 53744 | P19: 62900 | Q19: 53744 | R19: 563 | S19: 0 | T19: 09000870/Digital sales - DA | U19: REN | W19: Hamna Ali | X19: Comprehensive | Y19: Retail Renewal | Z19: Retail Renewal (June-2025)
A20: 19 | B20: LHR/LHR/D/MO/PC COMP/P/110111/06/2025 | E20: 45827 | F20: Progressive Textile | G20: 0300-8661774 | H20: AKN-625 | I20: Swift GLX CVT | J20: 2022 | K20: 4300000 | L20: 64500 | M20: 0.015 | N20: 45827 | O20: 55111 | P20: 64500 | Q20: 55111 | R20: 563 | S20: 0 | T20: 09000870/Digital sales - DA | U20: REN | W20: Hamna Ali | X20: Comprehensive | Y20: Retail Renewal | Z20: Retail Renewal (June-2025)
A21: 20 | B21: KHI/HO/D/MO/PC COMP/P/110021/06/2025 | E21: 45824 | F21: Haris Anwaar | G21: 0300-3252100 | H21: AKR-897 | I21: FORTUNER 645B 4X4 AT V | J21: 2022 | K21: 10000000 | L21: 150000 | M21: 0.015 | N21: 45822 | O21: 128879 | P21: 150000 | Q21: 128879 | R21: 563 | S21: 0 | T21: 09000870/Digital sales - DA | U21: REN | W21: Hamna Ali | X21: Comprehensive | Y21: Retail Renewal | Z21: Retail Renewal (June-2025)
A22: 21 | B22: KHI/HO/D/MO/PC COMP/P/109994/06/2025 | E22: 45821 | F22: Saima Irfan | G22: 0321-2766331 | H22: ATD-461 | I22: COROLLA GLI M/T 1.3 | J22: 2010 | K22: 2000000 | L22: 35000 | M22: 0.0175 | N22: 45821 | O22: 29742 | P22: 35000 | Q22: 29742 | R22: 563 | S22: 0 | T22: 09000870/Digital sales - DA | U22: REN | W22: Hamna Ali | X22: Comprehensive | Y22: Retail Renewal | Z22: Retail Renewal (June-2025)
A23: 22 | B23: LHR/LHR/D/MO/PC COMP/P/109996/06/2025 | E23: 45821 | F23: Furqan Muhammad Khan | G23: 0331-5569874 | H23: AZF-967 | I23: ALSVIN | J23: 2022 | K23: 4000000 | L23: 60000 | M23: 0.015 | N23: 45821 | O23: 51265 | P23: 60000 | Q23: 51265 | R23: 563 | S23: 0 | T23: 09000870/Digital sales - DA | U23: REN | W23: Hamna Ali | X23: Comprehensive | Y23: Retail Renewal | Z23: Retail Renewal (June-2025)
A24: 23 | B24: KHI/HO/D/MO/PC COMP/P/110182/06/2025 | E24: 45832 | F24: Khalid Deen | G24: 0334-2904798 | H24: BK-5923 | I24: KIA SPORTAGE | J24: 2022 | K24: 6500000 | L24: 94250 | M24: 0.0145 | N24: 45831 | O24: 80819 | P24: 94250 | Q24: 80819 | R24: 563 | S24: 0 | T24: 09000870/Digital sales - DA | U24: REN | W24: Hamna Ali | X24: Comprehensive | Y24: Retail Renewal | Z24: Retail Renewal (June-2025)
A25: 24 | B25: KHI/HO/D/MO/PC COMP/P/109991/06/2025 | E25: 45821 | F25: Saima Bano | G25: 0331-2198961 | H25: BK-6225 | I25: HS | J25: 2022 | K25: 10000000 | L25: 150000 | M25: 0.015 | N25: 45819 | O25: 128879 | P25: 150000 | Q25: 128879 | R25: 563 | S25: 0 | T25: 09000870/Digital sales - DA | U25: REN | W25: Hamna Ali | X25: Comprehensive | Y25: Retail Renewal | Z25: Retail Renewal (June-2025)
A26: 25 | B26: KHI/HO/D/MO/PC COMP/P/109939/06/2025 | E26: 45819 | F26: Harris Bin Shakir | G26: 0345-2145480 | H26: BML-992 | I26: PASSO A/T | J26: 2015 | K26: 2500000 | L26: 32500 | M26: 0.013 | N26: 45819 | O26: 27586 | P26: 32500 | Q26: 27586 | R26: 563 | S26: 0 | T26: 09000870/Digital sales - DA | U26: REN | W26: Hamna Ali | X26: Comprehensive | Y26: Direct Renewal | Z26: (Direct Renewal June-2025)
A27: 26 | B27: KHI/HO/D/MO/PC COMP/P/109930/06/2025 | E27: 45818 | F27: Faiq Ali HPA Meezan Bank Staff | G27: 0302-3935860 | H27: BMZ-608 | I27: WAGON-R | J27: 2018 | K27: 2400000 | L27: 33600 | M27: 0.014 | N27: 45818 | O27: 28535 | P27: 33600 | Q27: 28535 | R27: 563 | S27: 0 | T27: 09000870/Digital sales - DA | U27: REN | W27: Hamna Ali | X27: Comprehensive | Y27: Direct Renewal | Z27: (Direct Renewal June-2025)
A28: 27 | B28: KHI/HO/D/MO/PC COMP/P/109882/06/2025 | E28: 45813 | F28: Muhammad Waqas | G28: 0333-3455790 | H28: BWV-941 | I28: WAGON-R | J28: 2022 | K28: 3200000 | L28: 57600 | M28: 0.018 | N28: 45813 | O28: 49224 | P28: 57600 | Q28: 49224 | R28: 563 | S28: 0 | T28: 09000870/Digital sales - DA | U28: REN | W28: Hamna Ali | X28: Comprehensive | Y28: Retail Renewal | Z28: Retail Renewal (June-2025)
... A32: 31 | B32: LHR/LHR/D/MO/PC COMP/P/109860/06/2025 | E32: 45813 | F32: Kashif Iqbal Malik | G32: 0333-4242848 | H32: APL-4 | I32: Swift GLX CVT | J32: 2024 | K32: 4744000 | L32: 71160 | M32: 0.015 | N32: 45813 | O32: 60803 | P32: 71160 | Q32: 60803 | R32: 563 | S32: 0 | T32: 09000870/Digital sales - DA | U32: REN | W32: Hamna Ali | X32: Comprehensive | Y32: Retail Renewal | Z32: Retail Renewal (May-2025)
A33: 32 | B33: KHI/HO/D/MO/PD COMP/P/110175/06/2025 | E33: 45832 | F33: Muhammad Tayyab | G33: 0323-4179417 | H33: ALP-818 | I33: Suzuki Swift GL CVT | J33: 2022 | K33: 4800000 | L33: 10000 | M33: 0.025 | N33: 45829 | O33: 8190 | P33: 10000 | Q33: 8190 | R33: 563 | S33: - | T33: 09000870/Digital sales - DA | U33: REN | W33: Hamna Ali | X33: Pay As You Drive | Y33: Direct Renewal | Z33: (Direct Renewal June-2025)
A34: 33 | B34: KHI/HO/D/MO/PC COMP/P/109768/06/2025 | E34: 45810 | F34: ZAREEN GUL | G34: 0333-3638261 | H34: BRT-723 | I34: ALTO VXR | J34: 2020 | K34: 2000000 | L34: 36000 | M34: 0.018 | N34: 45810 | O34: 31535 | P34: 36000 | Q34: 31535 | R34: 563 | S34: 0 | T34: 09000870/Digital sales - DA | U34: REN | W34: Hamna Ali | X34: Comprehensive | Y34: Retail Renewal | Z34: Retail Renewal (June-2025)
A35: 34 | B35: LHR/LHR/D/MO/PC COMP/P/110518/07/2025 | C35: =VLOOKUP('IT Working sheet '!B35,'09000210'!B:C,2,0) -> 040000200531 | D35: ="Update ins_assorted_clients set commission_amount = '"&R35&"' where assorted_code = '"&C35&"' and agency_code = '09000870';" -> Update ins_assorted_clients set commission_amount = '563' where assorted_code = '040000200531' and agency_code = '09000870'; | E35: 45849 | F35: Shehar Bano | G35: 0332-9253454 | H35: AYW-172 | I35: ALTO | J35: 2022 | K35: 2000000 | L35: 30000 | M35: 0.015 | N35: 45811 | O35: 25624 | P35: 30000 | Q35: 25624 | R35: 563 | S35: 0 | T35: 09000870/Digital sales - DA | U35: REN | W35: Hamna Ali | X35: Comprehensive | Y35: Retail Renewal | Z35: Retail Renewal (May-2025)
A36: 35 | B36: KHI/HO/D/MO/MC COMP/P/110077/06/2025 | E36: 45826 | F36: Mr. Muhammad Hassan Raza | G36: 3412914850 | H36: KTD-2229 | I36: HONDA - Prider 100 | J36: 2025 | K36: 208900 | L36: 8356 | M36: 4 | N36: 45825 | O36: 6772 | P36: 8356 | Q36: 13544 | R36: 0 | S36: 0 | T36: 09000870/Digital sales - DA | U36: FRE | V36: 0 | W36: Syed Waqas Shah | X36: Comprehensive | Y36: Other | Z36: Other
A37: 36 | B37: KHI/HO/D/MO/PD COMP/P/109905/06/2025 | E37: 45814 | F37: Shakeel Ahmed | G37: 3343451716 | H37: CBR-607 | I37: Suzuki ALTO | J37: 2025 | K37: 3080000 | L37: 10000 | M37: 0.025 | N37: 45813 | O37: 8190 | P37: 10000 | Q37: 16380 | R37: 0 | S37: 0 | T37: 09000870/Digital sales - DA | U37: FRE | V37: 0 | W37: Syed Waqas Shah | X37: Pay As You Drive | Y37: Other | Z37: Other
A38: 37 | B38: KHI/HO/D/MO/PC COMP/P/110275/06/2025 | E38: 45838 | F38: Muhammad Noor Kamran | G38: 3072942941 | H38: BRT-862 | I38: Suzuki ALTO | J38: 2020 | K38: 2200000 | L38: 45500 | M38: 2 | N38: 45838 | O38: 38793 | P38: 45500 | Q38: 77586 | R38: 0 | S38: 0 | T38: 09000870/Digital sales - DA | U38: Fresh | W38: Syed Waqas Shah | X38: Comprehensive | Y38: Other | Z38: 0
A39: 38 | B39: KHI/HO/D/MO/PC COMP/P/110348/07/2025 | C39: =VLOOKUP('IT Working sheet '!B39,'09000210'!B:C,2,0) -> #N/A | E39: 45841 | F39: Mr. Mufti Ehsan Waquar Ahmed | G39: 3008286191 | H39: CAB-064 | I39: SUZUKI - ALTO VXR | J39: 2024 | K39: 3175000 | L39: 55563 | M39: 1.75 | N39: 45861 | O39: 47468 | P39: 55563 | Q39: 47468 | R39: 0 | S39: 0 | T39: 09000870/Digital sales - DA | U39: REN | V39: 0 | W39: Syed Waqas Shah | X39: Comprehensive | Y39: PAYD Renewal | Z39: PAYD Renewal (July-2025)
A40: 39 | B40: KHI/HO/D/MO/PC COMP/P/110556/07/2025 | C40: =VLOOKUP('IT Working sheet '!B40,'09000210'!B:C,2,0) -> #N/A | E40: 45853 | F40: Mr. Muhammad Moez Syed | G40: 3413832018 | H40: BVL-164 | I40: SUZUKI ALTO VXR | J40: 2021 | K40: 2300000 | L40: 39100 | M40: 1.7 | N40: 45853 | O40: 33276 | P40: 39100 | Q40: 33276 | R40: 0 | S40: 0 | T40: 09000870/Digital sales - DA | U40: REN | V40: 0 | W40: Syed Waqas Shah | X40: Comprehensive | Y40: Direct Renewal | Z40: Direct Renewal (July-2025)
A41: 40 | B41: KHI/HO/D/MO/PC COMP/P/110520/07/2025 | C41: =VLOOKUP('IT Working sheet '!B41,'09000210'!B:C,2,0) -> #N/A | E41: 45849 | F41: Mr. Adil Hussain | G41: 3212311508 | H41: BMV-766 | I41: SUZUKI CULTUS | J41: 2018 | K41: 2300000 | L41: 40250 | M41: 1.75 | N41: 45849 | O41: 34267 | P41: 40250 | Q41: 34267 | R41: 0 | S41: 0 | T41: 09000870/Digital sales - DA | U41: REN | V41: 0 | W41: Syed Waqas Shah | X41: Comprehensive | Y41: Direct Renewal | Z41: Direct Renewal (July-2025)
A42: 41 | B42: KHI/HO/D/MO/PC COMP/P/110425/07/2025 | C42: =VLOOKUP('IT Working sheet '!B42,'09000210'!B:C,2,0) -> #N/A | E42: 45845 | F42: Mr. Israr Ahmed Khan | G42: 3008940171 | H42: BXB-104 | I42: Suzuki ALTO | J42: 2021 | K42: 2500000 | L42: 41250 | M42: 1.65 | N42: 45845 | O42: 35130 | P42: 41250 | Q42: 35130 | R42: 0 | S42: 0 | T42: 09000870/Digital sales - DA | U42: REN | V42: 0 | W42: Syed Waqas Shah | X42: Comprehensive | Y42: Direct Renewal | Z42: Direct Renewal (July-2025)
A43: 42 | B43: KHI/HO/D/MO/CV/P/110054/06/2025 | E43: 45825 | F43: M.R Industries | G43: 3132816156 | H43: JZ-2455 | I43: MASTER - FORLAND | J43: 2016 | K43: 1000000 | L43: 15000 | M43: 1.5 | N43: 45807 | O43: 12500 | P43: 17500 | Q43: 12500 | R43: 0 | S43: 0 | T43: 09000870/Digital sales - DA | U43: REN | V43: 0 | W43: Syed Waqas Shah | X43: Comprehensive | Y43: Retail Renewal | Z43: Retail Renewal (May-2025)
...

Sheet 09000210
B1: POLICY | C1: ASSORTED_CODE
A2: 1 | B2: LHR/LHR/D/MO/PC COMP/P/110294/07/2025 | C2: 040000200020
A3: 2 | B3: LHR/LHR/D/MO/PC COMP/P/110296/07/2025 | C3: 040000200023
A4: 3 | B4: KHI/HO/D/MO/PC COMP/P/110297/07/2025 | C4: 040000200024
A5: 4 | B5: LHR/LHR/D/MO/PC COMP/P/110305/07/2025 | C5: 040000200033
A6: 5 | B6: KHI/HO/D/MO/PC COMP/P/110306/07/2025 | C6: 040000200036
A7: 6 | B7: LHR/LHR/D/MO/PC COMP/P/110307/07/2025 | C7: 040000200037
A8: 7 | B8: KHI/HO/D/MO/PC COMP/P/110334/07/2025 | C8: 040000200091
A9: 8 | B9: LHR/LHR/D/MO/PC COMP/P/110335/07/2025 | C9: 040000200092
A10: 9 | B10: KHI/HO/D/MO/PC COMP/P/110336/07/2025 | C10: 040000200103
A11: 10 | B11: LHR/LHR/D/MO/PC COMP/P/110338/07/2025 | C11: 040000200105
A12: 11 | B12: LHR/LHR/D/MO/PC COMP/P/110352/07/2025 | C12: 040000200132
A13: 12 | B13: KHI/HO/D/MO/PC COMP/P/110354/07/2025 | C13: 040000200134
... A51: 50 | B51: KHI/HO/D/MO/PC COMP/P/110563/07/2025 | C51: 040000200601

Sheet Already Marked Digital
B1: POLICY | C1: ASSORTED_CODE | D1: AGENCY_CODE
A2: 1 | B2: KHI/HO/D/MO/PC COMP/P/110301/07/2025 | C2: 040000200029 | D2: 09000870
A3: 2 | B3: KHI/HO/D/MO/PD COMP/P/110344/07/2025 | C3: 040000200115 | D3: 09000870
A4: 3 | B4: KHI/HO/D/MO/PD COMP/P/110345/07/2025 | C4: 040000200116 | D4: 09000870
A5: 4 | B5: KHI/HO/D/MO/PC COMP/P/110348/07/2025 | C5: 040000200128 | D5: 09000870
A6: 5 | B6: KHI/HO/D/MO/PC COMP/P/110425/07/2025 | C6: 040000200340 | D6: 09000870
A7: 6 | B7: KHI/HO/D/MO/PC COMP/P/110427/07/2025 | C7: 040000200342 | D7: 09000870
A8: 7 | B8: KHI/HO/D/MO/PD COMP/P/110437/07/2025 | C8: 040000200392 | D8: 09000870
A9: 8 | B9: KHI/HO/D/MO/PD COMP/P/110472/07/2025 | C9: 040000200444 | D9: 09000870
A10: 9 | B10: KHI/HO/D/MO/PC COMP/P/110479/07/2025 | C10: 040000200471 | D10: 09000870
A11: 10 | B11: KHI/HO/D/MO/PC COMP/P/110497/07/2025 | C11: 040000200500 | D11: 09000870
A12: 11 | B12: KHI/HO/D/MO/PC COMP/P/110499/07/2025 | C12: 040000200504 | D12: 09000870
A13: 12 | B13: KHI/HO/D/MO/PC COMP/P/110507/07/2025 | C13: 040000200513 | D13: 09000870
... A21: 20 | B21: KHI/HO/D/MO/PC COMP/P/110556/07/2025 | C21: 040000200592 | D21: 09000870

Sheet Sheet1
B1: POLICY | C1: ASSORTED_CODE
A2: 1 | B2: KHI/HO/D/MO/PC COMP/P/110080/06/2025 | C2: 040000199699
A3: 2 | B3: KHI/HO/D/MO/PC COMP/P/110121/06/2025 | C3: 040000199767
A4: 3 | B4: KHI/HO/D/MO/PC COMP/P/110075/06/2025 | C4: 040000199691
A5: 4 | B5: KHI/HO/D/MO/PC COMP/P/110334/07/2025 | C5: 040000200091
A6: 5 | B6: KHI/HO/D/MO/PC COMP/P/110132/06/2025 | C6: 040000199795
A7: 6 | B7: KHI/HO/D/MO/PC COMP/P/110164/06/2025 | C7: 040000199833
A8: 7 | B8: KHI/HO/D/MO/PD COMP/P/109863/06/2025 | C8: 040000199386
A9: 8 | B9: KHI/HO/D/MO/PC COMP/P/110002/06/2025 | C9: 040000199602
A10: 9 | B10: KHI/HO/D/MO/PC COMP/P/110060/06/2025 | C10: 040000199666
A11: 10 | B11: KHI/HO/D/MO/MC COMP/P/110077/06/2025 | C11: 040000199694
A12: 11 | B12: LHR/LHR/D/MO/PC COMP/P/109780/06/2025 | C12: 040000199289
A13: 12 | B13: KHI/HO/D/MO/PC COMP/P/109801/06/2025 | C13: 040000199314
... A220: 219 | B220: KHI/HO/D/MO/PC COMP/P/110143/06/2025 | C220: 040000199806
