Workbook

Sheet Fresh
A1: Policy | B1: Endorsement | C1: Issue Date | D1: Period From | E1: Period To | F1: Client Code | G1: Client Name | H1: Insured Name | I1: Make | J1: Model | K1: Reg No | L1: Engine | M1: Chassis | N1: Bank P.O No. | O1: Sum Covered | P1: Gross | Q1: Net | R1: Outstanding | S1: CNIC | T1: MOBILE | U1: Fre / Ren / Roll
A2: KHI/HO/D/MO/PC COMP/C/101342/1/11/2024 | C2: 45601 | D2: 45601 | E2: 45965 | F2: 08004499 | G2: AL BARAKA BANK (PAKISTAN) LIMITED | H2: Mr. Muhammad Ayaz Hpa M/S. Al Baraka Bank Pakitan Limited | I2: SUZUKI CULTUS | J2: 2024 | L2: 211066 | M2: 10111066 | N2: 0567-0158403371095 | O2: 4546000 | P2: 58353 | Q2: 68190 | R2: 68190 | S2: 32102-0974587-9 | T2: 0333-6488267 | U2: FRE
A3: KHI/HO/D/MO/PC COMP/C/101342/10/11/2024 | C3: 45611 | D3: 45611 | E3: 45975 | F3: 08004499 | G3: AL BARAKA BANK (PAKISTAN) LIMITED | H3: Mr. Suleman Ghufrani Hpa M/S. Al Baraka Bank Pakitan Limited | I3: PRINCE PEARL | J3: 2023 | K3: BYF-059 | L3: 4603174W | M3: 04244 | N3: 0144-0158662200017 | O3: 1430000 | P3: 24655 | Q3: 28600 | R3: 28600 | S3: 42401-7461409-5 | T3: 03243313987 | U3: FRE
A4: KHI/HO/D/MO/PC COMP/C/101342/11/11/2024 | C4: 45611 | D4: 45611 | E4: 45975 | F4: 08004499 | G4: AL BARAKA BANK (PAKISTAN) LIMITED | H4: Mr. Muhammad Asghar Hpa M/S. Al Baraka Bank Pakitan Limited | I4: SUZUKI ALTO VXR E-2 | J4: 2019 | K4: LE-19A-8013 | L4: 6R111597 | M4: H1011547 | N4: 0329-0158296002093 | O4: 2150000 | P4: 37069 | Q4: 43000 | R4: 43000 | S4: 0300-1868767 | T4: 35201-8547758-3 | U4: FRE
A5: KHI/HO/D/MO/PC COMP/C/101342/12/11/2024 | C5: 45614 | D5: 45614 | E5: 45978 | F5: 08004499 | G5: AL BARAKA BANK (PAKISTAN) LIMITED | H5: Mr. Yashwa Hpa M/S. Al Baraka Bank Pakitan Limited | I5: SUZUKI WAGON-R | J5: 2018 | K5: LEE-18-4617 | L5: 159369 | M5: 10059359 | N5: 0329-0158657010017 | O5: 2200000 | P5: 37931 | Q5: 44000 | R5: 44000 | S5: 35202-1038412-1 | T5: 0309-8489803 | U5: FRE
A6: KHI/HO/D/MO/PC COMP/C/101342/13/11/2024 | C6: 45614 | D6: 45614 | E6: 45978 | F6: 08004499 | G6: AL BARAKA BANK (PAKISTAN) LIMITED | H6: Mr. Syed Shariq Hussain Hpa M/S. Al Baraka Bank Pakitan Limited | I6: SUZUKI ALTO | J6: 2022 | K6: ANT-559 | L6: 6R264676 | M6: H1164657 | N6: 0329-0158659820016 | O6: 2350000 | P6: 40517 | Q6: 47000 | R6: 47000 | S6: 35202-0198993-4 | T6: 0334-4427974 | U6: FRE
A7: KHI/HO/D/MO/PC COMP/C/101342/14/11/2024 | C7: 45615 | D7: 45615 | E7: 45979 | F7: 08004499 | G7: AL BARAKA BANK (PAKISTAN) LIMITED | H7: Mr. Shehroze Sajjad Hpa M/S. Al Baraka Bank Pakitan Limited | I7: HONDA CIVIC | J7: 2016 | K7: LEH-16-929 | L7: R18Z 12900366 | M7: NFBFC6668GR000568 | N7: 0423-0158655221012 | O7: 4200000 | P7: 54310 | Q7: 63000 | R7: 63000 | S7: 33100-9728986-9 | T7: 03218022007 | U7: FRE
A8: KHI/HO/D/MO/PC COMP/C/101342/15/11/2024 | C8: 45615 | D8: 45615 | E8: 45979 | F8: 08004499 | G8: AL BARAKA BANK (PAKISTAN) LIMITED | H8: Mr. Muhammad Waqar Yasir Hpa M/S. Al Baraka Bank Pakitan Limited | I8: SUZUKI WAGON-R | J8: 2018 | K8: LEB-18A-2079 | L8: PK10B171472 | M8: A1J310PK10071464 | N8: 0423-0158659609018 | O8: 2200000 | P8: 37931 | Q8: 44000 | R8: 44000 | S8: 33100-8698249-7 | T8: 03006243112 | U8: FRE
A9: KHI/HO/D/MO/PC COMP/C/101342/16/11/2024 | C9: 45615 | D9: 45615 | E9: 45979 | F9: 08004499 | G9: AL BARAKA BANK (PAKISTAN) LIMITED | H9: Mr. Arslan Ahmad Hpa M/S. Al Baraka Bank Pakitan Limited | I9: CHANGAN ALSVIN | J9: 2021 | K9: AED-252 | L9: 504844 | M9: 1001076 | N9: 0329-0158659585016 | O9: 2200000 | P9: 37931 | Q9: 44000 | R9: 44000 | S9: 35202-5978593-3 | T9: 03230121377 | U9: FRE
A10: KHI/HO/D/MO/PC COMP/C/101342/17/11/2024 | C10: 45616 | D10: 45616 | E10: 45980 | F10: 08004499 | G10: AL BARAKA BANK (PAKISTAN) LIMITED | H10: Mr. Muhammad Ali Amjad Hpa M/S. Al Baraka Bank Pakitan Limited | I10: HONDA CITY 1.2 LS CVT | J10: 2024 | L10: 51028599 | M10: RR045379 | N10: 0329-0158599461021 | O10: 5118000 | P10: 66181 | Q10: 76770 | R10: 76770 | S10: 35202-0356548-1 | T10: 0305-7912778 | U10: FRE
A11: KHI/HO/D/MO/PC COMP/C/101342/18/11/2024 | C11: 45616 | D11: 45616 | E11: 45980 | F11: 08004499 | G11: AL BARAKA BANK (PAKISTAN) LIMITED | H11: Mr. Tariq Zaman Hpa M/S. Al Baraka Bank Pakitan Limited | I11: CHANGAN OSHAN X7 COMFORT | J11: 2024 | L11: 258334 | M11: 1001076 | N11: 0557-0158631946060 | O11: 8099000 | P11: 104729 | Q11: 121485 | R11: 121485 | S11: 35404-1231863-9 | T11: 0333-4696856 | U11: FRE
A12: KHI/HO/D/MO/PC COMP/C/101342/19/11/2024 | C12: 45617 | D12: 45617 | E12: 45981 | F12: 08004499 | G12: AL BARAKA BANK (PAKISTAN) LIMITED | H12: Mr. Zain Kamran Hpa M/S. Al Baraka Bank Pakitan Limited | I12: HONDA CIVIC | J12: 2017 | K12: LEA-18-5005 | L12: 2923652 | M12: R026853 | N12: 0329-0158662329019 | O12: 4500000 | P12: 58190 | Q12: 67500 | R12: 67500 | S12: 35202-1661348-5 | T12: 03224375761 | U12: FRE
A13: KHI/HO/D/MO/PC COMP/C/101342/2/11/2024 | C13: 45601 | D13: 45601 | E13: 45965 | F13: 08004499 | G13: AL BARAKA BANK (PAKISTAN) LIMITED | H13: M/S Al Baraka Bank Pvt Limited User Qamar Uz Zaman | I13: HONDA BRV - S | J13: 2018 | K13: BG-7323 | L13: 13508318 | M13: 008323 | N13: 0150-0158356943080 | O13: 4000000 | P13: 51724 | Q13: 60000 | R13: 60000 | S13: 13101-0987747-9 | T13: 0300-8293676 | U13: FRE
A14: KHI/HO/D/MO/PC COMP/C/101342/20/11/2024 | C14: 45617 | D14: 45617 | E14: 45981 | F14: 08004499 | G14: AL BARAKA BANK (PAKISTAN) LIMITED | H14: Mr. Muhammad Ashfaq Hpa M/S. Al Baraka Bank Pakitan Limited | I14: SUZUKI ALTO AGS A/T | J14: 2024 | L14: 327572 | M14: 1227594 | N14: 0329-0158354737051 | O14: 3045000 | P14: 52500 | Q14: 60900 | R14: 60900 | S14: 35201-8495750-1 | T14: 03154842519 | U14: FRE
A15: KHI/HO/D/MO/PC COMP/C/101342/21/11/2024 | C15: 45618 | D15: 45618 | E15: 45982 | F15: 08004499 | G15: AL BARAKA BANK (PAKISTAN) LIMITED | H15: Mr. Muhammad Ishaq Hpa M/S. Al Baraka Bank Pakitan Limited | I15: TOYOTA COROLLA XLI 1.3 | J15: 2016 | K15: LEE-16-7683 | L15: Z-453472 | M15: R-4082875 | N15: 0329-0190663097017 | O15: 3500000 | P15: 45258 | Q15: 52500 | R15: 52500 | S15: 35202-2743264-1 | T15: 0300-4124797 | U15: FRE
A16: KHI/HO/D/MO/PC COMP/C/101342/22/11/2024 | C16: 45621 | D16: 45621 | E16: 45985 | F16: 08004499 | G16: AL BARAKA BANK (PAKISTAN) LIMITED | H16: Mr. Muhammad Ishaq Hpa M/S. Al Baraka Bank Pakitan Limited | I16: TOYOTA COROLLA XLI 1.3 | J16: 2016 | K16: LEE-16-7683 | L16: Z-453472 | M16: R-4082875 | N16: 0329-0190663098017 | O16: 3500000 | P16: 45258 | Q16: 52500 | R16: 52500 | S16: 35202-2743264-1 | T16: 0300-4124797 | U16: FRE
A17: KHI/HO/D/MO/PC COMP/C/101342/23/11/2024 | C17: 45622 | D17: 45621 | E17: 45985 | F17: 08004499 | G17: AL BARAKA BANK (PAKISTAN) LIMITED | H17: Ms. Shazia Hpa M/S. Al Baraka Bank Pakitan Limited | I17: SUZUKI ALTO | J17: 2020 | K17: BRU-904 | L17: 132859 | M17: 1032848 | N17: 0144-0158662498016 | O17: 2200000 | P17: 37931 | Q17: 44000 | R17: 44000 | S17: 41304-5386428-2 | T17: 0316-2290124 / 0332-0129532 | U17: FRE
A18: KHI/HO/D/MO/PC COMP/C/101342/24/11/2024 | C18: 45623 | D18: 45623 | E18: 45987 | F18: 08004499 | G18: AL BARAKA BANK (PAKISTAN) LIMITED | H18: Mr. Fahad Khan Hpa M/S. Al Baraka Bank Pakitan Limited | I18: SUZUKI ALTO | J18: 2022 | K18: BXX-585 | L18: 259073 | M18: 1159056 | N18: 0144-0158484136024 | O18: 2580000 | P18: 44483 | Q18: 51600 | R18: 51600 | S18: 42201-8269267-9 | T18: 0321-3892668 | U18: FRE
A19: KHI/HO/D/MO/PC COMP/C/101342/25/11/2024 | C19: 45623 | D19: 45623 | E19: 45987 | F19: 08004499 | G19: AL BARAKA BANK (PAKISTAN) LIMITED | H19: Ms. Najma Khalid Hpa M/S. Al Baraka Bank Pakitan Limited | I19: SUZUKI ALTO | J19: 2024 | K19: BZP-223 | L19: 6R301631 | M19: 1201615 | N19: 0144-0158662042011 | O19: 3045000 | P19: 52500 | Q19: 60900 | R19: 60900 | S19: 42401-4528238-2 | T19: 0335-0364261 | U19: FRE
A20: KHI/HO/D/MO/PC COMP/C/101342/26/11/2024 | C20: 45623 | D20: 45623 | E20: 45987 | F20: 08004499 | G20: AL BARAKA BANK (PAKISTAN) LIMITED | H20: Mr. Masroor Hussain Shaikh Hpa M/S. Al Baraka Bank Pakitan Limited | I20: HAVAL H6 | J20: 2024 | L20: 24458525345 | M20: NF9EF4A55R2011384 | N20: 0423-0158453239055 | O20: 9240990 | P20: 119496 | Q20: 138615 | R20: 138615 | S20: 33100-8457855-3 | T20: 03006622609 | U20: FRE
A21: KHI/HO/D/MO/PC COMP/C/101342/27/11/2024 | C21: 45624 | D21: 45624 | E21: 45988 | F21: 08004499 | G21: AL BARAKA BANK (PAKISTAN) LIMITED | H21: Mr. Shoaib Mumtaz Karimi Hpa M/S. Al Baraka Bank Pakitan Limited | I21: HONDA CITY | J21: 2022 | K21: BVL-063 | L21: 1002546 | M21: R007831 | N21: 0144-0158573635040 | O21: 4300000 | P21: 55603 | Q21: 64500 | R21: 64500 | S21: 42201-1922431-9 | T21: 0323-2427407 | U21: FRE
A22: KHI/HO/D/MO/PC COMP/C/101342/28/11/2024 | C22: 45624 | D22: 45624 | E22: 45988 | F22: 08004499 | G22: AL BARAKA BANK (PAKISTAN) LIMITED | H22: Mr. Anwar Hussain Hpa M/S. Al Baraka Bank Pakitan Limited | I22: SUZUKI ALTO VXR | J22: 2021 | K22: ACE-549 | L22: 6R155121 | M22: NF1AET306H1055115 | N22: 0423-0158659786022 | O22: 2350000 | P22: 40517 | Q22: 47000 | R22: 47000 | S22: 33100-1018236-7 | T22: 03018477696 | U22: FRE
A23: KHI/HO/D/MO/PC COMP/C/101342/29/11/2024 | C23: 45624 | D23: 45624 | E23: 45988 | F23: 08004499 | G23: AL BARAKA BANK (PAKISTAN) LIMITED | H23: Mr. Abbas Ali Raza Hpa M/S. Al Baraka Bank Pakitan Limited | I23: SUZUKI ALTO VXL | J23: 2020 | K23: AAM-115 | L23: 141367 | M23: 1041346 | N23: 0329-0158393263093 | O23: 2600000 | P23: 44828 | Q23: 52000 | R23: 52000 | S23: 35202-2788820-9 | T23: 0321-8418668/03218877199 | U23: FRE
A24: KHI/HO/D/MO/PC COMP/C/101342/3/11/2024 | C24: 45601 | D24: 45601 | E24: 45965 | F24: 08004499 | G24: AL BARAKA BANK (PAKISTAN) LIMITED | H24: M/S. Al Baraka Bank Pakistan Limited User Mr. Salman Ul Hasan Farooqui | I24: TOYOTA Yaris ATIV 1.3 (CV | J24: 2021 | K24: BTJ-559 | L24: 23589 | M24: 7014189 | N24: 0150-0158660005011 | O24: 3800000 | P24: 49138 | Q24: 57000 | R24: 57000 | S24: 42201-3793346-7 | T24: 0334-2935319 | U24: FRE
A25: KHI/HO/D/MO/PC COMP/C/101342/30/11/2024 | C25: 45625 | D25: 45625 | E25: 45989 | F25: 08004499 | G25: AL BARAKA BANK (PAKISTAN) LIMITED | H25: Mr. Muhammad Imran Hpa M/S. Al Baraka Bank Pakitan Limited | I25: SUZUKI ALTO | J25: 2024 | L25: 329402 | M25: 1229433 | N25: 0471-0158539789073 | O25: 2707000 | P25: 46672 | Q25: 54140 | R25: 54140 | S25: 31202-7193485-7 | T25: 0331-9750269 | U25: FRE
A26: KHI/HO/D/MO/PC COMP/C/101342/31/11/2024 | C26: 45625 | D26: 45625 | E26: 45989 | F26: 08004499 | G26: AL BARAKA BANK (PAKISTAN) LIMITED | H26: Mr. Muhammad Khizar Shahid Hpa M/S. Al Baraka Bank Pakitan Limited | I26: CHANGAN ALSVIN | J26: 2024 | L26: JL473Q4R3EE503388 | M26: NKMA2CBR4R1002269 | N26: 0423-0158622007049 | O26: 3799000 | P26: 49125 | Q26: 56985 | R26: 56985 | S26: 33100-9965645-9 | T26: 03054752845 | U26: FRE
A27: KHI/HO/D/MO/PC COMP/C/101342/32/11/2024 | C27: 45625 | D27: 45625 | E27: 45989 | F27: 08004499 | G27: AL BARAKA BANK (PAKISTAN) LIMITED | H27: Mr. Ali Sajdain Hpa M/S. Al Baraka Bank Pakitan Limited | I27: TOYOTA FORTUNER | J27: 2017 | K27: LEB-17-85 | L27: 2TRA191376 | M27: R0440023 | N27: 0555-0158661913017 | O27: 10000000 | P27: 129310 | Q27: 150000 | R27: 150000 | S27: 36401-6862732-9 | T27: 0300-1737659 | U27: FRE
A28: KHI/HO/D/MO/PC COMP/C/101342/33/11/2024 | C28: 45625 | D28: 45625 | E28: 45989 | F28: 08004499 | G28: AL BARAKA BANK (PAKISTAN) LIMITED | H28: Mr. Muhammad Nafees Ul Hasan Hpa M/S. Al Baraka Bank Pakitan Limited | I28: HONDA CITY A/T | J28: 2019 | K28: AMY-625 | L28: 17528374 | M28: 246273 | N28: 0158212747061 | O28: 3700000 | P28: 47845 | Q28: 55500 | R28: 55500 | S28: 37406-4790615-3 | T28: 0334-5493469 | U28: FRE
A29: KHI/HO/D/MO/PC COMP/C/101342/34/11/2024 | C29: 45625 | D29: 45625 | E29: 45989 | F29: 08004499 | G29: AL BARAKA BANK (PAKISTAN) LIMITED | H29: Mr. Muhammad Kashif Riaz Hpa M/S. Al Baraka Bank Pakitan Limited | I29: TOYOTA COROLLA ALTIS GRAN | J29: 2021 | K29: AFL-382 | L29: 352872 | M29: 7052027 | N29: 0329-0190537150046 | O29: 6500000 | P29: 84051 | Q29: 97500 | R29: 97500 | S29: 35202-2738726-1 | T29: 0300-4274750 | U29: FRE
A30: KHI/HO/D/MO/PC COMP/C/101342/35/11/2024 | C30: 45625 | D30: 45625 | E30: 45989 | F30: 08004499 | G30: AL BARAKA BANK (PAKISTAN) LIMITED | H30: Mr. Muhammad Shahid Kamran Hpa M/S. Al Baraka Bank Pakitan Limited | I30: SUZUKI ALTO VXR | J30: 2021 | K30: ADT-706 | L30: 173118 | M30: 1073104 | N30: 04310158656888025 | O30: 2300000 | P30: 39655 | Q30: 46000 | R30: 46000 | S30: 36302-7849860-1 | T30: 0302-8281828 | U30: FRE
A31: KHI/HO/D/MO/PC COMP/C/101342/36/11/2024 | C31: 45625 | D31: 45625 | E31: 45989 | F31: 08004499 | G31: AL BARAKA BANK (PAKISTAN) LIMITED | H31: Mr. Jawad Ali Hpa M/S. Al Baraka Bank Pakitan Limited | I31: SUZUKI WAGON R VXL | J31: 2018 | K31: AHS-798 | L31: 154325 | M31: 10054284 | N31: 0158661996011 | O31: 2000000 | P31: 34483 | Q31: 40000 | R31: 40000 | S31: 37402-56363775 | T31: 0370-3607475 | U31: FRE
A32: KHI/HO/D/MO/PC COMP/C/101342/37/11/2024 | C32: 45625 | D32: 45625 | E32: 45989 | F32: 08004499 | G32: AL BARAKA BANK (PAKISTAN) LIMITED | H32: Mr. Malik Mudasir Ishaq Awan Hpa M/S. Al Baraka Bank Pakitan Limited | I32: SUZUKI WAGON-R | J32: 2018 | L32: 157394 | M32: 10057383 | N32: 0158656884017 | O32: 2350000 | P32: 40517 | Q32: 47000 | R32: 47000 | S32: 38403-5962463-5 | T32: 0343-6900055 | U32: FRE
A33: KHI/HO/D/MO/PC COMP/C/101342/38/11/2024 | C33: 45625 | D33: 45625 | E33: 45989 | F33: 08004499 | G33: AL BARAKA BANK (PAKISTAN) LIMITED | H33: Mr. Ali Raza Hpa M/S. Al Baraka Bank Pakitan Limited | I33: SUZUKI ALTO | J33: 2024 | L33: 6R327743 | M33: NF1AET306H1227717 | N33: 0423-0158664040019 | O33: 3045000 | P33: 52500 | Q33: 60900 | R33: 60900 | S33: 33102-7155367-3 | T33: 03009665273 | U33: FRE
A34: KHI/HO/D/MO/PC COMP/C/101342/39/11/2024 | C34: 45625 | D34: 45625 | E34: 45989 | F34: 08004499 | G34: AL BARAKA BANK (PAKISTAN) LIMITED | H34: Mr. Mashhood Hussain Hpa M/S. Al Baraka Bank Pakitan Limite | I34: TOYOTA COROLLA GLI M/T 1. | J34: 2017 | K34: LEB-17-9993 | L34: Z 488598 | M34: NZE170R-4115365 | N34: 0423-0158662834010 | O34: 3800000 | P34: 49138 | Q34: 57000 | R34: 57000 | S34: 33101-1692539-3 | T34: 03005812280 | U34: FRE
A35: KHI/HO/D/MO/PC COMP/C/101342/4/11/2024 | C35: 45601 | D35: 45601 | E35: 45965 | F35: 08004499 | G35: AL BARAKA BANK (PAKISTAN) LIMITED | H35: Mr. Saad Ali Malik Hpa M/S. Al Baraka Bank Pakitan Limited | I35: CHANGAN KARVAAN PLUS | J35: 2024 | L35: 503240 | M35: 1002056 | N35: 0329-0158639985010 | O35: 2999000 | P35: 51707 | Q35: 59980 | R35: 59980 | S35: 35202-2530201-9 | T35: 0323-4276411 | U35: FRE
A36: KHI/HO/D/MO/PC COMP/C/101342/40/11/2024 | C36: 45625 | D36: 45625 | E36: 45989 | F36: 08004499 | G36: AL BARAKA BANK (PAKISTAN) LIMITED | H36: Mr. Muhammad Shahbaz Hussain Hpa M/S. Al Baraka Bank Pakitan Limited | I36: TOYOTA COROLLA ALTIS 1.6 | J36: 2019 | K36: BPP-903 | L36: 055473 | M36: 6032976 | N36: 0431-0158663831015 | O36: 4700000 | P36: 60776 | Q36: 70500 | R36: 70500 | S36: 36302-6044116-3 | T36: 0300-6326541 | U36: FRE
A37: KHI/HO/D/MO/PC COMP/C/101342/41/11/2024 | C37: 45625 | D37: 45625 | E37: 45989 | F37: 08004499 | G37: AL BARAKA BANK (PAKISTAN) LIMITED | H37: Applicant Name: Yasir Malik Co Applicant Name: Noman Malik Hpa M/S. Al Baraka Bank Pakitan Limited Cnic No. 42301-8517065-9 | I37: TOYOTA COROLLA GLI | J37: 2017 | K37: BHQ-926 | L37: Z478235 | M37: 4103790 | N37: 0144-0158149211078 | O37: 3640000 | P37: 47069 | Q37: 54600 | R37: 54600 | S37: 42301-1696748-9 | T37: 0345-8127868 / 0315-3178600 | U37: FRE
A38: KHI/HO/D/MO/PC COMP/C/101342/42/11/2024 | C38: 45625 | D38: 45625 | E38: 45989 | F38: 08004499 | G38: AL BARAKA BANK (PAKISTAN) LIMITED | H38: Mr. Muhammad Shafiq Hpa M/S. Al Baraka Bank Pakitan Limited | I38: SUZUKI WAGON R VXL | J38: 2022 | K38: ALE-716 | L38: B238601 | M38: PK10138615 | N38: 0329-0158662901013 | O38: 2500000 | P38: 43103 | Q38: 50000 | R38: 50000 | S38: 35202-6534038-3 | T38: 0304-1490988 | U38: FRE
A39: KHI/HO/D/MO/PC COMP/C/101342/43/11/2024 | C39: 45625 | D39: 45625 | E39: 45989 | F39: 08004499 | G39: AL BARAKA BANK (PAKISTAN) LIMITED | H39: Mr. Muhammad Naeem Hpa M/S. Al Baraka Bank Pakitan Limited | I39: HONDA CIVIC | J39: 2018 | K39: AJB-629 | L39: 2934155 | M39: 037588 | N39: 0190663734017 | O39: 5000000 | P39: 64655 | Q39: 75000 | R39: 75000 | S39: 38103-9411169-1 | T39: 0313-5298606 | U39: FRE
A40: KHI/HO/D/MO/PC COMP/C/101342/44/11/2024 | C40: 45625 | D40: 45625 | E40: 45989 | F40: 08004499 | G40: AL BARAKA BANK (PAKISTAN) LIMITED | H40: Mr. Muhammad Mustafa Zaidi Hpa M/S. Al Baraka Bank Pakitan Limited | I40: TOYOTA YARIS ATIV X CVT | J40: 2021 | K40: AWU-417 | L40: 42433 | M40: 7026645 | N40: 0431-0190552825056 | O40: 3700000 | P40: 47845 | Q40: 55500 | R40: 55500 | S40: 36101-0262152-9 | T40: 03006884855 | U40: FRE
...

Sheet Renewal
A1: S.No. | B1: Policy | C1: Endorsement | D1: Issue Date | E1: Period From | F1: Period To | G1: Client Code | H1: Client Name | I1: Insured Name | J1: Make | K1: Model | L1: Reg No | M1: Engine | N1: Chassis | O1: Bank P.O No. | P1: Sum Covered | Q1: Gross | R1: Net | S1: Outstanding | T1: CNIC | U1: MOBILE | V1: Fre / Ren / Roll
A2: 1 | B2: KHI/HO/D/MO/PC COMP/C/102088/1/11/2024 | D2: 45614 | E2: 45600 | F2: 45964 | G2: 08004499 | H2: AL BARAKA BANK (PAKISTAN) LIMITED | I2: Mr. Muhammad Habib Ullah Hpa M/S. Al Baraka Bank (Pakistan) Limited | J2: SUZUKI ALTO VXR E-2 | K2: 2021 | L2: AFQ-947 | M2: 190976 | N2: 1091001 | O2: 0421-0158538331013 | P2: 1068000 | Q2: 22586 | R2: 26700 | S2: 26700 | T2: 3310477555807 | U2: 03217645628 | V2: REN
A3: 2 | B3: KHI/HO/D/MO/PC COMP/C/102088/10/11/2024 | D3: 45615 | E3: 45602 | F3: 45966 | G3: 08004499 | H3: AL BARAKA BANK (PAKISTAN) LIMITED | I3: Mr. Ch Zubair Sultan Hpa M/S. Al Baraka Bank (Pakistan) Limited | J3: SUZUKI ALTO VXL | K3: 2023 | M3: 286437 | N3: 1186398 | O3: 0158629318015 | P3: 2641500 | Q3: 45544 | R3: 52830 | S3: 52830 | T3: 37405-4068374-5 | U3: 0312-5062087 | V3: REN
A4: 3 | B4: KHI/HO/D/MO/PC COMP/C/102088/11/11/2024 | D4: 45615 | E4: 45609 | F4: 45973 | G4: 08004499 | H4: AL BARAKA BANK (PAKISTAN) LIMITED | I4: Mr. Khawaja Ghulam Qutubiddin Faridi Hpa M/S. Al Baraka Bank (Pakistan) Limited | J4: HYUNDAI TUSCON AWD | K4: 2023 | L4: AQL-303 | M4: 363639 | N4: 214684 | O4: 0475-0190561643031 | P4: 7991100 | Q4: 103334 | R4: 119867 | S4: 119867 | T4: 31301-1481658-9 | U4: 0300-9411696 | V4: REN
A5: 4 | B5: KHI/HO/D/MO/PC COMP/C/102088/12/11/2024 | D5: 45615 | E5: 45603 | F5: 45967 | G5: 08004499 | H5: AL BARAKA BANK (PAKISTAN) LIMITED | I5: Mr. Muhammad Sajid Akbar Hpa M/S. Al Baraka Bank (Pakistan) Limited | J5: HONDA CITY ASPIRE A/T | K5: 2015 | L5: LEB-15-154 | M5: 17424195 | N5: 161447 | O5: 0329-015862878014 | P5: 2340000 | Q5: 40345 | R5: 46800 | S5: 46800 | T5: 35202-3989676-1 | U5: 0307-4139338 | V5: REN
A6: 5 | B6: KHI/HO/D/MO/PC COMP/C/102088/13/11/2024 | D6: 45615 | E6: 45603 | F6: 45967 | G6: 08004499 | H6: AL BARAKA BANK (PAKISTAN) LIMITED | I6: Mr. Muhammad Tahir Khan Hpa M/S. Al Baraka Bank (Pakistan) Limited | J6: TOYOTA HILUX REVO 4X4 AT | K6: 2019 | L6: KY-7676 | M6: 0555514 | N6: 5533920 | O6: 0144-0190191987101 | P6: 9000000 | Q6: 116379 | R6: 135000 | S6: 135000 | T6: 42101-2186939-5 | U6: 0336-7000414 | V6: REN
A7: 6 | B7: KHI/HO/D/MO/PC COMP/C/102088/14/11/2024 | D7: 45615 | E7: 45602 | F7: 45966 | G7: 08004499 | H7: AL BARAKA BANK (PAKISTAN) LIMITED | I7: Mr. Muhammad Afzaal Hpa M/S. Al Baraka Bank (Pakistan) Limited | J7: SUZUKI Swift GLX CVT | K7: 2023 | M7: 1016022 | N7: 116050 | O7: 0329-0158398326082 | P7: 4026600 | Q7: 52068 | R7: 60399 | S7: 60399 | T7: 36502-3335632-3 | U7: 0301-6925966 | V7: REN
A8: 7 | B8: KHI/HO/D/MO/PC COMP/C/102088/15/11/2024 | D8: 45615 | E8: 45609 | F8: 45973 | G8: 08004499 | H8: AL BARAKA BANK (PAKISTAN) LIMITED | I8: Mr. Mola Bux Hpa M/S. Al Baraka Bank (Pakistan) Limited | J8: SUZUKI CULTUS VXL | K8: 2021 | L8: BVK-050 | M8: 176740 | N8: 10076759 | O8: 0291- 0158630981013 | P8: 2700000 | Q8: 46551 | R8: 54000 | S8: 54000 | T8: 41201-9470144-9 | U8: 0345-3559379 | V8: REN
A9: 8 | B9: KHI/HO/D/MO/PC COMP/C/102088/16/11/2024 | D9: 45615 | E9: 45611 | F9: 45975 | G9: 08004499 | H9: AL BARAKA BANK (PAKISTAN) LIMITED | I9: Ms. Rubina Shakil Hpa M/S. Al Baraka Bank (Pakistan) Limited | J9: HONDA CITY ASPIRE CVT PT | K9: 2020 | L9: AAP-682 | M9: 7979967 | N9: 263769 | O9: 0329-0158630213016 | P9: 3870000 | Q9: 50044 | R9: 58050 | S9: 58050 | T9: 35202-2631910-2 | U9: 0306-4006048 | V9: REN
A10: 9 | B10: KHI/HO/D/MO/PC COMP/C/102088/17/11/2024 | D10: 45615 | E10: 45613 | F10: 45977 | G10: 08004499 | H10: AL BARAKA BANK (PAKISTAN) LIMITED | I10: Mr. Ubaid Ul Hassan Hpa M/S. Al Baraka Bank (Pakistan) Limited | J10: SUZUKI MEHRAN | K10: 2019 | L10: BPZ-328 | M10: 769467 | N10: PK01307999 | O10: 0475-0158481245022 | P10: 1260000 | Q10: 21724 | R10: 25200 | S10: 25200 | T10: 31301-0794482-1 | U10: 0300-7595760 | V10: REN
A11: 10 | B11: KHI/HO/D/MO/PC COMP/C/102088/18/11/2024 | D11: 45615 | E11: 45623 | F11: 45987 | G11: 08004499 | H11: AL BARAKA BANK (PAKISTAN) LIMITED | I11: Mr. Adnan Manzoor Hpa M/S. Al Baraka Bank (Pakistan) Limited | J11: SUZUKI WAGON R VXL | K11: 2023 | M11: 245535 | N11: 10145532 | O11: 0329-0158535719082 | P11: 2889090 | Q11: 49812 | R11: 57782 | S11: 57782 | T11: 35202-6351581-9 | U11: 0300-4955525 | V11: REN
A12: 11 | B12: KHI/HO/D/MO/PC COMP/C/102088/19/11/2024 | D12: 45615 | E12: 45616 | F12: 45980 | G12: 08004499 | H12: AL BARAKA BANK (PAKISTAN) LIMITED | I12: Ms. Shazia Ilyas Hpa M/S. Al Baraka Bank (Pakistan) Limited | J12: SUZUKI ALTO AGS A/T | K12: 2019 | L12: LE-19A-8665 | M12: 6R114253 | N12: 1014246 | O12: 0329-0158631406016 | P12: 1980000 | Q12: 34138 | R12: 39600 | S12: 39600 | T12: 35201-8805782-4 | U12: 0320-0481224 | V12: REN
A13: 12 | B13: KHI/HO/D/MO/PC COMP/C/102088/2/11/2024 | D13: 45615 | E13: 45598 | F13: 45962 | G13: 08004499 | H13: AL BARAKA BANK (PAKISTAN) LIMITED | I13: Mr. Maqbool Hussain Hpa M/S. Al Baraka Bank (Pakistan) Limited | J13: SUZUKI MEHRAN VXR EURO-II | K13: 2016 | L13: MND-16-513 | M13: 646276 | N13: 1184768 | O13: 0431-0190629229014 | P13: 900000 | Q13: 15517 | R13: 18000 | S13: 18000 | T13: 36303-1218351-3 | U13: 0308-7337513 | V13: REN
A14: 13 | B14: KHI/HO/D/MO/PC COMP/C/102088/20/11/2024 | D14: 45615 | E14: 45616 | F14: 45980 | G14: 08004499 | H14: AL BARAKA BANK (PAKISTAN) LIMITED | I14: Mr. Umair Khurshid Hpa M/S. Al Baraka Bank (Pakistan) Limited | J14: SUZUKI CULTUS | K14: 2023 | L14: BZD-416 | M14: 206862 | N14: 10106865 | O14: 0251-0158630197010 | P14: 3675600 | Q14: 47530 | R14: 55134 | S14: 55134 | T14: 4180106338861 | U14: 0301-2547511/0301-3625771 | V14: REN
A15: 14 | B15: KHI/HO/D/MO/PC COMP/C/102088/21/11/2024 | D15: 45615 | E15: 45617 | F15: 45981 | G15: 08004499 | H15: AL BARAKA BANK (PAKISTAN) LIMITED | I15: Mr. Abdul Latif Anjum Hpa M/S. Al Baraka Bank (Pakistan) Limited | J15: TOYOTA COROLLA ALTIS GRAN | K15: 2015 | L15: LE-15-4944 | M15: Q305485 | N15: 7004493 | O15: 0329-0190625798015 | P15: 3420000 | Q15: 44224 | R15: 51300 | S15: 51300 | T15: 35301-7228382-3 | V15: REN
A16: 15 | B16: KHI/HO/D/MO/PC COMP/C/102088/22/11/2024 | D16: 45615 | E16: 45617 | F16: 45981 | G16: 08004499 | H16: AL BARAKA BANK (PAKISTAN) LIMITED | I16: Mr. Muhammad Bilal Hpa M/S. Al Baraka Bank (Pakistan) Limited | J16: SUZUKI CULTUS | K16: 2019 | L16: LEA-19A-8848 | M16: 153572 | N16: 10053552 | O16: 0329-0158631531011 | P16: 2655000 | Q16: 45776 | R16: 53100 | S16: 53100 | T16: 34501-5066738-3 | U16: 0344-9508864 | V16: REN
A17: 16 | B17: KHI/HO/D/MO/PC COMP/C/102088/23/11/2024 | D17: 45615 | E17: 45617 | F17: 45981 | G17: 08004499 | H17: AL BARAKA BANK (PAKISTAN) LIMITED | I17: Mr. Muhammad Faisal Hpa M/S. Al Baraka Bank (Pakistan) Limited | J17: TOYOTA COROLLA ALTIS 1.6 | K17: 2021 | L17: BUZ-973 | M17: Q076041 | N17: 6053544 | O17: 0144-015831554019 | P17: 4680000 | Q17: 60517 | R17: 70200 | S17: 70200 | T17: 42201-7547271-3 | U17: 0321-9234561 | V17: REN
A18: 17 | B18: KHI/HO/D/MO/PC COMP/C/102088/24/11/2024 | D18: 45615 | E18: 45618 | F18: 45982 | G18: 08004499 | H18: AL BARAKA BANK (PAKISTAN) LIMITED | I18: Mr. Waseem Ur Rehman Khan Hpa M/S. Al Baraka Bank (Pakistan) Limited | J18: HONDA BRV - S | K18: 2021 | L18: ADY-423 | M18: 14805426 | N18: R-022099 | O18: 0329-0158598069018 | P18: 4500000 | Q18: 58190 | R18: 67500 | S18: 67500 | T18: 35202-3039501-5 | U18: 0321-4447860 | V18: REN
A19: 18 | B19: KHI/HO/D/MO/PC COMP/C/102088/25/11/2024 | D19: 45615 | E19: 45618 | F19: 45982 | G19: 08004499 | H19: AL BARAKA BANK (PAKISTAN) LIMITED | I19: Mr. Irshad Hussain Shah Hpa M/S. Al Baraka Bank (Pakistan) Limited | J19: TOYOTA COROLLA GLI A/T 1. | K19: 2018 | L19: LEH-18-3592 | M19: Z522826 | N19: NZE170R4149473 | P19: 3600000 | Q19: 46551 | R19: 54000 | S19: 54000 | V19: REN
A20: 19 | B20: KHI/HO/D/MO/PC COMP/C/102088/26/11/2024 | D20: 45615 | E20: 45619 | F20: 45983 | G20: 08004499 | H20: AL BARAKA BANK (PAKISTAN) LIMITED | I20: Mr. Zee Waqar Hamdani Hpa M/S. Al Baraka Bank (Pakistan) Limited | J20: TOYOTA COROLLA ALTIS GRAN | K20: 2016 | L20: BGM-568 | M20: Q317657 | N20: 7016745 | O20: 0461-0158628225027 | P20: 3645000 | Q20: 47134 | R20: 54675 | S20: 54675 | T20: 31303-3792229-9 | U20: 0300-9672044 | V20: REN
A21: 20 | B21: KHI/HO/D/MO/PC COMP/C/102088/27/11/2024 | D21: 45615 | E21: 45619 | F21: 45983 | G21: 08004499 | H21: AL BARAKA BANK (PAKISTAN) LIMITED | I21: Mr. Qaseem Ghouri Hpa M/S. Al Baraka Bank (Pakistan) Limited | J21: HONDA CITY 1.2 LS CVT | K21: 2021 | L21: AHQ-222 | M21: 51005042 | N21: MR007389 | O21: 0329-0158631731015 | P21: 3856500 | Q21: 49869 | R21: 57848 | S21: 57848 | T21: 35200-6187214-5 | U21: 0333-4438757 | V21: REN
A22: 21 | B22: KHI/HO/D/MO/PC COMP/C/102088/28/11/2024 | D22: 45615 | E22: 45619 | F22: 45983 | G22: 08004499 | H22: AL BARAKA BANK (PAKISTAN) LIMITED | I22: Ms. Kousar Parveen Hpa M/S. Al Baraka Bank (Pakistan) Limited | J22: KIA SPORTAGE | K22: 2020 | L22: AQT-792 | M22: G4NALH311475 | N22: NNAQL51AZKP301959 | O22: 0423-0190631887012 | P22: 6210000 | Q22: 80302 | R22: 93150 | S22: 93150 | T22: 33100-7585016-4 | U22: 03335372555 | V22: REN
A23: 22 | B23: KHI/HO/D/MO/PC COMP/C/102088/29/11/2024 | D23: 45615 | E23: 45620 | F23: 45984 | G23: 08004499 | H23: AL BARAKA BANK (PAKISTAN) LIMITED | I23: Mr. Azhar Iqbal Hpa M/S. Al Baraka Bank (Pakistan) Limited | J23: HONDA CIVIC | K23: 2016 | L23: ABT-951 | M23: 12902029 | N23: 002548 | O23: 0329-0158055720024 | P23: 3600000 | Q23: 46551 | R23: 54000 | S23: 54000 | T23: 61101-2557033-3 | U23: 0321-7766666 | V23: REN
A24: 23 | B24: KHI/HO/D/MO/PC COMP/C/102088/3/11/2024 | D24: 45615 | E24: 45598 | F24: 45962 | G24: 08004499 | H24: AL BARAKA BANK (PAKISTAN) LIMITED | I24: Mr. Malik Azhar Rasheed Hpa M/S. Al Baraka Bank (Pakistan) Limited | J24: HONDA CITY I-VTEC (M/T) | K24: 2018 | L24: LE-19-4802 | M24: 17523976 | N24: 241102 | O24: 0431-0158623451011 | P24: 3150000 | Q24: 40733 | R24: 47250 | S24: 47250 | T24: 32302-0126354-7 | U24: 0300-6303070 | V24: REN
A25: 24 | B25: KHI/HO/D/MO/PC COMP/C/102088/30/11/2024 | D25: 45615 | E25: 45623 | F25: 45987 | G25: 08004499 | H25: AL BARAKA BANK (PAKISTAN) LIMITED | I25: Mr. Muhammad Kashif Hpa M/S. Al Baraka Bank (Pakistan) Limited | J25: SUZUKI ALTO VXR | K25: 2022 | L25: AKG-180 | M25: 6R207097 | N25: NF1AET306H1107105 | O25: 0431-0158631573019 | P25: 1890000 | Q25: 32586 | R25: 37800 | S25: 37800 | T25: 36303-8077968-9 | U25: 0305-7093427 | V25: REN
A26: 25 | B26: KHI/HO/D/MO/PC COMP/C/102088/31/11/2024 | D26: 45615 | E26: 45624 | F26: 45988 | G26: 08004499 | H26: AL BARAKA BANK (PAKISTAN) LIMITED | I26: Mr. Muhammad Danish Alvi Hpa M/S. Al Baraka Bank (Pakistan) Limited | J26: SUZUKI ALTO | K26: 2023 | L26: BZF-681 | M26: 285749 | N26: 1185525 | O26: 0144-0158520859021 | P26: 2641500 | Q26: 45544 | R26: 52830 | S26: 52830 | T26: 42000-4320363-1 | U26: 0333-0388313 | V26: REN
A27: 26 | B27: KHI/HO/D/MO/PC COMP/C/102088/32/11/2024 | D27: 45615 | E27: 45624 | F27: 45988 | G27: 08004499 | H27: AL BARAKA BANK (PAKISTAN) LIMITED | I27: Mr. Waseem Ali Hpa M/S. Al Baraka Bank (Pakistan) Limited | J27: CHANGAN KARVAAN PLUS | K27: 2023 | M27: 503682 | N27: 1000024 | O27: 0329-0158632233010 | P27: 2699100 | Q27: 46537 | R27: 53982 | S27: 53982 | T27: 35202-1851552-9 | U27: 0300-8809800 | V27: REN
A28: 27 | B28: KHI/HO/D/MO/PC COMP/C/102088/33/11/2024 | D28: 45615 | E28: 45624 | F28: 45988 | G28: 08004499 | H28: AL BARAKA BANK (PAKISTAN) LIMITED | I28: Mr. Muhammad Zahid Hameed Hpa M/S. Al Baraka Bank (Pakistan) Limited | J28: SUZUKI WAGON R VXL | K28: 2022 | L28: AKY-395 | M28: 237005 | N28: 1037003 | O28: 0158619518057 | P28: 1800000 | Q28: 31035 | R28: 36000 | S28: 36000 | T28: 36502-6470474-3 | U28: 0313-6472414 | V28: REN
A29: 28 | B29: KHI/HO/D/MO/PC COMP/C/102088/34/11/2024 | D29: 45615 | E29: 45624 | F29: 45988 | G29: 08004499 | H29: AL BARAKA BANK (PAKISTAN) LIMITED | I29: Mr. Tauqeer Nasir Hpa M/S. Al Baraka Bank (Pakistan) Limited | J29: TOYOTA COROLL A/T | K29: 2016 | L29: LEF-16-6741 | M29: Z456113 | N29: 4085409 | O29: 0401-0158630603013 | P29: 3420000 | Q29: 44224 | R29: 51300 | S29: 51300 | T29: 34101-2376692-5 | U29: 0321-6492517 | V29: REN
A30: 29 | B30: KHI/HO/D/MO/PC COMP/C/102088/35/11/2024 | D30: 45615 | E30: 45625 | F30: 45989 | G30: 08004499 | H30: AL BARAKA BANK (PAKISTAN) LIMITED | I30: Mr. Arslan Amanat Hpa M/S. Al Baraka Bank (Pakistan) Limited | J30: TOYOTA YARIS ATIV X 1.5 A | K30: 2020 | L30: AAG-432 | M30: 2A06448 | N30: R9502991 | O30: 0329-0158632221015 | P30: 4050000 | Q30: 52370 | R30: 60750 | S30: 60750 | T30: 35401-1388807-9 | U30: 03037127132 | V30: REN
A31: 30 | B31: KHI/HO/D/MO/PC COMP/C/102088/36/11/2024 | D31: 45615 | E31: 45625 | F31: 45989 | G31: 08004499 | H31: AL BARAKA BANK (PAKISTAN) LIMITED | I31: Mr. Syed Tasawar Hussain Shah Hpa M/S. Al Baraka Bank (Pakistan) Limited | J31: KIA SPORTAGE | K31: 2019 | L31: APY-19-105 | M31: H039166 | N31: P501200 | O31: 0329-0190535930038 | P31: 6300000 | Q31: 81465 | R31: 94500 | S31: 94500 | T31: 35202-3947424-3 | U31: 0309-8935828 | V31: REN
A32: 31 | B32: KHI/HO/D/MO/PC COMP/C/102088/37/11/2024 | D32: 45615 | E32: 45625 | F32: 45989 | G32: 08004499 | H32: AL BARAKA BANK (PAKISTAN) LIMITED | I32: Mr. Syed Kazim Raza Hpa M/S. Al Baraka Bank (Pakistan) Limited | J32: HYUNDAI TUCSON | K32: 2022 | L32: AXF-110 | M32: 166986 | N32: 205930 | O32: 0158512836103 | P32: 7200000 | Q32: 93103 | R32: 108000 | S32: 108000 | T32: 37405-2794958-7 | U32: 0300-8562457 | V32: REN
A33: 32 | B33: KHI/HO/D/MO/PC COMP/C/102088/38/11/2024 | D33: 45615 | E33: 45625 | F33: 45989 | G33: 08004499 | H33: AL BARAKA BANK (PAKISTAN) LIMITED | I33: Mr. Muhammad Atif Hpa M/S. Al Baraka Bank (Pakistan) Limited | J33: HONDA HRV-S | K33: 2022 | L33: BL-1701 | M33: 1000065 | N33: R000036 | O33: 0150-0158468151066 | P33: 6075000 | Q33: 78556 | R33: 91125 | S33: 91125 | T33: 42201-4240047-9 | U33: 0321-8992399 | V33: REN
A34: 33 | B34: KHI/HO/D/MO/PC COMP/C/102088/39/11/2024 | D34: 45615 | E34: 45625 | F34: 45989 | G34: 08004499 | H34: AL BARAKA BANK (PAKISTAN) LIMITED | I34: Mr. Asif Ali Hpa M/S. Al Baraka Bank (Pakistan) Limited | J34: CHANGAN KARVAAN PLUS | K34: 2023 | M34: 502000 | N34: 1000118 | O34: 0150-0158620484017 | P34: 2699100 | Q34: 46537 | R34: 53982 | S34: 53982 | T34: 42501-1452686-1 | U34: 0300-2664207 | V34: REN
A35: 34 | B35: KHI/HO/D/MO/PC COMP/C/102088/4/11/2024 | D35: 45615 | E35: 45598 | F35: 45962 | G35: 08004499 | H35: AL BARAKA BANK (PAKISTAN) LIMITED | I35: Mr. Asghar Hpa M/S. Al Baraka Bank (Pakistan) Limited | J35: SUZUKI ALTO | K35: 2023 | L35: BYR-476 | M35: 272065 | N35: 1172053 | O35: 0431-0158630120019 | P35: 2610000 | Q35: 45000 | R35: 52200 | S35: 52200 | T35: 36302-2216170-1 | U35: 0306-7348540 | V35: REN
A36: 35 | B36: KHI/HO/D/MO/PC COMP/C/102088/40/11/2024 | D36: 45615 | E36: 45626 | F36: 45990 | G36: 08004499 | H36: AL BARAKA BANK (PAKISTAN) LIMITED | I36: Mr. Noman Yaqoob Hpa M/S. Al Baraka Bank (Pakistan) Limited | J36: SUZUKI ALTO VXR | K36: 2022 | L36: BAW-357 | M36: 253142 | N36: 1153131 | O36: 0158632025019 | P36: 2340000 | Q36: 40345 | R36: 46800 | S36: 46800 | T36: 36201-1892246-9 | U36: 0333-5227921 | V36: REN
A37: 36 | B37: KHI/HO/D/MO/PC COMP/C/102088/41/11/2024 | D37: 45615 | E37: 45626 | F37: 45990 | G37: 08004499 | H37: AL BARAKA BANK (PAKISTAN) LIMITED | I37: Mr. Naik Muhammad Hpa M/S. Al Baraka Bank (Pakistan) Limited | J37: SUZUKI ALTO | K37: 2021 | L37: BVR-062 | M37: 172572 | N37: 1072558 | O37: 0252-0158632587019 | P37: 1890000 | Q37: 32586 | R37: 37800 | S37: 37800 | T37: 56201-8524762-9 | U37: 0312-8138981 | V37: REN
A38: 37 | B38: KHI/HO/D/MO/PC COMP/C/102088/42/11/2024 | D38: 45615 | E38: 45626 | F38: 45990 | G38: 08004499 | H38: AL BARAKA BANK (PAKISTAN) LIMITED | I38: Mr. Muhammad Maqsood Ahmad Hpa M/S. Al Baraka Bank (Pakistan) Limited | J38: SUZUKI CULTUS | K38: 2018 | L38: LEB-18-8695 | M38: 107875 | N38: 10007825 | O38: 0329-0158631063018 | P38: 1350000 | Q38: 23276 | R38: 27000 | S38: 27000 | T38: 31103-1148491-1 | U38: 03004169209 | V38: REN
A39: 38 | B39: KHI/HO/D/MO/PC COMP/C/102088/43/11/2024 | D39: 45615 | E39: 45626 | F39: 45990 | G39: 08004499 | H39: AL BARAKA BANK (PAKISTAN) LIMITED | I39: Applicant Name. Mr. Syed Saad Ahmed Co Applicant Name. Mr. Syed Mubussir Ahmed Cnic No. 42401-7695120-3 Hpa M/S. Al Baraka Bank (Pakistan) Limited | J39: FAW FAW V2 M/T | K39: 2018 | L39: BMZ ? 934 | M39: HJ-300217 | N39: M-18001686 | O39: 0144-0158631438013 | P39: 1192500 | Q39: 20560 | R39: 23850 | S39: 23850 | T39: 42401-2815097-9 | U39: 0313-2360329 - 0333-3144016 | V39: REN
A40: 39 | B40: KHI/HO/D/MO/PC COMP/C/102088/44/11/2024 | D40: 45615 | E40: 45626 | F40: 45990 | G40: 08004499 | H40: AL BARAKA BANK (PAKISTAN) LIMITED | I40: Mr. Anees Ahmad Hpa M/S. Al Baraka Bank (Pakistan) Limited | J40: DAIHATSU MOVE | K40: 2021 | L40: AQE-149 | M40: K091977KF | N40: LA150S2108067 | O40: 0471-0190632194014 | P40: 3420000 | Q40: 44224 | R40: 51300 | S40: 51300 | T40: 36201-2910103-7 | U40: 03002677666 | V40: REN
...

Sheet Previous
A1: S.No. | B1: Policy | C1: Endorsement | D1: Issue Date | E1: Period From | F1: Period To | G1: Client Code | H1: Client Name | I1: Insured Name | J1: Make | K1: Model | L1: Reg No | M1: Engine | N1: Chassis | O1: Bank P.O No. | P1: Sum Covered | Q1: Gross | R1: Net | S1: Outstanding | T1: CNIC | U1: MOBILE | V1: Fre / Ren / Roll
A2: 1 | B2: KHI/HO/D/MO/PC COMP/C/100245/13/10/2024 | D2: 45593 | E2: 45575 | F2: 45939 | G2: 08004499 | H2: AL BARAKA BANK (PAKISTAN) LIMITED | I2: M/S. Al Baraka Bank (Pakistan) Limited User:Abdul Raheem Khan | J2: SUZUKI ALTO VXR E-2 | K2: 2022 | L2: AMC-809 | M2: 6R250482 | N2: 1150468 | P2: 1423750 | Q2: 30684 | R2: 35594 | S2: 35594 | T2: 3520113900661 | U2: 0321-9460000 | V2: REN
A3: 2 | B3: KHI/HO/D/MO/PC COMP/C/100245/148/10/2024 | D3: 45593 | E3: 45590 | F3: 45954 | G3: 08004499 | H3: AL BARAKA BANK (PAKISTAN) LIMITED | I3: M/S. Al Baraka Bank (Pakistan) Limited User:Khawaja Adnan Farqalet | J3: HYUNDAI ELANTRA 2.0 MP1 A | K3: 2022 | L3: ALZ-424 | M3: 633253 | N3: 304093 | P3: 4845000 | Q3: 62650 | R3: 72675 | S3: 72675 | T3: 3130141526033 | U3: 0300-3212333 | V3: REN
A4: 3 | B4: KHI/HO/D/MO/PC COMP/C/100245/15/10/2024 | D4: 45593 | E4: 45578 | F4: 45942 | G4: 08004499 | H4: AL BARAKA BANK (PAKISTAN) LIMITED | I4: M/S. Al Baraka Bank (Pakistan) Limited User:Muhammad Imran | J4: SUZUKI ALTO | K4: 2022 | L4: AMJ-926 | M4: 6R250637 | N4: H1150643 | P4: 1108400 | Q4: 23888 | R4: 27710 | S4: 27710 | T4: 3520106651813 | U4: 0322-9333300 | V4: REN
A5: 4 | B5: KHI/HO/D/MO/PC COMP/C/100245/16/10/2024 | D5: 45593 | E5: 45579 | F5: 45943 | G5: 08004499 | H5: AL BARAKA BANK (PAKISTAN) LIMITED | I5: M/S. Al Baraka Bank (Pakistan) Limited User:Rehan Mehmood | J5: SUZUKI ALTO VX EURO II | K5: 2022 | L5: AMD-568 | M5: 250961 | N5: 1150921 | P5: 1473050 | Q5: 31747 | R5: 36826 | S5: 36826 | T5: 3640115109781 | U5: 0333-4977723 | V5: REN
A6: 5 | B6: KHI/HO/D/MO/PC COMP/C/100245/168/10/2024 | D6: 45593 | E6: 45577 | F6: 45941 | G6: 08004499 | H6: AL BARAKA BANK (PAKISTAN) LIMITED | I6: M/S. Al Baraka Bank (Pakistan) Limited User:Layon Ivan Patrick Lobo | J6: HONDA CITY 1.2 LS CVT | K6: 2023 | L6: BZB-199 | M6: 51019539 | N6: 034236 | P6: 4462200 | Q6: 48084 | R6: 55778 | S6: 55778 | T6: 4220198430769 | U6: 0300-8257704 | V6: REN
A7: 6 | B7: KHI/HO/D/MO/PC COMP/C/100245/17/10/2024 | D7: 45593 | E7: 45583 | F7: 45947 | G7: 08004499 | H7: AL BARAKA BANK (PAKISTAN) LIMITED | I7: M/S. Al Baraka Bank (Pakistan) Limited User:Nehal Ahmed | J7: SUZUKI ALTO VXL AGS E-2 | K7: 2022 | L7: BAW-147 | M7: 6R253021 | N7: H-1153014 | P7: 1603100 | Q7: 34549 | R7: 40078 | S7: 40078 | T7: 5230103220055 | U7: 0333-7887700 | V7: REN
A8: 7 | B8: KHI/HO/D/MO/PC COMP/C/100245/26/10/2024 | D8: 45593 | E8: 45577 | F8: 45941 | G8: 08004499 | H8: AL BARAKA BANK (PAKISTAN) LIMITED | I8: M/S. Al Baraka Bank (Pakistan) Limited User:Aziz Batool | J8: SUZUKI ALTO VXR E-2 | K8: 2021 | L8: AVH-254 | M8: 187234 | N8: 1087224 | P8: 1068000 | Q8: 23017 | R8: 26700 | S8: 26700 | T8: 3720192460774 | U8: 0343-1969934 | V8: REN
A9: 8 | B9: KHI/HO/D/MO/PC COMP/C/100245/28/10/2024 | D9: 45593 | E9: 45587 | F9: 45951 | G9: 08004499 | H9: AL BARAKA BANK (PAKISTAN) LIMITED | I9: M/S. Al Baraka Bank (Pakistan) Limited User:Imran Haider Leghari | J9: SUZUKI ALTO VXR E-2 | K9: 2021 | L9: AFV-613 | M9: 187642 | N9: 1087640 | P9: 1068000 | Q9: 23017 | R9: 26700 | S9: 26700 | T9: 3210260846063 | U9: 0333-6474347 | V9: REN
A10: 9 | B10: KHI/HO/D/MO/PC COMP/C/100245/40/10/2024 | D10: 45593 | E10: 45567 | F10: 45931 | G10: 08004499 | H10: AL BARAKA BANK (PAKISTAN) LIMITED | I10: M/S. Al Baraka Bank (Pakistan) Limited User:Muhammad Imran Khan | J10: TOYOTA COROLLA ALTIS VVT- | K10: 2020 | L10: ART-351 | M10: Q067506 | N10: 6045004 | P10: 2507250 | Q10: 54036 | R10: 62681 | S10: 62681 | T10: 3540219739381 | U10: 0300-4041366 | V10: REN
A11: 10 | B11: KHI/HO/D/MO/PC COMP/C/100245/54/10/2024 | D11: 45593 | E11: 45594 | F11: 45958 | G11: 08004499 | H11: AL BARAKA BANK (PAKISTAN) LIMITED | I11: M/S. Al Baraka Bank (Pakistan) Limited User:Syeda Zehra Batool | J11: SUZUKI ALTO VXR E-2 | K11: 2020 | L11: BSL-343 | M11: 142335 | N11: 1042275 | P11: 1224750 | Q11: 26396 | R11: 30619 | S11: 30619 | T11: 4210169995720 | U11: 0335-3053466 | V11: REN
A12: 11 | B12: KHI/HO/D/MO/PC COMP/C/100245/62/10/2024 | D12: 45593 | E12: 45589 | F12: 45953 | G12: 08004499 | H12: AL BARAKA BANK (PAKISTAN) LIMITED | I12: M/S. Al Baraka Bank (Pakistan) Limited User:Salman Ali | J12: PRINCE PEARL | K12: 2020 | L12: AAT-347 | M12: K12611481W | N12: RAILPPM20E00125 | P12: 1080000 | Q12: 18621 | R12: 21600 | S12: 21600 | T12: 3120251917929 | U12: 0308-8208208 | V12: REN
A13: 12 | B13: KHI/HO/D/MO/PC COMP/C/100245/7/10/2024 | D13: 45593 | E13: 45581 | F13: 45945 | G13: 08004499 | H13: AL BARAKA BANK (PAKISTAN) LIMITED | I13: M/S. Al Baraka Bank (Pakistan) Limited User:Malik Javed | J13: HONDA N BOX | K13: 2014 | L13: LE-19A-6513 | M13: S07A 1766029 | N13: JF1-1505594 | P13: 857500 | Q13: 25873 | R13: 30013 | S13: 30013 | T13: 3520198476263 | U13: 0301-4465015 | V13: REN
A14: 13 | B14: KHI/HO/D/MO/PC COMP/C/49561/15/05/2018 | D14: 43242 | E14: 43235 | F14: 43599 | G14: 08004499 | H14: AL BARAKA BANK (PAKISTAN) LIMITED | I14: M/S Al Baraka Bank Pakistan Limited User: Mr. Muhammad Muzaffar Mughal (Cnic No. 35202-5119350-3),(Cell No. 0321-4832045) | J14: TOYOTA COROLLA GLI 588W M | K14: 2015 | M14: Z252513 | N14: 4031441 | P14: 1416400 | Q14: 39917 | R14: 53115 | S14: 53115 | V14: REN
A15: 14 | B15: KHI/HO/D/MO/PC COMP/C/50726/6/05/2019 | D15: 43608 | E15: 43600 | F15: 43965 | G15: 08004499 | H15: AL BARAKA BANK (PAKISTAN) LIMITED | I15: M/S Al Baraka Bank Pakistan Limited User: Mr. Muhammad Muzaffar Mughal | J15: TOYOTA COROLLA GLI 588W M | K15: 2015 | M15: Z252513 | N15: 4031441 | O15: 24052-1 | P15: 1327875 | Q15: 43680 | R15: 49795 | S15: 49795 | T15: 35202-5119350-3 | U15: 0321-4832045 | V15: REN
A16: 16 | B16: KHI/HO/D/MO/PC COMP/C/54476/35/05/2021 | D16: 44344 | E16: 44315 | F16: 44679 | G16: 08004499 | H16: AL BARAKA BANK (PAKISTAN) LIMITED | I16: Mr. Safdar Abbas M/S. Al Baraka Bank (Pakistan) Limited | J16: TOYOTA COROLLA ALTIS VVT- | K16: 2018 | L16: AKV-369 | M16: Q329822 | N16: 7028877 | P16: 2057600 | Q16: 67684 | R16: 77160 | S16: 77160 | T16: 36302-0314989-7 | U16: 0345-7309684 | V16: REN
A17: 17 | B17: KHI/HO/D/MO/PC COMP/C/54476/36/05/2021 | D17: 44344 | E17: 44195 | F17: 44559 | G17: 08004499 | H17: AL BARAKA BANK (PAKISTAN) LIMITED | I17: Mr. Atif Manzoor Hpa M/S. Al Baraka Bank (Pakistan) Limited | J17: TOYOTA COROLLA XLI 1.3 | K17: 2018 | M17: Z547382 | N17: 4173230 | O17: 0333-0158347835070 | P17: 1641060 | Q17: 53982 | R17: 61540 | S17: 61540 | T17: 35201-4190422-9 | U17: 0300-4895056 | V17: REN
A18: 18 | B18: KHI/HO/D/MO/PC COMP/C/55237/68/08/2021 | C18: KHI/HO/D/MO/PC COMP/E/17584/00068/09/2021 | D18: 44445 | E18: 44435 | F18: 44799 | G18: 08004499 | H18: AL BARAKA BANK (PAKISTAN) LIMITED | I18: Hpa M/S. Al Baraka Bank (Pakistan) Limited User: Mr. Muhammad Babar | J18: HONDA CIVIC VTI PT ORIEL | K18: 2021 | M18: Z16925066 | N18: R-077528 | P18: 115000 | Q18: 1513 | R18: 1725 | S18: 1725 | T18: 35202-4084513-3 | U18: 0333-4455210 | V18: FRE
A19: 19 | B19: KHI/HO/D/MO/PC COMP/C/55586/10/09/2021 | C19: KHI/HO/D/MO/PC COMP/E/17902/00010/10/2021 | D19: 44484 | E19: 44447 | F19: 44811 | G19: 08004499 | H19: AL BARAKA BANK (PAKISTAN) LIMITED | I19: Mr. Muhammad Shahnawaz Hpa M/S. Al Baraka Bank (Pakistan) Limited | J19: TOYOTA YARIS ATIV MT 1.3 | K19: 2021 | L19: BUK-180 | M19: 2A35165 | N19: R-7021901 | O19: 0144-0158539397012 | P19: 100000 | Q19: 2193 | R19: 2500 | S19: 2500 | T19: 3130490402153 | U19: 03002841960 | V19: FRE
A20: 20 | B20: KHI/HO/D/MO/PC COMP/C/58494/24/02/2022 | D20: 44602 | E20: 44588 | F20: 44952 | G20: 08004499 | H20: AL BARAKA BANK (PAKISTAN) LIMITED | I20: Mr. Fahad Mushtaq Hpa M/S Al Baraka Bank (Pakistan) Limited | J20: HYUNDAI ELANTRA 2.0 MP1 A | K20: 2022 | M20: 962406 | N20: 302794 | O20: 0329-0158551869019 | P20: 3607920 | Q20: 55385 | R20: 63139 | S20: 3007 | T20: 35202-0788593-1 | U20: 3330457507 | V20: REN
A21: 21 | B21: KHI/HO/D/MO/PC COMP/C/60196/1/04/2022 | D21: 44665 | E21: 44620 | F21: 44984 | G21: 08004499 | H21: AL BARAKA BANK (PAKISTAN) LIMITED | I21: Mr. Imran Ali Hpa M/S. Al Baraka Bank (Pakistan) Limited | J21: TOYOTA COROLLA GLI M/T 1. | K21: 2020 | L21: LEA20-101 | M21: Z575212 | N21: 4200921 | O21: 0329-0158477069012 | P21: 2322400 | Q21: 76350 | R21: 87090 | S21: 87090 | T21: 3520271630131 | U21: 0300-4129113 | V21: REN
A22: 22 | B22: KHI/HO/D/MO/PC COMP/C/62063/54/07/2022 | D22: 44770 | E22: 44770 | F22: 45134 | G22: 08004499 | H22: AL BARAKA BANK (PAKISTAN) LIMITED | I22: Mr. Sadaqat Hpa M/S. Al Baraka Bank (Pakistan) Limited | J22: SUZUKI WAGONR | K22: 2022 | M22: 239025 | N22: 10139045 | O22: 0158492561015 | P22: 2204000 | Q22: 38666 | R22: 44080 | S22: 100 | T22: 35202-1714731-5 | U22: 0300-4185945 | V22: FRE
A23: 23 | B23: KHI/HO/D/MO/PC COMP/C/64082/19/10/2022 | C23: KHI/HO/D/MO/PC COMP/E/22204/00019/11/2022 | D23: 44887 | E23: 44847 | F23: 45211 | G23: 08004499 | H23: AL BARAKA BANK (PAKISTAN) LIMITED | I23: Mr. Muhammad Imran Hpa M/S. Al Baraka Bank (Pakistan) Limited | J23: SUZUKI ALTO | K23: 2022 | M23: 6R250637 | N23: H1150643 | O23: 0329-0158568232019 | P23: 2000 | Q23: 44 | R23: 50 | S23: 50 | T23: 35201-0665181-3 | U23: 0322-9333300 | V23: FRE
A24: 26 | B24: KHI/HO/D/MO/PC COMP/C/67797/108/02/2023 | D24: 44973 | E24: 44985 | F24: 45349 | G24: 08004499 | H24: AL BARAKA BANK (PAKISTAN) LIMITED | I24: Mr. Umair Shahzad Hpa M/S Al Baraka Bank (Pakistan) Limited | J24: SUZUKI WAGON R VXL | K24: 2022 | L24: L E - 19A- 4333 | M24: pk10B 199398 | N24: A1J310PK 10099391 | O24: 0423-0158565040019 | P24: 1530000 | Q24: 33552 | R24: 38250 | S24: 38250 | T24: 33100-8960123-9 | U24: 0306-7923001 | V24: REN
A25: 30 | B25: KHI/HO/D/MO/PC COMP/C/70036/33/04/2023 | C25: KHI/HO/D/MO/PC COMP/E/33621/00033/10/2023 | D25: 45226 | E25: 45044 | F25: 45409 | G25: 08004499 | H25: AL BARAKA BANK (PAKISTAN) LIMITED | I25: Mr. Noman Mehdi Hpa M/S. Al Baraka Bank Pakistan Limited | J25: TOYOTA YARIS ATIV X CVT | K25: 2021 | M25: 24518 | N25: 9509772 | O25: 0150-0158513906013 | P25: 1479750 | Q25: 9922 | R25: 11311 | S25: 11311 | T25: 42201-0298934-3 | U25: 0331-2156400 | V25: REN
A26: 32 | B26: KHI/HO/D/MO/PC COMP/C/70038/18/04/2023 | D26: 45042 | E26: 45046 | F26: 45411 | G26: 08004499 | H26: AL BARAKA BANK (PAKISTAN) LIMITED | I26: Mr. Muhammad Kamran Riaz Hpa M/S. Al Baraka Bank (Pakistan) Limited | J26: SUZUKI WAGON R VXL AGS | K26: 2019 | L26: LEE-19-8850 | M26: 192111 | N26: 10092099 | O26: 8880-0158445660018 | P26: 1008000 | Q26: 33157 | R26: 37800 | S26: 37800 | T26: 35202-8023349-3 | U26: 0310-4400042 | V26: REN
A27: 33 | B27: KHI/HO/D/MO/PC COMP/C/71697/10/06/2023 | D27: 45083 | E27: 45084 | F27: 45449 | G27: 08004499 | H27: AL BARAKA BANK (PAKISTAN) LIMITED | I27: Mr. Manzoor Ahmad M/S Al Baraka Bank Pakistan Limited | J27: SUZUKI ALTO VXR | K27: 2022 | L27: APK-834 | M27: 6R233563 | N27: 1133544 | O27: 0158527786023 | P27: 1391400 | Q27: 30513 | R27: 34785 | S27: 34785 | T27: 35202-6840699-1 | U27: 0346-4625052 | V27: REN
A28: 35 | B28: KHI/HO/D/MO/PC COMP/C/72871/6/07/2023 | D28: 45120 | E28: 45113 | F28: 45478 | G28: 08004499 | H28: AL BARAKA BANK (PAKISTAN) LIMITED | I28: Mr. Sarwar Ijaz Yousaf Hpa M/S. Al Baraka Bank Pakistan Limited | J28: KIA PICANTO 1.0L A/T | K28: 2021 | L28: AED-923 | M28: 007315 | N28: 705193 | O28: 0329-015853493948035 | P28: 1761200 | Q28: 38623 | R28: 44030 | S28: 44030 | T28: 35201-1366351-9 | U28: 0305-4051947 | V28: REN
A29: 36 | B29: KHI/HO/D/MO/PC COMP/C/72882/14/07/2023 | D29: 45121 | E29: 45122 | F29: 45487 | G29: 08004499 | H29: AL BARAKA BANK (PAKISTAN) LIMITED | I29: Mr. Tariq Mehmood Khan Hpa M/S. Al Baraka Bank Pakistan Limited | J29: SUZUKI CULTUS VXL EURO II | K29: 2021 | L29: AUE-852 | M29: 178707 | N29: 10078700 | O29: 0158531470010 | P29: 1712880 | Q29: 37563 | R29: 42822 | S29: 2379 | T29: 61101-0332684-9 | U29: 0331-5022818 | V29: REN
A30: 37 | B30: KHI/HO/D/MO/PC COMP/C/73558/29/08/2023 | D30: 45169 | E30: 45169 | F30: 45534 | G30: 08004499 | H30: AL BARAKA BANK (PAKISTAN) LIMITED | I30: Mr Faraz Khan Hpa M/S. Al Baraka Bank (Pakistan) Limited | J30: CHANGAN ALSVIN LUMEIRE | K30: 2021 | L30: BVY-587 | M30: 507324 | N30: 001530 | O30: 0150-0158286624029 | P30: 3500000 | Q30: 46052 | R30: 52500 | S30: 52500 | T30: 4210179692533 | U30: 03361175137 | V30: FRE
A31: 38 | B31: KHI/HO/D/MO/PC COMP/C/73778/42/08/2023 | D31: 45147 | E31: 45154 | F31: 45519 | G31: 08004499 | H31: AL BARAKA BANK (PAKISTAN) LIMITED | I31: Mr. Nadeem Iqbal Hpa M/S. Al Baraka Bank (Pakistan) Limited | J31: TOYOTA YARIS ATIV CVT | K31: 2021 | L31: AEM-451 | M31: 2A33905 | N31: 7021031 | O31: 0329-0158542406018 | P31: 2297550 | Q31: 50385 | R31: 57439 | S31: 57439 | T31: 35202-2956612-5 | U31: 0300-4434559 | V31: REN
A32: 39 | B32: KHI/HO/D/MO/PC COMP/C/73783/5/08/2023 | D32: 45147 | E32: 45169 | F32: 45534 | G32: 08004499 | H32: AL BARAKA BANK (PAKISTAN) LIMITED | I32: Mr. Muhammad Iftikhar Shaheen Hpa M/S. Al Baraka Bank (Pakistan) Limited | J32: SUZUKI CULTUS VXR EURO-II | K32: 2014 | L32: LE-14-1776 | M32: 587861 | N32: 494732 | O32: 0432-0158420677024 | P32: 490000 | Q32: 16119 | R32: 18375 | S32: 18375 | T32: 36303-2959950-7 | U32: 0301-6585071 | V32: REN
A33: 40 | B33: KHI/HO/D/MO/PC COMP/C/73784/17/08/2023 | D33: 45147 | E33: 45168 | F33: 45533 | G33: 08004499 | H33: AL BARAKA BANK (PAKISTAN) LIMITED | I33: Mr. Ahmad Murtaza Hpa M/S. Al Baraka Bank (Pakistan) Limited | J33: SUZUKI ALTO VXL AGS E-2 | K33: 2019 | L33: LEH-19-8447 | M33: R100670 | N33: 1000635 | O33: 0334-0158460045013 | P33: 1046250 | Q33: 34416 | R33: 39234 | S33: 39234 | T33: 35202-2678669-9 | U33: 0345-6380511 | V33: REN
A34: 41 | B34: KHI/HO/D/MO/PC COMP/C/75212/45/09/2023 | D34: 45181 | E34: 45199 | F34: 45564 | G34: 08004499 | H34: AL BARAKA BANK (PAKISTAN) LIMITED | I34: Mr. Muzammil Sultan Hpa M/S. Al Baraka Bank (Pakistan) Limited | J34: SUZUKI HUSTLER | K34: 2014 | L34: LEF-18-1825 | M34: 587928 | N34: 248447 | O34: 0329-0158504578015 | P34: 1040000 | Q34: 22807 | R34: 26000 | S34: 26000 | T34: 35201-8859207-5 | U34: 0304-4868643 | V34: REN
A35: 42 | B35: KHI/HO/D/MO/CV/C/76377/2/10/2023 | D35: 45208 | E35: 45210 | F35: 45575 | G35: 08004499 | H35: AL BARAKA BANK (PAKISTAN) LIMITED | I35: Mr. Muhammad Irfan Hassan Hpa M/S. Al Baraka Bank (Pakistan) Limited | J35: SUZUKI RAVI VX EURO II | K35: 2018 | L35: LET-18-2500 | M35: 340052 | N35: 444709 | O35: 0318-0158393987047 | P35: 529200 | Q35: 17408 | R35: 19845 | S35: 19845 | T35: 35202-1142411-3 | U35: 0322-4057066 | V35: REN
A36: 45 | B36: KHI/HO/D/MO/PC COMP/C/77944/49/11/2023 | D36: 45243 | E36: 45260 | F36: 45625 | G36: 08004499 | H36: AL BARAKA BANK (PAKISTAN) LIMITED | I36: Mr. Asad Ur Rehman Hpa M/S Al Baraka Bank ( Pakistan ) Limited | J36: SUZUKI CULTUS | K36: 2018 | L36: LEB-18-5272 | M36: 116918 | N36: 10016932 | O36: 0329-0158588327024 | P36: 1665000 | Q36: 29211 | R36: 33300 | S36: 33300 | T36: 35202-6681934-9 | U36: 0322-8844215 | V36: REN
A37: 47 | B37: KHI/HO/D/MO/PC COMP/C/77949/38/11/2023 | D37: 45243 | E37: 45249 | F37: 45614 | G37: 08004499 | H37: AL BARAKA BANK (PAKISTAN) LIMITED | I37: Mr. Sohail Akhtar Hpa M/S. Al Baraka Bank (Pakistan) Limited | J37: TOYOTA COROLLA ALTIS A/T | K37: 2021 | L37: BVB-717 | M37: Q083847 | N37: 6061338 | O37: 0144-0158532430017 | P37: 2929500 | Q37: 32122 | R37: 36619 | S37: 2039 | T37: 42000-4357310-7 | U37: 0333-1034923 | V37: REN
A38: 48 | B38: KHI/HO/D/MO/CV/P/78003/11/2023 | D38: 45243 | E38: 45236 | F38: 47062 | G38: 08004499 | H38: AL BARAKA BANK (PAKISTAN) LIMITED | I38: Mr. Zulfiqar Ali HPA M/s. Al Baraka Bank (Pakistan) Limited Cnic No. 33100-2489572-1 Cell No. | J38: MESSY FERGUSEN MF-385 | K38: 2023 | L38: CAQ-8730 | M38: 618004 J | N38: 902141723 | P38: 3465000 | Q38: 75943 | R38: 86625 | S38: 86625 | V38: FRE
A39: 49 | B39: KHI/HO/D/MO/PC COMP/C/78104/4/11/2023 | D39: 45245 | E39: 45253 | F39: 45618 | G39: 08004499 | H39: AL BARAKA BANK (PAKISTAN) LIMITED | I39: Hpa M/S. Al Baraka Bank (Pakistan) Limited User: Imran Mehmood | J39: SUZUKI WAGON-R VXL E2 | K39: 2018 | L39: LEA-19-3100 | M39: 177360 | N39: 10077353 | O39: 0318-0158420742013 | P39: 891800 | Q39: 29336 | R39: 33443 | S39: 33443 | T39: 3520104051913 | U39: 0321-9464455 | V39: REN
A40: 50 | B40: KHI/HO/D/MO/PC COMP/C/78104/5/11/2023 | D40: 45245 | E40: 45237 | F40: 45602 | G40: 08004499 | H40: AL BARAKA BANK (PAKISTAN) LIMITED | I40: Hpa M/S. Al Baraka Bank (Pakistan) Limited User: Muhammad Kashif Javed | J40: TOYOTA COROLLA XLI 1.3 | K40: 2018 | L40: LED-19-3004 | M40: Z541722 | N40: 4167558 | O40: 0318-0158427595017 | P40: 1613250 | Q40: 53067 | R40: 60497 | S40: 60497 | T40: 3520222692645 | U40: 0333-4443107 | V40: REN
...

Sheet Summary
C4: Cases | D4: Total No. of Policies | E4: Outstanding
C5: Fresh | D5: 45 | E5: 2726635
C6: Renewal | D6: 204 | E6: 8646391
C7: Previous | D7: 121 | E7: 4818357
C8: Total | D8: 370 | E8: 16191383

Sheet Fresh Billing
A1: Fresh / Renewal | B1: Proposal No. | C1: Billing Month | D1: Takaful Company | E1: PMD / Cert | F1: Takaful Start Date | G1: Takaful End Date | H1: Customer Name | I1: CNIC | J1: Vehicle Make | K1: Reg. No | L1: Engine No | M1: Chassis No | N1: Proposal No. | O1: Region | P1: Unit ID | Q1: BR # | R1: Financing Date | S1: Maturity Date | T1: Asset Value | U1: Dep. % | V1: Dep. Amount | W1: Sum Cover Amount | X1: Takaful Rate | Y1: Premium Amount | Z1: For Takaful Company Rectifications | AA1: For COD Status | AB1: PO No. | AC1: PO Dates | AD1: Proposal Status | AE1: Default Case (Overdue Days) | AG1: Policy No. | AI1: Premium Amount | AJ1: Diff Amount | AK1: Sum Cover Amount | AL1: Diff Amount | AM1: Tagging | AN1: Tracker Name
A2: Fresh | B2: 71350/1 | C2: 45383 | D2: SALAAM TAKAFUL LTD | E2: KHI/HO/D/MO/PC COMP/C/86550/22/04/2024 | F2: 45404 | G2: 45768 | H2: Khalid Mehmood | I2: 3310031222097 | J2: TOYOTA YARIS | K2: AAN-359 | L2: 2A08640 | M2: NSP151R9503669 | N2: 71350/1 | O2: Central | P2: 0423 | Q2: 642882 | R2: 45406 | S2: 46512 | T2: 4100000 | W2: =T2 -> 4100000 | X2: 1.5 | Y2: =W2*X2% -> 61500 | Z2: already paid | AA2: paid | AB2: 1141069111 | AC2: 45432 | AD2: EARLY TERMINATED | AE2: 0 | AG2: KHI/HO/D/MO/PC COMP/C/86550/22/04/2024 | AI2: 82000 | AJ2: 20500 | AK2: 4100000 | AL2: 0 | AM2: FRE | AN2: TRACKER (TRASUR)
A3: Fresh | B3: 70289/1 | C3: 45383 | D3: SALAAM TAKAFUL LTD | E3: KHI/HO/D/MO/PC COMP/C/86550/7/04/2024 | F3: 45390 | G3: 45754 | H3: Ashar Azfar Hussain | I3: 4210140236367 | J3: TOYOTA COROLLA ALTIS 1.6 | K3: BXS-357 | L3: Q096872 | M3: R6074367 | N3: 70289/1 | O3: South | P3: 0144 | Q3: 639122 | R3: 45391 | S3: 46482 | T3: 5375000 | W3: =T3 -> 5375000 | X3: 1.5 | Y3: =W3*X3% -> 80625 | Z3: already paid | AA3: paid | AB3: 1141069111 | AC3: 45432 | AD3: STOPPED | AE3: 0 | AG3: KHI/HO/D/MO/PC COMP/C/86550/5/04/2024 | AI3: 80625 | AJ3: 0 | AK3: 5375000 | AL3: 0 | AM3: FRE | AN3: TRACKER (TRASUR)
A4: Fresh | B4: 74166/1 | C4: 45597 | D4: SALAAM TAKAFUL LTD | E4: KHI/HO/D/MO/PC COMP/C/101342/11/11/2024 | F4: 45611 | G4: 45975 | H4: MUHAMMAD ASGHAR | I4: 3520185477583 | J4: ALTO VXR (METALLIC) | K4: LE-19A-8013 | L4: 6R111597 | M4: H1011547 | N4: 74166/1 | O4: Central | P4: 0329 | Q4: 296002 | R4: 45597 | S4: 47427 | T4: 2150000 | W4: =T4 -> 2150000 | X4: 2 | Y4: =W4*X4% -> 43000 | Z4: already paid | AA4: paid | AB4: 1141071545 | AC4: 45622 | AD4: DISBURSED | AE4: 0 | AG4: KHI/HO/D/MO/PC COMP/C/101342/11/11/2024 | AI4: 43000 | AJ4: 0 | AK4: 2150000 | AL4: 0 | AM4: FRE | AN4: TRACKER (TRASUR)
A5: Fresh | B5: 75618/1 | C5: 45597 | D5: SALAAM TAKAFUL LTD | E5: KHI/HO/D/MO/PC COMP/C/101342/3/11/2024 | F5: 45601 | G5: 45965 | H5: SALMAN UL HASAN FAROOQUI | I5: 4220137933467 | J5: YARIS | K5: BTJ-559 | L5: 23589 | M5: 7014189 | N5: 75618/1 | O5: South | P5: 0150 | Q5: 660005 | R5: 45602 | S5: 46696 | T5: 3800000 | W5: =T5 -> 3800000 | X5: 1.5 | Y5: =W5*X5% -> 57000 | Z5: already paid | AA5: paid | AB5: 1141071545 | AC5: 45622 | AD5: DISBURSED | AE5: 0 | AG5: KHI/HO/D/MO/PC COMP/C/101342/3/11/2024 | AI5: 57000 | AJ5: 0 | AK5: 3800000 | AL5: 0 | AM5: FRE | AN5: TRACKER (TRASUR)
A6: Fresh | B6: Corporate | C6: 45231 | D6: SALAAM TAKAFUL LTD | E6: KHI/HO/D/MO/CV/P/78003/11/2023 | F6: 45236 | G6: 47062 | H6: Zulfiqar Ali | I6: 3310024895721 | J6: MESSY FERGUSEN MF-385 | K6: CAQ-8730 | L6: 618004 J | M6: 902141723 | N6: Corporate | O6: - | P6: - | Q6: - | R6: - | S6: - | T6: - | W6: - | X6: - | Y6: - | Z6: Corporate | AD6: Corporate | AE6: -
A7: Fresh | B7: Corporate | C7: 45261 | D7: SALAAM TAKAFUL LTD | E7: KHI/HO/D/MO/CV/P/80024/12/2023 | F7: 45274 | G7: 45639 | H7: Kashif Munawar | I7: 3540151169563 | J7: MESSY FERGUSEN MF-385 | K7: CAQ-2884 | L7: 619521-J | M7: 90277/22/23 | N7: Corporate | O7: - | P7: - | Q7: - | R7: - | S7: - | T7: - | W7: - | X7: - | Y7: - | Z7: Corporate | AD7: Corporate | AE7: -
A8: Fresh | B8: Corporate | C8: 45323 | D8: SALAAM TAKAFUL LTD | E8: KHI/HO/D/MO/CV/P/83823/02/2024 | F8: 45323 | G8: 47149 | H8: Naseer Ahmad | I8: 3130338365559 | J8: MILLAT TRACTOR MF 385 | K8: CAR-9912 | L8: 619338 J | M8: 902702423 | N8: Corporate | O8: - | P8: - | Q8: - | R8: - | S8: - | T8: - | W8: - | X8: - | Y8: - | Z8: Corporate | AD8: Corporate | AE8: -
A9: Fresh | B9: Corporate | C9: 45352 | D9: SALAAM TAKAFUL LTD | E9: KHI/HO/D/MO/CV/P/86492/04/2024 | F9: 45364 | G9: 47189 | H9: Shah Nawaz | I9: 1210120723961 | J9: MESSY FERGUSEN MF-385 | K9: K-3113 | L9: 619053J | M9: 90256/13/23 | N9: Corporate | O9: - | P9: - | Q9: - | R9: - | S9: - | T9: - | W9: - | X9: - | Y9: - | Z9: Corporate | AD9: Corporate | AE9: -
A10: Fresh | B10: Corporate | C10: 45352 | D10: SALAAM TAKAFUL LTD | E10: KHI/HO/D/MO/CV/P/86495/04/2024 | F10: 45372 | G10: 47197 | H10: Muhammad Ibrahim | I10: 1210122368311 | J10: BELARUS TRACTOR | K10: K3000 | L10: 208827 | M10: Y4R510Z02P1105082 | N10: Corporate | O10: - | P10: - | Q10: - | R10: - | S10: - | T10: - | W10: - | X10: - | Y10: - | Z10: Corporate | AD10: Corporate | AE10: -
A11: Fresh | B11: Corporate | C11: 45352 | D11: SALAAM TAKAFUL LTD | E11: KHI/HO/D/MO/CV/P/86585/04/2024 | F11: 45379 | G11: 47204 | H11: Muhammad Mumtaz | I11: 3660307336619 | J11: MESSY FERGUSEN MF-385 | K11: CAR-4516 | L11: 619918J | M11: 902950123 | N11: Corporate | O11: - | P11: - | Q11: - | R11: - | S11: - | T11: - | W11: - | X11: - | Y11: - | Z11: Corporate | AD11: Corporate | AE11: -
A12: Fresh | B12: Meezan Case | C12: 45383 | D12: SALAAM TAKAFUL LTD | E12: KHI/HO/D/MO/PC COMP/C/86550/9/04/2024 | F12: 45390 | G12: 45754 | H12: Meezan Bank Limited Main Branch Karachi | I12: 4230197595821 | J12: SUZUKI ALTO VXR | L12: 6R297940 | M12: NF1AET306H1197915 | N12: Meezan Case | O12: - | P12: - | Q12: - | R12: - | S12: - | T12: - | W12: - | X12: - | Y12: - | Z12: Meezan Case | AD12: Meezan Case | AE12: -
A13: Fresh | B13: 75531/1 | C13: 45566 | D13: SALAAM TAKAFUL LTD | E13: KHI/HO/D/MO/PC COMP/C/98823/23/10/2024 | F13: 45587 | G13: 45951 | H13: ISHTIAQ BHATTI | I13: 3520229568751 | J13: ALTO VXR (METALLIC) | K13: AYF-893 | L13: 215646 | M13: 1115638 | N13: 75531/1 | O13: North | P13: 0804 | Q13: 397683 | R13: 0 | S13: 47396 | T13: 2550000 | W13: =T13 -> 2550000 | X13: 2 | Y13: =W13*X13% -> 51000 | Z13: will pay later | AD13: APPROVED | AE13: 0
A14: Fresh | B14: 76818/1 | C14: 45597 | D14: SALAAM TAKAFUL LTD | E14: KHI/HO/D/MO/PC COMP/C/101342/44/11/2024 | F14: 45625 | G14: 45989 | H14: MUHAMMAD MUSTAFA ZAIDI | I14: 3610102621529 | J14: YARIS | K14: AWU-417 | L14: 42433 | M14: 7026645 | N14: 76818/1 | O14: Central | P14: 0431 | Q14: 552825 | R14: 0 | S14: 0 | T14: 3700000 | W14: =T14 -> 3700000 | X14: 1.5 | Y14: =W14*X14% -> 55500 | Z14: will pay later | AD14: APPLICATION | AE14: 0 | AG14: KHI/HO/D/MO/PC COMP/C/101342/44/11/2024 | AI14: 55500 | AJ14: 0 | AK14: 3700000 | AL14: 0 | AM14: FRE | AN14: TRACKER (TRASUR)
A15: Fresh | B15: wrong data | C15: 45139 | D15: SALAAM TAKAFUL LTD | E15: KHI/HO/D/MO/PC COMP/C/73558/29/08/2023 | F15: 45169 | G15: 45534 | H15: Faraz Khan | I15: 4210179692533 | J15: CHANGAN ALSVIN LUMEIRE | K15: BVY-587 | L15: 507324 | M15: 001530 | N15: wrong data | O15: - | P15: - | Q15: - | R15: - | S15: - | T15: - | W15: - | X15: - | Y15: - | Z15: wrong data | AD15: wrong data | AE15: -
A16: Fresh | B16: wrong data | C16: 45323 | D16: SALAAM TAKAFUL LTD | E16: KHI/HO/D/MO/PC COMP/C/83022/7/02/2024 | F16: 45331 | G16: 45696 | H16: Muhammad Tayyab | I16: 3520129679669 | J16: SUZUKI CULTUS VXR EURO-II | K16: LEC-17-8578 | L16: 637250 | M16: 544125 | N16: wrong data | O16: - | P16: - | Q16: - | R16: - | S16: - | T16: - | W16: - | X16: - | Y16: - | Z16: wrong data | AD16: wrong data | AE16: -
A17: Fresh | B17: 73786/1 | C17: 45597 | D17: SALAAM TAKAFUL LTD | E17: KHI/HO/D/MO/PC COMP/C/101342/1/11/2024 | F17: 45601 | G17: 45965 | H17: MUHAMMAD AYAZ | I17: 3210209745879 | J17: CULTUS VXL (NON-METALIC) | L17: 211066 | M17: 10111066 | N17: 73786/1 | O17: Central | P17: 0567 | Q17: 403371 | R17: 45611 | S17: 47427 | T17: 4546000 | W17: =T17 -> 4546000 | X17: 1.5 | Y17: =W17*X17% -> 68190 | AA17: paid | AB17: 1141071764 | AC17: 45637 | AD17: DISBURSED | AE17: 0 | AG17: KHI/HO/D/MO/PC COMP/C/101342/1/11/2024 | AI17: 68190 | AJ17: 0 | AK17: 4546000 | AL17: 0 | AM17: FRE | AN17: TRACKER (TRASUR)
