Workbook

Sheet Fresh
A1: Fresh / Renewal | B1: Proposal No. | C1: Billing Month | D1: Takaful Company | E1: PMD / Cert | F1: Takaful Start Date | G1: Takaful End Date | H1: Customer Name | I1: CNIC | J1: Vehicle Make | K1: Reg. No | L1: Engine No | M1: Chassis No | N1: Proposal No. | O1: Region | P1: Unit ID | Q1: BR # | R1: Financing Date | S1: Maturity Date | T1: Asset Value | U1: Dep. % | V1: Dep. Amount | W1: Sum Cover Amount | X1: Takaful Rate | Y1: Premium Amount | Z1: For Takaful Company Rectifications | AA1: For COD Status | AB1: PO No. | AC1: PO Dates | AD1: Proposal Status | AE1: Default Case (Overdue Days) | AF1: Policy # | AG1: End. # | AH1: Tms Prem | AI1: Difference | AJ1: Tagging | AK1: Tracker
A2: Fresh | B2: 73416/1 | C2: 45536 | D2: SALAAM TAKAFUL LTD | E2: KHI/HO/D/MO/PC COMP/C/96843/1/09/2024 | F2: 45541 | G2: 45905 | H2: Ella Hussain | I2: 4230174899114 | J2: SUZUKI SWIFT DLX EURO II | K2: BUD-129 | L2: 13050748 | M2: 10050701 | N2: 73416/1 | O2: South | P2: 0144 | Q2: 367615 | R2: 45546 | S2: 46636 | T2: 3100000 | W2: 3100000 | X2: 2 | Y2: 62000 | AA2: paid | AB2: 1141070982 | AC2: 45586 | AD2: DISBURSED | AE2: 0 | AF2: KHI/HO/D/MO/PC COMP/C/96843/1/09/2024 | AH2: 62000 | AI2: =Y2-AH2 -> 0 | AJ2: =VLOOKUP(AF2,[1]Sheet3!$B$2:$D$2361,3,0) -> FRE | AK2: TRACKER (TRASUR)
A3: Fresh | B3: 74833/1 | C3: 45536 | D3: SALAAM TAKAFUL LTD | E3: KHI/HO/D/MO/PC COMP/C/96843/10/09/2024 | F3: 45551 | G3: 45915 | H3: Muhammad Asif | I3: 3630201053933 | J3: KIA PICANTO 1.0L A/T | K3: AGC-458 | L3: 131175 | M3: 708259 | N3: 74833/1 | O3: Central | P3: 0431 | Q3: 651389 | R3: 45558 | S3: 47396 | T3: 2900000 | W3: 2900000 | X3: 2 | Y3: 58000 | AA3: paid | AB3: 1141070982 | AC3: 45586 | AD3: DISBURSED | AE3: 0 | AF3: KHI/HO/D/MO/PC COMP/C/96843/10/09/2024 | AH3: 58000 | AI3: =Y3-AH3 -> 0 | AJ3: =VLOOKUP(AF3,[1]Sheet3!$B$2:$D$2361,3,0) -> FRE | AK3: TRACKER (TRASUR)
A4: Fresh | B4: 74189/1 | C4: 45536 | D4: SALAAM TAKAFUL LTD | E4: KHI/HO/D/MO/PC COMP/C/96843/11/09/2024 | F4: 45553 | G4: 45917 | H4: Bilal Khan | I4: 1560703435961 | J4: SUZUKI WAGON-R | K4: AXK-221 | L4: PK10B230615 | M4: A1J310PK10130642 | N4: 74189/1 | O4: Central | P4: 0423 | Q4: 605795 | R4: 45558 | S4: 47396 | T4: 2700000 | W4: 2700000 | X4: 2 | Y4: 54000 | AA4: paid | AB4: 1141070982 | AC4: 45586 | AD4: DISBURSED | AE4: 0 | AF4: KHI/HO/D/MO/PC COMP/C/96843/11/09/2024 | AH4: 54000 | AI4: =Y4-AH4 -> 0 | AJ4: =VLOOKUP(AF4,[1]Sheet3!$B$2:$D$2361,3,0) -> FRE | AK4: TRACKER (TRASUR)
A5: Fresh | B5: 74813/1 | C5: 45536 | D5: SALAAM TAKAFUL LTD | E5: KHI/HO/D/MO/PC COMP/C/96843/12/09/2024 | F5: 45554 | G5: 45918 | H5: Shahzad Ahmad | I5: 3520131115579 | J5: HONDA CITY ASPIRE A/T | K5: ABG-644 | L5: Z17449363 | M5: R191016 | N5: 74813/1 | O5: Central | P5: 0329 | Q5: 461007 | R5: 45555 | S5: 46665 | T5: 3000000 | W5: 3000000 | X5: 2 | Y5: 60000 | AA5: paid | AB5: 1141070982 | AC5: 45586 | AD5: DISBURSED | AE5: 0 | AF5: KHI/HO/D/MO/PC COMP/C/96843/12/09/2024 | AH5: 60000 | AI5: =Y5-AH5 -> 0 | AJ5: =VLOOKUP(AF5,[1]Sheet3!$B$2:$D$2361,3,0) -> FRE | AK5: TRACKER (TRASUR)
A6: Fresh | B6: 74740/1 | C6: 45536 | D6: SALAAM TAKAFUL LTD | E6: KHI/HO/D/MO/PC COMP/C/96843/13/09/2024 | F6: 45554 | G6: 45918 | H6: Muhammad Bilal Shafiq | I6: 3520298870751 | J6: HONDA CITY | K6: ABC-608 | L6: 9800054 | M6: 265720 | N6: 74740/1 | O6: Central | P6: 0329 | Q6: 656348 | R6: 45555 | S6: 46665 | T6: 4000000 | W6: 4000000 | X6: 1.5 | Y6: 60000 | AA6: paid | AB6: 1141070982 | AC6: 45586 | AD6: DISBURSED | AE6: 0 | AF6: KHI/HO/D/MO/PC COMP/C/96843/13/09/2024 | AH6: 60000 | AI6: =Y6-AH6 -> 0 | AJ6: =VLOOKUP(AF6,[1]Sheet3!$B$2:$D$2361,3,0) -> FRE | AK6: TRACKER (TRASUR)
A7: Fresh | B7: 74170/1 | C7: 45536 | D7: SALAAM TAKAFUL LTD | E7: KHI/HO/D/MO/PC COMP/C/96843/14/09/2024 | F7: 45554 | G7: 45918 | H7: Muhammad Tahir Shifa | I7: 3130397947331 | J7: SUZUKI CULTUS VXL | K7: LEC-19-6343 | L7: 141503 | M7: 10041493 | N7: 74170/1 | O7: Central | P7: 0461 | Q7: 650204 | R7: 45558 | S7: 47396 | T7: 3000000 | W7: 3000000 | X7: 2 | Y7: 60000 | AA7: paid | AB7: 1141070982 | AC7: 45586 | AD7: DISBURSED | AE7: 0 | AF7: KHI/HO/D/MO/PC COMP/C/96843/14/09/2024 | AH7: 60000 | AI7: =Y7-AH7 -> 0 | AJ7: =VLOOKUP(AF7,[1]Sheet3!$B$2:$D$2361,3,0) -> FRE | AK7: TRACKER (TRASUR)
A8: Fresh | B8: 74778/1 | C8: 45536 | D8: SALAAM TAKAFUL LTD | E8: KHI/HO/D/MO/PC COMP/C/96843/15/09/2024 | F8: 45554 | G8: 45918 | H8: Sadaf Mateen Butt | I8: 3520256198050 | J8: HONDA CITY | K8: AEQ-468 | L8: 17547218 | M8: 272355 | N8: 74778/1 | O8: Central | P8: 0329 | Q8: 656353 | R8: 45555 | S8: 46665 | T8: 3900000 | W8: 3900000 | X8: 1.5 | Y8: 58500 | AA8: paid | AB8: 1141070982 | AC8: 45586 | AD8: DISBURSED | AE8: 0 | AF8: KHI/HO/D/MO/PC COMP/C/96843/15/09/2024 | AH8: 58500 | AI8: =Y8-AH8 -> 0 | AJ8: =VLOOKUP(AF8,[1]Sheet3!$B$2:$D$2361,3,0) -> FRE | AK8: TRACKER (TRASUR)
A9: Fresh | B9: 74041/1 | C9: 45536 | D9: SALAAM TAKAFUL LTD | E9: KHI/HO/D/MO/PC COMP/C/96843/16/09/2024 | F9: 45554 | G9: 45918 | H9: Zeeshan Qaiser | I9: 3520230821215 | J9: TOYOTA YARIS ATIV X CVT | K9: AME-515 | L9: 2A57112 | M9: 9520943 | N9: 74041/1 | O9: Central | P9: 0329 | Q9: 653437 | R9: 45559 | S9: 46665 | T9: 4700000 | W9: 4700000 | X9: 1.5 | Y9: 70500 | AA9: paid | AB9: 1141070982 | AC9: 45586 | AD9: DISBURSED | AE9: 0 | AF9: KHI/HO/D/MO/PC COMP/C/96843/16/09/2024 | AH9: 70500 | AI9: =Y9-AH9 -> 0 | AJ9: =VLOOKUP(AF9,[1]Sheet3!$B$2:$D$2361,3,0) -> FRE | AK9: TRACKER (TRASUR)
A10: Fresh | B10: 72923/1 | C10: 45536 | D10: SALAAM TAKAFUL LTD | E10: KHI/HO/D/MO/PC COMP/C/96843/17/09/2024 | F10: 45555 | G10: 45919 | H10: Muhammad Shakeel | I10: 3520224697617 | J10: TOYOTA Yaris ATIV 1.3 (CV | L10: 2A69353 | M10: 7046692 | N10: 72923/1 | O10: Central | P10: 0329 | Q10: 649688 | R10: 45558 | S10: 46665 | T10: 4760000 | W10: 4760000 | X10: 1.5 | Y10: 71400 | AA10: paid | AB10: 1141070982 | AC10: 45586 | AD10: DISBURSED | AE10: 0 | AF10: KHI/HO/D/MO/PC COMP/C/96843/17/09/2024 | AH10: 71400 | AI10: =Y10-AH10 -> 0 | AJ10: =VLOOKUP(AF10,[1]Sheet3!$B$2:$D$2361,3,0) -> FRE | AK10: TRACKER (TRASUR)
A11: Fresh | B11: 73684/1 | C11: 45536 | D11: SALAAM TAKAFUL LTD | E11: KHI/HO/D/MO/PC COMP/C/96843/18/09/2024 | F11: 45555 | G11: 45919 | H11: Muhammad Haider Ali | I11: 3310273105991 | J11: HAVAL Haval Jolion HEV 1. | L11: 244H0005104 | M11: NF9EEUA59R2009219 | N11: 73684/1 | O11: Central | P11: 0423 | Q11: 652193 | R11: 45558 | S11: 46300 | T11: 9428950 | W11: 9428950 | X11: 1.5 | Y11: 141434.25 | AA11: paid | AB11: 1141070982 | AC11: 45586 | AD11: DISBURSED | AE11: 0 | AF11: KHI/HO/D/MO/PC COMP/C/96843/18/09/2024 | AH11: 141434 | AI11: =Y11-AH11 -> 0.25 | AJ11: =VLOOKUP(AF11,[1]Sheet3!$B$2:$D$2361,3,0) -> FRE | AK11: TRACKER (TRASUR)
A12: Fresh | B12: 74367/1 | C12: 45536 | D12: SALAAM TAKAFUL LTD | E12: KHI/HO/D/MO/PC COMP/C/96843/19/09/2024 | F12: 45558 | G12: 45922 | H12: Kamran Latif Rao | I12: 6110131920715 | J12: TOYOTA YARIS CVT | K12: BEJ-717 | L12: 2A69410 | M12: 9522730 | N12: 74367/1 | O12: North | P12: 0804 | Q12: 655104 | R12: 45565 | S12: 45936 | T12: 6404000 | W12: 6404000 | X12: 1.5 | Y12: 96060 | AA12: paid | AB12: 1141070982 | AC12: 45586 | AD12: DISBURSED | AE12: 0 | AF12: KHI/HO/D/MO/PC COMP/C/96843/19/09/2024 | AH12: 96060 | AI12: =Y12-AH12 -> 0 | AJ12: =VLOOKUP(AF12,[1]Sheet3!$B$2:$D$2361,3,0) -> FRE | AK12: TRACKER (TRASUR)
A13: Fresh | B13: 74289/1 | C13: 45536 | D13: SALAAM TAKAFUL LTD | E13: KHI/HO/D/MO/PC COMP/C/96843/2/09/2024 | F13: 45541 | G13: 45905 | H13: Hafiz Muhammad Abbas Ali | I13: 3310236731289 | J13: SUZUKI CULTUS | K13: LE-18A-6675 | L13: PK10K125857 | M13: NF1AVK31H10025842 | N13: 74289/1 | O13: Central | P13: 0423 | Q13: 654329 | R13: 45546 | S13: 47366 | T13: 2475000 | W13: 2475000 | X13: 2 | Y13: 49500 | AA13: paid | AB13: 1141070982 | AC13: 45586 | AD13: DISBURSED | AE13: 9 | AF13: KHI/HO/D/MO/PC COMP/C/96843/2/09/2024 | AH13: 49500 | AI13: =Y13-AH13 -> 0 | AJ13: =VLOOKUP(AF13,[1]Sheet3!$B$2:$D$2361,3,0) -> FRE | AK13: TRACKER (TRASUR)
A14: Fresh | B14: 74977/1 | C14: 45536 | D14: SALAAM TAKAFUL LTD | E14: KHI/HO/D/MO/PC COMP/C/96843/20/09/2024 | F14: 45558 | G14: 45922 | H14: Muhammad Akram | I14: 3520112664041 | J14: KIA KIA SPORTAGE | K14: LEB-20-37 | L14: H309588 | M14: P502294 | N14: 74977/1 | O14: Central | P14: 0329 | Q14: 445572 | R14: 45561 | S14: 46665 | T14: 5700000 | W14: 5700000 | X14: 1.5 | Y14: 85500 | AA14: paid | AB14: 1141070982 | AC14: 45586 | AD14: DISBURSED | AE14: 0 | AF14: KHI/HO/D/MO/PC COMP/C/96843/20/09/2024 | AH14: 85500 | AI14: =Y14-AH14 -> 0 | AJ14: =VLOOKUP(AF14,[1]Sheet3!$B$2:$D$2361,3,0) -> FRE | AK14: TRACKER (TRASUR)
A15: Fresh | B15: 74782/1 | C15: 45536 | D15: SALAAM TAKAFUL LTD | E15: KHI/HO/D/MO/PC COMP/C/96843/21/09/2024 | F15: 45559 | G15: 45923 | H15: Mohammed Imran Khawaja | I15: 3520224976297 | J15: HONDA CIVIC | K15: LEB-16A-21 | L15: 71402303 | M15: GR007223 | N15: 74782/1 | O15: Central | P15: 0329 | Q15: 655753 | R15: 45560 | S15: 46665 | T15: 4500000 | W15: 4500000 | X15: 1.5 | Y15: 67500 | AA15: paid | AB15: 1141070982 | AC15: 45586 | AD15: DISBURSED | AE15: 0 | AF15: KHI/HO/D/MO/PC COMP/C/96843/21/09/2024 | AH15: 67500 | AI15: =Y15-AH15 -> 0 | AJ15: =VLOOKUP(AF15,[1]Sheet3!$B$2:$D$2361,3,0) -> FRE | AK15: TRACKER (TRASUR)
A16: Fresh | B16: 73224/1 | C16: 45536 | D16: SALAAM TAKAFUL LTD | E16: KHI/HO/D/MO/PC COMP/C/96843/22/09/2024 | F16: 45559 | G16: 45923 | H16: Asher Javed | I16: 3520227891005 | J16: HONDA CITY 1.2 LS CVT | L16: 51026914 | M16: R043495 | N16: 73224/1 | O16: Central | P16: 0329 | Q16: 553816 | R16: 45560 | S16: 46300 | T16: 4719000 | W16: 4719000 | X16: 1.5 | Y16: 70785 | AA16: paid | AB16: 1141070982 | AC16: 45586 | AD16: DISBURSED | AE16: 0 | AF16: KHI/HO/D/MO/PC COMP/C/96843/22/09/2024 | AH16: 70785 | AI16: =Y16-AH16 -> 0 | AJ16: =VLOOKUP(AF16,[1]Sheet3!$B$2:$D$2361,3,0) -> FRE | AK16: TRACKER (TRASUR)
A17: Fresh | B17: 75356/1 | C17: 45536 | D17: SALAAM TAKAFUL LTD | E17: KHI/HO/D/MO/PC COMP/C/96843/23/09/2024 | F17: 45559 | G17: 45923 | H17: Faisal Saleem | I17: 4210118063795 | J17: TOYOTA AXIO | K17: BTW-310 | L17: 198616 | M17: 7144665 | N17: 75356/1 | O17: South | P17: 0150 | Q17: 274530 | R17: 45568 | S17: 46300 | T17: 4700000 | W17: 4700000 | X17: 1.5 | Y17: 70500 | AA17: paid | AB17: 1141070982 | AC17: 45586 | AD17: DISBURSED | AE17: 0 | AF17: KHI/HO/D/MO/PC COMP/C/96843/23/09/2024 | AH17: 70500 | AI17: =Y17-AH17 -> 0 | AJ17: =VLOOKUP(AF17,[1]Sheet3!$B$2:$D$2361,3,0) -> FRE | AK17: Tracker missing
A18: Fresh | B18: 75027/1 | C18: 45536 | D18: SALAAM TAKAFUL LTD | E18: KHI/HO/D/MO/PC COMP/C/96843/24/09/2024 | F18: 45559 | G18: 45923 | H18: Mamoon Mustafa | I18: 3520113938293 | J18: HONDA CIVIC I-VTEC | K18: LEA-19-6902 | L18: 150003 | M18: 610001 | N18: 75027/1 | O18: Central | P18: 0329 | Q18: 657391 | R18: 45560 | S18: 46665 | T18: 4610000 | W18: 4610000 | X18: 1.5 | Y18: 69150 | AA18: paid | AB18: 1141070982 | AC18: 45586 | AD18: DISBURSED | AE18: 0 | AF18: KHI/HO/D/MO/PC COMP/C/96843/24/09/2024 | AH18: 69150 | AI18: =Y18-AH18 -> 0 | AJ18: =VLOOKUP(AF18,[1]Sheet3!$B$2:$D$2361,3,0) -> FRE | AK18: TRACKER (TRASUR)
A19: Fresh | B19: 74998/1 | C19: 45536 | D19: SALAAM TAKAFUL LTD | E19: KHI/HO/D/MO/PC COMP/C/96843/25/09/2024 | F19: 45560 | G19: 45924 | H19: Uzair Amjad | I19: 3520251341519 | J19: KIA PICANTO 1.0L A/T | K19: ASG-822 | L19: P072447 | M19: KP703700 | N19: 74998/1 | O19: Central | P19: 0329 | Q19: 657283 | R19: 45561 | S19: 47396 | T19: 2930000 | W19: 2930000 | X19: 2 | Y19: 58600 | AA19: paid | AB19: 1141070982 | AC19: 45586 | AD19: DISBURSED | AE19: 0 | AF19: KHI/HO/D/MO/PC COMP/C/96843/25/09/2024 | AH19: 58600 | AI19: =Y19-AH19 -> 0 | AJ19: =VLOOKUP(AF19,[1]Sheet3!$B$2:$D$2361,3,0) -> FRE | AK19: TRACKER (TRASUR)
A20: Fresh | B20: 74881/1 | C20: 45536 | D20: SALAAM TAKAFUL LTD | E20: KHI/HO/D/MO/PC COMP/C/96843/26/09/2024 | F20: 45561 | G20: 45925 | H20: Zeeshan Ali | I20: 3310279085003 | J20: TOYOTA YARIS ATIV CVT | K20: LEB-20-4423 | L20: 2A03924 | M20: 7001990 | N20: 74881/1 | O20: Central | P20: 0329 | Q20: 656731 | R20: 45565 | S20: 46665 | T20: 3850000 | W20: 3850000 | X20: 1.5 | Y20: 57750 | AA20: paid | AB20: 1141070982 | AC20: 45586 | AD20: DISBURSED | AE20: 0 | AF20: KHI/HO/D/MO/PC COMP/C/96843/26/09/2024 | AH20: 57750 | AI20: =Y20-AH20 -> 0 | AJ20: =VLOOKUP(AF20,[1]Sheet3!$B$2:$D$2361,3,0) -> FRE | AK20: TRACKER (TRASUR)
A21: Fresh | B21: 74907/1 | C21: 45536 | D21: SALAAM TAKAFUL LTD | E21: KHI/HO/D/MO/PC COMP/C/96843/27/09/2024 | F21: 45561 | G21: 45925 | H21: Hamid Parvaiz | I21: 3520235703927 | J21: SUZUKI ALTO VXR | L21: 319662 | M21: 1219670 | N21: 74907/1 | O21: Central | P21: 0329 | Q21: 656957 | R21: 45565 | S21: 46665 | T21: 2707000 | W21: 2707000 | X21: 2 | Y21: 54140 | AA21: paid | AB21: 1141070982 | AC21: 45586 | AD21: DISBURSED | AE21: 0 | AF21: KHI/HO/D/MO/PC COMP/C/96843/27/09/2024 | AH21: 54140 | AI21: =Y21-AH21 -> 0 | AJ21: =VLOOKUP(AF21,[1]Sheet3!$B$2:$D$2361,3,0) -> FRE | AK21: TRACKER (TRASUR)
A22: Fresh | B22: 74889/1 | C22: 45536 | D22: SALAAM TAKAFUL LTD | E22: KHI/HO/D/MO/PC COMP/C/96843/28/09/2024 | F22: 45562 | G22: 45926 | H22: Muhammad Naeem Amjad | I22: 3120273822093 | J22: SUZUKI ALTO VXR | L22: 6R320270 | M22: 1220265 | N22: 74889/1 | O22: Central | P22: 0471 | Q22: 656520 | R22: 45562 | S22: 46665 | T22: 2707000 | W22: 2707000 | X22: 2 | Y22: 54140 | AA22: paid | AB22: 1141070982 | AC22: 45586 | AD22: DISBURSED | AE22: 0 | AF22: KHI/HO/D/MO/PC COMP/C/96843/28/09/2024 | AH22: 54140 | AI22: =Y22-AH22 -> 0 | AJ22: =VLOOKUP(AF22,[1]Sheet3!$B$2:$D$2361,3,0) -> FRE | AK22: TRACKER (TRASUR)
A23: Fresh | B23: 75328/1 | C23: 45536 | D23: SALAAM TAKAFUL LTD | E23: KHI/HO/D/MO/PC COMP/C/96843/29/09/2024 | F23: 45562 | G23: 45926 | H23: Abdul Mateen Shah | I23: 3740505478375 | J23: HONDA BRV - S | K23: AHY-675 | L23: 509473 | M23: 009475 | N23: 75328/1 | O23: North | P23: 0804 | Q23: 657061 | R23: 45565 | S23: 47031 | T23: 4000000 | W23: 4000000 | X23: 1.5 | Y23: 60000 | AA23: paid | AB23: 1141070982 | AC23: 45586 | AD23: DISBURSED | AE23: 0 | AF23: KHI/HO/D/MO/PC COMP/C/96843/29/09/2024 | AH23: 60000 | AI23: =Y23-AH23 -> 0 | AJ23: =VLOOKUP(AF23,[1]Sheet3!$B$2:$D$2361,3,0) -> FRE | AK23: TRACKER (TRASUR)
A24: Fresh | B24: 74235/1 | C24: 45536 | D24: SALAAM TAKAFUL LTD | E24: KHI/HO/D/MO/PC COMP/C/96843/3/09/2024 | F24: 45545 | G24: 45909 | H24: Mukhtiar Ahmad | I24: 3210232085597 | J24: SUZUKI WAGON R VXL | L24: 248289 | M24: 10148284 | N24: 74235/1 | O24: Central | P24: 0567 | Q24: 653278 | R24: 45562 | S24: 46665 | T24: 3412000 | W24: 3412000 | X24: 2 | Y24: 68240 | AA24: paid | AB24: 1141070982 | AC24: 45586 | AD24: DISBURSED | AE24: 0 | AF24: KHI/HO/D/MO/PC COMP/C/96843/3/09/2024 | AH24: 68240 | AI24: =Y24-AH24 -> 0 | AJ24: =VLOOKUP(AF24,[1]Sheet3!$B$2:$D$2361,3,0) -> FRE | AK24: TRACKER (TRASUR)
A25: Fresh | B25: 75068/1 | C25: 45536 | D25: SALAAM TAKAFUL LTD | E25: KHI/HO/D/MO/PC COMP/C/96843/30/09/2024 | F25: 45562 | G25: 45926 | H25: Iftikhar Ahmad | I25: 3520014737597 | J25: SUZUKI ALTO AGS A/T | K25: AAE-381 | L25: 122274 | M25: 1022259 | N25: 75068/1 | O25: Central | P25: 0329 | Q25: 657517 | R25: 45565 | S25: 47396 | T25: 2400000 | W25: 2400000 | X25: 2 | Y25: 48000 | AA25: paid | AB25: 1141070982 | AC25: 45586 | AD25: DISBURSED | AE25: 0 | AF25: KHI/HO/D/MO/PC COMP/C/96843/30/09/2024 | AH25: 48000 | AI25: =Y25-AH25 -> 0 | AJ25: =VLOOKUP(AF25,[1]Sheet3!$B$2:$D$2361,3,0) -> FRE | AK25: TRACKER (TRASUR)
A26: Fresh | B26: 75317/1 | C26: 45536 | D26: SALAAM TAKAFUL LTD | E26: KHI/HO/D/MO/PC COMP/C/96843/31/09/2024 | F26: 45562 | G26: 45926 | H26: Parveen Kusar | I26: 3520223629410 | J26: TOYOTA COROLLA GLI | K26: LEF-19-2220 | L26: Z562568 | M26: R-4187661 | N26: 75317/1 | O26: Central | P26: 0329 | Q26: 657616 | R26: 45565 | S26: 47031 | T26: 3600000 | W26: 3600000 | X26: 1.5 | Y26: 54000 | AA26: paid | AB26: 1141070982 | AC26: 45586 | AD26: DISBURSED | AE26: 0 | AF26: KHI/HO/D/MO/PC COMP/C/96843/31/09/2024 | AH26: 54000 | AI26: =Y26-AH26 -> 0 | AJ26: =VLOOKUP(AF26,[1]Sheet3!$B$2:$D$2361,3,0) -> FRE | AK26: TRACKER (TRASUR)
A27: Fresh | B27: 75318/1 | C27: 45536 | D27: SALAAM TAKAFUL LTD | E27: KHI/HO/D/MO/PC COMP/C/96843/32/09/2024 | F27: 45562 | G27: 45926 | H27: Salman Niaz | I27: 3520209281025 | J27: SUZUKI CULTUS | K27: LE-12-7519 | L27: PKF558624 | M27: PK465485 | N27: 75318/1 | O27: Central | P27: 0329 | Q27: 655536 | R27: 45566 | S27: 47031 | T27: 1225000 | W27: 1225000 | X27: 2 | Y27: 24500 | AA27: paid | AB27: 1141070982 | AC27: 45586 | AD27: DISBURSED | AE27: 0 | AF27: KHI/HO/D/MO/PC COMP/C/96843/32/09/2024 | AH27: 24500 | AI27: =Y27-AH27 -> 0 | AJ27: =VLOOKUP(AF27,[1]Sheet3!$B$2:$D$2361,3,0) -> FRE | AK27: TRACKER (TRASUR)
A28: Fresh | B28: 74922/1 | C28: 45536 | D28: SALAAM TAKAFUL LTD | E28: KHI/HO/D/MO/PC COMP/C/96843/33/09/2024 | F28: 45562 | G28: 45926 | H28: Ahmed Bin Ali Qundoos | I28: 4220182491477 | J28: SUZUKI ALTO VXR E-2 | K28: BTF-758 | L28: 159092 | M28: 1059059 | N28: 74922/1 | O28: South | P28: 0144 | Q28: 656977 | R28: 45566 | S28: 46665 | T28: 2280000 | W28: 2280000 | X28: 2 | Y28: 45600 | AA28: paid | AB28: 1141070982 | AC28: 45586 | AD28: DISBURSED | AE28: 0 | AF28: KHI/HO/D/MO/PC COMP/C/96843/33/09/2024 | AH28: 45600 | AI28: =Y28-AH28 -> 0 | AJ28: =VLOOKUP(AF28,[1]Sheet3!$B$2:$D$2361,3,0) -> FRE | AK28: TRACKER (TRASUR)
A29: Fresh | B29: 75323/2 | C29: 45536 | D29: SALAAM TAKAFUL LTD | E29: KHI/HO/D/MO/PC COMP/C/96843/34/09/2024 | F29: 45565 | G29: 45929 | H29: Saif Ullah Khan | I29: 3230361108491 | J29: TOYOTA RAIZE | K29: AXV-851 | M29: 55230 | N29: 75323/2 | O29: Central | P29: 0431 | Q29: 657390 | R29: 45566 | S29: 47031 | T29: 5200000 | W29: 5200000 | X29: 1.5 | Y29: 78000 | AA29: paid | AB29: 1141070982 | AC29: 45586 | AD29: DISBURSED | AE29: 0 | AF29: KHI/HO/D/MO/PC COMP/C/96843/34/09/2024 | AH29: 78000 | AI29: =Y29-AH29 -> 0 | AJ29: =VLOOKUP(AF29,[1]Sheet3!$B$2:$D$2361,3,0) -> FRE | AK29: TRACKER (TRASUR)
A30: Fresh | B30: 74676/1 | C30: 45536 | D30: SALAAM TAKAFUL LTD | E30: KHI/HO/D/MO/PC COMP/C/96843/35/09/2024 | F30: 45565 | G30: 45929 | H30: Ruslaan Zia | I30: 3410123970261 | J30: SUZUKI ALTO VXL AGS | L30: 6R320395 | M30: 1220418 | N30: 74676/1 | O30: Central | P30: 0329 | Q30: 655891 | R30: 45565 | S30: 45936 | T30: 3045000 | W30: 3045000 | X30: 2 | Y30: 60900 | AA30: paid | AB30: 1141070982 | AC30: 45586 | AD30: DISBURSED | AE30: 0 | AF30: KHI/HO/D/MO/PC COMP/C/96843/35/09/2024 | AH30: 60900 | AI30: =Y30-AH30 -> 0 | AJ30: =VLOOKUP(AF30,[1]Sheet3!$B$2:$D$2361,3,0) -> FRE | AK30: TRACKER (TRASUR)
A31: Fresh | B31: 75329/2 | C31: 45536 | D31: SALAAM TAKAFUL LTD | E31: KHI/HO/D/MO/PC COMP/C/96843/36/09/2024 | F31: 45565 | G31: 45929 | H31: Syeda Umme Farwa | I31: 6110119260276 | J31: HONDA BRV MTI I-VTEC 1.5L | K31: ALI-147 | L31: 14810324 | M31: 026945 | N31: 75329/2 | O31: North | P31: 0804 | Q31: 585941 | R31: 45565 | S31: 47031 | T31: 6000000 | W31: 6000000 | X31: 1.5 | Y31: 90000 | AA31: paid | AB31: 1141070982 | AC31: 45586 | AD31: DISBURSED | AE31: 0 | AF31: KHI/HO/D/MO/PC COMP/C/96843/36/09/2024 | AH31: 90000 | AI31: =Y31-AH31 -> 0 | AJ31: =VLOOKUP(AF31,[1]Sheet3!$B$2:$D$2361,3,0) -> FRE | AK31: TRACKER (TRASUR)
A32: Fresh | B32: 74475/1 | C32: 45536 | D32: SALAAM TAKAFUL LTD | E32: KHI/HO/D/MO/PC COMP/C/96843/37/09/2024 | F32: 45565 | G32: 45929 | H32: Syed Zia Ud Din Muhammad Faisal | I32: 3650191640463 | J32: CHANGAN OSHAN FUTURE SENS | L32: 201899 | M32: 1000446 | N32: 74475/1 | O32: Central | P32: 0329 | Q32: 447807 | R32: 45565 | S32: 46665 | T32: 8099000 | W32: 8099000 | X32: 1.5 | Y32: 121485 | AA32: paid | AB32: 1141070982 | AC32: 45586 | AD32: DISBURSED | AE32: 0 | AF32: KHI/HO/D/MO/PC COMP/C/96843/37/09/2024 | AH32: 121485 | AI32: =Y32-AH32 -> 0 | AJ32: =VLOOKUP(AF32,[1]Sheet3!$B$2:$D$2361,3,0) -> FRE | AK32: TRACKER (TRASUR)
A33: Fresh | B33: 74287/1 | C33: 45536 | D33: SALAAM TAKAFUL LTD | E33: KHI/HO/D/MO/PC COMP/C/96843/38/09/2024 | F33: 45565 | G33: 45929 | H33: Shahid Hussain | I33: 3630215803869 | J33: SUZUKI ALTO VXL AGS | K33: ACU-859 | L33: 161733 | M33: 1061750 | N33: 74287/1 | O33: Central | P33: 0431 | Q33: 654318 | R33: 45566 | S33: 47396 | T33: 2500000 | W33: 2500000 | X33: 2 | Y33: 50000 | AA33: paid | AB33: 1141070982 | AC33: 45586 | AD33: DISBURSED | AE33: 0 | AF33: KHI/HO/D/MO/PC COMP/C/96843/38/09/2024 | AH33: 50000 | AI33: =Y33-AH33 -> 0 | AJ33: =VLOOKUP(AF33,[1]Sheet3!$B$2:$D$2361,3,0) -> FRE | AK33: TRACKER (TRASUR)
A34: Fresh | B34: 74946/1 | C34: 45536 | D34: SALAAM TAKAFUL LTD | E34: KHI/HO/D/MO/PC COMP/C/96843/39/09/2024 | F34: 45565 | G34: 45929 | H34: Muhammad Adeel | I34: 4250152564159 | J34: SUZUKI ALTO | K34: BWW-451 | L34: R-130773 | M34: 1030784 | N34: 74946/1 | O34: South | P34: 0144 | Q34: 657138 | R34: 45567 | S34: 47396 | T34: 2550000 | W34: 2550000 | X34: 2 | Y34: 51000 | AA34: paid | AB34: 1141070982 | AC34: 45586 | AD34: DISBURSED | AE34: 0 | AF34: KHI/HO/D/MO/PC COMP/C/96843/39/09/2024 | AH34: 51000 | AI34: =Y34-AH34 -> 0 | AJ34: =VLOOKUP(AF34,[1]Sheet3!$B$2:$D$2361,3,0) -> FRE | AK34: TRACKER (TRASUR)
A35: Fresh | B35: 73599/1 | C35: 45536 | D35: SALAAM TAKAFUL LTD | E35: KHI/HO/D/MO/PC COMP/C/96843/4/09/2024 | F35: 45545 | G35: 45909 | H35: Muhammad Zubair Ameen | I35: 3520265554231 | J35: SUZUKI CULTUS VXL AGS | K35: ASZ-794 | L35: 168843 | M35: 10068855 | N35: 73599/1 | O35: Central | P35: 0329 | Q35: 651982 | R35: 45546 | S35: 47366 | T35: 3350000 | W35: 3350000 | X35: 2 | Y35: 67000 | AA35: paid | AB35: 1141070982 | AC35: 45586 | AD35: DISBURSED | AE35: 9 | AF35: KHI/HO/D/MO/PC COMP/C/96843/4/09/2024 | AH35: 67000 | AI35: =Y35-AH35 -> 0 | AJ35: =VLOOKUP(AF35,[1]Sheet3!$B$2:$D$2361,3,0) -> FRE | AK35: TRACKER (TRASUR)
A36: Fresh | B36: 74862/1 | C36: 45536 | D36: SALAAM TAKAFUL LTD | E36: KHI/HO/D/MO/PC COMP/C/96843/40/09/2024 | F36: 45565 | G36: 45929 | H36: Rahima Jillani | I36: 4210140600168 | J36: SUZUKI ALTO | K36: BVM-911 | L36: 6R202720 | M36: 1102666 | N36: 74862/1 | O36: South | P36: 0144 | Q36: 656704 | R36: 45566 | S36: 46300 | T36: 2150000 | W36: 2150000 | X36: 2 | Y36: 43000 | AA36: paid | AB36: 1141070982 | AC36: 45586 | AD36: DISBURSED | AE36: 0 | AF36: KHI/HO/D/MO/PC COMP/C/96843/40/09/2024 | AH36: 43000 | AI36: =Y36-AH36 -> 0 | AJ36: =VLOOKUP(AF36,[1]Sheet3!$B$2:$D$2361,3,0) -> FRE | AK36: TRACKER (TRASUR)
A37: Fresh | B37: 74808/1 | C37: 45536 | D37: SALAAM TAKAFUL LTD | E37: KHI/HO/D/MO/PC COMP/C/96843/41/09/2024 | F37: 45565 | G37: 45929 | H37: Zain Javed | I37: 3520122661525 | J37: KIA PICANTO 1.0L A/T | K37: AKD-207 | L37: P153730 | M37: P709096 | N37: 74808/1 | O37: Central | P37: 0329 | Q37: 656483 | R37: 45566 | S37: 47396 | T37: 3300000 | W37: 3300000 | X37: 2 | Y37: 66000 | AA37: paid | AB37: 1141070982 | AC37: 45586 | AD37: DISBURSED | AE37: 0 | AF37: KHI/HO/D/MO/PC COMP/C/96843/41/09/2024 | AH37: 66000 | AI37: =Y37-AH37 -> 0 | AJ37: =VLOOKUP(AF37,[1]Sheet3!$B$2:$D$2361,3,0) -> FRE | AK37: TRACKER (TRASUR)
A38: Fresh | B38: 75066/1 | C38: 45536 | D38: SALAAM TAKAFUL LTD | E38: KHI/HO/D/MO/PC COMP/C/96843/42/09/2024 | F38: 45565 | G38: 45929 | H38: Naheed Asghar Ali | I38: 4250114575894 | J38: CHANGAN ALSVIN | K38: BVL-012 | L38: 521095 | M38: 1004108 | N38: 75066/1 | O38: South | P38: 0144 | Q38: 657523 | R38: 45566 | S38: 46665 | T38: 3200000 | W38: 3200000 | X38: 2 | Y38: 64000 | AA38: paid | AB38: 1141070982 | AC38: 45586 | AD38: DISBURSED | AE38: 0 | AF38: KHI/HO/D/MO/PC COMP/C/96843/42/09/2024 | AH38: 64000 | AI38: =Y38-AH38 -> 0 | AJ38: =VLOOKUP(AF38,[1]Sheet3!$B$2:$D$2361,3,0) -> FRE | AK38: TRACKER (TRASUR)
A39: Fresh | B39: 75243/1 | C39: 45536 | D39: SALAAM TAKAFUL LTD | E39: KHI/HO/D/MO/PC COMP/C/96843/43/09/2024 | F39: 45565 | G39: 45929 | H39: Sikandar Hussain | I39: 3740209791349 | J39: SUZUKI BOLAN | L39: 1032816 | M39: 01149315 | N39: 75243/1 | O39: North | P39: 0804 | Q39: 658427 | R39: 45566 | S39: 47396 | T39: 1940000 | W39: 1940000 | X39: 2 | Y39: 38800 | AA39: paid | AB39: 1141070982 | AC39: 45586 | AD39: DISBURSED | AE39: 0 | AF39: KHI/HO/D/MO/PC COMP/C/96843/43/09/2024 | AH39: 38800 | AI39: =Y39-AH39 -> 0 | AJ39: =VLOOKUP(AF39,[1]Sheet3!$B$2:$D$2361,3,0) -> FRE | AK39: TRACKER (TRASUR)
A40: Fresh | B40: 74935/1 | C40: 45536 | D40: SALAAM TAKAFUL LTD | E40: KHI/HO/D/MO/PC COMP/C/96843/44/09/2024 | F40: 45565 | G40: 45929 | H40: Muhammad Kashif | I40: 3520197275909 | J40: SUZUKI WAGON R VXL | K40: LEC-19-7721 | L40: 176360 | M40: 10076402 | N40: 74935/1 | O40: Central | P40: 0329 | Q40: 629773 | R40: 45566 | S40: 47396 | T40: 2000000 | W40: 2000000 | X40: 2 | Y40: 40000 | AA40: paid | AB40: 1141070982 | AC40: 45586 | AD40: DISBURSED | AE40: 0 | AF40: KHI/HO/D/MO/PC COMP/C/96843/44/09/2024 | AH40: 40000 | AI40: =Y40-AH40 -> 0 | AJ40: =VLOOKUP(AF40,[1]Sheet3!$B$2:$D$2361,3,0) -> FRE | AK40: TRACKER (TRASUR)
...

Sheet Renewal
A1: Fresh / Renewal | B1: Proposal No. | C1: Billing Month | D1: Takaful Company | E1: PMD / Cert | F1: Takaful Start Date | G1: Takaful End Date | H1: Customer Name | I1: CNIC | J1: Vehicle Make | K1: Reg. No | L1: Engine No | M1: Chassis No | N1: Proposal No. | O1: Region | P1: Unit ID | Q1: BR # | R1: Financing Date | S1: Maturity Date | T1: Asset Value | U1: Dep. % | V1: Dep. Amount | W1: Sum Cover Amount | X1: Takaful Rate | Y1: Premium Amount | Z1: For Takaful Company Rectifications | AA1: For COD Status | AB1: PO No. | AC1: PO Dates | AD1: Proposal Status | AE1: Default Case (Overdue Days) | AF1: Policy # | AG1: Tms Prem | AH1: Difference | AI1: Tagging | AJ1: Tracker
A2: Renewal | B2: 50798/1 | C2: 45536 | D2: SALAAM TAKAFUL LTD | E2: KHI/HO/D/MO/CV/C/96712/1/09/2024 | F2: 45543 | G2: 45907 | H2: Muhammad Ashfaq Cheema | I2: 3460122746801 | J2: SUZUKI RAVI VX EURO II | K2: TC-346 | L2: 374791 | M2: 479181 | N2: 50798/1 | O2: North | P2: 0804 | Q2: 544015 | R2: 44455 | S2: 46300 | T2: 1020000 | U2: 20 | V2: 204000 | W2: 816000 | X2: 2.5 | Y2: 20400 | AA2: paid | AB2: 1141071091 | AC2: 45593 | AD2: DISBURSED | AE2: 9 | AF2: KHI/HO/D/MO/CV/C/96712/1/09/2024 | AG2: 20400 | AH2: =Y2-AG2 -> 0 | AI2: REN | AJ2: TRACKER (TRASUR)
A3: Renewal | B3: 50973/1 | C3: 45536 | D3: SALAAM TAKAFUL LTD | E3: KHI/HO/D/MO/CV/C/96712/2/09/2024 | F3: 45550 | G3: 45914 | H3: Saani Gul | I3: 1610137614695 | J3: SUZUKI RAVI VX EURO II | K3: JA-9912 | L3: 372743 | M3: 477395 | N3: 50973/1 | O3: North | P3: 0610 | Q3: 539428 | R3: 44466 | S3: 46300 | T3: 1020000 | U3: 20 | V3: 204000 | W3: 816000 | X3: 2.5 | Y3: 20400 | AA3: paid | AB3: 1141071091 | AC3: 45593 | AD3: DISBURSED | AE3: 9 | AF3: KHI/HO/D/MO/CV/C/96712/2/09/2024 | AG3: 20400 | AH3: =Y3-AG3 -> 0 | AI3: REN | AJ3: TRACKER (TRASUR)
A4: Renewal | B4: 60136/1 | C4: 45536 | D4: SALAAM TAKAFUL LTD | E4: KHI/HO/D/MO/CV/C/96713/1/09/2024 | F4: 45562 | G4: 45926 | H4: Qasim Yaqoob | I4: 3520214283093 | J4: FORLAND PICKUP C-10 | K4: CAL-779 | L4: N03601681 | M4: NL004450 | N4: 60136/1 | O4: Central | P4: 0329 | Q4: 586296 | R4: 44833 | S4: 46665 | T4: 1659000 | U4: 15 | V4: 248850 | W4: 1410150 | X4: 2 | Y4: 28203 | AA4: paid | AB4: 1141071091 | AC4: 45593 | AD4: DISBURSED | AE4: 9 | AF4: KHI/HO/D/MO/CV/C/96713/1/09/2024 | AG4: 28203 | AH4: =Y4-AG4 -> 0 | AI4: REN | AJ4: TRACKER (TRASUR)
A5: Renewal | B5: 60159/1 | C5: 45536 | D5: SALAAM TAKAFUL LTD | E5: KHI/HO/D/MO/CV/C/96713/2/09/2024 | F5: 45562 | G5: 45926 | H5: Imran Khan | I5: 3740550368021 | J5: SUZUKI RAVI VX EURO II | K5: TAB-37 | L5: 386797 | M5: 491470 | N5: 60159/1 | O5: North | P5: 0804 | Q5: 583321 | R5: 44833 | S5: 46665 | T5: 1424000 | U5: 15 | V5: 213600 | W5: 1210400 | X5: 2 | Y5: 24208 | AA5: paid | AB5: 1141071091 | AC5: 45593 | AD5: DISBURSED | AE5: 9 | AF5: KHI/HO/D/MO/CV/C/96713/2/09/2024 | AG5: 24208 | AH5: =Y5-AG5 -> 0 | AI5: REN | AJ5: TRACKER (TRASUR)
A6: Renewal | B6: 60153/1 | C6: 45536 | D6: SALAAM TAKAFUL LTD | E6: KHI/HO/D/MO/CV/C/96713/4/09/2024 | F6: 45564 | G6: 45928 | H6: Muhammad Asghar | I6: 4210114228835 | J6: SUZUKI RAVI VX EURO II | K6: LC-0312 | L6: 386268 | M6: 490935 | N6: 60153/1 | O6: South | P6: 0150 | Q6: 196873 | R6: 44834 | S6: 46665 | T6: 1424000 | U6: 15 | V6: 213600 | W6: 1210400 | X6: 2 | Y6: 24208 | AA6: paid | AB6: 1141071091 | AC6: 45593 | AD6: DISBURSED | AE6: 39 | AF6: KHI/HO/D/MO/CV/C/96713/4/09/2024 | AG6: 24208 | AH6: =Y6-AG6 -> 0 | AI6: REN | AJ6: TRACKER (TRASUR)
A7: Renewal | B7: 60289/1 | C7: 45536 | D7: SALAAM TAKAFUL LTD | E7: KHI/HO/D/MO/CV/C/96713/5/09/2024 | F7: 45565 | G7: 45929 | H7: Abdur Rabb | I7: 6110177334495 | J7: SUZUKI RAVI VX EURO II | K7: CAL-3837 | L7: 386523 | M7: 491186 | N7: 60289/1 | O7: Central | P7: 0329 | Q7: 586490 | R7: 44837 | S7: 46665 | T7: 1424000 | U7: 15 | V7: 213600 | W7: 1210400 | X7: 2 | Y7: 24208 | AA7: paid | AB7: 1141071091 | AC7: 45593 | AD7: DISBURSED | AE7: 9 | AF7: KHI/HO/D/MO/CV/C/96713/5/09/2024 | AG7: 24208 | AH7: =Y7-AG7 -> 0 | AI7: REN | AJ7: TRACKER (TRASUR)
A8: Renewal | B8: 43673/1 | C8: 45536 | D8: SALAAM TAKAFUL LTD | E8: KHI/HO/D/MO/CV/C/96714/1/09/2024 | F8: 45564 | G8: 45928 | H8: Ahamd Shahzad | I8: 3740115070783 | J8: SUZUKI RAVI VX EURO II | K8: TAA-634 | L8: 363681 | M8: 468344 | N8: 43673/1 | O8: North | P8: 0804 | Q8: 336286 | R8: 44105 | S8: 45936 | T8: 1034000 | U8: 25 | V8: 258500 | W8: 775500 | X8: 2.5 | Y8: 19387.5 | AA8: paid | AB8: 1141071091 | AC8: 45593 | AD8: DISBURSED | AE8: 0 | AF8: KHI/HO/D/MO/CV/C/96714/1/09/2024 | AG8: 19388 | AH8: =Y8-AG8 -> -0.5 | AI8: REN | AJ8: TRACKER (TRASUR)
A9: Renewal | B9: 43701/1 | C9: 45536 | D9: SALAAM TAKAFUL LTD | E9: KHI/HO/D/MO/CV/C/96714/2/09/2024 | F9: 45565 | G9: 45929 | H9: Muhammad Tahir | I9: 3740575231283 | J9: SUZUKI RAVI VX EURO II | K9: TAA-583 | L9: 363607 | M9: 468274 | N9: 43701/1 | O9: North | P9: 0804 | Q9: 497892 | R9: 44105 | S9: 45936 | T9: 1034000 | U9: 25 | V9: 258500 | W9: 775500 | X9: 2.5 | Y9: 19387.5 | AA9: paid | AB9: 1141071091 | AC9: 45593 | AD9: DISBURSED | AE9: 39 | AF9: KHI/HO/D/MO/CV/C/96714/2/09/2024 | AG9: 19388 | AH9: =Y9-AG9 -> -0.5 | AI9: REN | AJ9: TRACKER (TRASUR)
A10: Renewal | B10: 66237/1 | C10: 45536 | D10: SALAAM TAKAFUL LTD | E10: KHI/HO/D/MO/PC COMP/C/96715/1/09/2024 | F10: 45542 | G10: 45906 | H10: Imran Javed | I10: 3520213666053 | J10: HONDA BRV - S | K10: LE-17A-225 | L10: 13502509 | M10: HR002526 | N10: 66237/1 | O10: Central | P10: 0329 | Q10: 622666 | R10: 45187 | S10: 46300 | T10: 3800000 | U10: 10 | V10: 380000 | W10: 3420000 | X10: 1.5 | Y10: 51300 | AA10: paid | AB10: 1141071091 | AC10: 45593 | AD10: DISBURSED | AE10: 9 | AF10: KHI/HO/D/MO/PC COMP/C/96715/1/09/2024 | AG10: 51300 | AH10: =Y10-AG10 -> 0 | AI10: REN | AJ10: TRACKER (TRASUR)
A11: Renewal | B11: 66115/1 | C11: 45536 | D11: SALAAM TAKAFUL LTD | E11: KHI/HO/D/MO/PC COMP/C/96715/10/09/2024 | F11: 45562 | G11: 45926 | H11: Syed Umair Ahmed Zaidi | I11: 6110123000241 | J11: HONDA CITY 1.5 ASPIRE CVT | K11: AXW-46 | L11: 81006393 | M11: 016267 | N11: 66115/1 | O11: North | P11: 0804 | Q11: 622031 | R11: 45197 | S11: 46300 | T11: 5350000 | U11: 10 | V11: 535000 | W11: 4815000 | X11: 1.5 | Y11: 72225 | AA11: paid | AB11: 1141071091 | AC11: 45593 | AD11: DISBURSED | AE11: 0 | AF11: KHI/HO/D/MO/PC COMP/C/96715/10/09/2024 | AG11: 72225 | AH11: =Y11-AG11 -> 0 | AI11: REN | AJ11: TRACKER (TRASUR)
A12: Renewal | B12: 66643/1 | C12: 45536 | D12: SALAAM TAKAFUL LTD | E12: KHI/HO/D/MO/PC COMP/C/96715/11/09/2024 | F12: 45563 | G12: 45927 | H12: Muhammad Azeem Khalid | I12: 3650173272615 | J12: SUZUKI ALTO VXR E-2 | K12: LEA-20-8853 | L12: 6R131403 | M12: 1031389 | N12: 66643/1 | O12: Central | P12: 0329 | Q12: 624549 | R12: 45197 | S12: 47031 | T12: 2100000 | U12: 10 | V12: 210000 | W12: 1890000 | X12: 2 | Y12: 37800 | AA12: paid | AB12: 1141071091 | AC12: 45593 | AD12: DISBURSED | AE12: 9 | AF12: KHI/HO/D/MO/PC COMP/C/96715/11/09/2024 | AG12: 37800 | AH12: =Y12-AG12 -> 0 | AI12: REN | AJ12: TRACKER (TRASUR)
A13: Renewal | B13: 67246/1 | C13: 45536 | D13: SALAAM TAKAFUL LTD | E13: KHI/HO/D/MO/PC COMP/C/96715/13/09/2024 | F13: 45563 | G13: 45927 | H13: Muhammad Danish | I13: 3740552473459 | J13: SUZUKI ALTO AGS A/T | L13: 283805 | M13: 1183866 | N13: 67246/1 | O13: North | P13: 0804 | Q13: 573734 | R13: 45201 | S13: 47031 | T13: 2935000 | U13: 10 | V13: 293500 | W13: 2641500 | X13: 2 | Y13: 52830 | AA13: paid | AB13: 1141071091 | AC13: 45593 | AD13: DISBURSED | AE13: 9 | AF13: KHI/HO/D/MO/PC COMP/C/96715/13/09/2024 | AG13: 52830 | AH13: =Y13-AG13 -> 0 | AI13: REN | AJ13: TRACKER (TRASUR)
A14: Renewal | B14: 67464/1 | C14: 45536 | D14: SALAAM TAKAFUL LTD | E14: KHI/HO/D/MO/PC COMP/C/96715/14/09/2024 | F14: 45563 | G14: 45927 | H14: Adil Bin Arshad | I14: 6110184847261 | J14: TOYOTA VITZ | K14: BCA-134 | L14: 2037375 | M14: 2224105 | N14: 67464/1 | O14: North | P14: 0804 | Q14: 589875 | R14: 45201 | S14: 46665 | T14: 4000000 | U14: 10 | V14: 400000 | W14: 3600000 | X14: 1.5 | Y14: 54000 | AA14: paid | AB14: 1141071091 | AC14: 45593 | AD14: DISBURSED | AE14: 9 | AF14: KHI/HO/D/MO/PC COMP/C/96715/14/09/2024 | AG14: 54000 | AH14: =Y14-AG14 -> 0 | AI14: REN | AJ14: TRACKER (TRASUR)
A15: Renewal | B15: 66628/1 | C15: 45536 | D15: SALAAM TAKAFUL LTD | E15: KHI/HO/D/MO/PC COMP/C/96715/15/09/2024 | F15: 45563 | G15: 45927 | H15: Basit Mahmood | I15: 3520234855241 | J15: KIA SPORTAGE AWD-CW | K15: ACN-351 | L15: 328864 | M15: 100617 | N15: 66628/1 | O15: Central | P15: 0338 | Q15: 624398 | R15: 45201 | S15: 46300 | T15: 6000000 | U15: 10 | V15: 600000 | W15: 5400000 | X15: 1.5 | Y15: 81000 | AA15: paid | AB15: 1141071091 | AC15: 45593 | AD15: DISBURSED | AE15: 0 | AF15: KHI/HO/D/MO/PC COMP/C/96715/15/09/2024 | AG15: 81000 | AH15: =Y15-AG15 -> 0 | AI15: REN | AJ15: TRACKER (TRASUR)
A16: Renewal | B16: 66626/1 | C16: 45536 | D16: SALAAM TAKAFUL LTD | E16: KHI/HO/D/MO/PC COMP/C/96715/16/09/2024 | F16: 45563 | G16: 45927 | H16: Fazal Muhammad | I16: 4220154356145 | J16: SUZUKI ALTO VXR E-2 | K16: BSR-603 | L16: R147259 | M16: 1047244 | N16: 66626/1 | O16: South | P16: 0144 | Q16: 610496 | R16: 45201 | S16: 47031 | T16: 2450000 | U16: 10 | V16: 245000 | W16: 2205000 | X16: 2 | Y16: 44100 | AA16: paid | AB16: 1141071091 | AC16: 45593 | AD16: DISBURSED | AE16: 0 | AF16: KHI/HO/D/MO/PC COMP/C/96715/16/09/2024 | AG16: 44100 | AH16: =Y16-AG16 -> 0 | AI16: REN | AJ16: TRACKER (TRASUR)
A17: Renewal | B17: 67303/1 | C17: 45536 | D17: SALAAM TAKAFUL LTD | E17: KHI/HO/D/MO/PC COMP/C/96715/17/09/2024 | F17: 45563 | G17: 45927 | H17: Muhammad Rashid Latif | I17: 3520171467503 | J17: SUZUKI ALTO VX | K17: AQC-748 | L17: 284156 | M17: 1184180 | N17: 67303/1 | O17: Central | P17: 0329 | Q17: 595430 | R17: 45201 | S17: 47031 | T17: 2612000 | U17: 10 | V17: 261200 | W17: 2350800 | X17: 2 | Y17: 47016 | AA17: paid | AB17: 1141071091 | AC17: 45593 | AD17: DISBURSED | AE17: 0 | AF17: KHI/HO/D/MO/PC COMP/C/96715/17/09/2024 | AG17: 47016 | AH17: =Y17-AG17 -> 0 | AI17: REN | AJ17: TRACKER (TRASUR)
A18: Renewal | B18: 67444/1 | C18: 45536 | D18: SALAAM TAKAFUL LTD | E18: KHI/HO/D/MO/PC COMP/C/96715/18/09/2024 | F18: 45563 | G18: 45927 | H18: Shan Shahbaz | I18: 3740559793113 | J18: HONDA CIVIC VTI ORIEL I-V | K18: AVF-706 | L18: 925506 | M18: 077858 | N18: 67444/1 | O18: North | P18: 0804 | Q18: 300129 | R18: 45197 | S18: 45936 | T18: 6500000 | U18: 10 | V18: 650000 | W18: 5850000 | X18: 1.5 | Y18: 87750 | AA18: paid | AB18: 1141071091 | AC18: 45593 | AD18: DISBURSED | AE18: 0 | AF18: KHI/HO/D/MO/PC COMP/C/96715/18/09/2024 | AG18: 87750 | AH18: =Y18-AG18 -> 0 | AI18: REN | AJ18: TRACKER (TRASUR)
A19: Renewal | B19: 66538/1 | C19: 45536 | D19: SALAAM TAKAFUL LTD | E19: KHI/HO/D/MO/PC COMP/C/96715/2/09/2024 | F19: 45546 | G19: 45910 | H19: Haroon Shahzad | I19: 3520216111429 | J19: KIA PICANTO 1.0L A/T | K19: AMQ-599 | L19: P020764 | M19: P710149 | N19: 66538/1 | O19: Central | P19: 0329 | Q19: 624189 | R19: 45183 | S19: 47001 | T19: 3000000 | U19: 10 | V19: 300000 | W19: 2700000 | X19: 2 | Y19: 54000 | AA19: paid | AB19: 1141071091 | AC19: 45593 | AD19: DISBURSED | AE19: 0 | AF19: KHI/HO/D/MO/PC COMP/C/96715/2/09/2024 | AG19: 54000 | AH19: =Y19-AG19 -> 0 | AI19: REN | AJ19: TRACKER (TRASUR)
A20: Renewal | B20: 67319/1 | C20: 45536 | D20: SALAAM TAKAFUL LTD | E20: KHI/HO/D/MO/PC COMP/C/96715/20/09/2024 | F20: 45563 | G20: 45927 | H20: Muhammad Tayyab | I20: 3520259450479 | J20: SUZUKI WAGON R VXL AGS | K20: AQD-991 | L20: 246460 | M20: 10146459 | N20: 67319/1 | O20: Central | P20: 0329 | Q20: 627154 | R20: 45203 | S20: 47031 | T20: 3641000 | U20: 10 | V20: 364100 | W20: 3276900 | X20: 1.5 | Y20: 49153.5 | AA20: paid | AB20: 1141071091 | AC20: 45593 | AD20: DISBURSED | AE20: 0 | AF20: KHI/HO/D/MO/PC COMP/C/96715/20/09/2024 | AG20: 49154 | AH20: =Y20-AG20 -> -0.5 | AI20: REN | AJ20: TRACKER (TRASUR)
A21: Renewal | B21: 67290/1 | C21: 45536 | D21: SALAAM TAKAFUL LTD | E21: KHI/HO/D/MO/PC COMP/C/96715/21/09/2024 | F21: 45563 | G21: 45927 | H21: Ali Abid | I21: 3520167450389 | J21: HONDA CIVIC VTI ORIEL PT | K21: AVT-543 | L21: Z16926830 | M21: MR079418 | N21: 67290/1 | O21: Central | P21: 0329 | Q21: 421545 | R21: 45201 | S21: 46300 | T21: 6300000 | U21: 10 | V21: 630000 | W21: 5670000 | X21: 1.5 | Y21: 85050 | AA21: paid | AB21: 1141071091 | AC21: 45593 | AD21: DISBURSED | AE21: 9 | AF21: KHI/HO/D/MO/PC COMP/C/96715/21/09/2024 | AG21: 85050 | AH21: =Y21-AG21 -> 0 | AI21: REN | AJ21: TRACKER (TRASUR)
A22: Renewal | B22: 66270/1 | C22: 45536 | D22: SALAAM TAKAFUL LTD | E22: KHI/HO/D/MO/PC COMP/C/96715/3/09/2024 | F22: 45547 | G22: 45911 | H22: Shah Zaman | I22: 1560221122683 | J22: PRINCE PEARL | K22: BSE-417 | L22: L06605804W | M22: 20100982 | N22: 66270/1 | O22: South | P22: 0138 | Q22: 621992 | R22: 45190 | S22: 47031 | T22: 930000 | U22: 10 | V22: 93000 | W22: 837000 | X22: 2 | Y22: 16740 | AA22: paid | AB22: 1141071091 | AC22: 45593 | AD22: DISBURSED | AE22: 70 | AF22: KHI/HO/D/MO/PC COMP/C/96715/3/09/2024 | AG22: 16740 | AH22: =Y22-AG22 -> 0 | AI22: REN | AJ22: TRACKER (TRASUR)
A23: Renewal | B23: 67215/2 | C23: 45536 | D23: SALAAM TAKAFUL LTD | E23: KHI/HO/D/MO/PC COMP/C/96715/4/09/2024 | F23: 45555 | G23: 45919 | H23: Zia Shahid | I23: 4210104448245 | J23: HONDA CITY I-VTEC (M/T) | K23: BFJ-943 | L23: 7441633 | M23: GR181879 | N23: 67215/2 | O23: South | P23: 0144 | Q23: 334577 | R23: 45191 | S23: 46300 | T23: 2250000 | U23: 10 | V23: 225000 | W23: 2025000 | X23: 2 | Y23: 40500 | AA23: paid | AB23: 1141071091 | AC23: 45593 | AD23: DISBURSED | AE23: 0 | AF23: KHI/HO/D/MO/PC COMP/C/96715/4/09/2024 | AG23: 40500 | AH23: =Y23-AG23 -> 0 | AI23: REN | AJ23: TRACKER (TRASUR)
A24: Renewal | B24: 67093/1 | C24: 45536 | D24: SALAAM TAKAFUL LTD | E24: KHI/HO/D/MO/PC COMP/C/96715/5/09/2024 | F24: 45555 | G24: 45919 | H24: Umair Ata | I24: 4130207327153 | J24: SUZUKI ALTO VXR | L24: 283708 | M24: 1183674 | N24: 67093/1 | O24: South | P24: 0252 | Q24: 626677 | R24: 45195 | S24: 47031 | T24: 2612000 | U24: 10 | V24: 261200 | W24: 2350800 | X24: 2 | Y24: 47016 | AA24: paid | AB24: 1141071091 | AC24: 45593 | AD24: DISBURSED | AE24: 9 | AF24: KHI/HO/D/MO/PC COMP/C/96715/5/09/2024 | AG24: 47016 | AH24: =Y24-AG24 -> 0 | AI24: REN | AJ24: TRACKER (TRASUR)
A25: Renewal | B25: 65939/2 | C25: 45536 | D25: SALAAM TAKAFUL LTD | E25: KHI/HO/D/MO/PC COMP/C/96715/6/09/2024 | F25: 45557 | G25: 45921 | H25: Salman Pervaiz | I25: 4230177909083 | J25: SUZUKI ALTO | K25: BYZ-581 | L25: 6R283657 | M25: 1183655 | N25: 65939/2 | O25: South | P25: 0144 | Q25: 621108 | R25: 45194 | S25: 46300 | T25: 2935000 | U25: 10 | V25: 293500 | W25: 2641500 | X25: 2 | Y25: 52830 | AA25: paid | AB25: 1141071091 | AC25: 45593 | AD25: DISBURSED | AE25: 0 | AF25: KHI/HO/D/MO/PC COMP/C/96715/6/09/2024 | AG25: 52830 | AH25: =Y25-AG25 -> 0 | AI25: REN | AJ25: TRACKER (TRASUR)
A26: Renewal | B26: 66574/1 | C26: 45536 | D26: SALAAM TAKAFUL LTD | E26: KHI/HO/D/MO/PC COMP/C/96715/7/09/2024 | F26: 45561 | G26: 45925 | H26: Bilal Shamim | I26: 3530271985517 | J26: HONDA CIVIC | K26: LEE-17-5886 | L26: Z12915185 | M26: HR018489 | N26: 66574/1 | O26: Central | P26: 0329 | Q26: 624289 | R26: 45196 | S26: 46300 | T26: 4950000 | U26: 10 | V26: 495000 | W26: 4455000 | X26: 1.5 | Y26: 66825 | AA26: paid | AB26: 1141071091 | AC26: 45593 | AD26: DISBURSED | AE26: 9 | AF26: KHI/HO/D/MO/PC COMP/C/96715/7/09/2024 | AG26: 66825 | AH26: =Y26-AG26 -> 0 | AI26: REN | AJ26: TRACKER (TRASUR)
A27: Renewal | B27: 67448/1 | C27: 45536 | D27: SALAAM TAKAFUL LTD | E27: KHI/HO/D/MO/PC COMP/C/96715/8/09/2024 | F27: 45562 | G27: 45926 | H27: Zaid Haris | I27: 3540136617571 | J27: HONDA FIT HYBRID | K27: APS-290 | L27: 6306277 | M27: 1105146 | N27: 67448/1 | O27: North | P27: 0804 | Q27: 624748 | R27: 45201 | S27: 46665 | T27: 4500000 | U27: 10 | V27: 450000 | W27: 4050000 | X27: 1.5 | Y27: 60750 | AA27: paid | AB27: 1141071091 | AC27: 45593 | AD27: DISBURSED | AE27: 0 | AF27: KHI/HO/D/MO/PC COMP/C/96715/8/09/2024 | AG27: 60750 | AH27: =Y27-AG27 -> 0 | AI27: REN | AJ27: TRACKER (TRASUR)
A28: Renewal | B28: 66394/1 | C28: 45536 | D28: SALAAM TAKAFUL LTD | E28: KHI/HO/D/MO/PC COMP/C/96715/9/09/2024 | F28: 45562 | G28: 45926 | H28: Naeem Qaisar | I28: 3520270676873 | J28: HONDA CITY 1.2 LS MT | K28: LEH-18-8444 | L28: Z17515321 | M28: JR229748 | N28: 66394/1 | O28: Central | P28: 0329 | Q28: 623713 | R28: 45197 | S28: 46300 | T28: 3500000 | U28: 10 | V28: 350000 | W28: 3150000 | X28: 1.5 | Y28: 47250 | AA28: paid | AB28: 1141071091 | AC28: 45593 | AD28: DISBURSED | AE28: 9 | AF28: KHI/HO/D/MO/PC COMP/C/96715/9/09/2024 | AG28: 47250 | AH28: =Y28-AG28 -> 0 | AI28: REN | AJ28: TRACKER (TRASUR)
A29: Renewal | B29: 47214/2 | C29: 45536 | D29: SALAAM TAKAFUL LTD | E29: KHI/HO/D/MO/PC COMP/C/96721/1/09/2024 | F29: 45537 | G29: 45901 | H29: Saddam Hussain | I29: 4250139796069 | J29: KIA PICANTO 1.0L A/T | K29: BUR-017 | L29: G3LAMP107755 | M29: NNATA52AZKP707470 | N29: 47214/2 | O29: South | P29: 0150 | Q29: 528939 | R29: 44461 | S29: 46300 | T29: 1927000 | U29: 20 | V29: 385400 | W29: 1541600 | X29: 2.5 | Y29: 38540 | AA29: paid | AB29: 1141071091 | AC29: 45593 | AD29: DISBURSED | AE29: 0 | AF29: KHI/HO/D/MO/PC COMP/C/96721/1/09/2024 | AG29: 38540 | AH29: =Y29-AG29 -> 0 | AI29: REN | AJ29: TRACKER (TRASUR)
A30: Renewal | B30: 50693/1 | C30: 45536 | D30: SALAAM TAKAFUL LTD | E30: KHI/HO/D/MO/PC COMP/C/96721/10/09/2024 | F30: 45545 | G30: 45909 | H30: Syed Ikram Shah | I30: 4250171163791 | J30: TOYOTA COROLLA GLI M/T 1. | K30: BQV-624 | L30: Z565452 | M30: 4190820 | N30: 50693/1 | O30: South | P30: 0125 | Q30: 545233 | R30: 44455 | S30: 47031 | T30: 3000000 | U30: 20 | V30: 600000 | W30: 2400000 | X30: 1.5 | Y30: 36000 | AA30: paid | AB30: 1141071091 | AC30: 45593 | AD30: DISBURSED | AE30: 9 | AF30: KHI/HO/D/MO/PC COMP/C/96721/10/09/2024 | AG30: 36000 | AH30: =Y30-AG30 -> 0 | AI30: REN | AJ30: TRACKER (TRASUR)
A31: Renewal | B31: 50718/2 | C31: 45536 | D31: SALAAM TAKAFUL LTD | E31: KHI/HO/D/MO/PC COMP/C/96721/11/09/2024 | F31: 45548 | G31: 45912 | H31: Kashif Masood Malik | I31: 3510341525211 | J31: TOYOTA COROLLA GLI M/T 1. | K31: BGY-918 | L31: Z470761 | M31: 4096690 | N31: 50718/2 | O31: South | P31: 0125 | Q31: 545557 | R31: 44456 | S31: 46300 | T31: 2600000 | U31: 20 | V31: 520000 | W31: 2080000 | X31: 1.5 | Y31: 31200 | AA31: paid | AB31: 1141071091 | AC31: 45593 | AD31: DISBURSED | AE31: 0 | AF31: KHI/HO/D/MO/PC COMP/C/96721/11/09/2024 | AG31: 31200 | AH31: =Y31-AG31 -> 0 | AI31: REN | AJ31: TRACKER (TRASUR)
A32: Renewal | B32: 50861/1 | C32: 45536 | D32: SALAAM TAKAFUL LTD | E32: KHI/HO/D/MO/PC COMP/C/96721/12/09/2024 | F32: 45549 | G32: 45913 | H32: Khurram Raza | I32: 3520241553043 | J32: TOYOTA COROLLA ALTIS CVT | K32: LEC-19-1297 | L32: Q339263 | M32: 7038430 | N32: 50861/1 | O32: Central | P32: 0329 | Q32: 544050 | R32: 44459 | S32: 47031 | T32: 3950000 | U32: 20 | V32: 790000 | W32: 3160000 | X32: 1.5 | Y32: 47400 | AA32: paid | AB32: 1141071091 | AC32: 45593 | AD32: DISBURSED | AE32: 9 | AF32: KHI/HO/D/MO/PC COMP/C/96721/12/09/2024 | AG32: 47400 | AH32: =Y32-AG32 -> 0 | AI32: REN | AJ32: TRACKER (TRASUR)
A33: Renewal | B33: 50910/1 | C33: 45536 | D33: SALAAM TAKAFUL LTD | E33: KHI/HO/D/MO/PC COMP/C/96721/13/09/2024 | F33: 45550 | G33: 45914 | H33: Asrar Ahmed Malik | I33: 3630256921579 | J33: TOYOTA FORTUNER A/T 2.7L | K33: AUW-080 | L33: 1GD5043736 | M33: 1096144 | N33: 50910/1 | O33: Central | P33: 0431 | Q33: 472097 | R33: 44468 | S33: 46300 | T33: 9305000 | U33: 20 | V33: 1861000 | W33: 7444000 | X33: 1.5 | Y33: 111660 | AA33: paid | AB33: 1141071091 | AC33: 45593 | AD33: DISBURSED | AE33: 0 | AF33: KHI/HO/D/MO/PC COMP/C/96721/13/09/2024 | AG33: 111660 | AH33: =Y33-AG33 -> 0 | AI33: REN | AJ33: TRACKER (TRASUR)
A34: Renewal | B34: 50859/1 | C34: 45536 | D34: SALAAM TAKAFUL LTD | E34: KHI/HO/D/MO/PC COMP/C/96721/14/09/2024 | F34: 45551 | G34: 45915 | H34: Nasir Mahmood | I34: 3510250113737 | J34: HONDA CITY I-VTEC (M/T) | K34: LEF-16-449 | L34: L13Z17448590 | M34: GR190063 | N34: 50859/1 | O34: Central | P34: 0329 | Q34: 548401 | R34: 44459 | S34: 45936 | T34: 1975000 | U34: 20 | V34: 395000 | W34: 1580000 | X34: 1.5 | Y34: 23700 | AA34: paid | AB34: 1141071091 | AC34: 45593 | AD34: DISBURSED | AE34: 9 | AF34: KHI/HO/D/MO/PC COMP/C/96721/14/09/2024 | AG34: 23700 | AH34: =Y34-AG34 -> 0 | AI34: REN | AJ34: TRACKER (TRASUR)
A35: Renewal | B35: 49396/1 | C35: 45536 | D35: SALAAM TAKAFUL LTD | E35: KHI/HO/D/MO/PC COMP/C/96721/15/09/2024 | F35: 45552 | G35: 45916 | H35: Abrar Ahmad Khan | I35: 3740511475803 | J35: SUZUKI CULTUS VXL EURO II | K35: AVC-778 | L35: 183570 | M35: 10083560 | N35: 49396/1 | O35: North | P35: 0804 | Q35: 538078 | R35: 44461 | S35: 46300 | T35: 1830000 | U35: 20 | V35: 366000 | W35: 1464000 | X35: 2.5 | Y35: 36600 | AA35: paid | AB35: 1141071091 | AC35: 45593 | AD35: DISBURSED | AE35: 9 | AF35: KHI/HO/D/MO/PC COMP/C/96721/15/09/2024 | AG35: 36600 | AH35: =Y35-AG35 -> 0 | AI35: REN | AJ35: TRACKER (TRASUR)
A36: Renewal | B36: 47628/1 | C36: 45536 | D36: SALAAM TAKAFUL LTD | E36: KHI/HO/D/MO/PC COMP/C/96721/16/09/2024 | F36: 45552 | G36: 45916 | H36: Muhammad Ahmer Khan | I36: 4230135774829 | J36: KIA SPORTAGE FWD | K36: BJ-6457 | L36: 314723 | M36: 307119 | N36: 47628/1 | O36: South | P36: 0150 | Q36: 531400 | R36: 44461 | S36: 46300 | T36: 4788000 | U36: 20 | V36: 957600 | W36: 3830400 | X36: 1.5 | Y36: 57456 | AA36: paid | AB36: 1141071091 | AC36: 45593 | AD36: DISBURSED | AE36: 9 | AF36: KHI/HO/D/MO/PC COMP/C/96721/16/09/2024 | AG36: 57456 | AH36: =Y36-AG36 -> 0 | AI36: REN | AJ36: TRACKER (TRASUR)
A37: Renewal | B37: 49431/1 | C37: 45536 | D37: SALAAM TAKAFUL LTD | E37: KHI/HO/D/MO/PC COMP/C/96721/17/09/2024 | F37: 45553 | G37: 45917 | H37: Muhammad Aslam | I37: 3110223290155 | J37: TOYOTA YARIS ATIV MT 1.3 | K37: KEY-857 | L37: 2A36524 | M37: NSP150R-7022779 | N37: 49431/1 | O37: Central | P37: 0329 | Q37: 392883 | R37: 44463 | S37: 46300 | T37: 2703000 | U37: 20 | V37: 540600 | W37: 2162400 | X37: 2.5 | Y37: 54060 | AA37: paid | AB37: 1141071091 | AC37: 45593 | AD37: DISBURSED | AE37: 9 | AF37: KHI/HO/D/MO/PC COMP/C/96721/17/09/2024 | AG37: 54060 | AH37: =Y37-AG37 -> 0 | AI37: REN | AJ37: TRACKER (TRASUR)
A38: Renewal | B38: 50960/1 | C38: 45536 | D38: SALAAM TAKAFUL LTD | E38: KHI/HO/D/MO/PC COMP/C/96721/18/09/2024 | F38: 45553 | G38: 45917 | H38: Muhammad Asad Ullah | I38: 3530161548479 | J38: TOYOTA COROLLA ALTIS CVT | K38: AEV-783 | L38: Q352158 | M38: 7051327 | N38: 50960/1 | O38: Central | P38: 0565 | Q38: 544908 | R38: 44462 | S38: 47031 | T38: 3923000 | U38: 20 | V38: 784600 | W38: 3138400 | X38: 1.5 | Y38: 47076 | AA38: paid | AB38: 1141071091 | AC38: 45593 | AD38: DISBURSED | AE38: 9 | AF38: KHI/HO/D/MO/PC COMP/C/96721/18/09/2024 | AG38: 47076 | AH38: =Y38-AG38 -> 0 | AI38: REN | AJ38: TRACKER (TRASUR)
A39: Renewal | B39: 49675/1 | C39: 45536 | D39: SALAAM TAKAFUL LTD | E39: KHI/HO/D/MO/PC COMP/C/96721/19/09/2024 | F39: 45556 | G39: 45920 | H39: Imtiaz Ahmed | I39: 3310034871109 | J39: SUZUKI WAGON-R VXL E2 | K39: AVC-458 | L39: PK10B319808 | M39: A1J310PK10119807 | N39: 49675/1 | O39: Central | P39: 0422 | Q39: 163196 | R39: 44467 | S39: 46300 | T39: 1610000 | U39: 20 | V39: 322000 | W39: 1288000 | X39: 2.5 | Y39: 32200 | AA39: paid | AB39: 1141071091 | AC39: 45593 | AD39: DISBURSED | AE39: 9 | AF39: KHI/HO/D/MO/PC COMP/C/96721/19/09/2024 | AG39: 32200 | AH39: =Y39-AG39 -> 0 | AI39: REN | AJ39: TRACKER (TRASUR)
A40: Renewal | B40: 46269/1 | C40: 45536 | D40: SALAAM TAKAFUL LTD | E40: KHI/HO/D/MO/PC COMP/C/96721/2/09/2024 | F40: 45537 | G40: 45901 | H40: Muhammad Aamir Khan | I40: 4210156975001 | J40: CHANGAN KARVAAN VAN | K40: CZ-4191 | L40: 502617 | M40: 1007915 | N40: 46269/1 | O40: South | P40: 0150 | Q40: 521737 | R40: 44454 | S40: 47001 | T40: 1554000 | U40: 20 | V40: 310800 | W40: 1243200 | X40: 2.5 | Y40: 31080 | AA40: paid | AB40: 1141071091 | AC40: 45593 | AD40: DISBURSED | AE40: 0 | AF40: KHI/HO/D/MO/PC COMP/C/96721/2/09/2024 | AG40: 31080 | AH40: =Y40-AG40 -> 0 | AI40: REN | AJ40: TRACKER (TRASUR)
...

Sheet working
A1: POLICY NO. | B1: Assorted_code | D1: Premium | E1: 28Oct240058
A2: KHI/HO/D/MO/CV/C/96712/1/09/2024 | B2: =VLOOKUP(A2,policy!B:C,2,0) -> 070000165016 | C2: 20400 | D2: =ROUND(C2,0) -> 20400 | E2: 28Oct240058 | F2: ="insert into ins_premium_det (premium_rcv_code,assorted_code, rec_amount,premium_rcv_detail_code,remaining_amt, payrec, mode_code,coinsurance_code,class_cd,it_remarks) values" -> insert into ins_premium_det (premium_rcv_code,assorted_code, rec_amount,premium_rcv_detail_code,remaining_amt, payrec, mode_code,coinsurance_code,class_cd,it_remarks) values | G2: ="('"&E2&"','"&B2&"','"&D2&"',(select max(to_number(i.premium_rcv_detail_code))+1 from ins_premium_det i),'"&D2&"','"&D2&"','02', '11000003','00','Request by Mr. Reheel Malik 29-Oct-2024');" -> ('28Oct240058','070000165016','20400',(select max(to_number(i.premium_rcv_detail_code))+1 from ins_premium_det i),'20400','20400','02', '11000003','00','Request by Mr. Reheel Malik 29-Oct-2024'); | H2: =F2&G2 -> insert into ins_premium_det (premium_rcv_code,assorted_code, rec_amount,premium_rcv_detail_code,remaining_amt, payrec, mode_code,coinsurance_code,class_cd,it_remarks) values('28Oct240058','070000165016','20400',(select max(to_number(i.premium_rcv_detail_code))+1 from ins_premium_det i),'20400','20400','02', '11000003','00','Request by Mr. Reheel Malik 29-Oct-2024');
A3: KHI/HO/D/MO/CV/C/96712/2/09/2024 | B3: =VLOOKUP(A3,policy!B:C,2,0) -> 070000165017 | C3: 20400 | D3: =ROUND(C3,0) -> 20400 | E3: 28Oct240058 | F3: ="insert into ins_premium_det (premium_rcv_code,assorted_code, rec_amount,premium_rcv_detail_code,remaining_amt, payrec, mode_code,coinsurance_code,class_cd,it_remarks) values" -> insert into ins_premium_det (premium_rcv_code,assorted_code, rec_amount,premium_rcv_detail_code,remaining_amt, payrec, mode_code,coinsurance_code,class_cd,it_remarks) values | G3: ="('"&E3&"','"&B3&"','"&D3&"',(select max(to_number(i.premium_rcv_detail_code))+1 from ins_premium_det i),'"&D3&"','"&D3&"','02', '11000003','00','Request by Mr. Reheel Malik 29-Oct-2024');" -> ('28Oct240058','070000165017','20400',(select max(to_number(i.premium_rcv_detail_code))+1 from ins_premium_det i),'20400','20400','02', '11000003','00','Request by Mr. Reheel Malik 29-Oct-2024'); | H3: =F3&G3 -> insert into ins_premium_det (premium_rcv_code,assorted_code, rec_amount,premium_rcv_detail_code,remaining_amt, payrec, mode_code,coinsurance_code,class_cd,it_remarks) values('28Oct240058','070000165017','20400',(select max(to_number(i.premium_rcv_detail_code))+1 from ins_premium_det i),'20400','20400','02', '11000003','00','Request by Mr. Reheel Malik 29-Oct-2024');
A4: KHI/HO/D/MO/CV/C/96713/1/09/2024 | B4: =VLOOKUP(A4,policy!B:C,2,0) -> 070000165019 | C4: 28203 | D4: =ROUND(C4,0) -> 28203 | E4: 28Oct240058 | F4: ="insert into ins_premium_det (premium_rcv_code,assorted_code, rec_amount,premium_rcv_detail_code,remaining_amt, payrec, mode_code,coinsurance_code,class_cd,it_remarks) values" -> insert into ins_premium_det (premium_rcv_code,assorted_code, rec_amount,premium_rcv_detail_code,remaining_amt, payrec, mode_code,coinsurance_code,class_cd,it_remarks) values | G4: ="('"&E4&"','"&B4&"','"&D4&"',(select max(to_number(i.premium_rcv_detail_code))+1 from ins_premium_det i),'"&D4&"','"&D4&"','02', '11000003','00','Request by Mr. Reheel Malik 29-Oct-2024');" -> ('28Oct240058','070000165019','28203',(select max(to_number(i.premium_rcv_detail_code))+1 from ins_premium_det i),'28203','28203','02', '11000003','00','Request by Mr. Reheel Malik 29-Oct-2024'); | H4: =F4&G4 -> insert into ins_premium_det (premium_rcv_code,assorted_code, rec_amount,premium_rcv_detail_code,remaining_amt, payrec, mode_code,coinsurance_code,class_cd,it_remarks) values('28Oct240058','070000165019','28203',(select max(to_number(i.premium_rcv_detail_code))+1 from ins_premium_det i),'28203','28203','02', '11000003','00','Request by Mr. Reheel Malik 29-Oct-2024');
A5: KHI/HO/D/MO/CV/C/96713/2/09/2024 | B5: =VLOOKUP(A5,policy!B:C,2,0) -> 070000165020 | C5: 24208 | D5: =ROUND(C5,0) -> 24208 | E5: 28Oct240058 | F5: ="insert into ins_premium_det (premium_rcv_code,assorted_code, rec_amount,premium_rcv_detail_code,remaining_amt, payrec, mode_code,coinsurance_code,class_cd,it_remarks) values" -> insert into ins_premium_det (premium_rcv_code,assorted_code, rec_amount,premium_rcv_detail_code,remaining_amt, payrec, mode_code,coinsurance_code,class_cd,it_remarks) values | G5: ="('"&E5&"','"&B5&"','"&D5&"',(select max(to_number(i.premium_rcv_detail_code))+1 from ins_premium_det i),'"&D5&"','"&D5&"','02', '11000003','00','Request by Mr. Reheel Malik 29-Oct-2024');" -> ('28Oct240058','070000165020','24208',(select max(to_number(i.premium_rcv_detail_code))+1 from ins_premium_det i),'24208','24208','02', '11000003','00','Request by Mr. Reheel Malik 29-Oct-2024'); | H5: =F5&G5 -> insert into ins_premium_det (premium_rcv_code,assorted_code, rec_amount,premium_rcv_detail_code,remaining_amt, payrec, mode_code,coinsurance_code,class_cd,it_remarks) values('28Oct240058','070000165020','24208',(select max(to_number(i.premium_rcv_detail_code))+1 from ins_premium_det i),'24208','24208','02', '11000003','00','Request by Mr. Reheel Malik 29-Oct-2024');
A6: KHI/HO/D/MO/CV/C/96713/4/09/2024 | B6: =VLOOKUP(A6,policy!B:C,2,0) -> 070000165022 | C6: 24208 | D6: =ROUND(C6,0) -> 24208 | E6: 28Oct240058 | F6: ="insert into ins_premium_det (premium_rcv_code,assorted_code, rec_amount,premium_rcv_detail_code,remaining_amt, payrec, mode_code,coinsurance_code,class_cd,it_remarks) values" -> insert into ins_premium_det (premium_rcv_code,assorted_code, rec_amount,premium_rcv_detail_code,remaining_amt, payrec, mode_code,coinsurance_code,class_cd,it_remarks) values | G6: ="('"&E6&"','"&B6&"','"&D6&"',(select max(to_number(i.premium_rcv_detail_code))+1 from ins_premium_det i),'"&D6&"','"&D6&"','02', '11000003','00','Request by Mr. Reheel Malik 29-Oct-2024');" -> ('28Oct240058','070000165022','24208',(select max(to_number(i.premium_rcv_detail_code))+1 from ins_premium_det i),'24208','24208','02', '11000003','00','Request by Mr. Reheel Malik 29-Oct-2024'); | H6: =F6&G6 -> insert into ins_premium_det (premium_rcv_code,assorted_code, rec_amount,premium_rcv_detail_code,remaining_amt, payrec, mode_code,coinsurance_code,class_cd,it_remarks) values('28Oct240058','070000165022','24208',(select max(to_number(i.premium_rcv_detail_code))+1 from ins_premium_det i),'24208','24208','02', '11000003','00','Request by Mr. Reheel Malik 29-Oct-2024');
A7: KHI/HO/D/MO/CV/C/96713/5/09/2024 | B7: =VLOOKUP(A7,policy!B:C,2,0) -> 070000165024 | C7: 24208 | D7: =ROUND(C7,0) -> 24208 | E7: 28Oct240058 | F7: ="insert into ins_premium_det (premium_rcv_code,assorted_code, rec_amount,premium_rcv_detail_code,remaining_amt, payrec, mode_code,coinsurance_code,class_cd,it_remarks) values" -> insert into ins_premium_det (premium_rcv_code,assorted_code, rec_amount,premium_rcv_detail_code,remaining_amt, payrec, mode_code,coinsurance_code,class_cd,it_remarks) values | G7: ="('"&E7&"','"&B7&"','"&D7&"',(select max(to_number(i.premium_rcv_detail_code))+1 from ins_premium_det i),'"&D7&"','"&D7&"','02', '11000003','00','Request by Mr. Reheel Malik 29-Oct-2024');" -> ('28Oct240058','070000165024','24208',(select max(to_number(i.premium_rcv_detail_code))+1 from ins_premium_det i),'24208','24208','02', '11000003','00','Request by Mr. Reheel Malik 29-Oct-2024'); | H7: =F7&G7 -> insert into ins_premium_det (premium_rcv_code,assorted_code, rec_amount,premium_rcv_detail_code,remaining_amt, payrec, mode_code,coinsurance_code,class_cd,it_remarks) values('28Oct240058','070000165024','24208',(select max(to_number(i.premium_rcv_detail_code))+1 from ins_premium_det i),'24208','24208','02', '11000003','00','Request by Mr. Reheel Malik 29-Oct-2024');
A8: KHI/HO/D/MO/CV/C/96714/1/09/2024 | B8: =VLOOKUP(A8,policy!B:C,2,0) -> 070000165026 | C8: 19388 | D8: =ROUND(C8,0) -> 19388 | E8: 28Oct240058 | F8: ="insert into ins_premium_det (premium_rcv_code,assorted_code, rec_amount,premium_rcv_detail_code,remaining_amt, payrec, mode_code,coinsurance_code,class_cd,it_remarks) values" -> insert into ins_premium_det (premium_rcv_code,assorted_code, rec_amount,premium_rcv_detail_code,remaining_amt, payrec, mode_code,coinsurance_code,class_cd,it_remarks) values | G8: ="('"&E8&"','"&B8&"','"&D8&"',(select max(to_number(i.premium_rcv_detail_code))+1 from ins_premium_det i),'"&D8&"','"&D8&"','02', '11000003','00','Request by Mr. Reheel Malik 29-Oct-2024');" -> ('28Oct240058','070000165026','19388',(select max(to_number(i.premium_rcv_detail_code))+1 from ins_premium_det i),'19388','19388','02', '11000003','00','Request by Mr. Reheel Malik 29-Oct-2024'); | H8: =F8&G8 -> insert into ins_premium_det (premium_rcv_code,assorted_code, rec_amount,premium_rcv_detail_code,remaining_amt, payrec, mode_code,coinsurance_code,class_cd,it_remarks) values('28Oct240058','070000165026','19388',(select max(to_number(i.premium_rcv_detail_code))+1 from ins_premium_det i),'19388','19388','02', '11000003','00','Request by Mr. Reheel Malik 29-Oct-2024');
A9: KHI/HO/D/MO/CV/C/96714/2/09/2024 | B9: =VLOOKUP(A9,policy!B:C,2,0) -> 070000165027 | C9: 19388 | D9: =ROUND(C9,0) -> 19388 | E9: 28Oct240058 | F9: ="insert into ins_premium_det (premium_rcv_code,assorted_code, rec_amount,premium_rcv_detail_code,remaining_amt, payrec, mode_code,coinsurance_code,class_cd,it_remarks) values" -> insert into ins_premium_det (premium_rcv_code,assorted_code, rec_amount,premium_rcv_detail_code,remaining_amt, payrec, mode_code,coinsurance_code,class_cd,it_remarks) values | G9: ="('"&E9&"','"&B9&"','"&D9&"',(select max(to_number(i.premium_rcv_detail_code))+1 from ins_premium_det i),'"&D9&"','"&D9&"','02', '11000003','00','Request by Mr. Reheel Malik 29-Oct-2024');" -> ('28Oct240058','070000165027','19388',(select max(to_number(i.premium_rcv_detail_code))+1 from ins_premium_det i),'19388','19388','02', '11000003','00','Request by Mr. Reheel Malik 29-Oct-2024'); | H9: =F9&G9 -> insert into ins_premium_det (premium_rcv_code,assorted_code, rec_amount,premium_rcv_detail_code,remaining_amt, payrec, mode_code,coinsurance_code,class_cd,it_remarks) values('28Oct240058','070000165027','19388',(select max(to_number(i.premium_rcv_detail_code))+1 from ins_premium_det i),'19388','19388','02', '11000003','00','Request by Mr. Reheel Malik 29-Oct-2024');
