Workbook

Sheet T-PAK
A1: Sr. | B1: Status | C1: Contract No. | D1: Class Code | E1: Contract Status | F1: Insurance Agency | G1: Dealer Name | H1: App ID | I1: CIF # | J1: Insurance Rate | K1: Profit Rate | L1: ISI Account No. | M1: Customer Name | N1: City | O1: CNIC No. | P1: Home Phone# | Q1: Mobile Number | R1: Business Phone# | S1: Mail Address | T1: Finance Amount | U1: Car Price | V1: Ins. Policy | W1: Ins. Expiry Date | X1: Engine No. | Y1: Chassis No. | Z1: Car Category | AA1: Reg. No. | AB1: Car Name | AC1: Model | AD1: Contract Booking Date | AE1: Contract Value Date | AF1: Contract Maturity Date | AG1: Purchase Order No. | AH1: Tenor#2 | AI1: Tracker Company | AJ1: Tracker Reference Number | AK1: Tracker Installation Date | AL1: Contract No.2 | AM1: Rate | AN1: Sum Insured | AO1: Premium | AP1: OLD Contract Ref | AQ1: Remarks-I | AR1: Remarks-II
A2: 1 | B2: CLOSED | C2: 9976AD1210740004 | D2: 6AD1 | E2: A | F2: T-PAK | G2: TOYOTA LAYALPUR MOTOR | H2: 643165 | I2: 0679228 | J2: 2 | K2: 25.45 | L2: 0679228001 | M2: MURAD SALEEM | N2: Faisalabad | O2: 33102-9076864-7 | P2: 03216664328 | Q2: 03216664328, 03216664328 | R2: 0418860340 | S2: P-4041 MAIN SHEIKHUPURA ROAD HAJI A BAD FAISALABAD PK | T2: 2746100 | U2: 3923000 | V2: 55601/00054/09/2021 | W2: 29-SEP-2022 | X2: Q0352444 | Y2: 7051600 | Z2: NEW | AB2: TOYOTA COROLLA ALTIS GRANDE CVT | AC2: 2021 | AD2: 15-MAR-2021 | AE2: 03-OCT-2021 | AF2: 03-Oct-2024 | AG2: OLAFSD300066742 | AH2: 3 | AI2: ITFT | AJ2: 5442/09/2021/ITFM | AK2: 30-SEP-2021 | AM2: 2% | AN2: 0 | AO2: 0
A3: 2 | B3: CLOSED | C3: 9976AP1222730064 | D3: 6AP1 | E3: A | F3: T-PAK | G3: NEW CAR COMPLEX | H3: 1200610 | I3: 0074972 | J3: 1.75 | K3: 25.2 | L3: 0074972005 | M3: MUSHTAQ HAROON | N3: Karachi | O3: 42201-4972674-3 | P3: 32256416 | Q3: 03002369446 | R3: 35216213 | S3: FLAT NO A 2 SOUTHERN COPERATIVE SOCIETY 106 DEPOT LINE RIZVI SHAHEED ROAD PLOT 106 FIRST FLOOR KARACHI | T3: 1300000 | U3: 2000000 | V3: 63286/00098/09/2022 | W3: 29-SEP-2023 | X3: 13041512 | Y3: 10041514 | Z3: USD | AA3: BMT-564 | AB3: SUZUKI SWIFT A/T NAVIGATION | AC3: 2018 | AD3: 30-SEP-2022 | AE3: 03-OCT-2022 | AF3: 03-Oct-2024 | AG3: OLUKHI300090209 | AH3: 2 | AI3: ITFM | AJ3: 8911/09/2022/ITFM | AK3: 30-SEP-2022 | AM3: 1.75% | AN3: 0 | AO3: 0
A4: 3 | B4: CLOSED | C4: 9976AD1211830084 | D4: 6AD1 | E4: A | F4: T-PAK | G4: KIA CLIFTON | H4: 1091257 | I4: 0462522 | J4: 1.75 | K4: 25.95 | L4: 0462522002 | M4: ANIL KUMAR | N4: Karachi | O4: 42301-1102183-1 | Q4: 03333430536 | R4: 32786657 | S4: KARACHI CHEMIST AND DRUGGIEST SHOP NO 1 SHABAZ PLAZA OPPOSITE CIVIL HOSPITAL BABA E URDU ROAD KARACHI | T4: 3386349 | U4: 5275999 | V4: DIB/T/BT/33727/KHI/0921 | W4: 29-SEP-2022 | X4: 315536 | Y4: 512969 | Z4: NEW | AB4: KIA SPORTAGE AWD | AC4: 2021 | AD4: 02-JUL-2021 | AE4: 03-OCT-2021 | AF4: 03-Oct-2024 | AG4: OLAKHI300070365 | AH4: 3 | AM4: 1.75% | AN4: 0 | AO4: 0
A5: 4 | B5: CLOSED | C5: 9976AP1212740089 | D5: 6AP1 | E5: A | F5: T-PAK | G5: NEW S.S MOTORS | H5: 1099727 | I5: 0361983 | J5: 2 | K5: 25.69 | L5: 0361983002 | M5: ABID ALI | N5: Faisalabad | O5: 33100-6228369-3 | Q5: 03009653100 | S5: HOUSE NO 174 B D-GROUND MOHALA PEOPLES COLONY NO 1 FAISALABAD | T5: 2832500 | U5: 5150000 | V5: 56038/00001/10/2021 | W5: 29-SEP-2022 | X5: G4NALH3413439 | Y5: NNAQL51AZKP304712 | Z5: USD | AA5: ASH-882 | AB5: KIA SPORTAGE FWD | AC5: 2021 | AD5: 01-OCT-2021 | AE5: 03-OCT-2021 | AF5: 03-Oct-2024 | AG5: OLUFSD300074560 | AH5: 3 | AM5: 2% | AN5: 0 | AO5: 0
A6: 5 | B6: CLOSED | C6: 997AAD1202100014 | D6: AAD1 | E6: A | F6: T-PAK | G6: HONDA LYALLPUR | H6: 598281 | I6: 0075974 | J6: 1.5 | K6: 26.78 | L6: 0075974003 | M6: ADNAN ALI | N6: Faisalabad | O6: 33100-7791721-1 | P6: 8733900 | Q6: 03218733900 | S6: H NO P-990 RAJA GHULAM RASOOL NAGAR PEOPLES COLONY NO 2 FAISALABAD | T6: 2837450 | U6: 4053500 | V6: COMP/P/52740/09/2020 | W6: 29-SEP-2021 | X6: R18Z16913639 | Y6: NFBFC6661LR065434 | Z6: NEW | AB6: CIVIC VTI ORIEL P/T | AC6: 2020 | AD6: 28-JUL-2020 | AE6: 03-OCT-2020 | AF6: 03-Oct-2024 | AG6: POAFSD300055961 | AH6: 4 | AI6: ITFM | AJ6: 3117/09/2020/ITFM | AK6: 30-SEP-2020 | AM6: 1.5% | AN6: 0 | AO6: 0
A7: 6 | B7: CLOSED | C7: 9976AP1192730026 | D7: 6AP1 | E7: A | F7: T-PAK | G7: TOYOTA CAPITAL MOTORS | H7: 587018 | I7: 0562911 | J7: 2.5 | K7: 26.7 | L7: 0562911001 | M7: ASIF IQBAL | N7: Islamabad | O7: 61101-1847774-9 | P7: 03425474950 | R7: 0 | S7: H # 385 ST # 17 SECTOR I-10/2 ISLAMABAD PK | T7: 2198570 | U7: 2783000 | V7: 51132/00104/09/2019 | W7: 29-SEP-2020 | X7: Z566768 | Y7: 4192614 | Z7: NEW | AA7: APS-981 | AB7: COROLLA GLI | AC7: 2019 | AD7: 30-SEP-2019 | AE7: 03-OCT-2019 | AF7: 03-Oct-2024 | AG7: PODISD300049568 | AH7: 5 | AI7: ITFM | AJ7: 1824/09/2019/ITFM | AK7: 30-SEP-2019 | AM7: 2.5% | AN7: 0 | AO7: 0
A8: 7 | B8: CLOSED | C8: 9976AD1212120063 | D8: 6AD1 | E8: A | F8: T-PAK | G8: PAK SUZUKI MOTOR CO LTD | H8: 1097432 | I8: 0710135 | J8: 2 | K8: 25.61 | L8: 0710135001 | M8: ABDUL HASEEB AHMED | N8: Lahore | O8: 35202-2877846-9 | P8: 03004236503 | Q8: 03004236503 | R8: 35860721 | S8: 34/B MOH MILITARY ACCOUNTS SOCIETY COLLEGE LAHORE | T8: 915000 | U8: 1830000 | V8: 2524/02640/00133/09/2021 | W8: 29-SEP-2022 | X8: 185135 | Y8: 10085125 | Z8: NEW | AB8: SUZUKI CULTUS VXL EURO II | AC8: 2021 | AD8: 31-JUL-2021 | AE8: 03-OCT-2021 | AF8: 03-Oct-2024 | AG8: OLALHR300071392 | AH8: 3 | AI8: ITECL | AJ8: 5480/09/2021 | AK8: 30-SEP-2021 | AM8: 2% | AN8: 0 | AO8: 0
A9: 8 | B9: CLOSED | C9: 9976AD1210300090 | D9: 6AD1 | E9: A | F9: T-PAK | G9: CHANGAN AL NOOR MOTORS | H9: 637252 | I9: 0669115 | J9: 2 | K9: 25.45 | L9: 0669115001 | M9: FARMAN IDREES | N9: Faisalabad | O9: 33100-0715241-7 | P9: 03017051197 | Q9: 03017051197, 03017051197 | R9: 03017051197 | S9: H NO P-791 ST NO 06 NEW GARDEN TOWN MILLAT ROAD FAISALABAD PK | T9: 1077300 | U9: 1539000 | V9: 2021-09-205-V01501DP0002198 | W9: 28-SEP-2022 | X9: 504293 | Y9: 1008681 | Z9: NEW | AB9: CHANGAN KARVAAN PLUS | AC9: 2021 | AD9: 30-JAN-2021 | AE9: 11-OCT-2021 | AF9: 11-Oct-2024 | AG9: OLAFSD300064649 | AH9: 3 | AI9: ITFM | AJ9: 5453/09/2021 | AK9: 29-SEP-2021 | AM9: 2% | AN9: 0 | AO9: 0
A10: 9 | B10: CLOSED | C10: 9976AD1211670013 | D10: 6AD1 | E10: A | F10: T-PAK | G10: PRINCE PUNJAB MOTORS | H10: 1097740 | I10: 0264812 | J10: 1.5 | K10: 25.56 | L10: 0264812002 | M10: MUKHTAR AHMAD | N10: Faisalabad | O10: 33100-8231808-5 | Q10: 03009661442 | R10: 0412600992 | S10: ALIYAAN FABRICS SHOP NO 27 NEAR ANAYAT CLOTH MARKET RAIL BAZAR FAISALABAD 03009661442 | T10: 3200300 | U10: 4610000 | V10: 55601/00081/09/2021 | W10: 27-SEP-2022 | X10: SFG15T-2101391 | Y10: PDF580PALR21H1791 | Z10: NEW | AB10: PRINCE GLORY 580 PRO | AC10: 2021 | AD10: 16-JUN-2021 | AE10: 03-OCT-2021 | AF10: 03-Oct-2024 | AG10: OLAFSD300069478 | AH10: 3 | AI10: CTRK | AJ10: DIB0031802 | AK10: 28-SEP-2021 | AM10: 1.5% | AN10: 0 | AO10: 0
A11: 10 | B11: CLOSED | C11: 9976AD2212420005 | D11: 6AD2 | E11: A | F11: T-PAK | G11: TOYOTA CENTRAL MOTORS | H11: 1105528 | I11: 0717785 | J11: 2 | K11: 26.2 | L11: 0717785001 | M11: KULSOOM RAUF | N11: Karachi | O11: 42201-6322286-6 | P11: 03212888320 | Q11: 03212888320 | R11: 02134328787 | S11: A- 15 KDA SCH 1 EXT PIR PAGARA HOUS E KARACHI PK | T11: 2954600 | U11: 7386500 | V11: 2021/09/CLFTTPCDP01050 | W11: 27-SEP-2022 | X11: 1GD5058617 | Y11: GUN126R-5548153 | Z11: NEW | AB11: TOYOTA HILUX REVO V DC | AC11: 2021 | AD11: 30-AUG-2021 | AE11: 03-OCT-2021 | AF11: 03-Oct-2024 | AG11: OLAKHI300072646 | AH11: 3 | AI11: CTRK | AJ11: DIB0031835 | AK11: 24-SEP-2021 | AM11: 2% | AN11: 0 | AO11: 0
A12: 11 | B12: CLOSED | C12: 9976AD2212120055 | D12: 6AD2 | E12: A | F12: T-PAK | G12: SUZUKI ISLAMABAD MOTORS | H12: 639476 | I12: 0534737 | J12: 2 | K12: 26.11 | L12: 0534737003 | M12: ZEESHAN AHMED | N12: Rawalpindi | O12: 37405-3410919-5 | P12: 03365251627 | R12: 0512801311 | S12: H # BII 265 ST # 09 MUSLIM TOWN RAWALPINDI | T12: 1324000 | U12: 1655000 | V12: 01-2109-PO-MTR-PCCM-D001335 | W12: 27-SEP-2022 | X12: 186242 | Y12: 10086241 | Z12: NEW | AB12: CULTUS VXR EURO-II | AC12: 2021 | AD12: 31-JUL-2021 | AE12: 11-OCT-2021 | AF12: 11-Oct-2024 | AG12: OLARWP300071598 | AH12: 3 | AI12: ITECL | AJ12: 5472/09/2021 | AK12: 28-SEP-2021 | AM12: 2% | AN12: 0 | AO12: 0
A13: 12 | B13: CLOSED | C13: 9976AP2192730005 | D13: 6AP2 | E13: A | F13: T-PAK | G13: SUZUKI MUZAFARABAD MOTOR | H13: 602999 | I13: 0561735 | J13: 2.5 | K13: 25.2 | L13: 0561735001 | M13: SHAHID IFTIKHAR | N13: Islamabad | O13: 61101-4610207-1 | P13: 03135257237 | R13: 0514100311 | S13: H # 86 MAIN STREET ISLAMABAD HOMES PHASE-2 JHANGI SYEDAN NEAR MOTORWAY ISLAMABAD PK | T13: 1003100 | U13: 1433000 | V13: 51132/00084/09/2019 | W13: 27-SEP-2020 | X13: 110794 | Y13: 1010754 | Z13: NEW | AA13: ANZ-539 | AB13: ALTO VXL AGS EURO-II | AC13: 2019 | AD13: 30-SEP-2019 | AE13: 03-OCT-2019 | AF13: 03-Oct-2024 | AG13: PODISD300049427 | AH13: 5 | AI13: ITFM | AJ13: 1796/09/2019/ITFM | AK13: 28-SEP-2019 | AM13: 2.5% | AN13: 0 | AO13: 0
A14: 13 | B14: CLOSED | C14: 9976AP1212720027 | D14: 6AP1 | E14: A | F14: T-PAK | G14: SHAHNAWAZ PVT LTD | H14: 1102777 | I14: 0198992 | J14: 2 | K14: 25.69 | L14: 0198992003 | M14: MIAN HUMAYUN HASSAN | N14: Karachi | O14: 42201-9223228-5 | Q14: 03212447500 | R14: 0412612045 | S14: K A ENTERPRISES PVT LTD OFFICE NO 206 2ND FLOOR GUL TOWER II CHUNDRIGAR ROAD KARACHI | T14: 6925000 | U14: 13850000 | V14: 55601/00103/09/2021 | W14: 26-SEP-2022 | X14: 282914-80-613133 | Y14: W1K-177187-25-311776 | Z14: NEW | AB14: MERCEDES CLA 200 | AC14: 2021 | AD14: 29-SEP-2021 | AE14: 03-OCT-2021 | AF14: 03-Oct-2024 | AG14: OLDKHI300074131 | AH14: 3 | AM14: 2% | AN14: 0 | AO14: 0
A15: 14 | B15: CLOSED | C15: 9976AD2212250017 | D15: 6AD2 | E15: A | F15: T-PAK | G15: TOYOTA SOUTHERN MOTORS | H15: 1108028 | I15: 0127265 | J15: 2 | K15: 26.06 | L15: 0127265020 | M15: MUHAMMAD ALI SHAHZADA | N15: Karachi | O15: 42201-5958122-7 | P15: 34523930 | Q15: 03008278770 | R15: 356670609 35662609 | S15: H# R-87 ST# 20 KHAYABAN-E-ROOMI PHASE-8 NEAR KHAYABAN-E-TARIQ KARACHI | T15: 2006250 | U15: 2675000 | V15: 2524/02640/00113/09/2021 | W15: 26-SEP-2022 | X15: 2A36510 | Y15: 7022861 | Z15: NEW | AB15: TOYOTA YARIS ATIV CVT 1.3 | AC15: 2021 | AD15: 13-AUG-2021 | AE15: 03-OCT-2021 | AF15: 03-Oct-2024 | AG15: OLAKHI300071930 | AH15: 3 | AI15: ITECL | AJ15: 5441/09/2021 | AK15: 16-SEP-2021 | AM15: 2% | AN15: 0 | AO15: 0
A16: 15 | B16: CLOSED | C16: 9976AD1211790005 | D16: 6AD1 | E16: A | F16: T-PAK | G16: PAK SUZUKI MOTOR CO LTD | H16: 638979 | I16: 0545421 | J16: 2 | K16: 25.55 | L16: 0545421002 | M16: MUHAMMAD ZEESHAN HAMEED | N16: Lahore | O16: 33303-3677318-3 | Q16: 03312328682 | S16: HOUSE NO 87 MAIN STREET, ARSLAN TOWN MULTAN, MULTAN.0331-2328682 MULTAN | T16: 1704000 | U16: 2130000 | V16: 2021-09-205-V015010P0002294 | W16: 26-SEP-2022 | X16: 183379 | Y16: 10083374 | Z16: NEW | AB16: SUZUKI CULTUS VXL | AC16: 2021 | AD16: 28-JUN-2021 | AE16: 03-OCT-2021 | AF16: 03-Oct-2024 | AG16: OLALHR300069975 | AH16: 3 | AI16: CTRK | AJ16: DIB0031892 | AK16: 28-SEP-2021 | AM16: 2% | AN16: 0 | AO16: 0
A17: 16 | B17: CLOSED | C17: 9976AD2192120019 | D17: 6AD2 | E17: A | F17: T-PAK | G17: KIA MOTORS CANAL ROAD | H17: 594274 | I17: 0185121 | J17: 2.5 | K17: 26.2 | L17: 0185121003 | M17: FARAN AHMED | N17: Faisalabad | O17: 33100-1356810-7 | P17: 0333-6633311 | Q17: 03336633311 | R17: 041-8547511 | S17: H NO P-101 1ST FLOOR SHADMAN COLONY PEOPLES COLONY NO 1 NEAR ABU BAKAR MASJID FAISALABAD | T17: 2999400 | U17: 4999000 | V17: 51132/00065/09/2019 | W17: 24-SEP-2020 | X17: KH025588 | Y17: KP500548 | Z17: NEW | AA17: APJ-811 | AB17: KIA SPORTAGE | AC17: 2019 | AD17: 31-JUL-2019 | AE17: 03-OCT-2019 | AF17: 03-Oct-2024 | AG17: POAFSD300048094 | AH17: 5 | AI17: ITFM | AM17: 2.5% | AN17: 0 | AO17: 0
A18: 17 | B18: CLOSED | C18: 9976AD1210700029 | D18: 6AD1 | E18: A | F18: T-PAK | G18: TOYOTA AIRPORT MOTOR | H18: 654464 | I18: 0678803 | J18: 2 | K18: 25.45 | L18: 0678803001 | M18: SHAHID ALI | N18: Lahore | O18: 35201-6724429-1 | P18: 03214269841 | Q18: 03214269841 | R18: 03214269841 | S18: STREET NO 18 DILSHAD STREET SHALAMA R TOWN LAHORE | T18: 2041800 | U18: 3403000 | V18: DIB/T/BT/33692/0921 | W18: 23-SEP-2022 | X18: Q080853 | Y18: 6058309 | Z18: NEW | AB18: TOYOTA COROLLA ALTIS A/T | AC18: 2021 | AD18: 11-MAR-2021 | AE18: 03-OCT-2021 | AF18: 03-Oct-2024 | AG18: OLALHR300066679 | AH18: 3 | AI18: CTRK | AJ18: TDIDIB0029647 | AK18: 24-SEP-2021 | AM18: 2% | AN18: 0 | AO18: 0
A19: 18 | B19: CLOSED | C19: 9976AD2212500002 | D19: 6AD2 | E19: A | F19: T-PAK | G19: HYUNDAI D GROUND MOTORS | H19: 1103498 | I19: 0339233 | J19: 2 | K19: 26.19 | L19: 0339233005 | M19: MUHAMMAD ATTIQUE UR REHMAN | N19: Faisalabad | O19: 33100-2350567-5 | P19: 0418717495 | Q19: 03217835276 | R19: 2647349 | S19: H NO P-488 STREET NO 6 SARFRAZ COLONY FAISALABAD | T19: 2927250 | U19: 3903000 | V19: 2021-09-205-V01501OP0002187 | W19: 22-SEP-2022 | X19: G4NAMU877378 | Y19: PMHD841FMMN301545 | Z19: NEW | AB19: HYUNDAI ELANTRA | AC19: 2021 | AD19: 07-SEP-2021 | AE19: 27-SEP-2021 | AF19: 27-Sep-2024 | AG19: OLAFSD300073136 | AH19: 3 | AI19: CTRK | AJ19: DIB0031766 | AK19: 23-SEP-2021 | AM19: 2% | AN19: 0 | AO19: 0
A20: 19 | B20: CLOSED | C20: 9976AD1211730019 | D20: 6AD1 | E20: A | F20: T-PAK | G20: PAK SUZUKI MOTOR CO LTD | H20: 1097822 | I20: 0701206 | J20: 2 | K20: 25.56 | L20: 0701206001 | M20: NAJMA BEGUM | N20: Faisalabad | O20: 33100-0660926-0 | P20: 03007623818 | Q20: 03007623818, 03007623818 | R20: 03007623818 | S20: P- 528 ST NO 10 NAIMAT COLONY 1 FAISALABAD PK | T20: 993000 | U20: 1655000 | V20: 2021/09/CLFTTPCDP01011 | W20: 22-SEP-2022 | X20: 184610 | Y20: 10084587 | Z20: NEW | AB20: SUZUKI CULTUS VXR EURO II | AC20: 2021 | AD20: 22-JUN-2021 | AE20: 03-OCT-2021 | AF20: 03-Oct-2024 | AG20: OLAFSD300069682 | AH20: 3 | AI20: CTRK | AJ20: DIB0031656 | AK20: 23-SEP-2021 | AM20: 2% | AN20: 0 | AO20: 0
A21: 20 | B21: CLOSED | C21: 9976AP1232690003 | D21: 6AP1 | E21: A | F21: T-PAK | G21: MASTER MOTORS | H21: 23208170408861 | I21: 0618569 | J21: 1.4 | K21: 22.69 | L21: 0618569005 | M21: MOHAMMAD QASIM FAROOQI | N21: Lahore | O21: 61101-9156805-3 | P21: 03354552446 | Q21: 00971502319295 | R21: 0 | S21: VILLA 57 STREET 6C AL SATWA DUBAI UNITED ARAB EMIRATES | T21: 3720000 | U21: 4960000 | V21: 74853/00026/09/2023 | W21: 21-SEP-2024 | X21: 1016642 | Y21: 116646 | Z21: RDA | AB21: SUZUKI SWIFT GLX | AC21: 2023 | AD21: 45195 | AE21: 27-SEP-2023 | AF21: 27-Sep-2024 | AG21: OLDLHR300097243 | AH21: 1 | AI21: CTRK | AJ21: DIB0035322 | AK21: 25-SEP-2023 | AM21: 1.4% | AN21: 0 | AO21: 0
A22: 21 | B22: CLOSED | C22: 9976AD1211380004 | D22: 6AD1 | E22: A | F22: T-PAK | G22: KIA MOTORS MARSHALS | H22: 526643 | I22: 0688678 | J22: 1.75 | K22: 26.21 | L22: 0688678001 | M22: FIDA MUHAMMAD | N22: Islamabad | O22: 17301-1523055-9 | P22: 0512728354 | R22: 03429090337 | S22: UNDP (IFAD) LEVEL II SERENA BUSINES S COMPLEX SECTOR G-5 ISLAMABAD | T22: 4074750 | U22: 5433000 | V22: 2021/09/CLFTTPCDPO1029 | W22: 21-SEP-2022 | X22: 314372 | Y22: 512829 | Z22: NEW | AB22: SPORTAGE AWD | AC22: 2021 | AD22: 18-MAY-2021 | AE22: 03-OCT-2021 | AF22: 03-Oct-2024 | AG22: OLAISD300068749 | AH22: 3 | AM22: 1.75% | AN22: 0 | AO22: 0
A23: 22 | B23: CLOSED | C23: 9976AD1212560018 | D23: 6AD1 | E23: A | F23: T-PAK | G23: HYUNDAI D GROUND MOTORS | H23: 1100503 | I23: 0547484 | J23: 2 | K23: 25.68 | L23: 0547484003 | M23: NUMAN AFZAL | N23: Faisalabad | O23: 33102-1783712-5 | P23: 03018661999 | Q23: 03018661999, 03018661999 | R23: 0418724999 | S23: P-136-B LIAQUAT TOWN JHANG ROAD FS D FAISALABAD PK | T23: 1949500 | U23: 3899000 | V23: 2021-09-205-V01501OP0002195 | W23: 21-SEP-2022 | X23: G4NAM877342 | Y23: PMHD841FMMN301680 | Z23: NEW | AB23: HYUNDAI ELANTRA | AC23: 2021 | AD23: 13-SEP-2021 | AE23: 27-SEP-2021 | AF23: 27-Sep-2024 | AG23: OLAFSD300073444 | AH23: 3 | AI23: CTRK | AJ23: DIB0031790 | AK23: 22-SEP-2021 | AM23: 2% | AN23: 0 | AO23: 0
A24: 23 | B24: CLOSED | C24: 9976AD2212090010 | D24: 6AD2 | E24: A | F24: T-PAK | G24: SUZUKI RACECOURSE MOTORS | H24: 635669 | I24: 0704288 | J24: 2 | K24: 26.06 | L24: 0704288001 | M24: AAMER SHAHZAD | N24: Rawalpindi | O24: 13302-4178537-5 | P24: 03146262797 | R24: 0512724178 | S24: FLAT # 6 4TH FLOOR PLAZA # 14 CIVI C CENTRE BAHRIA TOWN PHASE 4 RAWALPINDI PK | T24: 1464000 | U24: 1830000 | V24: PL-0921-1101010102-V14-D-00435 | W24: 21-SEP-2022 | X24: 185155 | Y24: 10085145 | Z24: NEW | AB24: CULTUS VXL EURO-II | AC24: 2021 | AD24: 28-JUL-2021 | AE24: 03-OCT-2021 | AF24: 03-Oct-2024 | AG24: OLARWP300071014 | AH24: 3 | AI24: CTRK | AJ24: DIB0031789 | AK24: 23-SEP-2021 | AM24: 2% | AN24: 0 | AO24: 0
A25: 24 | B25: CLOSED | C25: 9976AP1172690005 | D25: 6AP1 | E25: A | F25: T-PAK | G25: NEW CAR COMPLEX | H25: 403169 | I25: 0421008 | J25: 3.2 | K25: 27.69 | L25: 0421008002 | M25: SAJJAD HAIDER | N25: Karachi | O25: 42201-0702394-3 | Q25: 03002115346 | S25: FLAT NO E01, GROUND FLOOR SAIMA HEAVEN , GULSHAN E IQBAL BLOCK 4 KARACHI PK | T25: 855000 | U25: 1140000 | V25: DIB/T/17887/KHI/0917 | W25: 21-SEP-2018 | X25: 13019609 | Y25: 10019608 | Z25: USD | AA25: AZR-987 | AB25: SWIFT DLX ABS WITH EBD | AC25: 2013 | AD25: 26-SEP-2017 | AE25: 27-SEP-2017 | AF25: 27-Sep-2024 | AG25: POUKHI300025782 | AH25: 7 | AI25: FLCN | AJ25: 13250/09/2017 | AK25: 23-SEP-2017 | AM25: 3.2% | AN25: 0 | AO25: 0
A26: 25 | B26: CLOSED | C26: 9976AP1222640006 | D26: 6AP1 | E26: A | F26: T-PAK | G26: FAROOQ MOTORS | H26: 1150447 | I26: 0295543 | J26: 1.75 | K26: 25.19 | L26: 0295543003 | M26: MUZAMAL ALI | N26: Lahore | O26: 35202-1486167-9 | Q26: 03204496693 | R26: 04235774125 | S26: H NO.190/D-2 GULSHAN E RAVI NEAR LAHORE PUBLIC SCHOOL LAHORE | T26: 1470000 | U26: 2100000 | V26: 63286/00047/09/2022 | W26: 20-SEP-2023 | X26: 6R210377 | Y26: 1110453 | Z26: USD | AA26: AJA-183 | AB26: SUZUKI ALTO VXL AGS EURO-II | AC26: 2022 | AD26: 21-SEP-2022 | AE26: 21-SEP-2022 | AF26: 21-Sep-2024 | AG26: OLULHR300089914 | AH26: 2 | AI26: ITFM | AJ26: 8712/09/2022/ITFM | AK26: 21-SEP-2022 | AM26: 1.75% | AN26: 0 | AO26: 0
A27: 26 | B27: CLOSED | C27: 9976AP2192660005 | D27: 6AP2 | E27: A | F27: T-PAK | G27: NEW S.S MOTORS | H27: 591073 | I27: 0560406 | J27: 2.5 | K27: 29.44 | L27: 0560406001 | M27: KHURAM ZIA | N27: Faisalabad | O27: 33100-6507523-5 | P27: 03216611003 | Q27: 03216611003, 03216611003 | R27: 0419200183 | S27: P-70 ST NO 01 EAST CANAL ROAD RAZA TOWN FSD FAISALABAD PK | T27: 1820000 | U27: 2600000 | V27: 51132/00045/09/2019 | W27: 20-SEP-2020 | X27: 1NZ-7995674 | Y27: NHP10-2558682 | Z27: RCN | AA27: APG-630 | AB27: AQUA | AC27: 2016 | AD27: 23-SEP-2019 | AE27: 21-SEP-2019 | AF27: 21-Sep-2024 | AG27: POUFSD300049274 | AH27: 5 | AI27: CTRK | AJ27: DIB0027845 | AK27: 21-SEP-2019 | AM27: 2.5% | AN27: 0 | AO27: 0
A28: 27 | B28: CLOSED | C28: 9976AP1222650011 | D28: 6AP1 | E28: A | F28: T-PAK | G28: NEW CAR COMPLEX | H28: 1197710 | I28: 0801675 | J28: 1.5 | K28: 26.19 | L28: 0801675001 | M28: ASIM MIRZA | N28: Karachi | O28: 42301-0262971-9 | P28: 03133803682 | Q28: 03133803682 | R28: 0 | S28: 402 FLAT 04 FLOOR CITY VIEW APPARTM ENT SADDAR KHI NEAR NMI HOSPITAL KARACHI PK | T28: 2968000 | U28: 5600000 | V28: 63286/00045/09/2022 | W28: 19-SEP-2023 | X28: 312210 | Y28: 302280 | Z28: USD | AA28: BH-6588 | AB28: KIA SPORTAGE FWD | AC28: 2020 | AD28: 22-SEP-2022 | AE28: 27-SEP-2022 | AF28: 27-Sep-2024 | AG28: OLUKHI300089980 | AH28: 2 | AI28: ITFM | AJ28: 8720/09/2022/ITFM | AK28: 21-SEP-2022 | AM28: 1.5% | AN28: 0 | AO28: 0
A29: 28 | B29: CLOSED | C29: 9976AD1210460011 | D29: 6AD1 | E29: A | F29: T-PAK | G29: JW SEZ (PVT) LTD | H29: 627518 | I29: 0671787 | J29: 1.75 | K29: 25.94 | L29: 0671787001 | M29: IMRAN SAJID | N29: Gujranwala | O29: 34101-6864800-1 | P29: 03228624200 | Q29: 03228624200 | R29: 03228624200 | S29: NEAR 132 KV GRID STATION CHANWALI G T ROAD GUJRANWALA | T29: 3814300 | U29: 5449000 | V29: 17578/00039/09/2021 | W29: 19-SEP-2022 | X29: 5MGM5180052 | Y29: MN093965 | Z29: NEW | AB29: MG HS TURBO | AC29: 2021 | AD29: 15-FEB-2021 | AE29: 27-SEP-2021 | AF29: 27-Sep-2024 | AG29: OLAGWL300065808 | AH29: 3 | AI29: CTRK | AJ29: TDIDIB0029545 | AK29: 28-AUG-2021 | AM29: 1.75% | AN29: 0 | AO29: 0
A30: 29 | B30: CLOSED | C30: 9976AD1210760016 | D30: 6AD1 | E30: A | F30: T-PAK | G30: JW SEZ (PVT) LTD | H30: 627595 | I30: 0680554 | J30: 1.75 | K30: 25.94 | L30: 0680554001 | M30: REHMAN UL HAQ | N30: Gujrat | O30: 34201-1842388-7 | P30: 03040554133 | Q30: 03040554133 | R30: 03040554133 | S30: OPP. ANMOL MARRIAGE HALL GT ROAD GUJRAT | T30: 3432870 | U30: 5449000 | V30: DIB/T/BT/33669/FSD/0921 | W30: 19-SEP-2022 | X30: MSM3080220 | Y30: LSJA24U93MN060005 | Z30: NEW | AB30: MG HS TURBO | AC30: 2021 | AD30: 17-MAR-2021 | AE30: 21-SEP-2021 | AF30: 21-Sep-2024 | AG30: OLAGJR300066793 | AH30: 3 | AI30: CTRK | AJ30: TDIDIB0029567 | AK30: 26-AUG-2021 | AM30: 1.75% | AN30: 0 | AO30: 0
A31: 30 | B31: CLOSED | C31: 9976AP2192660006 | D31: 6AP2 | E31: A | F31: T-PAK | G31: CAR CAPITAL | H31: 532106 | I31: 0559435 | J31: 2.5 | K31: 29.19 | L31: 0559435001 | M31: NAZISH FATIMA | N31: Karachi | O31: 42101-2290780-6 | P31: 03332301275 | Q31: 03332301275 | R31: 037130068 | S31: H.NO 148 BANGLOW TOWN TIPU SULTAN R OAD KCHS NEAR MACCA MASJID KARACHI PK | T31: 1200000 | U31: 1500000 | V31: 51132/00037/09/2019 | W31: 18-SEP-2020 | X31: 7423533 | Y31: 160728 | Z31: USD | AA31: BCX-524 | AB31: HONDA CITY M/T | AC31: 2015 | AD31: 23-SEP-2019 | AE31: 21-SEP-2019 | AF31: 21-Sep-2024 | AG31: POUKHI300049222 | AH31: 5 | AI31: ITFM | AJ31: 1765/09/2019/ITFM | AK31: 20-SEP-2019 | AM31: 2.5% | AN31: 0 | AO31: 0
A32: 31 | B32: CLOSED | C32: 9976AP1192660011 | D32: 6AP1 | E32: A | F32: T-PAK | G32: MINI MOTORS | H32: 589261 | I32: 0560108 | J32: 2.5 | K32: 25.19 | L32: 0560108001 | M32: MUHAMMAD ADREES | N32: Lahore | O32: 35202-8119531-3 | P32: 03127241094 | Q32: 03024719541, 03127241094 | R32: 03127241094 | S32: 47 MIAN BAZAR GAWALMANDI LAHORE | T32: 1137500 | U32: 1625000 | V32: 51132/00038/09/2019 | W32: 18-SEP-2020 | X32: 200197 | Y32: 10100189 | Z32: NEW | AA32: LE-19A-4552 | AB32: SUZUKI WAGONR VXL | AC32: 2019 | AD32: 23-SEP-2019 | AE32: 21-SEP-2019 | AF32: 21-Sep-2024 | AG32: PODLHR300049226 | AH32: 5 | AI32: CTRK | AJ32: DIB0027837 | AK32: 19-SEP-2019 | AM32: 2.5% | AN32: 0 | AO32: 0
A33: 32 | B33: CLOSED | C33: 9976AD2171180004 | D33: 6AD2 | E33: A | F33: T-PAK | G33: PAK SUZUKI MOTOR CO LTD | H33: 326088 | I33: 0405406 | J33: 3.1 | K33: 24.03 | L33: 0405406001 | M33: ATIF IQBAL | N33: Karachi | O33: 42201-0495130-1 | P33: N/A | Q33: 03405558394 | R33: 04685383 | S33: H#A39 1ST FLOOR GULSHAN E FATIMA KEHKASHAN SOCIETY MALIR HALT NEAR BISMILLAH BAKERY AFZAL HOTEL KARACHI | T33: 790500 | U33: 1054000 | V33: DIB/T/17847/KHI/0917 | W33: 18-SEP-2018 | X33: 139186 | Y33: 10039177 | Z33: NEW | AA33: BKJ-413 | AB33: WAGONR VXR | AC33: 2017 | AD33: 28-APR-2017 | AE33: 27-SEP-2017 | AF33: 27-Sep-2024 | AG33: POAKHI300021482 | AH33: 7 | AI33: CTRK | AJ33: TDIDIB0021047 | AK33: 11-SEP-2017 | AM33: 3.1% | AN33: 0 | AO33: 0
A34: 33 | B34: CLOSED | C34: 9976AP1212700025 | D34: 6AP1 | E34: A | F34: T-PAK | G34: FAROOQ MOTORS | H34: 1104880 | I34: 0719635 | J34: 2 | K34: 25.54 | L34: 0719635001 | M34: ADNAN SHAHZAD | N34: Lahore | O34: 35202-8493779-1 | P34: 03334286567 | Q34: 03334286567 | R34: 03334286567 | S34: KABIR STREET NO 2 URDU BAZAR LAHORE | T34: 1516500 | U34: 3033000 | V34: 55601/00062/09/2021 | W34: 16-SEP-2022 | X34: 2A30426 | Y34: NSP151R-9511635 | Z34: NEW | AB34: YARIS ATIV X CVT 1.5 | AC34: 2021 | AD34: 27-SEP-2021 | AE34: 27-SEP-2021 | AF34: 27-Sep-2024 | AG34: OLDLHR300073646 | AH34: 3 | AI34: CTRK | AJ34: DIB0031741 | AK34: 20-SEP-2021 | AM34: 2% | AN34: 0 | AO34: 0
A35: 34 | B35: CLOSED | C35: 9976AD1211970005 | D35: 6AD1 | E35: A | F35: T-PAK | G35: PAK SUZUKI MOTOR CO LTD | H35: 1098924 | I35: 0431603 | J35: 2 | K35: 25.6 | L35: 0431603003 | M35: MUHAMMAD IRFAN | N35: Faisalabad | O35: 33100-6988210-3 | P35: 03217843232 | Q35: 03217843232 | R35: 03217843232 | S35: P-28 BLOCK X ST NO 12 MADINA TOWN M USTFAI MASJID FAISALABAD PK | T35: 1372500 | U35: 1830000 | V35: DIB/T/BT/33652/LHR/0921 | W35: 15-SEP-2022 | X35: 185102 | Y35: 10085105 | Z35: NEW | AB35: SUZUKI CULTUS VXL EURO-II | AC35: 2021 | AD35: 16-JUL-2021 | AE35: 27-SEP-2021 | AF35: 27-Sep-2024 | AG35: OLAFSD300070802 | AH35: 3 | AI35: CTRK | AJ35: DIB0031709 | AK35: 16-SEP-2021 | AM35: 2% | AN35: 0 | AO35: 0
A36: 35 | B36: CLOSED | C36: 9976AD1211790003 | D36: 6AD1 | E36: A | F36: T-PAK | G36: KIA CLIFTON | H36: 575336 | I36: 0703739 | J36: 1.75 | K36: 25.94 | L36: 0703739001 | M36: KHURRAM | N36: Karachi | O36: 42301-0987315-5 | P36: 03222383101 | Q36: 03222383101 | R36: 0 | S36: MADINA HEIGHTS DHELI COLONY FLAT # 104 GALI # zero line clifotn near a KARACHI PK | T36: 3509350 | U36: 5399000 | V36: 2524/02640/00062/09/2021 | W36: 15-SEP-2022 | X36: G4NAMH313747 | Y36: NNAQL51AZKP513013 | Z36: NEW | AB36: KIA SPORTGE | AC36: 2021 | AD36: 28-JUN-2021 | AE36: 21-SEP-2021 | AF36: 21-Sep-2024 | AG36: OLAKHI300070009 | AH36: 3 | AM36: 1.75% | AN36: 0 | AO36: 0
A37: 36 | B37: CLOSED | C37: 9976AP1212650005 | D37: 6AP1 | E37: A | F37: T-PAK | G37: MUAZ MOTORS | H37: 1107932 | I37: 0720281 | J37: 1.75 | K37: 25.54 | L37: 0720281001 | M37: SHABNAM NIAZ | N37: Lahore | O37: 35202-2583875-4 | P37: 03344113234 | Q37: 03344113234 | R37: 03344113234 | S37: LAHORE COLLEGE FOR WOMEN UNIVERSITY JAIL ROAD LAHORE | T37: 1305500 | U37: 1865000 | V37: 55601/00056/09/2021 | W37: 15-SEP-2022 | X37: R06A-1857217 | Y37: DA17V-808397 | Z37: RCN | AB37: SUZUKI EVERY | AC37: 2016 | AD37: 22-SEP-2021 | AE37: 21-SEP-2021 | AF37: 21-Sep-2024 | AG37: OLULHR300073634 | AH37: 3 | AI37: CTRK | AJ37: DIB0031725 | AK37: 17-SEP-2021 | AM37: 1.75% | AN37: 0 | AO37: 0
A38: 37 | B38: CLOSED | C38: 9976AD1211120026 | D38: 6AD1 | E38: A | F38: T-PAK | G38: PRINCE PUNJAB MOTORS | H38: 643102 | I38: 0622692 | J38: 2 | K38: 25.45 | L38: 0622692003 | M38: MUHAMMAD SHAKIR | N38: Faisalabad | O38: 33100-0897584-5 | P38: 03007654806 | Q38: 03007654806, 03007654806 | R38: 2652220 | S38: H NO266 ST NO 14 AYUB COLONY JHANG ROAD FSD NEAR FAISAL BAKERY Faisalabad PK | T38: 712725 | U38: 1096500 | V38: 55601/00029/09/2021 | W38: 15-SEP-2022 | X38: M04603857W | Y38: RAILPPM21G02736 | Z38: NEW | AB38: PRINCE PEARL | AC38: 2021 | AD38: 22-APR-2021 | AE38: 03-OCT-2021 | AF38: 03-Oct-2024 | AG38: OLAFSD300068015 | AH38: 3 | AI38: CTRK | AJ38: DIB0031637 | AK38: 16-SEP-2021 | AM38: 2% | AN38: 0 | AO38: 0
A39: 38 | B39: CLOSED | C39: 9976AD1211960006 | D39: 6AD1 | E39: A | F39: T-PAK | G39: PAK SUZUKI MOTOR CO LTD | H39: 1098985 | I39: 0472807 | J39: 2 | K39: 25.55 | L39: 0472807004 | M39: MUHAMMAD TARIQ | N39: Faisalabad | O39: 90403-0108361-7 | P39: 03007204256 | Q39: 03007204256, 03007204256, 03411076986 | R39: 03007204256 | S39: 975-C QASIM PARK PEOPLES COLONY NO2 FAISALABAD | T39: 1555500 | U39: 1830000 | V39: 2021/09/CLFTTPCDP01002 | W39: 14-SEP-2022 | X39: 183231 | Y39: 10083200 | Z39: NEW | AB39: CULTUS VXL EURO II | AC39: 2021 | AD39: 15-JUL-2021 | AE39: 27-SEP-2021 | AF39: 27-Sep-2024 | AG39: OLAFSD300070688 | AH39: 3 | AI39: CTRK | AJ39: DIB0031629 | AK39: 15-SEP-2021 | AM39: 2% | AN39: 0 | AO39: 0
A40: 39 | B40: CLOSED | C40: 9976AD2212430057 | D40: 6AD2 | E40: A | F40: T-PAK | G40: PAK SUZUKI MOTOR CO LTD | H40: 6277755 | I40: 0718426 | J40: 2 | K40: 26.2 | L40: 0718426001 | M40: BILAL IQBAL | N40: Bahawalpur | O40: 31202-4467991-1 | P40: 03123456735 | Q40: 03123456735 | R40: 03123456735 | S40: H NO 269 BHATTA NO 01 GULBERG ROAD BAHAWALPUR PK | T40: 801000 | U40: 1335000 | V40: 2021-09-CLFTTPCDP01013 | W40: 13-SEP-2022 | X40: 6R183003 | Y40: H1082988 | Z40: NEW | AB40: SUZUKI ALTO VXR EURO II | AC40: 2021 | AD40: 31-AUG-2021 | AE40: 03-OCT-2021 | AF40: 03-Oct-2024 | AG40: OLABHP300072888 | AH40: 3 | AI40: ITECL | AJ40: 5430/09/2021 | AK40: 14-SEP-2021 | AM40: 2% | AN40: 0 | AO40: 0
...

Sheet Sheet1
AO1: =SUBTOTAL(9,AO3:AO325) -> 14988194
A2: Sr. | B2: Status | C2: Contract No. | D2: Class Code | E2: Contract Status | F2: Insurance Agency | G2: Dealer Name | H2: App ID | I2: CIF # | J2: Insurance Rate | K2: Profit Rate | L2: ISI Account No. | M2: Customer Name | N2: City | O2: CNIC No. | P2: Home Phone# | Q2: Mobile Number | R2: Business Phone# | S2: Mail Address | T2: Finance Amount | U2: Car Price | V2: Ins. Policy | W2: Ins. Expiry Date | X2: Engine No. | Y2: Chassis No. | Z2: Car Category | AA2: Reg. No. | AB2: Car Name | AC2: Model | AD2: Contract Booking Date | AE2: Contract Value Date | AF2: Contract Maturity Date | AG2: Purchase Order No. | AH2: Tenor#2 | AI2: Tracker Company | AJ2: Tracker Reference Number | AK2: Tracker Installation Date | AL2: Contract No.2 | AM2: Rate | AN2: Sum Insured | AO2: Premium | AP2: OLD Contract Ref | AQ2: Remarks-I | AR2: Remarks-II | AS2: Policy # | AT2: End. # | AU2: Tms prem | AV2: Difference | AW2: Tagging | AX2: End. Amount | AY2: End. Difference
A3: 1 | B3: NORM | C3: 9976AD1211510031 | D3: 6AD1 | E3: A | F3: T-PAK | G3: PAK SUZUKI MOTOR CO LTD | H3: 649576 | I3: 0695379 | J3: 2 | K3: 25.79 | L3: 0695379001 | M3: MARYAM SIDDIQA | N3: Rahim Yar Khan | O3: 31303-5638787-8 | P3: 03342844446 | Q3: 03342844446 | R3: 03342844446 | S3: HOUSE NO 120-D SCHEME 03 BLOCK Y GU LSHAN IQBAL COLONY RAHIM YAR KHAN PK | T3: 801000 | U3: 1335000 | V3: DIB/T/BT/33330/LHR/0921 | W3: 01-SEP-2022 | X3: 180368 | Y3: 1080364 | Z3: NEW | AB3: ALTO VXR EURO-II | AC3: 2021 | AD3: 31-MAY-2021 | AE3: 03-OCT-2021 | AF3: 03-Oct-2028 | AG3: OLARYK300069033 | AH3: 7 | AI3: FLCN | AJ3: 108568/09/2021 | AK3: 02-SEP-2021 | AM3: 2% | AN3: 1068000 | AO3: 21360 | AS3: KHI/HO/D/MO/PC COMP/C/97805/1/09/2024 | AU3: 21360 | AV3: 0 | AW3: REN
A4: 2 | B4: NORM | C4: 997AAD1202090003 | D4: AAD1 | E4: A | F4: T-PAK | G4: HONDA CHENAB-GREEN VIEW MOTORS | H4: 593276 | I4: 0621607 | J4: 2 | K4: 20.8 | L4: 0621607001 | M4: MUHAMMAD LATIF | N4: SHEIKUPURA | O4: 34103-0458295-1 | P4: 03008893133 | Q4: 03138893133, 03008893133 | R4: 03008893133 | S4: GALI LATIF DOGAR WALI GUJRAWANWALA ROAD MOHALLAH ATA ABAD NEAR SHISH M SHEIKHUPURA PK | T4: 1916000 | U4: 2395000 | V4: DIB/T/BT/28482/LHR/0920 | W4: 01-SEP-2021 | X4: L13Z17540161 | Y4: NFBGM1544LR262747 | Z4: NEW | AB4: CITY IVTEC M/T | AC4: 2020 | AD4: 27-JUL-2020 | AE4: 11-SEP-2020 | AF4: 11-Sep-2025 | AG4: POASHK300055899 | AH4: 5 | AI4: ITFM | AJ4: 09/2020/ITFM | AK4: 02-SEP-2020 | AM4: 2% | AN4: 1796250 | AO4: 35925 | AS4: KHI/HO/D/MO/PC COMP/C/97805/2/09/2024 | AT4: KHI/HO/D/MO/PC COMP/E/47950/00002/10/2024 | AU4: 40715 | AV4: -4790 | AW4: REN | AX4: -4790 | AY4: 0
A5: 3 | B5: NORM | C5: 9976AD1211680026 | D5: 6AD1 | E5: A | F5: T-PAK | G5: KIA MOTORS TOWNSHIP | H5: 633467 | I5: 0699405 | J5: 2 | K5: 25.79 | L5: 0699405001 | M5: SHAHID IQBAL | N5: Sialkot | O5: 34603-6763335-7 | P5: 03026486200 | Q5: 03026486200 | R5: 03326486200 | S5: NEAR OPPOSITE CHINA HOTEL B-BLOCK C ITY HOUSING SOCIETY SIALKOT | T5: 2880800 | U5: 4432000 | V5: UWT/D/P002/0000000984/0921/109 | W5: 01-SEP-2022 | X5: 312732 | Y5: 101956 | Z5: NEW | AB5: SPORTGE ALPHA | AC5: 2021 | AD5: 17-JUN-2021 | AE5: 27-SEP-2021 | AF5: 27-Sep-2026 | AG5: OLASKT300069462 | AH5: 5 | AM5: 2% | AN5: 3545600 | AO5: 70912 | AS5: KHI/HO/D/MO/PC COMP/C/97805/3/09/2024 | AU5: 70912 | AV5: 0 | AW5: REN
A6: 4 | B6: NORM | C6: 9976AD1211670015 | D6: 6AD1 | E6: A | F6: T-PAK | G6: KIA MOTORS TOWNSHIP | H6: 526980 | I6: 0698981 | J6: 2 | K6: 26.29 | L6: 0698981001 | M6: MUHAMMAD SALEEM | N6: Sialkot | O6: 34603-0385945-5 | P6: 03456861572 | Q6: 03456861572 | R6: 05235422700 | S6: ANJOTAR HUNDAL ROAD NEAR GOVT HIGH SCHOOL SIALKOT | T6: 3102400 | U6: 4432000 | V6: UWT/D/T002/0000001040/0921/109-0 | W6: 01-SEP-2022 | X6: 314208 | Y6: 102175 | Z6: NEW | AB6: KIA SPORTAGE ALPHA | AC6: 2021 | AD6: 16-JUN-2021 | AE6: 21-SEP-2021 | AF6: 21-Sep-2026 | AG6: OLDSKT300069423 | AH6: 5 | AM6: 2% | AN6: 3545600 | AO6: 70912 | AS6: KHI/HO/D/MO/PC COMP/C/97805/4/09/2024 | AU6: 70912 | AV6: 0 | AW6: REN
A7: 5 | B7: NORM | C7: 997AAD1201740007 | D7: AAD1 | E7: A | F7: T-PAK | G7: KIA MOTORS MUREE ROAD | H7: 581825 | I7: 0614893 | J7: 1.5 | K7: 20.8 | L7: 0614893001 | M7: MIAN MUHAMMAD USMAN | N7: Rawalpindi | O7: 37405-9191077-3 | P7: 03325001991 | Q7: 03325001991 | R7: 0518449997 | S7: H # 341 ST # 37 UMER BLOCK BAHRIA T OWN PHASE-8 RAWALPINDI PK | T7: 3995260 | U7: 5399000 | V7: DIB/T/BT/28484/ISB/0920 | W7: 01-SEP-2021 | X7: G4NALH310866 | Y7: NNAQL51AZKP504398 | Z7: NEW | AB7: KIA SPORTAGE AWD | AC7: 2020 | AD7: 22-JUN-2020 | AE7: 11-SEP-2020 | AF7: 11-Sep-2025 | AG7: POARWP300054451 | AH7: 5 | AM7: 1.5% | AN7: 4049250 | AO7: 60738.75 | AS7: KHI/HO/D/MO/PC COMP/C/97805/5/09/2024 | AT7: KHI/HO/D/MO/PC COMP/E/47950/00005/10/2024 | AU7: 68837 | AV7: -8098.25 | AW7: REN | AX7: -8099 | AY7: 0.75
A8: 6 | B8: NORM | C8: 9976AD2210880002 | D8: 6AD2 | E8: A | F8: T-PAK | G8: TOYOTA AIRPORT MOTOR | H8: 599353 | I8: 0059143 | J8: 1.75 | K8: 26.18 | L8: 0059143008 | M8: RAZA ISHAQ BABAR | N8: Lahore | O8: 35201-1236948-3 | Q8: 03217736777 | R8: 37309855 | S8: HOUSE NO 41 FF BLOCK DHA PHASE 04 LAHORE | T8: 4953200 | U8: 7076000 | V8: DIB/T/BT/3327/LHR/0921 | W8: 01-SEP-2022 | X8: 2GD5028612 | Y8: GUN126R-5547602 | Z8: NEW | AB8: TOYOTA HILUX REVO V DC A/T 4X4 | AC8: 2021 | AD8: 29-MAR-2021 | AE8: 21-SEP-2021 | AF8: 21-Sep-2026 | AG8: OLALHR300067061 | AH8: 5 | AI8: CTRK | AJ8: TDIDIB0029595 | AK8: 02-SEP-2021 | AM8: 1.75% | AN8: 5660800 | AO8: 99064 | AS8: KHI/HO/D/MO/PC COMP/C/97805/7/09/2024 | AU8: 99064 | AV8: 0 | AW8: REN
A9: 7 | B9: NORM | C9: 9976AD2211810008 | D9: 6AD2 | E9: A | F9: T-PAK | G9: TOYOTA RAWAL MOTORS | H9: 579222 | I9: 0697627 | J9: 2 | K9: 22.47 | L9: 0697627002 | M9: BIBI SALMA ZAHID NAQVI | N9: Haripur | O9: 13302-5232838-2 | Q9: 03305849914 | S9: W/O ZAHID UL HASSAN ST # 7 H # 13 TIP HOUSING COLONY HRP CITY TEHSIL & DIST. HARIPUR PAKISTAN | T9: 2102250 | U9: 2803000 | V9: UWT/D/T002/0000001039/0921/109-0 | W9: 01-SEP-2022 | X9: 2A34671 | Y9: 150R-7021678 | Z9: NEW | AB9: YARIS ATIV CVT 1.3 | AC9: 2021 | AD9: 30-JUN-2021 | AE9: 11-SEP-2021 | AF9: 11-Sep-2026 | AG9: OLAHRP300070037 | AH9: 5 | AI9: ITECL | AJ9: 5404/09/2021 | AK9: 02-SEP-2021 | AM9: 2% | AN9: 2242400 | AO9: 44848 | AS9: KHI/HO/D/MO/PC COMP/C/97805/8/09/2024 | AU9: 44848 | AV9: 0 | AW9: REN
A10: 8 | B10: NORM | C10: 9976AD1222340001 | D10: 6AD1 | E10: A | F10: T-PAK | G10: KIA MACCA MOTORS | H10: 1204280 | I10: 0388812 | J10: 2 | K10: 26.69 | L10: 0388812006 | M10: FARHAN AHMED | N10: Karachi | O10: 42101-1940633-7 | Q10: 03368518786 | S10: HOUSE NO D49/1 BLOCK 6 F.B.AREA KARACHI NEAR BY RANGERS HEADQUARTERS | T10: 1820000 | U10: 2600000 | V10: 63286/00002/09/2022 | W10: 01-SEP-2023 | X10: 030853 | Y10: 504085 | Z10: NEW | AB10: KIA PICANTO 1.0 L MT | AC10: 2022 | AD10: 22-AUG-2022 | AE10: 21-SEP-2022 | AF10: 21-Sep-2025 | AG10: OLAKHI300089389 | AH10: 3 | AI10: ITFM | AJ10: 8454/08/2022/ITFM | AK10: 26-AUG-2022 | AM10: 2% | AN10: 2210000 | AO10: 44200 | AS10: KHI/HO/D/MO/PC COMP/C/97805/9/09/2024 | AU10: 44200 | AV10: 0 | AW10: REN
A11: 9 | B11: NORM | C11: 9976AD1211660012 | D11: 6AD1 | E11: A | F11: T-PAK | G11: SUZUKI MINI MOTORS | H11: 1104677 | I11: 0693673 | J11: 2 | K11: 25.79 | L11: 0693673001 | M11: SALMAN AMJAD | N11: Lahore | O11: 35202-4109105-3 | P11: 03333333626 | Q11: 03333333626 | R11: 03333333626 | S11: ISLAMIC HOUSE 99-A TRICON VILLAGE LAHORE | T11: 1146400 | U11: 1433000 | V11: 2524/02640/00010/09/2021 | W11: 02-SEP-2022 | X11: 6R181159 | Y11: NF1AET306H1081166 | Z11: NEW | AB11: SUZUKI ALTO VXR EURO | AC11: 2021 | AD11: 15-JUN-2021 | AE11: 21-SEP-2021 | AF11: 21-Sep-2026 | AG11: OLALHR300069461 | AH11: 5 | AI11: ITECL | AJ11: 5409/09/2021 | AK11: 03-SEP-2021 | AM11: 2% | AN11: 1146400 | AO11: 22928 | AS11: KHI/HO/D/MO/PC COMP/C/97805/13/09/2024 | AU11: 22928 | AV11: 0 | AW11: REN
A12: 10 | B12: NORM | C12: 9976AP2212510006 | D12: 6AP2 | E12: A | F12: T-PAK | G12: MARGALLA MOTORS | H12: 625980 | I12: 0616216 | J12: 2 | K12: 22.02 | L12: 0616216002 | M12: MUHAMMAD HASSAN KHAN | N12: Karachi | O12: 42501-9396639-5 | Q12: 03340295259 | S12: HOUSE # R- 210 CAPITAL SOCIETY SCHEME # 33 NEAR SAFOORA CHOWRANGI KARACHI. | T12: 1408000 | U12: 1760000 | V12: 55601/00004/09/2021 | W12: 02-SEP-2022 | X12: 218938 | Y12: 10118958 | Z12: NEW | AB12: WAGONR VXL AGS | AC12: 2021 | AD12: 08-SEP-2021 | AE12: 11-SEP-2021 | AF12: 11-Sep-2028 | AG12: OLDKHI300073107 | AH12: 7 | AI12: CTRK | AJ12: DIB0031542 | AK12: 08-SEP-2021 | AM12: 2% | AN12: 1408000 | AO12: 28160 | AS12: KHI/HO/D/MO/PC COMP/C/97805/14/09/2024 | AU12: 28160 | AV12: 0 | AW12: REN
A13: 11 | B13: NORM | C13: 997AAD2202120003 | D13: AAD2 | E13: A | F13: T-PAK | G13: HONDA CHENAB-GREEN VIEW MOTORS | H13: 598313 | I13: 0495988 | J13: 2 | K13: 21.05 | L13: 0495988003 | M13: ABDUL REHMAN | N13: Faisalabad | O13: 33100-4936955-5 | P13: 2695119 | Q13: 03028655454, 03028655454 | R13: 03028655454 | S13: 522-A BLOCK GM ABAD FAISALABAD PK | T13: 1921200 | U13: 2401500 | V13: 2524/0211/00003/09/2020 | W13: 02-SEP-2021 | X13: L13Z17540156 | Y13: NFBGM1545LR262742 | Z13: NEW | AA13: ARF-522 | AB13: HONDA CITY IVTEC M/T | AC13: 2020 | AD13: 30-JUL-2020 | AE13: 11-SEP-2020 | AF13: 11-Sep-2025 | AG13: POAFSD300056085 | AH13: 5 | AI13: ITFM | AJ13: 2943/09/2020/ITFM | AK13: 03-SEP-2020 | AM13: 2% | AN13: 1801125 | AO13: 36022.5 | AS13: KHI/HO/D/MO/PC COMP/C/97805/15/09/2024 | AT13: KHI/HO/D/MO/PC COMP/E/47950/00015/10/2024 | AU13: 40826 | AV13: -4803.5 | AW13: REN | AX13: -4803 | AY13: -0.5
A14: 12 | B14: NORM | C14: 9976AD1211510008 | D14: 6AD1 | E14: A | F14: T-PAK | G14: PAK SUZUKI MOTOR CO LTD | H14: 639041 | I14: 0132188 | J14: 2 | K14: 25.79 | L14: 0132188003 | M14: NASIR MEHMOOD | N14: Lahore | O14: 45504-1133892-3 | Q14: 0343-6600006, 0319-3118020 | R14: 051-2096014 | S14: H NO E-66 SHERAZ VILLAS PHASE II GAVALRY GROUND LAHORE | T14: 1704000 | U14: 2130000 | V14: 2021-09-205-V015010PD002106 | W14: 02-SEP-2022 | X14: 183356 | Y14: 10083360 | Z14: NEW | AB14: SUZUKI CULTUS VXL AGS EURO II | AC14: 2021 | AD14: 31-MAY-2021 | AE14: 03-OCT-2021 | AF14: 03-Oct-2026 | AG14: OLALHR300069018 | AH14: 5 | AI14: CTRK | AJ14: DIB0031548 | AK14: 06-SEP-2021 | AM14: 2% | AN14: 1704000 | AO14: 34080 | AS14: KHI/HO/D/MO/PC COMP/C/97805/18/09/2024 | AU14: 34080 | AV14: 0 | AW14: REN
A15: 13 | B15: NORM | C15: 997AAD1202530011 | D15: AAD1 | E15: A | F15: T-PAK | G15: HONDA AVENUE | H15: 635431 | I15: 0630360 | J15: 2 | K15: 27.93 | L15: 0630360001 | M15: SHEIKH AHSAN ANJUM | N15: Islamabad | O15: 37405-2517483-1 | P15: 03218505189 | R15: 0515772064 | S15: H # 184 ST # 11 BLOCK-D MEDIA TOWN ISLAMABAD PK | T15: 2187900 | U15: 2574000 | V15: DIB/T/BT/28487/ISB/0920 | W15: 02-SEP-2021 | X15: 7540202 | Y15: LR262950 | Z15: NEW | AB15: CITY IVTEC P/T | AC15: 2020 | AD15: 09-SEP-2020 | AE15: 21-SEP-2020 | AF15: 21-Sep-2025 | AG15: POAISD300057149 | AH15: 5 | AI15: CTRK | AJ15: TDIDIB0028623 | AK15: 08-SEP-2020 | AM15: 2% | AN15: 1930500 | AO15: 38610 | AS15: KHI/HO/D/MO/PC COMP/C/97805/19/09/2024 | AT15: KHI/HO/D/MO/PC COMP/E/47950/00019/10/2024 | AU15: 43758 | AV15: -5148 | AW15: REN | AX15: -5148 | AY15: 0
A16: 14 | B16: NORM | C16: 9976AD2211830045 | D16: 6AD2 | E16: A | F16: T-PAK | G16: TOYOTA JINNAH MOTORS | H16: 1094475 | I16: 0705239 | J16: 2 | K16: 26.29 | L16: 0705239001 | M16: ABDUL REHMAN | N16: Lahore | O16: 35202-1658380-7 | P16: 03458461611, 0334-4617900 | Q16: 03458461611, 0334-4617900 | R16: 03458461611 | S16: PLOT NO 380-381 RAVI LANE SUNDAR IN DUSTRIAL ESTATE LAHORE | T16: 2102250 | U16: 2803000 | V16: 2021-09-205-V01501OP0002105 | W16: 02-SEP-2022 | X16: 2A34742 | Y16: NSP150R-7021707 | Z16: NEW | AB16: YARIS ATIV CVT 1.3 | AC16: 2021 | AD16: 02-JUL-2021 | AE16: 21-SEP-2021 | AF16: 21-Sep-2026 | AG16: OLALHR300070327 | AH16: 5 | AI16: ITECL | AJ16: 5410/09/2021 | AK16: 03-SEP-2021 | AM16: 2% | AN16: 2242400 | AO16: 44848 | AS16: KHI/HO/D/MO/PC COMP/C/97805/21/09/2024 | AU16: 44848 | AV16: 0 | AW16: REN | BA16: 323
A17: 15 | B17: NORM | C17: 9976AD1210580011 | D17: 6AD1 | E17: A | F17: T-PAK | G17: PRINCE SAJJAD MOTORS | H17: 633662 | I17: 0084680 | J17: 2 | K17: 21.86 | L17: 0084680009 | M17: MUHAMMAD TALHA RASHEED | N17: Rawalpindi | O17: 37405-9507730-3 | P17: 03005214577 | Q17: 03005214577 | R17: 051-5491209 | S17: H # 67-D SECTOR 4-B KHAYABAN E SIRSYED NR D.H.O OFFICE RAWALPINDI | T17: 2956850 | U17: 4549000 | V17: 2021-09-205-V01501DP0002110 | W17: 02-SEP-2022 | X17: 21019969 | Y17: ALR1H1730 | Z17: NEW | AB17: PRINCE GLORY 580 PRO | AC17: 2021 | AD17: 27-FEB-2021 | AE17: 11-SEP-2021 | AF17: 11-Sep-2026 | AG17: OLARWP300066285 | AH17: 5 | AI17: CTRK | AJ17: B0031562 | AK17: 06-SEP-2021 | AM17: 2% | AN17: 3639200 | AO17: 72784 | AS17: KHI/HO/D/MO/PC COMP/C/97805/23/09/2024 | AU17: 72784 | AV17: 0 | AW17: REN | BA17: 145
A18: 16 | B18: NORM | C18: 9976AD1211810040 | D18: 6AD1 | E18: A | F18: T-PAK | G18: KIA MACCA MOTORS | H18: 1097834 | I18: 0704828 | J18: 1.75 | K18: 25.95 | L18: 0704828001 | M18: MUDASSER SHAHID | N18: Faisalabad | O18: 33100-0989902-7 | P18: 03217659090 | Q18: 03217659090, 03217659090 | R18: 03217659090 | S18: H NO 61 PARADISE VALLEY SHEIKHUPURA ROAD FAISALABAD PK | T18: 2917020 | U18: 4782000 | V18: DIB/T/33204/LHR/0821 | W18: 02-SEP-2022 | X18: 313847 | Y18: 306935 | Z18: NEW | AB18: SPORTAGE FWD | AC18: 2021 | AD18: 30-JUN-2021 | AE18: 03-OCT-2021 | AF18: 03-Oct-2026 | AG18: OLAFSD300070236 | AH18: 5 | AM18: 1.75% | AN18: 3825600 | AO18: 66948 | AS18: KHI/HO/D/MO/PC COMP/C/97805/24/09/2024 | AU18: 66948 | AV18: 0 | AW18: REN | BA18: =SUM(BA16:BA17) -> 468
A19: 17 | B19: NORM | C19: 9976AD2210580011 | D19: 6AD2 | E19: A | F19: T-PAK | G19: MG CENTER | H19: 636858 | I19: 0675736 | J19: 1.75 | K19: 19.87 | L19: 0675736001 | M19: YAHYA MASOOD DAR | N19: Faisalabad | O19: 33100-5686337-3 | P19: 03336533386 | Q19: 03336533386, 03336533386 | R19: 0412500175 | S19: H NO 23-A MADINA TOWN OFFICER COLON Y NO 2 FAISALABAD PK | T19: 3541850 | U19: 5449000 | V19: DIB/T/BT/33214/FSD/0821 | W19: 02-SEP-2022 | X19: 3080081 | Y19: 059722 | Z19: NEW | AB19: MG HS TURBO | AC19: 2021 | AD19: 27-FEB-2021 | AE19: 11-SEP-2021 | AF19: 11-Sep-2026 | AG19: OLAFSD300066229 | AH19: 5 | AI19: CTRK | AJ19: TDIDIB0029566 | AK19: 03-SEP-2021 | AM19: 1.75% | AN19: 4359200 | AO19: 76286 | AS19: KHI/HO/D/MO/PC COMP/C/97805/25/09/2024 | AU19: 76286 | AV19: 0 | AW19: REN
A20: 18 | B20: NORM | C20: 997APD1202680061 | D20: APD1 | E20: A | F20: T-PAK | G20: HONDA EXPRESS PVT LTD | H20: 640552 | I20: 0237825 | J20: 1.5 | K20: 20.3 | L20: 0237825003 | M20: RAANA ZEESHAN | N20: Rawalpindi | O20: 37405-0482476-2 | P20: N/A | Q20: 03455410096 | R20: 4461660 | S20: H # 141 ST # 1 AIRPORT HOUSING SOCIETY SECTOR 1 RAWALPINDI | T20: 2300000 | U20: 2875000 | V20: DIB/T/BT/28251/ISB/0820 | W20: 02-SEP-2021 | X20: 9799259 | Y20: LR262396 | Z20: NEW | AB20: HONDA CITY ASPIRE 1.5 A/T | AC20: 2020 | AD20: 24-SEP-2020 | AE20: 03-SEP-2020 | AF20: 03-Sep-2027 | AG20: PODRWP300056653 | AH20: 7 | AM20: 1.5% | AN20: 2156250 | AO20: 32343.75 | AS20: KHI/HO/D/MO/PC COMP/C/97805/26/09/2024 | AU20: 32344 | AV20: -0.25 | AW20: REN
A21: 19 | B21: NORM | C21: 9976AD2192100002 | D21: 6AD2 | E21: A | F21: T-PAK | G21: NASEER AUTOS | H21: 578216 | I21: 0547879 | J21: 2.5 | K21: 25.19 | L21: 0547879001 | M21: KIRAN FATIMA | N21: Karachi | O21: 42101-8700799-8 | P21: 03333571867 | Q21: 03333571867, 03333571867 | R21: 03333571867 | S21: FLAT # A-4 AFNAN DUPLEX NEAR KAMRAN CHOWRANGI BLOCK 3-A GULISTAN-E-JOH KARACHI PK | T21: 841750 | U21: 1295000 | V21: 51132/00005/09/2019 | W21: 03-SEP-2020 | X21: 109512 | Y21: 1009498 | Z21: NEW | AA21: BQT-391 | AB21: ALTO VXR AGS EURO-II | AC21: 2019 | AD21: 29-JUL-2019 | AE21: 21-SEP-2019 | AF21: 21-Sep-2026 | AG21: POAKHI300047840 | AH21: 7 | AI21: ITFM | AJ21: 1649/08/2019/ITFM | AK21: 23-SEP-2019 | AM21: 2.5% | AN21: 906500 | AO21: 22662.5 | AS21: KHI/HO/D/MO/PC COMP/C/97805/28/09/2024 | AT21: KHI/HO/D/MO/PC COMP/E/47950/00028/10/2024 | AU21: 25900 | AV21: -3237.5 | AW21: REN | AX21: -3238 | AY21: 0.5
A22: 20 | B22: NORM | C22: 9976AP1232490001 | D22: 6AP1 | E22: A | F22: T-PAK | G22: CITY CARS | H22: 1408905 | I22: 0726894 | J22: 1.5 | K22: 20.87 | L22: 0726894001 | M22: UMAIR ISMAIL | N22: Karachi | O22: 42201-8645528-9 | S22: FLAT NO 370-L BLOCK 3 HAJI LEMO GOTH GULSHAN E IQBAL KARACHI | T22: 3000000 | U22: 6000000 | V22: 74853/00001/09/2023 | W22: 03-SEP-2024 | X22: Q350606 | Y22: R7049790 | Z22: USD | AA22: BUC-943 | AB22: TOYOTA COROLLA ALTIS GRANDE CVT | AC22: 2021 | AD22: 45175 | AE22: 11-SEP-2023 | AF22: 11-Sep-2026 | AG22: OLUKHI300096535 | AH22: 3 | AI22: ITFM | AJ22: 10488/09/2023/ITFM | AK22: 04-SEP-2023 | AM22: 1.5% | AN22: 5400000 | AO22: 81000 | AS22: KHI/HO/D/MO/PC COMP/C/97805/34/09/2024 | AT22: KHI/HO/D/MO/PC COMP/E/47950/00034/10/2024 | AU22: 76500 | AV22: 4500 | AW22: REN | AX22: 4500 | AY22: 0
A23: 21 | B23: NORM | C23: 9976AD1192120016 | D23: 6AD1 | E23: A | F23: T-PAK | G23: MINI MOTORS | H23: 585736 | I23: 0552977 | J23: 2.5 | K23: 20.87 | L23: 0552977001 | M23: TANZEELA ASHRAF | N23: Lahore | O23: 35202-3282725-8 | P23: 03319315144 | Q23: 03319315144 | R23: 04235441150 | S23: H NO 137 ST NO 8 SECTOR E NISHTAR B LOCK BAHRIA TOWN LAHORE PK | T23: 1036000 | U23: 1295000 | V23: 51132/00013/09/2019 | W23: 04-SEP-2020 | X23: 111794 | Y23: 1011708 | Z23: NEW | AA23: LE-19A-1446 | AB23: ALTO VXL AGS EURO II | AC23: 2019 | AD23: 31-JUL-2019 | AE23: 11-SEP-2019 | AF23: 11-Sep-2026 | AG23: POALHR300048077 | AH23: 7 | AI23: CTRK | AJ23: DIB0027823 | AK23: 06-SEP-2019 | AM23: 2.5% | AN23: 906500 | AO23: 22662.5 | AS23: KHI/HO/D/MO/PC COMP/C/97805/37/09/2024 | AT23: KHI/HO/D/MO/PC COMP/E/47950/00037/10/2024 | AU23: 25900 | AV23: -3237.5 | AW23: REN | AX23: -3238 | AY23: 0.5
A24: 22 | B24: NORM | C24: 9976AD1221400024 | D24: 6AD1 | E24: A | F24: T-PAK | G24: HONDA GATEWAY PVT LTD | H24: 22034621046791 | I24: 0744154 | J24: 1.4 | K24: 18.87 | L24: 0744154004 | M24: MUHAMMAD AWAIS MUNEER | N24: Lahore | O24: 35202-1059168-3 | Q24: 00971522705097 | S24: M 17 MUSAFFAH ABU DHABU 51133 UNITED ARAB EMIRATES | T24: 2377200 | U24: 3396000 | V24: 62089/00082/07/2022 | W24: 04-SEP-2023 | X24: 1012682 | Y24: 022802 | Z24: RDA | AB24: HONDA CIVIC I-VTEC | AC24: 2022 | AD24: 20-MAY-2022 | AE24: 11-SEP-2022 | AF24: 11-Sep-2027 | AG24: OLALHR300087262 | AH24: 5 | AI24: ITFM | AJ24: 8090/07/2022/ITFM | AK24: 20-JUL-2022 | AM24: 1.4% | AN24: 2886600 | AO24: 40412.4 | AS24: KHI/HO/D/MO/PC COMP/C/97805/38/09/2024 | AT24: KHI/HO/D/MO/PC COMP/E/47950/00038/10/2024 | AU24: 35658 | AV24: 4754.4 | AW24: REN | AX24: 4754 | AY24: 0.4
A25: 23 | B25: NORM | C25: 9976AD1220900058 | D25: 6AD1 | E25: A | F25: T-PAK | G25: PAK SUZUKI MOTOR CO LTD | H25: 1149791 | I25: 0521751 | J25: 2 | K25: 22.37 | L25: 0521751003 | M25: KHALID MEHMOOD QURESHI | N25: Rawalpindi | O25: 37405-6717186-9 | P25: 03218502531 | R25: 4446281 | S25: H # B-1334 B-BLOCK SATELLITE TOWN NEAR MASJID UMER RAWALPINDI PK | T25: 1310250 | U25: 1747000 | V25: 62698/00106/08/2022 | W25: 04-SEP-2023 | X25: 247550 | Y25: 1147549 | Z25: NEW | AB25: SUZUKI ALTO VXL AGS EURO II | AC25: 2022 | AD25: 31-MAR-2022 | AE25: 11-SEP-2022 | AF25: 11-Sep-2025 | AG25: OLARWP300086201 | AH25: 3 | AI25: CTRK | AJ25: DIB0034745 | AK25: 05-SEP-2022 | AM25: 2% | AN25: 1484950 | AO25: 29699 | AS25: KHI/HO/D/MO/PC COMP/C/97805/40/09/2024 | AU25: 29699 | AV25: 0 | AW25: REN
A26: 24 | B26: NORM | C26: 9976AD2222360002 | D26: 6AD2 | E26: A | F26: T-PAK | G26: KIA MOTORS MUREE ROAD | H26: AL-1209821 | I26: 0810289 | J26: 2 | K26: 27.44 | L26: 0810289001 | M26: MALIK TAHIR BASHIR | N26: Islamabad | O26: 37405-8477777-9 | P26: 03008501930 | R26: 0514438886 | S26: H # 23 ST # 1 ROSE LANE # 1 NEW LAL AZAR RAWALPINDI PK | T26: 2927400 | U26: 4879000 | V26: 63286/00003/09/2022 | W26: 04-SEP-2023 | X26: 876516 | Y26: 701941 | Z26: NEW | AB26: KIA STONIC EX + | AC26: 2022 | AD26: 24-AUG-2022 | AE26: 21-SEP-2022 | AF26: 21-Sep-2025 | AG26: OLAISD300089502 | AH26: 3 | AI26: ITFT | AJ26: 8601/09/2022/ITFM | AK26: 07-SEP-2022 | AM26: 2% | AN26: 4147150 | AO26: 82943 | AS26: KHI/HO/D/MO/PC COMP/C/97805/41/09/2024 | AU26: 82943 | AV26: 0 | AW26: REN
A27: 25 | B27: NORM | C27: 9976AP2232490002 | D27: 6AP2 | E27: A | F27: T-PAK | G27: AL-QURASH MOTORS | H27: 1441687 | I27: 0901282 | J27: 1.75 | K27: 22.37 | L27: 0901282001 | M27: FAHAD ASHRAF | N27: Lahore | O27: 35201-2118465-7 | P27: 03211486243 | Q27: 03211486243 | R27: 03211486243 | S27: H NO 171-E MOHALLAH BANKER AVENUE C OOPERATIVE HOUSING SOCIETY BEDIAN R LAHORE PK | T27: 2355000 | U27: 7850000 | V27: 74853/00002/09/2023 | W27: 04-SEP-2024 | X27: 180922 | Y27: 206905 | Z27: USD | AA27: AJR-339 | AB27: HYUNDAI TUCSON FWD | AC27: 2022 | AD27: 45175 | AE27: 11-SEP-2023 | AF27: 11-Sep-2025 | AG27: OLULHR300096593 | AH27: 2 | AI27: CTRK | AJ27: DIB0035274 | AK27: 06-SEP-2023 | AM27: 1.75% | AN27: 7065000 | AO27: 123637.5 | AS27: KHI/HO/D/MO/PC COMP/C/97805/45/09/2024 | AU27: 123638 | AV27: -0.5 | AW27: REN
A28: 26 | B28: NORM | C28: 9976AD1211790006 | D28: 6AD1 | E28: A | F28: T-PAK | G28: PAK SUZUKI MOTOR CO LTD | H28: 536205 | I28: 0423485 | J28: 2 | K28: 25.79 | L28: 0423485006 | M28: FARRUKH ABBAS | N28: Lahore | O28: 35202-9924667-9 | P28: 03454181846 | Q28: 03454181846 | R28: 37634642 | S28: H 18 KARIM BAKHSH ROAD NEW SAMANAB AD NEAR BOHAR WALA CHOWK LAHORE PK | T28: 838600 | U28: 1198000 | V28: 2524/02640/00015/09/2021 | W28: 05-SEP-2021 | X28: 6R180191 | Y28: NF1AET306H1080152 | Z28: NEW | AB28: SUZUKI ALTO VX EURO 11 | AC28: 2021 | AD28: 28-JUN-2021 | AE28: 21-SEP-2021 | AF28: 21-Sep-2026 | AG28: OLAHR300069777 | AH28: 5 | AI28: CTRK | AJ28: DIB0031566 | AK28: 06-SEP-2021 | AM28: 2% | AN28: 958400 | AO28: 19168 | AS28: KHI/HO/D/MO/PC COMP/C/97805/53/09/2024 | AU28: 19168 | AV28: 0 | AW28: REN
A29: 27 | B29: NORM | C29: 9976AD1211790007 | D29: 6AD1 | E29: A | F29: T-PAK | G29: PAK SUZUKI MOTOR CO LTD | H29: 536231 | I29: 0423485 | J29: 2 | K29: 25.79 | L29: 0423485004 | M29: FARRUKH ABBAS | N29: Lahore | O29: 35202-9924667-9 | P29: 03454181846 | Q29: 03454181846 | R29: 37634642 | S29: H 18 KARIM BAKHSH ROAD NEW SAMANAB AD NEAR BOHAR WALA CHOWK LAHORE PK | T29: 958400 | U29: 1198000 | V29: 2524/02640/00014/09/2021 | W29: 05-SEP-2022 | X29: 6R180061 | Y29: NF1AET306H1080070 | Z29: NEW | AB29: SUZUKI ALTO VX-11 | AC29: 2021 | AD29: 28-JUN-2021 | AE29: 27-SEP-2021 | AF29: 27-Sep-2026 | AG29: OLAHR300069667 | AH29: 5 | AI29: CTRK | AJ29: DIB0031568 | AK29: 06-SEP-2021 | AM29: 2% | AN29: 958400 | AO29: 19168 | AS29: KHI/HO/D/MO/PC COMP/C/97805/54/09/2024 | AU29: 19168 | AV29: 0 | AW29: REN
A30: 28 | B30: NORM | C30: 9976AD1210700022 | D30: 6AD1 | E30: A | F30: T-PAK | G30: CHANGAN ADIL ASHRAF MOTORS | H30: 589731 | I30: 0663901 | J30: 2 | K30: 25.68 | L30: 0663901002 | M30: ABDUL SAMAD | N30: Lahore | O30: 35202-5999191-3 | Q30: 03331439659 | S30: HOUSE NO NILL GULSHAN.E.ISLAM COLONY QAZI PARK SHAHDRA (NEAR FURQAN MODEL SCHOOL) TOWN LAHORE | T30: 1148000 | U30: 1640000 | V30: 55601/00009/09/2021 | W30: 05-SEP-2022 | X30: 504362 | Y30: 1008353 | Z30: NEW | AB30: CHANGAN KARVAAN PLUS | AC30: 2021 | AD30: 11-MAR-2021 | AE30: 21-SEP-2021 | AF30: 21-Sep-2026 | AG30: OLALHR300066548 | AH30: 5 | AI30: CTRK | AJ30: DIB0031574 | AK30: 07-SEP-2021 | AM30: 2% | AN30: 1312000 | AO30: 26240 | AS30: KHI/HO/D/MO/PC COMP/C/97805/55/09/2024 | AU30: 26240 | AV30: 0 | AW30: REN
A31: 29 | B31: NORM | C31: 9976AD1211100017 | D31: 6AD1 | E31: A | F31: T-PAK | G31: SUZUKI MEHRAN MOTORS | H31: 632204 | I31: 0686400 | J31: 2 | K31: 21.96 | L31: 0686400001 | M31: MUHAMMAD ALTAF HUSSAIN | N31: Hyderabad | O31: 41303-2090371-7 | P31: 03332735769 | Q31: 03332735769 | R31: 0720224 | S31: HOUSE # F 1337 SALMAN SOHAG MANZIL KHOKHAR MUHALLAH BEAR BYCO PETROL P HYDERABAD PK | T31: 1379000 | U31: 1970000 | V31: 01-2108-PO-MTR-PCCM-D-001173 | W31: 05-SEP-2022 | X31: 178369 | Y31: 10078364 | Z31: NEW | AB31: SUZUKI CULTUS VXL | AC31: 2021 | AD31: 20-APR-2021 | AE31: 11-SEP-2021 | AF31: 11-Sep-2026 | AG31: OLAHYD300067731 | AH31: 5 | AI31: FLCN | AJ31: 108569/09/2021 | AK31: 02-SEP-2021 | AM31: 2% | AN31: 1576000 | AO31: 31520 | AS31: KHI/HO/D/MO/PC COMP/C/97805/56/09/2024 | AU31: 31520 | AV31: 0 | AW31: REN
A32: 30 | B32: NORM | C32: 9976AD1212450035 | D32: 6AD1 | E32: A | F32: T-PAK | G32: PREMIER SYSTEMS (PVT) LTD | H32: 1107497 | I32: 0157816 | J32: 1.75 | K32: 22.02 | L32: 0157816004 | M32: MUHAMMAD KUMAIL POLANI | N32: Karachi | O32: 42201-5815704-1 | Q32: 03412777777 03332470777 | R32: 32462000 | S32: POLANIS PVT LIMITED 49-53 SINDH MADRESSAH TUL ISLAM HASRAT MOHANI ROAD KARACHI | T32: 10118500 | U32: 14455000 | V32: 2021/09/CLFTTPCDP00986 | W32: 05-SEP-2022 | X32: EAS-138209 | Y32: WAUZZZGE2MB035231 | Z32: NEW | AB32: AUDI E-TRON 50 QUATTRO | AC32: 2021 | AD32: 02-SEP-2021 | AE32: 11-SEP-2021 | AF32: 11-Sep-2026 | AG32: OLAKHI300070315 | AH32: 5 | AM32: 1.75% | AN32: 11564000 | AO32: 202370 | AS32: KHI/HO/D/MO/PC COMP/C/97805/60/09/2024 | AU32: 202370 | AV32: 0 | AW32: REN
A33: 31 | B33: NORM | C33: 9976AD1220260027 | D33: 6AD1 | E33: A | F33: T-PAK | G33: CHANGAN SINDH MOTORS | H33: AL-1092370 | I33: 0753020 | J33: 2 | K33: 22.36 | L33: 0753020001 | M33: RAO MASOOD UR REHMAN | N33: Nawab Shah | O33: 45402-8944172-3 | P33: 03045834464 | Q33: 03045834464 | R33: 03045834464 | S33: HOUSE # IIA 836/154 KAMORA COLONY NAWABSHAH PK | T33: 1269800 | U33: 1814000 | V33: 63286/00008/09/2022 | W33: 05-SEP-2023 | X33: 503846 | Y33: 1016466 | Z33: NEW | AB33: CHANGAN KARVAN PLUS | AC33: 2022 | AD33: 26-JAN-2022 | AE33: 11-SEP-2022 | AF33: 11-Sep-2027 | AG33: OLANWB300083303 | AH33: 5 | AI33: ITECL | AJ33: 8492/08/2022 | AK33: 29-AUG-2022 | AM33: 2% | AN33: 1541900 | AO33: 30838 | AS33: KHI/HO/D/MO/PC COMP/C/97805/62/09/2024 | AT33: KHI/HO/D/MO/PC COMP/E/47950/00062/10/2024 | AU33: 27210 | AV33: 3628 | AW33: REN | AX33: 3628 | AY33: 0
A34: 32 | B34: NORM | C34: 9976AD2220190006 | D34: 6AD2 | E34: A | F34: T-PAK | G34: PAK SUZUKI MOTOR CO LTD | H34: 1141848 | I34: 0716961 | J34: 2 | K34: 22.86 | L34: 0716961004 | M34: BILAL IKRAM | N34: Islamabad | O34: 61101-4385442-7 | Q34: 03335517158 | S34: BLOCK NO.1A, FLAT NO.9-A, ST NO.1, SECTOR I-8/1,ISLAMABAD | T34: 1131000 | U34: 1508000 | V34: 62698/00114/08/2022 | W34: 05-SEP-2023 | X34: 247953 | Y34: 1147941 | Z34: NEW | AB34: SUZUKI ALTO VXR EURO II | AC34: 2022 | AD34: 19-JAN-2022 | AE34: 11-SEP-2022 | AF34: 11-Sep-2029 | AG34: OLAISD300083253 | AH34: 7 | AI34: ITECL | AJ34: 8477/08/2022 | AK34: 06-SEP-2022 | AM34: 2% | AN34: 1281800 | AO34: 25636 | AS34: KHI/HO/D/MO/PC COMP/C/97805/64/09/2024 | AU34: 25636 | AV34: 0 | AW34: REN
A35: 33 | B35: NORM | C35: 9976AP1222510005 | D35: 6AP1 | E35: A | F35: T-PAK | G35: NEW CAR COMPLEX | H35: AL-1147709 | I35: 0801889 | J35: 1.5 | K35: 21.37 | L35: 0801889001 | M35: AMIR KHALID | N35: Karachi | O35: 42201-9594326-7 | P35: 03222130782 | Q35: 03222130782 | R35: 0 | S35: HNO 77/4 STREET 14 KHAYABAN E SEHER PHASE 6 DHA NEAR NIXOR CELLEGE KARACHI PK | T35: 2415000 | U35: 3450000 | V35: 63286/00009/09/2022 | W35: 05-SEP-2023 | X35: Q034703 | Y35: R6012169 | Z35: USD | AA35: BHJ-203 | AB35: TOYOTA COROLLA ALTIS A/T | AC35: 2016 | AD35: 08-SEP-2022 | AE35: 11-SEP-2022 | AF35: 11-Sep-2025 | AG35: OLUKHI300089724 | AH35: 3 | AI35: ITFM | AJ35: 8602/09/2022/ITFM | AK35: 07-SEP-2022 | AM35: 1.5% | AN35: 2932500 | AO35: 43987.5 | AS35: KHI/HO/D/MO/PC COMP/C/97805/65/09/2024 | AU35: 43988 | AV35: -0.5 | AW35: REN
A36: 34 | B36: NORM | C36: 9976AD1221390023 | D36: 6AD1 | E36: A | F36: T-PAK | G36: PAK SUZUKI MOTOR CO LTD | H36: 1209240 | I36: 0786014 | J36: 1.5 | K36: 25.19 | L36: 0786014001 | M36: RABIA AWAN | N36: Lahore | O36: 35202-7590673-0 | Q36: 0346-4687037 / 0333-6812012 | S36: FLAT # 06, 2ND FLOOR JAHANGIR PARK NEW MAZANG LAHORE | T36: 1519100 | U36: 2762000 | V36: 63286/00007/09/2022 | W36: 05-SEP-2023 | X36: 200538 | Y36: 10100532 | Z36: NEW | AB36: SUZUKI CULTUS VXL AGS EURO II | AC36: 2022 | AD36: 19-MAY-2022 | AE36: 21-SEP-2022 | AF36: 21-Sep-2025 | AG36: OLALHR300087344 | AH36: 3 | AI36: ITFM | AJ36: 8598/09/2022/ITFM | AK36: 06-SEP-2022 | AM36: 1.5% | AN36: 2347700 | AO36: 35215.5 | AS36: KHI/HO/D/MO/PC COMP/C/97805/69/09/2024 | AU36: 35216 | AV36: -0.5 | AW36: REN
A37: 35 | B37: NORM | C37: 9976AP2222560002 | D37: 6AP2 | E37: A | F37: T-PAK | G37: NEW CAR COMPLEX | H37: AL-1201870 | I37: 0795572 | J37: 1.5 | K37: 26.19 | L37: 0795572002 | M37: REBAL ISRAIL | N37: Karachi | O37: 42201-4370083-1 | Q37: 03314969006 | S37: HOUSE NO A-1/125 BLOCK 13-A RAILWAY HOUSING SOCIETY GULSHAN-E-IQBAL NEAR STUDENT BIRYANI KARACHI | T37: 1082200 | U37: 1546000 | V37: 63286/00005/09/2022 | W37: 05-SEP-2023 | X37: 6R234553 | Y37: 1134530 | Z37: USD | AA37: BWX-081 | AB37: SUZUKI ALTO VXR EURO II | AC37: 2022 | AD37: 13-SEP-2022 | AE37: 21-SEP-2022 | AF37: 21-Sep-2025 | AG37: OLUKHI300089710 | AH37: 3 | AI37: ITFT | AJ37: 8595/09/2022/ITFM | AK37: 06-SEP-2022 | AM37: 1.5% | AN37: 1314100 | AO37: 19711.5 | AS37: KHI/HO/D/MO/PC COMP/C/97805/70/09/2024 | AU37: 19712 | AV37: -0.5 | AW37: REN
A38: 36 | B38: NORM | C38: 9976AD1222270002 | D38: 6AD1 | E38: A | F38: T-PAK | G38: KIA MOTORS POTOHAR | H38: AL-1191862 | I38: 0807008 | J38: 2 | K38: 26.69 | L38: 0807008001 | M38: ARQAM MUSTAFA | N38: Rawalpindi | O38: 37405-7954606-1 | P38: 03315013061 | R38: 0517066383 | S38: H # 684 ST # 7 SECTOR 1 AIRPORT HOU SING SOCIEITY NEAR CENTRAL PARK RAWALPINDI PK | T38: 1820000 | U38: 2600000 | V38: 62698/00122/08/2022 | W38: 05-SEP-2023 | X38: 047695 | Y38: 504159 | Z38: NEW | AB38: KIA PICANTO 1.0 L M/T | AC38: 2022 | AD38: 15-AUG-2022 | AE38: 21-SEP-2022 | AF38: 21-Sep-2025 | AG38: OLARWP300089282 | AH38: 3 | AI38: ITFM | AJ38: 8485/08/2022/ITFM | AK38: 06-SEP-2022 | AM38: 2% | AN38: 2210000 | AO38: 44200 | AS38: KHI/HO/D/MO/PC COMP/C/97805/72/09/2024 | AU38: 44200 | AV38: 0 | AW38: REN
A39: 37 | B39: NORM | C39: 9976AP1232510004 | D39: 6AP1 | E39: A | F39: T-PAK | G39: KHALID MOTORS | H39: 1441374 | I39: 0804337 | J39: 1.75 | K39: 22.12 | L39: 0804337003 | M39: ALI ARSLAN | N39: Lahore | O39: 35202-0488967-3 | P39: 03217875335 | Q39: 03217875335 | R39: 03217875335 | S39: H NO 250 IRIS BLOCK BAHRIA TOWN LAHORE PK | T39: 1261000 | U39: 1940000 | V39: 74853/0005/09/2023 | W39: 05-SEP-2024 | X39: 1029660 | Y39: 1146173 | Z39: NEW | AB39: SUZUKI BOLAN VX EURO II | AC39: 2023 | AD39: 45177 | AE39: 11-SEP-2023 | AF39: 11-Sep-2028 | AG39: OLDLHR300096603 | AH39: 5 | AI39: CTRK | AJ39: DIB0035279 | AK39: 08-SEP-2023 | AM39: 1.75% | AN39: 1746000 | AO39: 30555 | AS39: KHI/HO/D/MO/PC COMP/C/97805/74/09/2024 | AT39: KHI/HO/D/MO/PC COMP/E/47950/00074/10/2024 | AU39: 27160 | AV39: 3395 | AW39: REN | AX39: 3395 | AY39: 3.6379788e-12
A40: 38 | B40: NORM | C40: 9976AP2232500005 | D40: 6AP2 | E40: A | F40: T-PAK | G40: MOTOR TREND | H40: 1408001 | I40: 0313344 | J40: 1.75 | K40: 22.37 | L40: 0313344004 | M40: SAIF ALI SHOUKAT | N40: Islamabad | O40: 35202-1039697-1 | P40: NA | Q40: 03214007837 | R40: 8355139 | S40: SHOP NO 06, F-7-3 GATE MARKET SHAMSABAD, RAWALPINDI 03214007837 | T40: 1980000 | U40: 3300000 | V40: 74853/00003/09/2023 | W40: 05-SEP-2024 | X40: 503965 | Y40: 1000485 | Z40: USD | AA40: AWH-869 | AB40: CHANGAN ALSVIN COMFORT M/T | AC40: 2021 | AD40: 45176 | AE40: 11-SEP-2023 | AF40: 11-Sep-2026 | AG40: OLUISD300096614 | AH40: 3 | AI40: CTRK | AJ40: DIB0035277 | AK40: 07-SEP-2023 | AM40: 1.75% | AN40: 2970000 | AO40: 51975 | AS40: KHI/HO/D/MO/PC COMP/C/97805/76/09/2024 | AT40: KHI/HO/D/MO/PC COMP/E/47950/00076/10/2024 | AU40: 49088 | AV40: 2887 | AW40: REN | AX40: 2888 | AY40: -1
...

Sheet working
A1: POLICY NO. | B1: Assorted_code | D1: Premium | E1: 29Oct240041
