Workbook

Sheet PAYMENT ON MONTH OF DEC-2024
A1: Contract No. | B1: Customer Name | C1: CNIC No. | D1: Engine No. | E1: Chassis No. | F1: Premium | G1: ACC Number | H1: ACC Branch | I1: INSURANCE CO. | J1: Policy No. | K1: Endorsement No. | L1: TMS Premium | M1: Difference Amount
A2: 9976AD1242960001 | B2: MOIZ KHAN | C2: 42201-0169202-5 | D2: 1001614 | E2: NF1ADE17V00101620 | F2: 55980 | G2: 0006437055 | H2: 106 | I2: SALAAM TAKAFUL PAKISTAN | J2: KHI/HO/D/MO/PC COMP/C/103276/18/12/2024 | L2: 55980 | M2: =L2-F2 -> 0
A3: 9976AD2242560001 | B3: AZEEM KHITAB | C3: 37405-3883858-7 | D3: 329164 | E3: 1229026 | F3: 46620 | G3: 0006437055 | H3: 106 | I3: SALAAM TAKAFUL PAKISTAN | J3: KHI/HO/D/MO/PC COMP/C/103276/1/12/2024 | L3: 46620 | M3: =L3-F3 -> 0
A4: 9976AP1243400002 | B4: MUHAMMAD NAVEED KHAN NIAZI | C4: 42501-8238002-7 | D4: 6R172159 | E4: H1072139 | F4: 42000 | G4: 0006437055 | H4: 106 | I4: SALAAM TAKAFUL PAKISTAN | J4: KHI/HO/D/MO/PC COMP/C/103276/6/12/2024 | L4: 42000 | M4: =L4-F4 -> 0
A5: 9976AP1243400003 | B5: SHAKIR ALI IMTIAZ | C5: 42401-3221628-7 | D5: 6R121384 | E5: 1021361 | F5: 36750 | G5: 0006437055 | H5: 106 | I5: SALAAM TAKAFUL PAKISTAN | J5: KHI/HO/D/MO/PC COMP/C/103276/4/12/2024 | L5: 36750 | M5: =L5-F5 -> 0
A6: 9976AP1243410005 | B6: MUHAMMAD AMIR | C6: 42401-2850195-5 | D6: 327421 | E6: 1227275 | F6: 53288 | G6: 0006437055 | H6: 106 | I6: SALAAM TAKAFUL PAKISTAN | J6: KHI/HO/D/MO/PC COMP/C/103276/2/12/2024 | L6: 53288 | M6: =L6-F6 -> 0
A7: 9976AP1243460001 | B7: AMAN KHURSHID | C7: 33102-1789872-3 | D7: 6R329945 | E7: 1229887 | F7: 47373 | G7: 0006437055 | H7: 106 | I7: SALAAM TAKAFUL PAKISTAN | J7: KHI/HO/D/MO/PC COMP/C/103276/12/12/2024 | L7: 47373 | M7: =L7-F7 -> 0
A8: 9976AP1243460003 | B8: MUHAMMAD AYAZ | C8: 42201-7932103-7 | D8: 6R215933 | E8: 1115919 | F8: 37625 | G8: 0006437055 | H8: 106 | I8: SALAAM TAKAFUL PAKISTAN | J8: KHI/HO/D/MO/PC COMP/C/103276/14/12/2024 | L8: 37625 | M8: =L8-F8 -> 0
A9: 9976AP1243520002 | B9: FAYYAZ HUSSAIN FAREEDI | C9: 42101-1858408-1 | D9: 189960 | E9: NF1AETH306H1090016 | F9: 39025 | G9: 0006437055 | H9: 106 | I9: SALAAM TAKAFUL PAKISTAN | J9: KHI/HO/D/MO/PC COMP/C/103276/24/12/2024 | L9: 39025 | M9: =L9-F9 -> 0
A10: 9976AP1243530004 | B10: SYED WAJAHAT ALI RIZVI | C10: 42000-0409144-5 | D10: 6R151826 | E10: 1051724 | F10: 39550 | G10: 0006437055 | H10: 106 | I10: SALAAM TAKAFUL PAKISTAN | J10: KHI/HO/D/MO/PC COMP/C/103276/25/12/2024 | L10: 39550 | M10: =L10-F10 -> 0
A11: 9976AP1243530004 | B11: SYED WAJAHAT ALI RIZVI | C11: 42000-0409144-5 | D11: 6R151826 | E11: 1051724 | F11: 39550 | G11: 0006437055 | H11: 106 | I11: SALAAM TAKAFUL PAKISTAN | J11: KHI/HO/D/MO/PC COMP/C/103276/25/12/2024 | L11: 39550 | M11: =L11-F11 -> 0
A12: 9976AP1243550001 | B12: MUHAMMAD SHAFIQ | C12: 32303-2297524-7 | D12: 17514668 | E12: NFBGM1642JR229046 | F12: 68250 | G12: 0006437055 | H12: 106 | I12: SALAAM TAKAFUL PAKISTAN | J12: KHI/HO/D/MO/PC COMP/C/103276/39/12/2024 | L12: 68250 | M12: =L12-F12 -> 0
A13: 9976AP1243580011 | B13: HASSAN AHMED | C13: 42401-9848846-3 | D13: 6R329022 | E13: 1228844 | F13: 53288 | G13: 0006437055 | H13: 106 | I13: SALAAM TAKAFUL PAKISTAN | J13: KHI/HO/D/MO/PC COMP/C/103276/33/12/2024 | L13: 53288 | M13: =L13-F13 -> 0
... A25: 9976AP1243660037 | B25: FAYAZ ALI SHAH | C25: 42501-6850000-1 | D25: 6R211431 | E25: H1111438 | F25: 43313 | G25: 0006437055 | H25: 106 | I25: SALAAM TAKAFUL PAKISTAN | J25: KHI/HO/D/MO/PC COMP/C/103276/80/12/2024 | L25: 43313 | M25: =L25-F25 -> 0
A26: 9976AP1243660038 | B26: SHOAIB ANJUM | C26: 33100-8697725-1 | D26: 179410 | E26: NKMASE2E6N1002629 | F26: 135188 | G26: 0006437055 | H26: 106 | I26: SALAAM TAKAFUL PAKISTAN | J26: KHI/HO/D/MO/PC COMP/C/103276/81/12/2024 | K26: KHI/HO/D/MO/PC COMP/E/50716/00081/01/2025 | L26: 128188 | M26: =L26-F26 -> -7000
A27: 9976AP1243660041 | B27: JAWAD AHMED ARAIN | C27: 42201-7058894-5 | D27: 17527427 | E27: NFBGM164XKR245190 | F27: 64750 | G27: 0006437055 | H27: 106 | I27: SALAAM TAKAFUL PAKISTAN | J27: KHI/HO/D/MO/PC COMP/C/103276/82/12/2024 | L27: 64750 | M27: =L27-F27 -> 0
A28: 9976AP2243410002 | B28: MUHAMMAD DANISH | C28: 42201-3140726-1 | D28: 148115 | E28: NF1AET306H1048101 | F28: 42000 | G28: 0006437055 | H28: 106 | I28: SALAAM TAKAFUL PAKISTAN | J28: KHI/HO/D/MO/PC COMP/C/103276/3/12/2024 | L28: 42000 | M28: =L28-F28 -> 0
A29: 9976AP2243440001 | B29: SHAGUFTA SOHAIL | C29: 42401-4149273-6 | D29: 175436 | E29: NF1AET306H1075417 | F29: 45500 | G29: 0006437055 | H29: 106 | I29: SALAAM TAKAFUL PAKISTAN | J29: KHI/HO/D/MO/PC COMP/C/103276/10/12/2024 | L29: 45500 | M29: =L29-F29 -> 0
A30: 9976AP2243510003 | B30: MUHAMMAD FAHEEM | C30: 35201-9010452-3 | D30: 329742 | E30: 1229787 | F30: 47373 | G30: 0006437055 | H30: 106 | I30: SALAAM TAKAFUL PAKISTAN | J30: KHI/HO/D/MO/PC COMP/C/103276/22/12/2024 | L30: 47373 | M30: =L30-F30 -> 0
A31: 9976AP2243550001 | B31: SANA KHAN | C31: 37405-8030235-8 | D31: 51029549 | E31: RR046409 | F31: 58988 | G31: 0006437055 | H31: 106 | I31: SALAAM TAKAFUL PAKISTAN | J31: KHI/HO/D/MO/PC COMP/C/103276/40/12/2024 | L31: 58988 | M31: =L31-F31 -> 0
A32: 9976AP2243610010 | B32: MUNAWAR ABBAS WAZIR | C32: 42201-0521303-5 | D32: 221958 | E32: 714431 | F32: 67375 | G32: 0006437055 | H32: 106 | I32: SALAAM TAKAFUL PAKISTAN | J32: KHI/HO/D/MO/PC COMP/C/103276/56/12/2024 | L32: 67375 | M32: =L32-F32 -> 0
A33: 9976AP2243620014 | B33: SAJID ALI | C33: 35201-5825733-9 | D33: 1001032 | E33: NFBRV3852NR00127 | F33: 99750 | G33: 0006437055 | H33: 106 | I33: SALAAM TAKAFUL PAKISTAN | J33: KHI/HO/D/MO/PC COMP/C/103276/58/12/2024 | L33: 99750 | M33: =L33-F33 -> 0
A34: 9976AP2243660008 | B34: MAH JABEEN ADIL | C34: 42101-2502305-4 | D34: 68033 | E34: NF1AET306H1167945 | F34: 47250 | G34: 0006437055 | H34: 106 | I34: SALAAM TAKAFUL PAKISTAN | J34: KHI/HO/D/MO/PC COMP/C/103276/64/12/2024 | L34: 47250 | M34: =L34-F34 -> 0
A35: 9976AP2243660010 | B35: AMJAD KHAN | C35: 42201-3581366-5 | D35: 294890 | E35: NF1AET306H1194931 | F35: 46813 | G35: 0006437055 | H35: 106 | I35: SALAAM TAKAFUL PAKISTAN | J35: KHI/HO/D/MO/PC COMP/C/103276/75/12/2024 | L35: 46813 | M35: =L35-F35 -> 0
A36: 9976AP2243660013 | B36: SYED MUHAMMAD FAZLE TEHAMI | C36: 35202-8625982-1 | D36: 14807808 | E36: NFBDG1836NR024494 | F36: 91438 | G36: 0006437055 | H36: 106 | I36: SALAAM TAKAFUL PAKISTAN | J36: KHI/HO/D/MO/PC COMP/C/103276/77/12/2024 | L36: 91438 | M36: =L36-F36 -> 0
A37: 9976AP2243660014 | B37: IMRAN SHAFIQUE | C37: 35202-2563167-5 | D37: 205397 | E37: A1J310PK10105391 | F37: 44625 | G37: 0006437055 | H37: 106 | I37: SALAAM TAKAFUL PAKISTAN | J37: KHI/HO/D/MO/PC COMP/C/103276/79/12/2024 | L37: 44625 | M37: =L37-F37 -> 0
A38: 9976AP2250020001 | B38: MIR AHMED WASEEM | C38: 35202-2928596-5 | D38: 331845 | E38: NF1AET306H1231876 | F38: 47373 | G38: 0006437055 | H38: 106 | I38: SALAAM TAKAFUL PAKISTAN | J38: KHI/HO/D/MO/PC COMP/C/103276/67/12/2024 | L38: 47373 | M38: =L38-F38 -> 0
... A51: 997AFRR243410013 | B51: SYED KASHAN NASIR | C51: 45504-1074581-1 | D51: Q087476 | E51: 6064943 | F51: 99750 | G51: 0006437055 | H51: 106 | I51: SALAAM TAKAFUL PAKISTAN | J51: KHI/HO/D/MO/PC COMP/C/103276/7/12/2024 | L51: 99750 | M51: =L51-F51 -> 0
A52: 997AFRR243440009 | B52: AMINA JAMIL | C52: 33100-6848671-0 | D52: 566948 | E52: NZE170R-4189909 | F52: 61500 | G52: 0006437055 | H52: 106 | I52: SALAAM TAKAFUL PAKISTAN | J52: KHI/HO/D/MO/PC COMP/C/103276/11/12/2024 | K52: KHI/HO/D/MO/PC COMP/E/50716/00011/01/2025 | L52: 71750 | M52: =L52-F52 -> 10250
A53: 997AFRR243510005 | B53: ALI SHAHZAD | C53: 35202-1886636-0 | D53: 1029303 | E53: 046141 | F53: 82583 | G53: 0006437055 | H53: 106 | I53: SALAAM TAKAFUL PAKISTAN | J53: KHI/HO/D/MO/PC COMP/C/103276/20/12/2024 | L53: 82583 | M53: =L53-F53 -> 0
A54: 997AFRR243510010 | B54: SYED SHAHEER SHAHID | C54: 42101-6774457-1 | D54: 192545 | E54: NF1AETH306H1092375 | F54: 42000 | G54: 0006437055 | H54: 106 | I54: SALAAM TAKAFUL PAKISTAN | J54: KHI/HO/D/MO/PC COMP/C/103276/19/12/2024 | L54: 42000 | M54: =L54-F54 -> 0
A55: 997AFRR243520001 | B55: SHAHRUKH SHAKEEL | C55: 42201-4728265-5 | D55: 17543384 | E55: NFBGN1648MR267174 | F55: 68250 | G55: 0006437055 | H55: 106 | I55: SALAAM TAKAFUL PAKISTAN | J55: KHI/HO/D/MO/PC COMP/C/103276/17/12/2024 | L55: 68250 | M55: =L55-F55 -> 0
A56: 997AFRR243520002 | B56: MUHAMMAD KHABAB KHAN | C56: 42501-9675193-7 | D56: Q083343 | E56: 6060829 | F56: 91000 | G56: 0006437055 | H56: 106 | I56: SALAAM TAKAFUL PAKISTAN | J56: KHI/HO/D/MO/PC COMP/C/103276/26/12/2024 | L56: 91000 | M56: =L56-F56 -> 0
A57: 997AFRR243520003 | B57: AYAZ AHMED | C57: 42201-0894422-9 | D57: 513123 | E57: NZE170R4139302 | F57: 61250 | G57: 0006437055 | H57: 106 | I57: SALAAM TAKAFUL PAKISTAN | J57: KHI/HO/D/MO/PC COMP/C/103276/21/12/2024 | L57: 61250 | M57: =L57-F57 -> 0
A58: 997AFRR243520004 | B58: ZIKRAN KHAN | C58: 42201-7400991-5 | D58: R329058 | E58: 1228837 | F58: 53288 | G58: 0006437055 | H58: 106 | I58: SALAAM TAKAFUL PAKISTAN | J58: KHI/HO/D/MO/PC COMP/C/103276/27/12/2024 | L58: 53288 | M58: =L58-F58 -> 0
A59: 997AFRR243530010 | B59: SAJJAD YAMIN | C59: 35202-8570819-3 | D59: 13041445 | E59: RS413PK10041443 | F59: 41125 | G59: 0006437055 | H59: 106 | I59: SALAAM TAKAFUL PAKISTAN | J59: KHI/HO/D/MO/PC COMP/C/103276/23/12/2024 | L59: 41125 | M59: =L59-F59 -> 0
A60: 997AFRR243530013 | B60: ALI RAZA | C60: 42201-5421027-7 | D60: 17515690 | E60: NFBGM1640JR230115 | F60: 56875 | G60: 0006437055 | H60: 106 | I60: SALAAM TAKAFUL PAKISTAN | J60: KHI/HO/D/MO/PC COMP/C/103276/31/12/2024 | L60: 56875 | M60: =L60-F60 -> 0
A61: 997AFRR243530015 | B61: ANAYAT ULLAH | C61: 21706-8691135-9 | D61: 6R312835 | E61: 1212747 | F61: 47285 | G61: 0006437055 | H61: 106 | I61: SALAAM TAKAFUL PAKISTAN | J61: KHI/HO/D/MO/PC COMP/C/103276/30/12/2024 | L61: 47285 | M61: =L61-F61 -> 0
A62: 997AFRR243540003 | B62: AHMAD NOORANI | C62: 35202-7531680-3 | D62: 329341 | E62: 1229303 | F62: 53288 | G62: 0006437055 | H62: 106 | I62: SALAAM TAKAFUL PAKISTAN | J62: KHI/HO/D/MO/PC COMP/C/103276/37/12/2024 | L62: 53288 | M62: =L62-F62 -> 0
A63: 997AFRR243550003 | B63: HAIDER ALI | C63: 35202-6094321-1 | D63: 6R330748 | E63: 1230763 | F63: 53288 | G63: 0006437055 | H63: 106 | I63: SALAAM TAKAFUL PAKISTAN | J63: KHI/HO/D/MO/PC COMP/C/103276/41/12/2024 | L63: 53288 | M63: =L63-F63 -> 0
...

Sheet WORKING
A1: POLICY NO. | B1: Assorted_code | D1: Premium | E1: 13Jan250053
A2: KHI/HO/D/MO/PC COMP/C/103276/18/12/2024 | B2: =VLOOKUP(A2,POLICY!B:C,2,0) -> 070000171729 | C2: 55980 | D2: =ROUND(C2,0) -> 55980 | E2: 13Jan250053 | F2: ="insert into ins_premium_det (premium_rcv_code,assorted_code, rec_amount,premium_rcv_detail_code,remaining_amt, payrec, mode_code,coinsurance_code,class_cd,it_remarks) values" -> insert into ins_premium_det (premium_rcv_code,assorted_code, rec_amount,premium_rcv_detail_code,remaining_amt, payrec, mode_code,coinsurance_code,class_cd,it_remarks) values | G2: ="('"&E2&"','"&B2&"','"&D2&"',(select max(to_number(i.premium_rcv_detail_code))+1 from ins_premium_det i),'"&D2&"','"&D2&"','02', '11000003','00','Request by Mr. Saqib Saleem 13-Jan-2024');" -> ('13Jan250053','070000171729','55980',(select max(to_number(i.premium_rcv_detail_code))+1 from ins_premium_det i),'55980','55980','02', '11000003','00','Request by Mr. Saqib Saleem 13-Jan-2024'); | H2: =F2&G2 -> insert into ins_premium_det (premium_rcv_code,assorted_code, rec_amount,premium_rcv_detail_code,remaining_amt, payrec, mode_code,coinsurance_code,class_cd,it_remarks) values('13Jan250053','070000171729','55980',(select max(to_number(i.premium_rcv_detail_code))+1 from ins_premium_det i),'55980','55980','02', '11000003','00','Request by Mr. Saqib Saleem 13-Jan-2024');
A3: KHI/HO/D/MO/PC COMP/C/103276/1/12/2024 | B3: =VLOOKUP(A3,POLICY!B:C,2,0) -> 070000171508 | C3: 46620 | D3: =ROUND(C3,0) -> 46620 | E3: 13Jan250053 | F3: ="insert into ins_premium_det (premium_rcv_code,assorted_code, rec_amount,premium_rcv_detail_code,remaining_amt, payrec, mode_code,coinsurance_code,class_cd,it_remarks) values" -> insert into ins_premium_det (premium_rcv_code,assorted_code, rec_amount,premium_rcv_detail_code,remaining_amt, payrec, mode_code,coinsurance_code,class_cd,it_remarks) values | G3: ="('"&E3&"','"&B3&"','"&D3&"',(select max(to_number(i.premium_rcv_detail_code))+1 from ins_premium_det i),'"&D3&"','"&D3&"','02', '11000003','00','Request by Mr. Saqib Saleem 13-Jan-2024');" -> ('13Jan250053','070000171508','46620',(select max(to_number(i.premium_rcv_detail_code))+1 from ins_premium_det i),'46620','46620','02', '11000003','00','Request by Mr. Saqib Saleem 13-Jan-2024'); | H3: =F3&G3 -> insert into ins_premium_det (premium_rcv_code,assorted_code, rec_amount,premium_rcv_detail_code,remaining_amt, payrec, mode_code,coinsurance_code,class_cd,it_remarks) values('13Jan250053','070000171508','46620',(select max(to_number(i.premium_rcv_detail_code))+1 from ins_premium_det i),'46620','46620','02', '11000003','00','Request by Mr. Saqib Saleem 13-Jan-2024');
A4: KHI/HO/D/MO/PC COMP/C/103276/6/12/2024 | B4: =VLOOKUP(A4,POLICY!B:C,2,0) -> 070000171566 | C4: 42000 | D4: =ROUND(C4,0) -> 42000 | E4: 13Jan250053 | F4: ="insert into ins_premium_det (premium_rcv_code,assorted_code, rec_amount,premium_rcv_detail_code,remaining_amt, payrec, mode_code,coinsurance_code,class_cd,it_remarks) values" -> insert into ins_premium_det (premium_rcv_code,assorted_code, rec_amount,premium_rcv_detail_code,remaining_amt, payrec, mode_code,coinsurance_code,class_cd,it_remarks) values | G4: ="('"&E4&"','"&B4&"','"&D4&"',(select max(to_number(i.premium_rcv_detail_code))+1 from ins_premium_det i),'"&D4&"','"&D4&"','02', '11000003','00','Request by Mr. Saqib Saleem 13-Jan-2024');" -> ('13Jan250053','070000171566','42000',(select max(to_number(i.premium_rcv_detail_code))+1 from ins_premium_det i),'42000','42000','02', '11000003','00','Request by Mr. Saqib Saleem 13-Jan-2024'); | H4: =F4&G4 -> insert into ins_premium_det (premium_rcv_code,assorted_code, rec_amount,premium_rcv_detail_code,remaining_amt, payrec, mode_code,coinsurance_code,class_cd,it_remarks) values('13Jan250053','070000171566','42000',(select max(to_number(i.premium_rcv_detail_code))+1 from ins_premium_det i),'42000','42000','02', '11000003','00','Request by Mr. Saqib Saleem 13-Jan-2024');
A5: KHI/HO/D/MO/PC COMP/C/103276/4/12/2024 | B5: =VLOOKUP(A5,POLICY!B:C,2,0) -> 070000171538 | C5: 36750 | D5: =ROUND(C5,0) -> 36750 | E5: 13Jan250053 | F5: ="insert into ins_premium_det (premium_rcv_code,assorted_code, rec_amount,premium_rcv_detail_code,remaining_amt, payrec, mode_code,coinsurance_code,class_cd,it_remarks) values" -> insert into ins_premium_det (premium_rcv_code,assorted_code, rec_amount,premium_rcv_detail_code,remaining_amt, payrec, mode_code,coinsurance_code,class_cd,it_remarks) values | G5: ="('"&E5&"','"&B5&"','"&D5&"',(select max(to_number(i.premium_rcv_detail_code))+1 from ins_premium_det i),'"&D5&"','"&D5&"','02', '11000003','00','Request by Mr. Saqib Saleem 13-Jan-2024');" -> ('13Jan250053','070000171538','36750',(select max(to_number(i.premium_rcv_detail_code))+1 from ins_premium_det i),'36750','36750','02', '11000003','00','Request by Mr. Saqib Saleem 13-Jan-2024'); | H5: =F5&G5 -> insert into ins_premium_det (premium_rcv_code,assorted_code, rec_amount,premium_rcv_detail_code,remaining_amt, payrec, mode_code,coinsurance_code,class_cd,it_remarks) values('13Jan250053','070000171538','36750',(select max(to_number(i.premium_rcv_detail_code))+1 from ins_premium_det i),'36750','36750','02', '11000003','00','Request by Mr. Saqib Saleem 13-Jan-2024');
A6: KHI/HO/D/MO/PC COMP/C/103276/2/12/2024 | B6: =VLOOKUP(A6,POLICY!B:C,2,0) -> 070000171536 | C6: 53288 | D6: =ROUND(C6,0) -> 53288 | E6: 13Jan250053 | F6: ="insert into ins_premium_det (premium_rcv_code,assorted_code, rec_amount,premium_rcv_detail_code,remaining_amt, payrec, mode_code,coinsurance_code,class_cd,it_remarks) values" -> insert into ins_premium_det (premium_rcv_code,assorted_code, rec_amount,premium_rcv_detail_code,remaining_amt, payrec, mode_code,coinsurance_code,class_cd,it_remarks) values | G6: ="('"&E6&"','"&B6&"','"&D6&"',(select max(to_number(i.premium_rcv_detail_code))+1 from ins_premium_det i),'"&D6&"','"&D6&"','02', '11000003','00','Request by Mr. Saqib Saleem 13-Jan-2024');" -> ('13Jan250053','070000171536','53288',(select max(to_number(i.premium_rcv_detail_code))+1 from ins_premium_det i),'53288','53288','02', '11000003','00','Request by Mr. Saqib Saleem 13-Jan-2024'); | H6: =F6&G6 -> insert into ins_premium_det (premium_rcv_code,assorted_code, rec_amount,premium_rcv_detail_code,remaining_amt, payrec, mode_code,coinsurance_code,class_cd,it_remarks) values('13Jan250053','070000171536','53288',(select max(to_number(i.premium_rcv_detail_code))+1 from ins_premium_det i),'53288','53288','02', '11000003','00','Request by Mr. Saqib Saleem 13-Jan-2024');
A7: KHI/HO/D/MO/PC COMP/C/103276/12/12/2024 | B7: =VLOOKUP(A7,POLICY!B:C,2,0) -> 070000171610 | C7: 47373 | D7: =ROUND(C7,0) -> 47373 | E7: 13Jan250053 | F7: ="insert into ins_premium_det (premium_rcv_code,assorted_code, rec_amount,premium_rcv_detail_code,remaining_amt, payrec, mode_code,coinsurance_code,class_cd,it_remarks) values" -> insert into ins_premium_det (premium_rcv_code,assorted_code, rec_amount,premium_rcv_detail_code,remaining_amt, payrec, mode_code,coinsurance_code,class_cd,it_remarks) values | G7: ="('"&E7&"','"&B7&"','"&D7&"',(select max(to_number(i.premium_rcv_detail_code))+1 from ins_premium_det i),'"&D7&"','"&D7&"','02', '11000003','00','Request by Mr. Saqib Saleem 13-Jan-2024');" -> ('13Jan250053','070000171610','47373',(select max(to_number(i.premium_rcv_detail_code))+1 from ins_premium_det i),'47373','47373','02', '11000003','00','Request by Mr. Saqib Saleem 13-Jan-2024'); | H7: =F7&G7 -> insert into ins_premium_det (premium_rcv_code,assorted_code, rec_amount,premium_rcv_detail_code,remaining_amt, payrec, mode_code,coinsurance_code,class_cd,it_remarks) values('13Jan250053','070000171610','47373',(select max(to_number(i.premium_rcv_detail_code))+1 from ins_premium_det i),'47373','47373','02', '11000003','00','Request by Mr. Saqib Saleem 13-Jan-2024');
A8: KHI/HO/D/MO/PC COMP/C/103276/14/12/2024 | B8: =VLOOKUP(A8,POLICY!B:C,2,0) -> 070000171616 | C8: 37625 | D8: =ROUND(C8,0) -> 37625 | E8: 13Jan250053 | F8: ="insert into ins_premium_det (premium_rcv_code,assorted_code, rec_amount,premium_rcv_detail_code,remaining_amt, payrec, mode_code,coinsurance_code,class_cd,it_remarks) values" -> insert into ins_premium_det (premium_rcv_code,assorted_code, rec_amount,premium_rcv_detail_code,remaining_amt, payrec, mode_code,coinsurance_code,class_cd,it_remarks) values | G8: ="('"&E8&"','"&B8&"','"&D8&"',(select max(to_number(i.premium_rcv_detail_code))+1 from ins_premium_det i),'"&D8&"','"&D8&"','02', '11000003','00','Request by Mr. Saqib Saleem 13-Jan-2024');" -> ('13Jan250053','070000171616','37625',(select max(to_number(i.premium_rcv_detail_code))+1 from ins_premium_det i),'37625','37625','02', '11000003','00','Request by Mr. Saqib Saleem 13-Jan-2024'); | H8: =F8&G8 -> insert into ins_premium_det (premium_rcv_code,assorted_code, rec_amount,premium_rcv_detail_code,remaining_amt, payrec, mode_code,coinsurance_code,class_cd,it_remarks) values('13Jan250053','070000171616','37625',(select max(to_number(i.premium_rcv_detail_code))+1 from ins_premium_det i),'37625','37625','02', '11000003','00','Request by Mr. Saqib Saleem 13-Jan-2024');
A9: KHI/HO/D/MO/PC COMP/C/103276/24/12/2024 | B9: =VLOOKUP(A9,POLICY!B:C,2,0) -> 070000171750 | C9: 39025 | D9: =ROUND(C9,0) -> 39025 | E9: 13Jan250053 | F9: ="insert into ins_premium_det (premium_rcv_code,assorted_code, rec_amount,premium_rcv_detail_code,remaining_amt, payrec, mode_code,coinsurance_code,class_cd,it_remarks) values" -> insert into ins_premium_det (premium_rcv_code,assorted_code, rec_amount,premium_rcv_detail_code,remaining_amt, payrec, mode_code,coinsurance_code,class_cd,it_remarks) values | G9: ="('"&E9&"','"&B9&"','"&D9&"',(select max(to_number(i.premium_rcv_detail_code))+1 from ins_premium_det i),'"&D9&"','"&D9&"','02', '11000003','00','Request by Mr. Saqib Saleem 13-Jan-2024');" -> ('13Jan250053','070000171750','39025',(select max(to_number(i.premium_rcv_detail_code))+1 from ins_premium_det i),'39025','39025','02', '11000003','00','Request by Mr. Saqib Saleem 13-Jan-2024'); | H9: =F9&G9 -> insert into ins_premium_det (premium_rcv_code,assorted_code, rec_amount,premium_rcv_detail_code,remaining_amt, payrec, mode_code,coinsurance_code,class_cd,it_remarks) values('13Jan250053','070000171750','39025',(select max(to_number(i.premium_rcv_detail_code))+1 from ins_premium_det i),'39025','39025','02', '11000003','00','Request by Mr. Saqib Saleem 13-Jan-2024');
A10: KHI/HO/D/MO/PC COMP/C/103276/25/12/2024 | B10: =VLOOKUP(A10,POLICY!B:C,2,0) -> 070000171751 | C10: 39550 | D10: =ROUND(C10,0) -> 39550 | E10: 13Jan250053 | F10: ="insert into ins_premium_det (premium_rcv_code,assorted_code, rec_amount,premium_rcv_detail_code,remaining_amt, payrec, mode_code,coinsurance_code,class_cd,it_remarks) values" -> insert into ins_premium_det (premium_rcv_code,assorted_code, rec_amount,premium_rcv_detail_code,remaining_amt, payrec, mode_code,coinsurance_code,class_cd,it_remarks) values | G10: ="('"&E10&"','"&B10&"','"&D10&"',(select max(to_number(i.premium_rcv_detail_code))+1 from ins_premium_det i),'"&D10&"','"&D10&"','02', '11000003','00','Request by Mr. Saqib Saleem 13-Jan-2024');" -> ('13Jan250053','070000171751','39550',(select max(to_number(i.premium_rcv_detail_code))+1 from ins_premium_det i),'39550','39550','02', '11000003','00','Request by Mr. Saqib Saleem 13-Jan-2024'); | H10: =F10&G10 -> insert into ins_premium_det (premium_rcv_code,assorted_code, rec_amount,premium_rcv_detail_code,remaining_amt, payrec, mode_code,coinsurance_code,class_cd,it_remarks) values('13Jan250053','070000171751','39550',(select max(to_number(i.premium_rcv_detail_code))+1 from ins_premium_det i),'39550','39550','02', '11000003','00','Request by Mr. Saqib Saleem 13-Jan-2024');
A11: KHI/HO/D/MO/PC COMP/C/103276/25/12/2024 | B11: =VLOOKUP(A11,POLICY!B:C,2,0) -> 070000171751 | C11: 39550 | D11: =ROUND(C11,0) -> 39550 | E11: 13Jan250053 | F11: ="insert into ins_premium_det (premium_rcv_code,assorted_code, rec_amount,premium_rcv_detail_code,remaining_amt, payrec, mode_code,coinsurance_code,class_cd,it_remarks) values" -> insert into ins_premium_det (premium_rcv_code,assorted_code, rec_amount,premium_rcv_detail_code,remaining_amt, payrec, mode_code,coinsurance_code,class_cd,it_remarks) values | G11: ="('"&E11&"','"&B11&"','"&D11&"',(select max(to_number(i.premium_rcv_detail_code))+1 from ins_premium_det i),'"&D11&"','"&D11&"','02', '11000003','00','Request by Mr. Saqib Saleem 13-Jan-2024');" -> ('13Jan250053','070000171751','39550',(select max(to_number(i.premium_rcv_detail_code))+1 from ins_premium_det i),'39550','39550','02', '11000003','00','Request by Mr. Saqib Saleem 13-Jan-2024'); | H11: =F11&G11 -> insert into ins_premium_det (premium_rcv_code,assorted_code, rec_amount,premium_rcv_detail_code,remaining_amt, payrec, mode_code,coinsurance_code,class_cd,it_remarks) values('13Jan250053','070000171751','39550',(select max(to_number(i.premium_rcv_detail_code))+1 from ins_premium_det i),'39550','39550','02', '11000003','00','Request by Mr. Saqib Saleem 13-Jan-2024');
A12: KHI/HO/D/MO/PC COMP/C/103276/39/12/2024 | B12: =VLOOKUP(A12,POLICY!B:C,2,0) -> 070000172622 | C12: 68250 | D12: =ROUND(C12,0) -> 68250 | E12: 13Jan250053 | F12: ="insert into ins_premium_det (premium_rcv_code,assorted_code, rec_amount,premium_rcv_detail_code,remaining_amt, payrec, mode_code,coinsurance_code,class_cd,it_remarks) values" -> insert into ins_premium_det (premium_rcv_code,assorted_code, rec_amount,premium_rcv_detail_code,remaining_amt, payrec, mode_code,coinsurance_code,class_cd,it_remarks) values | G12: ="('"&E12&"','"&B12&"','"&D12&"',(select max(to_number(i.premium_rcv_detail_code))+1 from ins_premium_det i),'"&D12&"','"&D12&"','02', '11000003','00','Request by Mr. Saqib Saleem 13-Jan-2024');" -> ('13Jan250053','070000172622','68250',(select max(to_number(i.premium_rcv_detail_code))+1 from ins_premium_det i),'68250','68250','02', '11000003','00','Request by Mr. Saqib Saleem 13-Jan-2024'); | H12: =F12&G12 -> insert into ins_premium_det (premium_rcv_code,assorted_code, rec_amount,premium_rcv_detail_code,remaining_amt, payrec, mode_code,coinsurance_code,class_cd,it_remarks) values('13Jan250053','070000172622','68250',(select max(to_number(i.premium_rcv_detail_code))+1 from ins_premium_det i),'68250','68250','02', '11000003','00','Request by Mr. Saqib Saleem 13-Jan-2024');
A13: KHI/HO/D/MO/PC COMP/C/103276/33/12/2024 | B13: =VLOOKUP(A13,POLICY!B:C,2,0) -> 070000172304 | C13: 53288 | D13: =ROUND(C13,0) -> 53288 | E13: 13Jan250053 | F13: ="insert into ins_premium_det (premium_rcv_code,assorted_code, rec_amount,premium_rcv_detail_code,remaining_amt, payrec, mode_code,coinsurance_code,class_cd,it_remarks) values" -> insert into ins_premium_det (premium_rcv_code,assorted_code, rec_amount,premium_rcv_detail_code,remaining_amt, payrec, mode_code,coinsurance_code,class_cd,it_remarks) values | G13: ="('"&E13&"','"&B13&"','"&D13&"',(select max(to_number(i.premium_rcv_detail_code))+1 from ins_premium_det i),'"&D13&"','"&D13&"','02', '11000003','00','Request by Mr. Saqib Saleem 13-Jan-2024');" -> ('13Jan250053','070000172304','53288',(select max(to_number(i.premium_rcv_detail_code))+1 from ins_premium_det i),'53288','53288','02', '11000003','00','Request by Mr. Saqib Saleem 13-Jan-2024'); | H13: =F13&G13 -> insert into ins_premium_det (premium_rcv_code,assorted_code, rec_amount,premium_rcv_detail_code,remaining_amt, payrec, mode_code,coinsurance_code,class_cd,it_remarks) values('13Jan250053','070000172304','53288',(select max(to_number(i.premium_rcv_detail_code))+1 from ins_premium_det i),'53288','53288','02', '11000003','00','Request by Mr. Saqib Saleem 13-Jan-2024');
... A86: KHI/HO/D/MO/PC COMP/C/105332/22/01/2025 | B86: =VLOOKUP(A86,POLICY!B:C,2,0) -> 070000173922 | C86: 82583 | D86: =ROUND(C86,0) -> 82583 | E86: 13Jan250053 | F86: ="insert into ins_premium_det (premium_rcv_code,assorted_code, rec_amount,premium_rcv_detail_code,remaining_amt, payrec, mode_code,coinsurance_code,class_cd,it_remarks) values" -> insert into ins_premium_det (premium_rcv_code,assorted_code, rec_amount,premium_rcv_detail_code,remaining_amt, payrec, mode_code,coinsurance_code,class_cd,it_remarks) values | G86: ="('"&E86&"','"&B86&"','"&D86&"',(select max(to_number(i.premium_rcv_detail_code))+1 from ins_premium_det i),'"&D86&"','"&D86&"','02', '11000003','00','Request by Mr. Saqib Saleem 13-Jan-2024');" -> ('13Jan250053','070000173922','82583',(select max(to_number(i.premium_rcv_detail_code))+1 from ins_premium_det i),'82583','82583','02', '11000003','00','Request by Mr. Saqib Saleem 13-Jan-2024'); | H86: =F86&G86 -> insert into ins_premium_det (premium_rcv_code,assorted_code, rec_amount,premium_rcv_detail_code,remaining_amt, payrec, mode_code,coinsurance_code,class_cd,it_remarks) values('13Jan250053','070000173922','82583',(select max(to_number(i.premium_rcv_detail_code))+1 from ins_premium_det i),'82583','82583','02', '11000003','00','Request by Mr. Saqib Saleem 13-Jan-2024');
C88: =SUM(C2:C86) -> 5562764 | D88: =SUM(D2:D86) -> 5562764

Sheet Sheet1
H1: A
A2: KHI/HO/D/MO/PC COMP/C/103276/18/12/2024 | B2: -12-2024 | H2: 103276 | I2: 00018 | J2: ="ia.assorted_string like '%"&H2&"-"&I2&B2&"%' or" -> ia.assorted_string like '%103276-00018-12-2024%' or
A3: KHI/HO/D/MO/PC COMP/C/103276/1/12/2024 | B3: -12-2024 | H3: 103276 | I3: 00001 | J3: ="ia.assorted_string like '%"&H3&"-"&I3&B3&"%' or" -> ia.assorted_string like '%103276-00001-12-2024%' or
A4: KHI/HO/D/MO/PC COMP/C/103276/6/12/2024 | B4: -12-2024 | H4: 103276 | I4: 00006 | J4: ="ia.assorted_string like '%"&H4&"-"&I4&B4&"%' or" -> ia.assorted_string like '%103276-00006-12-2024%' or
A5: KHI/HO/D/MO/PC COMP/C/103276/4/12/2024 | B5: -12-2024 | H5: 103276 | I5: 00004 | J5: ="ia.assorted_string like '%"&H5&"-"&I5&B5&"%' or" -> ia.assorted_string like '%103276-00004-12-2024%' or
A6: KHI/HO/D/MO/PC COMP/C/103276/2/12/2024 | B6: -12-2024 | H6: 103276 | I6: 00002 | J6: ="ia.assorted_string like '%"&H6&"-"&I6&B6&"%' or" -> ia.assorted_string like '%103276-00002-12-2024%' or
A7: KHI/HO/D/MO/PC COMP/C/103276/12/12/2024 | B7: -12-2024 | H7: 103276 | I7: 00012 | J7: ="ia.assorted_string like '%"&H7&"-"&I7&B7&"%' or" -> ia.assorted_string like '%103276-00012-12-2024%' or
A8: KHI/HO/D/MO/PC COMP/C/103276/14/12/2024 | B8: -12-2024 | H8: 103276 | I8: 00014 | J8: ="ia.assorted_string like '%"&H8&"-"&I8&B8&"%' or" -> ia.assorted_string like '%103276-00014-12-2024%' or
A9: KHI/HO/D/MO/PC COMP/C/103276/24/12/2024 | B9: -12-2024 | H9: 103276 | I9: 00024 | J9: ="ia.assorted_string like '%"&H9&"-"&I9&B9&"%' or" -> ia.assorted_string like '%103276-00024-12-2024%' or
A10: KHI/HO/D/MO/PC COMP/C/103276/25/12/2024 | B10: -12-2024 | H10: 103276 | I10: 00025 | J10: ="ia.assorted_string like '%"&H10&"-"&I10&B10&"%' or" -> ia.assorted_string like '%103276-00025-12-2024%' or
A11: KHI/HO/D/MO/PC COMP/C/103276/25/12/2024 | B11: -12-2024 | H11: 103276 | I11: 00025 | J11: ="ia.assorted_string like '%"&H11&"-"&I11&B11&"%' or" -> ia.assorted_string like '%103276-00025-12-2024%' or
A12: KHI/HO/D/MO/PC COMP/C/103276/39/12/2024 | B12: -12-2024 | H12: 103276 | I12: 00039 | J12: ="ia.assorted_string like '%"&H12&"-"&I12&B12&"%' or" -> ia.assorted_string like '%103276-00039-12-2024%' or
A13: KHI/HO/D/MO/PC COMP/C/103276/33/12/2024 | B13: -12-2024 | H13: 103276 | I13: 00033 | J13: ="ia.assorted_string like '%"&H13&"-"&I13&B13&"%' or" -> ia.assorted_string like '%103276-00033-12-2024%' or
... A86: KHI/HO/D/MO/PC COMP/C/105332/22/01/2025 | B86: -01-2025 | H86: 105332 | I86: 00022 | J86: ="ia.assorted_string like '%"&H86&"-"&I86&B86&"%' or" -> ia.assorted_string like '%105332-00022-01-2025%' or

Sheet POLICY
B1: FUNC_ASSORTED_STRING(IA.ASSORTED_CODE) | C1: ASSORTED_CODE
A2: 1 | B2: KHI/HO/D/MO/PC COMP/C/103276/56/12/2024 | C2: 070000172816
A3: 2 | B3: KHI/HO/D/MO/PC COMP/C/101257/64/11/2024 | C3: 070000171335
A4: 3 | B4: KHI/HO/D/MO/PC COMP/C/103276/25/12/2024 | C4: 070000171751
A5: 4 | B5: KHI/HO/D/MO/PC COMP/C/103276/60/12/2024 | C5: 070000172884
A6: 5 | B6: KHI/HO/D/MO/PC COMP/C/103276/36/12/2024 | C6: 070000172311
A7: 6 | B7: KHI/HO/D/MO/PC COMP/C/103276/75/12/2024 | C7: 070000173572
A8: 7 | B8: KHI/HO/D/MO/PC COMP/C/103276/76/12/2024 | C8: 070000173576
A9: 8 | B9: KHI/HO/D/MO/PC COMP/C/103276/79/12/2024 | C9: 070000173585
A10: 9 | B10: KHI/HO/D/MO/PC COMP/C/103276/80/12/2024 | C10: 070000173586
A11: 10 | B11: KHI/HO/D/MO/PC COMP/C/103276/52/12/2024 | C11: 070000172805
A12: 11 | B12: KHI/HO/D/MO/PC COMP/C/103276/63/12/2024 | C12: 070000173484
A13: 12 | B13: KHI/HO/D/MO/PC COMP/C/103276/64/12/2024 | C13: 070000173485
... A85: 84 | B85: KHI/HO/D/MO/PC COMP/C/103276/11/12/2024 | C85: 070000171607
