Workbook

Sheet Sheet2
AC1: =SUBTOTAL(9,AC3:AC1740) -> 81176
A2: S.No. | B2: Policy | C2: Endorsement | D2: Branch CoverNote No. | E2: Class | F2: Issue Date | G2: Period From | H2: Period To | I2: Client Code | J2: Client Name | K2: Insured Name | L2: Vehicle Name | M2: REG | N2: ENGINE | O2: CHASSIS | P2: MODEL | Q2: NIC | R2: MOBILE | S2: Type | T2: AGENCY CODE | U2: Sum Covered | V2: Gross | W2: FIF | X2: FED | Y2: SD | Z2: Net | AA2: Paid | AB2: Co Paid | AC2: Outstanding | AD2: Not Due | AE2: Due | AF2: Leader Name | AG2: Leader Policy No | AH2: Leader Endr No | AI2: Custodian Name | AJ2: Actual Milage | AK2: Charge Milage | AL2: EMAIL
A3: 2 | B3: KHI/HO/D/MO/PD COMP/P/55880/09/2021 | C3: KHI/HO/D/MO/PD COMP/E/18327/12/2021 | D3: - | E3: MOTOR | F3: 44552 | G3: 44460 | H3: 44824 | I3: 08802641 | J3: Mr. Muhammad Ramzan CNIC# 17101-4623280-9 CELL# 0333-9558134 / 0347-9002576 | L3: TOYOTA COROLLA XLI | M3: WD-206 | N3: Y558252 | O3: NZE140-2138364 | P3: 2012 | Q3: 17101-4623280-9 | S3: D | T3: 09000221-Muhammad Irfan | U3: 1900000 | V3: 1956 | W3: 20 | X3: 255 | Y3: 0 | Z3: 2231 | AA3: 0 | AB3: 0 | AC3: 2231 | AD3: 0 | AE3: 2231 | AL3: mayazkhan957@gmail.com
A4: 3 | B4: KHI/HO/D/MO/PD COMP/P/55880/09/2021 | C4: KHI/HO/D/MO/PD COMP/E/48693/10/2024 | D4: - | E4: MOTOR | F4: 45596 | G4: 44460 | H4: 44824 | I4: 08802641 | J4: Mr. Muhammad Ramzan CNIC# 17101-4623280-9 CELL# 0333-9558134 / 0347-9002576 | L4: TOYOTA COROLLA XLI | M4: WD-206 | N4: Y558252 | O4: NZE140-2138364 | P4: 2012 | Q4: 17101-4623280-9 | S4: D | T4: 09000221-Muhammad Irfan | U4: -1 | V4: -2209 | W4: -22 | X4: 0 | Y4: 0 | Z4: -2231 | AA4: 0 | AB4: 0 | AC4: -2231 | AD4: 0 | AE4: -2231
A5: 4 | B5: KHI/HO/D/MO/PD COMP/P/56730/11/2021 | C5: KHI/HO/D/MO/PD COMP/E/18537/01/2022 | D5: - | E5: MOTOR | F5: 44592 | G5: 44508 | H5: 44872 | I5: 08803143 | J5: Ms. Mumtaz Bushra CELL# 03348706662 | L5: NISSAN DAYZ | M5: AHY-973 | N5: 3B20-JY6220 | O5: B21W-0222046 | P5: 2015 | Q5: 33100-4566935-6 | S5: D | T5: 09000221-Muhammad Irfan | U5: 1400000 | V5: 2436 | W5: 25 | X5: 316 | Y5: 0 | Z5: 2777 | AA5: 813 | AB5: 0 | AC5: 1964 | AD5: 0 | AE5: 1964
A6: 5 | B6: KHI/HO/D/MO/PD COMP/P/56730/11/2021 | C6: KHI/HO/D/MO/PD COMP/E/21803/10/2022 | D6: - | E6: MOTOR | F6: 44845 | G6: 44508 | H6: 44872 | I6: 08803143 | J6: Ms. Mumtaz Bushra CELL# 03348706662 | L6: NISSAN DAYZ | M6: AHY-973 | N6: 3B20-JY6220 | O6: B21W-0222046 | P6: 2015 | Q6: 33100-4566935-6 | S6: D | T6: 09000221-Muhammad Irfan | U6: 1400000 | V6: 1124 | W6: 12 | X6: 146 | Y6: 0 | Z6: 1282 | AA6: 0 | AB6: 0 | AC6: 1282 | AD6: 0 | AE6: 1282 | AJ6: 2106.4182 | AK6: 1327.8243
A7: 6 | B7: KHI/HO/D/MO/PD COMP/P/56730/11/2021 | C7: KHI/HO/D/MO/PD COMP/E/48694/10/2024 | D7: - | E7: MOTOR | F7: 45596 | G7: 44508 | H7: 44872 | I7: 08803143 | J7: Ms. Mumtaz Bushra CELL# 03348706662 | L7: NISSAN DAYZ | M7: AHY-973 | N7: 3B20-JY6220 | O7: B21W-0222046 | P7: 2015 | Q7: 33100-4566935-6 | S7: D | T7: 09000221-Muhammad Irfan | U7: -1 | V7: -3214 | W7: -32 | X7: 0 | Y7: 0 | Z7: -3246 | AA7: 0 | AB7: 0 | AC7: -3246 | AD7: 0 | AE7: -3246
A8: 7 | B8: KHI/HO/D/MO/PD COMP/P/56778/11/2021 | C8: KHI/HO/D/MO/PD COMP/E/18227/12/2021 | D8: - | E8: MOTOR | F8: 44542 | G8: 44511 | H8: 44875 | I8: 08803172 | J8: Mr. Waqas Khan CNIC # 61101-0177170-1 NTN # 2881163-1 CELL # 0321-5048444 | L8: TOYOTA COROLLA ALTIS GRAN | N8: Q347055 | O8: ZRE172R-7046163 | P8: 2020 | S8: D | T8: 09000248-Hassan Malik | U8: 3899000 | V8: 4533 | W8: 46 | X8: 590 | Y8: 0 | Z8: 5169 | AA8: 0 | AB8: 0 | AC8: 5169 | AD8: 0 | AE8: 5169
A9: 8 | B9: KHI/HO/D/MO/PD COMP/P/56778/11/2021 | C9: KHI/HO/D/MO/PD COMP/E/21801/10/2022 | D9: - | E9: MOTOR | F9: 44845 | G9: 44511 | H9: 44875 | I9: 08803172 | J9: Mr. Waqas Khan CNIC # 61101-0177170-1 NTN # 2881163-1 CELL # 0321-5048444 | L9: TOYOTA COROLLA ALTIS GRAN | N9: Q347055 | O9: ZRE172R-7046163 | P9: 2020 | S9: D | T9: 09000248-Hassan Malik | U9: 3899000 | V9: 3613 | W9: 36 | X9: 469 | Y9: 0 | Z9: 4118 | AA9: 0 | AB9: 0 | AC9: 4118 | AD9: 0 | AE9: 4118 | AJ9: 1835.0036 | AK9: 1534.1142
A10: 9 | B10: KHI/HO/D/MO/PD COMP/P/56778/11/2021 | C10: KHI/HO/D/MO/PD COMP/E/48695/10/2024 | D10: - | E10: MOTOR | F10: 45596 | G10: 44511 | H10: 44875 | I10: 08803172 | J10: Mr. Waqas Khan CNIC # 61101-0177170-1 NTN # 2881163-1 CELL # 0321-5048444 | L10: TOYOTA COROLLA ALTIS GRAN | N10: Q347055 | O10: ZRE172R-7046163 | P10: 2020 | S10: D | T10: 09000248-Hassan Malik | U10: -1 | V10: -9195 | W10: -92 | X10: 0 | Y10: 0 | Z10: -9287 | AA10: 0 | AB10: 0 | AC10: -9287 | AD10: 0 | AE10: -9287
A11: 10 | B11: KHI/HO/D/MO/PD COMP/P/56936/11/2021 | C11: KHI/HO/D/MO/PD COMP/E/22006/11/2022 | D11: - | E11: MOTOR | F11: 44867 | G11: 44518 | H11: 44882 | I11: 08802248 | J11: M/S. ARIF HABIB LIMITED User: Mr. Amir Hassan Cell No: 03218282839 | L11: SUZUKI ALTO AGS A/T | N11: 193511 | O11: 1093470 | P11: 2021 | S11: D | T11: 09000313-Abdus Saboor Khan | U11: 1950000 | V11: 889 | W11: 9 | X11: 115 | Y11: 0 | Z11: 1013 | AA11: 0 | AB11: 0 | AC11: 1013 | AD11: 0 | AE11: 1013 | AJ11: 828.1602 | AK11: 755.8009
A12: 11 | B12: KHI/HO/D/MO/PD COMP/P/56936/11/2021 | C12: KHI/HO/D/MO/PD COMP/E/48793/10/2024 | D12: - | E12: MOTOR | F12: 45596 | G12: 44518 | H12: 44882 | I12: 08802248 | J12: M/S. ARIF HABIB LIMITED User: Mr. Amir Hassan Cell No: 03218282839 | L12: SUZUKI ALTO AGS A/T | N12: 193511 | O12: 1093470 | P12: 2021 | S12: D | T12: 09000313-Abdus Saboor Khan | U12: -1 | V12: -1003 | W12: -10 | X12: 0 | Y12: 0 | Z12: -1013 | AA12: 0 | AB12: 0 | AC12: -1013 | AD12: 0 | AE12: -1013
A13: 20 | B13: KHI/HO/D/MO/PD COMP/P/58087/01/2022 | C13: KHI/HO/D/MO/PD COMP/E/18671/02/2022 | D13: - | E13: MOTOR | F13: 44597 | G13: 44565 | H13: 44929 | I13: 08804041 | J13: Mr. Masud Mir CNIC# 35202-2821316-9 Cell No. 0300-4138769 | L13: SUZUKI SWIFT GL M/T | M13: LE-4079 | N13: 13004044 | O13: PK10004039 | P13: 2011 | S13: D | T13: 09000221-Muhammad Irfan | U13: 1400000 | V13: 92 | W13: 1 | X13: 12 | Y13: 0 | Z13: 105 | AA13: 0 | AB13: 0 | AC13: 105 | AD13: 0 | AE13: 105 | AL13: musaudmir1932@gmail.com
A14: 21 | B14: KHI/HO/D/MO/PD COMP/P/58087/01/2022 | C14: KHI/HO/D/MO/PD COMP/E/19615/05/2022 | D14: - | E14: MOTOR | F14: 44687 | G14: 44565 | H14: 44929 | I14: 08804041 | J14: Mr. Masud Mir CNIC# 35202-2821316-9 Cell No. 0300-4138769 | L14: SUZUKI SWIFT GL M/T | M14: LE-4079 | N14: 13004044 | O14: PK10004039 | P14: 2011 | S14: D | T14: 09000221-Muhammad Irfan | U14: 1400000 | V14: 1081 | W14: 11 | X14: 140 | Y14: 0 | Z14: 1232 | AA14: 0 | AB14: 0 | AC14: 1232 | AD14: 0 | AE14: 1232 | AL14: musaudmir1932@gmail.com
A15: 22 | B15: KHI/HO/D/MO/PD COMP/P/58087/01/2022 | C15: KHI/HO/D/MO/PD COMP/E/19649/05/2022 | D15: - | E15: MOTOR | F15: 44687 | G15: 44565 | H15: 44929 | I15: 08804041 | J15: Mr. Masud Mir CNIC# 35202-2821316-9 Cell No. 0300-4138769 | L15: SUZUKI SWIFT GL M/T | M15: LE-4079 | N15: 13004044 | O15: PK10004039 | P15: 2011 | S15: D | T15: 09000221-Muhammad Irfan | U15: 1400000 | V15: 1001 | W15: 10 | X15: 130 | Y15: 0 | Z15: 1141 | AA15: 0 | AB15: 0 | AC15: 1141 | AD15: 0 | AE15: 1141 | AL15: musaudmir1932@gmail.com
A16: 23 | B16: KHI/HO/D/MO/PD COMP/P/58087/01/2022 | C16: KHI/HO/D/MO/PD COMP/E/21806/10/2022 | D16: - | E16: MOTOR | F16: 44845 | G16: 44565 | H16: 44929 | I16: 08804041 | J16: Mr. Masud Mir CNIC# 35202-2821316-9 Cell No. 0300-4138769 | L16: SUZUKI SWIFT GL M/T | M16: LE-4079 | N16: 13004044 | O16: PK10004039 | P16: 2011 | S16: D | T16: 09000221-Muhammad Irfan | U16: 1400000 | V16: 93 | W16: 1 | X16: 11 | Y16: 0 | Z16: 105 | AA16: 0 | AB16: 0 | AC16: 105 | AD16: 0 | AE16: 105 | AJ16: 108.84577 | AK16: 108.84577 | AL16: musaudmir1932@gmail.com
A17: 24 | B17: KHI/HO/D/MO/PD COMP/P/58087/01/2022 | C17: KHI/HO/D/MO/PD COMP/E/50450/12/2024 | D17: - | E17: MOTOR | F17: 45655 | G17: 44565 | H17: 44929 | I17: 08804041 | J17: Mr. Masud Mir CNIC# 35202-2821316-9 Cell No. 0300-4138769 | L17: SUZUKI SWIFT GL M/T | M17: LE-4079 | N17: 13004044 | O17: PK10004039 | P17: 2011 | S17: D | T17: 09000221-Muhammad Irfan | U17: -1 | V17: -2265 | W17: -23 | X17: -295 | Y17: 0 | Z17: -2583 | AA17: 0 | AB17: 0 | AC17: -2583 | AD17: 0 | AE17: -2583
A18: 25 | B18: KHI/HO/D/MO/PD COMP/P/58088/01/2022 | C18: KHI/HO/D/MO/PD COMP/E/22012/11/2022 | D18: - | E18: MOTOR | F18: 44867 | G18: 44574 | H18: 44938 | I18: 08804042 | J18: Mr. Yasar Sattar CNIC# 91506-0139010-5 CELL# 03104166440 | L18: MG HS 1.5 T | M18: AGK-572 | N18: 3150636 | O18: 063373 | P18: 2021 | S18: D | T18: 09000324-Smart PFM (Pvt.) Limited | U18: 5600000 | V18: 203 | W18: 2 | X18: 26 | Y18: 0 | Z18: 231 | AA18: 0 | AB18: 0 | AC18: 231 | AD18: 0 | AE18: 231 | AJ18: 59.711286 | AK18: 59.711286 | AL18: starcom647@yahoo.com
A19: 26 | B19: KHI/HO/D/MO/PD COMP/P/58088/01/2022 | C19: KHI/HO/D/MO/PD COMP/E/22239/11/2022 | D19: - | E19: MOTOR | F19: 44888 | G19: 44574 | H19: 44938 | I19: 08804042 | J19: Mr. Yasar Sattar CNIC# 91506-0139010-5 CELL# 03104166440 | L19: MG HS 1.5 T | M19: AGK-572 | N19: 3150636 | O19: 063373 | P19: 2021 | S19: D | T19: 09000324-Smart PFM (Pvt.) Limited | U19: 5600000 | V19: 669 | W19: 6 | X19: 87 | Y19: 0 | Z19: 762 | AA19: 0 | AB19: 0 | AC19: 762 | AD19: 0 | AE19: 762 | AJ19: 197.49643 | AK19: 197.49643 | AL19: starcom647@yahoo.com
A20: 27 | B20: KHI/HO/D/MO/PD COMP/P/58088/01/2022 | C20: KHI/HO/D/MO/PD COMP/E/50451/12/2024 | D20: - | E20: MOTOR | F20: 45655 | G20: 44574 | H20: 44938 | I20: 08804042 | J20: Mr. Yasar Sattar CNIC# 91506-0139010-5 CELL# 03104166440 | L20: MG HS 1.5 T | M20: AGK-572 | N20: 3150636 | O20: 063373 | P20: 2021 | S20: D | T20: 09000324-Smart PFM (Pvt.) Limited | U20: -1 | V20: -871 | W20: -9 | X20: -113 | Y20: 0 | Z20: -993 | AA20: 0 | AB20: 0 | AC20: -993 | AD20: 0 | AE20: -993
A21: 29 | B21: KHI/HO/D/MO/PD COMP/P/58180/01/2022 | C21: KHI/HO/D/MO/PD COMP/E/18762/02/2022 | D21: - | E21: MOTOR | F21: 44609 | G21: 44578 | H21: 44942 | I21: 08804115 | J21: Mr. Shaikh Muhammad Usama Noman CNIC# 4220193638919 Cell No. 03443014737 | L21: DAIHATSU MIRA | M21: BLN-782 | N21: KF-J340463 | O21: LA310S-103993 | P21: 2016 | S21: D | T21: 09000324-Smart PFM (Pvt.) Limited | U21: 1400000 | V21: 145 | W21: 2 | X21: 19 | Y21: 0 | Z21: 166 | AA21: 0 | AB21: 0 | AC21: 166 | AD21: 0 | AE21: 166 | AL21: s.usama.noman@gmail.com
A22: 30 | B22: KHI/HO/D/MO/PD COMP/P/58180/01/2022 | C22: KHI/HO/D/MO/PD COMP/E/48696/10/2024 | D22: - | E22: MOTOR | F22: 45596 | G22: 44578 | H22: 44942 | I22: 08804115 | J22: Mr. Shaikh Muhammad Usama Noman CNIC# 4220193638919 Cell No. 03443014737 | L22: DAIHATSU MIRA | M22: BLN-782 | N22: KF-J340463 | O22: LA310S-103993 | P22: 2016 | S22: D | T22: 09000324-Smart PFM (Pvt.) Limited | U22: -1 | V22: -164 | W22: -2 | X22: 0 | Y22: 0 | Z22: -166 | AA22: 0 | AB22: 0 | AC22: -166 | AD22: 0 | AE22: -166
A23: 31 | B23: KHI/HO/D/MO/PD COMP/P/58224/01/2022 | C23: KHI/HO/D/MO/PD COMP/E/22027/11/2022 | D23: - | E23: MOTOR | F23: 44867 | G23: 44580 | H23: 44944 | I23: 08804148 | J23: Mr. Hassan Ahmed CNIC# 37405-4482774-7 Cell No. 03445287446 | L23: TOYOTA YARIS ATIV AT | M23: BTX-660 | N23: 2A26538 | O23: 7015943 | P23: 2021 | S23: D | T23: 09000324-Smart PFM (Pvt.) Limited | U23: 2800000 | V23: 2042 | W23: 19 | X23: 0 | Y23: 0 | Z23: 2061 | AA23: 0 | AB23: 0 | AC23: 2061 | AD23: 0 | AE23: 2061 | AJ23: 1382.6682 | AK23: 1066.2163 | AL23: hassaan_ahmed@msn.com
A24: 32 | B24: KHI/HO/D/MO/PD COMP/P/58224/01/2022 | C24: KHI/HO/D/MO/PD COMP/E/22227/11/2022 | D24: - | E24: MOTOR | F24: 44888 | G24: 44580 | H24: 44944 | I24: 08804148 | J24: Mr. Hassan Ahmed CNIC# 37405-4482774-7 Cell No. 03445287446 | L24: TOYOTA YARIS ATIV AT | M24: BTX-660 | N24: 2A26538 | O24: 7015943 | P24: 2021 | S24: D | T24: 09000324-Smart PFM (Pvt.) Limited | U24: 2800000 | V24: 341 | W24: 3 | X24: 0 | Y24: 0 | Z24: 344 | AA24: 0 | AB24: 0 | AC24: 344 | AD24: 0 | AE24: 344 | AJ24: 178.72179 | AK24: 178.72179 | AL24: hassaan_ahmed@msn.com
A25: 33 | B25: KHI/HO/D/MO/PD COMP/P/58224/01/2022 | C25: KHI/HO/D/MO/PD COMP/E/22541/12/2022 | D25: - | E25: MOTOR | F25: 44919 | G25: 44580 | H25: 44944 | I25: 08804148 | J25: Mr. Hassan Ahmed CNIC# 37405-4482774-7 Cell No. 03445287446 | K25: ... | L25: TOYOTA YARIS ATIV AT | M25: BTX-660 | N25: 2A26538 | O25: 7015943 | P25: 2021 | S25: D | T25: 09000324-Smart PFM (Pvt.) Limited | U25: 2800000 | V25: 656 | W25: 8 | X25: 395 | Y25: 0 | Z25: 1059 | AA25: 0 | AB25: 0 | AC25: 1059 | AD25: 0 | AE25: 1059 | AJ25: 704.40179 | AK25: 548.62538 | AL25: hassaan_ahmed@msn.com
A26: 34 | B26: KHI/HO/D/MO/PD COMP/P/58224/01/2022 | C26: KHI/HO/D/MO/PD COMP/E/48697/10/2024 | D26: - | E26: MOTOR | F26: 45596 | G26: 44580 | H26: 44944 | I26: 08804148 | J26: Mr. Hassan Ahmed CNIC# 37405-4482774-7 Cell No. 03445287446 | K26: ... | L26: TOYOTA YARIS ATIV AT | M26: BTX-660 | N26: 2A26538 | O26: 7015943 | P26: 2021 | S26: D | T26: 09000324-Smart PFM (Pvt.) Limited | U26: -1 | V26: -3430 | W26: -34 | X26: 0 | Y26: 0 | Z26: -3464 | AA26: 0 | AB26: 0 | AC26: -3464 | AD26: 0 | AE26: -3464
A27: 35 | B27: KHI/HO/D/MO/PD COMP/P/58234/01/2022 | D27: - | E27: MOTOR | F27: 44583 | G27: 44581 | H27: 44945 | I27: 08804155 | J27: Mr. Muhammad Ismail Mian CNIC# 35202-2462925-7 CELL# 03244370464 | L27: SUZUKI ALTO VXL | M27: AGF-857 | N27: 6R193595 | O27: NF1AET306H1093581 | P27: 2021 | S27: D | T27: 09000324-Smart PFM (Pvt.) Limited | U27: -1 | V27: 13217 | W27: 132 | X27: 1718 | Y27: 50 | Z27: 15117 | AA27: 13815 | AB27: 0 | AC27: 1302 | AD27: 0 | AE27: 1302 | AL27: muhammadwaqasrph@gmail.com
A28: 36 | B28: KHI/HO/D/MO/PD COMP/P/58234/01/2022 | C28: KHI/HO/D/MO/PD COMP/E/22226/11/2022 | D28: - | E28: MOTOR | F28: 44888 | G28: 44581 | H28: 44945 | I28: 08804155 | J28: Mr. Muhammad Ismail Mian CNIC# 35202-2462925-7 CELL# 03244370464 | L28: SUZUKI ALTO VXL | M28: AGF-857 | N28: 6R193595 | O28: NF1AET306H1093581 | P28: 2021 | S28: D | T28: 09000324-Smart PFM (Pvt.) Limited | U28: 1527000 | V28: 1451 | W28: 14 | X28: 189 | Y28: 0 | Z28: 1654 | AA28: 75 | AB28: 0 | AC28: 1579 | AD28: 0 | AE28: 1579 | AJ28: 2453.3275 | AK28: 1575.047 | AL28: muhammadwaqasrph@gmail.com
A29: 37 | B29: KHI/HO/D/MO/PD COMP/P/58234/01/2022 | C29: KHI/HO/D/MO/PD COMP/E/22607/12/2022 | D29: - | E29: MOTOR | F29: 44924 | G29: 44581 | H29: 44945 | I29: 08804155 | J29: Mr. Muhammad Ismail Mian CNIC# 35202-2462925-7 CELL# 03244370464 | L29: SUZUKI ALTO VXL | M29: AGF-857 | N29: 6R193595 | O29: NF1AET306H1093581 | P29: 2021 | S29: D | T29: 09000324-Smart PFM (Pvt.) Limited | U29: 1527000 | V29: 1420 | W29: 15 | X29: 184 | Y29: 0 | Z29: 1619 | AA29: 0 | AB29: 0 | AC29: 1619 | AD29: 0 | AE29: 1619 | AJ29: 2131.4093 | AK29: 1540.4798 | AL29: muhammadwaqasrph@gmail.com
A30: 38 | B30: KHI/HO/D/MO/PD COMP/P/58234/01/2022 | C30: KHI/HO/D/MO/PD COMP/E/48698/10/2024 | D30: - | E30: MOTOR | F30: 45596 | G30: 44581 | H30: 44945 | I30: 08804155 | J30: Mr. Muhammad Ismail Mian CNIC# 35202-2462925-7 CELL# 03244370464 | L30: SUZUKI ALTO VXL | M30: AGF-857 | N30: 6R193595 | O30: NF1AET306H1093581 | P30: 2021 | S30: D | T30: 09000324-Smart PFM (Pvt.) Limited | U30: -1 | V30: -4455 | W30: -45 | X30: 0 | Y30: 0 | Z30: -4500 | AA30: 0 | AB30: 0 | AC30: -4500 | AD30: 0 | AE30: -4500
A31: 42 | B31: KHI/HO/D/MO/PD COMP/P/58677/02/2022 | C31: KHI/HO/D/MO/PD COMP/E/21805/10/2022 | D31: - | E31: MOTOR | F31: 44845 | G31: 44593 | H31: 44957 | I31: 08804445 | J31: Miss. Syeda Bisma Haider CNIC# 42201-2639277-8 Cell No. 0345-2410113 | L31: TOYOTA PIXIS EPOCH A/T | M31: BPH-058 | N31: KF-J247694 | O31: 1036112 | P31: 2015 | S31: D | T31: 09000221-Muhammad Irfan | U31: 1612000 | V31: 3483 | W31: 35 | X31: 452 | Y31: 0 | Z31: 3970 | AA31: 0 | AB31: 0 | AC31: 3970 | AD31: 0 | AE31: 3970 | AJ31: 3715.4417 | AK31: 3587.7491 | AL31: bisma_haider@live.com
A32: 43 | B32: KHI/HO/D/MO/PD COMP/P/58677/02/2022 | C32: KHI/HO/D/MO/PD COMP/E/48700/10/2024 | D32: - | E32: MOTOR | F32: 45596 | G32: 44593 | H32: 44957 | I32: 08804445 | J32: Miss. Syeda Bisma Haider CNIC# 42201-2639277-8 Cell No. 0345-2410113 | L32: TOYOTA PIXIS EPOCH A/T | M32: BPH-058 | N32: KF-J247694 | O32: 1036112 | P32: 2015 | S32: D | T32: 09000221-Muhammad Irfan | U32: -1 | V32: -3931 | W32: -39 | X32: 0 | Y32: 0 | Z32: -3970 | AA32: 0 | AB32: 0 | AC32: -3970 | AD32: 0 | AE32: -3970 | AI32: MAHRUKH
A33: 44 | B33: KHI/HO/D/MO/PD COMP/P/58795/02/2022 | C33: KHI/HO/D/MO/PD COMP/E/22651/01/2023 | D33: - | E33: MOTOR | F33: 44929 | G33: 44585 | H33: 44949 | I33: 08804538 | J33: Mr. Abdul Malik Ghori CNIC# 42301-3931939-5 CELL# 03313334417 | K33: ..... | L33: TOYOTA COROLLA ALTIS 1.6 | M33: BSW-164 | N33: Q071086 | O33: ZRE171R-6048579 | P33: 2021 | S33: D | T33: 09000324-Smart PFM (Pvt.) Limited | U33: 3700000 | V33: 683 | W33: 7 | X33: 89 | Y33: 0 | Z33: 779 | AA33: 0 | AB33: 0 | AC33: 779 | AD33: 0 | AE33: 779 | AL33: malikghori@aol.com
A34: 45 | B34: KHI/HO/D/MO/PD COMP/P/58795/02/2022 | C34: KHI/HO/D/MO/PD COMP/E/48701/10/2024 | D34: - | E34: MOTOR | F34: 45596 | G34: 44585 | H34: 44949 | I34: 08804538 | J34: Mr. Abdul Malik Ghori CNIC# 42301-3931939-5 CELL# 03313334417 | K34: ..... | L34: TOYOTA COROLLA ALTIS 1.6 | M34: BSW-164 | N34: Q071086 | O34: ZRE171R-6048579 | P34: 2021 | S34: D | T34: 09000324-Smart PFM (Pvt.) Limited | U34: -1 | V34: -771 | W34: -8 | X34: 0 | Y34: 0 | Z34: -779 | AA34: 0 | AB34: 0 | AC34: -779 | AD34: 0 | AE34: -779
A35: 49 | B35: KHI/HO/D/MO/PD COMP/P/59606/03/2022 | C35: KHI/HO/D/MO/PD COMP/E/22261/11/2022 | D35: - | E35: MOTOR | F35: 44889 | G35: 44627 | H35: 44991 | I35: 08805070 | J35: Ms. Fahmida Sarfaraz CNIC# 35201-1539446-0 CELL# 0300-4331273 | L35: TOYOTA YARIS GLI MT | M35: ACC-629 | N35: 2A04449 | O35: NSP150R-7002240 | P35: 2020 | S35: D | T35: 09000226-Yasir Muhammad | U35: 2500000 | V35: 336 | W35: 3 | X35: 0 | Y35: 0 | Z35: 339 | AA35: 0 | AB35: 0 | AC35: 339 | AD35: 0 | AE35: 339 | AJ35: 195.47546 | AK35: 195.47546 | AL35: fahmida.safaraz@gmail.com
A36: 50 | B36: KHI/HO/D/MO/PD COMP/P/59606/03/2022 | C36: KHI/HO/D/MO/PD COMP/E/22399/12/2022 | D36: - | E36: MOTOR | F36: 44902 | G36: 44627 | H36: 44991 | I36: 08805070 | J36: Ms. Fahmida Sarfaraz CNIC# 35201-1539446-0 CELL# 0300-4331273 | L36: TOYOTA YARIS GLI MT | M36: ACC-629 | N36: 2A04449 | O36: NSP150R-7002240 | P36: 2020 | S36: D | T36: 09000226-Yasir Muhammad | U36: 2500000 | V36: 202 | W36: 2 | X36: 0 | Y36: 0 | Z36: 204 | AA36: 0 | AB36: 0 | AC36: 204 | AD36: 0 | AE36: 204 | AJ36: 118.29876 | AK36: 118.29876 | AL36: fahmida.safaraz@gmail.com
A37: 51 | B37: KHI/HO/D/MO/PD COMP/P/59606/03/2022 | C37: KHI/HO/D/MO/PD COMP/E/22778/01/2023 | D37: - | E37: MOTOR | F37: 44942 | G37: 44627 | H37: 44991 | I37: 08805070 | J37: Ms. Fahmida Sarfaraz CNIC# 35201-1539446-0 CELL# 0300-4331273 | L37: TOYOTA YARIS GLI MT | M37: ACC-629 | N37: 2A04449 | O37: NSP150R-7002240 | P37: 2020 | S37: D | T37: 09000226-Yasir Muhammad | U37: 2500000 | V37: 111 | W37: 0 | X37: 0 | Y37: 0 | Z37: 111 | AA37: 0 | AB37: 0 | AC37: 111 | AD37: 0 | AE37: 111 | AJ37: 64.672563 | AK37: 64.672563 | AL37: fahmida.safaraz@gmail.com
A38: 52 | B38: KHI/HO/D/MO/PD COMP/P/59606/03/2022 | C38: KHI/HO/D/MO/PD COMP/E/23073/02/2023 | D38: - | E38: MOTOR | F38: 44967 | G38: 44627 | H38: 44991 | I38: 08805070 | J38: Ms. Fahmida Sarfaraz CNIC# 35201-1539446-0 CELL# 0300-4331273 | L38: TOYOTA YARIS GLI MT | M38: ACC-629 | N38: 2A04449 | O38: NSP150R-7002240 | P38: 2020 | S38: D | T38: 09000226-Yasir Muhammad | U38: 2500000 | V38: 336 | W38: 3 | X38: 0 | Y38: 0 | Z38: 339 | AA38: 0 | AB38: 0 | AC38: 339 | AD38: 0 | AE38: 339 | AJ38: 197.6038 | AK38: 197.6038 | AL38: fahmida.safaraz@gmail.com
A39: 53 | B39: KHI/HO/D/MO/PD COMP/P/59606/03/2022 | C39: KHI/HO/D/MO/PD COMP/E/48703/10/2024 | D39: - | E39: MOTOR | F39: 45596 | G39: 44627 | H39: 44991 | I39: 08805070 | J39: Ms. Fahmida Sarfaraz CNIC# 35201-1539446-0 CELL# 0300-4331273 | L39: TOYOTA YARIS GLI MT | M39: ACC-629 | N39: 2A04449 | O39: NSP150R-7002240 | P39: 2020 | S39: D | T39: 09000226-Yasir Muhammad | U39: -1 | V39: -983 | W39: -10 | X39: 0 | Y39: 0 | Z39: -993 | AA39: 0 | AB39: 0 | AC39: -993 | AD39: 0 | AE39: -993
A40: 59 | B40: KHI/HO/D/MO/PD COMP/P/60210/04/2022 | C40: KHI/HO/D/MO/PD COMP/E/24332/03/2023 | D40: - | E40: MOTOR | F40: 45012 | G40: 44659 | H40: 45023 | I40: 08805421 | J40: Mr. Sheikh Rizwan Ahmed CNIC # 33100-0997944-9 CELL # 0332-7866612 / 0311-1150000 | L40: SUZUKI SWIFT GL M/T | M40: AKH-269 | N40: 13042650 | O40: 10042652 | P40: 2018 | S40: D | T40: 09000309-Zeeshan Mohi-u-din | U40: 1800000 | V40: 471 | W40: 4 | X40: 61 | Y40: 0 | Z40: 536 | AA40: 0 | AB40: 0 | AC40: 536 | AD40: 0 | AE40: 536 | AJ40: 401.53758 | AK40: 401.37383 | AL40: daudahmad.sh@gmail.com
...

Sheet Sheet3
A3: Row Labels | B3: Sum of Outstanding
A4: KHI/HO/D/MO/PD COMP/P/100636/10/2024 | B4: 0
A5: KHI/HO/D/MO/PD COMP/E/49352/11/2024 | B5: 886
A6: KHI/HO/D/MO/PD COMP/E/50422/12/2024 | B6: 14614
A7: KHI/HO/D/MO/PD COMP/E/51897/01/2025 | B7: 7860
A8: KHI/HO/D/MO/PD COMP/E/52749/02/2025 | B8: 14467
A9: KHI/HO/D/MO/PD COMP/E/58983/03/2025 | B9: 2291
A10: KHI/HO/D/MO/PD COMP/E/59235/03/2025 | B10: -40118
A11: KHI/HO/D/MO/PD COMP/P/55880/09/2021 | B11: 0
A12: KHI/HO/D/MO/PD COMP/E/18327/12/2021 | B12: 2231
A13: KHI/HO/D/MO/PD COMP/E/48693/10/2024 | B13: -2231
A14: KHI/HO/D/MO/PD COMP/P/56730/11/2021 | B14: 0
A15: KHI/HO/D/MO/PD COMP/E/18537/01/2022 | B15: 1964
... A2088: Grand Total | B2088: 0

Sheet Sheet1
A1: Row Labels | B1: Sum of Outstanding
A2: (blank) | B2: -557 | D2: PLEASE SHARE POLICY/ENDORSEMENT AGAINST THESE BLANKS
A3: (blank) | B3: -537
A4: (blank) | B4: -454
A5: (blank) | B5: -428
A6: (blank) | B6: -404
A7: (blank) | B7: -400
A8: (blank) | B8: -374
A9: (blank) | B9: -370
A10: (blank) | B10: -362
A11: (blank) | B11: -165
A12: (blank) | B12: -102
A13: (blank) | B13: -99
A14: (blank) | B14: -99
... A2085: LHR/LHR/D/MO/PD COMP/P/72469/06/2023 | B2085: 0

Sheet FINAL LIST
A1: POLICY NO | B1: AMOUNT
A2: KHI/HO/D/MO/PD COMP/P/58234/01/2022 | B2: 1302
A3: KHI/HO/D/MO/PD COMP/P/60538/05/2022 | B3: -1
A4: KHI/HO/D/MO/PD COMP/P/61418/06/2022 | B4: -404
A5: KHI/HO/D/MO/PD COMP/P/63305/09/2022 | B5: -374
A6: KHI/HO/D/MO/PD COMP/P/66017/12/2022 | B6: -1
A7: KHI/HO/D/MO/PD COMP/P/66188/12/2022 | B7: -3
A8: KHI/HO/D/MO/PD COMP/P/66820/01/2023 | B8: -5
A9: KHI/HO/D/MO/PD COMP/P/66962/01/2023 | B9: -8
A10: KHI/HO/D/MO/PD COMP/P/66983/01/2023 | B10: -99
A11: KHI/HO/D/MO/PD COMP/P/66986/01/2023 | B11: -2
A12: KHI/HO/D/MO/PD COMP/P/67223/01/2023 | B12: -370
A13: KHI/HO/D/MO/PD COMP/P/67508/02/2023 | B13: -2
... A1751: LHR/LHR/D/MO/CV/E/59625/04/2025 | B1751: -8572
B1752: =SUM(B2:B1751) -> 0

Sheet working
A1: POLICY NO. | B1: Assorted_code | D1: Premium | E1: 29Apr250042
A2: KHI/HO/D/MO/PD COMP/P/58234/01/2022 | B2: =VLOOKUP(A2,Sheet5!B:C,2,0) -> 040000111554 | C2: 1302 | D2: =ROUND(C2,0) -> 1302 | E2: 29Apr250042 | F2: ="insert into ins_premium_det (premium_rcv_code,assorted_code, rec_amount,premium_rcv_detail_code,remaining_amt, payrec, mode_code,coinsurance_code,class_cd,it_remarks) values" -> insert into ins_premium_det (premium_rcv_code,assorted_code, rec_amount,premium_rcv_detail_code,remaining_amt, payrec, mode_code,coinsurance_code,class_cd,it_remarks) values | G2: ="('"&E2&"','"&B2&"','"&D2&"',(select max(to_number(i.premium_rcv_detail_code))+1 from ins_premium_det i),'"&D2&"','"&D2&"','02', '11000003','00','Request by Mr. Omair Ali 30-Apr-2025');" -> ('29Apr250042','040000111554','1302',(select max(to_number(i.premium_rcv_detail_code))+1 from ins_premium_det i),'1302','1302','02', '11000003','00','Request by Mr. Omair Ali 30-Apr-2025'); | H2: =F2&G2 -> insert into ins_premium_det (premium_rcv_code,assorted_code, rec_amount,premium_rcv_detail_code,remaining_amt, payrec, mode_code,coinsurance_code,class_cd,it_remarks) values('29Apr250042','040000111554','1302',(select max(to_number(i.premium_rcv_detail_code))+1 from ins_premium_det i),'1302','1302','02', '11000003','00','Request by Mr. Omair Ali 30-Apr-2025');
A3: KHI/HO/D/MO/PD COMP/P/60538/05/2022 | B3: =VLOOKUP(A3,Sheet5!B:C,2,0) -> 040000115951 | C3: -1 | D3: =ROUND(C3,0) -> -1 | E3: 29Apr250042 | F3: ="insert into ins_premium_det (premium_rcv_code,assorted_code, rec_amount,premium_rcv_detail_code,remaining_amt, payrec, mode_code,coinsurance_code,class_cd,it_remarks) values" -> insert into ins_premium_det (premium_rcv_code,assorted_code, rec_amount,premium_rcv_detail_code,remaining_amt, payrec, mode_code,coinsurance_code,class_cd,it_remarks) values | G3: ="('"&E3&"','"&B3&"','"&D3&"',(select max(to_number(i.premium_rcv_detail_code))+1 from ins_premium_det i),'"&D3&"','"&D3&"','02', '11000003','00','Request by Mr. Omair Ali 30-Apr-2025');" -> ('29Apr250042','040000115951','-1',(select max(to_number(i.premium_rcv_detail_code))+1 from ins_premium_det i),'-1','-1','02', '11000003','00','Request by Mr. Omair Ali 30-Apr-2025'); | H3: =F3&G3 -> insert into ins_premium_det (premium_rcv_code,assorted_code, rec_amount,premium_rcv_detail_code,remaining_amt, payrec, mode_code,coinsurance_code,class_cd,it_remarks) values('29Apr250042','040000115951','-1',(select max(to_number(i.premium_rcv_detail_code))+1 from ins_premium_det i),'-1','-1','02', '11000003','00','Request by Mr. Omair Ali 30-Apr-2025');
A4: KHI/HO/D/MO/PD COMP/P/61418/06/2022 | B4: =VLOOKUP(A4,Sheet5!B:C,2,0) -> 040000118340 | C4: -404 | D4: =ROUND(C4,0) -> -404 | E4: 29Apr250042 | F4: ="insert into ins_premium_det (premium_rcv_code,assorted_code, rec_amount,premium_rcv_detail_code,remaining_amt, payrec, mode_code,coinsurance_code,class_cd,it_remarks) values" -> insert into ins_premium_det (premium_rcv_code,assorted_code, rec_amount,premium_rcv_detail_code,remaining_amt, payrec, mode_code,coinsurance_code,class_cd,it_remarks) values | G4: ="('"&E4&"','"&B4&"','"&D4&"',(select max(to_number(i.premium_rcv_detail_code))+1 from ins_premium_det i),'"&D4&"','"&D4&"','02', '11000003','00','Request by Mr. Omair Ali 30-Apr-2025');" -> ('29Apr250042','040000118340','-404',(select max(to_number(i.premium_rcv_detail_code))+1 from ins_premium_det i),'-404','-404','02', '11000003','00','Request by Mr. Omair Ali 30-Apr-2025'); | H4: =F4&G4 -> insert into ins_premium_det (premium_rcv_code,assorted_code, rec_amount,premium_rcv_detail_code,remaining_amt, payrec, mode_code,coinsurance_code,class_cd,it_remarks) values('29Apr250042','040000118340','-404',(select max(to_number(i.premium_rcv_detail_code))+1 from ins_premium_det i),'-404','-404','02', '11000003','00','Request by Mr. Omair Ali 30-Apr-2025');
A5: KHI/HO/D/MO/PD COMP/P/63305/09/2022 | B5: =VLOOKUP(A5,Sheet5!B:C,2,0) -> 040000125277 | C5: -374 | D5: =ROUND(C5,0) -> -374 | E5: 29Apr250042 | F5: ="insert into ins_premium_det (premium_rcv_code,assorted_code, rec_amount,premium_rcv_detail_code,remaining_amt, payrec, mode_code,coinsurance_code,class_cd,it_remarks) values" -> insert into ins_premium_det (premium_rcv_code,assorted_code, rec_amount,premium_rcv_detail_code,remaining_amt, payrec, mode_code,coinsurance_code,class_cd,it_remarks) values | G5: ="('"&E5&"','"&B5&"','"&D5&"',(select max(to_number(i.premium_rcv_detail_code))+1 from ins_premium_det i),'"&D5&"','"&D5&"','02', '11000003','00','Request by Mr. Omair Ali 30-Apr-2025');" -> ('29Apr250042','040000125277','-374',(select max(to_number(i.premium_rcv_detail_code))+1 from ins_premium_det i),'-374','-374','02', '11000003','00','Request by Mr. Omair Ali 30-Apr-2025'); | H5: =F5&G5 -> insert into ins_premium_det (premium_rcv_code,assorted_code, rec_amount,premium_rcv_detail_code,remaining_amt, payrec, mode_code,coinsurance_code,class_cd,it_remarks) values('29Apr250042','040000125277','-374',(select max(to_number(i.premium_rcv_detail_code))+1 from ins_premium_det i),'-374','-374','02', '11000003','00','Request by Mr. Omair Ali 30-Apr-2025');
A6: KHI/HO/D/MO/PD COMP/P/66017/12/2022 | B6: =VLOOKUP(A6,Sheet5!B:C,2,0) -> 040000134619 | C6: -1 | D6: =ROUND(C6,0) -> -1 | E6: 29Apr250042 | F6: ="insert into ins_premium_det (premium_rcv_code,assorted_code, rec_amount,premium_rcv_detail_code,remaining_amt, payrec, mode_code,coinsurance_code,class_cd,it_remarks) values" -> insert into ins_premium_det (premium_rcv_code,assorted_code, rec_amount,premium_rcv_detail_code,remaining_amt, payrec, mode_code,coinsurance_code,class_cd,it_remarks) values | G6: ="('"&E6&"','"&B6&"','"&D6&"',(select max(to_number(i.premium_rcv_detail_code))+1 from ins_premium_det i),'"&D6&"','"&D6&"','02', '11000003','00','Request by Mr. Omair Ali 30-Apr-2025');" -> ('29Apr250042','040000134619','-1',(select max(to_number(i.premium_rcv_detail_code))+1 from ins_premium_det i),'-1','-1','02', '11000003','00','Request by Mr. Omair Ali 30-Apr-2025'); | H6: =F6&G6 -> insert into ins_premium_det (premium_rcv_code,assorted_code, rec_amount,premium_rcv_detail_code,remaining_amt, payrec, mode_code,coinsurance_code,class_cd,it_remarks) values('29Apr250042','040000134619','-1',(select max(to_number(i.premium_rcv_detail_code))+1 from ins_premium_det i),'-1','-1','02', '11000003','00','Request by Mr. Omair Ali 30-Apr-2025');
A7: KHI/HO/D/MO/PD COMP/P/66188/12/2022 | B7: =VLOOKUP(A7,Sheet5!B:C,2,0) -> 040000135023 | C7: -3 | D7: =ROUND(C7,0) -> -3 | E7: 29Apr250042 | F7: ="insert into ins_premium_det (premium_rcv_code,assorted_code, rec_amount,premium_rcv_detail_code,remaining_amt, payrec, mode_code,coinsurance_code,class_cd,it_remarks) values" -> insert into ins_premium_det (premium_rcv_code,assorted_code, rec_amount,premium_rcv_detail_code,remaining_amt, payrec, mode_code,coinsurance_code,class_cd,it_remarks) values | G7: ="('"&E7&"','"&B7&"','"&D7&"',(select max(to_number(i.premium_rcv_detail_code))+1 from ins_premium_det i),'"&D7&"','"&D7&"','02', '11000003','00','Request by Mr. Omair Ali 30-Apr-2025');" -> ('29Apr250042','040000135023','-3',(select max(to_number(i.premium_rcv_detail_code))+1 from ins_premium_det i),'-3','-3','02', '11000003','00','Request by Mr. Omair Ali 30-Apr-2025'); | H7: =F7&G7 -> insert into ins_premium_det (premium_rcv_code,assorted_code, rec_amount,premium_rcv_detail_code,remaining_amt, payrec, mode_code,coinsurance_code,class_cd,it_remarks) values('29Apr250042','040000135023','-3',(select max(to_number(i.premium_rcv_detail_code))+1 from ins_premium_det i),'-3','-3','02', '11000003','00','Request by Mr. Omair Ali 30-Apr-2025');
A8: KHI/HO/D/MO/PD COMP/P/66820/01/2023 | B8: =VLOOKUP(A8,Sheet5!B:C,2,0) -> 040000136812 | C8: -5 | D8: =ROUND(C8,0) -> -5 | E8: 29Apr250042 | F8: ="insert into ins_premium_det (premium_rcv_code,assorted_code, rec_amount,premium_rcv_detail_code,remaining_amt, payrec, mode_code,coinsurance_code,class_cd,it_remarks) values" -> insert into ins_premium_det (premium_rcv_code,assorted_code, rec_amount,premium_rcv_detail_code,remaining_amt, payrec, mode_code,coinsurance_code,class_cd,it_remarks) values | G8: ="('"&E8&"','"&B8&"','"&D8&"',(select max(to_number(i.premium_rcv_detail_code))+1 from ins_premium_det i),'"&D8&"','"&D8&"','02', '11000003','00','Request by Mr. Omair Ali 30-Apr-2025');" -> ('29Apr250042','040000136812','-5',(select max(to_number(i.premium_rcv_detail_code))+1 from ins_premium_det i),'-5','-5','02', '11000003','00','Request by Mr. Omair Ali 30-Apr-2025'); | H8: =F8&G8 -> insert into ins_premium_det (premium_rcv_code,assorted_code, rec_amount,premium_rcv_detail_code,remaining_amt, payrec, mode_code,coinsurance_code,class_cd,it_remarks) values('29Apr250042','040000136812','-5',(select max(to_number(i.premium_rcv_detail_code))+1 from ins_premium_det i),'-5','-5','02', '11000003','00','Request by Mr. Omair Ali 30-Apr-2025');
A9: KHI/HO/D/MO/PD COMP/P/66962/01/2023 | B9: =VLOOKUP(A9,Sheet5!B:C,2,0) -> 040000137224 | C9: -8 | D9: =ROUND(C9,0) -> -8 | E9: 29Apr250042 | F9: ="insert into ins_premium_det (premium_rcv_code,assorted_code, rec_amount,premium_rcv_detail_code,remaining_amt, payrec, mode_code,coinsurance_code,class_cd,it_remarks) values" -> insert into ins_premium_det (premium_rcv_code,assorted_code, rec_amount,premium_rcv_detail_code,remaining_amt, payrec, mode_code,coinsurance_code,class_cd,it_remarks) values | G9: ="('"&E9&"','"&B9&"','"&D9&"',(select max(to_number(i.premium_rcv_detail_code))+1 from ins_premium_det i),'"&D9&"','"&D9&"','02', '11000003','00','Request by Mr. Omair Ali 30-Apr-2025');" -> ('29Apr250042','040000137224','-8',(select max(to_number(i.premium_rcv_detail_code))+1 from ins_premium_det i),'-8','-8','02', '11000003','00','Request by Mr. Omair Ali 30-Apr-2025'); | H9: =F9&G9 -> insert into ins_premium_det (premium_rcv_code,assorted_code, rec_amount,premium_rcv_detail_code,remaining_amt, payrec, mode_code,coinsurance_code,class_cd,it_remarks) values('29Apr250042','040000137224','-8',(select max(to_number(i.premium_rcv_detail_code))+1 from ins_premium_det i),'-8','-8','02', '11000003','00','Request by Mr. Omair Ali 30-Apr-2025');
A10: KHI/HO/D/MO/PD COMP/P/66983/01/2023 | B10: =VLOOKUP(A10,Sheet5!B:C,2,0) -> 040000137319 | C10: -99 | D10: =ROUND(C10,0) -> -99 | E10: 29Apr250042 | F10: ="insert into ins_premium_det (premium_rcv_code,assorted_code, rec_amount,premium_rcv_detail_code,remaining_amt, payrec, mode_code,coinsurance_code,class_cd,it_remarks) values" -> insert into ins_premium_det (premium_rcv_code,assorted_code, rec_amount,premium_rcv_detail_code,remaining_amt, payrec, mode_code,coinsurance_code,class_cd,it_remarks) values | G10: ="('"&E10&"','"&B10&"','"&D10&"',(select max(to_number(i.premium_rcv_detail_code))+1 from ins_premium_det i),'"&D10&"','"&D10&"','02', '11000003','00','Request by Mr. Omair Ali 30-Apr-2025');" -> ('29Apr250042','040000137319','-99',(select max(to_number(i.premium_rcv_detail_code))+1 from ins_premium_det i),'-99','-99','02', '11000003','00','Request by Mr. Omair Ali 30-Apr-2025'); | H10: =F10&G10 -> insert into ins_premium_det (premium_rcv_code,assorted_code, rec_amount,premium_rcv_detail_code,remaining_amt, payrec, mode_code,coinsurance_code,class_cd,it_remarks) values('29Apr250042','040000137319','-99',(select max(to_number(i.premium_rcv_detail_code))+1 from ins_premium_det i),'-99','-99','02', '11000003','00','Request by Mr. Omair Ali 30-Apr-2025');
A11: KHI/HO/D/MO/PD COMP/P/66986/01/2023 | B11: =VLOOKUP(A11,Sheet5!B:C,2,0) -> 040000137323 | C11: -2 | D11: =ROUND(C11,0) -> -2 | E11: 29Apr250042 | F11: ="insert into ins_premium_det (premium_rcv_code,assorted_code, rec_amount,premium_rcv_detail_code,remaining_amt, payrec, mode_code,coinsurance_code,class_cd,it_remarks) values" -> insert into ins_premium_det (premium_rcv_code,assorted_code, rec_amount,premium_rcv_detail_code,remaining_amt, payrec, mode_code,coinsurance_code,class_cd,it_remarks) values | G11: ="('"&E11&"','"&B11&"','"&D11&"',(select max(to_number(i.premium_rcv_detail_code))+1 from ins_premium_det i),'"&D11&"','"&D11&"','02', '11000003','00','Request by Mr. Omair Ali 30-Apr-2025');" -> ('29Apr250042','040000137323','-2',(select max(to_number(i.premium_rcv_detail_code))+1 from ins_premium_det i),'-2','-2','02', '11000003','00','Request by Mr. Omair Ali 30-Apr-2025'); | H11: =F11&G11 -> insert into ins_premium_det (premium_rcv_code,assorted_code, rec_amount,premium_rcv_detail_code,remaining_amt, payrec, mode_code,coinsurance_code,class_cd,it_remarks) values('29Apr250042','040000137323','-2',(select max(to_number(i.premium_rcv_detail_code))+1 from ins_premium_det i),'-2','-2','02', '11000003','00','Request by Mr. Omair Ali 30-Apr-2025');
A12: KHI/HO/D/MO/PD COMP/P/67223/01/2023 | B12: =VLOOKUP(A12,Sheet5!B:C,2,0) -> 040000138322 | C12: -370 | D12: =ROUND(C12,0) -> -370 | E12: 29Apr250042 | F12: ="insert into ins_premium_det (premium_rcv_code,assorted_code, rec_amount,premium_rcv_detail_code,remaining_amt, payrec, mode_code,coinsurance_code,class_cd,it_remarks) values" -> insert into ins_premium_det (premium_rcv_code,assorted_code, rec_amount,premium_rcv_detail_code,remaining_amt, payrec, mode_code,coinsurance_code,class_cd,it_remarks) values | G12: ="('"&E12&"','"&B12&"','"&D12&"',(select max(to_number(i.premium_rcv_detail_code))+1 from ins_premium_det i),'"&D12&"','"&D12&"','02', '11000003','00','Request by Mr. Omair Ali 30-Apr-2025');" -> ('29Apr250042','040000138322','-370',(select max(to_number(i.premium_rcv_detail_code))+1 from ins_premium_det i),'-370','-370','02', '11000003','00','Request by Mr. Omair Ali 30-Apr-2025'); | H12: =F12&G12 -> insert into ins_premium_det (premium_rcv_code,assorted_code, rec_amount,premium_rcv_detail_code,remaining_amt, payrec, mode_code,coinsurance_code,class_cd,it_remarks) values('29Apr250042','040000138322','-370',(select max(to_number(i.premium_rcv_detail_code))+1 from ins_premium_det i),'-370','-370','02', '11000003','00','Request by Mr. Omair Ali 30-Apr-2025');
A13: KHI/HO/D/MO/PD COMP/P/67508/02/2023 | B13: =VLOOKUP(A13,Sheet5!B:C,2,0) -> 040000139024 | C13: -2 | D13: =ROUND(C13,0) -> -2 | E13: 29Apr250042 | F13: ="insert into ins_premium_det (premium_rcv_code,assorted_code, rec_amount,premium_rcv_detail_code,remaining_amt, payrec, mode_code,coinsurance_code,class_cd,it_remarks) values" -> insert into ins_premium_det (premium_rcv_code,assorted_code, rec_amount,premium_rcv_detail_code,remaining_amt, payrec, mode_code,coinsurance_code,class_cd,it_remarks) values | G13: ="('"&E13&"','"&B13&"','"&D13&"',(select max(to_number(i.premium_rcv_detail_code))+1 from ins_premium_det i),'"&D13&"','"&D13&"','02', '11000003','00','Request by Mr. Omair Ali 30-Apr-2025');" -> ('29Apr250042','040000139024','-2',(select max(to_number(i.premium_rcv_detail_code))+1 from ins_premium_det i),'-2','-2','02', '11000003','00','Request by Mr. Omair Ali 30-Apr-2025'); | H13: =F13&G13 -> insert into ins_premium_det (premium_rcv_code,assorted_code, rec_amount,premium_rcv_detail_code,remaining_amt, payrec, mode_code,coinsurance_code,class_cd,it_remarks) values('29Apr250042','040000139024','-2',(select max(to_number(i.premium_rcv_detail_code))+1 from ins_premium_det i),'-2','-2','02', '11000003','00','Request by Mr. Omair Ali 30-Apr-2025');
... A1751: LHR/LHR/D/MO/CV/E/59625/04/2025 | B1751: =VLOOKUP(A1751,Sheet5!B:C,2,0) -> 050000879114 | C1751: -8572 | D1751: =ROUND(C1751,0) -> -8572 | E1751: 29Apr250042 | F1751: ="insert into ins_premium_det (premium_rcv_code,assorted_code, rec_amount,premium_rcv_detail_code,remaining_amt, payrec, mode_code,coinsurance_code,class_cd,it_remarks) values" -> insert into ins_premium_det (premium_rcv_code,assorted_code, rec_amount,premium_rcv_detail_code,remaining_amt, payrec, mode_code,coinsurance_code,class_cd,it_remarks) values | G1751: ="('"&E1751&"','"&B1751&"','"&D1751&"',(select max(to_number(i.premium_rcv_detail_code))+1 from ins_premium_det i),'"&D1751&"','"&D1751&"','02', '11000003','00','Request by Mr. Omair Ali 30-Apr-2025');" -> ('29Apr250042','050000879114','-8572',(select max(to_number(i.premium_rcv_detail_code))+1 from ins_premium_det i),'-8572','-8572','02', '11000003','00','Request by Mr. Omair Ali 30-Apr-2025'); | H1751: =F1751&G1751 -> insert into ins_premium_det (premium_rcv_code,assorted_code, rec_amount,premium_rcv_detail_code,remaining_amt, payrec, mode_code,coinsurance_code,class_cd,it_remarks) values('29Apr250042','050000879114','-8572',(select max(to_number(i.premium_rcv_detail_code))+1 from ins_premium_det i),'-8572','-8572','02', '11000003','00','Request by Mr. Omair Ali 30-Apr-2025');
D1752: =SUM(D2:D1751) -> 0

Sheet Sheet5
B1: FUNC_ASSORTED_STRING(IA.ASSORTED_CODE) | C1: ASSORTED_CODE
A2: 1 | B2: KHI/HO/D/MO/PD COMP/E/18327/12/2021 | C2: 050000430288
A3: 2 | B3: KHI/HO/D/MO/PD COMP/E/18671/02/2022 | C3: 050000443235
A4: 3 | B4: KHI/HO/D/MO/PD COMP/E/18537/01/2022 | C4: 050000440437
A5: 4 | B5: KHI/HO/D/MR/IMPORTS/C/18762/02/2022 | C5: 020000023825
A6: 5 | B6: KHI/HO/D/MO/PD COMP/P/67739/02/2023 | C6: 040000139494
A7: 6 | B7: KHI/HO/D/MO/PD COMP/E/22227/11/2022 | C7: 050000529874
A8: 7 | B8: KHI/HO/D/MO/PD COMP/E/18762/02/2022 | C8: 050000445441
A9: 8 | B9: KHI/HO/D/MO/PD COMP/E/22778/01/2023 | C9: 050000548195
A10: 9 | B10: KHI/HO/D/MO/PD COMP/E/22399/12/2022 | C10: 050000534339
A11: 10 | B11: KHI/HO/D/MO/PD COMP/E/44627/08/2024 | C11: 050000777712
A12: 11 | B12: KHI/HO/D/MO/PD COMP/E/44630/08/2024 | C12: 050000777715
A13: 12 | B13: KHI/HO/D/MO/PD COMP/P/66188/12/2022 | C13: 040000135023
... A1816: 1815 | B1816: LHR/LHR/D/MO/CV/E/59621/04/2025 | C1816: 050000878855

Sheet policy
A1: KHI/HO/D/MO/PD COMP/P/58234/01/2022 | B1: -01-2022 | D1: 58234 | E1: ="ia.assorted_string like '%"&D1&B1&"%' or" -> ia.assorted_string like '%58234-01-2022%' or
A2: KHI/HO/D/MO/PD COMP/P/60538/05/2022 | B2: -05-2022 | D2: 60538 | E2: ="ia.assorted_string like '%"&D2&B2&"%' or" -> ia.assorted_string like '%60538-05-2022%' or
A3: KHI/HO/D/MO/PD COMP/P/61418/06/2022 | B3: -06-2022 | D3: 61418 | E3: ="ia.assorted_string like '%"&D3&B3&"%' or" -> ia.assorted_string like '%61418-06-2022%' or
A4: KHI/HO/D/MO/PD COMP/P/63305/09/2022 | B4: -09-2022 | D4: 63305 | E4: ="ia.assorted_string like '%"&D4&B4&"%' or" -> ia.assorted_string like '%63305-09-2022%' or
A5: KHI/HO/D/MO/PD COMP/P/66017/12/2022 | B5: -12-2022 | D5: 66017 | E5: ="ia.assorted_string like '%"&D5&B5&"%' or" -> ia.assorted_string like '%66017-12-2022%' or
A6: KHI/HO/D/MO/PD COMP/P/66188/12/2022 | B6: -12-2022 | D6: 66188 | E6: ="ia.assorted_string like '%"&D6&B6&"%' or" -> ia.assorted_string like '%66188-12-2022%' or
A7: KHI/HO/D/MO/PD COMP/P/66820/01/2023 | B7: -01-2023 | D7: 66820 | E7: ="ia.assorted_string like '%"&D7&B7&"%' or" -> ia.assorted_string like '%66820-01-2023%' or
A8: KHI/HO/D/MO/PD COMP/P/66962/01/2023 | B8: -01-2023 | D8: 66962 | E8: ="ia.assorted_string like '%"&D8&B8&"%' or" -> ia.assorted_string like '%66962-01-2023%' or
A9: KHI/HO/D/MO/PD COMP/P/66983/01/2023 | B9: -01-2023 | D9: 66983 | E9: ="ia.assorted_string like '%"&D9&B9&"%' or" -> ia.assorted_string like '%66983-01-2023%' or
A10: KHI/HO/D/MO/PD COMP/P/66986/01/2023 | B10: -01-2023 | D10: 66986 | E10: ="ia.assorted_string like '%"&D10&B10&"%' or" -> ia.assorted_string like '%66986-01-2023%' or
A11: KHI/HO/D/MO/PD COMP/P/67223/01/2023 | B11: -01-2023 | D11: 67223 | E11: ="ia.assorted_string like '%"&D11&B11&"%' or" -> ia.assorted_string like '%67223-01-2023%' or
A12: KHI/HO/D/MO/PD COMP/P/67508/02/2023 | B12: -02-2023 | D12: 67508 | E12: ="ia.assorted_string like '%"&D12&B12&"%' or" -> ia.assorted_string like '%67508-02-2023%' or
... A1750: LHR/LHR/D/MO/CV/E/59625/04/2025 | B1750: -04-2025 | D1750: 59625 | E1750: ="ia.assorted_string like '%"&D1750&B1750&"%' or" -> ia.assorted_string like '%59625-04-2025%' or
