Workbook

Sheet Sheet1
B3: Account Description | C3: Company | D3: Policy No | E3: Client Name | F3: Branch | G3: Year | H3: Amount Payable | I3: STL Policy No. | J3: Updated Amount
B4: COINSURANCE RECEIVABLE - CLAIM | C4: SALAAM TAKAFUL LTD | D4: 2024HOSALOI00062-2-1 | E4: OXFORD UNIVERSITY PRESS PAKISTAN (SMC-PRIVATE) LIMITED (FORMERLY OXFORD UNIVERSITY PRESS) | F4: Head Office | G4: 2024 | H4: 3356 | J4: -3356
B5: COINSURANCE RECEIVABLE - CLAIM | C5: SALAAM TAKAFUL LTD | D5: 2024HOSALOI00089-2-1 | E5: OXFORD UNIVERSITY PRESS PAKISTAN (SMC-PRIVATE) LIMITED (FORMERLY OXFORD UNIVERSITY PRESS) | F5: Head Office | G5: 2024 | H5: 1929 | J5: -1929
B6: COINSURANCE RECEIVABLE - CLAIM | C6: SALAAM TAKAFUL LTD | D6: 2024HOSALOI00090-2-1 | E6: OXFORD UNIVERSITY PRESS PAKISTAN (SMC-PRIVATE) LIMITED (FORMERLY OXFORD UNIVERSITY PRESS) | F6: Head Office | G6: 2024 | H6: 3975 | J6: -3975
B7: COINSURANCE RECEIVABLE - CLAIM | C7: SALAAM TAKAFUL LTD | D7: 2024HOSALOI00125-2-1 | E7: OXFORD UNIVERSITY PRESS PAKISTAN (SMC-PRIVATE) LIMITED (FORMERLY OXFORD UNIVERSITY PRESS) | F7: Head Office | G7: 2024 | H7: 4184 | J7: -4184
B8: COINSURANCE RECEIVABLE - CLAIM | C8: SALAAM TAKAFUL LTD | D8: 2024HOSALOI00088-2-1 | E8: OXFORD UNIVERSITY PRESS PAKISTAN (SMC-PRIVATE) LIMITED (FORMERLY OXFORD UNIVERSITY PRESS) | F8: Head Office | G8: 2024 | H8: 8430 | J8: -8430
B9: COINSURANCE RECEIVABLE - CLAIM | C9: SALAAM TAKAFUL LTD | D9: 2024HOSALOI00080-3-1 | E9: #N/A | F9: #N/A | G9: 2024 | H9: 33675 | J9: -33675
B10: COINSURANCE RECEIVABLE - CLAIM | C10: SALAAM TAKAFUL LTD | D10: 2024HOEEEOI00068-2-1 | E10: #N/A | F10: #N/A | G10: 2024 | H10: 2655 | J10: -2655
B11: PREMIUM PAYABLE - COINSURANCE | C11: SALAAM TAKAFUL LTD | D11: 2024/04/HOSFGOP00750 | E11: OXFORD UNIVERSITY PRESS PAKISTAN (SMC-PRIVATE) LIMITED (FORMERLY OXFORD UNIVERSITY PRESS) | F11: Head Office | G11: 2024 | H11: -13427 | I11: KHI/HO/F/MI/FG/P/4642/10/2024 | J11: 13427
B12: PREMIUM PAYABLE - COINSURANCE | C12: SALAAM TAKAFUL LTD | D12: 2024/04/HOSCIOP00751 | E12: OXFORD UNIVERSITY PRESS PAKISTAN (SMC-PRIVATE) LIMITED (FORMERLY OXFORD UNIVERSITY PRESS) | F12: Head Office | G12: 2024 | H12: -17035 | I12: KHI/HO/F/MI/CT/P/4643/10/2024 | J12: 17035
B13: PREMIUM PAYABLE - COINSURANCE | C13: SALAAM TAKAFUL LTD | D13: 2024/04/HOSCIOP00752 | E13: OXFORD UNIVERSITY PRESS PAKISTAN (SMC-PRIVATE) LIMITED (FORMERLY OXFORD UNIVERSITY PRESS) | F13: Head Office | G13: 2024 | H13: -7297 | I13: KHI/HO/F/MI/CT/P/4644/10/2024 | J13: 7297
B14: PREMIUM PAYABLE - COINSURANCE | C14: SALAAM TAKAFUL LTD | D14: 2024/04/HOSALOP00753 | E14: OXFORD UNIVERSITY PRESS PAKISTAN (SMC-PRIVATE) LIMITED (FORMERLY OXFORD UNIVERSITY PRESS) | F14: Head Office | G14: 2024 | H14: -25320 | I14: KHI/HO/F/MI/ARC/P/4645/10/2024 | J14: 25320
B15: PREMIUM PAYABLE - COINSURANCE | C15: SALAAM TAKAFUL LTD | D15: 2024/04/HOEEEOP00097 | E15: OXFORD UNIVERSITY PRESS PAKISTAN (SMC-PRIVATE) LIMITED (FORMERLY OXFORD UNIVERSITY PRESS) | F15: Head Office | G15: 2024 | H15: -7264 | I15: KHI/HO/F/EG/EET/P/1196/05/2024 | J15: 7264
B16: PREMIUM PAYABLE - COINSURANCE | C16: SALAAM TAKAFUL LTD | D16: 2024/04/HOSALOP00754 | E16: OXFORD UNIVERSITY PRESS PAKISTAN (SMC-PRIVATE) LIMITED (FORMERLY OXFORD UNIVERSITY PRESS) | F16: Head Office | G16: 2024 | H16: -20613 | I16: KHI/HO/F/MI/ARC/P/4646/10/2024 | J16: 20613
B17: PREMIUM PAYABLE - COINSURANCE | C17: SALAAM TAKAFUL LTD | D17: 2024/04/HOEMBOP00098 | E17: OXFORD UNIVERSITY PRESS PAKISTAN (SMC-PRIVATE) LIMITED (FORMERLY OXFORD UNIVERSITY PRESS) | F17: Head Office | G17: 2024 | H17: -16401 | I17: KHI/HO/F/EG/MBD/P/1197/05/2024 | J17: 16401
B18: PREMIUM PAYABLE - COINSURANCE | C18: SALAAM TAKAFUL LTD | D18: 2024/04/HOECPOP00099 | E18: OXFORD UNIVERSITY PRESS PAKISTAN (SMC-PRIVATE) LIMITED (FORMERLY OXFORD UNIVERSITY PRESS) | F18: Head Office | G18: 2024 | H18: -10487 | I18: KHI/HO/F/EG/CPM/P/1198/05/2024 | J18: 10487
B19: PREMIUM PAYABLE - COINSURANCE | C19: SALAAM TAKAFUL LTD | D19: 2024/04/HOFFNOP00319 | E19: OXFORD UNIVERSITY PRESS PAKISTAN (SMC-PRIVATE) LIMITED (FORMERLY OXFORD UNIVERSITY PRESS) | F19: Head Office | G19: 2024 | H19: -39947 | I19: KHI/HO/F/FR/ND/P/22274/05/2024 | J19: 39947
B20: PREMIUM PAYABLE - COINSURANCE | C20: SALAAM TAKAFUL LTD | D20: 2024/04/HOFTROP00320 | E20: OXFORD UNIVERSITY PRESS PAKISTAN (SMC-PRIVATE) LIMITED (FORMERLY OXFORD UNIVERSITY PRESS) | F20: Head Office | G20: 2024 | H20: -14026 | I20: KHI/HO/F/MI/TRR/P/290/05/2024 | J20: 14026
B21: PREMIUM PAYABLE - COINSURANCE | C21: SALAAM TAKAFUL LTD | D21: 2024/04/HOFCMOP00342 | E21: SANOFI-AVENTIS PAKISTAN LTD | F21: Head Office | G21: 2024 | H21: -277951 | I21: KHI/HO/F/FR/CMFTP/22347/05/2024 | J21: 277951
B22: PREMIUM PAYABLE - COINSURANCE | C22: SALAAM TAKAFUL LTD | D22: 2024/04/HOFCMOP00343 | E22: SANOFI-AVENTIS PAKISTAN LTD | F22: Head Office | G22: 2024 | H22: -2734 | I22: LHR/LHR/F/FR/CMFTP/22495/05/2024 | J22: 2734
... B42: PREMIUM PAYABLE - COINSURANCE | C42: SALAAM TAKAFUL LTD | D42: 2024/07/HOEBPOP00185 | E42: GHANDHARA TYRE AND RUBBER COMPANY LIMITED. (FORMERLY THE GENERAL TYRE AND RUBBER CO OF PAKISTAN LIMITED) | F42: Head Office | G42: 2024 | H42: -15850 | I42: KHI/HO/F/EG/BPV/P/1244/08/2024 | J42: 15850
B43: PREMIUM PAYABLE - COINSURANCE | C43: SALAAM TAKAFUL LTD | D43: 2023/10/HOFCMOE00635 | E43: ENGRO FERTILIZER LIMITED | F43: Head Office | G43: 2023 | H43: -3264 | J43: 3264
B44: PREMIUM PAYABLE - COINSURANCE | C44: SALAAM TAKAFUL LTD | D44: 2023/10/HOEMBOP00122 | E44: ENGRO CORPORATION LIMITED | F44: Head Office | G44: 2023 | H44: -16801 | I44: KHI/HO/F/EG/MBD/P/1081/12/2023 | J44: 16801
B45: PREMIUM PAYABLE - COINSURANCE | C45: SALAAM TAKAFUL LTD | D45: 2024/09/HOFCMOE01445 | E45: SANOFI-AVENTIS PAKISTAN LTD | F45: Head Office | G45: 2024 | H45: -68040 | I45: KHI/HO/F/FR/CMFTE/10713/10/2024 | J45: 68040
B46: PREMIUM PAYABLE - COINSURANCE | C46: SALAAM TAKAFUL LTD | D46: 2024/09/HOFTSROE01447 | E46: SANOFI-AVENTIS PAKISTAN LTD | F46: Head Office | G46: 2024 | H46: -27149 | I46: KHI/HO/F/MI/TRR/E/412/12/2024 | J46: 27149
B47: COINSURANCE RECEIVABLE - COMMISSION | C47: SALAAM TAKAFUL LTD | D47: 2024/09/HOFCMOE01517 | E47: SANOFI-AVENTIS PAKISTAN LTD | F47: Head Office | G47: 2024 | H47: -22 | I47: LHR/LHR/F/FR/CMFTE/10711/10/2024 | J47: 22
B48: COINSURANCE RECEIVABLE - SERVICE CHARGES | C48: SALAAM TAKAFUL LTD | D48: 2024/09/HOFCMOE01517 | E48: SANOFI-AVENTIS PAKISTAN LTD | F48: Head Office | G48: 2024 | H48: -4 | I48: LHR/LHR/F/FR/CMFTE/10711/10/2024 | J48: 4
B49: PREMIUM PAYABLE - COINSURANCE | C49: SALAAM TAKAFUL LTD | D49: 2024/09/HOFCMOE01576 | E49: SANOFI-AVENTIS PAKISTAN LTD | F49: Head Office | G49: 2024 | H49: -42051 | I49: KHI/HO/F/FR/CMFTE/10715/10/2024 | J49: 42051
B50: PREMIUM PAYABLE - COINSURANCE | C50: SALAAM TAKAFUL LTD | D50: 2024/09/HOFCMOE01577 | E50: SANOFI-AVENTIS PAKISTAN LTD | F50: Head Office | G50: 2024 | H50: -16 | I50: LHR/LHR/F/FR/CMFTE/10714/10/2024 | J50: 16
B51: PREMIUM PAYABLE - COINSURANCE | C51: SALAAM TAKAFUL LTD | D51: 2024/09/HOFTSROE01578 | E51: SANOFI-AVENTIS PAKISTAN LTD | F51: Head Office | G51: 2024 | H51: -16827 | I51: KHI/HO/F/MI/TRR/E/413/12/2024 | J51: 16827
B52: PREMIUM PAYABLE - COINSURANCE | C52: SALAAM TAKAFUL LTD | D52: 2024/10/HOEEEOP00314 | E52: GHANDHARA AUTOMOBILES LIMITED (FORMERLY GHANDHARA NISSAN LIMITED). | F52: Head Office | G52: 2024 | H52: -3045 | I52: KHI/HO/F/EG/EET/P/1256/11/2024 | J52: 3045
B53: COINSURANCE RECEIVABLE - SERVICE CHARGES | C53: SALAAM TAKAFUL LTD | D53: 2024/04/HOSFGOP00750 | E53: OXFORD UNIVERSITY PRESS PAKISTAN (SMC-PRIVATE) LIMITED (FORMERLY OXFORD UNIVERSITY PRESS) | F53: Head Office | G53: 2024 | H53: 286 | I53: KHI/HO/F/MI/FG/P/4642/10/2024 | J53: -286
B54: COINSURANCE RECEIVABLE - SERVICE CHARGES | C54: SALAAM TAKAFUL LTD | D54: 2024/04/HOSCIOP00751 | E54: OXFORD UNIVERSITY PRESS PAKISTAN (SMC-PRIVATE) LIMITED (FORMERLY OXFORD UNIVERSITY PRESS) | F54: Head Office | G54: 2024 | H54: 356 | I54: KHI/HO/F/MI/CT/P/4643/10/2024 | J54: -356
B55: COINSURANCE RECEIVABLE - SERVICE CHARGES | C55: SALAAM TAKAFUL LTD | D55: 2024/04/HOSCIOP00752 | E55: OXFORD UNIVERSITY PRESS PAKISTAN (SMC-PRIVATE) LIMITED (FORMERLY OXFORD UNIVERSITY PRESS) | F55: Head Office | G55: 2024 | H55: 153 | I55: KHI/HO/F/MI/CT/P/4644/10/2024 | J55: -153
... B73: COINSURANCE RECEIVABLE - SERVICE CHARGES | C73: SALAAM TAKAFUL LTD | D73: 2024/04/HOFTSROP00344 | E73: SANOFI-AVENTIS PAKISTAN LTD | F73: Head Office | G73: 2024 | H73: 1833 | I73: KHI/HO/F/MI/TRR/P/291/06/2024 | J73: -1833
B74: COINSURANCE RECEIVABLE - COMMISSION | C74: SALAAM TAKAFUL LTD | D74: 2024/05/HOSCIOE00180 | E74: OXFORD UNIVERSITY PRESS PAKISTAN (SMC-PRIVATE) LIMITED (FORMERLY OXFORD UNIVERSITY PRESS) | F74: Head Office | G74: 2024 | H74: 2846 | J74: -2846
B75: COINSURANCE RECEIVABLE - COMMISSION | C75: SALAAM TAKAFUL LTD | D75: 2024/06/HOEEEOP00145 | E75: THINK PVC (PRIVATE) LIMITED | F75: Head Office | G75: 2024 | H75: 44 | I75: KHI/HO/F/EG/EET/P/1237/07/2024 | J75: -44
B76: COINSURANCE RECEIVABLE - SERVICE CHARGES | C76: SALAAM TAKAFUL LTD | D76: 2024/06/HOEEEOP00145 | E76: THINK PVC (PRIVATE) LIMITED | F76: Head Office | G76: 2024 | H76: 11 | I76: KHI/HO/F/EG/EET/P/1237/07/2024 | J76: -11
B77: COINSURANCE RECEIVABLE - COMMISSION | C77: SALAAM TAKAFUL LTD | D77: 2024/07/HOEEEOP00180 | E77: ENGRO ENFRASHARE (PRIVATE) LIMITED | F77: Head Office | G77: 2024 | H77: 3349 | I77: KHI/HO/F/EG/EET/P/1243/08/2024 | J77: -3349
B78: COINSURANCE RECEIVABLE - SERVICE CHARGES | C78: SALAAM TAKAFUL LTD | D78: 2024/07/HOEEEOP00180 | E78: ENGRO ENFRASHARE (PRIVATE) LIMITED | F78: Head Office | G78: 2024 | H78: 837 | I78: KHI/HO/F/EG/EET/P/1243/08/2024 | J78: -837
...

Sheet Sheet2
A2: Account Description | B2: Company | C2: Policy No | D2: Client Name | E2: Branch | F2: Year | G2: Amount Payable | H2: STL Policy No. | I2: Updated Amount
A3: COINSURANCE RECEIVABLE - CLAIM | B3: SALAAM TAKAFUL LTD | C3: 2024HOSALOI00062-2-1 | D3: OXFORD UNIVERSITY PRESS PAKISTAN (SMC-PRIVATE) LIMITED (FORMERLY OXFORD UNIVERSITY PRESS) | E3: Head Office | F3: 2024 | G3: 3356 | I3: -3356
A4: COINSURANCE RECEIVABLE - CLAIM | B4: SALAAM TAKAFUL LTD | C4: 2024HOSALOI00089-2-1 | D4: OXFORD UNIVERSITY PRESS PAKISTAN (SMC-PRIVATE) LIMITED (FORMERLY OXFORD UNIVERSITY PRESS) | E4: Head Office | F4: 2024 | G4: 1929 | I4: -1929
A5: COINSURANCE RECEIVABLE - CLAIM | B5: SALAAM TAKAFUL LTD | C5: 2024HOSALOI00090-2-1 | D5: OXFORD UNIVERSITY PRESS PAKISTAN (SMC-PRIVATE) LIMITED (FORMERLY OXFORD UNIVERSITY PRESS) | E5: Head Office | F5: 2024 | G5: 3975 | I5: -3975
A6: COINSURANCE RECEIVABLE - CLAIM | B6: SALAAM TAKAFUL LTD | C6: 2024HOSALOI00125-2-1 | D6: OXFORD UNIVERSITY PRESS PAKISTAN (SMC-PRIVATE) LIMITED (FORMERLY OXFORD UNIVERSITY PRESS) | E6: Head Office | F6: 2024 | G6: 4184 | I6: -4184
A7: COINSURANCE RECEIVABLE - CLAIM | B7: SALAAM TAKAFUL LTD | C7: 2024HOSALOI00088-2-1 | D7: OXFORD UNIVERSITY PRESS PAKISTAN (SMC-PRIVATE) LIMITED (FORMERLY OXFORD UNIVERSITY PRESS) | E7: Head Office | F7: 2024 | G7: 8430 | I7: -8430
A8: COINSURANCE RECEIVABLE - CLAIM | B8: SALAAM TAKAFUL LTD | C8: 2024HOSALOI00080-3-1 | D8: #N/A | E8: #N/A | F8: 2024 | G8: 33675 | I8: -33675
A9: COINSURANCE RECEIVABLE - CLAIM | B9: SALAAM TAKAFUL LTD | C9: 2024HOEEEOI00068-2-1 | D9: #N/A | E9: #N/A | F9: 2024 | G9: 2655 | I9: -2655
C11: PREMIUM
B12: Account Description | C12: STL Policy No. | D12: Updated Amount
B13: PREMIUM PAYABLE - COINSURANCE | C13: KHI/HO/F/MI/FG/P/4642/10/2024 | D13: 13427
B14: PREMIUM PAYABLE - COINSURANCE | C14: KHI/HO/F/MI/CT/P/4643/10/2024 | D14: 17035
B15: PREMIUM PAYABLE - COINSURANCE | C15: KHI/HO/F/MI/CT/P/4644/10/2024 | D15: 7297
B16: PREMIUM PAYABLE - COINSURANCE | C16: KHI/HO/F/MI/ARC/P/4645/10/2024 | D16: 25320
B17: PREMIUM PAYABLE - COINSURANCE | C17: KHI/HO/F/EG/EET/P/1196/05/2024 | D17: 7264
B18: PREMIUM PAYABLE - COINSURANCE | C18: KHI/HO/F/MI/ARC/P/4646/10/2024 | D18: 20613
B19: PREMIUM PAYABLE - COINSURANCE | C19: KHI/HO/F/EG/MBD/P/1197/05/2024 | D19: 16401
B20: PREMIUM PAYABLE - COINSURANCE | C20: KHI/HO/F/EG/CPM/P/1198/05/2024 | D20: 10487
B21: PREMIUM PAYABLE - COINSURANCE | C21: KHI/HO/F/FR/ND/P/22274/05/2024 | D21: 39947
B22: PREMIUM PAYABLE - COINSURANCE | C22: KHI/HO/F/MI/TRR/P/290/05/2024 | D22: 14026
B23: PREMIUM PAYABLE - COINSURANCE | C23: KHI/HO/F/FR/CMFTP/22347/05/2024 | D23: 277951
B24: PREMIUM PAYABLE - COINSURANCE | C24: LHR/LHR/F/FR/CMFTP/22495/05/2024 | D24: 2734
... B44: PREMIUM PAYABLE - COINSURANCE | C44: KHI/HO/F/EG/BPV/P/1244/08/2024 | D44: 15850
B45: PREMIUM PAYABLE - COINSURANCE | D45: 3264
B46: PREMIUM PAYABLE - COINSURANCE | C46: KHI/HO/F/EG/MBD/P/1081/12/2023 | D46: 16801
B47: PREMIUM PAYABLE - COINSURANCE | C47: KHI/HO/F/FR/CMFTE/10713/10/2024 | D47: 68040
B48: PREMIUM PAYABLE - COINSURANCE | C48: KHI/HO/F/MI/TRR/E/412/12/2024 | D48: 27149
B49: PREMIUM PAYABLE - COINSURANCE | C49: KHI/HO/F/FR/CMFTE/10715/10/2024 | D49: 42051
B50: PREMIUM PAYABLE - COINSURANCE | C50: LHR/LHR/F/FR/CMFTE/10714/10/2024 | D50: 16
B51: PREMIUM PAYABLE - COINSURANCE | C51: KHI/HO/F/MI/TRR/E/413/12/2024 | D51: 16827
B52: PREMIUM PAYABLE - COINSURANCE | C52: KHI/HO/F/EG/EET/P/1256/11/2024 | D52: 3045
B53: PREMIUM PAYABLE - COINSURANCE | C53: LHR/LHR/F/FR/CMFTE/10711/10/2024 | D53: -170
B56: Account Description | C56: STL Policy No. | D56: Updated Amount
B57: COINSURANCE RECEIVABLE - COMMISSION | C57: LHR/LHR/F/FR/CMFTE/10711/10/2024 | D57: 22
B58: COINSURANCE RECEIVABLE - COMMISSION | C58: KHI/HO/F/EG/EET/P/1196/05/2024 | D58: -910
B59: COINSURANCE RECEIVABLE - COMMISSION | C59: KHI/HO/F/EG/MBD/P/1197/05/2024 | D59: -2107
B60: COINSURANCE RECEIVABLE - COMMISSION | C60: KHI/HO/F/EG/CPM/P/1198/05/2024 | D60: -1330
B61: COINSURANCE RECEIVABLE - COMMISSION | C61: KHI/HO/F/FR/ND/P/22274/05/2024 | D61: -5206
B62: COINSURANCE RECEIVABLE - COMMISSION | C62: KHI/HO/F/MI/TRR/P/290/05/2024 | D62: -1795
B63: COINSURANCE RECEIVABLE - COMMISSION | C63: KHI/HO/F/FR/CMFTP/22347/05/2024 | D63: -36558
...

Sheet Sheet2 (2)
C2: PREMIUM
B3: Account Description | C3: STL Policy No. | D3: Updated Amount
B4: PREMIUM PAYABLE - COINSURANCE | C4: KHI/HO/F/MI/FG/P/4642/10/2024 | D4: 13427
B5: PREMIUM PAYABLE - COINSURANCE | C5: KHI/HO/F/MI/CT/P/4643/10/2024 | D5: 17035
B6: PREMIUM PAYABLE - COINSURANCE | C6: KHI/HO/F/MI/CT/P/4644/10/2024 | D6: 7297
B7: PREMIUM PAYABLE - COINSURANCE | C7: KHI/HO/F/MI/ARC/P/4645/10/2024 | D7: 25320
B8: PREMIUM PAYABLE - COINSURANCE | C8: KHI/HO/F/EG/EET/P/1196/05/2024 | D8: 7264
B9: PREMIUM PAYABLE - COINSURANCE | C9: KHI/HO/F/MI/ARC/P/4646/10/2024 | D9: 20613
B10: PREMIUM PAYABLE - COINSURANCE | C10: KHI/HO/F/EG/MBD/P/1197/05/2024 | D10: 16401
B11: PREMIUM PAYABLE - COINSURANCE | C11: KHI/HO/F/EG/CPM/P/1198/05/2024 | D11: 10487
B12: PREMIUM PAYABLE - COINSURANCE | C12: KHI/HO/F/FR/ND/P/22274/05/2024 | D12: 39947
B13: PREMIUM PAYABLE - COINSURANCE | C13: KHI/HO/F/MI/TRR/P/290/05/2024 | D13: 14026
B14: PREMIUM PAYABLE - COINSURANCE | C14: KHI/HO/F/FR/CMFTP/22347/05/2024 | D14: 277951
B15: PREMIUM PAYABLE - COINSURANCE | C15: LHR/LHR/F/FR/CMFTP/22495/05/2024 | D15: 2734
... B43: PREMIUM PAYABLE - COINSURANCE | C43: LHR/LHR/F/FR/CMFTE/10711/10/2024 | D43: -170
D44: =SUM(D4:D43) -> 4355032
C45: COMISSION
B46: Account Description | C46: STL Policy No. | D46: Updated Amount
B47: COINSURANCE RECEIVABLE - COMMISSION | C47: LHR/LHR/F/FR/CMFTE/10711/10/2024 | D47: 22
B48: COINSURANCE RECEIVABLE - COMMISSION | C48: KHI/HO/F/EG/EET/P/1196/05/2024 | D48: -910
B49: COINSURANCE RECEIVABLE - COMMISSION | C49: KHI/HO/F/EG/MBD/P/1197/05/2024 | D49: -2107
B50: COINSURANCE RECEIVABLE - COMMISSION | C50: KHI/HO/F/EG/CPM/P/1198/05/2024 | D50: -1330
B51: COINSURANCE RECEIVABLE - COMMISSION | C51: KHI/HO/F/FR/ND/P/22274/05/2024 | D51: -5206
B52: COINSURANCE RECEIVABLE - COMMISSION | C52: KHI/HO/F/MI/TRR/P/290/05/2024 | D52: -1795
B53: COINSURANCE RECEIVABLE - COMMISSION | C53: KHI/HO/F/FR/CMFTP/22347/05/2024 | D53: -36558
B54: COINSURANCE RECEIVABLE - COMMISSION | C54: LHR/LHR/F/FR/CMFTP/22495/05/2024 | D54: -337
B55: COINSURANCE RECEIVABLE - COMMISSION | C55: KHI/HO/F/MI/TRR/P/291/06/2024 | D55: -10998
B56: COINSURANCE RECEIVABLE - COMMISSION | C56: KHI/HO/F/EG/EET/P/1237/07/2024 | D56: -44
B57: COINSURANCE RECEIVABLE - COMMISSION | C57: KHI/HO/F/EG/EET/P/1243/08/2024 | D57: -3349
B58: COINSURANCE RECEIVABLE - COMMISSION | C58: KHI/HO/F/EG/EET/P/1242/08/2024 | D58: -1748
... B76: COINSURANCE RECEIVABLE - COMMISSION | C76: KHI/HO/F/EG/EET/P/1256/11/2024 | D76: -375
D77: =SUM(D47:D76) -> -471654
C78: SERVICE CHARGES
B79: Account Description | C79: STL Policy No. | D79: Updated Amount
B80: COINSURANCE RECEIVABLE - SERVICE CHARGES | C80: LHR/LHR/F/FR/CMFTE/10711/10/2024 | D80: 4
B81: COINSURANCE RECEIVABLE - SERVICE CHARGES | C81: KHI/HO/F/MI/FG/P/4642/10/2024 | D81: -286
B82: COINSURANCE RECEIVABLE - SERVICE CHARGES | C82: KHI/HO/F/MI/CT/P/4643/10/2024 | D82: -356
B83: COINSURANCE RECEIVABLE - SERVICE CHARGES | C83: KHI/HO/F/MI/CT/P/4644/10/2024 | D83: -153
B84: COINSURANCE RECEIVABLE - SERVICE CHARGES | C84: KHI/HO/F/MI/ARC/P/4645/10/2024 | D84: -546
B85: COINSURANCE RECEIVABLE - SERVICE CHARGES | C85: KHI/HO/F/EG/EET/P/1196/05/2024 | D85: -151
...

Sheet WORKING
A1: POLICY NO. | B1: Assorted_code | D1: Premium | E1: 15Apr250002
A2: KHI/HO/F/MI/FG/P/4642/10/2024 | B2: =VLOOKUP(A2,policy!B:C,2,0) -> 040000185733 | C2: 13427 | D2: =ROUND(C2,0) -> 13427 | E2: 15Apr250002 | F2: ="insert into ins_premium_det (premium_rcv_code,assorted_code, rec_amount,premium_rcv_detail_code,remaining_amt, payrec, mode_code,coinsurance_code,class_cd,it_remarks) values" -> insert into ins_premium_det (premium_rcv_code,assorted_code, rec_amount,premium_rcv_detail_code,remaining_amt, payrec, mode_code,coinsurance_code,class_cd,it_remarks) values | G2: ="('"&E2&"','"&B2&"','"&D2&"',(select max(to_number(i.premium_rcv_detail_code))+1 from ins_premium_det i),'"&D2&"','"&D2&"','02', '11000003','00','Request by Mr. Raheel Malik 16-Apr-2025');" -> ('15Apr250002','040000185733','13427',(select max(to_number(i.premium_rcv_detail_code))+1 from ins_premium_det i),'13427','13427','02', '11000003','00','Request by Mr. Raheel Malik 16-Apr-2025'); | H2: =F2&G2 -> insert into ins_premium_det (premium_rcv_code,assorted_code, rec_amount,premium_rcv_detail_code,remaining_amt, payrec, mode_code,coinsurance_code,class_cd,it_remarks) values('15Apr250002','040000185733','13427',(select max(to_number(i.premium_rcv_detail_code))+1 from ins_premium_det i),'13427','13427','02', '11000003','00','Request by Mr. Raheel Malik 16-Apr-2025');
A3: KHI/HO/F/MI/CT/P/4643/10/2024 | B3: =VLOOKUP(A3,policy!B:C,2,0) -> 040000185737 | C3: 17035 | D3: =ROUND(C3,0) -> 17035 | E3: 15Apr250002 | F3: ="insert into ins_premium_det (premium_rcv_code,assorted_code, rec_amount,premium_rcv_detail_code,remaining_amt, payrec, mode_code,coinsurance_code,class_cd,it_remarks) values" -> insert into ins_premium_det (premium_rcv_code,assorted_code, rec_amount,premium_rcv_detail_code,remaining_amt, payrec, mode_code,coinsurance_code,class_cd,it_remarks) values | G3: ="('"&E3&"','"&B3&"','"&D3&"',(select max(to_number(i.premium_rcv_detail_code))+1 from ins_premium_det i),'"&D3&"','"&D3&"','02', '11000003','00','Request by Mr. Raheel Malik 16-Apr-2025');" -> ('15Apr250002','040000185737','17035',(select max(to_number(i.premium_rcv_detail_code))+1 from ins_premium_det i),'17035','17035','02', '11000003','00','Request by Mr. Raheel Malik 16-Apr-2025'); | H3: =F3&G3 -> insert into ins_premium_det (premium_rcv_code,assorted_code, rec_amount,premium_rcv_detail_code,remaining_amt, payrec, mode_code,coinsurance_code,class_cd,it_remarks) values('15Apr250002','040000185737','17035',(select max(to_number(i.premium_rcv_detail_code))+1 from ins_premium_det i),'17035','17035','02', '11000003','00','Request by Mr. Raheel Malik 16-Apr-2025');
A4: KHI/HO/F/MI/CT/P/4644/10/2024 | B4: =VLOOKUP(A4,policy!B:C,2,0) -> 040000185739 | C4: 7297 | D4: =ROUND(C4,0) -> 7297 | E4: 15Apr250002 | F4: ="insert into ins_premium_det (premium_rcv_code,assorted_code, rec_amount,premium_rcv_detail_code,remaining_amt, payrec, mode_code,coinsurance_code,class_cd,it_remarks) values" -> insert into ins_premium_det (premium_rcv_code,assorted_code, rec_amount,premium_rcv_detail_code,remaining_amt, payrec, mode_code,coinsurance_code,class_cd,it_remarks) values | G4: ="('"&E4&"','"&B4&"','"&D4&"',(select max(to_number(i.premium_rcv_detail_code))+1 from ins_premium_det i),'"&D4&"','"&D4&"','02', '11000003','00','Request by Mr. Raheel Malik 16-Apr-2025');" -> ('15Apr250002','040000185739','7297',(select max(to_number(i.premium_rcv_detail_code))+1 from ins_premium_det i),'7297','7297','02', '11000003','00','Request by Mr. Raheel Malik 16-Apr-2025'); | H4: =F4&G4 -> insert into ins_premium_det (premium_rcv_code,assorted_code, rec_amount,premium_rcv_detail_code,remaining_amt, payrec, mode_code,coinsurance_code,class_cd,it_remarks) values('15Apr250002','040000185739','7297',(select max(to_number(i.premium_rcv_detail_code))+1 from ins_premium_det i),'7297','7297','02', '11000003','00','Request by Mr. Raheel Malik 16-Apr-2025');
A5: KHI/HO/F/MI/ARC/P/4645/10/2024 | B5: =VLOOKUP(A5,policy!B:C,2,0) -> 040000185751 | C5: 25320 | D5: =ROUND(C5,0) -> 25320 | E5: 15Apr250002 | F5: ="insert into ins_premium_det (premium_rcv_code,assorted_code, rec_amount,premium_rcv_detail_code,remaining_amt, payrec, mode_code,coinsurance_code,class_cd,it_remarks) values" -> insert into ins_premium_det (premium_rcv_code,assorted_code, rec_amount,premium_rcv_detail_code,remaining_amt, payrec, mode_code,coinsurance_code,class_cd,it_remarks) values | G5: ="('"&E5&"','"&B5&"','"&D5&"',(select max(to_number(i.premium_rcv_detail_code))+1 from ins_premium_det i),'"&D5&"','"&D5&"','02', '11000003','00','Request by Mr. Raheel Malik 16-Apr-2025');" -> ('15Apr250002','040000185751','25320',(select max(to_number(i.premium_rcv_detail_code))+1 from ins_premium_det i),'25320','25320','02', '11000003','00','Request by Mr. Raheel Malik 16-Apr-2025'); | H5: =F5&G5 -> insert into ins_premium_det (premium_rcv_code,assorted_code, rec_amount,premium_rcv_detail_code,remaining_amt, payrec, mode_code,coinsurance_code,class_cd,it_remarks) values('15Apr250002','040000185751','25320',(select max(to_number(i.premium_rcv_detail_code))+1 from ins_premium_det i),'25320','25320','02', '11000003','00','Request by Mr. Raheel Malik 16-Apr-2025');
A6: KHI/HO/F/EG/EET/P/1196/05/2024 | B6: =VLOOKUP(A6,policy!B:C,2,0) -> 040000172420 | C6: 7264 | D6: =ROUND(C6,0) -> 7264 | E6: 15Apr250002 | F6: ="insert into ins_premium_det (premium_rcv_code,assorted_code, rec_amount,premium_rcv_detail_code,remaining_amt, payrec, mode_code,coinsurance_code,class_cd,it_remarks) values" -> insert into ins_premium_det (premium_rcv_code,assorted_code, rec_amount,premium_rcv_detail_code,remaining_amt, payrec, mode_code,coinsurance_code,class_cd,it_remarks) values | G6: ="('"&E6&"','"&B6&"','"&D6&"',(select max(to_number(i.premium_rcv_detail_code))+1 from ins_premium_det i),'"&D6&"','"&D6&"','02', '11000003','00','Request by Mr. Raheel Malik 16-Apr-2025');" -> ('15Apr250002','040000172420','7264',(select max(to_number(i.premium_rcv_detail_code))+1 from ins_premium_det i),'7264','7264','02', '11000003','00','Request by Mr. Raheel Malik 16-Apr-2025'); | H6: =F6&G6 -> insert into ins_premium_det (premium_rcv_code,assorted_code, rec_amount,premium_rcv_detail_code,remaining_amt, payrec, mode_code,coinsurance_code,class_cd,it_remarks) values('15Apr250002','040000172420','7264',(select max(to_number(i.premium_rcv_detail_code))+1 from ins_premium_det i),'7264','7264','02', '11000003','00','Request by Mr. Raheel Malik 16-Apr-2025');
A7: KHI/HO/F/MI/ARC/P/4646/10/2024 | B7: =VLOOKUP(A7,policy!B:C,2,0) -> 040000185754 | C7: 20613 | D7: =ROUND(C7,0) -> 20613 | E7: 15Apr250002 | F7: ="insert into ins_premium_det (premium_rcv_code,assorted_code, rec_amount,premium_rcv_detail_code,remaining_amt, payrec, mode_code,coinsurance_code,class_cd,it_remarks) values" -> insert into ins_premium_det (premium_rcv_code,assorted_code, rec_amount,premium_rcv_detail_code,remaining_amt, payrec, mode_code,coinsurance_code,class_cd,it_remarks) values | G7: ="('"&E7&"','"&B7&"','"&D7&"',(select max(to_number(i.premium_rcv_detail_code))+1 from ins_premium_det i),'"&D7&"','"&D7&"','02', '11000003','00','Request by Mr. Raheel Malik 16-Apr-2025');" -> ('15Apr250002','040000185754','20613',(select max(to_number(i.premium_rcv_detail_code))+1 from ins_premium_det i),'20613','20613','02', '11000003','00','Request by Mr. Raheel Malik 16-Apr-2025'); | H7: =F7&G7 -> insert into ins_premium_det (premium_rcv_code,assorted_code, rec_amount,premium_rcv_detail_code,remaining_amt, payrec, mode_code,coinsurance_code,class_cd,it_remarks) values('15Apr250002','040000185754','20613',(select max(to_number(i.premium_rcv_detail_code))+1 from ins_premium_det i),'20613','20613','02', '11000003','00','Request by Mr. Raheel Malik 16-Apr-2025');
A8: KHI/HO/F/EG/MBD/P/1197/05/2024 | B8: =VLOOKUP(A8,policy!B:C,2,0) -> 040000172425 | C8: 16401 | D8: =ROUND(C8,0) -> 16401 | E8: 15Apr250002 | F8: ="insert into ins_premium_det (premium_rcv_code,assorted_code, rec_amount,premium_rcv_detail_code,remaining_amt, payrec, mode_code,coinsurance_code,class_cd,it_remarks) values" -> insert into ins_premium_det (premium_rcv_code,assorted_code, rec_amount,premium_rcv_detail_code,remaining_amt, payrec, mode_code,coinsurance_code,class_cd,it_remarks) values | G8: ="('"&E8&"','"&B8&"','"&D8&"',(select max(to_number(i.premium_rcv_detail_code))+1 from ins_premium_det i),'"&D8&"','"&D8&"','02', '11000003','00','Request by Mr. Raheel Malik 16-Apr-2025');" -> ('15Apr250002','040000172425','16401',(select max(to_number(i.premium_rcv_detail_code))+1 from ins_premium_det i),'16401','16401','02', '11000003','00','Request by Mr. Raheel Malik 16-Apr-2025'); | H8: =F8&G8 -> insert into ins_premium_det (premium_rcv_code,assorted_code, rec_amount,premium_rcv_detail_code,remaining_amt, payrec, mode_code,coinsurance_code,class_cd,it_remarks) values('15Apr250002','040000172425','16401',(select max(to_number(i.premium_rcv_detail_code))+1 from ins_premium_det i),'16401','16401','02', '11000003','00','Request by Mr. Raheel Malik 16-Apr-2025');
A9: KHI/HO/F/EG/CPM/P/1198/05/2024 | B9: =VLOOKUP(A9,policy!B:C,2,0) -> 040000172427 | C9: 10487 | D9: =ROUND(C9,0) -> 10487 | E9: 15Apr250002 | F9: ="insert into ins_premium_det (premium_rcv_code,assorted_code, rec_amount,premium_rcv_detail_code,remaining_amt, payrec, mode_code,coinsurance_code,class_cd,it_remarks) values" -> insert into ins_premium_det (premium_rcv_code,assorted_code, rec_amount,premium_rcv_detail_code,remaining_amt, payrec, mode_code,coinsurance_code,class_cd,it_remarks) values | G9: ="('"&E9&"','"&B9&"','"&D9&"',(select max(to_number(i.premium_rcv_detail_code))+1 from ins_premium_det i),'"&D9&"','"&D9&"','02', '11000003','00','Request by Mr. Raheel Malik 16-Apr-2025');" -> ('15Apr250002','040000172427','10487',(select max(to_number(i.premium_rcv_detail_code))+1 from ins_premium_det i),'10487','10487','02', '11000003','00','Request by Mr. Raheel Malik 16-Apr-2025'); | H9: =F9&G9 -> insert into ins_premium_det (premium_rcv_code,assorted_code, rec_amount,premium_rcv_detail_code,remaining_amt, payrec, mode_code,coinsurance_code,class_cd,it_remarks) values('15Apr250002','040000172427','10487',(select max(to_number(i.premium_rcv_detail_code))+1 from ins_premium_det i),'10487','10487','02', '11000003','00','Request by Mr. Raheel Malik 16-Apr-2025');
A10: KHI/HO/F/FR/ND/P/22274/05/2024 | B10: =VLOOKUP(A10,policy!B:C,2,0) -> 040000172409 | C10: 39947 | D10: =ROUND(C10,0) -> 39947 | E10: 15Apr250002 | F10: ="insert into ins_premium_det (premium_rcv_code,assorted_code, rec_amount,premium_rcv_detail_code,remaining_amt, payrec, mode_code,coinsurance_code,class_cd,it_remarks) values" -> insert into ins_premium_det (premium_rcv_code,assorted_code, rec_amount,premium_rcv_detail_code,remaining_amt, payrec, mode_code,coinsurance_code,class_cd,it_remarks) values | G10: ="('"&E10&"','"&B10&"','"&D10&"',(select max(to_number(i.premium_rcv_detail_code))+1 from ins_premium_det i),'"&D10&"','"&D10&"','02', '11000003','00','Request by Mr. Raheel Malik 16-Apr-2025');" -> ('15Apr250002','040000172409','39947',(select max(to_number(i.premium_rcv_detail_code))+1 from ins_premium_det i),'39947','39947','02', '11000003','00','Request by Mr. Raheel Malik 16-Apr-2025'); | H10: =F10&G10 -> insert into ins_premium_det (premium_rcv_code,assorted_code, rec_amount,premium_rcv_detail_code,remaining_amt, payrec, mode_code,coinsurance_code,class_cd,it_remarks) values('15Apr250002','040000172409','39947',(select max(to_number(i.premium_rcv_detail_code))+1 from ins_premium_det i),'39947','39947','02', '11000003','00','Request by Mr. Raheel Malik 16-Apr-2025');
A11: KHI/HO/F/MI/TRR/P/290/05/2024 | B11: =VLOOKUP(A11,policy!B:C,2,0) -> 040000174621 | C11: 14026 | D11: =ROUND(C11,0) -> 14026 | E11: 15Apr250002 | F11: ="insert into ins_premium_det (premium_rcv_code,assorted_code, rec_amount,premium_rcv_detail_code,remaining_amt, payrec, mode_code,coinsurance_code,class_cd,it_remarks) values" -> insert into ins_premium_det (premium_rcv_code,assorted_code, rec_amount,premium_rcv_detail_code,remaining_amt, payrec, mode_code,coinsurance_code,class_cd,it_remarks) values | G11: ="('"&E11&"','"&B11&"','"&D11&"',(select max(to_number(i.premium_rcv_detail_code))+1 from ins_premium_det i),'"&D11&"','"&D11&"','02', '11000003','00','Request by Mr. Raheel Malik 16-Apr-2025');" -> ('15Apr250002','040000174621','14026',(select max(to_number(i.premium_rcv_detail_code))+1 from ins_premium_det i),'14026','14026','02', '11000003','00','Request by Mr. Raheel Malik 16-Apr-2025'); | H11: =F11&G11 -> insert into ins_premium_det (premium_rcv_code,assorted_code, rec_amount,premium_rcv_detail_code,remaining_amt, payrec, mode_code,coinsurance_code,class_cd,it_remarks) values('15Apr250002','040000174621','14026',(select max(to_number(i.premium_rcv_detail_code))+1 from ins_premium_det i),'14026','14026','02', '11000003','00','Request by Mr. Raheel Malik 16-Apr-2025');
A12: KHI/HO/F/FR/CMFTP/22347/05/2024 | B12: =VLOOKUP(A12,policy!B:C,2,0) -> 040000174195 | C12: 277951 | D12: =ROUND(C12,0) -> 277951 | E12: 15Apr250002 | F12: ="insert into ins_premium_det (premium_rcv_code,assorted_code, rec_amount,premium_rcv_detail_code,remaining_amt, payrec, mode_code,coinsurance_code,class_cd,it_remarks) values" -> insert into ins_premium_det (premium_rcv_code,assorted_code, rec_amount,premium_rcv_detail_code,remaining_amt, payrec, mode_code,coinsurance_code,class_cd,it_remarks) values | G12: ="('"&E12&"','"&B12&"','"&D12&"',(select max(to_number(i.premium_rcv_detail_code))+1 from ins_premium_det i),'"&D12&"','"&D12&"','02', '11000003','00','Request by Mr. Raheel Malik 16-Apr-2025');" -> ('15Apr250002','040000174195','277951',(select max(to_number(i.premium_rcv_detail_code))+1 from ins_premium_det i),'277951','277951','02', '11000003','00','Request by Mr. Raheel Malik 16-Apr-2025'); | H12: =F12&G12 -> insert into ins_premium_det (premium_rcv_code,assorted_code, rec_amount,premium_rcv_detail_code,remaining_amt, payrec, mode_code,coinsurance_code,class_cd,it_remarks) values('15Apr250002','040000174195','277951',(select max(to_number(i.premium_rcv_detail_code))+1 from ins_premium_det i),'277951','277951','02', '11000003','00','Request by Mr. Raheel Malik 16-Apr-2025');
A13: LHR/LHR/F/FR/CMFTP/22495/05/2024 | B13: =VLOOKUP(A13,policy!B:C,2,0) -> 040000174755 | C13: 2734 | D13: =ROUND(C13,0) -> 2734 | E13: 15Apr250002 | F13: ="insert into ins_premium_det (premium_rcv_code,assorted_code, rec_amount,premium_rcv_detail_code,remaining_amt, payrec, mode_code,coinsurance_code,class_cd,it_remarks) values" -> insert into ins_premium_det (premium_rcv_code,assorted_code, rec_amount,premium_rcv_detail_code,remaining_amt, payrec, mode_code,coinsurance_code,class_cd,it_remarks) values | G13: ="('"&E13&"','"&B13&"','"&D13&"',(select max(to_number(i.premium_rcv_detail_code))+1 from ins_premium_det i),'"&D13&"','"&D13&"','02', '11000003','00','Request by Mr. Raheel Malik 16-Apr-2025');" -> ('15Apr250002','040000174755','2734',(select max(to_number(i.premium_rcv_detail_code))+1 from ins_premium_det i),'2734','2734','02', '11000003','00','Request by Mr. Raheel Malik 16-Apr-2025'); | H13: =F13&G13 -> insert into ins_premium_det (premium_rcv_code,assorted_code, rec_amount,premium_rcv_detail_code,remaining_amt, payrec, mode_code,coinsurance_code,class_cd,it_remarks) values('15Apr250002','040000174755','2734',(select max(to_number(i.premium_rcv_detail_code))+1 from ins_premium_det i),'2734','2734','02', '11000003','00','Request by Mr. Raheel Malik 16-Apr-2025');
... A41: LHR/LHR/F/FR/CMFTE/10711/10/2024 | B41: =VLOOKUP(A41,policy!B:C,2,0) -> 050000799611 | C41: -170 | D41: =ROUND(C41,0) -> -170 | E41: 15Apr250002 | F41: ="insert into ins_premium_det (premium_rcv_code,assorted_code, rec_amount,premium_rcv_detail_code,remaining_amt, payrec, mode_code,coinsurance_code,class_cd,it_remarks) values" -> insert into ins_premium_det (premium_rcv_code,assorted_code, rec_amount,premium_rcv_detail_code,remaining_amt, payrec, mode_code,coinsurance_code,class_cd,it_remarks) values | G41: ="('"&E41&"','"&B41&"','"&D41&"',(select max(to_number(i.premium_rcv_detail_code))+1 from ins_premium_det i),'"&D41&"','"&D41&"','02', '11000003','00','Request by Mr. Raheel Malik 16-Apr-2025');" -> ('15Apr250002','050000799611','-170',(select max(to_number(i.premium_rcv_detail_code))+1 from ins_premium_det i),'-170','-170','02', '11000003','00','Request by Mr. Raheel Malik 16-Apr-2025'); | H41: =F41&G41 -> insert into ins_premium_det (premium_rcv_code,assorted_code, rec_amount,premium_rcv_detail_code,remaining_amt, payrec, mode_code,coinsurance_code,class_cd,it_remarks) values('15Apr250002','050000799611','-170',(select max(to_number(i.premium_rcv_detail_code))+1 from ins_premium_det i),'-170','-170','02', '11000003','00','Request by Mr. Raheel Malik 16-Apr-2025');
C43: =SUM(C2:C41) -> 4355032 | D43: =SUM(D2:D41) -> 4355032

Sheet Sheet4
A1: KHI/HO/F/MI/FG/P/4642/10/2024 | B1: -10-2024 | D1: 4642 | E1: ="ia.assorted_string like '%"&D1&B1&"%' or" -> ia.assorted_string like '%4642-10-2024%' or
A2: KHI/HO/F/MI/CT/P/4643/10/2024 | B2: -10-2024 | D2: 4643 | E2: ="ia.assorted_string like '%"&D2&B2&"%' or" -> ia.assorted_string like '%4643-10-2024%' or
A3: KHI/HO/F/MI/CT/P/4644/10/2024 | B3: -10-2024 | D3: 4644 | E3: ="ia.assorted_string like '%"&D3&B3&"%' or" -> ia.assorted_string like '%4644-10-2024%' or
A4: KHI/HO/F/MI/ARC/P/4645/10/2024 | B4: -10-2024 | D4: 4645 | E4: ="ia.assorted_string like '%"&D4&B4&"%' or" -> ia.assorted_string like '%4645-10-2024%' or
A5: KHI/HO/F/EG/EET/P/1196/05/2024 | B5: -05-2024 | D5: 1196 | E5: ="ia.assorted_string like '%"&D5&B5&"%' or" -> ia.assorted_string like '%1196-05-2024%' or
A6: KHI/HO/F/MI/ARC/P/4646/10/2024 | B6: -10-2024 | D6: 4646 | E6: ="ia.assorted_string like '%"&D6&B6&"%' or" -> ia.assorted_string like '%4646-10-2024%' or
A7: KHI/HO/F/EG/MBD/P/1197/05/2024 | B7: -05-2024 | D7: 1197 | E7: ="ia.assorted_string like '%"&D7&B7&"%' or" -> ia.assorted_string like '%1197-05-2024%' or
A8: KHI/HO/F/EG/CPM/P/1198/05/2024 | B8: -05-2024 | D8: 1198 | E8: ="ia.assorted_string like '%"&D8&B8&"%' or" -> ia.assorted_string like '%1198-05-2024%' or
A9: KHI/HO/F/FR/ND/P/22274/05/2024 | B9: -05-2024 | D9: 22274 | E9: ="ia.assorted_string like '%"&D9&B9&"%' or" -> ia.assorted_string like '%22274-05-2024%' or
A10: KHI/HO/F/MI/TRR/P/290/05/2024 | B10: -05-2024 | D10: 290 | E10: ="ia.assorted_string like '%"&D10&B10&"%' or" -> ia.assorted_string like '%290-05-2024%' or
A11: KHI/HO/F/FR/CMFTP/22347/05/2024 | B11: -05-2024 | D11: 22347 | E11: ="ia.assorted_string like '%"&D11&B11&"%' or" -> ia.assorted_string like '%22347-05-2024%' or
A12: LHR/LHR/F/FR/CMFTP/22495/05/2024 | B12: -05-2024 | D12: 22495 | E12: ="ia.assorted_string like '%"&D12&B12&"%' or" -> ia.assorted_string like '%22495-05-2024%' or
... A40: LHR/LHR/F/FR/CMFTE/10711/10/2024 | B40: -10-2024 | D40: 10711 | E40: ="ia.assorted_string like '%"&D40&B40&"%' or" -> ia.assorted_string like '%10711-10-2024%' or

Sheet policy
B1: FUNC_ASSORTED_STRING(IA.ASSORTED_CODE) | C1: ASSORTED_CODE
A2: 1 | B2: KHI/HO/D/MO/PC COMP/C/22843/08/2024 | C2: 020000046453
A3: 2 | B3: LHR/LHR/F/FR/D/P/22843/08/2024 | C3: 040000181344
A4: 3 | B4: KHI/HO/F/MI/TRR/P/291/06/2024 | C4: 040000175006
A5: 4 | B5: FSD/FSD/D/FR/ND/P/21081/12/2023 | C5: 040000161221
A6: 5 | B6: KHI/HO/F/EG/MBD/P/1081/12/2023 | C6: 040000160795
A7: 6 | B7: LHR/LHR/D/MO/PC COMP/R/72290/05/2024 | C7: 080000160269
A8: 7 | B8: KHI/HO/F/EG/EET/P/1196/05/2024 | C8: 040000172420
A9: 8 | B9: KHI/HO/F/EG/CPM/P/1198/05/2024 | C9: 040000172427
A10: 9 | B10: KHI/HO/D/MO/PC COMP/E/41290/05/2024 | C10: 050000740706
A11: 10 | B11: KHI/HO/F/EG/MBD/P/1197/05/2024 | C11: 040000172425
A12: 11 | B12: KHI/HO/F/FR/ND/P/22274/05/2024 | C12: 040000172409
A13: 12 | B13: LHR/LHR/D/MO/PC TPP/P/88290/05/2024 | C13: 040000172481
... A102: 101 | B102: KHI/HO/D/MO/PC COMP/P/103412/12/2024 | C102: 040000191023

Sheet WC
A1: POLICY NO. | B1: Assorted_code | C1: Commission | D1: 15Apr250002
A2: LHR/LHR/F/FR/CMFTE/10711/10/2024 | B2: =VLOOKUP(A2,PC!B:C,2,0) -> 050000799611 | C2: 22 | D2: 15Apr250002 | E2: =VLOOKUP(A2,PC!B:D,3,0) -> 09000397 | F2: ="insert into ins_premium_det (premium_rcv_code,assorted_code, rec_amount,premium_rcv_detail_code,remaining_amt, payrec, mode_code,paid_to_code,class_cd) values" -> insert into ins_premium_det (premium_rcv_code,assorted_code, rec_amount,premium_rcv_detail_code,remaining_amt, payrec, mode_code,paid_to_code,class_cd) values | G2: ="('"&D1&"','"&B2&"','"&C2&"',(select max(to_number(i.premium_rcv_detail_code))+1 from ins_premium_det i),'"&C2&"','"&C2&"','03', '"&E2&"','00');" -> ('15Apr250002','050000799611','22',(select max(to_number(i.premium_rcv_detail_code))+1 from ins_premium_det i),'22','22','03', '09000397','00'); | H2: =F2&G2 -> insert into ins_premium_det (premium_rcv_code,assorted_code, rec_amount,premium_rcv_detail_code,remaining_amt, payrec, mode_code,paid_to_code,class_cd) values('15Apr250002','050000799611','22',(select max(to_number(i.premium_rcv_detail_code))+1 from ins_premium_det i),'22','22','03', '09000397','00');
A3: KHI/HO/F/EG/EET/P/1196/05/2024 | B3: =VLOOKUP(A3,PC!B:C,2,0) -> 040000172420 | C3: -910 | D3: 15Apr250002 | E3: =VLOOKUP(A3,PC!B:D,3,0) -> 09000278 | F3: ="insert into ins_premium_det (premium_rcv_code,assorted_code, rec_amount,premium_rcv_detail_code,remaining_amt, payrec, mode_code,paid_to_code,class_cd) values" -> insert into ins_premium_det (premium_rcv_code,assorted_code, rec_amount,premium_rcv_detail_code,remaining_amt, payrec, mode_code,paid_to_code,class_cd) values | G3: ="('"&D2&"','"&B3&"','"&C3&"',(select max(to_number(i.premium_rcv_detail_code))+1 from ins_premium_det i),'"&C3&"','"&C3&"','03', '"&E3&"','00');" -> ('15Apr250002','040000172420','-910',(select max(to_number(i.premium_rcv_detail_code))+1 from ins_premium_det i),'-910','-910','03', '09000278','00'); | H3: =F3&G3 -> insert into ins_premium_det (premium_rcv_code,assorted_code, rec_amount,premium_rcv_detail_code,remaining_amt, payrec, mode_code,paid_to_code,class_cd) values('15Apr250002','040000172420','-910',(select max(to_number(i.premium_rcv_detail_code))+1 from ins_premium_det i),'-910','-910','03', '09000278','00');
A4: KHI/HO/F/EG/MBD/P/1197/05/2024 | B4: =VLOOKUP(A4,PC!B:C,2,0) -> 040000172425 | C4: -2107 | D4: 15Apr250002 | E4: =VLOOKUP(A4,PC!B:D,3,0) -> 09000278 | F4: ="insert into ins_premium_det (premium_rcv_code,assorted_code, rec_amount,premium_rcv_detail_code,remaining_amt, payrec, mode_code,paid_to_code,class_cd) values" -> insert into ins_premium_det (premium_rcv_code,assorted_code, rec_amount,premium_rcv_detail_code,remaining_amt, payrec, mode_code,paid_to_code,class_cd) values | G4: ="('"&D3&"','"&B4&"','"&C4&"',(select max(to_number(i.premium_rcv_detail_code))+1 from ins_premium_det i),'"&C4&"','"&C4&"','03', '"&E4&"','00');" -> ('15Apr250002','040000172425','-2107',(select max(to_number(i.premium_rcv_detail_code))+1 from ins_premium_det i),'-2107','-2107','03', '09000278','00'); | H4: =F4&G4 -> insert into ins_premium_det (premium_rcv_code,assorted_code, rec_amount,premium_rcv_detail_code,remaining_amt, payrec, mode_code,paid_to_code,class_cd) values('15Apr250002','040000172425','-2107',(select max(to_number(i.premium_rcv_detail_code))+1 from ins_premium_det i),'-2107','-2107','03', '09000278','00');
A5: KHI/HO/F/EG/CPM/P/1198/05/2024 | B5: =VLOOKUP(A5,PC!B:C,2,0) -> 040000172427 | C5: -1330 | D5: 15Apr250002 | E5: =VLOOKUP(A5,PC!B:D,3,0) -> 09000278 | F5: ="insert into ins_premium_det (premium_rcv_code,assorted_code, rec_amount,premium_rcv_detail_code,remaining_amt, payrec, mode_code,paid_to_code,class_cd) values" -> insert into ins_premium_det (premium_rcv_code,assorted_code, rec_amount,premium_rcv_detail_code,remaining_amt, payrec, mode_code,paid_to_code,class_cd) values | G5: ="('"&D4&"','"&B5&"','"&C5&"',(select max(to_number(i.premium_rcv_detail_code))+1 from ins_premium_det i),'"&C5&"','"&C5&"','03', '"&E5&"','00');" -> ('15Apr250002','040000172427','-1330',(select max(to_number(i.premium_rcv_detail_code))+1 from ins_premium_det i),'-1330','-1330','03', '09000278','00'); | H5: =F5&G5 -> insert into ins_premium_det (premium_rcv_code,assorted_code, rec_amount,premium_rcv_detail_code,remaining_amt, payrec, mode_code,paid_to_code,class_cd) values('15Apr250002','040000172427','-1330',(select max(to_number(i.premium_rcv_detail_code))+1 from ins_premium_det i),'-1330','-1330','03', '09000278','00');
A6: KHI/HO/F/FR/ND/P/22274/05/2024 | B6: =VLOOKUP(A6,PC!B:C,2,0) -> 040000172409 | C6: -5206 | D6: 15Apr250002 | E6: =VLOOKUP(A6,PC!B:D,3,0) -> 09000278 | F6: ="insert into ins_premium_det (premium_rcv_code,assorted_code, rec_amount,premium_rcv_detail_code,remaining_amt, payrec, mode_code,paid_to_code,class_cd) values" -> insert into ins_premium_det (premium_rcv_code,assorted_code, rec_amount,premium_rcv_detail_code,remaining_amt, payrec, mode_code,paid_to_code,class_cd) values | G6: ="('"&D5&"','"&B6&"','"&C6&"',(select max(to_number(i.premium_rcv_detail_code))+1 from ins_premium_det i),'"&C6&"','"&C6&"','03', '"&E6&"','00');" -> ('15Apr250002','040000172409','-5206',(select max(to_number(i.premium_rcv_detail_code))+1 from ins_premium_det i),'-5206','-5206','03', '09000278','00'); | H6: =F6&G6 -> insert into ins_premium_det (premium_rcv_code,assorted_code, rec_amount,premium_rcv_detail_code,remaining_amt, payrec, mode_code,paid_to_code,class_cd) values('15Apr250002','040000172409','-5206',(select max(to_number(i.premium_rcv_detail_code))+1 from ins_premium_det i),'-5206','-5206','03', '09000278','00');
A7: KHI/HO/F/MI/TRR/P/290/05/2024 | B7: =VLOOKUP(A7,PC!B:C,2,0) -> 040000174621 | C7: -1795 | D7: 15Apr250002 | E7: =VLOOKUP(A7,PC!B:D,3,0) -> 09000278 | F7: ="insert into ins_premium_det (premium_rcv_code,assorted_code, rec_amount,premium_rcv_detail_code,remaining_amt, payrec, mode_code,paid_to_code,class_cd) values" -> insert into ins_premium_det (premium_rcv_code,assorted_code, rec_amount,premium_rcv_detail_code,remaining_amt, payrec, mode_code,paid_to_code,class_cd) values | G7: ="('"&D6&"','"&B7&"','"&C7&"',(select max(to_number(i.premium_rcv_detail_code))+1 from ins_premium_det i),'"&C7&"','"&C7&"','03', '"&E7&"','00');" -> ('15Apr250002','040000174621','-1795',(select max(to_number(i.premium_rcv_detail_code))+1 from ins_premium_det i),'-1795','-1795','03', '09000278','00'); | H7: =F7&G7 -> insert into ins_premium_det (premium_rcv_code,assorted_code, rec_amount,premium_rcv_detail_code,remaining_amt, payrec, mode_code,paid_to_code,class_cd) values('15Apr250002','040000174621','-1795',(select max(to_number(i.premium_rcv_detail_code))+1 from ins_premium_det i),'-1795','-1795','03', '09000278','00');
A8: KHI/HO/F/FR/CMFTP/22347/05/2024 | B8: =VLOOKUP(A8,PC!B:C,2,0) -> 040000174195 | C8: -36558 | D8: 15Apr250002 | E8: =VLOOKUP(A8,PC!B:D,3,0) -> 09000397 | F8: ="insert into ins_premium_det (premium_rcv_code,assorted_code, rec_amount,premium_rcv_detail_code,remaining_amt, payrec, mode_code,paid_to_code,class_cd) values" -> insert into ins_premium_det (premium_rcv_code,assorted_code, rec_amount,premium_rcv_detail_code,remaining_amt, payrec, mode_code,paid_to_code,class_cd) values | G8: ="('"&D7&"','"&B8&"','"&C8&"',(select max(to_number(i.premium_rcv_detail_code))+1 from ins_premium_det i),'"&C8&"','"&C8&"','03', '"&E8&"','00');" -> ('15Apr250002','040000174195','-36558',(select max(to_number(i.premium_rcv_detail_code))+1 from ins_premium_det i),'-36558','-36558','03', '09000397','00'); | H8: =F8&G8 -> insert into ins_premium_det (premium_rcv_code,assorted_code, rec_amount,premium_rcv_detail_code,remaining_amt, payrec, mode_code,paid_to_code,class_cd) values('15Apr250002','040000174195','-36558',(select max(to_number(i.premium_rcv_detail_code))+1 from ins_premium_det i),'-36558','-36558','03', '09000397','00');
A9: LHR/LHR/F/FR/CMFTP/22495/05/2024 | B9: =VLOOKUP(A9,PC!B:C,2,0) -> 040000174755 | C9: -337 | D9: 15Apr250002 | E9: =VLOOKUP(A9,PC!B:D,3,0) -> 09000397 | F9: ="insert into ins_premium_det (premium_rcv_code,assorted_code, rec_amount,premium_rcv_detail_code,remaining_amt, payrec, mode_code,paid_to_code,class_cd) values" -> insert into ins_premium_det (premium_rcv_code,assorted_code, rec_amount,premium_rcv_detail_code,remaining_amt, payrec, mode_code,paid_to_code,class_cd) values | G9: ="('"&D8&"','"&B9&"','"&C9&"',(select max(to_number(i.premium_rcv_detail_code))+1 from ins_premium_det i),'"&C9&"','"&C9&"','03', '"&E9&"','00');" -> ('15Apr250002','040000174755','-337',(select max(to_number(i.premium_rcv_detail_code))+1 from ins_premium_det i),'-337','-337','03', '09000397','00'); | H9: =F9&G9 -> insert into ins_premium_det (premium_rcv_code,assorted_code, rec_amount,premium_rcv_detail_code,remaining_amt, payrec, mode_code,paid_to_code,class_cd) values('15Apr250002','040000174755','-337',(select max(to_number(i.premium_rcv_detail_code))+1 from ins_premium_det i),'-337','-337','03', '09000397','00');
A10: KHI/HO/F/MI/TRR/P/291/06/2024 | B10: =VLOOKUP(A10,PC!B:C,2,0) -> 040000175006 | C10: -10998 | D10: 15Apr250002 | E10: =VLOOKUP(A10,PC!B:D,3,0) -> 09000397 | F10: ="insert into ins_premium_det (premium_rcv_code,assorted_code, rec_amount,premium_rcv_detail_code,remaining_amt, payrec, mode_code,paid_to_code,class_cd) values" -> insert into ins_premium_det (premium_rcv_code,assorted_code, rec_amount,premium_rcv_detail_code,remaining_amt, payrec, mode_code,paid_to_code,class_cd) values | G10: ="('"&D9&"','"&B10&"','"&C10&"',(select max(to_number(i.premium_rcv_detail_code))+1 from ins_premium_det i),'"&C10&"','"&C10&"','03', '"&E10&"','00');" -> ('15Apr250002','040000175006','-10998',(select max(to_number(i.premium_rcv_detail_code))+1 from ins_premium_det i),'-10998','-10998','03', '09000397','00'); | H10: =F10&G10 -> insert into ins_premium_det (premium_rcv_code,assorted_code, rec_amount,premium_rcv_detail_code,remaining_amt, payrec, mode_code,paid_to_code,class_cd) values('15Apr250002','040000175006','-10998',(select max(to_number(i.premium_rcv_detail_code))+1 from ins_premium_det i),'-10998','-10998','03', '09000397','00');
A11: KHI/HO/F/EG/EET/P/1237/07/2024 | B11: =VLOOKUP(A11,PC!B:C,2,0) -> 040000180179 | C11: -44 | D11: 15Apr250002 | E11: =VLOOKUP(A11,PC!B:D,3,0) -> 09000271 | F11: ="insert into ins_premium_det (premium_rcv_code,assorted_code, rec_amount,premium_rcv_detail_code,remaining_amt, payrec, mode_code,paid_to_code,class_cd) values" -> insert into ins_premium_det (premium_rcv_code,assorted_code, rec_amount,premium_rcv_detail_code,remaining_amt, payrec, mode_code,paid_to_code,class_cd) values | G11: ="('"&D10&"','"&B11&"','"&C11&"',(select max(to_number(i.premium_rcv_detail_code))+1 from ins_premium_det i),'"&C11&"','"&C11&"','03', '"&E11&"','00');" -> ('15Apr250002','040000180179','-44',(select max(to_number(i.premium_rcv_detail_code))+1 from ins_premium_det i),'-44','-44','03', '09000271','00'); | H11: =F11&G11 -> insert into ins_premium_det (premium_rcv_code,assorted_code, rec_amount,premium_rcv_detail_code,remaining_amt, payrec, mode_code,paid_to_code,class_cd) values('15Apr250002','040000180179','-44',(select max(to_number(i.premium_rcv_detail_code))+1 from ins_premium_det i),'-44','-44','03', '09000271','00');
A12: KHI/HO/F/EG/EET/P/1243/08/2024 | B12: =VLOOKUP(A12,PC!B:C,2,0) -> 040000181263 | C12: -3349 | D12: 15Apr250002 | E12: =VLOOKUP(A12,PC!B:D,3,0) -> 09000266 | F12: ="insert into ins_premium_det (premium_rcv_code,assorted_code, rec_amount,premium_rcv_detail_code,remaining_amt, payrec, mode_code,paid_to_code,class_cd) values" -> insert into ins_premium_det (premium_rcv_code,assorted_code, rec_amount,premium_rcv_detail_code,remaining_amt, payrec, mode_code,paid_to_code,class_cd) values | G12: ="('"&D11&"','"&B12&"','"&C12&"',(select max(to_number(i.premium_rcv_detail_code))+1 from ins_premium_det i),'"&C12&"','"&C12&"','03', '"&E12&"','00');" -> ('15Apr250002','040000181263','-3349',(select max(to_number(i.premium_rcv_detail_code))+1 from ins_premium_det i),'-3349','-3349','03', '09000266','00'); | H12: =F12&G12 -> insert into ins_premium_det (premium_rcv_code,assorted_code, rec_amount,premium_rcv_detail_code,remaining_amt, payrec, mode_code,paid_to_code,class_cd) values('15Apr250002','040000181263','-3349',(select max(to_number(i.premium_rcv_detail_code))+1 from ins_premium_det i),'-3349','-3349','03', '09000266','00');
A13: KHI/HO/F/EG/EET/P/1242/08/2024 | B13: =VLOOKUP(A13,PC!B:C,2,0) -> 040000181262 | C13: -1748 | D13: 15Apr250002 | E13: =VLOOKUP(A13,PC!B:D,3,0) -> 09000271 | F13: ="insert into ins_premium_det (premium_rcv_code,assorted_code, rec_amount,premium_rcv_detail_code,remaining_amt, payrec, mode_code,paid_to_code,class_cd) values" -> insert into ins_premium_det (premium_rcv_code,assorted_code, rec_amount,premium_rcv_detail_code,remaining_amt, payrec, mode_code,paid_to_code,class_cd) values | G13: ="('"&D12&"','"&B13&"','"&C13&"',(select max(to_number(i.premium_rcv_detail_code))+1 from ins_premium_det i),'"&C13&"','"&C13&"','03', '"&E13&"','00');" -> ('15Apr250002','040000181262','-1748',(select max(to_number(i.premium_rcv_detail_code))+1 from ins_premium_det i),'-1748','-1748','03', '09000271','00'); | H13: =F13&G13 -> insert into ins_premium_det (premium_rcv_code,assorted_code, rec_amount,premium_rcv_detail_code,remaining_amt, payrec, mode_code,paid_to_code,class_cd) values('15Apr250002','040000181262','-1748',(select max(to_number(i.premium_rcv_detail_code))+1 from ins_premium_det i),'-1748','-1748','03', '09000271','00');
... A31: KHI/HO/F/EG/EET/P/1256/11/2024 | B31: =VLOOKUP(A31,PC!B:C,2,0) -> 040000188606 | C31: -375 | D31: 15Apr250002 | E31: =VLOOKUP(A31,PC!B:D,3,0) -> 09000397 | F31: ="insert into ins_premium_det (premium_rcv_code,assorted_code, rec_amount,premium_rcv_detail_code,remaining_amt, payrec, mode_code,paid_to_code,class_cd) values" -> insert into ins_premium_det (premium_rcv_code,assorted_code, rec_amount,premium_rcv_detail_code,remaining_amt, payrec, mode_code,paid_to_code,class_cd) values | G31: ="('"&D30&"','"&B31&"','"&C31&"',(select max(to_number(i.premium_rcv_detail_code))+1 from ins_premium_det i),'"&C31&"','"&C31&"','03', '"&E31&"','00');" -> ('15Apr250002','040000188606','-375',(select max(to_number(i.premium_rcv_detail_code))+1 from ins_premium_det i),'-375','-375','03', '09000397','00'); | H31: =F31&G31 -> insert into ins_premium_det (premium_rcv_code,assorted_code, rec_amount,premium_rcv_detail_code,remaining_amt, payrec, mode_code,paid_to_code,class_cd) values('15Apr250002','040000188606','-375',(select max(to_number(i.premium_rcv_detail_code))+1 from ins_premium_det i),'-375','-375','03', '09000397','00');

Sheet Sheet7
A1: LHR/LHR/F/FR/CMFTE/10711/10/2024 | B1: -10-2024 | D1: 10711 | E1: ="ia.assorted_string like '%"&D1&B1&"%' or" -> ia.assorted_string like '%10711-10-2024%' or
A2: KHI/HO/F/EG/EET/P/1196/05/2024 | B2: -05-2024 | D2: 1196 | E2: ="ia.assorted_string like '%"&D2&B2&"%' or" -> ia.assorted_string like '%1196-05-2024%' or
A3: KHI/HO/F/EG/MBD/P/1197/05/2024 | B3: -05-2024 | D3: 1197 | E3: ="ia.assorted_string like '%"&D3&B3&"%' or" -> ia.assorted_string like '%1197-05-2024%' or
A4: KHI/HO/F/EG/CPM/P/1198/05/2024 | B4: -05-2024 | D4: 1198 | E4: ="ia.assorted_string like '%"&D4&B4&"%' or" -> ia.assorted_string like '%1198-05-2024%' or
A5: KHI/HO/F/FR/ND/P/22274/05/2024 | B5: -05-2024 | D5: 22274 | E5: ="ia.assorted_string like '%"&D5&B5&"%' or" -> ia.assorted_string like '%22274-05-2024%' or
A6: KHI/HO/F/MI/TRR/P/290/05/2024 | B6: -05-2024 | D6: 290 | E6: ="ia.assorted_string like '%"&D6&B6&"%' or" -> ia.assorted_string like '%290-05-2024%' or
A7: KHI/HO/F/FR/CMFTP/22347/05/2024 | B7: -05-2024 | D7: 22347 | E7: ="ia.assorted_string like '%"&D7&B7&"%' or" -> ia.assorted_string like '%22347-05-2024%' or
A8: LHR/LHR/F/FR/CMFTP/22495/05/2024 | B8: -05-2024 | D8: 22495 | E8: ="ia.assorted_string like '%"&D8&B8&"%' or" -> ia.assorted_string like '%22495-05-2024%' or
A9: KHI/HO/F/MI/TRR/P/291/06/2024 | B9: -06-2024 | D9: 291 | E9: ="ia.assorted_string like '%"&D9&B9&"%' or" -> ia.assorted_string like '%291-06-2024%' or
A10: KHI/HO/F/EG/EET/P/1237/07/2024 | B10: -07-2024 | D10: 1237 | E10: ="ia.assorted_string like '%"&D10&B10&"%' or" -> ia.assorted_string like '%1237-07-2024%' or
A11: KHI/HO/F/EG/EET/P/1243/08/2024 | B11: -08-2024 | D11: 1243 | E11: ="ia.assorted_string like '%"&D11&B11&"%' or" -> ia.assorted_string like '%1243-08-2024%' or
A12: KHI/HO/F/EG/EET/P/1242/08/2024 | B12: -08-2024 | D12: 1242 | E12: ="ia.assorted_string like '%"&D12&B12&"%' or" -> ia.assorted_string like '%1242-08-2024%' or
... A30: KHI/HO/F/EG/EET/P/1256/11/2024 | B30: -11-2024 | D30: 1256 | E30: ="ia.assorted_string like '%"&D30&B30&"%' or" -> ia.assorted_string like '%1256-11-2024%' or

Sheet PC
B1: FUNC_ASSORTED_STRING(IA.ASSORTED_CODE) | C1: ASSORTED_CODE | D1: AGENCY_CODE
A2: 1 | B2: KHI/HO/F/MI/TRR/P/291/06/2024 | C2: 040000175006 | D2: 09000397
A3: 2 | B3: LHR/LHR/D/MO/PC COMP/R/72290/05/2024 | C3: 080000160269 | D3: 09000497
A4: 3 | B4: KHI/HO/F/EG/EET/P/1196/05/2024 | C4: 040000172420 | D4: 09000278
A5: 4 | B5: KHI/HO/F/EG/CPM/P/1198/05/2024 | C5: 040000172427 | D5: 09000278
A6: 5 | B6: KHI/HO/D/MO/PC COMP/E/41290/05/2024 | C6: 050000740706 | D6: 09000323
A7: 6 | B7: KHI/HO/F/EG/MBD/P/1197/05/2024 | C7: 040000172425 | D7: 09000278
A8: 7 | B8: KHI/HO/F/FR/ND/P/22274/05/2024 | C8: 040000172409 | D8: 09000278
A9: 8 | B9: LHR/LHR/D/MO/PC TPP/P/88290/05/2024 | C9: 040000172481 | D9: 09000442
A10: 9 | B10: KHI/HO/F/FR/CMFTE/10487/08/2024 | C10: 050000777897 | D10: 09000397
A11: 10 | B11: LHR/LHR/D/FR/ND/P/22290/05/2024 | C11: 040000172919 | D11: 09000738
A12: 11 | B12: KHI/AR/AR/D/MO/MC TTT/R/69290/05/2024 | C12: 080000159921 | D12: 09000221
A13: 12 | B13: KHI/HO/D/MO/PD COMP/E/42291/06/2024 | C13: 050000756532 | D13: 09000329
... A71: 70 | B71: KHI/HO/D/MO/PC COMP/P/103412/12/2024 | C71: 040000191023 | D71: 09000539

Sheet wsc
A1: POLICY NO. | B1: Assorted_code | C1: Commission | D1: 15Apr250002
A2: LHR/LHR/F/FR/CMFTE/10711/10/2024 | B2: =VLOOKUP(A2,psc!B:D,2,0) -> 050000799611 | C2: 4 | D2: 15Apr250002 | E2: =VLOOKUP(A2,psc!B:D,3,0) -> 09000397 | F2: ="insert into ins_premium_det (premium_rcv_code,assorted_code, rec_amount,premium_rcv_detail_code,remaining_amt, payrec, mode_code,paid_to_code,class_cd) values" -> insert into ins_premium_det (premium_rcv_code,assorted_code, rec_amount,premium_rcv_detail_code,remaining_amt, payrec, mode_code,paid_to_code,class_cd) values | G2: ="('"&D1&"','"&B2&"','"&C2&"',(select max(to_number(i.premium_rcv_detail_code))+1 from ins_premium_det i),'"&C2&"','"&C2&"','05', '"&E2&"','00');" -> ('15Apr250002','050000799611','4',(select max(to_number(i.premium_rcv_detail_code))+1 from ins_premium_det i),'4','4','05', '09000397','00'); | H2: =F2&G2 -> insert into ins_premium_det (premium_rcv_code,assorted_code, rec_amount,premium_rcv_detail_code,remaining_amt, payrec, mode_code,paid_to_code,class_cd) values('15Apr250002','050000799611','4',(select max(to_number(i.premium_rcv_detail_code))+1 from ins_premium_det i),'4','4','05', '09000397','00');
A3: KHI/HO/F/MI/FG/P/4642/10/2024 | B3: =VLOOKUP(A3,psc!B:D,2,0) -> 040000185733 | C3: -286 | D3: 15Apr250002 | E3: =VLOOKUP(A3,psc!B:D,3,0) -> 09000278 | F3: ="insert into ins_premium_det (premium_rcv_code,assorted_code, rec_amount,premium_rcv_detail_code,remaining_amt, payrec, mode_code,paid_to_code,class_cd) values" -> insert into ins_premium_det (premium_rcv_code,assorted_code, rec_amount,premium_rcv_detail_code,remaining_amt, payrec, mode_code,paid_to_code,class_cd) values | G3: ="('"&D2&"','"&B3&"','"&C3&"',(select max(to_number(i.premium_rcv_detail_code))+1 from ins_premium_det i),'"&C3&"','"&C3&"','05', '"&E3&"','00');" -> ('15Apr250002','040000185733','-286',(select max(to_number(i.premium_rcv_detail_code))+1 from ins_premium_det i),'-286','-286','05', '09000278','00'); | H3: =F3&G3 -> insert into ins_premium_det (premium_rcv_code,assorted_code, rec_amount,premium_rcv_detail_code,remaining_amt, payrec, mode_code,paid_to_code,class_cd) values('15Apr250002','040000185733','-286',(select max(to_number(i.premium_rcv_detail_code))+1 from ins_premium_det i),'-286','-286','05', '09000278','00');
A4: KHI/HO/F/MI/CT/P/4643/10/2024 | B4: =VLOOKUP(A4,psc!B:D,2,0) -> 040000185737 | C4: -356 | D4: 15Apr250002 | E4: =VLOOKUP(A4,psc!B:D,3,0) -> 09000278 | F4: ="insert into ins_premium_det (premium_rcv_code,assorted_code, rec_amount,premium_rcv_detail_code,remaining_amt, payrec, mode_code,paid_to_code,class_cd) values" -> insert into ins_premium_det (premium_rcv_code,assorted_code, rec_amount,premium_rcv_detail_code,remaining_amt, payrec, mode_code,paid_to_code,class_cd) values | G4: ="('"&D3&"','"&B4&"','"&C4&"',(select max(to_number(i.premium_rcv_detail_code))+1 from ins_premium_det i),'"&C4&"','"&C4&"','05', '"&E4&"','00');" -> ('15Apr250002','040000185737','-356',(select max(to_number(i.premium_rcv_detail_code))+1 from ins_premium_det i),'-356','-356','05', '09000278','00'); | H4: =F4&G4 -> insert into ins_premium_det (premium_rcv_code,assorted_code, rec_amount,premium_rcv_detail_code,remaining_amt, payrec, mode_code,paid_to_code,class_cd) values('15Apr250002','040000185737','-356',(select max(to_number(i.premium_rcv_detail_code))+1 from ins_premium_det i),'-356','-356','05', '09000278','00');
A5: KHI/HO/F/MI/CT/P/4644/10/2024 | B5: =VLOOKUP(A5,psc!B:D,2,0) -> 040000185739 | C5: -153 | D5: 15Apr250002 | E5: =VLOOKUP(A5,psc!B:D,3,0) -> 09000278 | F5: ="insert into ins_premium_det (premium_rcv_code,assorted_code, rec_amount,premium_rcv_detail_code,remaining_amt, payrec, mode_code,paid_to_code,class_cd) values" -> insert into ins_premium_det (premium_rcv_code,assorted_code, rec_amount,premium_rcv_detail_code,remaining_amt, payrec, mode_code,paid_to_code,class_cd) values | G5: ="('"&D4&"','"&B5&"','"&C5&"',(select max(to_number(i.premium_rcv_detail_code))+1 from ins_premium_det i),'"&C5&"','"&C5&"','05', '"&E5&"','00');" -> ('15Apr250002','040000185739','-153',(select max(to_number(i.premium_rcv_detail_code))+1 from ins_premium_det i),'-153','-153','05', '09000278','00'); | H5: =F5&G5 -> insert into ins_premium_det (premium_rcv_code,assorted_code, rec_amount,premium_rcv_detail_code,remaining_amt, payrec, mode_code,paid_to_code,class_cd) values('15Apr250002','040000185739','-153',(select max(to_number(i.premium_rcv_detail_code))+1 from ins_premium_det i),'-153','-153','05', '09000278','00');
