Workbook

Sheet Fresh
A1: Fresh / Renewal | B1: Proposal No. | C1: Billing Month | D1: Takaful Company | E1: PMD / Cert | F1: Takaful Start Date | G1: Takaful End Date | H1: Customer Name | I1: CNIC | J1: Vehicle Make | K1: Reg. No | L1: Engine No | M1: Chassis No | N1: Proposal No. | O1: Region | P1: Unit ID | Q1: BR # | R1: Financing Date | S1: Maturity Date | T1: Asset Value | U1: Dep. % | V1: Dep. Amount | W1: Sum Cover Amount | X1: Takaful Rate | Y1: Premium Amount | Z1: For Takaful Company Rectifications | AA1: For COD Status | AB1: PO No. | AC1: PO Dates | AD1: Proposal Status | AE1: Default Case (Overdue Days) | AF1: Policy # 2024 | AG1: Tms Prem | AH1: Difference
A2: Fresh | B2: 75893/1 | C2: 45566 | D2: SALAAM TAKAFUL LTD | E2: KHI/HO/D/MO/PC COMP/C/98823/51/10/2024 | F2: 45596 | G2: 45960 | H2: KHURRAM MUSADDIQ | I2: 1350332678601 | J2: TOYOTA COROLLA ALTIS (MANUAL) | K2: BAA-759 | L2: 97221 | M2: 6074725 | N2: 75893/1 | O2: North | P2: 0804 | Q2: 242368 | R2: 45597 | S2: 46696 | T2: 5000000 | W2: 5000000 | X2: 1.5 | Y2: 75000 | AA2: paid | AB2: 1141071545 | AC2: 45622 | AD2: DISBURSED | AE2: 0 | AF2: KHI/HO/D/MO/PC COMP/C/98823/51/10/2024 | AG2: 75000 | AH2: =Y2-AG2 -> 0
A3: Fresh | B3: 76157/1 | C3: 45566 | D3: SALAAM TAKAFUL LTD | E3: KHI/HO/D/MO/PC COMP/C/98823/50/10/2024 | F3: 45596 | G3: 45960 | H3: MUHAMMAD SHAHBAZ | I3: 4220174438973 | J3: DAYZ | K3: BTH-458 | L3: 3B20LK5102 | M3: W0484257 | N3: 76157/1 | O3: South | P3: 0144 | Q3: 343045 | R3: 45597 | S3: 47063 | T3: 2700000 | W3: 2700000 | X3: 2 | Y3: 54000 | AA3: paid | AB3: 1141071545 | AC3: 45622 | AD3: DISBURSED | AE3: 0 | AF3: KHI/HO/D/MO/PC COMP/C/98823/50/10/2024 | AG3: 54000 | AH3: =Y3-AG3 -> 0
A4: Fresh | B4: 76158/1 | C4: 45566 | D4: SALAAM TAKAFUL LTD | E4: KHI/HO/D/MO/PC COMP/C/98823/49/10/2024 | F4: 45596 | G4: 45960 | H4: SHAKEEL AHMAD | I4: 3520211099861 | J4: TOYOTA COROLLA GLI | K4: AAL-595 | L4: Z574209 | M4: R-4200501 | N4: 76158/1 | O4: Central | P4: 0329 | Q4: 497100 | R4: 45597 | S4: 47063 | T4: 4400000 | W4: 4400000 | X4: 1.5 | Y4: 66000 | AA4: paid | AB4: 1141071545 | AC4: 45622 | AD4: DISBURSED | AE4: 0 | AF4: KHI/HO/D/MO/PC COMP/C/98823/49/10/2024 | AG4: 66000 | AH4: =Y4-AG4 -> 0
A5: Fresh | B5: 75915/1 | C5: 45566 | D5: SALAAM TAKAFUL LTD | E5: KHI/HO/D/MO/PC COMP/C/98823/48/10/2024 | F5: 45596 | G5: 45960 | H5: MUHAMMAD ASIM | I5: 1350333830439 | J5: ALSVIN 1.5 L LUMIERE | K5: AZT-636 | L5: 531660 | M5: 1009870 | N5: 75915/1 | O5: North | P5: 0804 | Q5: 164222 | R5: 45597 | S5: 46696 | T5: 3900000 | W5: 3900000 | X5: 1.5 | Y5: 58500 | AA5: paid | AB5: 1141071545 | AC5: 45622 | AD5: DISBURSED | AE5: 0 | AF5: KHI/HO/D/MO/PC COMP/C/98823/48/10/2024 | AG5: 58500 | AH5: =Y5-AG5 -> 0
A6: Fresh | B6: 76079/1 | C6: 45566 | D6: SALAAM TAKAFUL LTD | E6: KHI/HO/D/MO/PC COMP/C/98823/47/10/2024 | F6: 45596 | G6: 45960 | H6: ALI HUSSNAIN | I6: 3660309485047 | J6: ALSVIN 1.3 | K6: - | L6: 503322 | M6: 1002216 | N6: 76079/1 | O6: Central | P6: 0555 | Q6: 657557 | R6: 45597 | S6: 46696 | T6: 3799000 | W6: 3799000 | X6: 1.5 | Y6: 56985 | AA6: paid | AB6: 1141071545 | AC6: 45622 | AD6: DISBURSED | AE6: 0 | AF6: KHI/HO/D/MO/PC COMP/C/98823/47/10/2024 | AG6: 56985 | AH6: =Y6-AG6 -> 0
A7: Fresh | B7: 75688/1 | C7: 45566 | D7: SALAAM TAKAFUL LTD | E7: KHI/HO/D/MO/PC COMP/C/98823/46/10/2024 | F7: 45596 | G7: 45960 | H7: RAJA RIZWAN LATIF | I7: 3520220667145 | J7: MEHRAN VXR (METALLIC) | K7: LEB-17A-5788 | L7: PKB708422 | M7: PK01246990 | N7: 75688/1 | O7: Central | P7: 0329 | Q7: 659875 | R7: 45597 | S7: 47063 | T7: 1030000 | W7: 1030000 | X7: 2 | Y7: 20600 | AA7: paid | AB7: 1141071545 | AC7: 45622 | AD7: DISBURSED | AE7: 0 | AF7: KHI/HO/D/MO/PC COMP/C/98823/46/10/2024 | AG7: 20600 | AH7: =Y7-AG7 -> 0
A8: Fresh | B8: 75570/1 | C8: 45566 | D8: SALAAM TAKAFUL LTD | E8: KHI/HO/D/MO/PC COMP/C/98823/45/10/2024 | F8: 45596 | G8: 45960 | H8: NABEEL AHMED | I8: 3520230934073 | J8: ALSVIN 1.5 L LUMIERE | K8: AHA-376 | L8: 529309 | M8: 1006094 | N8: 75570/1 | O8: Central | P8: 0329 | Q8: 659581 | R8: 45597 | S8: 46696 | T8: 4000000 | W8: 4000000 | X8: 1.5 | Y8: 60000 | AA8: paid | AB8: 1141071545 | AC8: 45622 | AD8: DISBURSED | AE8: 0 | AF8: KHI/HO/D/MO/PC COMP/C/98823/45/10/2024 | AG8: 60000 | AH8: =Y8-AG8 -> 0
A9: Fresh | B9: 74166/1 | C9: 45566 | D9: SALAAM TAKAFUL LTD | E9: KHI/HO/D/MO/PC COMP/C/98823/44/10/2024 | F9: 45596 | G9: 45960 | H9: MUHAMMAD ASGHAR | I9: 3520185477583 | J9: ALTO VXR (METALLIC) | K9: AAK-969 | L9: 6R138903 | M9: H1038896 | N9: 74166/1 | O9: Central | P9: 0329 | Q9: 296002 | R9: 45597 | S9: 47427 | T9: 2150000 | W9: 2150000 | X9: 2 | Y9: 43000 | AA9: paid | AB9: 1141071545 | AC9: 45622 | AD9: DISBURSED | AE9: 0 | AF9: KHI/HO/D/MO/PC COMP/C/98823/44/10/2024 | AG9: 43000 | AH9: =Y9-AG9 -> 0
A10: Fresh | B10: 75618/1 | C10: 45566 | D10: SALAAM TAKAFUL LTD | E10: KHI/HO/D/MO/PC COMP/C/98823/43/10/2024 | F10: 45596 | G10: 45960 | H10: SALMAN UL HASAN FAROOQUI | I10: 4220137933467 | J10: YARIS | K10: BTJ-559 | L10: 23589 | M10: 7014189 | N10: 75618/1 | O10: South | P10: 0150 | Q10: 660005 | R10: 45602 | S10: 46696 | T10: 3800000 | W10: 3800000 | X10: 1.5 | Y10: 57000 | AA10: paid | AB10: 1141071545 | AC10: 45622 | AD10: DISBURSED | AE10: 0 | AF10: KHI/HO/D/MO/PC COMP/C/98823/43/10/2024 | AG10: 57000 | AH10: =Y10-AG10 -> 0
A11: Fresh | B11: 75942/1 | C11: 45566 | D11: SALAAM TAKAFUL LTD | E11: KHI/HO/D/MO/PC COMP/C/98823/42/10/2024 | F11: 45595 | G11: 45959 | H11: HAIDER ALI | I11: 9030901099687 | J11: CIVIC (MANUAL) | K11: LEA-18-903 | L11: 12926921 | M11: R030285 | N11: 75942/1 | O11: Central | P11: 0431 | Q11: 661080 | R11: 45597 | S11: 46696 | T11: 4850000 | W11: 4850000 | X11: 1.5 | Y11: 72750 | AA11: paid | AB11: 1141071545 | AC11: 45622 | AD11: DISBURSED | AE11: 0 | AF11: KHI/HO/D/MO/PC COMP/C/98823/42/10/2024 | AG11: 72750 | AH11: =Y11-AG11 -> 0
A12: Fresh | B12: 75891/1 | C12: 45566 | D12: SALAAM TAKAFUL LTD | E12: KHI/HO/D/MO/PC COMP/C/98823/41/10/2024 | F12: 45595 | G12: 45959 | H12: QAMAR UZ ZAMAN | I12: 3520243032339 | J12: ALTO VXR (NON-METALLIC) | K12: - | L12: 6R323153 | M12: H1223088 | N12: 75891/1 | O12: Central | P12: 0329 | Q12: 626392 | R12: 45597 | S12: 46331 | T12: 2707000 | W12: 2707000 | X12: 2 | Y12: 54140 | AA12: paid | AB12: 1141071545 | AC12: 45622 | AD12: DISBURSED | AE12: 0 | AF12: KHI/HO/D/MO/PC COMP/C/98823/41/10/2024 | AG12: 54140 | AH12: =Y12-AG12 -> 0
A13: Fresh | B13: 75543/1 | C13: 45566 | D13: SALAAM TAKAFUL LTD | E13: KHI/HO/D/MO/PC COMP/C/98823/40/10/2024 | F13: 45595 | G13: 45959 | H13: MUHAMMAD MUZAFFAR ALI KHAN | I13: 3660151263187 | J13: CULTUS VXR (METALIC) | K13: ABV-425 | L13: 634550 | M13: 541421 | N13: 75543/1 | O13: North | P13: 0804 | Q13: 659612 | R13: 45596 | S13: 47063 | T13: 2120000 | W13: 2120000 | X13: 2 | Y13: 42400 | AA13: paid | AB13: 1141071545 | AC13: 45622 | AD13: DISBURSED | AE13: 0 | AF13: KHI/HO/D/MO/PC COMP/C/98823/40/10/2024 | AG13: 42400 | AH13: =Y13-AG13 -> 0
A14: Fresh | B14: 76121/1 | C14: 45566 | D14: SALAAM TAKAFUL LTD | E14: KHI/HO/D/MO/PC COMP/C/98823/39/10/2024 | F14: 45595 | G14: 45959 | H14: REHAN NAZIR | I14: 3610168395965 | J14: TOYOTA COROLLA ALTIS (AUTOMATIC) | K14: BRP-676 | L14: Q062300 | M14: 6039799 | N14: 76121/1 | O14: Central | P14: 0431 | Q14: 436812 | R14: 45597 | S14: 46696 | T14: 4700000 | W14: 4700000 | X14: 1.5 | Y14: 70500 | AA14: paid | AB14: 1141071545 | AC14: 45622 | AD14: DISBURSED | AE14: 0 | AF14: KHI/HO/D/MO/PC COMP/C/98823/39/10/2024 | AG14: 70500 | AH14: =Y14-AG14 -> 0
A15: Fresh | B15: 75678/1 | C15: 45566 | D15: SALAAM TAKAFUL LTD | E15: KHI/HO/D/MO/PC COMP/C/98823/38/10/2024 | F15: 45595 | G15: 45959 | H15: WASEEM AHMED | I15: 3520273878127 | J15: ALTO VXR (NON-METALLIC) | K15: AJB-244 | L15: R197948 | M15: 1097956 | N15: 75678/1 | O15: Central | P15: 0329 | Q15: 660574 | R15: 45597 | S15: 47427 | T15: 2400000 | W15: 2400000 | X15: 2 | Y15: 48000 | AA15: paid | AB15: 1141071545 | AC15: 45622 | AD15: DISBURSED | AE15: 0 | AF15: KHI/HO/D/MO/PC COMP/C/98823/38/10/2024 | AG15: 48000 | AH15: =Y15-AG15 -> 0
A16: Fresh | B16: 75529/1 | C16: 45566 | D16: SALAAM TAKAFUL LTD | E16: KHI/HO/D/MO/PC COMP/C/98823/37/10/2024 | F16: 45595 | G16: 45959 | H16: KASHIF FAZAL HUSSAIN | I16: 3410126964351 | J16: CITY (AUTOMATIC) | K16: - | L16: 1028092 | M16: RR044847 | N16: 75529/1 | O16: Central | P16: 0329 | Q16: 340359 | R16: 45597 | S16: 46696 | T16: 4749000 | W16: 4749000 | X16: 1.5 | Y16: 71235 | AA16: paid | AB16: 1141071545 | AC16: 45622 | AD16: DISBURSED | AE16: 0 | AF16: KHI/HO/D/MO/PC COMP/C/98823/37/10/2024 | AG16: 71235 | AH16: =Y16-AG16 -> 0
A17: Fresh | B17: 76128/1 | C17: 45566 | D17: SALAAM TAKAFUL LTD | E17: KHI/HO/D/MO/PC COMP/C/98823/36/10/2024 | F17: 45595 | G17: 45959 | H17: AWAIS ZAHID | I17: 3520108366339 | J17: REVO | K17: KW-8800 | L17: 963667 | M17: 0963412 | N17: 76128/1 | O17: Central | P17: 0329 | Q17: 592294 | R17: 45601 | S17: 47063 | T17: 8500000 | W17: 8500000 | X17: 1.5 | Y17: 127500 | AA17: paid | AB17: 1141071545 | AC17: 45622 | AD17: DISBURSED | AE17: 0 | AF17: KHI/HO/D/MO/PC COMP/C/98823/36/10/2024 | AG17: 127500 | AH17: =Y17-AG17 -> 0
A18: Fresh | B18: 75659/1 | C18: 45566 | D18: SALAAM TAKAFUL LTD | E18: KHI/HO/D/MO/PC COMP/C/98823/35/10/2024 | F18: 45595 | G18: 45959 | H18: ABDUL RAZZAK VOHRA | I18: 4210160978429 | J18: ALTO VXL | K18: BZD-477 | L18: 6R284803 | M18: H1185221 | N18: 75659/1 | O18: South | P18: 0144 | Q18: 659794 | R18: 45597 | S18: 47427 | T18: 2950000 | W18: 2950000 | X18: 2 | Y18: 59000 | AA18: paid | AB18: 1141071545 | AC18: 45622 | AD18: DISBURSED | AE18: 0 | AF18: KHI/HO/D/MO/PC COMP/C/98823/35/10/2024 | AG18: 59000 | AH18: =Y18-AG18 -> 0
A19: Fresh | B19: 75276/1 | C19: 45566 | D19: SALAAM TAKAFUL LTD | E19: KHI/HO/D/MO/PC COMP/C/98823/34/10/2024 | F19: 45595 | G19: 45959 | H19: HARIS ZAHID BUTT | I19: 3520260172681 | J19: SWIFT GL CVT | K19: LED-19-2722 | L19: PKS13045075 | M19: PK100450 | N19: 75276/1 | O19: Central | P19: 0329 | Q19: 430990 | R19: 45597 | S19: 46331 | T19: 2300000 | W19: 2300000 | X19: 2 | Y19: 46000 | AA19: paid | AB19: 1141071545 | AC19: 45622 | AD19: DISBURSED | AE19: 0 | AF19: KHI/HO/D/MO/PC COMP/C/98823/34/10/2024 | AG19: 46000 | AH19: =Y19-AG19 -> 0
A20: Fresh | B20: 75419/1 | C20: 45566 | D20: SALAAM TAKAFUL LTD | E20: KHI/HO/D/MO/PC COMP/C/98823/33/10/2024 | F20: 45594 | G20: 45958 | H20: HASSAN RAZA | I20: 3520161498951 | J20: GRANDE AT | K20: LEF-16-163 | L20: Q317215 | M20: R7016267 | N20: 75419/1 | O20: Central | P20: 0329 | Q20: 635955 | R20: 45595 | S20: 46331 | T20: 3800000 | W20: 3800000 | X20: 1.5 | Y20: 57000 | AA20: paid | AB20: 1141071545 | AC20: 45622 | AD20: DISBURSED | AE20: 0 | AF20: KHI/HO/D/MO/PC COMP/C/98823/33/10/2024 | AG20: 57000 | AH20: =Y20-AG20 -> 0
A21: Fresh | B21: 75744/1 | C21: 45566 | D21: SALAAM TAKAFUL LTD | E21: KHI/HO/D/MO/PC COMP/C/98823/32/10/2024 | F21: 45594 | G21: 45958 | H21: MUHAMMAD NAZEEM | I21: 4220105169215 | J21: ALTO VXL AGS | K21: BZL-889 | L21: 6R294906 | M21: 1194752 | N21: 75744/1 | O21: South | P21: 0155 | Q21: 575700 | R21: 45595 | S21: 46696 | T21: 3045000 | W21: 3045000 | X21: 2 | Y21: 60900 | AA21: paid | AB21: 1141071545 | AC21: 45622 | AD21: DISBURSED | AE21: 0 | AF21: KHI/HO/D/MO/PC COMP/C/98823/32/10/2024 | AG21: 60900 | AH21: =Y21-AG21 -> 0
A22: Fresh | B22: 75404/1 | C22: 45566 | D22: SALAAM TAKAFUL LTD | E22: KHI/HO/D/MO/PC COMP/C/98823/31/10/2024 | F22: 45593 | G22: 45957 | H22: NASEEB ULLAH | I22: 4230136322853 | J22: GRANDE AT | K22: BWV-034 | L22: Q350356 | M22: 7049517 | N22: 75404/1 | O22: South | P22: 0144 | Q22: 658879 | R22: 45595 | S22: 46696 | T22: 5950000 | W22: 5950000 | X22: 1.5 | Y22: 89250 | AA22: paid | AB22: 1141071545 | AC22: 45622 | AD22: DISBURSED | AE22: 0 | AF22: KHI/HO/D/MO/PC COMP/C/98823/31/10/2024 | AG22: 89250 | AH22: =Y22-AG22 -> 0
A23: Fresh | B23: 75532/1 | C23: 45566 | D23: SALAAM TAKAFUL LTD | E23: KHI/HO/D/MO/PC COMP/C/98823/30/10/2024 | F23: 45590 | G23: 45590 | H23: KAMRAN KHAN | I23: 3710480453647 | J23: ALTO VXL AGS | K23: - | L23: R323698 | M23: 1223645 | N23: 75532/1 | O23: North | P23: 0804 | Q23: 658220 | R23: 45596 | S23: 47427 | T23: 3045000 | W23: 3045000 | X23: 2 | Y23: 60900 | AA23: paid | AB23: 1141071545 | AC23: 45622 | AD23: DISBURSED | AE23: 0 | AF23: KHI/HO/D/MO/PC COMP/C/98823/30/10/2024 | AG23: 60900 | AH23: =Y23-AG23 -> 0
A24: Fresh | B24: 75064/1 | C24: 45566 | D24: SALAAM TAKAFUL LTD | E24: KHI/HO/D/MO/PC COMP/C/98823/29/10/2024 | F24: 45590 | G24: 45590 | H24: MUHAMMAD ATIF MAQSOOD | I24: 3520230152945 | J24: TOYOTA COROLLA ALTIS (AUTOMATIC) | K24: LEB-19-1822 | L24: Q048527 | M24: 6026008 | N24: 75064/1 | O24: Central | P24: 0329 | Q24: 557830 | R24: 45596 | S24: 46696 | T24: 4200000 | W24: 4200000 | X24: 1.5 | Y24: 63000 | AA24: paid | AB24: 1141071545 | AC24: 45622 | AD24: DISBURSED | AE24: 0 | AF24: KHI/HO/D/MO/PC COMP/C/98823/29/10/2024 | AG24: 63000 | AH24: =Y24-AG24 -> 0
A25: Fresh | B25: 75560/1 | C25: 45566 | D25: SALAAM TAKAFUL LTD | E25: KHI/HO/D/MO/PC COMP/C/98823/28/10/2024 | F25: 45590 | G25: 45590 | H25: GHULAM MUJTABA | I25: 3310015879093 | J25: CITY (AUTOMATIC) | K25: LEA-17A-2349 | L25: L13Z17500856 | M25: NFBGM1640HR210005 | N25: 75560/1 | O25: Central | P25: 0423 | Q25: 15130 | R25: 45594 | S25: 46696 | T25: 3500000 | W25: 3500000 | X25: 1.5 | Y25: 52500 | AA25: paid | AB25: 1141071545 | AC25: 45622 | AD25: DISBURSED | AE25: 0 | AF25: KHI/HO/D/MO/PC COMP/C/98823/28/10/2024 | AG25: 52500 | AH25: =Y25-AG25 -> 0
A26: Fresh | B26: 75540/1 | C26: 45566 | D26: SALAAM TAKAFUL LTD | E26: KHI/HO/D/MO/PC COMP/C/98823/27/10/2024 | F26: 45590 | G26: 45590 | H26: MUHAMMAD MUZAFFAR ALI KHAN | I26: 3660151263187 | J26: CULTUS VXR (METALIC) | K26: ADU-892 | L26: 637570 | M26: 544430 | N26: 75540/1 | O26: North | P26: 0804 | Q26: 659612 | R26: 45596 | S26: 47063 | T26: 2150000 | W26: 2150000 | X26: 2 | Y26: 43000 | AA26: paid | AB26: 1141071545 | AC26: 45622 | AD26: DISBURSED | AE26: 0 | AF26: KHI/HO/D/MO/PC COMP/C/98823/27/10/2024 | AG26: 43000 | AH26: =Y26-AG26 -> 0
A27: Fresh | B27: 75189/1 | C27: 45566 | D27: SALAAM TAKAFUL LTD | E27: KHI/HO/D/MO/PC COMP/C/98823/26/10/2024 | F27: 45590 | G27: 45590 | H27: SHAHBAZ ALI | I27: 3310418487213 | J27: GRANDE AT | K27: ACF-477 | L27: Q319940 | M27: NRE172R-7018991 | N27: 75189/1 | O27: Central | P27: 0423 | Q27: 658243 | R27: 45594 | S27: 46696 | T27: 4500000 | W27: 4500000 | X27: 1.5 | Y27: 67500 | AA27: paid | AB27: 1141071545 | AC27: 45622 | AD27: DISBURSED | AE27: 0 | AF27: KHI/HO/D/MO/PC COMP/C/98823/26/10/2024 | AG27: 67500 | AH27: =Y27-AG27 -> 0
A28: Fresh | B28: 75030/1 | C28: 45566 | D28: SALAAM TAKAFUL LTD | E28: KHI/HO/D/MO/PC COMP/C/98823/25/10/2024 | F28: 45588 | G28: 45588 | H28: EJAZ MASIH | I28: 6110141122185 | J28: MEHRAN VX (NON-METALLIC) | K28: ALG-208 | L28: 756098 | M28: 1294616 | N28: 75030/1 | O28: North | P28: 0804 | Q28: 660018 | R28: 45594 | S28: 47063 | T28: 1400000 | W28: 1400000 | X28: 2 | Y28: 28000 | AA28: paid | AB28: 1141071545 | AC28: 45622 | AD28: DISBURSED | AE28: 0 | AF28: KHI/HO/D/MO/PC COMP/C/98823/25/10/2024 | AG28: 28000 | AH28: =Y28-AG28 -> 0
A29: Fresh | B29: 75522/1 | C29: 45566 | D29: SALAAM TAKAFUL LTD | E29: KHI/HO/D/MO/PC COMP/C/98823/24/10/2024 | F29: 45587 | G29: 45587 | H29: REHMAN ALI KHAN | I29: 3310242736081 | J29: SWIFT GL M/T | K29: BDW-794 | L29: K12MR1019201 | M29: NF1SZC63S00201884 | N29: 75522/1 | O29: Central | P29: 0423 | Q29: 659341 | R29: 45593 | S29: 46696 | T29: 4400000 | W29: 4400000 | X29: 1.5 | Y29: 66000 | AA29: paid | AB29: 1141071545 | AC29: 45622 | AD29: DISBURSED | AE29: 0 | AF29: KHI/HO/D/MO/PC COMP/C/98823/24/10/2024 | AG29: 66000 | AH29: =Y29-AG29 -> 0
A30: Fresh | B30: 76083/1 | C30: 45566 | D30: SALAAM TAKAFUL LTD | E30: KHI/HO/D/MO/PC COMP/C/98823/22/10/2024 | F30: 45587 | G30: 45587 | H30: ABDUL QAYOUM | I30: 3520198743205 | J30: ALTO VXR (NON-METALLIC) | K30: - | L30: 324746 | M30: 1224757 | N30: 76083/1 | O30: Central | P30: 0341 | Q30: 610578 | R30: 45597 | S30: 47427 | T30: 2707000 | W30: 2707000 | X30: 2 | Y30: 54140 | AA30: paid | AB30: 1141071545 | AC30: 45622 | AD30: DISBURSED | AE30: 0 | AF30: KHI/HO/D/MO/PC COMP/C/98823/22/10/2024 | AG30: 54140 | AH30: =Y30-AG30 -> 0
A31: Fresh | B31: 75945/1 | C31: 45566 | D31: SALAAM TAKAFUL LTD | E31: KHI/HO/D/MO/PC COMP/C/98823/21/10/2024 | F31: 45587 | G31: 45587 | H31: IZHAR ALI | I31: 3310049923115 | J31: FORTUNER | K31: APS-777 | L31: 1 GD0768522 | M31: GUN156R-1093247 | N31: 75945/1 | O31: Central | P31: 0423 | Q31: 658761 | R31: 45589 | S31: 47063 | T31: 10500000 | W31: 10500000 | X31: 1.5 | Y31: 157500 | AA31: paid | AB31: 1141071545 | AC31: 45622 | AD31: DISBURSED | AE31: 0 | AF31: KHI/HO/D/MO/PC COMP/C/98823/21/10/2024 | AG31: 157500 | AH31: =Y31-AG31 -> 0
A32: Fresh | B32: 74929/1 | C32: 45566 | D32: SALAAM TAKAFUL LTD | E32: KHI/HO/D/MO/CV/C/100145/1/10/2024 | F32: 45587 | G32: 45587 | H32: MUHAMMAD AMIR | I32: 3520109166531 | J32: RAVI | K32: - | L32: 393412 | M32: 498041 | N32: 74929/1 | O32: North | P32: 0804 | Q32: 656990 | R32: 45589 | S32: 46696 | T32: 1856000 | W32: 1856000 | X32: 2 | Y32: 37120 | AA32: paid | AB32: 1141071545 | AC32: 45622 | AD32: DISBURSED | AE32: 0 | AF32: KHI/HO/D/MO/CV/C/100145/1/10/2024 | AG32: 37120 | AH32: =Y32-AG32 -> 0
A33: Fresh | B33: 74284/1 | C33: 45566 | D33: SALAAM TAKAFUL LTD | E33: KHI/HO/D/MO/PC COMP/C/98823/20/10/2024 | F33: 45586 | G33: 45586 | H33: SAMAD KHAN | I33: 3310019683673 | J33: MEHRAN VX (METALLIC) | K33: LEC-19-7620 | L33: PKB723603 | M33: SB308PK01262094 | N33: 74284/1 | O33: Central | P33: 0423 | Q33: 654335 | R33: 45588 | S33: 46696 | T33: 1400000 | W33: 1400000 | X33: 2 | Y33: 28000 | AA33: paid | AB33: 1141071545 | AC33: 45622 | AD33: DISBURSED | AE33: 0 | AF33: KHI/HO/D/MO/PC COMP/C/98823/20/10/2024 | AG33: 28000 | AH33: =Y33-AG33 -> 0
A34: Fresh | B34: 75605/1 | C34: 45566 | D34: SALAAM TAKAFUL LTD | E34: KHI/HO/D/MO/PC COMP/C/98823/19/10/2024 | F34: 45583 | G34: 45583 | H34: MASOOD AKHTAR | I34: 3520290536175 | J34: ALTO VXR (NON-METALLIC) | K34: AMT 813 | L34: 6R265885 | M34: H1165789 | N34: 75605/1 | O34: Central | P34: 0329 | Q34: 659689 | R34: 45587 | S34: 47427 | T34: 2450000 | W34: 2450000 | X34: 2 | Y34: 49000 | AA34: paid | AB34: 1141071545 | AC34: 45622 | AD34: DISBURSED | AE34: 0 | AF34: KHI/HO/D/MO/PC COMP/C/98823/19/10/2024 | AG34: 49000 | AH34: =Y34-AG34 -> 0
A35: Fresh | B35: 75858/1 | C35: 45566 | D35: SALAAM TAKAFUL LTD | E35: KHI/HO/D/MO/PC COMP/C/98823/18/10/2024 | F35: 45583 | G35: 45583 | H35: ABRAR AHMED | I35: 4230121989345 | J35: CITY (AUTOMATIC) | K35: LEF-19-3080 | L35: 7531875 | M35: 250853 | N35: 75858/1 | O35: Central | P35: 0329 | Q35: 648575 | R35: 45588 | S35: 46696 | T35: 3600000 | W35: 3600000 | X35: 1.5 | Y35: 54000 | AA35: paid | AB35: 1141071545 | AC35: 45622 | AD35: DISBURSED | AE35: 0 | AF35: KHI/HO/D/MO/PC COMP/C/98823/18/10/2024 | AG35: 54000 | AH35: =Y35-AG35 -> 0
A36: Fresh | B36: 75454/1 | C36: 45566 | D36: SALAAM TAKAFUL LTD | E36: KHI/HO/D/MO/PC COMP/C/98823/17/10/2024 | F36: 45583 | G36: 45583 | H36: SUMBLE RIAZ | I36: 3520291735858 | J36: SUZUKI CULTUS AGS | K36: LE-19A-9305 | L36: 153457 | M36: 10053471 | N36: 75454/1 | O36: Central | P36: 0329 | Q36: 658995 | R36: 45588 | S36: 47427 | T36: 2600000 | W36: 2600000 | X36: 2 | Y36: 52000 | AA36: paid | AB36: 1141071545 | AC36: 45622 | AD36: DISBURSED | AE36: 0 | AF36: KHI/HO/D/MO/PC COMP/C/98823/17/10/2024 | AG36: 52000 | AH36: =Y36-AG36 -> 0
A37: Fresh | B37: 75067/1 | C37: 45566 | D37: SALAAM TAKAFUL LTD | E37: KHI/HO/D/MO/PC COMP/C/98823/16/10/2024 | F37: 45583 | G37: 45583 | H37: MUHAMMAD IMRAN NAWAZ | I37: 3520155712061 | J37: WAGON R VXL | K37: LEB-18A-6817 | L37: PK10B173696 | M37: A1J310PK10073695 | N37: 75067/1 | O37: Central | P37: 0329 | Q37: 393963 | R37: 45587 | S37: 47427 | T37: 2200000 | W37: 2200000 | X37: 2 | Y37: 44000 | AA37: paid | AB37: 1141071545 | AC37: 45622 | AD37: DISBURSED | AE37: 0 | AF37: KHI/HO/D/MO/PC COMP/C/98823/16/10/2024 | AG37: 44000 | AH37: =Y37-AG37 -> 0
A38: Fresh | B38: 74356/1 | C38: 45566 | D38: SALAAM TAKAFUL LTD | E38: KHI/HO/D/MO/PC COMP/C/98823/15/10/2024 | F38: 45581 | G38: 45581 | H38: SALMAN RASHEED | I38: 3410195731381 | J38: KIA SPORTAGE AWD | K38: LEA-20-8936 | L38: H301680 | M38: P300770 | N38: 74356/1 | O38: Central | P38: 0329 | Q38: 544238 | R38: 45586 | S38: 46696 | T38: 6000000 | W38: 6000000 | X38: 1.5 | Y38: 90000 | AA38: paid | AB38: 1141071545 | AC38: 45622 | AD38: DISBURSED | AE38: 0 | AF38: KHI/HO/D/MO/PC COMP/C/98823/15/10/2024 | AG38: 90000 | AH38: =Y38-AG38 -> 0
A39: Fresh | B39: 75409/1 | C39: 45566 | D39: SALAAM TAKAFUL LTD | E39: KHI/HO/D/MO/PC COMP/C/98823/14/10/2024 | F39: 45581 | G39: 45581 | H39: BILAL ASLAM | I39: 3520230627787 | J39: CITY ASPIRE PT | K39: - | L39: 1027377 | M39: RR044063 | N39: 75409/1 | O39: Central | P39: 0329 | Q39: 658874 | R39: 45587 | S39: 46696 | T39: 4719000 | W39: 4719000 | X39: 1.5 | Y39: 70785 | AA39: paid | AB39: 1141071545 | AC39: 45622 | AD39: DISBURSED | AE39: 0 | AF39: KHI/HO/D/MO/PC COMP/C/98823/14/10/2024 | AG39: 70785 | AH39: =Y39-AG39 -> 0
A40: Fresh | B40: 75459/1 | C40: 45566 | D40: SALAAM TAKAFUL LTD | E40: KHI/HO/D/MO/PC COMP/C/98823/13/10/2024 | F40: 45579 | G40: 45579 | H40: MOHSIN ALI | I40: 3410166298665 | J40: CHANGAN KARVAAN | K40: AGE-578 | L40: 500489 | M40: 1002268 | N40: 75459/1 | O40: Central | P40: 0401 | Q40: 658987 | R40: 45580 | S40: 47396 | T40: 2200000 | W40: 2200000 | X40: 2 | Y40: 44000 | AA40: paid | AB40: 1141071545 | AC40: 45622 | AD40: DISBURSED | AE40: 10 | AF40: KHI/HO/D/MO/PC COMP/C/98823/13/10/2024 | AG40: 44000 | AH40: =Y40-AG40 -> 0
...

Sheet working
A1: POLICY NO. | B1: Assorted_code | D1: Premium | E1: 28Nov240018
A2: KHI/HO/D/MO/PC COMP/C/98823/51/10/2024 | B2: =VLOOKUP(A2,policy!B:C,2,0) -> 070000169427 | C2: =VLOOKUP(A2,Fresh!AF:AG,2,0) -> 75000 | D2: =ROUND(C2,0) -> 75000 | E2: 28Nov240018 | F2: ="insert into ins_premium_det (premium_rcv_code,assorted_code, rec_amount,premium_rcv_detail_code,remaining_amt, payrec, mode_code,coinsurance_code,class_cd,it_remarks) values" -> insert into ins_premium_det (premium_rcv_code,assorted_code, rec_amount,premium_rcv_detail_code,remaining_amt, payrec, mode_code,coinsurance_code,class_cd,it_remarks) values | G2: ="('"&E2&"','"&B2&"','"&D2&"',(select max(to_number(i.premium_rcv_detail_code))+1 from ins_premium_det i),'"&D2&"','"&D2&"','02', '11000003','00','Request by Mr.Reheel Malik Fresh 02-Dec-2024');" -> ('28Nov240018','070000169427','75000',(select max(to_number(i.premium_rcv_detail_code))+1 from ins_premium_det i),'75000','75000','02', '11000003','00','Request by Mr.Reheel Malik Fresh 02-Dec-2024'); | H2: =F2&G2 -> insert into ins_premium_det (premium_rcv_code,assorted_code, rec_amount,premium_rcv_detail_code,remaining_amt, payrec, mode_code,coinsurance_code,class_cd,it_remarks) values('28Nov240018','070000169427','75000',(select max(to_number(i.premium_rcv_detail_code))+1 from ins_premium_det i),'75000','75000','02', '11000003','00','Request by Mr.Reheel Malik Fresh 02-Dec-2024');
A3: KHI/HO/D/MO/PC COMP/C/98823/50/10/2024 | B3: =VLOOKUP(A3,policy!B:C,2,0) -> 070000169426 | C3: =VLOOKUP(A3,Fresh!AF:AG,2,0) -> 54000 | D3: =ROUND(C3,0) -> 54000 | E3: 28Nov240018 | F3: ="insert into ins_premium_det (premium_rcv_code,assorted_code, rec_amount,premium_rcv_detail_code,remaining_amt, payrec, mode_code,coinsurance_code,class_cd,it_remarks) values" -> insert into ins_premium_det (premium_rcv_code,assorted_code, rec_amount,premium_rcv_detail_code,remaining_amt, payrec, mode_code,coinsurance_code,class_cd,it_remarks) values | G3: ="('"&E3&"','"&B3&"','"&D3&"',(select max(to_number(i.premium_rcv_detail_code))+1 from ins_premium_det i),'"&D3&"','"&D3&"','02', '11000003','00','Request by Mr.Reheel Malik Fresh 02-Dec-2024');" -> ('28Nov240018','070000169426','54000',(select max(to_number(i.premium_rcv_detail_code))+1 from ins_premium_det i),'54000','54000','02', '11000003','00','Request by Mr.Reheel Malik Fresh 02-Dec-2024'); | H3: =F3&G3 -> insert into ins_premium_det (premium_rcv_code,assorted_code, rec_amount,premium_rcv_detail_code,remaining_amt, payrec, mode_code,coinsurance_code,class_cd,it_remarks) values('28Nov240018','070000169426','54000',(select max(to_number(i.premium_rcv_detail_code))+1 from ins_premium_det i),'54000','54000','02', '11000003','00','Request by Mr.Reheel Malik Fresh 02-Dec-2024');
A4: KHI/HO/D/MO/PC COMP/C/98823/49/10/2024 | B4: =VLOOKUP(A4,policy!B:C,2,0) -> 070000169425 | C4: =VLOOKUP(A4,Fresh!AF:AG,2,0) -> 66000 | D4: =ROUND(C4,0) -> 66000 | E4: 28Nov240018 | F4: ="insert into ins_premium_det (premium_rcv_code,assorted_code, rec_amount,premium_rcv_detail_code,remaining_amt, payrec, mode_code,coinsurance_code,class_cd,it_remarks) values" -> insert into ins_premium_det (premium_rcv_code,assorted_code, rec_amount,premium_rcv_detail_code,remaining_amt, payrec, mode_code,coinsurance_code,class_cd,it_remarks) values | G4: ="('"&E4&"','"&B4&"','"&D4&"',(select max(to_number(i.premium_rcv_detail_code))+1 from ins_premium_det i),'"&D4&"','"&D4&"','02', '11000003','00','Request by Mr.Reheel Malik Fresh 02-Dec-2024');" -> ('28Nov240018','070000169425','66000',(select max(to_number(i.premium_rcv_detail_code))+1 from ins_premium_det i),'66000','66000','02', '11000003','00','Request by Mr.Reheel Malik Fresh 02-Dec-2024'); | H4: =F4&G4 -> insert into ins_premium_det (premium_rcv_code,assorted_code, rec_amount,premium_rcv_detail_code,remaining_amt, payrec, mode_code,coinsurance_code,class_cd,it_remarks) values('28Nov240018','070000169425','66000',(select max(to_number(i.premium_rcv_detail_code))+1 from ins_premium_det i),'66000','66000','02', '11000003','00','Request by Mr.Reheel Malik Fresh 02-Dec-2024');
A5: KHI/HO/D/MO/PC COMP/C/98823/48/10/2024 | B5: =VLOOKUP(A5,policy!B:C,2,0) -> 070000169424 | C5: =VLOOKUP(A5,Fresh!AF:AG,2,0) -> 58500 | D5: =ROUND(C5,0) -> 58500 | E5: 28Nov240018 | F5: ="insert into ins_premium_det (premium_rcv_code,assorted_code, rec_amount,premium_rcv_detail_code,remaining_amt, payrec, mode_code,coinsurance_code,class_cd,it_remarks) values" -> insert into ins_premium_det (premium_rcv_code,assorted_code, rec_amount,premium_rcv_detail_code,remaining_amt, payrec, mode_code,coinsurance_code,class_cd,it_remarks) values | G5: ="('"&E5&"','"&B5&"','"&D5&"',(select max(to_number(i.premium_rcv_detail_code))+1 from ins_premium_det i),'"&D5&"','"&D5&"','02', '11000003','00','Request by Mr.Reheel Malik Fresh 02-Dec-2024');" -> ('28Nov240018','070000169424','58500',(select max(to_number(i.premium_rcv_detail_code))+1 from ins_premium_det i),'58500','58500','02', '11000003','00','Request by Mr.Reheel Malik Fresh 02-Dec-2024'); | H5: =F5&G5 -> insert into ins_premium_det (premium_rcv_code,assorted_code, rec_amount,premium_rcv_detail_code,remaining_amt, payrec, mode_code,coinsurance_code,class_cd,it_remarks) values('28Nov240018','070000169424','58500',(select max(to_number(i.premium_rcv_detail_code))+1 from ins_premium_det i),'58500','58500','02', '11000003','00','Request by Mr.Reheel Malik Fresh 02-Dec-2024');
A6: KHI/HO/D/MO/PC COMP/C/98823/47/10/2024 | B6: =VLOOKUP(A6,policy!B:C,2,0) -> 070000169423 | C6: =VLOOKUP(A6,Fresh!AF:AG,2,0) -> 56985 | D6: =ROUND(C6,0) -> 56985 | E6: 28Nov240018 | F6: ="insert into ins_premium_det (premium_rcv_code,assorted_code, rec_amount,premium_rcv_detail_code,remaining_amt, payrec, mode_code,coinsurance_code,class_cd,it_remarks) values" -> insert into ins_premium_det (premium_rcv_code,assorted_code, rec_amount,premium_rcv_detail_code,remaining_amt, payrec, mode_code,coinsurance_code,class_cd,it_remarks) values | G6: ="('"&E6&"','"&B6&"','"&D6&"',(select max(to_number(i.premium_rcv_detail_code))+1 from ins_premium_det i),'"&D6&"','"&D6&"','02', '11000003','00','Request by Mr.Reheel Malik Fresh 02-Dec-2024');" -> ('28Nov240018','070000169423','56985',(select max(to_number(i.premium_rcv_detail_code))+1 from ins_premium_det i),'56985','56985','02', '11000003','00','Request by Mr.Reheel Malik Fresh 02-Dec-2024'); | H6: =F6&G6 -> insert into ins_premium_det (premium_rcv_code,assorted_code, rec_amount,premium_rcv_detail_code,remaining_amt, payrec, mode_code,coinsurance_code,class_cd,it_remarks) values('28Nov240018','070000169423','56985',(select max(to_number(i.premium_rcv_detail_code))+1 from ins_premium_det i),'56985','56985','02', '11000003','00','Request by Mr.Reheel Malik Fresh 02-Dec-2024');
A7: KHI/HO/D/MO/PC COMP/C/98823/46/10/2024 | B7: =VLOOKUP(A7,policy!B:C,2,0) -> 070000169419 | C7: =VLOOKUP(A7,Fresh!AF:AG,2,0) -> 20600 | D7: =ROUND(C7,0) -> 20600 | E7: 28Nov240018 | F7: ="insert into ins_premium_det (premium_rcv_code,assorted_code, rec_amount,premium_rcv_detail_code,remaining_amt, payrec, mode_code,coinsurance_code,class_cd,it_remarks) values" -> insert into ins_premium_det (premium_rcv_code,assorted_code, rec_amount,premium_rcv_detail_code,remaining_amt, payrec, mode_code,coinsurance_code,class_cd,it_remarks) values | G7: ="('"&E7&"','"&B7&"','"&D7&"',(select max(to_number(i.premium_rcv_detail_code))+1 from ins_premium_det i),'"&D7&"','"&D7&"','02', '11000003','00','Request by Mr.Reheel Malik Fresh 02-Dec-2024');" -> ('28Nov240018','070000169419','20600',(select max(to_number(i.premium_rcv_detail_code))+1 from ins_premium_det i),'20600','20600','02', '11000003','00','Request by Mr.Reheel Malik Fresh 02-Dec-2024'); | H7: =F7&G7 -> insert into ins_premium_det (premium_rcv_code,assorted_code, rec_amount,premium_rcv_detail_code,remaining_amt, payrec, mode_code,coinsurance_code,class_cd,it_remarks) values('28Nov240018','070000169419','20600',(select max(to_number(i.premium_rcv_detail_code))+1 from ins_premium_det i),'20600','20600','02', '11000003','00','Request by Mr.Reheel Malik Fresh 02-Dec-2024');
A8: KHI/HO/D/MO/PC COMP/C/98823/45/10/2024 | B8: =VLOOKUP(A8,policy!B:C,2,0) -> 070000169410 | C8: =VLOOKUP(A8,Fresh!AF:AG,2,0) -> 60000 | D8: =ROUND(C8,0) -> 60000 | E8: 28Nov240018 | F8: ="insert into ins_premium_det (premium_rcv_code,assorted_code, rec_amount,premium_rcv_detail_code,remaining_amt, payrec, mode_code,coinsurance_code,class_cd,it_remarks) values" -> insert into ins_premium_det (premium_rcv_code,assorted_code, rec_amount,premium_rcv_detail_code,remaining_amt, payrec, mode_code,coinsurance_code,class_cd,it_remarks) values | G8: ="('"&E8&"','"&B8&"','"&D8&"',(select max(to_number(i.premium_rcv_detail_code))+1 from ins_premium_det i),'"&D8&"','"&D8&"','02', '11000003','00','Request by Mr.Reheel Malik Fresh 02-Dec-2024');" -> ('28Nov240018','070000169410','60000',(select max(to_number(i.premium_rcv_detail_code))+1 from ins_premium_det i),'60000','60000','02', '11000003','00','Request by Mr.Reheel Malik Fresh 02-Dec-2024'); | H8: =F8&G8 -> insert into ins_premium_det (premium_rcv_code,assorted_code, rec_amount,premium_rcv_detail_code,remaining_amt, payrec, mode_code,coinsurance_code,class_cd,it_remarks) values('28Nov240018','070000169410','60000',(select max(to_number(i.premium_rcv_detail_code))+1 from ins_premium_det i),'60000','60000','02', '11000003','00','Request by Mr.Reheel Malik Fresh 02-Dec-2024');
A9: KHI/HO/D/MO/PC COMP/C/98823/44/10/2024 | B9: =VLOOKUP(A9,policy!B:C,2,0) -> 070000169395 | C9: =VLOOKUP(A9,Fresh!AF:AG,2,0) -> 43000 | D9: =ROUND(C9,0) -> 43000 | E9: 28Nov240018 | F9: ="insert into ins_premium_det (premium_rcv_code,assorted_code, rec_amount,premium_rcv_detail_code,remaining_amt, payrec, mode_code,coinsurance_code,class_cd,it_remarks) values" -> insert into ins_premium_det (premium_rcv_code,assorted_code, rec_amount,premium_rcv_detail_code,remaining_amt, payrec, mode_code,coinsurance_code,class_cd,it_remarks) values | G9: ="('"&E9&"','"&B9&"','"&D9&"',(select max(to_number(i.premium_rcv_detail_code))+1 from ins_premium_det i),'"&D9&"','"&D9&"','02', '11000003','00','Request by Mr.Reheel Malik Fresh 02-Dec-2024');" -> ('28Nov240018','070000169395','43000',(select max(to_number(i.premium_rcv_detail_code))+1 from ins_premium_det i),'43000','43000','02', '11000003','00','Request by Mr.Reheel Malik Fresh 02-Dec-2024'); | H9: =F9&G9 -> insert into ins_premium_det (premium_rcv_code,assorted_code, rec_amount,premium_rcv_detail_code,remaining_amt, payrec, mode_code,coinsurance_code,class_cd,it_remarks) values('28Nov240018','070000169395','43000',(select max(to_number(i.premium_rcv_detail_code))+1 from ins_premium_det i),'43000','43000','02', '11000003','00','Request by Mr.Reheel Malik Fresh 02-Dec-2024');
A10: KHI/HO/D/MO/PC COMP/C/98823/43/10/2024 | B10: =VLOOKUP(A10,policy!B:C,2,0) -> 070000169385 | C10: =VLOOKUP(A10,Fresh!AF:AG,2,0) -> 57000 | D10: =ROUND(C10,0) -> 57000 | E10: 28Nov240018 | F10: ="insert into ins_premium_det (premium_rcv_code,assorted_code, rec_amount,premium_rcv_detail_code,remaining_amt, payrec, mode_code,coinsurance_code,class_cd,it_remarks) values" -> insert into ins_premium_det (premium_rcv_code,assorted_code, rec_amount,premium_rcv_detail_code,remaining_amt, payrec, mode_code,coinsurance_code,class_cd,it_remarks) values | G10: ="('"&E10&"','"&B10&"','"&D10&"',(select max(to_number(i.premium_rcv_detail_code))+1 from ins_premium_det i),'"&D10&"','"&D10&"','02', '11000003','00','Request by Mr.Reheel Malik Fresh 02-Dec-2024');" -> ('28Nov240018','070000169385','57000',(select max(to_number(i.premium_rcv_detail_code))+1 from ins_premium_det i),'57000','57000','02', '11000003','00','Request by Mr.Reheel Malik Fresh 02-Dec-2024'); | H10: =F10&G10 -> insert into ins_premium_det (premium_rcv_code,assorted_code, rec_amount,premium_rcv_detail_code,remaining_amt, payrec, mode_code,coinsurance_code,class_cd,it_remarks) values('28Nov240018','070000169385','57000',(select max(to_number(i.premium_rcv_detail_code))+1 from ins_premium_det i),'57000','57000','02', '11000003','00','Request by Mr.Reheel Malik Fresh 02-Dec-2024');
A11: KHI/HO/D/MO/PC COMP/C/98823/42/10/2024 | B11: =VLOOKUP(A11,policy!B:C,2,0) -> 070000169382 | C11: =VLOOKUP(A11,Fresh!AF:AG,2,0) -> 72750 | D11: =ROUND(C11,0) -> 72750 | E11: 28Nov240018 | F11: ="insert into ins_premium_det (premium_rcv_code,assorted_code, rec_amount,premium_rcv_detail_code,remaining_amt, payrec, mode_code,coinsurance_code,class_cd,it_remarks) values" -> insert into ins_premium_det (premium_rcv_code,assorted_code, rec_amount,premium_rcv_detail_code,remaining_amt, payrec, mode_code,coinsurance_code,class_cd,it_remarks) values | G11: ="('"&E11&"','"&B11&"','"&D11&"',(select max(to_number(i.premium_rcv_detail_code))+1 from ins_premium_det i),'"&D11&"','"&D11&"','02', '11000003','00','Request by Mr.Reheel Malik Fresh 02-Dec-2024');" -> ('28Nov240018','070000169382','72750',(select max(to_number(i.premium_rcv_detail_code))+1 from ins_premium_det i),'72750','72750','02', '11000003','00','Request by Mr.Reheel Malik Fresh 02-Dec-2024'); | H11: =F11&G11 -> insert into ins_premium_det (premium_rcv_code,assorted_code, rec_amount,premium_rcv_detail_code,remaining_amt, payrec, mode_code,coinsurance_code,class_cd,it_remarks) values('28Nov240018','070000169382','72750',(select max(to_number(i.premium_rcv_detail_code))+1 from ins_premium_det i),'72750','72750','02', '11000003','00','Request by Mr.Reheel Malik Fresh 02-Dec-2024');
A12: KHI/HO/D/MO/PC COMP/C/98823/41/10/2024 | B12: =VLOOKUP(A12,policy!B:C,2,0) -> 070000169381 | C12: =VLOOKUP(A12,Fresh!AF:AG,2,0) -> 54140 | D12: =ROUND(C12,0) -> 54140 | E12: 28Nov240018 | F12: ="insert into ins_premium_det (premium_rcv_code,assorted_code, rec_amount,premium_rcv_detail_code,remaining_amt, payrec, mode_code,coinsurance_code,class_cd,it_remarks) values" -> insert into ins_premium_det (premium_rcv_code,assorted_code, rec_amount,premium_rcv_detail_code,remaining_amt, payrec, mode_code,coinsurance_code,class_cd,it_remarks) values | G12: ="('"&E12&"','"&B12&"','"&D12&"',(select max(to_number(i.premium_rcv_detail_code))+1 from ins_premium_det i),'"&D12&"','"&D12&"','02', '11000003','00','Request by Mr.Reheel Malik Fresh 02-Dec-2024');" -> ('28Nov240018','070000169381','54140',(select max(to_number(i.premium_rcv_detail_code))+1 from ins_premium_det i),'54140','54140','02', '11000003','00','Request by Mr.Reheel Malik Fresh 02-Dec-2024'); | H12: =F12&G12 -> insert into ins_premium_det (premium_rcv_code,assorted_code, rec_amount,premium_rcv_detail_code,remaining_amt, payrec, mode_code,coinsurance_code,class_cd,it_remarks) values('28Nov240018','070000169381','54140',(select max(to_number(i.premium_rcv_detail_code))+1 from ins_premium_det i),'54140','54140','02', '11000003','00','Request by Mr.Reheel Malik Fresh 02-Dec-2024');
A13: KHI/HO/D/MO/PC COMP/C/98823/40/10/2024 | B13: =VLOOKUP(A13,policy!B:C,2,0) -> 070000169379 | C13: =VLOOKUP(A13,Fresh!AF:AG,2,0) -> 42400 | D13: =ROUND(C13,0) -> 42400 | E13: 28Nov240018 | F13: ="insert into ins_premium_det (premium_rcv_code,assorted_code, rec_amount,premium_rcv_detail_code,remaining_amt, payrec, mode_code,coinsurance_code,class_cd,it_remarks) values" -> insert into ins_premium_det (premium_rcv_code,assorted_code, rec_amount,premium_rcv_detail_code,remaining_amt, payrec, mode_code,coinsurance_code,class_cd,it_remarks) values | G13: ="('"&E13&"','"&B13&"','"&D13&"',(select max(to_number(i.premium_rcv_detail_code))+1 from ins_premium_det i),'"&D13&"','"&D13&"','02', '11000003','00','Request by Mr.Reheel Malik Fresh 02-Dec-2024');" -> ('28Nov240018','070000169379','42400',(select max(to_number(i.premium_rcv_detail_code))+1 from ins_premium_det i),'42400','42400','02', '11000003','00','Request by Mr.Reheel Malik Fresh 02-Dec-2024'); | H13: =F13&G13 -> insert into ins_premium_det (premium_rcv_code,assorted_code, rec_amount,premium_rcv_detail_code,remaining_amt, payrec, mode_code,coinsurance_code,class_cd,it_remarks) values('28Nov240018','070000169379','42400',(select max(to_number(i.premium_rcv_detail_code))+1 from ins_premium_det i),'42400','42400','02', '11000003','00','Request by Mr.Reheel Malik Fresh 02-Dec-2024');
... A53: KHI/HO/D/MO/PC COMP/C/100245/1/10/2024 | B53: =VLOOKUP(A53,policy!B:C,2,0) -> 070000167949 | C53: =VLOOKUP(A53,Fresh!AF:AG,2,0) -> 51000 | D53: =ROUND(C53,0) -> 51000 | E53: 28Nov240018 | F53: ="insert into ins_premium_det (premium_rcv_code,assorted_code, rec_amount,premium_rcv_detail_code,remaining_amt, payrec, mode_code,coinsurance_code,class_cd,it_remarks) values" -> insert into ins_premium_det (premium_rcv_code,assorted_code, rec_amount,premium_rcv_detail_code,remaining_amt, payrec, mode_code,coinsurance_code,class_cd,it_remarks) values | G53: ="('"&E53&"','"&B53&"','"&D53&"',(select max(to_number(i.premium_rcv_detail_code))+1 from ins_premium_det i),'"&D53&"','"&D53&"','02', '11000003','00','Request by Mr.Reheel Malik Fresh 02-Dec-2024');" -> ('28Nov240018','070000167949','51000',(select max(to_number(i.premium_rcv_detail_code))+1 from ins_premium_det i),'51000','51000','02', '11000003','00','Request by Mr.Reheel Malik Fresh 02-Dec-2024'); | H53: =F53&G53 -> insert into ins_premium_det (premium_rcv_code,assorted_code, rec_amount,premium_rcv_detail_code,remaining_amt, payrec, mode_code,coinsurance_code,class_cd,it_remarks) values('28Nov240018','070000167949','51000',(select max(to_number(i.premium_rcv_detail_code))+1 from ins_premium_det i),'51000','51000','02', '11000003','00','Request by Mr.Reheel Malik Fresh 02-Dec-2024');
C54: =SUM(C2:C53) -> 3231350 | D54: =SUM(D2:D53) -> 3231350

Sheet Sheet2
A2: KHI/HO/D/MO/PC COMP/C/98823/51/10/2024 | B2: -10-2024 | H2: 98823 | I2: 00051 | J2: ="ia.assorted_string like '%"&H2&"-"&I2&B2&"%' or" -> ia.assorted_string like '%98823-00051-10-2024%' or
A3: KHI/HO/D/MO/PC COMP/C/98823/50/10/2024 | B3: -10-2024 | H3: 98823 | I3: 00050 | J3: ="ia.assorted_string like '%"&H3&"-"&I3&B3&"%' or" -> ia.assorted_string like '%98823-00050-10-2024%' or
A4: KHI/HO/D/MO/PC COMP/C/98823/49/10/2024 | B4: -10-2024 | H4: 98823 | I4: 00049 | J4: ="ia.assorted_string like '%"&H4&"-"&I4&B4&"%' or" -> ia.assorted_string like '%98823-00049-10-2024%' or
A5: KHI/HO/D/MO/PC COMP/C/98823/48/10/2024 | B5: -10-2024 | H5: 98823 | I5: 00048 | J5: ="ia.assorted_string like '%"&H5&"-"&I5&B5&"%' or" -> ia.assorted_string like '%98823-00048-10-2024%' or
A6: KHI/HO/D/MO/PC COMP/C/98823/47/10/2024 | B6: -10-2024 | H6: 98823 | I6: 00047 | J6: ="ia.assorted_string like '%"&H6&"-"&I6&B6&"%' or" -> ia.assorted_string like '%98823-00047-10-2024%' or
A7: KHI/HO/D/MO/PC COMP/C/98823/46/10/2024 | B7: -10-2024 | H7: 98823 | I7: 00046 | J7: ="ia.assorted_string like '%"&H7&"-"&I7&B7&"%' or" -> ia.assorted_string like '%98823-00046-10-2024%' or
A8: KHI/HO/D/MO/PC COMP/C/98823/45/10/2024 | B8: -10-2024 | H8: 98823 | I8: 00045 | J8: ="ia.assorted_string like '%"&H8&"-"&I8&B8&"%' or" -> ia.assorted_string like '%98823-00045-10-2024%' or
A9: KHI/HO/D/MO/PC COMP/C/98823/44/10/2024 | B9: -10-2024 | H9: 98823 | I9: 00044 | J9: ="ia.assorted_string like '%"&H9&"-"&I9&B9&"%' or" -> ia.assorted_string like '%98823-00044-10-2024%' or
A10: KHI/HO/D/MO/PC COMP/C/98823/43/10/2024 | B10: -10-2024 | H10: 98823 | I10: 00043 | J10: ="ia.assorted_string like '%"&H10&"-"&I10&B10&"%' or" -> ia.assorted_string like '%98823-00043-10-2024%' or
A11: KHI/HO/D/MO/PC COMP/C/98823/42/10/2024 | B11: -10-2024 | H11: 98823 | I11: 00042 | J11: ="ia.assorted_string like '%"&H11&"-"&I11&B11&"%' or" -> ia.assorted_string like '%98823-00042-10-2024%' or
A12: KHI/HO/D/MO/PC COMP/C/98823/41/10/2024 | B12: -10-2024 | H12: 98823 | I12: 00041 | J12: ="ia.assorted_string like '%"&H12&"-"&I12&B12&"%' or" -> ia.assorted_string like '%98823-00041-10-2024%' or
A13: KHI/HO/D/MO/PC COMP/C/98823/40/10/2024 | B13: -10-2024 | H13: 98823 | I13: 00040 | J13: ="ia.assorted_string like '%"&H13&"-"&I13&B13&"%' or" -> ia.assorted_string like '%98823-00040-10-2024%' or
... A53: KHI/HO/D/MO/PC COMP/C/100245/1/10/2024 | B53: -10-2024 | H53: 100245 | I53: 00001 | J53: ="ia.assorted_string like '%"&H53&"-"&I53&B53&"%' or" -> ia.assorted_string like '%100245-00001-10-2024%' or

Sheet policy
B1: FUNC_ASSORTED_STRING(IA.ASSORTED_CODE) | C1: ASSORTED_CODE
A2: 1 | B2: KHI/HO/D/MO/PC COMP/C/98823/8/10/2024 | C2: 070000167273
A3: 2 | B3: KHI/HO/D/MO/PC COMP/C/98823/18/10/2024 | C3: 070000167626
A4: 3 | B4: KHI/HO/D/MO/PC COMP/C/98823/19/10/2024 | C4: 070000167628
A5: 4 | B5: KHI/HO/D/MO/PC COMP/C/98823/3/10/2024 | C5: 070000166962
A6: 5 | B6: KHI/HO/D/MO/PC COMP/C/98823/15/10/2024 | C6: 070000167548
A7: 6 | B7: KHI/HO/D/MO/PC COMP/C/98823/16/10/2024 | C7: 070000167614
A8: 7 | B8: KHI/HO/D/MO/PC COMP/C/98823/41/10/2024 | C8: 070000169381
A9: 8 | B9: KHI/HO/D/MO/PC COMP/C/98823/35/10/2024 | C9: 070000169368
A10: 9 | B10: KHI/HO/D/MO/PC COMP/C/98823/36/10/2024 | C10: 070000169374
A11: 10 | B11: KHI/HO/D/MO/PC COMP/C/98823/37/10/2024 | C11: 070000169375
A12: 11 | B12: KHI/HO/D/MO/PC COMP/C/98823/38/10/2024 | C12: 070000169377
A13: 12 | B13: KHI/HO/D/MO/PC COMP/C/98823/31/10/2024 | C13: 070000169290
... A53: 52 | B53: KHI/HO/D/MO/PC COMP/C/98823/1/10/2024 | C53: 070000166939

Sheet Renewal
A1: Fresh / Renewal | B1: Proposal No. | C1: Billing Month | D1: Takaful Company | E1: PMD / Cert | F1: Takaful Start Date | G1: Takaful End Date | H1: Customer Name | I1: CNIC | J1: Vehicle Make | K1: Reg. No | L1: Engine No | M1: Chassis No | N1: Proposal No. | O1: Region | P1: Unit ID | Q1: BR # | R1: Financing Date | S1: Maturity Date | T1: Asset Value | U1: Dep. % | V1: Dep. Amount | W1: Sum Cover Amount | X1: Takaful Rate | Y1: Premium Amount | Z1: For Takaful Company Rectifications | AA1: For COD Status | AB1: PO No. | AC1: PO Dates | AD1: Proposal Status | AE1: Default Case (Overdue Days) | AF1: Policy # 2024 | AG1: Tms Prem | AH1: Difference
A2: Renewal | B2: 66295/1 | C2: 45566 | D2: SALAAM TAKAFUL LTD | E2: KHI/HO/D/MO/PC COMP/C/100245/58/10/2024 | F2: 45567 | G2: 45931 | H2: SHAHBAZ QADEER | I2: 3520296702827 | J2: SUZUKI BOLAN VX EURO II | K2: LET-16-2248 | L2: PKT932090 | M2: PK01048577 | N2: 66295/1 | O2: Central | P2: 0329 | Q2: 622993 | R2: 45203 | S2: 46300 | T2: 990000 | U2: 10 | V2: 99000 | W2: 891000 | X2: 2 | Y2: 17820 | AA2: paid | AB2: 1141071585 | AC2: 45624 | AD2: DISBURSED | AE2: 0 | AF2: KHI/HO/D/MO/PC COMP/C/100245/58/10/2024 | AG2: 17820 | AH2: =Y2-AG2 -> 0
A3: Renewal | B3: 54142/1 | C3: 45566 | D3: SALAAM TAKAFUL LTD | E3: KHI/HO/D/MO/PC COMP/C/100245/145/10/2024 | F3: 45568 | G3: 45932 | H3: ZEESHAN ALI | I3: 3330313904909 | J3: TOYOTA COROLLA ALTIS VVT- | K3: NA-295 | L3: Q100687 | M3: 6078161 | N3: 54142/1 | O3: Central | P3: 0454 | Q3: 492664 | R3: 44841 | S3: 46665 | T3: 4000920 | U3: 15 | V3: 600138 | W3: 3400782 | X3: 1.5 | Y3: 51011.73 | AA3: paid | AB3: 1141071585 | AC3: 45624 | AD3: DISBURSED | AE3: 10 | AF3: KHI/HO/D/MO/PC COMP/C/100245/145/10/2024 | AG3: 51012 | AH3: =Y3-AG3 -> -0.27
A4: Renewal | B4: 67392/1 | C4: 45566 | D4: SALAAM TAKAFUL LTD | E4: KHI/HO/D/MO/PC COMP/C/100245/64/10/2024 | F4: 45568 | G4: 45932 | H4: MEHWISH FAREED | I4: 3460391725170 | J4: SUZUKI ALTO AGS A/T | K4: AKN-394 | L4: 6R225831 | M4: 6H1125988 | N4: 67392/1 | O4: Central | P4: 0329 | Q4: 582757 | R4: 45209 | S4: 47031 | T4: 2800000 | U4: 10 | V4: 280000 | W4: 2520000 | X4: 2 | Y4: 50400 | AA4: paid | AB4: 1141071585 | AC4: 45624 | AD4: DISBURSED | AE4: 10 | AF4: KHI/HO/D/MO/PC COMP/C/100245/64/10/2024 | AG4: 50400 | AH4: =Y4-AG4 -> 0
A5: Renewal | B5: 51399/1 | C5: 45566 | D5: SALAAM TAKAFUL LTD | E5: KHI/HO/D/MO/PC COMP/C/100245/29/10/2024 | F5: 45569 | G5: 45933 | H5: MANSOOR ELAHI | I5: 3520251957221 | J5: TOYOTA COROLLA GLI M/T 1. | K5: LEA-17A-9517 | L5: Z505322 | M5: 4131361 | N5: 51399/1 | O5: Central | P5: 0329 | Q5: 545670 | R5: 44476 | S5: 46300 | T5: 2900000 | U5: 20 | V5: 580000 | W5: 2320000 | X5: 2.5 | Y5: 58000 | AA5: paid | AB5: 1141071585 | AC5: 45624 | AD5: DISBURSED | AE5: 0 | AF5: KHI/HO/D/MO/PC COMP/C/100245/29/10/2024 | AG5: 58000 | AH5: =Y5-AG5 -> 0
A6: Renewal | B6: 60332/3 | C6: 45566 | D6: SALAAM TAKAFUL LTD | E6: KHI/HO/D/MO/PC COMP/C/100245/152/10/2024 | F6: 45570 | G6: 45934 | H6: RAO AZHAR HUSSAIN | I6: 4220103914415 | J6: SUZUKI ALTO | K6: BVB-980 | L6: R-173845 | M6: 1073867 | N6: 60332/3 | O6: South | P6: 0136 | Q6: 566743 | R6: 44845 | S6: 46665 | T6: 1699000 | U6: 15 | V6: 254850 | W6: 1444150 | X6: 1.5 | Y6: 21662.25 | AA6: paid | AB6: 1141071585 | AC6: 45624 | AD6: DISBURSED | AE6: 0 | AF6: KHI/HO/D/MO/PC COMP/C/100245/152/10/2024 | AG6: 21662 | AH6: =Y6-AG6 -> 0.25
A7: Renewal | B7: 58841/3 | C7: 45566 | D7: SALAAM TAKAFUL LTD | E7: KHI/HO/D/MO/PC COMP/C/100245/149/10/2024 | F7: 45570 | G7: 45934 | H7: MUHAMMAD ALI | I7: 4230101503407 | J7: CHANGAN KARVAAN PLUS | K7: SA-0960 | L7: 503797 | M7: 1016773 | N7: 58841/3 | O7: South | P7: 0144 | Q7: 334871 | R7: 44851 | S7: 46696 | T7: 2569000 | U7: 15 | V7: 385350 | W7: 2183650 | X7: 1.5 | Y7: 32754.75 | AA7: paid | AB7: 1141071585 | AC7: 45624 | AD7: DISBURSED | AE7: 0 | AF7: KHI/HO/D/MO/PC COMP/C/100245/149/10/2024 | AG7: 32755 | AH7: =Y7-AG7 -> -0.25
A8: Renewal | B8: 56084/1 | C8: 45566 | D8: SALAAM TAKAFUL LTD | E8: KHI/HO/D/MO/PC COMP/C/100245/130/10/2024 | F8: 45570 | G8: 45934 | H8: MARYAM FAHEEM | I8: 3740682376118 | J8: TOYOTA YARIS ATIV X CVT | K8: AMG-993 | L8: 2A57141 | M8: 7036144 | N8: 56084/1 | O8: Central | P8: 0329 | Q8: 257363 | R8: 44848 | S8: 46665 | T8: 3331290 | U8: 15 | V8: 499693.5 | W8: 2831596.5 | X8: 1.5 | Y8: 42473.948 | AA8: paid | AB8: 1141071585 | AC8: 45624 | AD8: DISBURSED | AE8: 0 | AF8: KHI/HO/D/MO/PC COMP/C/100245/130/10/2024 | AG8: 42474 | AH8: =Y8-AG8 -> -0.0525
A9: Renewal | B9: 44005/1 | C9: 45566 | D9: SALAAM TAKAFUL LTD | E9: KHI/HO/D/MO/PC COMP/C/100245/55/10/2024 | F9: 45570 | G9: 45934 | H9: MUHAMMAD RIAZ | I9: 3310421179559 | J9: SUZUKI HUSTLER | K9: LEF-18-9188 | L9: R06AF623590 | M9: MR31S257835 | N9: 44005/1 | O9: Central | P9: 0556 | Q9: 225506 | R9: 44120 | S9: 45966 | T9: 1600000 | U9: 25 | V9: 400000 | W9: 1200000 | X9: 2.5 | Y9: 30000 | AA9: paid | AB9: 1141071585 | AC9: 45624 | AD9: DISBURSED | AE9: 0 | AF9: KHI/HO/D/MO/PC COMP/C/100245/55/10/2024 | AG9: 30000 | AH9: =Y9-AG9 -> 0
A10: Renewal | B10: 43873/1 | C10: 45566 | D10: SALAAM TAKAFUL LTD | E10: KHI/HO/D/MO/PC COMP/C/100245/53/10/2024 | F10: 45570 | G10: 45934 | H10: MUHAMMAD DANISH | I10: 3740575939467 | J10: SUZUKI WAGON-R VXL E2 | K10: ART-569 | L10: 206357 | M10: 10106359 | N10: 43873/1 | O10: North | P10: 0804 | Q10: 503851 | R10: 44112 | S10: 45936 | T10: 1695000 | U10: 25 | V10: 423750 | W10: 1271250 | X10: 2.5 | Y10: 31781.25 | AA10: paid | AB10: 1141071585 | AC10: 45624 | AD10: DISBURSED | AE10: 0 | AF10: KHI/HO/D/MO/PC COMP/C/100245/53/10/2024 | AG10: 31781 | AH10: =Y10-AG10 -> 0.25
A11: Renewal | B11: 43867/1 | C11: 45566 | D11: SALAAM TAKAFUL LTD | E11: KHI/HO/D/MO/PC COMP/C/100245/44/10/2024 | F11: 45570 | G11: 45934 | H11: MEHMOOD RAZA | I11: 3640119159919 | J11: SUZUKI ALTO VXL AGS E-2 | K11: AAR-518 | L11: 130521 | M11: 1030881 | N11: 43867/1 | O11: Central | P11: 0555 | Q11: 503036 | R11: 44111 | S11: 45936 | T11: 1598000 | U11: 25 | V11: 399500 | W11: 1198500 | X11: 2.5 | Y11: 29962.5 | AA11: paid | AB11: 1141071585 | AC11: 45624 | AD11: DISBURSED | AE11: 10 | AF11: KHI/HO/D/MO/PC COMP/C/100245/44/10/2024 | AG11: 29963 | AH11: =Y11-AG11 -> -0.5
A12: Renewal | B12: 56146/1 | C12: 45566 | D12: SALAAM TAKAFUL LTD | E12: KHI/HO/D/MO/PC COMP/C/100245/20/10/2024 | F12: 45570 | G12: 45934 | H12: MALIK MUHAMMAD ABID SARWAR | I12: 3520290433639 | J12: SUZUKI ALTO | K12: ALZ-845 | L12: R250930 | M12: H1150937 | N12: 56146/1 | O12: Central | P12: 0329 | Q12: 568203 | R12: 44841 | S12: 46665 | T12: 1675000 | U12: 15 | V12: 251250 | W12: 1423750 | X12: 2.5 | Y12: 35593.75 | AA12: paid | AB12: 1141071585 | AC12: 45624 | AD12: DISBURSED | AE12: 10 | AF12: KHI/HO/D/MO/PC COMP/C/100245/20/10/2024 | AG12: 35594 | AH12: =Y12-AG12 -> -0.25
A13: Renewal | B13: 53963/1 | C13: 45566 | D13: SALAAM TAKAFUL LTD | E13: KHI/HO/D/MO/PC COMP/C/100245/155/10/2024 | F13: 45571 | G13: 45935 | H13: SHAFIQ UR REHMAN | I13: 3520146667101 | J13: TOYOTA COROLLA ALTIS | K13: ALY-767 | L13: Q100675 | M13: 6078158 | N13: 53963/1 | O13: Central | P13: 0329 | Q13: 421089 | R13: 44844 | S13: 46300 | T13: 3639340 | U13: 15 | V13: 545901 | W13: 3093439 | X13: 1.5 | Y13: 46401.585 | AA13: paid | AB13: 1141071585 | AC13: 45624 | AD13: DISBURSED | AE13: 10 | AF13: KHI/HO/D/MO/PC COMP/C/100245/155/10/2024 | AG13: 46402 | AH13: =Y13-AG13 -> -0.415
A14: Renewal | B14: 53438/1 | C14: 45566 | D14: SALAAM TAKAFUL LTD | E14: KHI/HO/D/MO/PC COMP/C/100245/131/10/2024 | F14: 45571 | G14: 45935 | H14: SHAZIA SHEIKH | I14: 3740540534006 | J14: TOYOTA COROLLA ALTIS A/T | K14: BAS-44 | L14: 100619 | M14: 6078124 | N14: 53438/1 | O14: North | P14: 0804 | Q14: 555744 | R14: 44844 | S14: 46665 | T14: 4215005 | U14: 15 | V14: 632250.75 | W14: 3582754.2 | X14: 1.5 | Y14: 53741.314 | AA14: paid | AB14: 1141071585 | AC14: 45624 | AD14: DISBURSED | AE14: 10 | AF14: KHI/HO/D/MO/PC COMP/C/100245/131/10/2024 | AG14: 53741 | AH14: =Y14-AG14 -> 0.31375
A15: Renewal | B15: 60376/1 | C15: 45566 | D15: SALAAM TAKAFUL LTD | E15: KHI/HO/D/MO/PC COMP/C/100245/110/10/2024 | F15: 45571 | G15: 45935 | H15: SHABBIR ALI | I15: 3530290311197 | J15: SUZUKI WAGON-R VXL E2 | K15: LEC-18-2015 | L15: B152238 | M15: K10052199 | N15: 60376/1 | O15: Central | P15: 0329 | Q15: 587906 | R15: 44844 | S15: 46665 | T15: 1750000 | U15: 15 | V15: 262500 | W15: 1487500 | X15: 2 | Y15: 29750 | AA15: paid | AB15: 1141071585 | AC15: 45624 | AD15: DISBURSED | AE15: 10 | AF15: KHI/HO/D/MO/PC COMP/C/100245/110/10/2024 | AG15: 29750 | AH15: =Y15-AG15 -> 0
A16: Renewal | B16: 55589/1 | C16: 45566 | D16: SALAAM TAKAFUL LTD | E16: KHI/HO/D/MO/PC COMP/C/100245/25/10/2024 | F16: 45571 | G16: 45935 | H16: KASHIF SARWAR | I16: 3520296205209 | J16: SUZUKI ALTO VX | K16: ALZ-871 | L16: 6R250670 | M16: 1150672 | N16: 55589/1 | O16: Central | P16: 0329 | Q16: 566286 | R16: 44841 | S16: 45936 | T16: 1306000 | U16: 15 | V16: 195900 | W16: 1110100 | X16: 2.5 | Y16: 27752.5 | AA16: paid | AB16: 1141071585 | AC16: 45624 | AD16: DISBURSED | AE16: 0 | AF16: KHI/HO/D/MO/PC COMP/C/100245/25/10/2024 | AG16: 27753 | AH16: =Y16-AG16 -> -0.5
A17: Renewal | B17: 60342/1 | C17: 45566 | D17: SALAAM TAKAFUL LTD | E17: KHI/HO/D/MO/PC COMP/C/100245/165/10/2024 | F17: 45572 | G17: 45936 | H17: SULEMAN AHMED | I17: 3740581806851 | J17: SUZUKI ALTO VXR E-2 | K17: APG-782 | L17: 111397 | M17: 1011332 | N17: 60342/1 | O17: North | P17: 0804 | Q17: 579263 | R17: 44840 | S17: 46665 | T17: 1900000 | U17: 15 | V17: 285000 | W17: 1615000 | X17: 1.5 | Y17: 24225 | AA17: paid | AB17: 1141071585 | AC17: 45624 | AD17: DISBURSED | AE17: 10 | AF17: KHI/HO/D/MO/PC COMP/C/100245/165/10/2024 | AG17: 24225 | AH17: =Y17-AG17 -> 0
A18: Renewal | B18: 60426/1 | C18: 45566 | D18: SALAAM TAKAFUL LTD | E18: KHI/HO/D/MO/PC COMP/C/100245/87/10/2024 | F18: 45572 | G18: 45936 | H18: BASHARAT HUSSAIN AWAN | I18: 3740579404039 | J18: SUZUKI SWIFT DLX A/T NAV. | K18: APY-145 | L18: 13047835 | M18: 10047826 | N18: 60426/1 | O18: North | P18: 0804 | Q18: 586649 | R18: 44851 | S18: 45966 | T18: 2500000 | U18: 15 | V18: 375000 | W18: 2125000 | X18: 2 | Y18: 42500 | AA18: paid | AB18: 1141071585 | AC18: 45624 | AD18: DISBURSED | AE18: 10 | AF18: KHI/HO/D/MO/PC COMP/C/100245/87/10/2024 | AG18: 42500 | AH18: =Y18-AG18 -> 0
A19: Renewal | B19: 60393/1 | C19: 45566 | D19: SALAAM TAKAFUL LTD | E19: KHI/HO/D/MO/PC COMP/C/100245/86/10/2024 | F19: 45572 | G19: 45936 | H19: WAQAR ZULFIQAR | I19: 3520239789593 | J19: SUZUKI WAGON-R VXL E2 | K19: AML-960 | L19: B241216 | M19: K10141215 | N19: 60393/1 | O19: Central | P19: 0329 | Q19: 585391 | R19: 44848 | S19: 46665 | T19: 2421000 | U19: 15 | V19: 363150 | W19: 2057850 | X19: 2 | Y19: 41157 | AA19: paid | AB19: 1141071585 | AC19: 45624 | AD19: DISBURSED | AE19: 10 | AF19: KHI/HO/D/MO/PC COMP/C/100245/86/10/2024 | AG19: 41157 | AH19: =Y19-AG19 -> 0
A20: Renewal | B20: 60379/1 | C20: 45566 | D20: SALAAM TAKAFUL LTD | E20: KHI/HO/D/MO/PC COMP/C/100245/85/10/2024 | F20: 45572 | G20: 45936 | H20: MASOOD AHMED | I20: 4210111858317 | J20: SUZUKI ALTO VXR E-2 | K20: BQP-342 | L20: 6R100907 | M20: 1000912 | N20: 60379/1 | O20: South | P20: 0150 | Q20: 587460 | R20: 44844 | S20: 46665 | T20: 1800000 | U20: 15 | V20: 270000 | W20: 1530000 | X20: 2 | Y20: 30600 | AA20: paid | AB20: 1141071585 | AC20: 45624 | AD20: DISBURSED | AE20: 10 | AF20: KHI/HO/D/MO/PC COMP/C/100245/85/10/2024 | AG20: 30600 | AH20: =Y20-AG20 -> 0
A21: Renewal | B21: 55108/1 | C21: 45566 | D21: SALAAM TAKAFUL LTD | E21: KHI/HO/D/MO/PC COMP/C/100245/84/10/2024 | F21: 45572 | G21: 45936 | H21: MUHAMMAD ZAHID AWAN | I21: 3520154692391 | J21: SUZUKI ALTO | K21: alz-189 | L21: 6R250564 | M21: 6H1150569 | N21: 55108/1 | O21: Central | P21: 0314 | Q21: 568886 | R21: 44845 | S21: 46665 | T21: 1306000 | U21: 15 | V21: 195900 | W21: 1110100 | X21: 2 | Y21: 22202 | AA21: paid | AB21: 1141071585 | AC21: 45624 | AD21: DISBURSED | AE21: 0 | AF21: KHI/HO/D/MO/PC COMP/C/100245/84/10/2024 | AG21: 22202 | AH21: =Y21-AG21 -> 0
A22: Renewal | B22: 43907/1 | C22: 45566 | D22: SALAAM TAKAFUL LTD | E22: KHI/HO/D/MO/PC COMP/C/100245/56/10/2024 | F22: 45572 | G22: 45936 | H22: TAHIR MAHMOOD | I22: 3520182730219 | J22: HONDA CITY I-VTEC A/T PT | K22: AAS-317 | L22: 7541214 | M22: 264152 | N22: 43907/1 | O22: Central | P22: 0329 | Q22: 191712 | R22: 44116 | S22: 45936 | T22: 2645000 | U22: 25 | V22: 661250 | W22: 1983750 | X22: 2.5 | Y22: 49593.75 | AA22: paid | AB22: 1141071585 | AC22: 45624 | AD22: DISBURSED | AE22: 10 | AF22: KHI/HO/D/MO/PC COMP/C/100245/56/10/2024 | AG22: 49594 | AH22: =Y22-AG22 -> -0.25
A23: Renewal | B23: 51486/1 | C23: 45566 | D23: SALAAM TAKAFUL LTD | E23: KHI/HO/D/MO/PC COMP/C/100245/32/10/2024 | F23: 45573 | G23: 45937 | H23: JAVED IQBAL | I23: 3520198788985 | J23: SUZUKI WAGON R VXL AGS | K23: AGQ-752 | L23: 214320 | M23: 10114327 | N23: 51486/1 | O23: Central | P23: 0322 | Q23: 545272 | R23: 44491 | S23: 47063 | T23: 1890000 | U23: 20 | V23: 378000 | W23: 1512000 | X23: 2.5 | Y23: 37800 | AA23: paid | AB23: 1141071585 | AC23: 45624 | AD23: DISBURSED | AE23: 0 | AF23: KHI/HO/D/MO/PC COMP/C/100245/32/10/2024 | AG23: 37800 | AH23: =Y23-AG23 -> 0
A24: Renewal | B24: 60412/1 | C24: 45566 | D24: SALAAM TAKAFUL LTD | E24: KHI/HO/D/MO/PC COMP/C/100245/89/10/2024 | F24: 45575 | G24: 45939 | H24: MUHAMMAD BABAR | I24: 3520233874473 | J24: HONDA CITY I-VTEC (M/T) | K24: LEE-18-3628 | L24: 17507002 | M24: 219022 | N24: 60412/1 | O24: Central | P24: 0329 | Q24: 584800 | R24: 44846 | S24: 45936 | T24: 2450000 | U24: 15 | V24: 367500 | W24: 2082500 | X24: 2 | Y24: 41650 | AA24: paid | AB24: 1141071585 | AC24: 45624 | AD24: DISBURSED | AE24: 0 | AF24: KHI/HO/D/MO/PC COMP/C/100245/89/10/2024 | AG24: 41650 | AH24: =Y24-AG24 -> 0
A25: Renewal | B25: 60447/1 | C25: 45566 | D25: SALAAM TAKAFUL LTD | E25: KHI/HO/D/MO/PC COMP/C/100245/88/10/2024 | F25: 45575 | G25: 45939 | H25: GHULAM MUSTAFA | I25: 3210171174349 | J25: SUZUKI Swift GL CVT | K25: AMF-561 | L25: 1007562 | M25: 107572 | N25: 60447/1 | O25: Central | P25: 0567 | Q25: 587184 | R25: 44851 | S25: 45966 | T25: 3420000 | U25: 15 | V25: 513000 | W25: 2907000 | X25: 2 | Y25: 58140 | AA25: paid | AB25: 1141071585 | AC25: 45624 | AD25: DISBURSED | AE25: 0 | AF25: KHI/HO/D/MO/PC COMP/C/100245/88/10/2024 | AG25: 58140 | AH25: =Y25-AG25 -> 0
A26: Renewal | B26: 66433/1 | C26: 45566 | D26: SALAAM TAKAFUL LTD | E26: KHI/HO/D/MO/PC COMP/C/100245/77/10/2024 | F26: 45575 | G26: 45939 | H26: MUHAMMAD ALEEM KHAN | I26: 3520215315397 | J26: SUZUKI WAGON R VXL | K26: LEB-17A-9781 | L26: 142686 | M26: 10042672 | N26: 66433/1 | O26: Central | P26: 0329 | Q26: 623608 | R26: 45212 | S26: 47031 | T26: 1650000 | U26: 10 | V26: 165000 | W26: 1485000 | X26: 2 | Y26: 29700 | AA26: paid | AB26: 1141071585 | AC26: 45624 | AD26: DISBURSED | AE26: 41 | AF26: KHI/HO/D/MO/PC COMP/C/100245/77/10/2024 | AG26: 29700 | AH26: =Y26-AG26 -> 0
A27: Renewal | B27: 48688/1 | C27: 45566 | D27: SALAAM TAKAFUL LTD | E27: KHI/HO/D/MO/PC COMP/C/100245/34/10/2024 | F27: 45576 | G27: 45940 | H27: NAZMA MANZOOR | I27: 8220393528592 | J27: SUZUKI ALTO VXR EURO II A | K27: AVJ-134 | L27: 186398 | M27: 1086458 | N27: 48688/1 | O27: North | P27: 0482 | Q27: 533714 | R27: 44495 | S27: 47063 | T27: 1335000 | U27: 20 | V27: 267000 | W27: 1068000 | X27: 2.5 | Y27: 26700 | AA27: paid | AB27: 1141071585 | AC27: 45624 | AD27: DISBURSED | AE27: 10 | AF27: KHI/HO/D/MO/PC COMP/C/100245/34/10/2024 | AG27: 26700 | AH27: =Y27-AG27 -> 0
A28: Renewal | B28: 48864/2 | C28: 45566 | D28: SALAAM TAKAFUL LTD | E28: KHI/HO/D/MO/PC COMP/C/100245/33/10/2024 | F28: 45576 | G28: 45940 | H28: SHAHEEN KHALIL | I28: 3520227462346 | J28: SUZUKI ALTO VXR EURO II A | K28: AFD-307 | L28: 186434 | M28: 1086432 | N28: 48864/2 | O28: Central | P28: 0336 | Q28: 537654 | R28: 44482 | S28: 45936 | T28: 1335000 | U28: 20 | V28: 267000 | W28: 1068000 | X28: 2.5 | Y28: 26700 | AA28: paid | AB28: 1141071585 | AC28: 45624 | AD28: DISBURSED | AE28: 10 | AF28: KHI/HO/D/MO/PC COMP/C/100245/33/10/2024 | AG28: 26700 | AH28: =Y28-AG28 -> 0
A29: Renewal | B29: 56107/2 | C29: 45566 | D29: SALAAM TAKAFUL LTD | E29: KHI/HO/D/MO/PC COMP/C/100245/14/10/2024 | F29: 45576 | G29: 45940 | H29: MUHAMMAD ISRAR UL HAQ | I29: 3740581548867 | J29: SUZUKI ALTO VXR | K29: BAK-594 | L29: 251750 | M29: 1151776 | N29: 56107/2 | O29: North | P29: 0566 | Q29: 571646 | R29: 44851 | S29: 46696 | T29: 1675000 | U29: 15 | V29: 251250 | W29: 1423750 | X29: 2.5 | Y29: 35593.75 | AA29: paid | AB29: 1141071585 | AC29: 45624 | AD29: DISBURSED | AE29: 0 | AF29: KHI/HO/D/MO/PC COMP/C/100245/14/10/2024 | AG29: 35594 | AH29: =Y29-AG29 -> -0.25
