Workbook

Sheet Payment
A1: Sr. | B1: Status | C1: Contract No. | D1: Status2 | E1: Insurance Agency | F1: Dealer Name | G1: Customer Name | H1: City | I1: CNIC No. | J1: Home Phone# | K1: Mobile Number | L1: Business Phone# | M1: Mail Address | N1: Finance Amount | O1: Car Price | P1: Ins. Policy | Q1: Ins. Expiry Date | R1: Engine No. | S1: Chassis No. | T1: Car Category | U1: Reg. No. | V1: Car Name | W1: Model | X1: Contract Booking Date | Y1: Contract Value Date | Z1: Contract Maturity Date | AA1: Purchase Order No. | AB1: Tenor#2 | AC1: Tracker Company | AD1: Tracker Reference Number | AE1: Tracker Installation Date | AF1: Rate | AG1: Sum Insured | AH1: Premium | AI1: OLD Contract Ref | AJ1: Remarks-I | AK1: Remarks-II | AL1: Policy # 2024 | AM1: Tms prem | AN1: Difference
A2: 1 | B2: NORM | C2: 9976AD1211950014 | D2: Active | E2: T-PAK | F2: TOYOTA FAISALABAD | G2: MUHAMMAD ASIF | H2: Faisalabad | I2: 33100-5411156-3 | J2: 03217606970 | K2: 03217606970, 03217606970 | L2: 03217606970 | M2: H NO P-162 MAIN CHOWK ALI HOUSING C OLONY JHANG ROAD FAISALABAD PK | N2: 1156991 | O2: 2933000 | Q2: 45566 | R2: 2A34500 | S2: 9512872 | T2: NEW | V2: TOYOTA YARIS ATIV X CVT 1.5 | W2: 2021 | X2: 14-JUL-2021 | Y2: 03-SEP-2021 | Z2: 03-Sep-2026 | AA2: OLAFSD0300070634 | AB2: 5 | AC2: ITECL | AD2: 5370/08/2021 | AE2: 25-AUG-2021 | AF2: 2% | AG2: 2346400 | AH2: 46928 | AL2: KHI/HO/D/MO/PC COMP/C/99821/2/10/2024 | AM2: 46928 | AN2: =Table9[[#This Row],[Premium]]-Table9[[#This Row],[Tms prem]] -> 0
A3: 2 | B3: NORM | C3: 9976AD1232710002 | D3: Active | E3: T-PAK | F3: PAK SUZUKI MOTOR CO LTD | G3: MISBAH BATOOL | H3: Rawalpindi | I3: 37201-9259868-6 | K3: 03327555233 | M3: PLAZA # 10 ORCHARD RD, SECTOR-A,COMMERICAL DHA-2 ISLAMABAD 03327555233 | N3: 1874609 | O3: 2935000 | P3: 76078/000021/10/2023 | Q3: 02-OCT-2024 | R3: 284024 | S3: 1184046 | T3: NEW | V3: SUZUKI ALTO VXL AGS EURO II | W3: 2023 | X3: 45197 | Y3: 11-OCT-2023 | Z3: 11-Oct-2028 | AA3: OLARWP300097295 | AB3: 5 | AC3: CTRK | AD3: DIB0035359 | AE3: 04-OCT-2023 | AF3: 2% | AG3: 2641500 | AH3: 52830 | AL3: KHI/HO/D/MO/PC COMP/C/99821/5/10/2024 | AM3: 52830 | AN3: =Table9[[#This Row],[Premium]]-Table9[[#This Row],[Tms prem]] -> 0
A4: 3 | B4: NORM | C4: 9976AD1212070016 | D4: Active | E4: T-PAK | F4: PAK SUZUKI MOTOR CO LTD | G4: SAFIA BASHIR | H4: Lahore | I4: 35404-1497221-2 | J4: 03017982777 | K4: 03017982777 | L4: 04236680434 | M4: LAHORE GARRISON ACADEMY FOR BOYS TU FAIL ROAD CAMPUS LAHORE | N4: 374556 | O4: 1521000 | P4: 2524/02692/00002/10/2021 | Q4: 45568 | R4: 187796 | S4: 1085753 | T4: NEW | V4: SUZUKI ALTO VXL AGS EURO II | W4: 2021 | X4: 26-JUL-2021 | Y4: 27-OCT-2021 | Z4: 27-Oct-2026 | AA4: OLALHR300071150 | AB4: 5 | AC4: CTRK | AD4: DIB0032003 | AE4: 04-OCT-2021 | AF4: 2% | AG4: 1216800 | AH4: 24336 | AL4: KHI/HO/D/MO/PC COMP/C/99821/6/10/2024 | AM4: 24336 | AN4: =Table9[[#This Row],[Premium]]-Table9[[#This Row],[Tms prem]] -> 0
A5: 4 | B5: NORM | C5: 9976AD1211950016 | D5: Active | E5: T-PAK | F5: PAK SUZUKI MOTOR CO LTD | G5: FAISAL AHMAD | H5: Faisalabad | I5: 33100-0218679-7 | J5: 03006635147 | K5: 03006635147, 03006635147 | L5: 03006635147 | M5: P-12 ST 1 SHADMAN COLONY NEAR CITY MEGA MART FAISALABAD PK | N5: 273496 | O5: 1521000 | P5: 2021/09/CLFTTPCDP01047 | Q5: 45568 | R5: 6R185734 | S5: NF1AET306H1085750 | T5: NEW | V5: SUZUKI ALTO VXL AGS EURO-II | W5: 2021 | X5: 14-JUL-2021 | Y5: 11-OCT-2021 | Z5: 11-Oct-2025 | AA5: OLAFSD300070632 | AB5: 4 | AC5: ITECL | AD5: 5473/09/2021 | AE5: 04-OCT-2021 | AF5: 2% | AG5: 1216800 | AH5: 24336 | AL5: KHI/HO/D/MO/PC COMP/C/99821/7/10/2024 | AM5: 24336 | AN5: =Table9[[#This Row],[Premium]]-Table9[[#This Row],[Tms prem]] -> 0
A6: 5 | B6: NORM | C6: 9976AD2211180001 | D6: Active | E6: T-PAK | F6: CHANGAN JHELUM MOTORS | G6: ABAIDA LATIF | H6: Rawalpindi | I6: 35404-1723467-2 | K6: 03007969570 | M6: SHOP NO 07 GROUND FLOOR SADAT ARCADE WALLAYAT COMPLEX BAHRIA TOWN PH 7 RAWLAPINDI | N6: 590378 | O6: 1490000 | P6: DIB/T/BT/33754/ISB/1021 | Q6: 45568 | R6: M69U505255 | S6: M1009190 | T6: NEW | V6: CHANGAN KARVAAN | W6: 2021 | X6: 28-APR-2021 | Y6: 27-OCT-2021 | Z6: 27-Oct-2026 | AA6: OLARWP300068075 | AB6: 5 | AC6: FLCN | AD6: 108582/10/2021 | AE6: 01-OCT-2021 | AF6: 2% | AG6: 1192000 | AH6: 23840 | AL6: KHI/HO/D/MO/PC COMP/C/99821/8/10/2024 | AM6: 23840 | AN6: =Table9[[#This Row],[Premium]]-Table9[[#This Row],[Tms prem]] -> 0
A7: 6 | B7: NORM | C7: 9976AD1210890010 | D7: Active | E7: T-PAK | F7: CHANGAN JHELUM MOTORS | G7: MUHAMMAD NAWAZ | H7: Islamabad | I7: 61101-7100750-7 | K7: 03005750960 | M7: SHOP 9-B ROSE ARCADE G-11 MARKAZ ISLAMABAD | N7: 691695 | O7: 1640000 | P7: DIB/T/BT/33756/ISB/1021 | Q7: 45568 | R7: U504960 | S7: 1008837 | T7: NEW | V7: CHANGAN KARVAAN PLUS | W7: 2021 | X7: 30-MAR-2021 | Y7: 21-OCT-2021 | Z7: 21-Oct-2026 | AA7: OLAISD300067083 | AB7: 5 | AC7: CTRK | AD7: TDIDIB0029635 | AE7: 06-OCT-2021 | AF7: 2% | AG7: 1312000 | AH7: 26240 | AL7: KHI/HO/D/MO/PC COMP/C/99821/9/10/2024 | AM7: 26240 | AN7: =Table9[[#This Row],[Premium]]-Table9[[#This Row],[Tms prem]] -> 0
A8: 7 | B8: NORM | C8: 9976AD1211510006 | D8: Active | E8: T-PAK | F8: KIA MOTORS KINGS GATE | G8: ZUBAID UL HASSAN | H8: Lahore | I8: 35301-1959371-7 | M8: PUNJAB EDUCATION FOUNDATION 52 -L GULBERG III LAHORE | N8: 2024250 | O8: 4815000 | P8: DIB/T/33758/LHR/1021 | Q8: 45568 | R8: G4NAMH318860 | S8: NNAQL51AZKP307432 | T8: NEW | V8: SPORTAGE FWD | W8: 2021 | X8: 31-MAY-2021 | Y8: 03-NOV-2021 | Z8: 03-Nov-2026 | AA8: OLALHR300069013 | AB8: 5 | AF8: 1.75% | AG8: 3852000 | AH8: 67410 | AL8: KHI/HO/D/MO/PC COMP/C/99821/10/10/2024 | AM8: 67410 | AN8: =Table9[[#This Row],[Premium]]-Table9[[#This Row],[Tms prem]] -> 0
A9: 8 | B9: NORM | C9: 9976AD1211800009 | D9: Active | E9: T-PAK | F9: KIA MOTORS KINGS GATE | G9: EHSAN ULLAH KHAN | H9: Lahore | I9: 42301-1181720-5 | K9: 03248444007 | M9: H.NO 8 GULBERG II LAHORE 0324-8444007 LAHORE | N9: 2080252 | O9: 5303000 | P9: 56038/00008/10/2021 | Q9: 45568 | R9: 312329 | S9: 513332 | T9: NEW | V9: SPORTAGE AWD | W9: 2021 | X9: 29-JUN-2021 | Y9: 03-NOV-2021 | Z9: 03-Nov-2026 | AA9: OLALHR300070015 | AB9: 5 | AC9: ITECL | AD9: 5487/10/2021 | AE9: 05-OCT-2021 | AF9: 1.75% | AG9: 4242400 | AH9: 74242 | AL9: KHI/HO/D/MO/PC COMP/C/99821/11/10/2024 | AM9: 74242 | AN9: =Table9[[#This Row],[Premium]]-Table9[[#This Row],[Tms prem]] -> 0
A10: 10 | B10: WACH | C10: 9976AP1212810009 | D10: Active | E10: T-PAK | F10: SHADOW MOTORS | G10: SYED ALI JAFFER NAQVI | H10: Karachi | I10: 42101-9473365-1 | J10: 03121014890 | K10: 03121014890 | L10: 02138771111 | M10: DOW UNIVERSITY HOSPITAL GROUND OJHA CAMP OFFICE SAFOORA GOTH KARACHI | N10: 567765 | O10: 1400000 | P10: 56038/00071/10/2021 | Q10: 45568 | R10: 690501437 | S10: 1L100173D | T10: USD | U10: CY-9101 | V10: CHANGAN KARVAAN PLUS | W10: 2020 | X10: 08-OCT-2021 | Y10: 11-OCT-2021 | Z10: 11-Oct-2026 | AA10: OLUKHI300074602 | AB10: 5 | AC10: CTRK | AD10: DIB0032006 | AE10: 05-OCT-2021 | AF10: 2% | AG10: 1120000 | AH10: 22400 | AL10: KHI/HO/D/MO/PC COMP/C/99821/12/10/2024 | AM10: 22400 | AN10: =Table9[[#This Row],[Premium]]-Table9[[#This Row],[Tms prem]] -> 0
A11: 11 | B11: NORM | C11: 9976AD2211980007 | D11: Active | E11: T-PAK | F11: SUZUKI SUMMIT MOTORS PVT LTD. | G11: WASEEM HAIDER | H11: Lahore | I11: 35201-3439490-1 | J11: 03004252278 | K11: 03004252278 | L11: 04235921742 | M11: 109/F MAIN BOULEVARD STATE LIFE SOC IETY LAHORE | N11: 546851 | O11: 1610000 | P11: 2524/02692/0005/10/2021 | Q11: 45569 | R11: 221437 | S11: 10121456 | T11: NEW | V11: SUZUKI WA GONR VXL | W11: 2021 | X11: 17-JUL-2021 | Y11: 27-OCT-2021 | Z11: 27-Oct-2026 | AA11: OLALHR300070905 | AB11: 5 | AC11: CTRK | AD11: DIB0032013 | AE11: 05-OCT-2021 | AF11: 2% | AG11: 1288000 | AH11: 25760 | AL11: KHI/HO/D/MO/PC COMP/C/99821/13/10/2024 | AM11: 25760 | AN11: =Table9[[#This Row],[Premium]]-Table9[[#This Row],[Tms prem]] -> 0
A12: 12 | B12: NORM | C12: 9976AD2211960006 | D12: Active | E12: T-PAK | F12: PAK SUZUKI MOTOR CO LTD | G12: HAMZA JAVAID | H12: Lahore | I12: 35202-0424391-9 | J12: 03214251488 | K12: 03214251488 | L12: 04232174604 | M12: 136-MB 4TH FLOOR J BLOCK DHA PHASE 6 LAHORE | N12: 585536 | O12: 1521000 | P12: 2524/02692/00041/10/2021 | Q12: 45569 | R12: 6R183797 | S12: 1084378 | T12: NEW | V12: ALTO VXL EURO II | W12: 2021 | X12: 15-JUL-2021 | Y12: 27-OCT-2021 | Z12: 27-Oct-2026 | AA12: OLALHR300070758 | AB12: 5 | AC12: ITECL | AD12: 5485/10/2021 | AE12: 05-OCT-2021 | AF12: 2% | AG12: 1216800 | AH12: 24336 | AL12: KHI/HO/D/MO/PC COMP/C/99821/14/10/2024 | AM12: 24336 | AN12: =Table9[[#This Row],[Premium]]-Table9[[#This Row],[Tms prem]] -> 0
A13: 14 | B13: NORM | C13: 9976AD1211830096 | D13: Active | E13: T-PAK | F13: PAK SUZUKI MOTOR CO LTD | G13: IMRAN ALI | H13: Lahore | I13: 35201-9659682-3 | J13: 03214570085 | K13: 03214570085 | L13: 03214570085 | M13: SHOP NO 1 MADINA MARKET DAKKHANA BA TAPUR JALLO MORE NEAR KHALID ABID M EDICAL STORE LAHORE | N13: 663971 | O13: 1610000 | P13: 2021-10-205-V01501OP0002387 | Q13: 45569 | R13: PK10B220862 | S13: 10120866 | T13: NEW | V13: SUZUKI WAGON R VXL | W13: 2021 | X13: 02-JUL-2021 | Y13: 03-NOV-2021 | Z13: 03-Nov-2026 | AA13: OLALHR300070342 | AB13: 5 | AC13: ITECL | AD13: 5488/10/2021 | AE13: 05-OCT-2021 | AF13: 2% | AG13: 1288000 | AH13: 25760 | AL13: KHI/HO/D/MO/PC COMP/C/99821/15/10/2024 | AM13: 25760 | AN13: =Table9[[#This Row],[Premium]]-Table9[[#This Row],[Tms prem]] -> 0
A14: 15 | B14: NORM | C14: 9976AD1212250009 | D14: Active | E14: T-PAK | F14: TOYOTA LAYALPUR MOTOR | G14: KHURAM ASLAM | H14: Faisalabad | I14: 33100-5280143-7 | K14: 03137228656 | M14: HOUSE NO.121, STREET NO.04, RAZA ABAD BAZAT 03, FASISALABAD CELL NO:0313-7228656 | N14: 1035681 | O14: 2703000 | P14: DIB/T/BT/33717/LHR/0921 | Q14: 45569 | R14: 2A37296 | S14: 7023330 | T14: NEW | V14: TOYATA YARIS AITV CVT 1.3 | W14: 2021 | X14: 13-AUG-2021 | Y14: 11-OCT-2021 | Z14: 11-Oct-2026 | AA14: OLAFSD300071796 | AB14: 5 | AC14: CTRK | AD14: DIB0031912 | AE14: 05-OCT-2021 | AF14: 2% | AG14: 2162400 | AH14: 43248 | AL14: KHI/HO/D/MO/PC COMP/C/99821/17/10/2024 | AM14: 43248 | AN14: =Table9[[#This Row],[Premium]]-Table9[[#This Row],[Tms prem]] -> 0
A15: 17 | B15: NORM | C15: 9976AD1212420005 | D15: Active | E15: T-PAK | F15: TOYOTA CENTRAL MOTORS | G15: RIAZ AHMED | H15: Karachi | I15: 42301-3237044-9 | K15: 00966544056631 | M15: BUILDING NO.284 HAI ALWAZARAT KSA RIYADH HAI ALWAZARAT 11564 SAUDIA ARABIA | N15: 1432879 | O15: 3875000 | P15: PL-1021-1101010102-V14-D-00464 | Q15: 45569 | R15: A352653 | S15: ZE172R-7051829 | T15: RDA | V15: COROLLA ALTIS GRANDE CVT | W15: 2021 | X15: 30-AUG-2021 | Y15: 11-OCT-2021 | Z15: 11-Oct-2026 | AA15: OLAKHI300072688 | AB15: 5 | AC15: CTRK | AD15: DIB0031910 | AE15: 29-SEP-2021 | AF15: 1.4% | AG15: 3100000 | AH15: 43400 | AL15: KHI/HO/D/MO/PC COMP/C/99821/18/10/2024 | AM15: 43400 | AN15: =Table9[[#This Row],[Premium]]-Table9[[#This Row],[Tms prem]] -> 0
A16: 18 | B16: NORM | C16: 9976AD1212120088 | D16: Active | E16: T-PAK | F16: CHANGAN YAZDANI MOTORS | G16: LIAQUAT ALI | H16: Karachi | I16: 42201-0256366-7 | J16: 03222042469 | K16: 03222042469 | L16: 02135064445 | M16: PLOT # 27 SEC 23 KORANGI INDUSTRIAL ARERA NEAR SUKI SOUTH KARACHI | N16: 283181 | O16: 1399000 | P16: 2524/02692/00009/10/2021 | Q16: 45570 | R16: JL466Q9M69U505280 | S16: NKMAAB3D1M1009187 | T16: NEW | V16: CHANGAN KARVAN PLUS | W16: 2021 | X16: 31-JUL-2021 | Y16: 11-OCT-2021 | Z16: 11-Oct-2026 | AA16: OLAKHI300071194 | AB16: 5 | AC16: ITECL | AD16: 5477/09/2021 | AE16: 30-SEP-2021 | AF16: 2% | AG16: 1119200 | AH16: 22384 | AL16: KHI/HO/D/MO/PC COMP/C/99821/32/10/2024 | AM16: 22384 | AN16: =Table9[[#This Row],[Premium]]-Table9[[#This Row],[Tms prem]] -> 0
A17: 19 | B17: NORM | C17: 9976AD2212120023 | D17: Active | E17: T-PAK | F17: SUZUKI RACECOURSE MOTORS | G17: MURAD ALI | H17: Islamabad | I17: 37405-6776422-1 | J17: 03215052143 | L17: 0512326121 | M17: UNION CONSAL ROAD OPP NEW ISLAMIC M OHIUD DEEN UNIVERSITY NEAR MAIN SIH ISLAMABAD PK | N17: 386828 | O17: 1335000 | P17: 01-2110-PO-MTR-PCCM-D-001362 | Q17: 45570 | R17: 186805 | S17: 1086812 | T17: NEW | V17: SUZUKI ALTO VXR EURO II | W17: 2021 | X17: 31-JUL-2021 | Y17: 21-OCT-2021 | Z17: 21-Oct-2027 | AA17: OLAISD300071378 | AB17: 6 | AC17: ITECL | AD17: 5494/10/2021 | AE17: 06-OCT-2021 | AF17: 2% | AG17: 1068000 | AH17: 21360 | AL17: KHI/HO/D/MO/PC COMP/C/99821/33/10/2024 | AM17: 21360 | AN17: =Table9[[#This Row],[Premium]]-Table9[[#This Row],[Tms prem]] -> 0
A18: 20 | B18: NORM | C18: 9976AD2211510034 | D18: Active | E18: T-PAK | F18: PAK SUZUKI MOTOR CO LTD | G18: ABDUL AHAD | H18: Karachi | I18: 42201-7837972-7 | J18: 03340313754 | K18: 03340313754, 03122017660 | L18: 02134507660 | M18: ABU ZAID TRAVEL and TOURS PVT LTD SHO P # 9 POPULAR PLAZA OPP DISTRICT and SESSION COURT MALIR MAIN NATIONAL H KARACHI | N18: 569103 | O18: 1335000 | P18: 2524/06292/00007/10/2021 | Q18: 45570 | R18: 6R185075 | S18: NF1AET306H1085049 | T18: NEW | V18: SUZUKI ALTO VXL AGS EURO II | W18: 2021 | X18: 31-MAY-2021 | Y18: 03-NOV-2021 | Z18: 03-Nov-2026 | AA18: OLAKHI300069137 | AB18: 5 | AC18: CTRK | AD18: DIB0032002 | AE18: 05-OCT-2021 | AF18: 2% | AG18: 1068000 | AH18: 21360 | AL18: KHI/HO/D/MO/PC COMP/C/99821/1/10/2024 | AM18: 21360 | AN18: =Table9[[#This Row],[Premium]]-Table9[[#This Row],[Tms prem]] -> 0
A19: 21 | B19: NORM | C19: 9976AD2211800006 | D19: Active | E19: T-PAK | F19: PAK SUZUKI MOTOR CO LTD | G19: MUHAMMAD SHAHZEB KHAN | H19: Karachi | I19: 42201-6028139-1 | J19: 0213453442 | K19: 03333114064 | L19: 0213453442 | M19: S 1 J BLOCK 2 PECHS NOORANI KABAB KARACHI | N19: 566861 | O19: 1655000 | P19: 2524/02692/00006/10/2021 | Q19: 45570 | R19: 186714 | S19: 10086714 | T19: NEW | V19: SUZUKI CULTUS VXR | W19: 2021 | X19: 29-JUN-2021 | Y19: 21-OCT-2021 | Z19: 21-Oct-2026 | AA19: OLAKHI300070136 | AB19: 5 | AC19: ITECL | AD19: 5495/10/2021 | AE19: 06-OCT-2021 | AF19: 2% | AG19: 1324000 | AH19: 26480 | AL19: KHI/HO/D/MO/PC COMP/C/99821/34/10/2024 | AM19: 26480 | AN19: =Table9[[#This Row],[Premium]]-Table9[[#This Row],[Tms prem]] -> 0
A20: 22 | B20: NORM | C20: 9976AP1212810007 | D20: Active | E20: T-PAK | F20: SAEED AUTOS | G20: BASIT QAYYUM | H20: Faisalabad | I20: 33100-2045155-1 | J20: 03216612621 | K20: 03216612621, 03216612621 | L20: 03216612621 | M20: P-142 SAMUNDRI ROAD SEGHAL CITY FAISALABAD PK | N20: 590122 | O20: 1350000 | P20: 56038/00013/10/2021 | Q20: 45570 | R20: PK10B115726 | S20: A1L310PK10015730 | T20: USD | U20: LEE-16-3731 | V20: SUZUKI WAGONR VXL | W20: 2016 | X20: 08-OCT-2021 | Y20: 11-OCT-2021 | Z20: 11-Oct-2026 | AA20: OLUFSD300074693 | AB20: 5 | AC20: CTRK | AD20: DIB0032024 | AE20: 06-OCT-2021 | AF20: 2% | AG20: 1080000 | AH20: 21600 | AL20: KHI/HO/D/MO/PC COMP/C/99821/35/10/2024 | AM20: 21600 | AN20: =Table9[[#This Row],[Premium]]-Table9[[#This Row],[Tms prem]] -> 0
A21: 23 | B21: NORM | C21: 9976AD1212120081 | D21: Active | E21: T-PAK | F21: SUZUKI RACECOURSE MOTORS | G21: FAISAL AKHTAR | H21: Islamabad | I21: 37405-0555458-1 | J21: 0515708627 | K21: 03215558255 | L21: 0512251891-93 | M21: H NO. 1024 A, ST 01, BLOCK C, NATIONAL POLICE FOUNDATION, ISLAMABAD. | N21: 849587 | O21: 1335000 | P21: 01-2110-PO-MTR-PCCM-D-001361 | Q21: 45570 | R21: 186804 | S21: 1086805 | T21: NEW | V21: SUZUKI ALTO VXR EURO II | W21: 2021 | X21: 31-JUL-2021 | Y21: 21-OCT-2021 | Z21: 21-Oct-2028 | AA21: OLAISD300071344 | AB21: 7 | AC21: ITECL | AD21: 5493/10/2021 | AE21: 06-OCT-2021 | AF21: 2% | AG21: 1068000 | AH21: 21360 | AL21: KHI/HO/D/MO/PC COMP/C/99821/37/10/2024 | AM21: 21360 | AN21: =Table9[[#This Row],[Premium]]-Table9[[#This Row],[Tms prem]] -> 0
A22: 24 | B22: NORM | C22: 9976AD1212000019 | D22: Active | E22: T-PAK | F22: PAK SUZUKI MOTOR CO LTD | G22: NASIR ALI | H22: Lahore | I22: 35201-4822544-9 | J22: 03094460040 | K22: 03094460040 | L22: 03094460040 | M22: STREET NO 1 MANAWAN STOP NEAR LASAN I PHARMA LAHORE PK | N22: 685181 | O22: 1521000 | P22: 2021-10-205-V01501OP0002394 | Q22: 45570 | R22: 185038 | S22: 1085041 | T22: NEW | V22: ALTO VXL AGS EURO-II | W22: 2021 | X22: 19-JUL-2021 | Y22: 27-OCT-2021 | Z22: 27-Oct-2026 | AA22: OLALHR300070954 | AB22: 5 | AC22: CTRK | AD22: DIB0032022 | AE22: 06-OCT-2021 | AF22: 2% | AG22: 1216800 | AH22: 24336 | AL22: KHI/HO/D/MO/PC COMP/C/99821/39/10/2024 | AM22: 24336 | AN22: =Table9[[#This Row],[Premium]]-Table9[[#This Row],[Tms prem]] -> 0
A23: 25 | B23: NORM | C23: 9976AP1212950001 | D23: Active | E23: T-PAK | F23: KHALID MOTORS | G23: MUBASHIR ALI | H23: Lahore | I23: 35202-5513748-1 | J23: 03247842306 | K23: 03247842306 | L23: 03247842306 | M23: OFFICE NO 3 JOHAR VIEW G-BLOCK JOHA R TOWN LAHORE | N23: 769146 | O23: 1760000 | P23: 2524/02692/00019/10/2021 | Q23: 45570 | R23: 221199 | S23: 10121213 | T23: NEW | V23: SUZUKI WAGON R VXL AGS | W23: 2021 | X23: 22-OCT-2021 | Y23: 27-OCT-2021 | Z23: 27-Oct-2026 | AA23: OLDLHR300074655 | AB23: 5 | AC23: CTRK | AD23: DIB0032034 | AE23: 12-OCT-2021 | AF23: 2% | AG23: 1408000 | AH23: 28160 | AL23: KHI/HO/D/MO/PC COMP/C/99821/41/10/2024 | AM23: 28160 | AN23: =Table9[[#This Row],[Premium]]-Table9[[#This Row],[Tms prem]] -> 0
A24: 27 | B24: NORM | C24: 9976AD1211400016 | D24: Active | E24: T-PAK | F24: CHANGAN YAZDANI MOTORS | G24: NIRMALA | H24: Hyderabad | I24: 44101-0154353-4 | K24: 03332841080 | M24: FLAT NO 43 4TH FLOOR CHANDNI SHOPPING CENTRE SADDAR CANTT HYDERABAD | N24: 1013218 | O24: 2650000 | P24: PL-1021-1101010102-V14-D-00466 | Q24: 45570 | R24: JL473QFM3CAD517773 | S24: NKMA2ASE5M1003376 | T24: NEW | V24: CHANGAN ALSVIN 1.5L LUMIERE | W24: 2021 | X24: 20-MAY-2021 | Y24: 21-OCT-2021 | Z24: 21-Oct-2026 | AA24: OLAHYD300068773 | AB24: 5 | AC24: ITECL | AD24: 5483/10/2021 | AE24: 04-OCT-2021 | AF24: 2% | AG24: 2120000 | AH24: 42400 | AL24: KHI/HO/D/MO/PC COMP/C/99821/42/10/2024 | AM24: 42400 | AN24: =Table9[[#This Row],[Premium]]-Table9[[#This Row],[Tms prem]] -> 0
A25: 28 | B25: NORM | C25: 9976AD1212250015 | D25: Active | E25: T-PAK | F25: TOYOTA ISLAMABAD MOTORS | G25: HASAN MEHMOOD BUTT | H25: Islamabad | I25: 61101-8755355-9 | J25: 03212036843 | L25: 0 | M25: H # 13-C ST # 9 SECTOR F-11/1 ISLAMABAD PK | N25: 1156549 | O25: 2933000 | P25: DIB/T/BT/33764/ISB/1021 | Q25: 45570 | R25: 2A37485 | S25: NSP151R-9514082 | T25: NEW | V25: TOYOTA YARIS ATIV X CVT 1.5 | W25: 2021 | X25: 13-AUG-2021 | Y25: 21-OCT-2021 | Z25: 21-Oct-2026 | AA25: OLAISD300071917 | AB25: 5 | AC25: CTRK | AD25: TDIDIB0029677 | AE25: 06-OCT-2021 | AF25: 2% | AG25: 2346400 | AH25: 46928 | AL25: KHI/HO/D/MO/PC COMP/C/99821/43/10/2024 | AM25: 46928 | AN25: =Table9[[#This Row],[Premium]]-Table9[[#This Row],[Tms prem]] -> 0
A26: 29 | B26: NORM | C26: 9976AD1212250010 | D26: Active | E26: T-PAK | F26: TOYOTA SOUTHERN MOTORS | G26: HARIS AHMED | H26: Karachi | I26: 42000-6970640-3 | J26: 03053000454 | L26: 02135374194 | M26: B8 KHY-ERUM BLOCK-13B GULSHAN E IQB AL KARACHI PK | N26: 1134684 | O26: 2595000 | P26: 56038/00011/10/2021 | Q26: 45570 | R26: 2A37336 | S26: 7023452 | T26: NEW | V26: TOYOTA YARIS GLI CVT 1.3 | W26: 2021 | X26: 13-AUG-2021 | Y26: 21-OCT-2021 | Z26: 21-Oct-2026 | AA26: OLAKHI300071817 | AB26: 5 | AC26: ITECL | AD26: 5475/09/2021 | AE26: 29-SEP-2021 | AF26: 2% | AG26: 2076000 | AH26: 41520 | AL26: KHI/HO/D/MO/PC COMP/C/99821/44/10/2024 | AM26: 41520 | AN26: =Table9[[#This Row],[Premium]]-Table9[[#This Row],[Tms prem]] -> 0
A27: 30 | B27: NORM | C27: 9976AD1212160152 | D27: Active | E27: T-PAK | F27: TOYOTA FAISALABAD | G27: TAHIR HUSSAIN | H27: Faisalabad | I27: 33100-2644226-1 | K27: 03208653379 | M27: 343-B EDEN GARDEN FSD | N27: 1533867 | O27: 2703000 | P27: 2021/10/CLFTTPCDP01114 | Q27: 45570 | R27: 2A37985 | S27: 7023828 | T27: NEW | V27: TOYOTA YARIS ATIV CVT 1.3 | W27: 2021 | X27: 04-AUG-2021 | Y27: 21-OCT-2021 | Z27: 21-Oct-2028 | AA27: OLASFSD300071601 | AB27: 7 | AC27: ITECL | AD27: 5492/10/2021 | AE27: 06-OCT-2021 | AF27: 2% | AG27: 2162400 | AH27: 43248 | AL27: KHI/HO/D/MO/PC COMP/C/99821/45/10/2024 | AM27: 43248 | AN27: =Table9[[#This Row],[Premium]]-Table9[[#This Row],[Tms prem]] -> 0
A28: 31 | B28: NORM | C28: 9976AD1211180015 | D28: Active | E28: T-PAK | F28: HONDA GATEWAY PVT LTD | G28: ASIF ALI | H28: Lahore | I28: 35201-1378953-7 | J28: 03004337415 | K28: 03004337415 | L28: 03004337415 | M28: MAIN CANAL ROAD NEAR LAL PUL MUGHAL PURA LAHORE | N28: 1292266 | O28: 2865000 | P28: 252403898/10/2021 | Q28: 45570 | R28: 1000984 | S28: 003623 | T28: NEW | V28: HONDA CITY ASPIRE | W28: 2021 | X28: 28-APR-2021 | Y28: 03-NOV-2021 | Z28: 03-Nov-2026 | AA28: OLALHR300068212 | AB28: 5 | AC28: CTRK | AD28: DIB0032031 | AE28: 07-OCT-2021 | AF28: 2% | AG28: 2292000 | AH28: 45840 | AL28: KHI/HO/D/MO/PC COMP/C/99821/46/10/2024 | AM28: 45840 | AN28: =Table9[[#This Row],[Premium]]-Table9[[#This Row],[Tms prem]] -> 0
A29: 32 | B29: NORM | C29: 9976AP1212880037 | D29: Active | E29: T-PAK | F29: TOYOTA AIRPORT MOTOR | G29: ANSAR ALI | H29: Lahore | I29: 35201-0874888-1 | J29: 03213943808 | K29: 03213943808 | L29: 03213943808 | M29: PL 51 SIDDIQ TRADE CENTER GULBERG I I LAHORE | N29: 1425134 | O29: 3903000 | P29: 2524/02692/00012/10/2021 | Q29: 45570 | R29: Q352901 | S29: 7052057 | T29: NEW | V29: TOYOTA COROLLA ALTIS GRANDE | W29: 2021 | X29: 15-OCT-2021 | Y29: 21-OCT-2021 | Z29: 21-Oct-2026 | AA29: OLDLHR300074666 | AB29: 5 | AC29: CTRK | AD29: DIB0032023 | AE29: 06-OCT-2021 | AF29: 2% | AG29: 3122400 | AH29: 62448 | AL29: KHI/HO/D/MO/PC COMP/C/99821/47/10/2024 | AM29: 62448 | AN29: =Table9[[#This Row],[Premium]]-Table9[[#This Row],[Tms prem]] -> 0
A30: 33 | B30: NORM | C30: 9976AD1211830098 | D30: Active | E30: T-PAK | F30: MG CENTER | G30: MUHAMMAD AHSAN | H30: Faisalabad | I30: 33100-0579077-5 | J30: 0418523339 | K30: 03218661622 | L30: 0412696716 | M30: HOUSE NO 41 AHMAD STREET MOHALLAH KHAYIBAN COLONY NO 1 NEAR PRIME CARE HOSPITAL FAISALABAD. | N30: 1371960 | O30: 5449000 | P30: DIB/T/BT/33708/FSD/0921 | Q30: 45570 | R30: 5MGM6180193 | S30: MN110733 | T30: NEW | V30: MG MOTORS MG HS TURBO | W30: 2021 | X30: 02-JUL-2021 | Y30: 21-OCT-2021 | Z30: 21-Oct-2025 | AA30: OLAFSD300070368 | AB30: 4 | AC30: CTRK | AD30: TDIDIB0029645 | AE30: 06-OCT-2021 | AF30: 1.75% | AG30: 4359200 | AH30: 76286 | AL30: KHI/HO/D/MO/PC COMP/C/99821/48/10/2024 | AM30: 76286 | AN30: =Table9[[#This Row],[Premium]]-Table9[[#This Row],[Tms prem]] -> 0
A31: 34 | B31: NORM | C31: 9976AD1212100029 | D31: Active | E31: T-PAK | F31: KIA MACCA MOTORS | G31: MUHAMMAD RAFIQ | H31: Karachi | I31: 42201-0733928-5 | J31: N/A | K31: 0300-8229541 | L31: 34944352 | M31: FLAT# D-2 JAN KABIR REDENCY PLOT# 160/0 BLOCK-3 PECHS NEAR PECHS GOVT BOYS COLLEGE KARACHI | N31: 2021485 | O31: 5270000 | P31: 56038/00010/10/2021 | Q31: 45570 | R31: G4NAMH3105350 | S31: NNAQL51AZKP512857 | T31: NEW | V31: KIA SPORTAGE AWD | W31: 2021 | X31: 29-JUL-2021 | Y31: 11-OCT-2021 | Z31: 11-Oct-2026 | AA31: OLAKHI300071316 | AB31: 5 | AF31: 2% | AG31: 4216000 | AH31: 84320 | AL31: KHI/HO/D/MO/PC COMP/C/99821/49/10/2024 | AM31: 84320 | AN31: =Table9[[#This Row],[Premium]]-Table9[[#This Row],[Tms prem]] -> 0
A32: 35 | B32: NORM | C32: 9976AP2222800007 | D32: Active | E32: T-PAK | F32: AL-QURASH MOTORS | G32: NASIR KHAN | H32: Lahore | I32: 21201-4848113-5 | J32: N/A | K32: 03218265003 0308-5999985 | L32: 32734422 | M32: FLAT# 103 BLOCK-B IST FLOOR NAZ PLAZA M A JINNAH ROAD NEAR NISHAT CINEMA KARACHI | N32: 629716 | O32: 2000000 | P32: 64081/000006/10/2022 | Q32: 45570 | R32: 6R123909 | S32: 1023608 | T32: USD | U32: AAW-884 | V32: SUZUKI ALTO VXR AGS EURO II | W32: 2019 | X32: 07-OCT-2022 | Y32: 11-OCT-2022 | Z32: 11-Oct-2025 | AA32: OLULHR300090255 | AB32: 3 | AC32: ITFT | AD32: 8955/10/2022/ITFM | AE32: 06-OCT-2022 | AF32: 1.75% | AG32: 1700000 | AH32: 29750 | AL32: KHI/HO/D/MO/PC COMP/C/99821/52/10/2024 | AM32: 29750 | AN32: =Table9[[#This Row],[Premium]]-Table9[[#This Row],[Tms prem]] -> 0
A33: 36 | B33: NORM | C33: 9976AD1213620030 | D33: Active | E33: T-PAK | F33: TOYOTA ISLAMABAD MOTORS | G33: SHAHZARA ABID | H33: Islamabad | I33: 61101-6668987-8 | J33: 03215099485 | L33: 03215099485 | M33: H # 480 ST # 67 SECTOR I-8/3 ISLAMABAD PK | N33: 1840431 | O33: 3490000 | P33: 64081/00005/10/2022 | Q33: 45570 | R33: 100624 | S33: 6077924 | T33: NEW | V33: TOYOTA COROLLA ALTIS A/T | W33: 2022 | X33: 28-DEC-2021 | Y33: 11-OCT-2022 | Z33: 11-Oct-2027 | AA33: OLAISD300082495 | AB33: 5 | AC33: ITFM | AD33: 8941/10/2022/ITFM | AE33: 06-OCT-2022 | AF33: 2% | AG33: 2966500 | AH33: 59330 | AL33: KHI/HO/D/MO/PC COMP/C/99821/54/10/2024 | AM33: 59330 | AN33: =Table9[[#This Row],[Premium]]-Table9[[#This Row],[Tms prem]] -> 0
A34: 37 | B34: NORM | C34: 9976AD1212090003 | D34: Active | E34: T-PAK | F34: PAK SUZUKI MOTOR CO LTD | G34: SALAMAT LATIF | H34: Faisalabad | I34: 33102-8605139-7 | J34: 0418753867 | K34: 03007913402, 03007913402 | L34: 03007913402 | M34: H NO P-05 ST NO 03 GHAZI ABAD NO 01 MILLAT ROAD FAISALABAD PK | N34: 328717 | O34: 1830000 | P34: DIB/T/BT/33759/LHR/1021 | Q34: 45571 | R34: 186632 | S34: 10086600 | T34: NEW | V34: CULTUS VXL | W34: 2021 | X34: 28-JUL-2021 | Y34: 21-OCT-2021 | Z34: 21-Oct-2025 | AA34: OLAFSD300071183 | AB34: 4 | AC34: CTRK | AD34: DIB0032012 | AE34: 07-OCT-2021 | AF34: 2% | AG34: 1464000 | AH34: 29280 | AL34: KHI/HO/D/MO/PC COMP/C/99821/59/10/2024 | AM34: 29280 | AN34: =Table9[[#This Row],[Premium]]-Table9[[#This Row],[Tms prem]] -> 0
A35: 38 | B35: NORM | C35: 9976AD1212120109 | D35: Active | E35: T-PAK | F35: PAK SUZUKI MOTOR CO LTD | G35: FATIMA SYED | H35: Rawalpindi | I35: 37406-6812273-4 | J35: 03325621994 | L35: 0518441376 | M35: H # 27 (FIRST FLOOR ) ST # 5 SECTOR # D DHA 1 NEAR DHA AVENUE MALL RAWALPINDI PK | N35: 887205 | O35: 1975000 | P35: 01-2110-PO-MTR-PCCM-D-001368 | Q35: 45571 | R35: 183915 | S35: 10083928 | T35: NEW | V35: SUZUKI CULTUS VXL AGS EURO II | W35: 2021 | X35: 31-JUL-2021 | Y35: 21-OCT-2021 | Z35: 21-Oct-2028 | AA35: OLARWP300071536 | AB35: 7 | AC35: ITECL | AD35: 5506/10/2021 | AE35: 07-OCT-2021 | AF35: 2% | AG35: 1580000 | AH35: 31600 | AL35: KHI/HO/D/MO/PC COMP/C/99821/62/10/2024 | AM35: 31600 | AN35: =Table9[[#This Row],[Premium]]-Table9[[#This Row],[Tms prem]] -> 0
A36: 39 | B36: NORM | C36: 9976AD1212110035 | D36: Active | E36: T-PAK | F36: SUZUKI GUJRANWALA MOTOR | G36: MUHAMMAD ZAKIR MAHMOOD-ASAAN ACCOUN | H36: Gujranwala | I36: 34101-2511164-5 | K36: 0300300884 03009646209 | L36: 554215233 | M36: CIRCULAR ROAD LOHA BAZAR KHALID MAHMOOD IRON MERCHANT GRW 03000300884/03009646209 | N36: 771918 | O36: 1830000 | P36: 56038/00016/10/2021 | Q36: 45571 | R36: PK10K186803 | S36: NF1AVK31H10086799 | T36: NEW | V36: CULTUS VXL EURO-II | W36: 2021 | X36: 30-JUL-2021 | Y36: 21-OCT-2021 | Z36: 21-Oct-2026 | AA36: OLAGWL300071242 | AB36: 5 | AC36: ITECL | AD36: 5502/10/2021 | AE36: 07-OCT-2021 | AF36: 2% | AG36: 1464000 | AH36: 29280 | AL36: KHI/HO/D/MO/PC COMP/C/99821/63/10/2024 | AM36: 29280 | AN36: =Table9[[#This Row],[Premium]]-Table9[[#This Row],[Tms prem]] -> 0
A37: 41 | B37: NORM | C37: 9976AD1212090006 | D37: Active | E37: T-PAK | F37: KIA CLIFTON | G37: ZAMAN ZED | H37: Hyderabad | I37: 41303-2362189-9 | K37: 03163029266,03313567600 | M37: M/S RAHAT PETROLIUM SERVICE NEAR NEW INDUS BRIDGE BY PASS HYDERABAD | N37: 1424967 | O37: 5270000 | P37: DIB/T/BT/33774/HYD/1021 | Q37: 45571 | R37: 306026 | S37: 513039 | T37: NEW | V37: KIA SPORTGE AWD | W37: 2021 | X37: 28-JUL-2021 | Y37: 21-OCT-2021 | Z37: 21-Oct-2026 | AA37: OLAHYD300070985 | AB37: 5 | AF37: 1.75% | AG37: 4216000 | AH37: 73780 | AL37: KHI/HO/D/MO/PC COMP/C/99821/65/10/2024 | AM37: 73780 | AN37: =Table9[[#This Row],[Premium]]-Table9[[#This Row],[Tms prem]] -> 0
A38: 42 | B38: NORM | C38: 9976AP1212930013 | D38: Active | E38: T-PAK | F38: H.N. MOTORS | G38: MANZOOR SHAHEEN RUPAL | H38: Lahore | I38: 35201-1513681-3 | K38: 03000773331 | M38: 278 R DHA PHASE 2 LAHORE 03000773331 | N38: 1608642 | O38: 5303000 | P38: 56038/00018/10/2021 | Q38: 45571 | R38: 318184 | S38: 513534 | T38: NEW | V38: KIA SPORTAGE AWD | W38: 2021 | X38: 20-OCT-2021 | Y38: 21-OCT-2021 | Z38: 21-Oct-2026 | AA38: OLDLHR300074733 | AB38: 5 | AC38: ITECL | AD38: 5501/10/2021 | AE38: 07-OCT-2021 | AF38: 2% | AG38: 4242400 | AH38: 84848 | AL38: KHI/HO/D/MO/PC COMP/C/99821/66/10/2024 | AM38: 84848 | AN38: =Table9[[#This Row],[Premium]]-Table9[[#This Row],[Tms prem]] -> 0
A39: 43 | B39: NORM | C39: 9976AD1212430085 | D39: Active | E39: T-PAK | F39: KIA MACCA MOTORS | G39: FAZAL ULLAH NOONARI | H39: Hyderabad | I39: 41306-0439472-3 | J39: 03008371215 | K39: 03008371215 | L39: 0223411264 | M39: B.NO RHS MAIN AUTO BHAN ROAD LATIFA BAD # 3 NEAR TANDORI GRILL HYD HYDERABAD | N39: 2226509 | O39: 5270000 | P39: 2021/10/CLFTTPCDP01118 | Q39: 45571 | R39: G4NAMH312305 | S39: NNAQL51AZKP513369 | T39: NEW | V39: KIA SPORTGE AWD | W39: 2021 | X39: 31-AUG-2021 | Y39: 21-OCT-2021 | Z39: 21-Oct-2026 | AA39: OLAHYD300072861 | AB39: 5 | AC39: CTRK | AF39: 1.75% | AG39: 4216000 | AH39: 73780 | AL39: KHI/HO/D/MO/PC COMP/C/99821/67/10/2024 | AM39: 73780 | AN39: =Table9[[#This Row],[Premium]]-Table9[[#This Row],[Tms prem]] -> 0
A40: 44 | B40: NORM | C40: 9976AP1222840011 | D40: Active | E40: T-PAK | F40: CRESENT CAR COMPANY | G40: MUHAMMAD AHMAD KHAN | H40: Lahore | I40: 42501-1030528-9 | J40: 03344317595 | K40: 03214305069, 03344317595 | L40: 03344317595 | M40: H NO 751 ST NO 46 OVERSEAS-B BLOCK BAHRIA TOWN LAHORE PK | N40: 634615 | O40: 1150000 | P40: 64081/00007/10/2022 | Q40: 45571 | R40: 726340 | S40: 01264862 | T40: USD | U40: LEH-19-3401 | V40: SUZUKI MEHRAN VX-EURO II | W40: 2019 | X40: 11-OCT-2022 | Y40: 11-OCT-2022 | Z40: 11-Oct-2027 | AA40: OLULHR300090256 | AB40: 5 | AC40: ITFT | AD40: 8983/10/2022/ITFM | AE40: 10-OCT-2022 | AF40: 1.75% | AG40: 977500 | AH40: 17106 | AL40: KHI/HO/D/MO/PC COMP/C/99821/72/10/2024 | AM40: 17106 | AN40: =Table9[[#This Row],[Premium]]-Table9[[#This Row],[Tms prem]] -> 0
...

Sheet working
A1: POLICY NO. | B1: Assorted_code | D1: Premium | E1: 29Nov240034
A2: KHI/HO/D/MO/PC COMP/C/99821/2/10/2024 | B2: =VLOOKUP(A2,policy!B:C,2,0) -> 070000167978 | C2: 46928 | D2: =ROUND(C2,0) -> 46928 | E2: 29Nov240034 | F2: ="insert into ins_premium_det (premium_rcv_code,assorted_code, rec_amount,premium_rcv_detail_code,remaining_amt, payrec, mode_code,coinsurance_code,class_cd,it_remarks) values" -> insert into ins_premium_det (premium_rcv_code,assorted_code, rec_amount,premium_rcv_detail_code,remaining_amt, payrec, mode_code,coinsurance_code,class_cd,it_remarks) values | G2: ="('"&E2&"','"&B2&"','"&D2&"',(select max(to_number(i.premium_rcv_detail_code))+1 from ins_premium_det i),'"&D2&"','"&D2&"','02', '11000003','00','Request by Mr. Reheel Malik 02-Dec-2024');" -> ('29Nov240034','070000167978','46928',(select max(to_number(i.premium_rcv_detail_code))+1 from ins_premium_det i),'46928','46928','02', '11000003','00','Request by Mr. Reheel Malik 02-Dec-2024'); | H2: =F2&G2 -> insert into ins_premium_det (premium_rcv_code,assorted_code, rec_amount,premium_rcv_detail_code,remaining_amt, payrec, mode_code,coinsurance_code,class_cd,it_remarks) values('29Nov240034','070000167978','46928',(select max(to_number(i.premium_rcv_detail_code))+1 from ins_premium_det i),'46928','46928','02', '11000003','00','Request by Mr. Reheel Malik 02-Dec-2024');
A3: KHI/HO/D/MO/PC COMP/C/99821/5/10/2024 | B3: =VLOOKUP(A3,policy!B:C,2,0) -> 070000167981 | C3: 52830 | D3: =ROUND(C3,0) -> 52830 | E3: 29Nov240034 | F3: ="insert into ins_premium_det (premium_rcv_code,assorted_code, rec_amount,premium_rcv_detail_code,remaining_amt, payrec, mode_code,coinsurance_code,class_cd,it_remarks) values" -> insert into ins_premium_det (premium_rcv_code,assorted_code, rec_amount,premium_rcv_detail_code,remaining_amt, payrec, mode_code,coinsurance_code,class_cd,it_remarks) values | G3: ="('"&E3&"','"&B3&"','"&D3&"',(select max(to_number(i.premium_rcv_detail_code))+1 from ins_premium_det i),'"&D3&"','"&D3&"','02', '11000003','00','Request by Mr. Reheel Malik 02-Dec-2024');" -> ('29Nov240034','070000167981','52830',(select max(to_number(i.premium_rcv_detail_code))+1 from ins_premium_det i),'52830','52830','02', '11000003','00','Request by Mr. Reheel Malik 02-Dec-2024'); | H3: =F3&G3 -> insert into ins_premium_det (premium_rcv_code,assorted_code, rec_amount,premium_rcv_detail_code,remaining_amt, payrec, mode_code,coinsurance_code,class_cd,it_remarks) values('29Nov240034','070000167981','52830',(select max(to_number(i.premium_rcv_detail_code))+1 from ins_premium_det i),'52830','52830','02', '11000003','00','Request by Mr. Reheel Malik 02-Dec-2024');
A4: KHI/HO/D/MO/PC COMP/C/99821/6/10/2024 | B4: =VLOOKUP(A4,policy!B:C,2,0) -> 070000167982 | C4: 24336 | D4: =ROUND(C4,0) -> 24336 | E4: 29Nov240034 | F4: ="insert into ins_premium_det (premium_rcv_code,assorted_code, rec_amount,premium_rcv_detail_code,remaining_amt, payrec, mode_code,coinsurance_code,class_cd,it_remarks) values" -> insert into ins_premium_det (premium_rcv_code,assorted_code, rec_amount,premium_rcv_detail_code,remaining_amt, payrec, mode_code,coinsurance_code,class_cd,it_remarks) values | G4: ="('"&E4&"','"&B4&"','"&D4&"',(select max(to_number(i.premium_rcv_detail_code))+1 from ins_premium_det i),'"&D4&"','"&D4&"','02', '11000003','00','Request by Mr. Reheel Malik 02-Dec-2024');" -> ('29Nov240034','070000167982','24336',(select max(to_number(i.premium_rcv_detail_code))+1 from ins_premium_det i),'24336','24336','02', '11000003','00','Request by Mr. Reheel Malik 02-Dec-2024'); | H4: =F4&G4 -> insert into ins_premium_det (premium_rcv_code,assorted_code, rec_amount,premium_rcv_detail_code,remaining_amt, payrec, mode_code,coinsurance_code,class_cd,it_remarks) values('29Nov240034','070000167982','24336',(select max(to_number(i.premium_rcv_detail_code))+1 from ins_premium_det i),'24336','24336','02', '11000003','00','Request by Mr. Reheel Malik 02-Dec-2024');
A5: KHI/HO/D/MO/PC COMP/C/99821/7/10/2024 | B5: =VLOOKUP(A5,policy!B:C,2,0) -> 070000167983 | C5: 24336 | D5: =ROUND(C5,0) -> 24336 | E5: 29Nov240034 | F5: ="insert into ins_premium_det (premium_rcv_code,assorted_code, rec_amount,premium_rcv_detail_code,remaining_amt, payrec, mode_code,coinsurance_code,class_cd,it_remarks) values" -> insert into ins_premium_det (premium_rcv_code,assorted_code, rec_amount,premium_rcv_detail_code,remaining_amt, payrec, mode_code,coinsurance_code,class_cd,it_remarks) values | G5: ="('"&E5&"','"&B5&"','"&D5&"',(select max(to_number(i.premium_rcv_detail_code))+1 from ins_premium_det i),'"&D5&"','"&D5&"','02', '11000003','00','Request by Mr. Reheel Malik 02-Dec-2024');" -> ('29Nov240034','070000167983','24336',(select max(to_number(i.premium_rcv_detail_code))+1 from ins_premium_det i),'24336','24336','02', '11000003','00','Request by Mr. Reheel Malik 02-Dec-2024'); | H5: =F5&G5 -> insert into ins_premium_det (premium_rcv_code,assorted_code, rec_amount,premium_rcv_detail_code,remaining_amt, payrec, mode_code,coinsurance_code,class_cd,it_remarks) values('29Nov240034','070000167983','24336',(select max(to_number(i.premium_rcv_detail_code))+1 from ins_premium_det i),'24336','24336','02', '11000003','00','Request by Mr. Reheel Malik 02-Dec-2024');
A6: KHI/HO/D/MO/PC COMP/C/99821/8/10/2024 | B6: =VLOOKUP(A6,policy!B:C,2,0) -> 070000167984 | C6: 23840 | D6: =ROUND(C6,0) -> 23840 | E6: 29Nov240034 | F6: ="insert into ins_premium_det (premium_rcv_code,assorted_code, rec_amount,premium_rcv_detail_code,remaining_amt, payrec, mode_code,coinsurance_code,class_cd,it_remarks) values" -> insert into ins_premium_det (premium_rcv_code,assorted_code, rec_amount,premium_rcv_detail_code,remaining_amt, payrec, mode_code,coinsurance_code,class_cd,it_remarks) values | G6: ="('"&E6&"','"&B6&"','"&D6&"',(select max(to_number(i.premium_rcv_detail_code))+1 from ins_premium_det i),'"&D6&"','"&D6&"','02', '11000003','00','Request by Mr. Reheel Malik 02-Dec-2024');" -> ('29Nov240034','070000167984','23840',(select max(to_number(i.premium_rcv_detail_code))+1 from ins_premium_det i),'23840','23840','02', '11000003','00','Request by Mr. Reheel Malik 02-Dec-2024'); | H6: =F6&G6 -> insert into ins_premium_det (premium_rcv_code,assorted_code, rec_amount,premium_rcv_detail_code,remaining_amt, payrec, mode_code,coinsurance_code,class_cd,it_remarks) values('29Nov240034','070000167984','23840',(select max(to_number(i.premium_rcv_detail_code))+1 from ins_premium_det i),'23840','23840','02', '11000003','00','Request by Mr. Reheel Malik 02-Dec-2024');
A7: KHI/HO/D/MO/PC COMP/C/99821/9/10/2024 | B7: =VLOOKUP(A7,policy!B:C,2,0) -> 070000167985 | C7: 26240 | D7: =ROUND(C7,0) -> 26240 | E7: 29Nov240034 | F7: ="insert into ins_premium_det (premium_rcv_code,assorted_code, rec_amount,premium_rcv_detail_code,remaining_amt, payrec, mode_code,coinsurance_code,class_cd,it_remarks) values" -> insert into ins_premium_det (premium_rcv_code,assorted_code, rec_amount,premium_rcv_detail_code,remaining_amt, payrec, mode_code,coinsurance_code,class_cd,it_remarks) values | G7: ="('"&E7&"','"&B7&"','"&D7&"',(select max(to_number(i.premium_rcv_detail_code))+1 from ins_premium_det i),'"&D7&"','"&D7&"','02', '11000003','00','Request by Mr. Reheel Malik 02-Dec-2024');" -> ('29Nov240034','070000167985','26240',(select max(to_number(i.premium_rcv_detail_code))+1 from ins_premium_det i),'26240','26240','02', '11000003','00','Request by Mr. Reheel Malik 02-Dec-2024'); | H7: =F7&G7 -> insert into ins_premium_det (premium_rcv_code,assorted_code, rec_amount,premium_rcv_detail_code,remaining_amt, payrec, mode_code,coinsurance_code,class_cd,it_remarks) values('29Nov240034','070000167985','26240',(select max(to_number(i.premium_rcv_detail_code))+1 from ins_premium_det i),'26240','26240','02', '11000003','00','Request by Mr. Reheel Malik 02-Dec-2024');
A8: KHI/HO/D/MO/PC COMP/C/99821/10/10/2024 | B8: =VLOOKUP(A8,policy!B:C,2,0) -> 070000167986 | C8: 67410 | D8: =ROUND(C8,0) -> 67410 | E8: 29Nov240034 | F8: ="insert into ins_premium_det (premium_rcv_code,assorted_code, rec_amount,premium_rcv_detail_code,remaining_amt, payrec, mode_code,coinsurance_code,class_cd,it_remarks) values" -> insert into ins_premium_det (premium_rcv_code,assorted_code, rec_amount,premium_rcv_detail_code,remaining_amt, payrec, mode_code,coinsurance_code,class_cd,it_remarks) values | G8: ="('"&E8&"','"&B8&"','"&D8&"',(select max(to_number(i.premium_rcv_detail_code))+1 from ins_premium_det i),'"&D8&"','"&D8&"','02', '11000003','00','Request by Mr. Reheel Malik 02-Dec-2024');" -> ('29Nov240034','070000167986','67410',(select max(to_number(i.premium_rcv_detail_code))+1 from ins_premium_det i),'67410','67410','02', '11000003','00','Request by Mr. Reheel Malik 02-Dec-2024'); | H8: =F8&G8 -> insert into ins_premium_det (premium_rcv_code,assorted_code, rec_amount,premium_rcv_detail_code,remaining_amt, payrec, mode_code,coinsurance_code,class_cd,it_remarks) values('29Nov240034','070000167986','67410',(select max(to_number(i.premium_rcv_detail_code))+1 from ins_premium_det i),'67410','67410','02', '11000003','00','Request by Mr. Reheel Malik 02-Dec-2024');
A9: KHI/HO/D/MO/PC COMP/C/99821/11/10/2024 | B9: =VLOOKUP(A9,policy!B:C,2,0) -> 070000167987 | C9: 74242 | D9: =ROUND(C9,0) -> 74242 | E9: 29Nov240034 | F9: ="insert into ins_premium_det (premium_rcv_code,assorted_code, rec_amount,premium_rcv_detail_code,remaining_amt, payrec, mode_code,coinsurance_code,class_cd,it_remarks) values" -> insert into ins_premium_det (premium_rcv_code,assorted_code, rec_amount,premium_rcv_detail_code,remaining_amt, payrec, mode_code,coinsurance_code,class_cd,it_remarks) values | G9: ="('"&E9&"','"&B9&"','"&D9&"',(select max(to_number(i.premium_rcv_detail_code))+1 from ins_premium_det i),'"&D9&"','"&D9&"','02', '11000003','00','Request by Mr. Reheel Malik 02-Dec-2024');" -> ('29Nov240034','070000167987','74242',(select max(to_number(i.premium_rcv_detail_code))+1 from ins_premium_det i),'74242','74242','02', '11000003','00','Request by Mr. Reheel Malik 02-Dec-2024'); | H9: =F9&G9 -> insert into ins_premium_det (premium_rcv_code,assorted_code, rec_amount,premium_rcv_detail_code,remaining_amt, payrec, mode_code,coinsurance_code,class_cd,it_remarks) values('29Nov240034','070000167987','74242',(select max(to_number(i.premium_rcv_detail_code))+1 from ins_premium_det i),'74242','74242','02', '11000003','00','Request by Mr. Reheel Malik 02-Dec-2024');
A10: KHI/HO/D/MO/PC COMP/C/99821/12/10/2024 | B10: =VLOOKUP(A10,policy!B:C,2,0) -> 070000167988 | C10: 22400 | D10: =ROUND(C10,0) -> 22400 | E10: 29Nov240034 | F10: ="insert into ins_premium_det (premium_rcv_code,assorted_code, rec_amount,premium_rcv_detail_code,remaining_amt, payrec, mode_code,coinsurance_code,class_cd,it_remarks) values" -> insert into ins_premium_det (premium_rcv_code,assorted_code, rec_amount,premium_rcv_detail_code,remaining_amt, payrec, mode_code,coinsurance_code,class_cd,it_remarks) values | G10: ="('"&E10&"','"&B10&"','"&D10&"',(select max(to_number(i.premium_rcv_detail_code))+1 from ins_premium_det i),'"&D10&"','"&D10&"','02', '11000003','00','Request by Mr. Reheel Malik 02-Dec-2024');" -> ('29Nov240034','070000167988','22400',(select max(to_number(i.premium_rcv_detail_code))+1 from ins_premium_det i),'22400','22400','02', '11000003','00','Request by Mr. Reheel Malik 02-Dec-2024'); | H10: =F10&G10 -> insert into ins_premium_det (premium_rcv_code,assorted_code, rec_amount,premium_rcv_detail_code,remaining_amt, payrec, mode_code,coinsurance_code,class_cd,it_remarks) values('29Nov240034','070000167988','22400',(select max(to_number(i.premium_rcv_detail_code))+1 from ins_premium_det i),'22400','22400','02', '11000003','00','Request by Mr. Reheel Malik 02-Dec-2024');
A11: KHI/HO/D/MO/PC COMP/C/99821/13/10/2024 | B11: =VLOOKUP(A11,policy!B:C,2,0) -> 070000167989 | C11: 25760 | D11: =ROUND(C11,0) -> 25760 | E11: 29Nov240034 | F11: ="insert into ins_premium_det (premium_rcv_code,assorted_code, rec_amount,premium_rcv_detail_code,remaining_amt, payrec, mode_code,coinsurance_code,class_cd,it_remarks) values" -> insert into ins_premium_det (premium_rcv_code,assorted_code, rec_amount,premium_rcv_detail_code,remaining_amt, payrec, mode_code,coinsurance_code,class_cd,it_remarks) values | G11: ="('"&E11&"','"&B11&"','"&D11&"',(select max(to_number(i.premium_rcv_detail_code))+1 from ins_premium_det i),'"&D11&"','"&D11&"','02', '11000003','00','Request by Mr. Reheel Malik 02-Dec-2024');" -> ('29Nov240034','070000167989','25760',(select max(to_number(i.premium_rcv_detail_code))+1 from ins_premium_det i),'25760','25760','02', '11000003','00','Request by Mr. Reheel Malik 02-Dec-2024'); | H11: =F11&G11 -> insert into ins_premium_det (premium_rcv_code,assorted_code, rec_amount,premium_rcv_detail_code,remaining_amt, payrec, mode_code,coinsurance_code,class_cd,it_remarks) values('29Nov240034','070000167989','25760',(select max(to_number(i.premium_rcv_detail_code))+1 from ins_premium_det i),'25760','25760','02', '11000003','00','Request by Mr. Reheel Malik 02-Dec-2024');
A12: KHI/HO/D/MO/PC COMP/C/99821/14/10/2024 | B12: =VLOOKUP(A12,policy!B:C,2,0) -> 070000167990 | C12: 24336 | D12: =ROUND(C12,0) -> 24336 | E12: 29Nov240034 | F12: ="insert into ins_premium_det (premium_rcv_code,assorted_code, rec_amount,premium_rcv_detail_code,remaining_amt, payrec, mode_code,coinsurance_code,class_cd,it_remarks) values" -> insert into ins_premium_det (premium_rcv_code,assorted_code, rec_amount,premium_rcv_detail_code,remaining_amt, payrec, mode_code,coinsurance_code,class_cd,it_remarks) values | G12: ="('"&E12&"','"&B12&"','"&D12&"',(select max(to_number(i.premium_rcv_detail_code))+1 from ins_premium_det i),'"&D12&"','"&D12&"','02', '11000003','00','Request by Mr. Reheel Malik 02-Dec-2024');" -> ('29Nov240034','070000167990','24336',(select max(to_number(i.premium_rcv_detail_code))+1 from ins_premium_det i),'24336','24336','02', '11000003','00','Request by Mr. Reheel Malik 02-Dec-2024'); | H12: =F12&G12 -> insert into ins_premium_det (premium_rcv_code,assorted_code, rec_amount,premium_rcv_detail_code,remaining_amt, payrec, mode_code,coinsurance_code,class_cd,it_remarks) values('29Nov240034','070000167990','24336',(select max(to_number(i.premium_rcv_detail_code))+1 from ins_premium_det i),'24336','24336','02', '11000003','00','Request by Mr. Reheel Malik 02-Dec-2024');
A13: KHI/HO/D/MO/PC COMP/C/99821/15/10/2024 | B13: =VLOOKUP(A13,policy!B:C,2,0) -> 070000167991 | C13: 25760 | D13: =ROUND(C13,0) -> 25760 | E13: 29Nov240034 | F13: ="insert into ins_premium_det (premium_rcv_code,assorted_code, rec_amount,premium_rcv_detail_code,remaining_amt, payrec, mode_code,coinsurance_code,class_cd,it_remarks) values" -> insert into ins_premium_det (premium_rcv_code,assorted_code, rec_amount,premium_rcv_detail_code,remaining_amt, payrec, mode_code,coinsurance_code,class_cd,it_remarks) values | G13: ="('"&E13&"','"&B13&"','"&D13&"',(select max(to_number(i.premium_rcv_detail_code))+1 from ins_premium_det i),'"&D13&"','"&D13&"','02', '11000003','00','Request by Mr. Reheel Malik 02-Dec-2024');" -> ('29Nov240034','070000167991','25760',(select max(to_number(i.premium_rcv_detail_code))+1 from ins_premium_det i),'25760','25760','02', '11000003','00','Request by Mr. Reheel Malik 02-Dec-2024'); | H13: =F13&G13 -> insert into ins_premium_det (premium_rcv_code,assorted_code, rec_amount,premium_rcv_detail_code,remaining_amt, payrec, mode_code,coinsurance_code,class_cd,it_remarks) values('29Nov240034','070000167991','25760',(select max(to_number(i.premium_rcv_detail_code))+1 from ins_premium_det i),'25760','25760','02', '11000003','00','Request by Mr. Reheel Malik 02-Dec-2024');
... A335: KHI/HO/D/MO/PC COMP/C/99821/327/10/2024 | B335: =VLOOKUP(A335,policy!B:C,2,0) -> 070000168303 | C335: 21360 | D335: =ROUND(C335,0) -> 21360 | E335: 29Nov240034 | F335: ="insert into ins_premium_det (premium_rcv_code,assorted_code, rec_amount,premium_rcv_detail_code,remaining_amt, payrec, mode_code,coinsurance_code,class_cd,it_remarks) values" -> insert into ins_premium_det (premium_rcv_code,assorted_code, rec_amount,premium_rcv_detail_code,remaining_amt, payrec, mode_code,coinsurance_code,class_cd,it_remarks) values | G335: ="('"&E335&"','"&B335&"','"&D335&"',(select max(to_number(i.premium_rcv_detail_code))+1 from ins_premium_det i),'"&D335&"','"&D335&"','02', '11000003','00','Request by Mr. Reheel Malik 02-Dec-2024');" -> ('29Nov240034','070000168303','21360',(select max(to_number(i.premium_rcv_detail_code))+1 from ins_premium_det i),'21360','21360','02', '11000003','00','Request by Mr. Reheel Malik 02-Dec-2024'); | H335: =F335&G335 -> insert into ins_premium_det (premium_rcv_code,assorted_code, rec_amount,premium_rcv_detail_code,remaining_amt, payrec, mode_code,coinsurance_code,class_cd,it_remarks) values('29Nov240034','070000168303','21360',(select max(to_number(i.premium_rcv_detail_code))+1 from ins_premium_det i),'21360','21360','02', '11000003','00','Request by Mr. Reheel Malik 02-Dec-2024');
C336: =SUM(C2:C335) -> 13701580 | D336: =SUM(D2:D335) -> 13701580

Sheet Sheet2
A2: KHI/HO/D/MO/PC COMP/C/99821/2/10/2024 | B2: -10-2024 | H2: 99821 | I2: 00002 | J2: ="ia.assorted_string like '%"&H2&"-"&I2&B2&"%' or" -> ia.assorted_string like '%99821-00002-10-2024%' or
A3: KHI/HO/D/MO/PC COMP/C/99821/5/10/2024 | B3: -10-2024 | H3: 99821 | I3: 00005 | J3: ="ia.assorted_string like '%"&H3&"-"&I3&B3&"%' or" -> ia.assorted_string like '%99821-00005-10-2024%' or
A4: KHI/HO/D/MO/PC COMP/C/99821/6/10/2024 | B4: -10-2024 | H4: 99821 | I4: 00006 | J4: ="ia.assorted_string like '%"&H4&"-"&I4&B4&"%' or" -> ia.assorted_string like '%99821-00006-10-2024%' or
A5: KHI/HO/D/MO/PC COMP/C/99821/7/10/2024 | B5: -10-2024 | H5: 99821 | I5: 00007 | J5: ="ia.assorted_string like '%"&H5&"-"&I5&B5&"%' or" -> ia.assorted_string like '%99821-00007-10-2024%' or
A6: KHI/HO/D/MO/PC COMP/C/99821/8/10/2024 | B6: -10-2024 | H6: 99821 | I6: 00008 | J6: ="ia.assorted_string like '%"&H6&"-"&I6&B6&"%' or" -> ia.assorted_string like '%99821-00008-10-2024%' or
A7: KHI/HO/D/MO/PC COMP/C/99821/9/10/2024 | B7: -10-2024 | H7: 99821 | I7: 00009 | J7: ="ia.assorted_string like '%"&H7&"-"&I7&B7&"%' or" -> ia.assorted_string like '%99821-00009-10-2024%' or
A8: KHI/HO/D/MO/PC COMP/C/99821/10/10/2024 | B8: -10-2024 | H8: 99821 | I8: 00010 | J8: ="ia.assorted_string like '%"&H8&"-"&I8&B8&"%' or" -> ia.assorted_string like '%99821-00010-10-2024%' or
A9: KHI/HO/D/MO/PC COMP/C/99821/11/10/2024 | B9: -10-2024 | H9: 99821 | I9: 00011 | J9: ="ia.assorted_string like '%"&H9&"-"&I9&B9&"%' or" -> ia.assorted_string like '%99821-00011-10-2024%' or
A10: KHI/HO/D/MO/PC COMP/C/99821/12/10/2024 | B10: -10-2024 | H10: 99821 | I10: 00012 | J10: ="ia.assorted_string like '%"&H10&"-"&I10&B10&"%' or" -> ia.assorted_string like '%99821-00012-10-2024%' or
A11: KHI/HO/D/MO/PC COMP/C/99821/13/10/2024 | B11: -10-2024 | H11: 99821 | I11: 00013 | J11: ="ia.assorted_string like '%"&H11&"-"&I11&B11&"%' or" -> ia.assorted_string like '%99821-00013-10-2024%' or
A12: KHI/HO/D/MO/PC COMP/C/99821/14/10/2024 | B12: -10-2024 | H12: 99821 | I12: 00014 | J12: ="ia.assorted_string like '%"&H12&"-"&I12&B12&"%' or" -> ia.assorted_string like '%99821-00014-10-2024%' or
A13: KHI/HO/D/MO/PC COMP/C/99821/15/10/2024 | B13: -10-2024 | H13: 99821 | I13: 00015 | J13: ="ia.assorted_string like '%"&H13&"-"&I13&B13&"%' or" -> ia.assorted_string like '%99821-00015-10-2024%' or
... A335: KHI/HO/D/MO/PC COMP/C/99821/327/10/2024 | B335: -10-2024 | H335: 99821 | I335: 00327 | J335: ="ia.assorted_string like '%"&H335&"-"&I335&B335&"%' or" -> ia.assorted_string like '%99821-00327-10-2024%' or

Sheet policy
B1: FUNC_ASSORTED_STRING(IA.ASSORTED_CODE) | C1: ASSORTED_CODE
A2: 1 | B2: KHI/HO/D/MO/PC COMP/C/99821/297/10/2024 | C2: 070000168273
A3: 2 | B3: KHI/HO/D/MO/PC COMP/C/99821/301/10/2024 | C3: 070000168277
A4: 3 | B4: KHI/HO/D/MO/PC COMP/C/99821/305/10/2024 | C4: 070000168281
A5: 4 | B5: KHI/HO/D/MO/PC COMP/C/99821/308/10/2024 | C5: 070000168284
A6: 5 | B6: KHI/HO/D/MO/PC COMP/C/99821/331/10/2024 | C6: 070000168307
A7: 6 | B7: KHI/HO/D/MO/PC COMP/C/99821/64/10/2024 | C7: 070000168040
A8: 7 | B8: KHI/HO/D/MO/PC COMP/C/99821/67/10/2024 | C8: 070000168043
A9: 8 | B9: KHI/HO/D/MO/PC COMP/C/99821/138/10/2024 | C9: 070000168114
A10: 9 | B10: KHI/HO/D/MO/PC COMP/C/99821/172/10/2024 | C10: 070000168148
A11: 10 | B11: KHI/HO/D/MO/PC COMP/C/99821/365/10/2024 | C11: 070000168341
A12: 11 | B12: KHI/HO/D/MO/PC COMP/C/99821/122/10/2024 | C12: 070000168098
A13: 12 | B13: KHI/HO/D/MO/PC COMP/C/99821/123/10/2024 | C13: 070000168099
... A335: 334 | B335: KHI/HO/D/MO/PC COMP/C/99821/235/10/2024 | C335: 070000168211

Sheet Cancelaltion cases
A1: Sr. | B1: Status | C1: Contract No. | D1: Status2 | E1: Insurance Agency | F1: Dealer Name | G1: Customer Name | H1: City | I1: CNIC No. | J1: Home Phone# | K1: Mobile Number | L1: Business Phone# | M1: Mail Address | N1: Finance Amount | O1: Car Price | P1: Ins. Policy | Q1: Ins. Expiry Date | R1: Engine No. | S1: Chassis No. | T1: Car Category | U1: Reg. No. | V1: Car Name | W1: Model | X1: Contract Booking Date | Y1: Contract Value Date | Z1: Contract Maturity Date | AA1: Purchase Order No. | AB1: Tenor#2 | AC1: Tracker Company | AD1: Tracker Reference Number | AE1: Tracker Installation Date | AF1: Rate | AG1: Sum Insured | AH1: Premium | AI1: OLD Contract Ref | AJ1: Remarks-I | AK1: Remarks-II | AL1: Policy # 2024 | AM1: Match
A2: 379 | B2: NORM | C2: 997APD2203020054 | D2: Closed | E2: T-PAK | F2: MIDWAY MOTORS | G2: SHERAZ AHMED | H2: Karachi | I2: 42000-5003107-5 | K2: 0345-8309626 | M2: FLAT#A-35 2ND FLOOR EVACUE SOCIETY GULSHAN E IQBAL BLOCK A-10 RASHID MINHAS ROAD KARACHI | N2: 64263 | O2: 1500000 | P2: 52921/00122/10/2020 | Q2: 45592 | R2: 9302212 | S2: 401691 | T2: RCN | U2: CY-5356 | V2: NISSAN CLIPPER | W2: 2014 | X2: 28-OCT-2020 | Y2: 27-OCT-2020 | Z2: 27-Oct-2024 | AA2: POUKHI300059221 | AB2: 4 | AC2: CTRK | AD2: DIB0028958 | AE2: 28-OCT-2020 | AF2: 2% | AG2: 1200000 | AH2: 0 | AL2: #N/A | AM2: 0
A3: 380 | B3: NORM | C3: 997APD2202960016 | D3: Closed | E3: T-PAK | F3: FAROOQ MOTORS | G3: JAWWAD AHMAD | H3: Lahore | I3: 35202-2471233-9 | J3: 03008436394 | K3: 03008436394 | L3: 35987000 | M3: 61 C MAIN BOULEVARD GULBERG III LAHORE | N3: 118814 | O3: 2600000 | P3: 52921/00092/10/2020 | Q3: 45586 | R3: Q033457 | S3: ZRE171R-6010925 | T3: USD | U3: LE-16-A-5534 | V3: COROLLA ALTIS A/T | W3: 2016 | X3: 22-OCT-2020 | Y3: 27-OCT-2020 | Z3: 27-Oct-2024 | AA3: POULHR300059022 | AB3: 4 | AC3: ITFM | AD3: 3351/10/2020/ITFM | AE3: 22-OCT-2020 | AF3: 2% | AG3: 2080000 | AH3: 0 | AL3: #N/A | AM3: 0
A4: 381 | B4: NORM | C4: 9976AD1221650011 | D4: Closed | E4: T-PAK | F4: PAK SUZUKI MOTOR CO LTD | G4: RASHID MASOOD | H4: Karachi | I4: 42401-0115108-3 | J4: 32890039 | K4: 03332279932, 03083772828 | L4: 03332279932 | M4: H # 7 SECTOR 4-A SAEEDABAD NEAR FAROOQ-E-AZAM MASJID NEAR BONITA BEAUTI PARLOR KARACHI PAKISTAN | N4: 173330 | O4: 2399000 | P4: 64081/00062/10/2022 | Q4: 45591 | R4: 242115 | S4: 10142115 | T4: NEW | V4: SUZUKI WAGNOR VXL AGS | W4: 2022 | X4: 14-JUN-2022 | Y4: 27-NOV-2022 | Z4: 27-Nov-2024 | AA4: OLAKHI300088028 | AB4: 2 | AC4: ITFM | AD4: 9163/10/2022/ITFM | AE4: 26-OCT-2022 | AF4: 2% | AG4: 1919200 | AH4: 0 | AL4: #N/A | AM4: 0
A5: 382 | B5: NORM | C5: 9976AD1211230086 | D5: Closed | E5: T-PAK | F5: TOYOTA WALTON MOTORS | G5: RANA RIZWAN AHMAD | H5: Lahore | I5: 35201-5124611-3 | J5: 03226941025 | K5: 03226941025 | L5: 04237663204 | M5: SHOP NO 07-A MADINA MARKET SHAH ALA M MARKET LAHORE | N5: 296269 | O5: 7414000 | P5: 2021/10/CLFTTPCDP01150 | Q5: 45589 | R5: 1GS5063015 | S5: 8723 | T5: NEW | V5: HLIUX REVO V DC A/T 4X4 | W5: 2021 | X5: 03-MAY-2021 | Y5: 03-NOV-2021 | Z5: 03-Nov-2024 | AA5: OLALHR300068645 | AB5: 3 | AC5: CTRK | AD5: DIB0032243 | AE5: 25-OCT-2021 | AF5: 1.75% | AG5: 5931200 | AH5: 0 | AL5: #N/A | AM5: 0
A6: 383 | B6: NORM | C6: 997APD1182600002 | D6: Closed | E6: T-PAK | F6: ALI JAN MOTORS | G6: AZEEM AMJAD | H6: Gujranwala | I6: 34101-7096736-5 | J6: 03074441107 | K6: 03074441107 | L6: 030744411107 | M6: ST# 10 MOH NATIONAL TOWN SIALKOT RO AD MUGHAL CHOWK GUJRANWALA PK | N6: 653650 | O6: 769000 | P6: 2018/09/CLFTTPCDP01654 | Q6: 09-SEP-2019 | R6: 743765 | S6: 1282892 | T6: NEW | U6: LEB-18A-8775 | V6: MEHRAN VX EURO-II | W6: 2018 | X6: 17-SEP-2018 | Y6: 21-SEP-2018 | Z6: 21-Sep-2025 | AA6: POAGWL300037973 | AB6: 7 | AC6: CTRK | AD6: DIB0025772 | AE6: 14-SEP-2018 | AF6: 3.1% | AG6: 499850 | AH6: 0 | AL6: KHI/HO/D/MO/PC COMP/C/97805/167/09/2024 | AM6: 15495
A7: 384 | B7: NORM | C7: 997APD1203050129 | D7: Closed | E7: T-PAK | F7: ALI JAN MOTORS | G7: ZAHID MEHMOOD | H7: Gujranwala | I7: 34101-1899214-7 | J7: 03008615820 | K7: 03008615820 | L7: 03008615820 | M7: GALA ASLAM NIMKO WALA MAIN ROAD NEW ABADI NOWSHEHRA GUJRANWALA | N7: 487068 | O7: 1730000 | P7: 01-2010-PO-MTR-PCCM-D-001965 | Q7: 45595 | R7: 207790 | S7: 10107788 | T7: NEW | V7: WAGON R VXL | W7: 2020 | X7: 31-OCT-2020 | Y7: 03-NOV-2020 | Z7: 03-Nov-2025 | AA7: PODGWL300059797 | AB7: 5 | AC7: ITFM | AD7: 3424/10/2020/ITFM | AE7: 31-OCT-2020 | AF7: 2% | AG7: 1297500 | AH7: 0 | AL7: KHI/HO/D/MO/PC COMP/C/99821/26/10/2024 | AM7: 25950
A8: 385 | B8: NORM | C8: 997AAD1202120036 | D8: Closed | E8: T-PAK | F8: KIA MOTORS TOWNSHIP | G8: ANJUM PERVAIZ | H8: Lahore | I8: 34603-2339147-3 | J8: 03217446366 | K8: 03217446366 | L8: 03217446366 | M8: OFF NO 301-3RD FLOOR THE ENTERPRISE BUILDING MULTAN ROAD LAHORE | N8: 173147 | O8: 5430000 | P8: 52921/00131/10/2020 | Q8: 45593 | R8: G4NALH326945 | S8: NNAQL51AZKP506071 | T8: NEW | V8: SPORATGE AWD | W8: 2020 | X8: 30-JUL-2020 | Y8: 03-NOV-2020 | Z8: 03-Nov-2024 | AA8: POALHR300056177 | AB8: 4 | AF8: 1.5% | AG8: 4344000 | AH8: 0 | AL8: #N/A | AM8: 0
A9: 386 | B9: NORM | C9: 997APD1203010050 | D9: Closed | E9: T-PAK | F9: FAROOQ MOTORS | G9: ABDUL WAJID KHILJI | H9: Lahore | I9: 35202-2338858-1 | J9: 03099113711 | K9: 03099113711 | L9: 03099113711 | M9: 39 ITIFAQ PAINT MANSOORA MULTAN ROA D LAHORE | N9: 36518 | O9: 1700000 | P9: 52921/00108/10/2020 | Q9: 45588 | R9: 1KR1503445 | S9: KGC300197325 | T9: RCN | U9: LE-17A-9574 | V9: TOYOTA PASSO | W9: 2014 | X9: 27-OCT-2020 | Y9: 27-OCT-2020 | Z9: 27-Oct-2024 | AA9: POULHR300059096 | AB9: 4 | AC9: CTRK | AD9: DIB0028939 | AE9: 26-OCT-2020 | AF9: 2% | AG9: 1360000 | AH9: 0 | AL9: #N/A | AM9: 0
A10: 387 | B10: NORM | C10: 997AAD1202530013 | D10: Closed | E10: T-PAK | F10: KIA SAMA MOTORS | G10: MUHAMMAD HAMEED | H10: Lahore | I10: 35202-2526081-3 | J10: 35187750 | K10: 03219478056 | L10: 37632400 37632500 | M10: HOUSE NO 167-D-1 NESPAK HOUSING SOCIETY COLLEGE ROAD LAHORE | N10: 1161433 | O10: 4930000 | P10: 52921/00095/10/2020 | Q10: 45586 | R10: G4NALH326560 | S10: NNAQL51AZKP303669 | T10: NEW | V10: SPORTAGE FWD | W10: 2020 | X10: 09-SEP-2020 | Y10: 27-OCT-2020 | Z10: 27-Oct-2025 | AA10: POALHR300057163 | AB10: 5 | AF10: 1.5% | AG10: 3697500 | AH10: 0 | AL10: KHI/HO/D/MO/PC COMP/C/99821/119/10/2024 | AM10: 55462.5
A11: 388 | B11: NORM | C11: 997AAD1202090001 | D11: Closed | E11: T-PAK | F11: TOYOTA FAISALABAD | G11: FARAH SOHAIL | H11: OKARA | I11: 35302-9084187-6 | J11: 0442511713 | K11: 03216957713 | M11: HOUSE NO B II 4S 52 STREET NO 4 MOHALLAH C BLOCK OKARA | N11: 111358 | O11: 3928000 | P11: DIB/T/BT/29050/LHR/1020 | Q11: 45585 | R11: Q345470 | S11: 7044638 | T11: NEW | V11: TOYOTA COROLLA ALTIS GRANDE CVT | W11: 2020 | X11: 27-JUL-2020 | Y11: 03-NOV-2020 | Z11: 03-Nov-2024 | AA11: POAOKR300055801 | AB11: 4 | AC11: ITFM | AD11: 3347/10/2020/ITFM | AE11: 22-OCT-2020 | AF11: 2% | AG11: 3142400 | AH11: 0 | AL11: #N/A | AM11: 0
A12: 389 | B12: NORM | C12: 997APD2202950008 | D12: Closed | E12: T-PAK | F12: CHANGAN GUL MOTORS | G12: MUHAMMAD SAJJAD | H12: Karachi | I12: 42401-1994186-7 | J12: 03132675799 | K12: 03132675799 | L12: 02135121220 | M12: PLOT # 5/2 SEC 15 KORANGI INDUSTRIA L AREA KARACHI | N12: 26956 | O12: 1555000 | P12: 52921/00074/10/2020 | Q12: 45584 | R12: U500860 | S12: L1002697 | T12: NEW | V12: KARAVAAN PLUS | W12: 2020 | X12: 21-OCT-2020 | Y12: 21-OCT-2020 | Z12: 21-Oct-2024 | AA12: PODKHI300058782 | AB12: 4 | AC12: ITFM | AD12: 3305/10/2020/ITFM | AE12: 16-OCT-2020 | AF12: 2% | AG12: 1244000 | AH12: 0 | AL12: #N/A | AM12: 0
A13: 390 | B13: NORM | C13: 997APD1202940001 | D13: Closed | E13: T-PAK | F13: SIDDIQUI MOTORS | G13: MUHAMMAD ASHRAF | H13: Hyderabad | I13: 44101-7685210-5 | J13: 03023263208 | K13: 03023263208, 03322693563 | L13: 0222789229 | M13: HOUSE # 44/2 ABDULLAH HAVEN NASEEM NAGAR QASIMABAD NEAR ABDULLAH SPORT HYDERABAD PK | N13: 108314 | O13: 2550000 | P13: 01-2010-PO-MTR-PCCM-D-001912 | Q13: 45580 | R13: Z504038 | S13: 4130481 | T13: USD | U13: BMV-934 | V13: TOYOTA COROLLA GLI | W13: 2017 | X13: 20-OCT-2020 | Y13: 21-OCT-2020 | Z13: 21-Oct-2024 | AA13: POUHYD300058601 | AB13: 4 | AC13: ITMM | AD13: 3304/10/2020/ITMM | AE13: 16-OCT-2020 | AF13: 2% | AG13: 2040000 | AH13: 0 | AL13: #N/A | AM13: 0
A14: 391 | B14: NORM | C14: 997AAD2202040004 | D14: Closed | E14: T-PAK | F14: TOYOTA CENTRAL MOTORS | G14: ZAMEER SIDDIQUE QURESHI | H14: Karachi | I14: 42301-6462847-9 | K14: 03008221646 | M14: 3RD FLOOR,E-23 2ND COMM.LANE ZAMZAMA,PHASE,V DHA KARACHI | N14: 297187 | O14: 7048500 | P14: DIB/T/BT/28942/KHI/1020 | Q14: 45578 | R14: 1GD0840309 | S14: GUN126R-5541061 | T14: NEW | V14: TOYOTA HILUX REVO DC A/T 4X4 | W14: 2020 | X14: 22-JUL-2020 | Y14: 03-NOV-2020 | Z14: 03-Nov-2024 | AA14: POAKHI300055421 | AB14: 4 | AC14: CTRK | AD14: TDIDIB0028679 | AE14: 13-OCT-2020 | AF14: 1.5% | AG14: 5638800 | AH14: 0 | AL14: #N/A | AM14: 0
