Workbook

Sheet Sheet1
A1: Our_Branch_ID | B1: Arrg_ID | C1: App_Name | D1: Value_Of_Asset | E1: Premium Amt | F1: Tenure | G1: Initial_Disbursment_Date | H1: Vehicle_Name | I1: Bank_Ins_Rate | J1: Insuarance_Company | K1: Engine_No | L1: Chasis_No | M1: Rental_Start_Date | N1: Registration_No | O1: city | P1: Policy No. | Q1: TMS PREMIUM | R1: End. # | S1: DIFFERENCE PREMIUM
A2: PK0010002 | B2: CI-2024-0106-0006 | C2: FURQAN AHMED | D2: 4574000 | E2: 68610 | F2: 3 | G2: 20240829 | H2: Alsvin Lumiere Black Edition | I2: 1.5 | J2: SALAM TAKAFUL LTD | K2: JL473QFR3CAD511795 | L2: NKMA2ASE6R1000153 | M2: 20241105 | N2: - | O2: Karachi | P2: KHI/HO/D/MO/PC COMP/C/96760/11/09/2024 | Q2: 68610 | S2: =E2-Q2 -> 0
A3: PK0010002 | B3: CI-2024-0127-0004 | C3: MUHAMMAD IRFAN | D3: 8063000 | E3: 120945 | F3: 3 | G3: 20240822 | H3: Tucson Ultimate | I3: 1.5 | J3: SALAM TAKAFUL LTD | K3: G4NAPU364433 | L3: PMHJ2813MRN217569 | M3: 20241020 | N3: - | O3: Karachi | P3: KHI/HO/D/MO/PC COMP/C/96760/3/09/2024 | Q3: 120945 | S3: =E3-Q3 -> 0
A4: PK0010002 | B4: CI-2024-0143-0003 | C4: FAYYAZ SHAHAB | D4: 2550000 | E4: 38250 | F4: 1 | G4: 20240911 | H4: Corolla XLI MT | I4: 1.5 | J4: SALAM TAKAFUL LTD | K4: Z483678 | L4: NZE170R-4109707 | M4: 20241020 | N4: BHW-095 | O4: Karachi | P4: KHI/HO/D/MO/PC COMP/C/96760/4/09/2024 | Q4: 38250 | S4: =E4-Q4 -> 0
A5: PK0010002 | B5: CI-2024-0143-0006 | C5: SYED MANZOOR ALI | D5: 4600000 | E5: 69000 | F5: 3 | G5: 20240919 | H5: Prince Glory 580 Pro 1.5 Turbo | I5: 1.5 | J5: SALAM TAKAFUL LTD | K5: SFG15T21718279 | L5: PDF580PALR21D0603 | M5: 20241025 | N5: BJ-3799 | O5: Karachi | P5: KHI/HO/D/MO/PC COMP/C/96760/7/09/2024 | Q5: 69000 | S5: =E5-Q5 -> 0
A6: PK0010002 | B6: CI-2024-0169-0005 | C6: NAEEM AHMED | D6: 3045000 | E6: 45675 | F6: 3 | G6: 20240627 | H6: Alto VXL AGS | I6: 1.5 | J6: SALAM TAKAFUL LTD | K6: 6R318003 | L6: NF1AET306H1218096 | M6: 20241010 | N6: - | O6: Karachi | P6: KHI/HO/D/MO/PC COMP/C/96760/2/09/2024 | Q6: 45675 | S6: =E6-Q6 -> 0
A7: PK0010002 | B7: CI-2024-0193-0008 | C7: YOUNUS ALI KHAN | D7: 2707000 | E7: 40605 | F7: 5 | G7: 20240826 | H7: Alto VXR | I7: 1.5 | J7: SALAM TAKAFUL LTD | K7: 6R313689 | L7: NF1AET306H1213686 | M7: 20241010 | N7: - | O7: Karachi | P7: KHI/HO/D/MO/PC COMP/C/96760/1/09/2024 | Q7: 40605 | S7: =E7-Q7 -> 0
A8: PK0010002 | B8: CI-2024-0193-0011 | C8: Moina Khatoon | D8: 4200000 | E8: 63000 | F8: 3 | G8: 20240823 | H8: City PT Aspire 1.5L | I8: 1.5 | J8: SALAM TAKAFUL LTD | K8: L15Z81005774 | L8: NFBGN9669NR14671 | M8: 20241005 | N8: BVZ-338 | O8: Karachi | P8: KHI/HO/D/MO/PC COMP/C/94384/23/08/2024 | Q8: 63000 | S8: =E8-Q8 -> 0
A9: PK0010002 | B9: CI-2024-0194-0006 | C9: ZUBAIR AHMED | D9: 4900000 | E9: 73500 | F9: 3 | G9: 20240828 | H9: Swift GLX CVT | I9: 1.5 | J9: SALAM TAKAFUL LTD | K9: K12MR1020453 | L9: NF1SZC63S00203124 | M9: 20241005 | N9: BZZ-590 | O9: Karachi | P9: KHI/HO/D/MO/PC COMP/C/94384/22/08/2024 | Q9: 73500 | S9: =E9-Q9 -> 0
A10: PK0010002 | B10: CI-2024-0196-0016 | C10: TAYYAB SHAFIQUE | D10: 3360000 | E10: 50400 | F10: 5 | G10: 20240918 | H10: Cultus VXL | I10: 1.5 | J10: SALAM TAKAFUL LTD | K10: PK10K188972 | L10: NF1AVK31H10088947 | M10: 20241025 | N10: BVE-270 | O10: Karachi | P10: KHI/HO/D/MO/PC COMP/C/96760/6/09/2024 | Q10: 50400 | S10: =E10-Q10 -> 0
A11: PK0010002 | B11: CI-2024-4101-0003 | C11: ABID . | D11: 3045000 | E11: 45675 | F11: 3 | G11: 20240628 | H11: Alto VXL AGS | I11: 1.5 | J11: SALAM TAKAFUL LTD | K11: 6R319665 | L11: NF1AET306H1219656 | M11: 20241025 | N11: - | O11: Mirpur Khas | P11: KHI/HO/D/MO/PC COMP/C/96760/8/09/2024 | Q11: 45675 | S11: =E11-Q11 -> 0
A12: PK0010002 | B12: CI-2024-9961-0012 | C12: KHAISTA REHMAN | D12: 4760000 | E12: 71400 | F12: 3 | G12: 20240730 | H12: Yaris 1.3L GLI CVT | I12: 1.5 | J12: SALAM TAKAFUL LTD | K12: 2A69338 | L12: NSP150R-7046693 | M12: 20241025 | N12: - | O12: Karachi | P12: KHI/HO/D/MO/PC COMP/C/96746/5/09/2024 | Q12: 71400 | S12: =E12-Q12 -> 0
A13: PK0010002 | B13: CI-2024-9975-0005 | C13: UMAIR ALI | D13: 3045000 | E13: 45675 | F13: 5 | G13: 20240726 | H13: Alto VXL AGS | I13: 1.5 | J13: SALAM TAKAFUL LTD | K13: 6R318588 | L13: NF1AET306H1218584 | M13: 20241025 | N13: - | O13: Karachi | P13: KHI/HO/D/MO/PC COMP/C/96760/10/09/2024 | Q13: 45675 | S13: =E13-Q13 -> 0
... A19: PK0010011 | B19: CI-2024-0524-0004 | C19: KHALIFA ALI ABBAS | D19: 4719000 | E19: 70785 | F19: 3 | G19: 20240612 | H19: Swift GLX CVT | I19: 1.5 | J19: SALAM TAKAFUL LTD | K19: K12MR1021789 | L19: NF1SZC63S00204441 | M19: 20241025 | N19: ATD-725 | O19: Multan | P19: KHI/HO/D/MO/PC COMP/C/96746/2/09/2024 | Q19: 70785 | S19: =E19-Q19 -> 0
A20: PK0010011 | B20: CI-2024-1297-0007 | C20: MUJAHID BASHEER | D20: 2707000 | E20: 40605 | F20: 5 | G20: 20240730 | H20: Alto VXR | I20: 1.5 | J20: SALAM TAKAFUL LTD | K20: 6R318380 | L20: NF1AET306H1218355 | M20: 20241110 | O20: Multan | P20: KHI/HO/D/MO/PC COMP/C/96746/6/09/2024 | Q20: 40605 | S20: =E20-Q20 -> 0
A21: PK0010011 | B21: CI-2024-5801-0005 | C21: MUHAMMAD IMRAN | D21: 4479000 | E21: 67185 | F21: 3 | G21: 20240725 | H21: Yaris 1.3 GLI MT | I21: 1.5 | J21: SALAM TAKAFUL LTD | K21: 2A68405 | L21: NSP150R-7045771 | M21: 20241025 | O21: Jampur | P21: KHI/HO/D/MO/PC COMP/C/96746/1/09/2024 | Q21: 67185 | S21: =E21-Q21 -> 0
A22: PK0010011 | B22: CI-2024-9803-0007 | C22: SARA GILLANI | D22: 2707000 | E22: 40605 | F22: 5 | G22: 20240815 | H22: Alto VXR | I22: 1.5 | J22: SALAM TAKAFUL LTD | K22: 6R317894 | L22: NF1AET306H1217858 | M22: 20241105 | O22: Pakpattan | P22: KHI/HO/D/MO/PC COMP/C/96746/4/09/2024 | Q22: 40605 | S22: =E22-Q22 -> 0
A23: PK0010014 | B23: CI-2024-2208-0007 | C23: MUHAMMAD KHALID CHOUDHARY | D23: 4800000 | E23: 72000 | F23: 3 | G23: 20240916 | H23: City PT Aspire 1.5L | I23: 1.5 | J23: SALAM TAKAFUL LTD | K23: NFBGN9661NR016298 | L23: L15Z81006410 | M23: 20241105 | N23: AJR-512 | O23: Bahawalpur | P23: KHI/HO/D/MO/PC COMP/C/97576/1/09/2024 | Q23: 72000 | S23: =E23-Q23 -> 0
A24: PK0010015 | B24: CI-2024-0913-0003 | C24: YASIR ALI | D24: 4400000 | E24: 66000 | F24: 3 | G24: 20240830 | H24: Yaris 1.5 ATIV X AT | I24: 1.5 | J24: SALAM TAKAFUL LTD | K24: 2A17503 | L24: NSP151R9507207 | M24: 20241015 | N24: AST-539 | O24: Gujranwala | P24: KHI/HO/D/MO/PC COMP/C/96617/1/09/2024 | Q24: 66000 | S24: =E24-Q24 -> 0
A25: PK0010015 | B25: CI-2024-0914-0004 | C25: MAJID NAWAZ | D25: 4200000 | E25: 63000 | F25: 3 | G25: 20240923 | H25: Yaris 1.5 ATIV X AT | I25: 1.5 | J25: SALAM TAKAFUL LTD | K25: 2A18155 | L25: NSP151R9507359 | M25: 20241105 | N25: ADU-048 | O25: Gujranwala | P25: KHI/HO/D/MO/PC COMP/C/96617/3/09/2024 | Q25: 63000 | S25: =E25-Q25 -> 0
A26: PK0010015 | B26: CI-2024-0916-0004 | C26: MIAN MUHAMMAD UMER MAQSOOD | D26: 4760000 | E26: 71400 | F26: 3 | G26: 20240705 | H26: Yaris 1.3 GLI AT | I26: 1.5 | J26: SALAM TAKAFUL LTD | K26: 2A68320 | L26: NSP150R7045682 | M26: 20241010 | N26: ATB-677 | O26: Gujranwala | P26: KHI/HO/D/MO/PC COMP/P/94440/06/08/2024 | Q26: 72555 | R26: KHI/HO/D/MO/PC COMP/E/46610/00006/10/2024 | S26: =E26-Q26 -> -1155
A27: PK0010015 | B27: CI-2024-0916-0005 | C27: IHTISHAM UL HAQ CHEEMA | D27: 4760000 | E27: 71400 | F27: 3 | G27: 20240711 | H27: Yaris 1.3 GLI AT | I27: 1.5 | J27: SALAM TAKAFUL LTD | K27: 2A68345 | L27: NSP150R7045750 | M27: 20241010 | N27: ASQ-217 | O27: Gujranwala | P27: KHI/HO/D/MO/PC COMP/P/94440/05/08/2024 | Q27: 71400 | S27: =E27-Q27 -> 0
A28: PK0010015 | B28: CI-2024-0918-0004 | C28: ARSHAD AZIZ | D28: 4719000 | E28: 70785 | F28: 3 | G28: 20240621 | H28: Swift GLX CVT | I28: 1.5 | J28: SALAM TAKAFUL LTD | K28: K12MR1022068 | L28: NF1SZC63S00204748 | M28: 20241020 | N28: BEH-269 | O28: Gujranwala | P28: KHI/HO/D/MO/PC COMP/C/96617/2/09/2024 | Q28: 70785 | S28: =E28-Q28 -> 0
A29: PK0010016 | B29: CI-2024-0802-0006 | C29: SAAD ABDULLAH | D29: 4400000 | E29: 66000 | F29: 3 | G29: 20240906 | H29: Civic 1.8 i VTEC CVT | I29: 1.5 | J29: SALAM TAKAFUL LTD | K29: R18Z12902301 | L29: NFBFC6669GR002992 | M29: 20241010 | N29: BGP-350 | O29: Islamabad | P29: KHI/HO/D/MO/PC COMP/C/96876/2/09/2024 | Q29: 77000 | R29: KHI/HO/D/MO/PC COMP/E/46595/00002/10/2024 | S29: =E29-Q29 -> -11000
A30: PK0010016 | B30: CI-2024-0804-0014 | C30: SHEIKH MUHAMMAD IQBAL ASHRAF | D30: 19993000 | E30: 299895 | F30: 2 | G30: 20240902 | H30: Fortuner GR-S | I30: 1.5 | J30: SALAM TAKAFUL LTD | K30: 1GD5621773 | L30: GUN156R-1105713 | M30: 20241015 | N30: DZ-60 | O30: Rawalpindi | P30: KHI/HO/D/MO/PC COMP/P/97564/09/2024 | Q30: 299895 | S30: =E30-Q30 -> 0
A31: PK0010016 | B31: CI-2024-0826-0005 | C31: MALIK YASIR AYUB | D31: 4760000 | E31: 71400 | F31: 2 | G31: 20240805 | H31: Yaris 1.3L GLI CVT | I31: 1.5 | J31: SALAM TAKAFUL LTD | K31: 2A68765 | L31: NSP150R-7046133 | M31: 20241015 | N31: BEH-607 | O31: Rawalpindi | P31: KHI/HO/D/MO/PC COMP/C/96876/3/09/2024 | Q31: 71400 | S31: =E31-Q31 -> 0
A32: PK0010016 | B32: CI-2024-0827-0002 | C32: HAFIZ SYED M ZUBAIR YOUNIS | D32: 4719000 | E32: 70785 | F32: 3 | G32: 20240614 | H32: Swift GL CVT | I32: 1.5 | J32: SALAM TAKAFUL LTD | K32: K12MR1022030 | L32: NF1SZC63S00204673 | M32: 20241010 | N32: BEG-958 | O32: Rawalpindi | P32: KHI/HO/D/MO/PC COMP/C/96876/1/09/2024 | Q32: 70785 | S32: =E32-Q32 -> 0
A33: PK0010016 | B33: CI-2024-0828-0007 | C33: ASAD SHAHZAD | D33: 4100000 | E33: 61500 | F33: 2 | G33: 20240829 | H33: BRV S CVT | I33: 1.5 | J33: SALAM TAKAFUL LTD | K33: L15Z13507316 | L33: NFBDG1838HR007328 | M33: 20241005 | N33: AHF-972 | O33: Rawalpindi | P33: KHI/HO/D/MO/PC COMP/P/94836/02/08/2024 | Q33: 61500 | S33: =E33-Q33 -> 0
A34: PK0010299 | B34: CI-2024-0000-0081 | C34: ZUBAIR IJAZ | D34: 4075000 | E34: 61125 | F34: 3 | G34: 20240913 | H34: Corolla XLI MT | I34: 1.5 | J34: SALAM TAKAFUL LTD | K34: Z553330 | L34: NZE170R-4179116 | M34: 20241105 | N34: LEC-19-8905 | O34: Lahore | P34: KHI/HO/D/MO/PC COMP/C/96627/4/09/2024 | Q34: 61125 | S34: =E34-Q34 -> 0
A35: PK0010299 | B35: CI-2024-0214-0014 | C35: MUHAMMAD YASIR | D35: 6641000 | E35: 99615 | F35: 2 | G35: 20240815 | H35: Corolla X 1.6 CVT-i | I35: 1.5 | J35: SALAM TAKAFUL LTD | K35: Q108535 | L35: ZRE171R-6086040 | M35: 20241005 | N35: ASQ 639 | O35: Lahore | P35: KHI/HO/D/MO/PC COMP/P/94431/40/08/2024 | Q35: 99615 | S35: =E35-Q35 -> 0
A36: PK0010299 | B36: CI-2024-0248-0015 | C36: AAL E ZAHRA RIZVI | D36: 2840000 | E36: 42600 | F36: 5 | G36: 20240918 | H36: Alto VXL | I36: 1.5 | J36: SALAM TAKAFUL LTD | K36: 6R256594 | L36: NF1AET306H1156593 | M36: 20241105 | N36: AMM 858 | O36: Lahore | P36: KHI/HO/D/MO/PC COMP/C/96627/5/09/2024 | Q36: 42600 | S36: =E36-Q36 -> 0
A37: PK0010299 | B37: CI-2024-0251-0007 | C37: MAHMOOD AHMAD | D37: 4719000 | E37: 70785 | F37: 3 | G37: 20240709 | H37: City CVT 1.2L, CVT Transmission | I37: 1.5 | J37: SALAM TAKAFUL LTD | K37: L12B51026562 | L37: NFBGN8621RR042946 | M37: 20241020 | N37: ATC 129 | O37: Lahore | P37: KHI/HO/D/MO/PC COMP/C/96627/2/09/2024 | Q37: 70785 | S37: =E37-Q37 -> 0
A38: PK0010299 | B38: CI-2024-0292-0019 | C38: MUHAMMAD ABUBAKAR FAROOQ | D38: 2800000 | E38: 42000 | F38: 2 | G38: 20240920 | H38: City MT 1.3L | I38: 1.5 | J38: SALAM TAKAFUL LTD | K38: L13Z17463407 | L38: NFBGM1549HR206777 | M38: 20241105 | N38: LEF-17-6318 | O38: Lahore | P38: KHI/HO/D/MO/PC COMP/C/96627/7/09/2024 | Q38: 42000 | S38: =E38-Q38 -> 0
A39: PK0010299 | B39: CI-2024-1146-0003 | C39: IRFAN HAFEEZ | D39: 8749000 | E39: 131235 | F39: 3 | G39: 20240819 | H39: Oshan X7 FutureSense | I39: 1.5 | J39: SALAM TAKAFUL LTD | K39: JL473ZQ7RN8AT208982 | L39: NKMASE2E8R1000190 | M39: 20241015 | N39: ASQ 866 | O39: Lahore | P39: KHI/HO/D/MO/PC COMP/C/96627/1/09/2024 | Q39: 131235 | S39: =E39-Q39 -> 0
A40: PK0010299 | B40: CI-2024-1166-0007 | C40: KASHIF BASHIR GORAYA | D40: 3750000 | E40: 56250 | F40: 3 | G40: 20240919 | H40: Yaris 1.3ATIV AT | I40: 1.5 | J40: SALAM TAKAFUL LTD | K40: 2A05715 | L40: NSP150R-7002989 | M40: 20241105 | N40: AAD-687 | O40: Lahore | P40: KHI/HO/D/MO/PC COMP/C/96627/6/09/2024 | Q40: 56250 | S40: =E40-Q40 -> 0
A41: PK0010300 | B41: CI-2024-0207-0005 | C41: ALI RAZA | D41: 5000000 | E41: 75000 | F41: 3 | G41: 20240906 | H41: Civic 1.8 i VTEC CVT | I41: 1.5 | J41: SALAM TAKAFUL LTD | K41: R18Z-16920929 | L41: NFBFC6666MR073210 | M41: 20241020 | N41: ATW 409 | O41: Lahore | P41: KHI/HO/D/MO/PC COMP/C/96627/3/09/2024 | Q41: 75000 | S41: =E41-Q41 -> 0
... A50: PK0010499 | B50: CI-2024-1260-0002 | C50: ATTA ULLAH | D50: 6641000 | E50: 99615 | F50: 2 | G50: 20240822 | H50: Corolla Altis 1.6 AT Special Edition | I50: 1.5 | J50: SALAM TAKAFUL LTD | K50: Q108452 | L50: ZRE171R-6085968 | M50: 20241015 | N50: ASR-925-PUNJAB | O50: Chak Jhumra | P50: KHI/HO/D/MO/PC COMP/C/96598/1/09/2024 | Q50: 99615 | S50: =E50-Q50 -> 0
A51: PK0010499 | B51: CI-2024-1265-0001 | C51: SHEIKH RIZWAN HAIDER | D51: 4200000 | E51: 63000 | F51: 3 | G51: 20240827 | H51: City 1.2 AT | I51: 1.5 | J51: SALAM TAKAFUL LTD | K51: L12B51010335 | L51: NFBGN8628NR017228 | M51: 20241010 | N51: AJH-164-PUNJAB | O51: Nankana Sahib | P51: KHI/HO/D/MO/PC COMP/P/94381/12/08/2024 | Q51: 630000 | R51: KHI/HO/D/MO/PC COMP/E/46608/00012/10/2024 | S51: =E51-Q51 -> -567000
A52: PK0010499 | B52: CI-2024-3301-0005 | C52: SAGHEER AHMAD | D52: 3858000 | E52: 57870 | F52: 3 | G52: 20240523 | H52: Cultus VXR | I52: 1.5 | J52: SALAM TAKAFUL LTD | K52: PK10K210775 | L52: NF1AVK31H10110787 | M52: 20241020 | N52: ASR-198-PUNJAB | O52: Jhang | P52: KHI/HO/D/MO/PC COMP/C/96772/2/09/2024 | Q52: 57870 | S52: =E52-Q52 -> 0
A53: PK0010499 | B53: CI-2024-9836-0011 | C53: MUHAMMAD ZUBAIR MUBARAK | D53: 6500000 | E53: 97500 | F53: 3 | G53: 20240910 | H53: Corolla Altis Grande AT | I53: 1.5 | J53: SALAM TAKAFUL LTD | K53: Q355524 | L53: ZRE172R-7054705 | M53: 20241025 | N53: AWJ-883-ICT | O53: Samundri | P53: KHI/HO/D/MO/PC COMP/C/96772/4/09/2024 | Q53: 97500 | S53: =E53-Q53 -> 0
...

Sheet working
A1: POLICY NO. | B1: Assorted_code | D1: Premium | E1: 08Oct240154
A2: KHI/HO/D/MO/PC COMP/C/96760/11/09/2024 | B2: =VLOOKUP(A2,Policy!A:B,2,0) -> 070000166608 | C2: 68610 | D2: =ROUND(C2,0) -> 68610 | E2: 08Oct240154 | F2: ="insert into ins_premium_det (premium_rcv_code,assorted_code, rec_amount,premium_rcv_detail_code,remaining_amt, payrec, mode_code,coinsurance_code,class_cd,it_remarks) values" -> insert into ins_premium_det (premium_rcv_code,assorted_code, rec_amount,premium_rcv_detail_code,remaining_amt, payrec, mode_code,coinsurance_code,class_cd,it_remarks) values | G2: ="('"&E2&"','"&B2&"','"&D2&"',(select max(to_number(i.premium_rcv_detail_code))+1 from ins_premium_det i),'"&D2&"','"&D2&"','02', '11000003','00','Request by Mr. Saqib Saleem 08-Oct-2024 Allocation no 08Oct240154');" -> ('08Oct240154','070000166608','68610',(select max(to_number(i.premium_rcv_detail_code))+1 from ins_premium_det i),'68610','68610','02', '11000003','00','Request by Mr. Saqib Saleem 08-Oct-2024 Allocation no 08Oct240154'); | H2: =F2&G2 -> insert into ins_premium_det (premium_rcv_code,assorted_code, rec_amount,premium_rcv_detail_code,remaining_amt, payrec, mode_code,coinsurance_code,class_cd,it_remarks) values('08Oct240154','070000166608','68610',(select max(to_number(i.premium_rcv_detail_code))+1 from ins_premium_det i),'68610','68610','02', '11000003','00','Request by Mr. Saqib Saleem 08-Oct-2024 Allocation no 08Oct240154');
A3: KHI/HO/D/MO/PC COMP/C/96760/3/09/2024 | B3: =VLOOKUP(A3,Policy!A:B,2,0) -> 070000165445 | C3: 120945 | D3: =ROUND(C3,0) -> 120945 | E3: 08Oct240154 | F3: ="insert into ins_premium_det (premium_rcv_code,assorted_code, rec_amount,premium_rcv_detail_code,remaining_amt, payrec, mode_code,coinsurance_code,class_cd,it_remarks) values" -> insert into ins_premium_det (premium_rcv_code,assorted_code, rec_amount,premium_rcv_detail_code,remaining_amt, payrec, mode_code,coinsurance_code,class_cd,it_remarks) values | G3: ="('"&E3&"','"&B3&"','"&D3&"',(select max(to_number(i.premium_rcv_detail_code))+1 from ins_premium_det i),'"&D3&"','"&D3&"','02', '11000003','00','Request by Mr. Saqib Saleem 08-Oct-2024 Allocation no 08Oct240154');" -> ('08Oct240154','070000165445','120945',(select max(to_number(i.premium_rcv_detail_code))+1 from ins_premium_det i),'120945','120945','02', '11000003','00','Request by Mr. Saqib Saleem 08-Oct-2024 Allocation no 08Oct240154'); | H3: =F3&G3 -> insert into ins_premium_det (premium_rcv_code,assorted_code, rec_amount,premium_rcv_detail_code,remaining_amt, payrec, mode_code,coinsurance_code,class_cd,it_remarks) values('08Oct240154','070000165445','120945',(select max(to_number(i.premium_rcv_detail_code))+1 from ins_premium_det i),'120945','120945','02', '11000003','00','Request by Mr. Saqib Saleem 08-Oct-2024 Allocation no 08Oct240154');
A4: KHI/HO/D/MO/PC COMP/C/96760/4/09/2024 | B4: =VLOOKUP(A4,Policy!A:B,2,0) -> 070000165514 | C4: 38250 | D4: =ROUND(C4,0) -> 38250 | E4: 08Oct240154 | F4: ="insert into ins_premium_det (premium_rcv_code,assorted_code, rec_amount,premium_rcv_detail_code,remaining_amt, payrec, mode_code,coinsurance_code,class_cd,it_remarks) values" -> insert into ins_premium_det (premium_rcv_code,assorted_code, rec_amount,premium_rcv_detail_code,remaining_amt, payrec, mode_code,coinsurance_code,class_cd,it_remarks) values | G4: ="('"&E4&"','"&B4&"','"&D4&"',(select max(to_number(i.premium_rcv_detail_code))+1 from ins_premium_det i),'"&D4&"','"&D4&"','02', '11000003','00','Request by Mr. Saqib Saleem 08-Oct-2024 Allocation no 08Oct240154');" -> ('08Oct240154','070000165514','38250',(select max(to_number(i.premium_rcv_detail_code))+1 from ins_premium_det i),'38250','38250','02', '11000003','00','Request by Mr. Saqib Saleem 08-Oct-2024 Allocation no 08Oct240154'); | H4: =F4&G4 -> insert into ins_premium_det (premium_rcv_code,assorted_code, rec_amount,premium_rcv_detail_code,remaining_amt, payrec, mode_code,coinsurance_code,class_cd,it_remarks) values('08Oct240154','070000165514','38250',(select max(to_number(i.premium_rcv_detail_code))+1 from ins_premium_det i),'38250','38250','02', '11000003','00','Request by Mr. Saqib Saleem 08-Oct-2024 Allocation no 08Oct240154');
A5: KHI/HO/D/MO/PC COMP/C/96760/7/09/2024 | B5: =VLOOKUP(A5,Policy!A:B,2,0) -> 070000165699 | C5: 69000 | D5: =ROUND(C5,0) -> 69000 | E5: 08Oct240154 | F5: ="insert into ins_premium_det (premium_rcv_code,assorted_code, rec_amount,premium_rcv_detail_code,remaining_amt, payrec, mode_code,coinsurance_code,class_cd,it_remarks) values" -> insert into ins_premium_det (premium_rcv_code,assorted_code, rec_amount,premium_rcv_detail_code,remaining_amt, payrec, mode_code,coinsurance_code,class_cd,it_remarks) values | G5: ="('"&E5&"','"&B5&"','"&D5&"',(select max(to_number(i.premium_rcv_detail_code))+1 from ins_premium_det i),'"&D5&"','"&D5&"','02', '11000003','00','Request by Mr. Saqib Saleem 08-Oct-2024 Allocation no 08Oct240154');" -> ('08Oct240154','070000165699','69000',(select max(to_number(i.premium_rcv_detail_code))+1 from ins_premium_det i),'69000','69000','02', '11000003','00','Request by Mr. Saqib Saleem 08-Oct-2024 Allocation no 08Oct240154'); | H5: =F5&G5 -> insert into ins_premium_det (premium_rcv_code,assorted_code, rec_amount,premium_rcv_detail_code,remaining_amt, payrec, mode_code,coinsurance_code,class_cd,it_remarks) values('08Oct240154','070000165699','69000',(select max(to_number(i.premium_rcv_detail_code))+1 from ins_premium_det i),'69000','69000','02', '11000003','00','Request by Mr. Saqib Saleem 08-Oct-2024 Allocation no 08Oct240154');
A6: KHI/HO/D/MO/PC COMP/C/96760/2/09/2024 | B6: =VLOOKUP(A6,Policy!A:B,2,0) -> 070000165263 | C6: 45675 | D6: =ROUND(C6,0) -> 45675 | E6: 08Oct240154 | F6: ="insert into ins_premium_det (premium_rcv_code,assorted_code, rec_amount,premium_rcv_detail_code,remaining_amt, payrec, mode_code,coinsurance_code,class_cd,it_remarks) values" -> insert into ins_premium_det (premium_rcv_code,assorted_code, rec_amount,premium_rcv_detail_code,remaining_amt, payrec, mode_code,coinsurance_code,class_cd,it_remarks) values | G6: ="('"&E6&"','"&B6&"','"&D6&"',(select max(to_number(i.premium_rcv_detail_code))+1 from ins_premium_det i),'"&D6&"','"&D6&"','02', '11000003','00','Request by Mr. Saqib Saleem 08-Oct-2024 Allocation no 08Oct240154');" -> ('08Oct240154','070000165263','45675',(select max(to_number(i.premium_rcv_detail_code))+1 from ins_premium_det i),'45675','45675','02', '11000003','00','Request by Mr. Saqib Saleem 08-Oct-2024 Allocation no 08Oct240154'); | H6: =F6&G6 -> insert into ins_premium_det (premium_rcv_code,assorted_code, rec_amount,premium_rcv_detail_code,remaining_amt, payrec, mode_code,coinsurance_code,class_cd,it_remarks) values('08Oct240154','070000165263','45675',(select max(to_number(i.premium_rcv_detail_code))+1 from ins_premium_det i),'45675','45675','02', '11000003','00','Request by Mr. Saqib Saleem 08-Oct-2024 Allocation no 08Oct240154');
A7: KHI/HO/D/MO/PC COMP/C/96760/1/09/2024 | B7: =VLOOKUP(A7,Policy!A:B,2,0) -> 070000165251 | C7: 40605 | D7: =ROUND(C7,0) -> 40605 | E7: 08Oct240154 | F7: ="insert into ins_premium_det (premium_rcv_code,assorted_code, rec_amount,premium_rcv_detail_code,remaining_amt, payrec, mode_code,coinsurance_code,class_cd,it_remarks) values" -> insert into ins_premium_det (premium_rcv_code,assorted_code, rec_amount,premium_rcv_detail_code,remaining_amt, payrec, mode_code,coinsurance_code,class_cd,it_remarks) values | G7: ="('"&E7&"','"&B7&"','"&D7&"',(select max(to_number(i.premium_rcv_detail_code))+1 from ins_premium_det i),'"&D7&"','"&D7&"','02', '11000003','00','Request by Mr. Saqib Saleem 08-Oct-2024 Allocation no 08Oct240154');" -> ('08Oct240154','070000165251','40605',(select max(to_number(i.premium_rcv_detail_code))+1 from ins_premium_det i),'40605','40605','02', '11000003','00','Request by Mr. Saqib Saleem 08-Oct-2024 Allocation no 08Oct240154'); | H7: =F7&G7 -> insert into ins_premium_det (premium_rcv_code,assorted_code, rec_amount,premium_rcv_detail_code,remaining_amt, payrec, mode_code,coinsurance_code,class_cd,it_remarks) values('08Oct240154','070000165251','40605',(select max(to_number(i.premium_rcv_detail_code))+1 from ins_premium_det i),'40605','40605','02', '11000003','00','Request by Mr. Saqib Saleem 08-Oct-2024 Allocation no 08Oct240154');
A8: KHI/HO/D/MO/PC COMP/C/94384/23/08/2024 | B8: =VLOOKUP(A8,Policy!A:B,2,0) -> 070000164915 | C8: 63000 | D8: =ROUND(C8,0) -> 63000 | E8: 08Oct240154 | F8: ="insert into ins_premium_det (premium_rcv_code,assorted_code, rec_amount,premium_rcv_detail_code,remaining_amt, payrec, mode_code,coinsurance_code,class_cd,it_remarks) values" -> insert into ins_premium_det (premium_rcv_code,assorted_code, rec_amount,premium_rcv_detail_code,remaining_amt, payrec, mode_code,coinsurance_code,class_cd,it_remarks) values | G8: ="('"&E8&"','"&B8&"','"&D8&"',(select max(to_number(i.premium_rcv_detail_code))+1 from ins_premium_det i),'"&D8&"','"&D8&"','02', '11000003','00','Request by Mr. Saqib Saleem 08-Oct-2024 Allocation no 08Oct240154');" -> ('08Oct240154','070000164915','63000',(select max(to_number(i.premium_rcv_detail_code))+1 from ins_premium_det i),'63000','63000','02', '11000003','00','Request by Mr. Saqib Saleem 08-Oct-2024 Allocation no 08Oct240154'); | H8: =F8&G8 -> insert into ins_premium_det (premium_rcv_code,assorted_code, rec_amount,premium_rcv_detail_code,remaining_amt, payrec, mode_code,coinsurance_code,class_cd,it_remarks) values('08Oct240154','070000164915','63000',(select max(to_number(i.premium_rcv_detail_code))+1 from ins_premium_det i),'63000','63000','02', '11000003','00','Request by Mr. Saqib Saleem 08-Oct-2024 Allocation no 08Oct240154');
A9: KHI/HO/D/MO/PC COMP/C/94384/22/08/2024 | B9: =VLOOKUP(A9,Policy!A:B,2,0) -> 070000164860 | C9: 73500 | D9: =ROUND(C9,0) -> 73500 | E9: 08Oct240154 | F9: ="insert into ins_premium_det (premium_rcv_code,assorted_code, rec_amount,premium_rcv_detail_code,remaining_amt, payrec, mode_code,coinsurance_code,class_cd,it_remarks) values" -> insert into ins_premium_det (premium_rcv_code,assorted_code, rec_amount,premium_rcv_detail_code,remaining_amt, payrec, mode_code,coinsurance_code,class_cd,it_remarks) values | G9: ="('"&E9&"','"&B9&"','"&D9&"',(select max(to_number(i.premium_rcv_detail_code))+1 from ins_premium_det i),'"&D9&"','"&D9&"','02', '11000003','00','Request by Mr. Saqib Saleem 08-Oct-2024 Allocation no 08Oct240154');" -> ('08Oct240154','070000164860','73500',(select max(to_number(i.premium_rcv_detail_code))+1 from ins_premium_det i),'73500','73500','02', '11000003','00','Request by Mr. Saqib Saleem 08-Oct-2024 Allocation no 08Oct240154'); | H9: =F9&G9 -> insert into ins_premium_det (premium_rcv_code,assorted_code, rec_amount,premium_rcv_detail_code,remaining_amt, payrec, mode_code,coinsurance_code,class_cd,it_remarks) values('08Oct240154','070000164860','73500',(select max(to_number(i.premium_rcv_detail_code))+1 from ins_premium_det i),'73500','73500','02', '11000003','00','Request by Mr. Saqib Saleem 08-Oct-2024 Allocation no 08Oct240154');
A10: KHI/HO/D/MO/PC COMP/C/96760/6/09/2024 | B10: =VLOOKUP(A10,Policy!A:B,2,0) -> 070000165596 | C10: 50400 | D10: =ROUND(C10,0) -> 50400 | E10: 08Oct240154 | F10: ="insert into ins_premium_det (premium_rcv_code,assorted_code, rec_amount,premium_rcv_detail_code,remaining_amt, payrec, mode_code,coinsurance_code,class_cd,it_remarks) values" -> insert into ins_premium_det (premium_rcv_code,assorted_code, rec_amount,premium_rcv_detail_code,remaining_amt, payrec, mode_code,coinsurance_code,class_cd,it_remarks) values | G10: ="('"&E10&"','"&B10&"','"&D10&"',(select max(to_number(i.premium_rcv_detail_code))+1 from ins_premium_det i),'"&D10&"','"&D10&"','02', '11000003','00','Request by Mr. Saqib Saleem 08-Oct-2024 Allocation no 08Oct240154');" -> ('08Oct240154','070000165596','50400',(select max(to_number(i.premium_rcv_detail_code))+1 from ins_premium_det i),'50400','50400','02', '11000003','00','Request by Mr. Saqib Saleem 08-Oct-2024 Allocation no 08Oct240154'); | H10: =F10&G10 -> insert into ins_premium_det (premium_rcv_code,assorted_code, rec_amount,premium_rcv_detail_code,remaining_amt, payrec, mode_code,coinsurance_code,class_cd,it_remarks) values('08Oct240154','070000165596','50400',(select max(to_number(i.premium_rcv_detail_code))+1 from ins_premium_det i),'50400','50400','02', '11000003','00','Request by Mr. Saqib Saleem 08-Oct-2024 Allocation no 08Oct240154');
A11: KHI/HO/D/MO/PC COMP/C/96760/8/09/2024 | B11: =VLOOKUP(A11,Policy!A:B,2,0) -> 070000165700 | C11: 45675 | D11: =ROUND(C11,0) -> 45675 | E11: 08Oct240154 | F11: ="insert into ins_premium_det (premium_rcv_code,assorted_code, rec_amount,premium_rcv_detail_code,remaining_amt, payrec, mode_code,coinsurance_code,class_cd,it_remarks) values" -> insert into ins_premium_det (premium_rcv_code,assorted_code, rec_amount,premium_rcv_detail_code,remaining_amt, payrec, mode_code,coinsurance_code,class_cd,it_remarks) values | G11: ="('"&E11&"','"&B11&"','"&D11&"',(select max(to_number(i.premium_rcv_detail_code))+1 from ins_premium_det i),'"&D11&"','"&D11&"','02', '11000003','00','Request by Mr. Saqib Saleem 08-Oct-2024 Allocation no 08Oct240154');" -> ('08Oct240154','070000165700','45675',(select max(to_number(i.premium_rcv_detail_code))+1 from ins_premium_det i),'45675','45675','02', '11000003','00','Request by Mr. Saqib Saleem 08-Oct-2024 Allocation no 08Oct240154'); | H11: =F11&G11 -> insert into ins_premium_det (premium_rcv_code,assorted_code, rec_amount,premium_rcv_detail_code,remaining_amt, payrec, mode_code,coinsurance_code,class_cd,it_remarks) values('08Oct240154','070000165700','45675',(select max(to_number(i.premium_rcv_detail_code))+1 from ins_premium_det i),'45675','45675','02', '11000003','00','Request by Mr. Saqib Saleem 08-Oct-2024 Allocation no 08Oct240154');
A12: KHI/HO/D/MO/PC COMP/C/96746/5/09/2024 | B12: =VLOOKUP(A12,Policy!A:B,2,0) -> 070000165656 | C12: 71400 | D12: =ROUND(C12,0) -> 71400 | E12: 08Oct240154 | F12: ="insert into ins_premium_det (premium_rcv_code,assorted_code, rec_amount,premium_rcv_detail_code,remaining_amt, payrec, mode_code,coinsurance_code,class_cd,it_remarks) values" -> insert into ins_premium_det (premium_rcv_code,assorted_code, rec_amount,premium_rcv_detail_code,remaining_amt, payrec, mode_code,coinsurance_code,class_cd,it_remarks) values | G12: ="('"&E12&"','"&B12&"','"&D12&"',(select max(to_number(i.premium_rcv_detail_code))+1 from ins_premium_det i),'"&D12&"','"&D12&"','02', '11000003','00','Request by Mr. Saqib Saleem 08-Oct-2024 Allocation no 08Oct240154');" -> ('08Oct240154','070000165656','71400',(select max(to_number(i.premium_rcv_detail_code))+1 from ins_premium_det i),'71400','71400','02', '11000003','00','Request by Mr. Saqib Saleem 08-Oct-2024 Allocation no 08Oct240154'); | H12: =F12&G12 -> insert into ins_premium_det (premium_rcv_code,assorted_code, rec_amount,premium_rcv_detail_code,remaining_amt, payrec, mode_code,coinsurance_code,class_cd,it_remarks) values('08Oct240154','070000165656','71400',(select max(to_number(i.premium_rcv_detail_code))+1 from ins_premium_det i),'71400','71400','02', '11000003','00','Request by Mr. Saqib Saleem 08-Oct-2024 Allocation no 08Oct240154');
A13: KHI/HO/D/MO/PC COMP/C/96760/10/09/2024 | B13: =VLOOKUP(A13,Policy!A:B,2,0) -> 070000166131 | C13: 45675 | D13: =ROUND(C13,0) -> 45675 | E13: 08Oct240154 | F13: ="insert into ins_premium_det (premium_rcv_code,assorted_code, rec_amount,premium_rcv_detail_code,remaining_amt, payrec, mode_code,coinsurance_code,class_cd,it_remarks) values" -> insert into ins_premium_det (premium_rcv_code,assorted_code, rec_amount,premium_rcv_detail_code,remaining_amt, payrec, mode_code,coinsurance_code,class_cd,it_remarks) values | G13: ="('"&E13&"','"&B13&"','"&D13&"',(select max(to_number(i.premium_rcv_detail_code))+1 from ins_premium_det i),'"&D13&"','"&D13&"','02', '11000003','00','Request by Mr. Saqib Saleem 08-Oct-2024 Allocation no 08Oct240154');" -> ('08Oct240154','070000166131','45675',(select max(to_number(i.premium_rcv_detail_code))+1 from ins_premium_det i),'45675','45675','02', '11000003','00','Request by Mr. Saqib Saleem 08-Oct-2024 Allocation no 08Oct240154'); | H13: =F13&G13 -> insert into ins_premium_det (premium_rcv_code,assorted_code, rec_amount,premium_rcv_detail_code,remaining_amt, payrec, mode_code,coinsurance_code,class_cd,it_remarks) values('08Oct240154','070000166131','45675',(select max(to_number(i.premium_rcv_detail_code))+1 from ins_premium_det i),'45675','45675','02', '11000003','00','Request by Mr. Saqib Saleem 08-Oct-2024 Allocation no 08Oct240154');
... A25: KHI/HO/D/MO/PC COMP/C/96617/3/09/2024 | B25: =VLOOKUP(A25,Policy!A:B,2,0) -> 070000166158 | C25: 63000 | D25: =ROUND(C25,0) -> 63000 | E25: 08Oct240154 | F25: ="insert into ins_premium_det (premium_rcv_code,assorted_code, rec_amount,premium_rcv_detail_code,remaining_amt, payrec, mode_code,coinsurance_code,class_cd,it_remarks) values" -> insert into ins_premium_det (premium_rcv_code,assorted_code, rec_amount,premium_rcv_detail_code,remaining_amt, payrec, mode_code,coinsurance_code,class_cd,it_remarks) values | G25: ="('"&E25&"','"&B25&"','"&D25&"',(select max(to_number(i.premium_rcv_detail_code))+1 from ins_premium_det i),'"&D25&"','"&D25&"','02', '11000003','00','Request by Mr. Saqib Saleem 08-Oct-2024 Allocation no 08Oct240154');" -> ('08Oct240154','070000166158','63000',(select max(to_number(i.premium_rcv_detail_code))+1 from ins_premium_det i),'63000','63000','02', '11000003','00','Request by Mr. Saqib Saleem 08-Oct-2024 Allocation no 08Oct240154'); | H25: =F25&G25 -> insert into ins_premium_det (premium_rcv_code,assorted_code, rec_amount,premium_rcv_detail_code,remaining_amt, payrec, mode_code,coinsurance_code,class_cd,it_remarks) values('08Oct240154','070000166158','63000',(select max(to_number(i.premium_rcv_detail_code))+1 from ins_premium_det i),'63000','63000','02', '11000003','00','Request by Mr. Saqib Saleem 08-Oct-2024 Allocation no 08Oct240154');
A26: KHI/HO/D/MO/PC COMP/P/94440/06/08/2024 | B26: 070000164914 | C26: 71400 | D26: =ROUND(C26,0) -> 71400 | E26: 08Oct240154 | F26: ="insert into ins_premium_det (premium_rcv_code,assorted_code, rec_amount,premium_rcv_detail_code,remaining_amt, payrec, mode_code,coinsurance_code,class_cd,it_remarks) values" -> insert into ins_premium_det (premium_rcv_code,assorted_code, rec_amount,premium_rcv_detail_code,remaining_amt, payrec, mode_code,coinsurance_code,class_cd,it_remarks) values | G26: ="('"&E26&"','"&B26&"','"&D26&"',(select max(to_number(i.premium_rcv_detail_code))+1 from ins_premium_det i),'"&D26&"','"&D26&"','02', '11000003','00','Request by Mr. Saqib Saleem 08-Oct-2024 Allocation no 08Oct240154');" -> ('08Oct240154','070000164914','71400',(select max(to_number(i.premium_rcv_detail_code))+1 from ins_premium_det i),'71400','71400','02', '11000003','00','Request by Mr. Saqib Saleem 08-Oct-2024 Allocation no 08Oct240154'); | H26: =F26&G26 -> insert into ins_premium_det (premium_rcv_code,assorted_code, rec_amount,premium_rcv_detail_code,remaining_amt, payrec, mode_code,coinsurance_code,class_cd,it_remarks) values('08Oct240154','070000164914','71400',(select max(to_number(i.premium_rcv_detail_code))+1 from ins_premium_det i),'71400','71400','02', '11000003','00','Request by Mr. Saqib Saleem 08-Oct-2024 Allocation no 08Oct240154');
A27: KHI/HO/D/MO/PC COMP/P/94440/05/08/2024 | B27: 070000164905 | C27: 71400 | D27: =ROUND(C27,0) -> 71400 | E27: 08Oct240154 | F27: ="insert into ins_premium_det (premium_rcv_code,assorted_code, rec_amount,premium_rcv_detail_code,remaining_amt, payrec, mode_code,coinsurance_code,class_cd,it_remarks) values" -> insert into ins_premium_det (premium_rcv_code,assorted_code, rec_amount,premium_rcv_detail_code,remaining_amt, payrec, mode_code,coinsurance_code,class_cd,it_remarks) values | G27: ="('"&E27&"','"&B27&"','"&D27&"',(select max(to_number(i.premium_rcv_detail_code))+1 from ins_premium_det i),'"&D27&"','"&D27&"','02', '11000003','00','Request by Mr. Saqib Saleem 08-Oct-2024 Allocation no 08Oct240154');" -> ('08Oct240154','070000164905','71400',(select max(to_number(i.premium_rcv_detail_code))+1 from ins_premium_det i),'71400','71400','02', '11000003','00','Request by Mr. Saqib Saleem 08-Oct-2024 Allocation no 08Oct240154'); | H27: =F27&G27 -> insert into ins_premium_det (premium_rcv_code,assorted_code, rec_amount,premium_rcv_detail_code,remaining_amt, payrec, mode_code,coinsurance_code,class_cd,it_remarks) values('08Oct240154','070000164905','71400',(select max(to_number(i.premium_rcv_detail_code))+1 from ins_premium_det i),'71400','71400','02', '11000003','00','Request by Mr. Saqib Saleem 08-Oct-2024 Allocation no 08Oct240154');
A28: KHI/HO/D/MO/PC COMP/C/96617/2/09/2024 | B28: =VLOOKUP(A28,Policy!A:B,2,0) -> 070000165288 | C28: 70785 | D28: =ROUND(C28,0) -> 70785 | E28: 08Oct240154 | F28: ="insert into ins_premium_det (premium_rcv_code,assorted_code, rec_amount,premium_rcv_detail_code,remaining_amt, payrec, mode_code,coinsurance_code,class_cd,it_remarks) values" -> insert into ins_premium_det (premium_rcv_code,assorted_code, rec_amount,premium_rcv_detail_code,remaining_amt, payrec, mode_code,coinsurance_code,class_cd,it_remarks) values | G28: ="('"&E28&"','"&B28&"','"&D28&"',(select max(to_number(i.premium_rcv_detail_code))+1 from ins_premium_det i),'"&D28&"','"&D28&"','02', '11000003','00','Request by Mr. Saqib Saleem 08-Oct-2024 Allocation no 08Oct240154');" -> ('08Oct240154','070000165288','70785',(select max(to_number(i.premium_rcv_detail_code))+1 from ins_premium_det i),'70785','70785','02', '11000003','00','Request by Mr. Saqib Saleem 08-Oct-2024 Allocation no 08Oct240154'); | H28: =F28&G28 -> insert into ins_premium_det (premium_rcv_code,assorted_code, rec_amount,premium_rcv_detail_code,remaining_amt, payrec, mode_code,coinsurance_code,class_cd,it_remarks) values('08Oct240154','070000165288','70785',(select max(to_number(i.premium_rcv_detail_code))+1 from ins_premium_det i),'70785','70785','02', '11000003','00','Request by Mr. Saqib Saleem 08-Oct-2024 Allocation no 08Oct240154');
A29: KHI/HO/D/MO/PC COMP/C/96876/2/09/2024 | B29: =VLOOKUP(A29,Policy!A:B,2,0) -> 070000165296 | C29: 66000 | D29: =ROUND(C29,0) -> 66000 | E29: 08Oct240154 | F29: ="insert into ins_premium_det (premium_rcv_code,assorted_code, rec_amount,premium_rcv_detail_code,remaining_amt, payrec, mode_code,coinsurance_code,class_cd,it_remarks) values" -> insert into ins_premium_det (premium_rcv_code,assorted_code, rec_amount,premium_rcv_detail_code,remaining_amt, payrec, mode_code,coinsurance_code,class_cd,it_remarks) values | G29: ="('"&E29&"','"&B29&"','"&D29&"',(select max(to_number(i.premium_rcv_detail_code))+1 from ins_premium_det i),'"&D29&"','"&D29&"','02', '11000003','00','Request by Mr. Saqib Saleem 08-Oct-2024 Allocation no 08Oct240154');" -> ('08Oct240154','070000165296','66000',(select max(to_number(i.premium_rcv_detail_code))+1 from ins_premium_det i),'66000','66000','02', '11000003','00','Request by Mr. Saqib Saleem 08-Oct-2024 Allocation no 08Oct240154'); | H29: =F29&G29 -> insert into ins_premium_det (premium_rcv_code,assorted_code, rec_amount,premium_rcv_detail_code,remaining_amt, payrec, mode_code,coinsurance_code,class_cd,it_remarks) values('08Oct240154','070000165296','66000',(select max(to_number(i.premium_rcv_detail_code))+1 from ins_premium_det i),'66000','66000','02', '11000003','00','Request by Mr. Saqib Saleem 08-Oct-2024 Allocation no 08Oct240154');
A30: KHI/HO/D/MO/PC COMP/P/97564/09/2024 | B30: =VLOOKUP(A30,Policy!A:B,2,0) -> 040000184290 | C30: 299895 | D30: =ROUND(C30,0) -> 299895 | E30: 08Oct240154 | F30: ="insert into ins_premium_det (premium_rcv_code,assorted_code, rec_amount,premium_rcv_detail_code,remaining_amt, payrec, mode_code,coinsurance_code,class_cd,it_remarks) values" -> insert into ins_premium_det (premium_rcv_code,assorted_code, rec_amount,premium_rcv_detail_code,remaining_amt, payrec, mode_code,coinsurance_code,class_cd,it_remarks) values | G30: ="('"&E30&"','"&B30&"','"&D30&"',(select max(to_number(i.premium_rcv_detail_code))+1 from ins_premium_det i),'"&D30&"','"&D30&"','02', '11000003','00','Request by Mr. Saqib Saleem 08-Oct-2024 Allocation no 08Oct240154');" -> ('08Oct240154','040000184290','299895',(select max(to_number(i.premium_rcv_detail_code))+1 from ins_premium_det i),'299895','299895','02', '11000003','00','Request by Mr. Saqib Saleem 08-Oct-2024 Allocation no 08Oct240154'); | H30: =F30&G30 -> insert into ins_premium_det (premium_rcv_code,assorted_code, rec_amount,premium_rcv_detail_code,remaining_amt, payrec, mode_code,coinsurance_code,class_cd,it_remarks) values('08Oct240154','040000184290','299895',(select max(to_number(i.premium_rcv_detail_code))+1 from ins_premium_det i),'299895','299895','02', '11000003','00','Request by Mr. Saqib Saleem 08-Oct-2024 Allocation no 08Oct240154');
A31: KHI/HO/D/MO/PC COMP/C/96876/3/09/2024 | B31: =VLOOKUP(A31,Policy!A:B,2,0) -> 070000165441 | C31: 71400 | D31: =ROUND(C31,0) -> 71400 | E31: 08Oct240154 | F31: ="insert into ins_premium_det (premium_rcv_code,assorted_code, rec_amount,premium_rcv_detail_code,remaining_amt, payrec, mode_code,coinsurance_code,class_cd,it_remarks) values" -> insert into ins_premium_det (premium_rcv_code,assorted_code, rec_amount,premium_rcv_detail_code,remaining_amt, payrec, mode_code,coinsurance_code,class_cd,it_remarks) values | G31: ="('"&E31&"','"&B31&"','"&D31&"',(select max(to_number(i.premium_rcv_detail_code))+1 from ins_premium_det i),'"&D31&"','"&D31&"','02', '11000003','00','Request by Mr. Saqib Saleem 08-Oct-2024 Allocation no 08Oct240154');" -> ('08Oct240154','070000165441','71400',(select max(to_number(i.premium_rcv_detail_code))+1 from ins_premium_det i),'71400','71400','02', '11000003','00','Request by Mr. Saqib Saleem 08-Oct-2024 Allocation no 08Oct240154'); | H31: =F31&G31 -> insert into ins_premium_det (premium_rcv_code,assorted_code, rec_amount,premium_rcv_detail_code,remaining_amt, payrec, mode_code,coinsurance_code,class_cd,it_remarks) values('08Oct240154','070000165441','71400',(select max(to_number(i.premium_rcv_detail_code))+1 from ins_premium_det i),'71400','71400','02', '11000003','00','Request by Mr. Saqib Saleem 08-Oct-2024 Allocation no 08Oct240154');
A32: KHI/HO/D/MO/PC COMP/C/96876/1/09/2024 | B32: =VLOOKUP(A32,Policy!A:B,2,0) -> 070000165292 | C32: 70785 | D32: =ROUND(C32,0) -> 70785 | E32: 08Oct240154 | F32: ="insert into ins_premium_det (premium_rcv_code,assorted_code, rec_amount,premium_rcv_detail_code,remaining_amt, payrec, mode_code,coinsurance_code,class_cd,it_remarks) values" -> insert into ins_premium_det (premium_rcv_code,assorted_code, rec_amount,premium_rcv_detail_code,remaining_amt, payrec, mode_code,coinsurance_code,class_cd,it_remarks) values | G32: ="('"&E32&"','"&B32&"','"&D32&"',(select max(to_number(i.premium_rcv_detail_code))+1 from ins_premium_det i),'"&D32&"','"&D32&"','02', '11000003','00','Request by Mr. Saqib Saleem 08-Oct-2024 Allocation no 08Oct240154');" -> ('08Oct240154','070000165292','70785',(select max(to_number(i.premium_rcv_detail_code))+1 from ins_premium_det i),'70785','70785','02', '11000003','00','Request by Mr. Saqib Saleem 08-Oct-2024 Allocation no 08Oct240154'); | H32: =F32&G32 -> insert into ins_premium_det (premium_rcv_code,assorted_code, rec_amount,premium_rcv_detail_code,remaining_amt, payrec, mode_code,coinsurance_code,class_cd,it_remarks) values('08Oct240154','070000165292','70785',(select max(to_number(i.premium_rcv_detail_code))+1 from ins_premium_det i),'70785','70785','02', '11000003','00','Request by Mr. Saqib Saleem 08-Oct-2024 Allocation no 08Oct240154');
A33: KHI/HO/D/MO/PC COMP/P/94836/02/08/2024 | B33: 070000164934 | C33: 61500 | D33: =ROUND(C33,0) -> 61500 | E33: 08Oct240154 | F33: ="insert into ins_premium_det (premium_rcv_code,assorted_code, rec_amount,premium_rcv_detail_code,remaining_amt, payrec, mode_code,coinsurance_code,class_cd,it_remarks) values" -> insert into ins_premium_det (premium_rcv_code,assorted_code, rec_amount,premium_rcv_detail_code,remaining_amt, payrec, mode_code,coinsurance_code,class_cd,it_remarks) values | G33: ="('"&E33&"','"&B33&"','"&D33&"',(select max(to_number(i.premium_rcv_detail_code))+1 from ins_premium_det i),'"&D33&"','"&D33&"','02', '11000003','00','Request by Mr. Saqib Saleem 08-Oct-2024 Allocation no 08Oct240154');" -> ('08Oct240154','070000164934','61500',(select max(to_number(i.premium_rcv_detail_code))+1 from ins_premium_det i),'61500','61500','02', '11000003','00','Request by Mr. Saqib Saleem 08-Oct-2024 Allocation no 08Oct240154'); | H33: =F33&G33 -> insert into ins_premium_det (premium_rcv_code,assorted_code, rec_amount,premium_rcv_detail_code,remaining_amt, payrec, mode_code,coinsurance_code,class_cd,it_remarks) values('08Oct240154','070000164934','61500',(select max(to_number(i.premium_rcv_detail_code))+1 from ins_premium_det i),'61500','61500','02', '11000003','00','Request by Mr. Saqib Saleem 08-Oct-2024 Allocation no 08Oct240154');
A34: KHI/HO/D/MO/PC COMP/C/96627/4/09/2024 | B34: =VLOOKUP(A34,Policy!A:B,2,0) -> 070000165515 | C34: 61125 | D34: =ROUND(C34,0) -> 61125 | E34: 08Oct240154 | F34: ="insert into ins_premium_det (premium_rcv_code,assorted_code, rec_amount,premium_rcv_detail_code,remaining_amt, payrec, mode_code,coinsurance_code,class_cd,it_remarks) values" -> insert into ins_premium_det (premium_rcv_code,assorted_code, rec_amount,premium_rcv_detail_code,remaining_amt, payrec, mode_code,coinsurance_code,class_cd,it_remarks) values | G34: ="('"&E34&"','"&B34&"','"&D34&"',(select max(to_number(i.premium_rcv_detail_code))+1 from ins_premium_det i),'"&D34&"','"&D34&"','02', '11000003','00','Request by Mr. Saqib Saleem 08-Oct-2024 Allocation no 08Oct240154');" -> ('08Oct240154','070000165515','61125',(select max(to_number(i.premium_rcv_detail_code))+1 from ins_premium_det i),'61125','61125','02', '11000003','00','Request by Mr. Saqib Saleem 08-Oct-2024 Allocation no 08Oct240154'); | H34: =F34&G34 -> insert into ins_premium_det (premium_rcv_code,assorted_code, rec_amount,premium_rcv_detail_code,remaining_amt, payrec, mode_code,coinsurance_code,class_cd,it_remarks) values('08Oct240154','070000165515','61125',(select max(to_number(i.premium_rcv_detail_code))+1 from ins_premium_det i),'61125','61125','02', '11000003','00','Request by Mr. Saqib Saleem 08-Oct-2024 Allocation no 08Oct240154');
A35: KHI/HO/D/MO/PC COMP/C/96627/5/09/2024 | B35: =VLOOKUP(A35,Policy!A:B,2,0) -> 070000165576 | C35: 42600 | D35: =ROUND(C35,0) -> 42600 | E35: 08Oct240154 | F35: ="insert into ins_premium_det (premium_rcv_code,assorted_code, rec_amount,premium_rcv_detail_code,remaining_amt, payrec, mode_code,coinsurance_code,class_cd,it_remarks) values" -> insert into ins_premium_det (premium_rcv_code,assorted_code, rec_amount,premium_rcv_detail_code,remaining_amt, payrec, mode_code,coinsurance_code,class_cd,it_remarks) values | G35: ="('"&E35&"','"&B35&"','"&D35&"',(select max(to_number(i.premium_rcv_detail_code))+1 from ins_premium_det i),'"&D35&"','"&D35&"','02', '11000003','00','Request by Mr. Saqib Saleem 08-Oct-2024 Allocation no 08Oct240154');" -> ('08Oct240154','070000165576','42600',(select max(to_number(i.premium_rcv_detail_code))+1 from ins_premium_det i),'42600','42600','02', '11000003','00','Request by Mr. Saqib Saleem 08-Oct-2024 Allocation no 08Oct240154'); | H35: =F35&G35 -> insert into ins_premium_det (premium_rcv_code,assorted_code, rec_amount,premium_rcv_detail_code,remaining_amt, payrec, mode_code,coinsurance_code,class_cd,it_remarks) values('08Oct240154','070000165576','42600',(select max(to_number(i.premium_rcv_detail_code))+1 from ins_premium_det i),'42600','42600','02', '11000003','00','Request by Mr. Saqib Saleem 08-Oct-2024 Allocation no 08Oct240154');
A36: KHI/HO/D/MO/PC COMP/C/96627/2/09/2024 | B36: =VLOOKUP(A36,Policy!A:B,2,0) -> 070000165272 | C36: 70785 | D36: =ROUND(C36,0) -> 70785 | E36: 08Oct240154 | F36: ="insert into ins_premium_det (premium_rcv_code,assorted_code, rec_amount,premium_rcv_detail_code,remaining_amt, payrec, mode_code,coinsurance_code,class_cd,it_remarks) values" -> insert into ins_premium_det (premium_rcv_code,assorted_code, rec_amount,premium_rcv_detail_code,remaining_amt, payrec, mode_code,coinsurance_code,class_cd,it_remarks) values | G36: ="('"&E36&"','"&B36&"','"&D36&"',(select max(to_number(i.premium_rcv_detail_code))+1 from ins_premium_det i),'"&D36&"','"&D36&"','02', '11000003','00','Request by Mr. Saqib Saleem 08-Oct-2024 Allocation no 08Oct240154');" -> ('08Oct240154','070000165272','70785',(select max(to_number(i.premium_rcv_detail_code))+1 from ins_premium_det i),'70785','70785','02', '11000003','00','Request by Mr. Saqib Saleem 08-Oct-2024 Allocation no 08Oct240154'); | H36: =F36&G36 -> insert into ins_premium_det (premium_rcv_code,assorted_code, rec_amount,premium_rcv_detail_code,remaining_amt, payrec, mode_code,coinsurance_code,class_cd,it_remarks) values('08Oct240154','070000165272','70785',(select max(to_number(i.premium_rcv_detail_code))+1 from ins_premium_det i),'70785','70785','02', '11000003','00','Request by Mr. Saqib Saleem 08-Oct-2024 Allocation no 08Oct240154');
A37: KHI/HO/D/MO/PC COMP/C/96627/7/09/2024 | B37: =VLOOKUP(A37,Policy!A:B,2,0) -> 070000165762 | C37: 42000 | D37: =ROUND(C37,0) -> 42000 | E37: 08Oct240154 | F37: ="insert into ins_premium_det (premium_rcv_code,assorted_code, rec_amount,premium_rcv_detail_code,remaining_amt, payrec, mode_code,coinsurance_code,class_cd,it_remarks) values" -> insert into ins_premium_det (premium_rcv_code,assorted_code, rec_amount,premium_rcv_detail_code,remaining_amt, payrec, mode_code,coinsurance_code,class_cd,it_remarks) values | G37: ="('"&E37&"','"&B37&"','"&D37&"',(select max(to_number(i.premium_rcv_detail_code))+1 from ins_premium_det i),'"&D37&"','"&D37&"','02', '11000003','00','Request by Mr. Saqib Saleem 08-Oct-2024 Allocation no 08Oct240154');" -> ('08Oct240154','070000165762','42000',(select max(to_number(i.premium_rcv_detail_code))+1 from ins_premium_det i),'42000','42000','02', '11000003','00','Request by Mr. Saqib Saleem 08-Oct-2024 Allocation no 08Oct240154'); | H37: =F37&G37 -> insert into ins_premium_det (premium_rcv_code,assorted_code, rec_amount,premium_rcv_detail_code,remaining_amt, payrec, mode_code,coinsurance_code,class_cd,it_remarks) values('08Oct240154','070000165762','42000',(select max(to_number(i.premium_rcv_detail_code))+1 from ins_premium_det i),'42000','42000','02', '11000003','00','Request by Mr. Saqib Saleem 08-Oct-2024 Allocation no 08Oct240154');
A38: KHI/HO/D/MO/PC COMP/C/96627/1/09/2024 | B38: =VLOOKUP(A38,Policy!A:B,2,0) -> 070000165000 | C38: 131235 | D38: =ROUND(C38,0) -> 131235 | E38: 08Oct240154 | F38: ="insert into ins_premium_det (premium_rcv_code,assorted_code, rec_amount,premium_rcv_detail_code,remaining_amt, payrec, mode_code,coinsurance_code,class_cd,it_remarks) values" -> insert into ins_premium_det (premium_rcv_code,assorted_code, rec_amount,premium_rcv_detail_code,remaining_amt, payrec, mode_code,coinsurance_code,class_cd,it_remarks) values | G38: ="('"&E38&"','"&B38&"','"&D38&"',(select max(to_number(i.premium_rcv_detail_code))+1 from ins_premium_det i),'"&D38&"','"&D38&"','02', '11000003','00','Request by Mr. Saqib Saleem 08-Oct-2024 Allocation no 08Oct240154');" -> ('08Oct240154','070000165000','131235',(select max(to_number(i.premium_rcv_detail_code))+1 from ins_premium_det i),'131235','131235','02', '11000003','00','Request by Mr. Saqib Saleem 08-Oct-2024 Allocation no 08Oct240154'); | H38: =F38&G38 -> insert into ins_premium_det (premium_rcv_code,assorted_code, rec_amount,premium_rcv_detail_code,remaining_amt, payrec, mode_code,coinsurance_code,class_cd,it_remarks) values('08Oct240154','070000165000','131235',(select max(to_number(i.premium_rcv_detail_code))+1 from ins_premium_det i),'131235','131235','02', '11000003','00','Request by Mr. Saqib Saleem 08-Oct-2024 Allocation no 08Oct240154');
A39: KHI/HO/D/MO/PC COMP/C/96627/6/09/2024 | B39: =VLOOKUP(A39,Policy!A:B,2,0) -> 070000165701 | C39: 56250 | D39: =ROUND(C39,0) -> 56250 | E39: 08Oct240154 | F39: ="insert into ins_premium_det (premium_rcv_code,assorted_code, rec_amount,premium_rcv_detail_code,remaining_amt, payrec, mode_code,coinsurance_code,class_cd,it_remarks) values" -> insert into ins_premium_det (premium_rcv_code,assorted_code, rec_amount,premium_rcv_detail_code,remaining_amt, payrec, mode_code,coinsurance_code,class_cd,it_remarks) values | G39: ="('"&E39&"','"&B39&"','"&D39&"',(select max(to_number(i.premium_rcv_detail_code))+1 from ins_premium_det i),'"&D39&"','"&D39&"','02', '11000003','00','Request by Mr. Saqib Saleem 08-Oct-2024 Allocation no 08Oct240154');" -> ('08Oct240154','070000165701','56250',(select max(to_number(i.premium_rcv_detail_code))+1 from ins_premium_det i),'56250','56250','02', '11000003','00','Request by Mr. Saqib Saleem 08-Oct-2024 Allocation no 08Oct240154'); | H39: =F39&G39 -> insert into ins_premium_det (premium_rcv_code,assorted_code, rec_amount,premium_rcv_detail_code,remaining_amt, payrec, mode_code,coinsurance_code,class_cd,it_remarks) values('08Oct240154','070000165701','56250',(select max(to_number(i.premium_rcv_detail_code))+1 from ins_premium_det i),'56250','56250','02', '11000003','00','Request by Mr. Saqib Saleem 08-Oct-2024 Allocation no 08Oct240154');
A40: KHI/HO/D/MO/PC COMP/C/96627/3/09/2024 | B40: =VLOOKUP(A40,Policy!A:B,2,0) -> 070000165290 | C40: 75000 | D40: =ROUND(C40,0) -> 75000 | E40: 08Oct240154 | F40: ="insert into ins_premium_det (premium_rcv_code,assorted_code, rec_amount,premium_rcv_detail_code,remaining_amt, payrec, mode_code,coinsurance_code,class_cd,it_remarks) values" -> insert into ins_premium_det (premium_rcv_code,assorted_code, rec_amount,premium_rcv_detail_code,remaining_amt, payrec, mode_code,coinsurance_code,class_cd,it_remarks) values | G40: ="('"&E40&"','"&B40&"','"&D40&"',(select max(to_number(i.premium_rcv_detail_code))+1 from ins_premium_det i),'"&D40&"','"&D40&"','02', '11000003','00','Request by Mr. Saqib Saleem 08-Oct-2024 Allocation no 08Oct240154');" -> ('08Oct240154','070000165290','75000',(select max(to_number(i.premium_rcv_detail_code))+1 from ins_premium_det i),'75000','75000','02', '11000003','00','Request by Mr. Saqib Saleem 08-Oct-2024 Allocation no 08Oct240154'); | H40: =F40&G40 -> insert into ins_premium_det (premium_rcv_code,assorted_code, rec_amount,premium_rcv_detail_code,remaining_amt, payrec, mode_code,coinsurance_code,class_cd,it_remarks) values('08Oct240154','070000165290','75000',(select max(to_number(i.premium_rcv_detail_code))+1 from ins_premium_det i),'75000','75000','02', '11000003','00','Request by Mr. Saqib Saleem 08-Oct-2024 Allocation no 08Oct240154');
A41: KHI/HO/D/MO/PC COMP/C/96627/8/09/2024 | B41: =VLOOKUP(A41,Policy!A:B,2,0) -> 070000166581 | C41: 88185 | D41: =ROUND(C41,0) -> 88185 | E41: 08Oct240154 | F41: ="insert into ins_premium_det (premium_rcv_code,assorted_code, rec_amount,premium_rcv_detail_code,remaining_amt, payrec, mode_code,coinsurance_code,class_cd,it_remarks) values" -> insert into ins_premium_det (premium_rcv_code,assorted_code, rec_amount,premium_rcv_detail_code,remaining_amt, payrec, mode_code,coinsurance_code,class_cd,it_remarks) values | G41: ="('"&E41&"','"&B41&"','"&D41&"',(select max(to_number(i.premium_rcv_detail_code))+1 from ins_premium_det i),'"&D41&"','"&D41&"','02', '11000003','00','Request by Mr. Saqib Saleem 08-Oct-2024 Allocation no 08Oct240154');" -> ('08Oct240154','070000166581','88185',(select max(to_number(i.premium_rcv_detail_code))+1 from ins_premium_det i),'88185','88185','02', '11000003','00','Request by Mr. Saqib Saleem 08-Oct-2024 Allocation no 08Oct240154'); | H41: =F41&G41 -> insert into ins_premium_det (premium_rcv_code,assorted_code, rec_amount,premium_rcv_detail_code,remaining_amt, payrec, mode_code,coinsurance_code,class_cd,it_remarks) values('08Oct240154','070000166581','88185',(select max(to_number(i.premium_rcv_detail_code))+1 from ins_premium_det i),'88185','88185','02', '11000003','00','Request by Mr. Saqib Saleem 08-Oct-2024 Allocation no 08Oct240154');
A42: KHI/HO/D/MO/PC COMP/C/94431/22/08/2024 | B42: =VLOOKUP(A42,Policy!A:B,2,0) -> 070000164951 | C42: 85290 | D42: =ROUND(C42,0) -> 85290 | E42: 08Oct240154 | F42: ="insert into ins_premium_det (premium_rcv_code,assorted_code, rec_amount,premium_rcv_detail_code,remaining_amt, payrec, mode_code,coinsurance_code,class_cd,it_remarks) values" -> insert into ins_premium_det (premium_rcv_code,assorted_code, rec_amount,premium_rcv_detail_code,remaining_amt, payrec, mode_code,coinsurance_code,class_cd,it_remarks) values | G42: ="('"&E42&"','"&B42&"','"&D42&"',(select max(to_number(i.premium_rcv_detail_code))+1 from ins_premium_det i),'"&D42&"','"&D42&"','02', '11000003','00','Request by Mr. Saqib Saleem 08-Oct-2024 Allocation no 08Oct240154');" -> ('08Oct240154','070000164951','85290',(select max(to_number(i.premium_rcv_detail_code))+1 from ins_premium_det i),'85290','85290','02', '11000003','00','Request by Mr. Saqib Saleem 08-Oct-2024 Allocation no 08Oct240154'); | H42: =F42&G42 -> insert into ins_premium_det (premium_rcv_code,assorted_code, rec_amount,premium_rcv_detail_code,remaining_amt, payrec, mode_code,coinsurance_code,class_cd,it_remarks) values('08Oct240154','070000164951','85290',(select max(to_number(i.premium_rcv_detail_code))+1 from ins_premium_det i),'85290','85290','02', '11000003','00','Request by Mr. Saqib Saleem 08-Oct-2024 Allocation no 08Oct240154');
A43: KHI/HO/D/MO/PC COMP/C/96772/3/09/2024 | B43: =VLOOKUP(A43,Policy!A:B,2,0) -> 070000165393 | C43: 63000 | D43: =ROUND(C43,0) -> 63000 | E43: 08Oct240154 | F43: ="insert into ins_premium_det (premium_rcv_code,assorted_code, rec_amount,premium_rcv_detail_code,remaining_amt, payrec, mode_code,coinsurance_code,class_cd,it_remarks) values" -> insert into ins_premium_det (premium_rcv_code,assorted_code, rec_amount,premium_rcv_detail_code,remaining_amt, payrec, mode_code,coinsurance_code,class_cd,it_remarks) values | G43: ="('"&E43&"','"&B43&"','"&D43&"',(select max(to_number(i.premium_rcv_detail_code))+1 from ins_premium_det i),'"&D43&"','"&D43&"','02', '11000003','00','Request by Mr. Saqib Saleem 08-Oct-2024 Allocation no 08Oct240154');" -> ('08Oct240154','070000165393','63000',(select max(to_number(i.premium_rcv_detail_code))+1 from ins_premium_det i),'63000','63000','02', '11000003','00','Request by Mr. Saqib Saleem 08-Oct-2024 Allocation no 08Oct240154'); | H43: =F43&G43 -> insert into ins_premium_det (premium_rcv_code,assorted_code, rec_amount,premium_rcv_detail_code,remaining_amt, payrec, mode_code,coinsurance_code,class_cd,it_remarks) values('08Oct240154','070000165393','63000',(select max(to_number(i.premium_rcv_detail_code))+1 from ins_premium_det i),'63000','63000','02', '11000003','00','Request by Mr. Saqib Saleem 08-Oct-2024 Allocation no 08Oct240154');
A44: KHI/HO/D/MO/PC COMP/C/96598/4/09/2024 | B44: =VLOOKUP(A44,Policy!A:B,2,0) -> 070000165776 | C44: 70785 | D44: =ROUND(C44,0) -> 70785 | E44: 08Oct240154 | F44: ="insert into ins_premium_det (premium_rcv_code,assorted_code, rec_amount,premium_rcv_detail_code,remaining_amt, payrec, mode_code,coinsurance_code,class_cd,it_remarks) values" -> insert into ins_premium_det (premium_rcv_code,assorted_code, rec_amount,premium_rcv_detail_code,remaining_amt, payrec, mode_code,coinsurance_code,class_cd,it_remarks) values | G44: ="('"&E44&"','"&B44&"','"&D44&"',(select max(to_number(i.premium_rcv_detail_code))+1 from ins_premium_det i),'"&D44&"','"&D44&"','02', '11000003','00','Request by Mr. Saqib Saleem 08-Oct-2024 Allocation no 08Oct240154');" -> ('08Oct240154','070000165776','70785',(select max(to_number(i.premium_rcv_detail_code))+1 from ins_premium_det i),'70785','70785','02', '11000003','00','Request by Mr. Saqib Saleem 08-Oct-2024 Allocation no 08Oct240154'); | H44: =F44&G44 -> insert into ins_premium_det (premium_rcv_code,assorted_code, rec_amount,premium_rcv_detail_code,remaining_amt, payrec, mode_code,coinsurance_code,class_cd,it_remarks) values('08Oct240154','070000165776','70785',(select max(to_number(i.premium_rcv_detail_code))+1 from ins_premium_det i),'70785','70785','02', '11000003','00','Request by Mr. Saqib Saleem 08-Oct-2024 Allocation no 08Oct240154');
A45: KHI/HO/D/MO/PC COMP/C/96598/3/09/2024 | B45: =VLOOKUP(A45,Policy!A:B,2,0) -> 070000165479 | C45: 70785 | D45: =ROUND(C45,0) -> 70785 | E45: 08Oct240154 | F45: ="insert into ins_premium_det (premium_rcv_code,assorted_code, rec_amount,premium_rcv_detail_code,remaining_amt, payrec, mode_code,coinsurance_code,class_cd,it_remarks) values" -> insert into ins_premium_det (premium_rcv_code,assorted_code, rec_amount,premium_rcv_detail_code,remaining_amt, payrec, mode_code,coinsurance_code,class_cd,it_remarks) values | G45: ="('"&E45&"','"&B45&"','"&D45&"',(select max(to_number(i.premium_rcv_detail_code))+1 from ins_premium_det i),'"&D45&"','"&D45&"','02', '11000003','00','Request by Mr. Saqib Saleem 08-Oct-2024 Allocation no 08Oct240154');" -> ('08Oct240154','070000165479','70785',(select max(to_number(i.premium_rcv_detail_code))+1 from ins_premium_det i),'70785','70785','02', '11000003','00','Request by Mr. Saqib Saleem 08-Oct-2024 Allocation no 08Oct240154'); | H45: =F45&G45 -> insert into ins_premium_det (premium_rcv_code,assorted_code, rec_amount,premium_rcv_detail_code,remaining_amt, payrec, mode_code,coinsurance_code,class_cd,it_remarks) values('08Oct240154','070000165479','70785',(select max(to_number(i.premium_rcv_detail_code))+1 from ins_premium_det i),'70785','70785','02', '11000003','00','Request by Mr. Saqib Saleem 08-Oct-2024 Allocation no 08Oct240154');
