Workbook

Sheet T-PAK
A1: Sr. | B1: Status | C1: Contract No. | D1: Contract Status | E1: Insurance Agency | F1: Customer Name | G1: City | H1: CNIC No. | I1: Home Phone# | J1: Mobile Number | K1: Business Phone# | L1: Mail Address | M1: Finance Amount | N1: Car Price | O1: Ins. Policy | P1: Ins. Expiry Date | Q1: Engine No. | R1: Chassis No. | S1: Car Category | T1: Reg. No. | U1: Car Name | V1: Model | W1: Contract Booking Date | X1: Contract Value Date | Y1: Contract Maturity Date | Z1: Purchase Order No. | AA1: Tenor#2 | AB1: Tracker Company | AC1: Tracker Reference Number | AD1: Tracker Installation Date | AE1: Insurance Rate | AF1: Sum Insured | AG1: Premium | AH1: Policy No. | AI1: TMS Premium | AJ1: Difference Amount | AK1: Endorsement No
A2: 1 | B2: NORM | C2: 9976AD2223640004 | D2: A | E2: T-PAK | F2: SAJJAD AHMED BAJWA | G2: Faisalabad | H2: 34501-2003546-9 | I2: 03017044648 | J2: 03017044648, 03017044648 | K2: 03017044648 | L2: P-465 E MILLAT TOWN MILLAT ROAD FSD NEAR ISMAIL GREEN VALLEY FAISALABAD PK | M2: 2800800 | N2: 6224000 | O2: 66406/0001/01/2023 | P2: 45689 | Q2: 1001261 | R2: 001297 | S2: NEW | U2: HONDA HR-V | V2: 2022 | W2: 44925 | X2: 11-JAN-2023 | Y2: 46033 | Z2: OLAFSD300091428 | AA2: 3 | AB2: FLCN | AC2: 109045/01/2023 | AD2: 44986 | AE2: 2% | AF2: 5290400 | AG2: 105808 | AH2: KHI/HO/D/MO/PC COMP/C/106590/4/01/2025 | AI2: 105808 | AJ2: 0
A3: 2 | B3: NORM | C3: 9976AP1220070001 | D3: A | E3: T-PAK | F3: TALHA AHMED KHAN | G3: Karachi | H3: 42201-4657682-7 | J3: 03362807093 | L3: HOUSE NO 90/1 20TH STREET KHAYBAN-E-RAHAT DHA PHASE 6 KARACHI | M3: 2380000 | N3: 3500000 | O3: 57872/00002/01/2022 | P3: 45717 | Q3: 12938588 | R3: R042010 | S3: USD | T3: BNC-303 | U3: HONDA CIVIC IVTEC | V3: 2018 | W3: 44743 | X3: 11-JAN-2022 | Y3: 46398 | Z3: OLUKHI300082915 | AA3: 5 | AB3: ITECL | AC3: 6069/01/2022 | AD3: 44682 | AE3: 1.5% | AF3: 2800000 | AG3: 42000 | AH3: KHI/HO/D/MO/PC COMP/C/106590/11/01/2025 | AI3: 42000 | AJ3: 0
A4: 3 | B4: NORM | C4: 9976AP1213650144 | D4: A | E4: T-PAK | F4: SHAIKH TALHA SAEED | G4: Karachi | H4: 42201-4531523-7 | J4: 03469099000 | L4: SHOP NO 3 AND 7 MOON ELECTRONICE MARKET, HING COURT ABDULLAH HAROON RD KHI | M4: 1519000 | N4: 2170000 | O4: 57132/00348/12/2021 | P4: 45717 | Q4: KP-701552 | R4: 216461 | S4: USD | U4: KIA PICANTO 1.0 L A/T | W4: 44561 | X4: 03-JAN-2022 | Y4: 46025 | Z4: OLUKHI300082782 | AA4: 4 | AB4: CTRK | AC4: DIB0033015 | AD4: 44561 | AE4: 1.5% | AF4: 1736000 | AG4: 26040 | AH4: KHI/HO/D/MO/PC COMP/C/106590/14/01/2025 | AI4: 26040 | AJ4: 0
A5: 4 | B5: NORM | C5: 9976AP1230060006 | D5: A | E5: T-PAK | F5: MUHAMMAD TAYYAB | G5: Karachi | H5: 54201-2441034-9 | I5: 34026311 | J5: 03212448229 | K5: 32465625 | L5: AL TIJJAR LOGISTICS HOUSE NO A-181 BLOCK 13 GULISTAN-E-JOHAR NEAR JOHAR CHOWRANGI KARACHI | M5: 2992000 | N5: 6800000 | O5: 66406/00008/01/2023 | P5: 45717 | Q5: 177158 | R5: 206550 | S5: USD | T5: BK-3294 | U5: HYUNDAI TUCSON FWD | V5: 2022 | W5: 45078 | X5: 11-JAN-2023 | Y5: 46033 | Z5: OLUKHI300091530 | AA5: 3 | AB5: ITFM | AC5: 9742/01/2023/ITFM | AD5: 45047 | AE5: 1.75% | AF5: 5780000 | AG5: 101150 | AH5: KHI/HO/D/MO/PC COMP/C/106590/15/01/2025 | AI5: 101150 | AJ5: 0
A6: 5 | B6: NORM | C6: 9976AD1223340010 | D6: A | E6: T-PAK | F6: WAJID ZAKIR | G6: Islamabad | H6: 82303-6957909-3 | J6: 03138586926 | K6: 0512201256 | L6: DANISH ENTERPRISES SHOP NO 4 ZAKIA PLAZA NEAR CHINA CHOWK FAZAL E HAQ ROAD BLUE AREA ISLAMABAD | M6: 1284400 | N6: 1976000 | O6: 66406/00005/01/2023 | P6: 45717 | Q6: 269085 | R6: 169037 | S6: NEW | U6: SUZUKI ALTO VXR EURO-II | V6: 2022 | W6: 44895 | X6: 11-JAN-2023 | Y6: 46763 | Z6: OLAISD300091055 | AA6: 5 | AB6: FLCN | AC6: 109047/01/2023 | AD6: 45017 | AE6: 2% | AF6: 1679600 | AG6: 33592 | AH6: KHI/HO/D/MO/PC COMP/C/106590/19/01/2025 | AI6: 33592 | AJ6: 0
A7: 6 | B7: NORM | C7: 9976AD2220900019 | D7: A | E7: T-PAK | F7: HIRA KHISAL | G7: Karachi | H7: 42101-0150581-8 | J7: 03343673345 | K7: 34912807 | L7: CLARITY BIOSCIENCES OFFICE 405 NAFEES ARCADE SC-14 CHANDNI CHOWK OPP OLD SABZI MANDI UNI ROAD KHI | M7: 1222900 | N7: 1747000 | O7: 66406/00004/01/2023 | P7: 45717 | Q7: 257467 | R7: 1157429 | S7: NEW | U7: SUZUKI ALTO VXL AGS EURO II | V7: 2022 | W7: 44651 | X7: 11-JAN-2023 | Y7: 46763 | Z7: OLAKHI300086247 | AA7: 5 | AB7: ITECL | AC7: 9657/12/2022 | AD7: 44911 | AE7: 2% | AF7: 1484950 | AG7: 29699 | AH7: KHI/HO/D/MO/PC COMP/C/106590/20/01/2025 | AI7: 29699 | AJ7: 0
A8: 7 | B8: NORM | C8: 9976AD1220900022 | D8: A | E8: T-PAK | F8: MUHAMMAD ARSLAN | G8: Karachi | H8: 13302-6125172-3 | J8: 03450011443 | L8: A-45 BLK C, GULISTAN-E-JAMAL KARACHI | M8: 2755200 | N8: 3936000 | O8: 66406/00007/01/2023 | P8: 45717 | Q8: Q102752 | R8: 6080227 | S8: NEW | U8: TOYOTA COROLLA ALTIS A/T S/R | V8: 2022 | W8: 44651 | X8: 11-JAN-2023 | Y8: 46033 | Z8: OLAKHI300086217 | AA8: 3 | AB8: FLCN | AC8: 108967/12/2022 | AD8: 44918 | AE8: 2% | AF8: 3345600 | AG8: 66912 | AH8: KHI/HO/D/MO/PC COMP/C/106590/21/01/2025 | AI8: 66912 | AJ8: 0
A9: 8 | B9: NORM | C9: 9976AP1230090010 | D9: A | E9: T-PAK | F9: MUKHTAR ABBAS | G9: Islamabad | H9: 61101-3468070-7 | J9: 03335141520 | K9: 051-2614931-32 | L9: HAKIM HOUSE, NEW SHAKRIAL, DAK KHANA KHANA DAK, TEH AND DISTT RWP | M9: 1512000 | N9: 2160000 | O9: 66406/00012/01/2023 | P9: 45748 | Q9: 245580 | R9: 1145561 | S9: USD | T9: AZX-596 | U9: SUZUKI ALTO VXR EURO-II | V9: 2022 | W9: 45170 | X9: 11-JAN-2023 | Y9: 46763 | Z9: OLUISD300091534 | AA9: 5 | AB9: ITFT | AC9: 9744/01/2023/ITFM | AD9: 45047 | AE9: 1.75% | AF9: 1836000 | AG9: 32130 | AH9: KHI/HO/D/MO/PC COMP/C/106590/48/01/2025 | AI9: 32130 | AJ9: 0
A10: 9 | B10: NORM | C10: 9976AD1223650009 | D10: A | E10: T-PAK | F10: USAMA NIZAM | G10: Faisalabad | H10: 33100-7913850-7 | I10: 03336667715 | J10: 03336667715, 03336667715 | K10: 03336667715 | L10: H NO 202 AYESHA BLOCK ABDULLAH GARD ENS CANAL ROAD FSD NEAR JAMIA MASJ FAISALABAD PK | M10: 2444000 | N10: 3760000 | O10: 66406/00013/01/2023 | P10: 45748 | Q10: 1013458 | R10: 113439 | S10: NEW | U10: SUZUKI SWIFT GLX CVT | V10: 2022 | W10: 44926 | X10: 11-JAN-2023 | Y10: 46033 | Z10: OLAFSD300091503 | AA10: 3 | AB10: ITECL | AC10: 9743/01/2023 | AD10: 45047 | AE10: 1.75% | AF10: 3196000 | AG10: 55930 | AH10: KHI/HO/D/MO/PC COMP/C/106590/49/01/2025 | AI10: 55930 | AJ10: 0
A11: 10 | B11: NORM | C11: 9976AD1223290002 | D11: A | E11: T-PAK | F11: MUHAMMAD ALI | G11: Islamabad | H11: 61101-1815849-9 | I11: 03455538334 | K11: 0514863370 | L11: FLATE # 8 BLOCK # 5-A STREET #| 1SE CTOR I-8/1 ISLAMABAD PK | M11: 1086800 | N11: 1976000 | O11: 66406/00010/01/2023 | P11: 45748 | Q11: E267475 | R11: 1167578 | S11: NEW | U11: SUZUKI ALTO VXR EURO-II | V11: 2022 | W11: 44890 | X11: 11-JAN-2023 | Y11: 46763 | Z11: OLAISD300090947 | AA11: 5 | AB11: FLCN | AC11: 109050/01/2023 | AD11: 45047 | AE11: 2% | AF11: 1679600 | AG11: 33592 | AH11: KHI/HO/D/MO/PC COMP/C/106590/53/01/2025 | AI11: 33592 | AJ11: 0
A12: 11 | B12: NORM | C12: 9976AD1223270006 | D12: A | E12: T-PAK | F12: SHEIKH MUHAMMAD ABID | G12: Islamabad | H12: 12101-0989951-7 | I12: 03018550519 | K12: 03018550519 | L12: H # 473 MAIN DOUBLE ROAD I-10/4 ISLAMABAD PK | M12: 1383200 | N12: 1976000 | O12: 66406/00009/01/2023 | P12: 45748 | Q12: 6R267556 | R12: 1167568 | S12: NEW | U12: SUZUKI ALTO VXR EURO-II | V12: 2022 | W12: 44888 | X12: 11-JAN-2023 | Y12: 46763 | Z12: OLAISD300090924 | AA12: 5 | AB12: FLCN | AC12: 109049/01/2023 | AD12: 45047 | AE12: 1.75% | AF12: 1679600 | AG12: 29393 | AH12: KHI/HO/D/MO/PC COMP/C/106590/54/01/2025 | AI12: 29393 | AJ12: 0
A13: 12 | B13: NORM | C13: 9976AP2240050001 | D13: A | E13: T-PAK | F13: MUHAMMAD USMAN | G13: Karachi | H13: 33301-0902233-3 | J13: 03253022800 | L13: AL HAMMAD INTERIORS OFFICE 7 APPLE GARDEN JAMAL UDDIN AFGHANI ROAD BAHADURABAD KARACHI 0307-8228000 | M13: 2562000 | N13: 3660000 | O13: 81032/00001/01/2024 | P13: 45748 | Q13: 17510250 | R13: R223177 | S13: USD | T13: BMT-010 | U13: HONDA CITY I-VTEC | V13: 2018 | W13: 45413 | X13: 11-JAN-2024 | Y13: 46398 | Z13: OLUKHI300098960 | AA13: 3 | AB13: ITFT | AC13: 10701/01/2024/ITFM | AD13: 45017 | AE13: 1.75% | AF13: 3294000 | AG13: 57645 | AH13: KHI/HO/D/MO/PC COMP/C/106590/61/01/2025 | AI13: 57645 | AJ13: 0
A14: 13 | B14: NORM | C14: 997AAD1203050085 | D14: A | E14: T-PAK | F14: GHULAM MURTAZA | G14: Islamabad | H14: 61101-1792198-5 | I14: 3228585196 | K14: 0 | L14: H # 18 ST # 5 SECTOR G-13/3 ISLAMABAD PK | M14: 2446500 | N14: 3495000 | O14: 2524/02288/00001/01/2021 | P14: 45657 | Q14: 4803418 | R14: LR020046 | S14: NEW | U14: BRV-IVTEC-S | V14: 2021 | W14: 44135 | X14: 11-JAN-2021 | Y14: 11-Jan-2026 | Z14: POAISD300059793 | AA14: 5 | AB14: CTRK | AC14: DIB0029295 | AD14: 44202 | AE14: 2% | AF14: 2621250 | AG14: 52425 | AH14: KHI/HO/D/MO/PC COMP/C/103702/12/12/2024 | AI14: 55920 | AJ14: 3495 | AK14: KHI/HO/D/MO/PC COMP/E/52165/00012/02/2025
A15: 14 | B15: NORM | C15: 9976AP1223650042 | D15: A | E15: T-PAK | F15: RANA ARSLAN ZAFAR | G15: Faisalabad | H15: 54401-9696683-3 | I15: 03008317668 | J15: 03008317668, 03008317668 | K15: 03008317668 | L15: CHAK NO 68 RAJPOOT HOUSE SHEIKHUPUR A ROAD ADDA JOHAL FAISALABAD PK | M15: 1330000 | N15: 1900000 | O15: 65483/00055/12/2022 | P15: 45656 | Q15: 118310 | R15: 10018506 | S15: USD | T15: LEC-18-8380 | U15: SUZUKI CULTUS VXL | V15: 2018 | W15: 44926 | X15: 03-JAN-2023 | Y15: 03-Jan-2028 | Z15: OLUFSD300091462 | AA15: 5 | AB15: ITFT | AC15: 9723/12/2022 | AD15: 44926 | AE15: 1.75% | AF15: 1615000 | AG15: 28263 | AH15: KHI/HO/D/MO/PC COMP/C/103702/16/12/2024 | AI15: 29925 | AJ15: 1662 | AK15: KHI/HO/D/MO/PC COMP/E/52165/00016/02/2025
A16: 15 | B16: NORM | C16: 9976AP1223650032 | D16: A | E16: T-PAK | F16: MUHAMMAD WAQAS AKRAM | G16: Faisalabad | H16: 35302-0726893-1 | I16: 03006681096 | J16: 03006681096, 03006681096 | K16: 03006681096 | L16: ST NO 3 HAMAYUN TOWN FSD NEAR MUMTA Z GRAMMAR HIGH SCHOOL FAISALABAD PK | M16: 1190000 | N16: 1700000 | O16: 65483/00058/12/2022 | P16: 45656 | Q16: 173902 | R16: 10073885 | S16: USD | T16: FDA-18-244 | U16: SUZUKI WAGONR VXL | V16: 2018 | W16: 44926 | X16: 03-JAN-2023 | Y16: 03-Jan-2028 | Z16: OLUFSD300091480 | AA16: 5 | AB16: ITECL | AC16: 9727/12/2022 | AD16: 44926 | AE16: 1.75% | AF16: 1445000 | AG16: 25288 | AH16: KHI/HO/D/MO/PC COMP/C/103702/19/12/2024 | AI16: 26775 | AJ16: 1487 | AK16: KHI/HO/D/MO/PC COMP/E/52165/00019/02/2025
A17: 16 | B17: NORM | C17: 9976AP1223650051 | D17: A | E17: T-PAK | F17: SYED ALI MURTAZA ZAIDI | G17: Islamabad | H17: 61101-9788983-3 | J17: 00407497358373 | L17: 48 OLD CRABTREE LANE HP24EX HEMEL HEMPSTEAD UNITED KINGDOM | M17: 3066460 | N17: 4509500 | O17: 65483/00060/12/2022 | P17: 45656 | Q17: 281012895 | R17: 029762 | S17: RDA | U17: HONDA CITY ASPIRE A/T | V17: 2022 | W17: 44926 | X17: 03-JAN-2023 | Y17: 03-Jan-2030 | Z17: OLDISD300091492 | AA17: 7 | AB17: FLCN | AC17: 109038/12/2022 | AD17: 44926 | AE17: 1.4% | AF17: 3833075 | AG17: 53663 | AH17: KHI/HO/D/MO/PC COMP/C/103702/25/12/2024 | AI17: 56820 | AJ17: 3157 | AK17: KHI/HO/D/MO/PC COMP/E/52165/00025/02/2025
A18: 17 | B18: NORM | C18: 9976AD2212510005 | D18: A | E18: T-PAK | F18: MUHAMMAD AFTAB KHAN | G18: Lahore | H18: 35200-1444731-9 | I18: 0300-4303941 | J18: 0300-4303941 0302-8403941 | K18: 04237000234 35218882 | L18: HOUSE NO 551 M BLOCK EXTENSION MODEL TOWN CIVIC CENTRE LAHORE | M18: 934500 | N18: 1335000 | O18: 57872/00011/01/2022 | P18: 45778 | Q18: R204358 | R18: 1104373 | S18: NEW | U18: SUZUKI ALTO VXR EURO II | V18: 2021 | W18: 44417 | X18: 21-JAN-2022 | Y18: 46408 | Z18: OLALHR300073212 | AA18: 5 | AB18: CTRK | AC18: DIB0033057 | AD18: 44713 | AE18: 2% | AF18: 1068000 | AG18: 21360 | AH18: KHI/HO/D/MO/PC COMP/C/106590/71/01/2025 | AI18: 21360 | AJ18: 0
A19: 18 | B19: NORM | C19: 997AAD1193340005 | D19: A | E19: T-PAK | F19: MOHAMMAD AHSAN AKBAR | G19: Karachi | H19: 42101-8221491-3 | I19: 03343898410 | J19: 03343898410 | K19: 02135170768 | L19: HOUSE # B-55 BLOCK C NORTH NAZIMABA D KARACHI | M19: 1299350 | N19: 1999000 | O19: 51671/00002/01/2019 | P19: 45778 | Q19: 168918 | R19: 700649 | S19: NEW | T19: #N/A | U19: KIA PICANTO 1.0 L A/T | V19: 2019 | W19: 43799 | X19: 21-JAN-2020 | Y19: 46408 | Z19: POAKHI300051235 | AA19: 7 | AB19: CTRK | AC19: DIB0028095 | AD19: 43891 | AE19: 2.75% | AF19: 1399300 | AG19: 38481 | AH19: KHI/HO/D/MO/PC COMP/C/106590/72/01/2025 | AI19: 38481 | AJ19: 0
A20: 19 | B20: NORM | C20: 9976AP1220040161 | D20: A | E20: T-PAK | F20: AMRITA VENOZ GILL | G20: Abotabad | H20: 13101-6645750-6 | J20: 03365504525 | K20: 0992403549 | L20: SPRING GILL MONTESSORI SCHOOL JHANGI SYEDIAN ABBOTTABAD | M20: 1885000 | N20: 2900000 | O20: 57132/00347/12/2021 | P20: 45656 | Q20: 530154 | R20: 4156502 | S20: USD | T20: AJT-097 | U20: TOYOTA GLI A/T | V20: 2018 | W20: 44565 | X20: 11-JAN-2022 | Y20: 11-Jan-2027 | Z20: OLUABD300082848 | AA20: 5 | AB20: ITECL | AC20: 6040/12/2021 | AD20: 44561 | AE20: 1.5% | AF20: 2320000 | AG20: 34800 | AH20: KHI/HO/D/MO/PC COMP/C/103702/29/12/2024 | AI20: 36975 | AJ20: 2175 | AK20: KHI/HO/D/MO/PC COMP/E/52165/00029/02/2025
A21: 20 | B21: NORM | C21: 9976AP1203660059 | D21: A | E21: T-PAK | F21: JAMAL ALI MIRZA | G21: Karachi | H21: 42201-2147828-7 | I21: 0333247114 | J21: 03332471114 | K21: 0 | L21: 2602 PIB COLONY JAMAL GENERAL STORE KARACHI PK | M21: 1237500 | N21: 1650000 | O21: 2524/02243/00088/12/2020 | P21: 45656 | Q21: 3B20-LB6651 | R21: 0338389 | S21: RCN | T21: BKS-521 | U21: NISSAN DAYS HIGHWAY STAR | V21: 2016 | W21: 44196 | X21: 03-JAN-2021 | Y21: 03-Jan-2026 | Z21: OLUKHI300064634 | AA21: 5 | AB21: ITFM | AC21: 3933/12/2020/ITFM | AD21: 44196 | AE21: 2% | AF21: 1237500 | AG21: 24750 | AH21: KHI/HO/D/MO/PC COMP/C/103702/31/12/2024 | AI21: 26400 | AJ21: 1650 | AK21: KHI/HO/D/MO/PC COMP/E/52165/00031/02/2025
A22: 21 | B22: NORM | C22: 997AAD1202480012 | D22: A | E22: T-PAK | F22: SHEIKH MUHAMMAD ARSLAN ALI | G22: Faisalabad | H22: 33100-8724276-7 | I22: 3004761508 | J22: 03004761508, 03004761508 | K22: 3004761508 | L22: H NO P-2 MAIN TOWN ST NO 13 ABC ROA D AFGHANABAD NO 2 FAISALABAD PK | M22: 1398750 | N22: 1865000 | O22: 53545/00001/01/2021 | P22: 45778 | Q22: 166469 | R22: 10066488 | S22: NEW | U22: CULTUS VXL | V22: 2020 | W22: 43930 | X22: 11-JAN-2021 | Y22: 46033 | Z22: POAFSD300057028 | AA22: 5 | AB22: ITFM | AC22: 3979/01/2021/ITFM | AD22: 44348 | AE22: 2% | AF22: 1398750 | AG22: 27975 | AH22: KHI/HO/D/MO/PC COMP/C/106590/73/01/2025 | AI22: 27975 | AJ22: 0
A23: 22 | B23: NORM | C23: 9976AP1220070002 | D23: A | E23: T-PAK | F23: ABDUL AZIZ KAKAR | G23: Karachi | H23: 54401-6140379-7 | I23: 03328824127 | J23: 03328824127, 03328824127 | K23: 03328824127 | L23: HOUSE # 4-C MEZZANINE FLOOR STREET 2 MAIN SABA COMM DHA PHASE 5 NEAR G KARACHI PK | M23: 1182500 | N23: 2150000 | O23: 57872/00017/01/2022 | P23: 45778 | Q23: Z327103 | R23: NZE170R-4047590 | S23: USD | T23: BEH-025 | U23: TOYOTA COROLLA GLI | V23: 2015 | W23: 44743 | X23: 11-JAN-2022 | Y23: 46398 | Z23: OLUKHI300082922 | AA23: 5 | AB23: CTRK | AC23: DIB0033069 | AD23: 44743 | AE23: 1.5% | AF23: 1720000 | AG23: 25800 | AH23: KHI/HO/D/MO/PC COMP/C/106590/74/01/2025 | AI23: 25800 | AJ23: 0
A24: 23 | B24: NORM | C24: 9976AD2212110014 | D24: A | E24: T-PAK | F24: ADEEL AHMED | G24: Karachi | H24: 42101-4655899-1 | I24: 03218211212 | J24: 03218211212 | K24: 0 | L24: R-128 SECTOR 5-C BILAL TOWN NORTH K HI NEAR THE BEST SCHOOL KARACHI PK | M24: 1216800 | N24: 1521000 | O24: 57872/00019/01/2022 | P24: 45778 | Q24: 197014 | R24: 4096983 | S24: NEW | U24: ALTO VXL AGS EURO-II | V24: 2021 | W24: 44407 | X24: 21-JAN-2022 | Y24: 46408 | Z24: OLAKHI300071413 | AA24: 5 | AB24: ITECL | AC24: 6070/01/2022 | AD24: 44682 | AE24: 2% | AF24: 1216800 | AG24: 24336 | AH24: KHI/HO/D/MO/PC COMP/C/106590/75/01/2025 | AI24: 24336 | AJ24: 0
A25: 24 | B25: NORM | C25: 9976AP1213650129 | D25: A | E25: T-PAK | F25: SYED AZAM ALI SHAH RIZVI | G25: Karachi | H25: 45502-8732960-9 | I25: 03213104006 | J25: 03213104006 | K25: 03213104006 | L25: HOUSE # B-15 ABDULLAH VILLAS NEAR B ILAL MASJID QASIMABAD HYDERABAD PK | M25: 896000 | N25: 1280000 | O25: 57132/00318/12/2021 | P25: 45656 | Q25: 638224 | R25: 545095 | S25: USD | T25: BJV-376 | U25: SUZUK CULTUS VXR CNG | V25: 2017 | W25: 44561 | X25: 03-JAN-2022 | Y25: 03-Jan-2027 | Z25: OLUKHI300082789 | AA25: 5 | AB25: CTRK | AC25: DIB0032990 | AD25: 44561 | AE25: 1.5% | AF25: 1024000 | AG25: 15360 | AH25: KHI/HO/D/MO/PC COMP/C/103702/32/12/2024 | AI25: 16320 | AJ25: 960 | AK25: KHI/HO/D/MO/PC COMP/E/52165/00032/02/2025
A26: 25 | B26: NORM | C26: 9976AP1223650046 | D26: A | E26: T-PAK | F26: SYED USAMA ALI SHAH | G26: Faisalabad | H26: 33102-6824894-1 | I26: 03202075588 | J26: 03202075588, 03202075588 | K26: 03202075588 | L26: P-170-ACANAL ROAD PHASE I EDEN GARD ENS FSD NEAR OPP PARK FAISALABAD PK | M26: 2454010 | N26: 5707000 | O26: 65483/00056/12/2022 | P26: 45656 | Q26: 273327 | R26: 306078 | S26: NEW | U26: HYUNDAI ELENTRA | V26: 2022 | W26: 44926 | X26: 03-JAN-2023 | Y26: 03-Jan-2026 | Z26: OLDFSD300091475 | AA26: 3 | AB26: ITECL | AC26: 9726/12/2022 | AD26: 44926 | AE26: 1.75% | AF26: 4850950 | AG26: 84892 | AH26: KHI/HO/D/MO/PC COMP/C/103702/34/12/2024 | AI26: 89885 | AJ26: 4993 | AK26: KHI/HO/D/MO/PC COMP/E/52165/00034/02/2025
A27: 26 | B27: NORM | C27: 9976AP1223650045 | D27: A | E27: T-PAK | F27: MUHAMMAD SHAHID | G27: Faisalabad | H27: 31303-8682978-9 | J27: 03127788700 | L27: P NO 17 BLOCK QUAID E AZAM ALLAMA COLONY FAISALABAD | M27: 1540000 | N27: 2200000 | O27: 65483/00061/12/2022 | P27: 45656 | Q27: 6R214379 | R27: 1114370 | S27: USD | T27: AJT-713 | U27: SUZUKI ALTO VXR | V27: 2022 | W27: 44926 | X27: 03-JAN-2023 | Y27: 03-Jan-2026 | Z27: OLUFSD300091497 | AA27: 3 | AB27: ITFT | AC27: 9730/12/2022 | AD27: 44926 | AE27: 1.75% | AF27: 1870000 | AG27: 32725 | AH27: KHI/HO/D/MO/PC COMP/C/103702/42/12/2024 | AI27: 34650 | AJ27: 1925 | AK27: KHI/HO/D/MO/PC COMP/E/52165/00042/02/2025
A28: 27 | B28: NORM | C28: 9976AP1223650030 | D28: A | E28: T-PAK | F28: REHMAT ALI | G28: Faisalabad | H28: 33100-9667888-5 | I28: 03226502244 | J28: 03226502244, 03226502244 | K28: 03226502244 | L28: P-29-A A BLOCK BARKAT PURA FAISALABAD PK | M28: 1368000 | N28: 2400000 | O28: 65483/00054/12/2022 | P28: 45656 | Q28: 6R213917 | R28: 113937 | S28: USD | T28: AJG-468 | U28: SUZUKI ALTO VXL AGS EURO-II | V28: 2022 | W28: 44926 | X28: 03-JAN-2023 | Y28: 03-Jan-2028 | Z28: OLUFSD300091457 | AA28: 5 | AB28: ITECL | AC28: 9722/12/2022 | AD28: 44926 | AE28: 1.75% | AF28: 2040000 | AG28: 35700 | AH28: KHI/HO/D/MO/PC COMP/C/103702/44/12/2024 | AI28: 37800 | AJ28: 2100 | AK28: KHI/HO/D/MO/PC COMP/E/52165/00044/02/2025
A29: 28 | B29: NORM | C29: 9976AP1223650029 | D29: A | E29: T-PAK | F29: MUHAMMAD ADNAN AMIR | G29: Faisalabad | H29: 33100-8007590-1 | I29: 03006620687 | J29: 03006620687, 03006620687 | K29: 03006620687 | L29: P-83 LASANI GARDENS SARGODHA ROAD F SD NEAR QUBA MASJID FAISALABAD PK | M29: 1940400 | N29: 3234000 | O29: 65483/00053/12/2022 | P29: 45656 | Q29: 204837 | R29: 10104844 | S29: NEW | U29: SUZUKI CULTUS VXL AGS EURO-II | V29: 2022 | W29: 44926 | X29: 03-JAN-2023 | Y29: 03-Jan-2028 | Z29: OLDFSD300091458 | AA29: 5 | AB29: ITECL | AC29: 9721/12/2022 | AD29: 44926 | AE29: 1.75% | AF29: 2748900 | AG29: 48106 | AH29: KHI/HO/D/MO/PC COMP/C/103702/46/12/2024 | AI29: 50936 | AJ29: 2830 | AK29: KHI/HO/D/MO/PC COMP/E/52165/00046/02/2025
A30: 29 | B30: NORM | C30: 9976AP2223650039 | D30: A | E30: T-PAK | F30: TARIQ MAWAZ | G30: Faisalabad | H30: 33100-0647226-5 | I30: 03007647050 | J30: 03007647050, 03007647050 | K30: 0412600882 | L30: H NO 30 ST NO 01 AL MASOOM TOWN FAISALABAD PK | M30: 2000000 | N30: 4000000 | O30: 65483/00059/12/2022 | P30: 45656 | Q30: Q326481 | R30: 7025687 | S30: USD | T30: AFJ-950 | U30: TOYOTA COROLLA ALTIS GRANDE CVT | V30: 2017 | W30: 44926 | X30: 03-JAN-2023 | Y30: 03-Jan-2026 | Z30: OLUFSD300091478 | AA30: 3 | AB30: ITECL | AC30: 9728/12/2022 | AD30: 44926 | AE30: 1.75% | AF30: 3400000 | AG30: 59500 | AH30: KHI/HO/D/MO/PC COMP/C/103702/47/12/2024 | AI30: 63000 | AJ30: 3500 | AK30: KHI/HO/D/MO/PC COMP/E/52165/00047/02/2025
A31: 30 | B31: NORM | C31: 9976AP1220120001 | D31: A | E31: T-PAK | F31: MUHAMMAD ARSALAN KHAN | G31: Karachi | H31: 54400-0542886-5 | I31: 03111027107 | J31: 03111027107 | K31: 0 | L31: HOUSE A- 136 SECTER Z SECTER 6 GULS HAN-E- MAYMAR RESTURENT Z- 06 KARACHI PK | M31: 2282000 | N31: 3260000 | O31: 57872/00018/01/2022 | P31: 45778 | Q31: Q332139Q | R31: ZRE172R-7031259 | S31: USD | T31: BMU-158 | U31: TOYOTA COROLLA ALTIS GRANDE CVT | V31: 2018 | W31: 44896 | X31: 21-JAN-2022 | Y31: 46408 | Z31: OLUKHI300082952 | AA31: 5 | AB31: CTRK | AC31: DIB0033073 | AD31: 44743 | AE31: 1.5% | AF31: 2608000 | AG31: 39120 | AH31: KHI/HO/D/MO/PC COMP/C/106590/81/01/2025 | AI31: 39120 | AJ31: 0
A32: 31 | B32: NORM | C32: 9976AD1212700057 | D32: A | E32: T-PAK | F32: MUHAMMAD BENYAMEEN TAHIR | G32: Lahore | H32: 36502-1378700-3 | I32: N/A | J32: 03009432338 | K32: N/A | L32: HNO. 167 SAPHIRE BLOCK PARK VIEW SOCIETY MULTAN ROAD LAHORE | M32: 2391000 | N32: 4782000 | O32: 57872/00014/01/2022 | P32: 45778 | Q32: G4NAMH315952 | R32: NNAQL51AZKP308394 | S32: NEW | U32: KIA SPORTAGE FWD | V32: 2021 | W32: 44466 | X32: 21-JAN-2022 | Y32: 46408 | Z32: OLALHR300073753 | AA32: 5 | AB32: ITECL | AC32: 6074/01/2022 | AD32: 44713 | AE32: 1.5% | AF32: 3825600 | AG32: 57384 | AH32: KHI/HO/D/MO/PC COMP/C/106590/82/01/2025 | AI32: 57384 | AJ32: 0
A33: 32 | B33: NORM | C33: 9976AP1213650138 | D33: A | E33: T-PAK | F33: MUHAMMAD ANEES | G33: Hyderabad | H33: 41303-6600627-7 | J33: 03213071774 | L33: HOUSE NO A/288 MOHALLA JAMIA MASJID ROAD TANDO WALI MOHAMMAD HYD | M33: 1890000 | N33: 2700000 | O33: 57132/00350/12/2021 | P33: 45656 | Q33: 547057 | R33: 4172790 | S33: USD | T33: BPX-345 | U33: TOYOTA COROLLA GLI A/T | V33: 2018 | W33: 44561 | X33: 03-JAN-2022 | Y33: 03-Jan-2027 | Z33: OLUHYD300082748 | AA33: 5 | AB33: ITECL | AC33: 6043/12/2021 | AD33: 44561 | AE33: 1.5% | AF33: 2160000 | AG33: 32400 | AH33: KHI/HO/D/MO/PC COMP/C/103702/48/12/2024 | AI33: 34425 | AJ33: 2025 | AK33: KHI/HO/D/MO/PC COMP/E/52165/00048/02/2025
A34: 33 | B34: NORM | C34: 9976AP2220040096 | D34: A | E34: T-PAK | F34: MUHAMMAD AHSAN MIR | G34: Islamabad | H34: 61101-1118384-7 | I34: 0515179507 | K34: 0512624800 | L34: H # 134 ST # 22 ALI BLOCK BAHRIA TO WN PH-8 RAWALPINDI PK | M34: 2762500 | N34: 4250000 | O34: 57132/00368/12/2021 | P34: 45656 | Q34: 16913445 | R34: 065243 | S34: USD | T34: AST-005 | U34: HONDA CIVIC VTI | V34: 2020 | W34: 44565 | X34: 11-JAN-2022 | Y34: 11-Jan-2027 | Z34: OLUISD300082881 | AA34: 5 | AB34: ITECL | AC34: 6056/12/2021 | AD34: 44561 | AE34: 1.5% | AF34: 3400000 | AG34: 51000 | AH34: KHI/HO/D/MO/PC COMP/C/103702/50/12/2024 | AI34: 54188 | AJ34: 3188 | AK34: KHI/HO/D/MO/PC COMP/E/52165/00050/02/2025
A35: 34 | B35: NORM | C35: 9976AD1212530032 | D35: A | E35: T-PAK | F35: SHAHZAD MUREED | G35: Lahore | H35: 36302-8603292-7 | I35: 03006320207 | J35: 03006320207 | K35: 03006320207 | L35: POST OFFICE KHAS KHAKI PANJANI SHUJ ABAD MULTAN | M35: 2407200 | N35: 4012000 | O35: 57132/00304/12/2021 | P35: 45656 | Q35: 6930139 | R35: 082737 | S35: NEW | T35: APL-4 | U35: HONDA CIVIC VTI ORIEL P/T | V35: 2021 | W35: 44449 | X35: 11-JAN-2022 | Y35: 11-Jan-2027 | Z35: OLALHR300073244 | AA35: 5 | AB35: CTRK | AC35: DIB0032981 | AD35: 44561 | AE35: 2% | AF35: 3209600 | AG35: 64192 | AH35: KHI/HO/D/MO/PC COMP/C/103702/51/12/2024 | AI35: 68204 | AJ35: 4012 | AK35: KHI/HO/D/MO/PC COMP/E/52165/00051/02/2025
A36: 35 | B36: NORM | C36: 9976AP1220040172 | D36: A | E36: T-PAK | F36: DANISH | G36: Lahore | H36: 35202-4154775-9 | I36: 03074363005 | J36: 03074363005 | K36: 03074363005 | L36: HOUSE NO 53 STREET NO 53 MOHALLAH C HAH MERAN ROAD FAIZ BAGH LAHORE PK | M36: 2380000 | N36: 3400000 | O36: 57132/00365/12/2021 | P36: 45656 | Q36: 12905954 | R36: R008418 | S36: USD | T36: LEA-18-A-2812 | U36: HONDA CIVIC VTI ORIEL | V36: 2016 | W36: 44565 | X36: 11-JAN-2022 | Y36: 11-Jan-2027 | Z36: OLULHR300082889 | AA36: 5 | AB36: CTRK | AC36: DIB0033023 | AD36: 44561 | AE36: 1.5% | AF36: 2720000 | AG36: 40800 | AH36: KHI/HO/D/MO/PC COMP/C/103702/52/12/2024 | AI36: 43350 | AJ36: 2550 | AK36: KHI/HO/D/MO/PC COMP/E/52165/00052/02/2025
A37: 36 | B37: NORM | C37: 9976AP1213650113 | D37: A | E37: T-PAK | F37: ABDUL SATTAR | G37: Hyderabad | H37: 41306-4264727-5 | I37: 03133009846 | J37: 03133009846 | K37: 03133009846 | L37: H NO B-34/1 HDA EDT 1 NORTH PHASE 1 QASIMABAD HYDERABAD PK | M37: 2100000 | N37: 3000000 | O37: 57132/00321/12/2021 | P37: 45656 | Q37: Q040457 | R37: 6017962 | S37: USD | T37: BKU-950 | U37: TOYOTA COROLLA ALTIS A/T | V37: 2017 | W37: 44561 | X37: 03-JAN-2022 | Y37: 03-Jan-2027 | Z37: OLUHYD300082761 | AA37: 5 | AB37: ITECL | AC37: 6034/12/2021 | AD37: 44561 | AE37: 1.5% | AF37: 2400000 | AG37: 36000 | AH37: KHI/HO/D/MO/PC COMP/C/103702/53/12/2024 | AI37: 38250 | AJ37: 2250 | AK37: KHI/HO/D/MO/PC COMP/E/52165/00053/02/2025
A38: 37 | B38: NORM | C38: 9976AP1230090008 | D38: A | E38: T-PAK | F38: SHEIKH MUJAHID ALI | G38: Faisalabad | H38: 33100-7650028-1 | I38: 03219478678 | J38: 03219478678, 03006633268 | K38: 03219478678 | L38: 3-C ST NO 31 MOHALLA ALI HOUSING CO LONY SHADAB COLONY JHANG ROAD FSD N FAISALABAD PK | M38: 1890000 | N38: 3000000 | O38: 66406/00018/01/2023 | P38: 45778 | Q38: 17528047 | R38: 245903 | S38: USD | T38: AMS-558 | U38: HONDA CITY I-VTEC P/T | V38: 2019 | W38: 45170 | X38: 11-JAN-2023 | Y38: 46033 | Z38: OLUFSD300091556 | AA38: 3 | AB38: ITECL | AC38: 9750/01/2023 | AD38: 44932 | AE38: 1.75% | AF38: 2550000 | AG38: 44625 | AH38: KHI/HO/D/MO/PC COMP/C/106590/89/01/2025 | AI38: 44625 | AJ38: 0
A39: 38 | B39: NORM | C39: 9976AP2213650079 | D39: A | E39: T-PAK | F39: GHULAM FAROOQ | G39: Peshawar | H39: 16101-4611758-7 | I39: 03444472038 | K39: 0 | L39: FLAT # B-33 GATE # 4 AGRICULTURE UN IVERSITY PESHAWAR PK | M39: 2054000 | N39: 2933000 | O39: 57132/00344/12/2021 | P39: 45656 | Q39: 2A42654 | R39: NSP151R-9515828 | S39: NEW | U39: TOYOTA YARIS ATIV X CVT 1.5 | V39: 2021 | W39: 44561 | X39: 03-JAN-2022 | Y39: 03-Jan-2027 | Z39: OLDPEW300082688 | AA39: 5 | AB39: CTRK | AC39: DIB0033001 | AD39: 44561 | AE39: 2% | AF39: 2346400 | AG39: 46928 | AH39: KHI/HO/D/MO/PC COMP/C/103702/54/12/2024 | AI39: 49861 | AJ39: 2933 | AK39: KHI/HO/D/MO/PC COMP/E/52165/00054/02/2025
A40: 39 | B40: NORM | C40: 9976AD1223220003 | D40: A | E40: T-PAK | F40: ZIA ZAMAN SHANWARI | G40: Islamabad | H40: 14301-3154269-9 | I40: 0514431044 | J40: 03455552172 | L40: HOUSE NO.800, STREET NO.72, I-8/3, ISLAMABAD. | M40: 1383200 | N40: 1976000 | O40: 66406/00015/01/2023 | P40: 45778 | Q40: 267040 | R40: 1167059 | S40: NEW | U40: SUZUKI ALTO VXR EURO-II | V40: 2022 | W40: 44883 | X40: 11-JAN-2023 | Y40: 46763 | Z40: OLAISD300090832 | AA40: 5 | AB40: FLCN | AC40: 109015/12/2022 | AD40: 44932 | AE40: 2% | AF40: 1679600 | AG40: 33592 | AH40: KHI/HO/D/MO/PC COMP/C/106590/91/01/2025 | AI40: 33592 | AJ40: 0
...

Sheet working
A1: POLICY NO. | B1: Assorted_code | D1: Premium | E1: 12Feb250043
A2: KHI/HO/D/MO/PC COMP/E/52165/00012/02/2025 | B2: =VLOOKUP(A2,policy!B:C,2,0) -> 050000851182 | C2: -3495 | D2: =ROUND(C2,0) -> -3495 | E2: 12Feb250043 | F2: ="insert into ins_premium_det (premium_rcv_code,assorted_code, rec_amount,premium_rcv_detail_code,remaining_amt, payrec, mode_code,coinsurance_code,class_cd,it_remarks) values" -> insert into ins_premium_det (premium_rcv_code,assorted_code, rec_amount,premium_rcv_detail_code,remaining_amt, payrec, mode_code,coinsurance_code,class_cd,it_remarks) values | G2: ="('"&E2&"','"&B2&"','"&D2&"',(select max(to_number(i.premium_rcv_detail_code))+1 from ins_premium_det i),'"&D2&"','"&D2&"','02', '11000003','00','Request by Mr. Saqib Saleem 13-Feb-2025');" -> ('12Feb250043','050000851182','-3495',(select max(to_number(i.premium_rcv_detail_code))+1 from ins_premium_det i),'-3495','-3495','02', '11000003','00','Request by Mr. Saqib Saleem 13-Feb-2025'); | H2: =F2&G2 -> insert into ins_premium_det (premium_rcv_code,assorted_code, rec_amount,premium_rcv_detail_code,remaining_amt, payrec, mode_code,coinsurance_code,class_cd,it_remarks) values('12Feb250043','050000851182','-3495',(select max(to_number(i.premium_rcv_detail_code))+1 from ins_premium_det i),'-3495','-3495','02', '11000003','00','Request by Mr. Saqib Saleem 13-Feb-2025');
A3: KHI/HO/D/MO/PC COMP/E/52165/00016/02/2025 | B3: =VLOOKUP(A3,policy!B:C,2,0) -> 050000851186 | C3: -1662 | D3: =ROUND(C3,0) -> -1662 | E3: 12Feb250043 | F3: ="insert into ins_premium_det (premium_rcv_code,assorted_code, rec_amount,premium_rcv_detail_code,remaining_amt, payrec, mode_code,coinsurance_code,class_cd,it_remarks) values" -> insert into ins_premium_det (premium_rcv_code,assorted_code, rec_amount,premium_rcv_detail_code,remaining_amt, payrec, mode_code,coinsurance_code,class_cd,it_remarks) values | G3: ="('"&E3&"','"&B3&"','"&D3&"',(select max(to_number(i.premium_rcv_detail_code))+1 from ins_premium_det i),'"&D3&"','"&D3&"','02', '11000003','00','Request by Mr. Saqib Saleem 13-Feb-2025');" -> ('12Feb250043','050000851186','-1662',(select max(to_number(i.premium_rcv_detail_code))+1 from ins_premium_det i),'-1662','-1662','02', '11000003','00','Request by Mr. Saqib Saleem 13-Feb-2025'); | H3: =F3&G3 -> insert into ins_premium_det (premium_rcv_code,assorted_code, rec_amount,premium_rcv_detail_code,remaining_amt, payrec, mode_code,coinsurance_code,class_cd,it_remarks) values('12Feb250043','050000851186','-1662',(select max(to_number(i.premium_rcv_detail_code))+1 from ins_premium_det i),'-1662','-1662','02', '11000003','00','Request by Mr. Saqib Saleem 13-Feb-2025');
A4: KHI/HO/D/MO/PC COMP/E/52165/00019/02/2025 | B4: =VLOOKUP(A4,policy!B:C,2,0) -> 050000851189 | C4: -1487 | D4: =ROUND(C4,0) -> -1487 | E4: 12Feb250043 | F4: ="insert into ins_premium_det (premium_rcv_code,assorted_code, rec_amount,premium_rcv_detail_code,remaining_amt, payrec, mode_code,coinsurance_code,class_cd,it_remarks) values" -> insert into ins_premium_det (premium_rcv_code,assorted_code, rec_amount,premium_rcv_detail_code,remaining_amt, payrec, mode_code,coinsurance_code,class_cd,it_remarks) values | G4: ="('"&E4&"','"&B4&"','"&D4&"',(select max(to_number(i.premium_rcv_detail_code))+1 from ins_premium_det i),'"&D4&"','"&D4&"','02', '11000003','00','Request by Mr. Saqib Saleem 13-Feb-2025');" -> ('12Feb250043','050000851189','-1487',(select max(to_number(i.premium_rcv_detail_code))+1 from ins_premium_det i),'-1487','-1487','02', '11000003','00','Request by Mr. Saqib Saleem 13-Feb-2025'); | H4: =F4&G4 -> insert into ins_premium_det (premium_rcv_code,assorted_code, rec_amount,premium_rcv_detail_code,remaining_amt, payrec, mode_code,coinsurance_code,class_cd,it_remarks) values('12Feb250043','050000851189','-1487',(select max(to_number(i.premium_rcv_detail_code))+1 from ins_premium_det i),'-1487','-1487','02', '11000003','00','Request by Mr. Saqib Saleem 13-Feb-2025');
A5: KHI/HO/D/MO/PC COMP/E/52165/00025/02/2025 | B5: =VLOOKUP(A5,policy!B:C,2,0) -> 050000851195 | C5: -3157 | D5: =ROUND(C5,0) -> -3157 | E5: 12Feb250043 | F5: ="insert into ins_premium_det (premium_rcv_code,assorted_code, rec_amount,premium_rcv_detail_code,remaining_amt, payrec, mode_code,coinsurance_code,class_cd,it_remarks) values" -> insert into ins_premium_det (premium_rcv_code,assorted_code, rec_amount,premium_rcv_detail_code,remaining_amt, payrec, mode_code,coinsurance_code,class_cd,it_remarks) values | G5: ="('"&E5&"','"&B5&"','"&D5&"',(select max(to_number(i.premium_rcv_detail_code))+1 from ins_premium_det i),'"&D5&"','"&D5&"','02', '11000003','00','Request by Mr. Saqib Saleem 13-Feb-2025');" -> ('12Feb250043','050000851195','-3157',(select max(to_number(i.premium_rcv_detail_code))+1 from ins_premium_det i),'-3157','-3157','02', '11000003','00','Request by Mr. Saqib Saleem 13-Feb-2025'); | H5: =F5&G5 -> insert into ins_premium_det (premium_rcv_code,assorted_code, rec_amount,premium_rcv_detail_code,remaining_amt, payrec, mode_code,coinsurance_code,class_cd,it_remarks) values('12Feb250043','050000851195','-3157',(select max(to_number(i.premium_rcv_detail_code))+1 from ins_premium_det i),'-3157','-3157','02', '11000003','00','Request by Mr. Saqib Saleem 13-Feb-2025');
A6: KHI/HO/D/MO/PC COMP/E/52165/00029/02/2025 | B6: =VLOOKUP(A6,policy!B:C,2,0) -> 050000851199 | C6: -2175 | D6: =ROUND(C6,0) -> -2175 | E6: 12Feb250043 | F6: ="insert into ins_premium_det (premium_rcv_code,assorted_code, rec_amount,premium_rcv_detail_code,remaining_amt, payrec, mode_code,coinsurance_code,class_cd,it_remarks) values" -> insert into ins_premium_det (premium_rcv_code,assorted_code, rec_amount,premium_rcv_detail_code,remaining_amt, payrec, mode_code,coinsurance_code,class_cd,it_remarks) values | G6: ="('"&E6&"','"&B6&"','"&D6&"',(select max(to_number(i.premium_rcv_detail_code))+1 from ins_premium_det i),'"&D6&"','"&D6&"','02', '11000003','00','Request by Mr. Saqib Saleem 13-Feb-2025');" -> ('12Feb250043','050000851199','-2175',(select max(to_number(i.premium_rcv_detail_code))+1 from ins_premium_det i),'-2175','-2175','02', '11000003','00','Request by Mr. Saqib Saleem 13-Feb-2025'); | H6: =F6&G6 -> insert into ins_premium_det (premium_rcv_code,assorted_code, rec_amount,premium_rcv_detail_code,remaining_amt, payrec, mode_code,coinsurance_code,class_cd,it_remarks) values('12Feb250043','050000851199','-2175',(select max(to_number(i.premium_rcv_detail_code))+1 from ins_premium_det i),'-2175','-2175','02', '11000003','00','Request by Mr. Saqib Saleem 13-Feb-2025');
A7: KHI/HO/D/MO/PC COMP/E/52165/00031/02/2025 | B7: =VLOOKUP(A7,policy!B:C,2,0) -> 050000851201 | C7: -1650 | D7: =ROUND(C7,0) -> -1650 | E7: 12Feb250043 | F7: ="insert into ins_premium_det (premium_rcv_code,assorted_code, rec_amount,premium_rcv_detail_code,remaining_amt, payrec, mode_code,coinsurance_code,class_cd,it_remarks) values" -> insert into ins_premium_det (premium_rcv_code,assorted_code, rec_amount,premium_rcv_detail_code,remaining_amt, payrec, mode_code,coinsurance_code,class_cd,it_remarks) values | G7: ="('"&E7&"','"&B7&"','"&D7&"',(select max(to_number(i.premium_rcv_detail_code))+1 from ins_premium_det i),'"&D7&"','"&D7&"','02', '11000003','00','Request by Mr. Saqib Saleem 13-Feb-2025');" -> ('12Feb250043','050000851201','-1650',(select max(to_number(i.premium_rcv_detail_code))+1 from ins_premium_det i),'-1650','-1650','02', '11000003','00','Request by Mr. Saqib Saleem 13-Feb-2025'); | H7: =F7&G7 -> insert into ins_premium_det (premium_rcv_code,assorted_code, rec_amount,premium_rcv_detail_code,remaining_amt, payrec, mode_code,coinsurance_code,class_cd,it_remarks) values('12Feb250043','050000851201','-1650',(select max(to_number(i.premium_rcv_detail_code))+1 from ins_premium_det i),'-1650','-1650','02', '11000003','00','Request by Mr. Saqib Saleem 13-Feb-2025');
A8: KHI/HO/D/MO/PC COMP/E/52165/00032/02/2025 | B8: =VLOOKUP(A8,policy!B:C,2,0) -> 050000851202 | C8: -960 | D8: =ROUND(C8,0) -> -960 | E8: 12Feb250043 | F8: ="insert into ins_premium_det (premium_rcv_code,assorted_code, rec_amount,premium_rcv_detail_code,remaining_amt, payrec, mode_code,coinsurance_code,class_cd,it_remarks) values" -> insert into ins_premium_det (premium_rcv_code,assorted_code, rec_amount,premium_rcv_detail_code,remaining_amt, payrec, mode_code,coinsurance_code,class_cd,it_remarks) values | G8: ="('"&E8&"','"&B8&"','"&D8&"',(select max(to_number(i.premium_rcv_detail_code))+1 from ins_premium_det i),'"&D8&"','"&D8&"','02', '11000003','00','Request by Mr. Saqib Saleem 13-Feb-2025');" -> ('12Feb250043','050000851202','-960',(select max(to_number(i.premium_rcv_detail_code))+1 from ins_premium_det i),'-960','-960','02', '11000003','00','Request by Mr. Saqib Saleem 13-Feb-2025'); | H8: =F8&G8 -> insert into ins_premium_det (premium_rcv_code,assorted_code, rec_amount,premium_rcv_detail_code,remaining_amt, payrec, mode_code,coinsurance_code,class_cd,it_remarks) values('12Feb250043','050000851202','-960',(select max(to_number(i.premium_rcv_detail_code))+1 from ins_premium_det i),'-960','-960','02', '11000003','00','Request by Mr. Saqib Saleem 13-Feb-2025');
A9: KHI/HO/D/MO/PC COMP/E/52165/00034/02/2025 | B9: =VLOOKUP(A9,policy!B:C,2,0) -> 050000851204 | C9: -4993 | D9: =ROUND(C9,0) -> -4993 | E9: 12Feb250043 | F9: ="insert into ins_premium_det (premium_rcv_code,assorted_code, rec_amount,premium_rcv_detail_code,remaining_amt, payrec, mode_code,coinsurance_code,class_cd,it_remarks) values" -> insert into ins_premium_det (premium_rcv_code,assorted_code, rec_amount,premium_rcv_detail_code,remaining_amt, payrec, mode_code,coinsurance_code,class_cd,it_remarks) values | G9: ="('"&E9&"','"&B9&"','"&D9&"',(select max(to_number(i.premium_rcv_detail_code))+1 from ins_premium_det i),'"&D9&"','"&D9&"','02', '11000003','00','Request by Mr. Saqib Saleem 13-Feb-2025');" -> ('12Feb250043','050000851204','-4993',(select max(to_number(i.premium_rcv_detail_code))+1 from ins_premium_det i),'-4993','-4993','02', '11000003','00','Request by Mr. Saqib Saleem 13-Feb-2025'); | H9: =F9&G9 -> insert into ins_premium_det (premium_rcv_code,assorted_code, rec_amount,premium_rcv_detail_code,remaining_amt, payrec, mode_code,coinsurance_code,class_cd,it_remarks) values('12Feb250043','050000851204','-4993',(select max(to_number(i.premium_rcv_detail_code))+1 from ins_premium_det i),'-4993','-4993','02', '11000003','00','Request by Mr. Saqib Saleem 13-Feb-2025');
A10: KHI/HO/D/MO/PC COMP/E/52165/00042/02/2025 | B10: =VLOOKUP(A10,policy!B:C,2,0) -> 050000851212 | C10: -1925 | D10: =ROUND(C10,0) -> -1925 | E10: 12Feb250043 | F10: ="insert into ins_premium_det (premium_rcv_code,assorted_code, rec_amount,premium_rcv_detail_code,remaining_amt, payrec, mode_code,coinsurance_code,class_cd,it_remarks) values" -> insert into ins_premium_det (premium_rcv_code,assorted_code, rec_amount,premium_rcv_detail_code,remaining_amt, payrec, mode_code,coinsurance_code,class_cd,it_remarks) values | G10: ="('"&E10&"','"&B10&"','"&D10&"',(select max(to_number(i.premium_rcv_detail_code))+1 from ins_premium_det i),'"&D10&"','"&D10&"','02', '11000003','00','Request by Mr. Saqib Saleem 13-Feb-2025');" -> ('12Feb250043','050000851212','-1925',(select max(to_number(i.premium_rcv_detail_code))+1 from ins_premium_det i),'-1925','-1925','02', '11000003','00','Request by Mr. Saqib Saleem 13-Feb-2025'); | H10: =F10&G10 -> insert into ins_premium_det (premium_rcv_code,assorted_code, rec_amount,premium_rcv_detail_code,remaining_amt, payrec, mode_code,coinsurance_code,class_cd,it_remarks) values('12Feb250043','050000851212','-1925',(select max(to_number(i.premium_rcv_detail_code))+1 from ins_premium_det i),'-1925','-1925','02', '11000003','00','Request by Mr. Saqib Saleem 13-Feb-2025');
A11: KHI/HO/D/MO/PC COMP/E/52165/00044/02/2025 | B11: =VLOOKUP(A11,policy!B:C,2,0) -> 050000851214 | C11: -2100 | D11: =ROUND(C11,0) -> -2100 | E11: 12Feb250043 | F11: ="insert into ins_premium_det (premium_rcv_code,assorted_code, rec_amount,premium_rcv_detail_code,remaining_amt, payrec, mode_code,coinsurance_code,class_cd,it_remarks) values" -> insert into ins_premium_det (premium_rcv_code,assorted_code, rec_amount,premium_rcv_detail_code,remaining_amt, payrec, mode_code,coinsurance_code,class_cd,it_remarks) values | G11: ="('"&E11&"','"&B11&"','"&D11&"',(select max(to_number(i.premium_rcv_detail_code))+1 from ins_premium_det i),'"&D11&"','"&D11&"','02', '11000003','00','Request by Mr. Saqib Saleem 13-Feb-2025');" -> ('12Feb250043','050000851214','-2100',(select max(to_number(i.premium_rcv_detail_code))+1 from ins_premium_det i),'-2100','-2100','02', '11000003','00','Request by Mr. Saqib Saleem 13-Feb-2025'); | H11: =F11&G11 -> insert into ins_premium_det (premium_rcv_code,assorted_code, rec_amount,premium_rcv_detail_code,remaining_amt, payrec, mode_code,coinsurance_code,class_cd,it_remarks) values('12Feb250043','050000851214','-2100',(select max(to_number(i.premium_rcv_detail_code))+1 from ins_premium_det i),'-2100','-2100','02', '11000003','00','Request by Mr. Saqib Saleem 13-Feb-2025');
A12: KHI/HO/D/MO/PC COMP/E/52165/00046/02/2025 | B12: =VLOOKUP(A12,policy!B:C,2,0) -> 050000851216 | C12: -2830 | D12: =ROUND(C12,0) -> -2830 | E12: 12Feb250043 | F12: ="insert into ins_premium_det (premium_rcv_code,assorted_code, rec_amount,premium_rcv_detail_code,remaining_amt, payrec, mode_code,coinsurance_code,class_cd,it_remarks) values" -> insert into ins_premium_det (premium_rcv_code,assorted_code, rec_amount,premium_rcv_detail_code,remaining_amt, payrec, mode_code,coinsurance_code,class_cd,it_remarks) values | G12: ="('"&E12&"','"&B12&"','"&D12&"',(select max(to_number(i.premium_rcv_detail_code))+1 from ins_premium_det i),'"&D12&"','"&D12&"','02', '11000003','00','Request by Mr. Saqib Saleem 13-Feb-2025');" -> ('12Feb250043','050000851216','-2830',(select max(to_number(i.premium_rcv_detail_code))+1 from ins_premium_det i),'-2830','-2830','02', '11000003','00','Request by Mr. Saqib Saleem 13-Feb-2025'); | H12: =F12&G12 -> insert into ins_premium_det (premium_rcv_code,assorted_code, rec_amount,premium_rcv_detail_code,remaining_amt, payrec, mode_code,coinsurance_code,class_cd,it_remarks) values('12Feb250043','050000851216','-2830',(select max(to_number(i.premium_rcv_detail_code))+1 from ins_premium_det i),'-2830','-2830','02', '11000003','00','Request by Mr. Saqib Saleem 13-Feb-2025');
A13: KHI/HO/D/MO/PC COMP/E/52165/00047/02/2025 | B13: =VLOOKUP(A13,policy!B:C,2,0) -> 050000851217 | C13: -3500 | D13: =ROUND(C13,0) -> -3500 | E13: 12Feb250043 | F13: ="insert into ins_premium_det (premium_rcv_code,assorted_code, rec_amount,premium_rcv_detail_code,remaining_amt, payrec, mode_code,coinsurance_code,class_cd,it_remarks) values" -> insert into ins_premium_det (premium_rcv_code,assorted_code, rec_amount,premium_rcv_detail_code,remaining_amt, payrec, mode_code,coinsurance_code,class_cd,it_remarks) values | G13: ="('"&E13&"','"&B13&"','"&D13&"',(select max(to_number(i.premium_rcv_detail_code))+1 from ins_premium_det i),'"&D13&"','"&D13&"','02', '11000003','00','Request by Mr. Saqib Saleem 13-Feb-2025');" -> ('12Feb250043','050000851217','-3500',(select max(to_number(i.premium_rcv_detail_code))+1 from ins_premium_det i),'-3500','-3500','02', '11000003','00','Request by Mr. Saqib Saleem 13-Feb-2025'); | H13: =F13&G13 -> insert into ins_premium_det (premium_rcv_code,assorted_code, rec_amount,premium_rcv_detail_code,remaining_amt, payrec, mode_code,coinsurance_code,class_cd,it_remarks) values('12Feb250043','050000851217','-3500',(select max(to_number(i.premium_rcv_detail_code))+1 from ins_premium_det i),'-3500','-3500','02', '11000003','00','Request by Mr. Saqib Saleem 13-Feb-2025');
... A155: KHI/HO/D/MO/PC COMP/E/52165/00337/02/2025 | B155: =VLOOKUP(A155,policy!B:C,2,0) -> 050000851084 | C155: -5449 | D155: =ROUND(C155,0) -> -5449 | E155: 12Feb250043 | F155: ="insert into ins_premium_det (premium_rcv_code,assorted_code, rec_amount,premium_rcv_detail_code,remaining_amt, payrec, mode_code,coinsurance_code,class_cd,it_remarks) values" -> insert into ins_premium_det (premium_rcv_code,assorted_code, rec_amount,premium_rcv_detail_code,remaining_amt, payrec, mode_code,coinsurance_code,class_cd,it_remarks) values | G155: ="('"&E155&"','"&B155&"','"&D155&"',(select max(to_number(i.premium_rcv_detail_code))+1 from ins_premium_det i),'"&D155&"','"&D155&"','02', '11000003','00','Request by Mr. Saqib Saleem 13-Feb-2025');" -> ('12Feb250043','050000851084','-5449',(select max(to_number(i.premium_rcv_detail_code))+1 from ins_premium_det i),'-5449','-5449','02', '11000003','00','Request by Mr. Saqib Saleem 13-Feb-2025'); | H155: =F155&G155 -> insert into ins_premium_det (premium_rcv_code,assorted_code, rec_amount,premium_rcv_detail_code,remaining_amt, payrec, mode_code,coinsurance_code,class_cd,it_remarks) values('12Feb250043','050000851084','-5449',(select max(to_number(i.premium_rcv_detail_code))+1 from ins_premium_det i),'-5449','-5449','02', '11000003','00','Request by Mr. Saqib Saleem 13-Feb-2025');

Sheet Sheet2
A2: KHI/HO/D/MO/PC COMP/E/52165/00012/02/2025 | B2: -02-2025 | H2: 52165 | I2: 00012 | J2: ="ia.assorted_string like '%"&H2&"-"&I2&B2&"%' or" -> ia.assorted_string like '%52165-00012-02-2025%' or
A3: KHI/HO/D/MO/PC COMP/E/52165/00016/02/2025 | B3: -02-2025 | H3: 52165 | I3: 00016 | J3: ="ia.assorted_string like '%"&H3&"-"&I3&B3&"%' or" -> ia.assorted_string like '%52165-00016-02-2025%' or
A4: KHI/HO/D/MO/PC COMP/E/52165/00019/02/2025 | B4: -02-2025 | H4: 52165 | I4: 00019 | J4: ="ia.assorted_string like '%"&H4&"-"&I4&B4&"%' or" -> ia.assorted_string like '%52165-00019-02-2025%' or
A5: KHI/HO/D/MO/PC COMP/E/52165/00025/02/2025 | B5: -02-2025 | H5: 52165 | I5: 00025 | J5: ="ia.assorted_string like '%"&H5&"-"&I5&B5&"%' or" -> ia.assorted_string like '%52165-00025-02-2025%' or
A6: KHI/HO/D/MO/PC COMP/E/52165/00029/02/2025 | B6: -02-2025 | H6: 52165 | I6: 00029 | J6: ="ia.assorted_string like '%"&H6&"-"&I6&B6&"%' or" -> ia.assorted_string like '%52165-00029-02-2025%' or
A7: KHI/HO/D/MO/PC COMP/E/52165/00031/02/2025 | B7: -02-2025 | H7: 52165 | I7: 00031 | J7: ="ia.assorted_string like '%"&H7&"-"&I7&B7&"%' or" -> ia.assorted_string like '%52165-00031-02-2025%' or
A8: KHI/HO/D/MO/PC COMP/E/52165/00032/02/2025 | B8: -02-2025 | H8: 52165 | I8: 00032 | J8: ="ia.assorted_string like '%"&H8&"-"&I8&B8&"%' or" -> ia.assorted_string like '%52165-00032-02-2025%' or
A9: KHI/HO/D/MO/PC COMP/E/52165/00034/02/2025 | B9: -02-2025 | H9: 52165 | I9: 00034 | J9: ="ia.assorted_string like '%"&H9&"-"&I9&B9&"%' or" -> ia.assorted_string like '%52165-00034-02-2025%' or
A10: KHI/HO/D/MO/PC COMP/E/52165/00042/02/2025 | B10: -02-2025 | H10: 52165 | I10: 00042 | J10: ="ia.assorted_string like '%"&H10&"-"&I10&B10&"%' or" -> ia.assorted_string like '%52165-00042-02-2025%' or
A11: KHI/HO/D/MO/PC COMP/E/52165/00044/02/2025 | B11: -02-2025 | H11: 52165 | I11: 00044 | J11: ="ia.assorted_string like '%"&H11&"-"&I11&B11&"%' or" -> ia.assorted_string like '%52165-00044-02-2025%' or
A12: KHI/HO/D/MO/PC COMP/E/52165/00046/02/2025 | B12: -02-2025 | H12: 52165 | I12: 00046 | J12: ="ia.assorted_string like '%"&H12&"-"&I12&B12&"%' or" -> ia.assorted_string like '%52165-00046-02-2025%' or
A13: KHI/HO/D/MO/PC COMP/E/52165/00047/02/2025 | B13: -02-2025 | H13: 52165 | I13: 00047 | J13: ="ia.assorted_string like '%"&H13&"-"&I13&B13&"%' or" -> ia.assorted_string like '%52165-00047-02-2025%' or
... A155: KHI/HO/D/MO/PC COMP/E/52165/00337/02/2025 | B155: -02-2025 | H155: 52165 | I155: 00337 | J155: ="ia.assorted_string like '%"&H155&"-"&I155&B155&"%' or" -> ia.assorted_string like '%52165-00337-02-2025%' or

Sheet policy
B1: FUNC_ASSORTED_STRING(IA.ASSORTED_CODE) | C1: ASSORTED_CODE
A2: 1 | B2: KHI/HO/D/MO/PC COMP/E/52165/00091/02/2025 | C2: 050000850838
A3: 2 | B3: KHI/HO/D/MO/PC COMP/E/52165/00119/02/2025 | C3: 050000850866
A4: 3 | B4: KHI/HO/D/MO/PC COMP/E/52165/00136/02/2025 | C4: 050000850883
A5: 4 | B5: KHI/HO/D/MO/PC COMP/E/52165/00144/02/2025 | C5: 050000850891
A6: 5 | B6: KHI/HO/D/MO/PC COMP/E/52165/00148/02/2025 | C6: 050000850895
A7: 6 | B7: KHI/HO/D/MO/PC COMP/E/52165/00159/02/2025 | C7: 050000850906
A8: 7 | B8: KHI/HO/D/MO/PC COMP/E/52165/00163/02/2025 | C8: 050000850910
A9: 8 | B9: KHI/HO/D/MO/PC COMP/E/52165/00171/02/2025 | C9: 050000850918
A10: 9 | B10: KHI/HO/D/MO/PC COMP/E/52165/00186/02/2025 | C10: 050000850933
A11: 10 | B11: KHI/HO/D/MO/PC COMP/E/52165/00385/02/2025 | C11: 050000851132
A12: 11 | B12: KHI/HO/D/MO/PC COMP/E/52165/00189/02/2025 | C12: 050000850936
A13: 12 | B13: KHI/HO/D/MO/PC COMP/E/52165/00197/02/2025 | C13: 050000850944
... A155: 154 | B155: KHI/HO/D/MO/PC COMP/E/52227/00098/02/2025 | C155: 050000852707
