Workbook

Sheet 3rd
A1: Salaam Takaful 3rd Quarter 2024 | N1: 92 DAYS
A2: 1st July to 30 September 2024
A3: Sr. # | B3: PMD# | C3: Policy # 2024 | D3: Reg. # | E3: Make | F3: Model | G3: Colour | H3: Engine # | I3: Chassis # | J3: Owner | K3: Sum Insured | L3: Ins Rat 1.65% | M3: Days | N3: 3rd Installment
A4: 1 | B4: P82142 | C4: KHI/HO/D/MO/PC TPP/P/82142/01/2024 | D4: LED-18-6255 | E4: T/C/Gli | F4: 2018 | G4: White | H4: 518514 | I4: 4144559 | J4: Mystic Tours PVT LTD | K4: 2600000 | L4: =K4*1.65/100 -> 42900 | M4: 92 | N4: =L4*M4/366 -> 10783.607
A5: 2 | B5: P82142 | C5: KHI/HO/D/MO/PC TPP/P/82142/01/2024 | D5: LED-18-4855 | E5: T/C/Gli | F5: 2018 | G5: White | H5: 518965 | I5: 4144935 | J5: Mystic Tours PVT LTD | K5: 2600000 | L5: =K5*1.65/100 -> 42900 | M5: 92 | N5: =L5*M5/366 -> 10783.607
A6: 3 | B6: P82142 | C6: KHI/HO/D/MO/CV/P/82154/01/2024 | D6: LES-18-7055 | E6: T/H/VAN | F6: 2018 | G6: Beig | H6: 8691439 | I6: 13577 | J6: Mystic Tours PVT LTD | K6: 3832000 | L6: =K6*1.65/100 -> 63228 | M6: 92 | N6: =L6*M6/366 -> 15893.377
A7: 4 | B7: P82142 | C7: KHI/HO/D/MO/CV/P/82154/01/2024 | D7: LES-18-9655 | E7: T/H/VAN | F7: 2018 | G7: Beig Golden | I7: 13563 | J7: Mystic Tours PVT LTD | K7: 3840000 | L7: =K7*1.65/100 -> 63360 | M7: 92 | N7: =L7*M7/366 -> 15926.557
A8: 5 | B8: P82142 | C8: KHI/HO/D/MO/PC TPP/P/82142/01/2024 | D8: LEE-18-6155 | E8: H/C/N | F8: 2018 | G8: White | H8: 2932030 | I8: 35456 | J8: Mystic Tours PVT LTD | K8: 2627500 | L8: =K8*1.65/100 -> 43353.75 | M8: 81 | N8: =L8*M8/366 -> 9594.6824 | O8: Sold 19.09.24 | P8: =31+31+19 -> 81
A9: 6 | B9: P82142 | C9: KHI/HO/D/MO/PC TPP/P/82142/01/2024 | D9: LEE-18-5655 | E9: H/C/N | F9: 2018 | G9: White | H9: 2932026 | I9: 35453 | J9: Mystic Tours PVT LTD | K9: 2627500 | L9: =K9*1.65/100 -> 43353.75 | M9: 92 | N9: =L9*M9/366 -> 10897.664 | O9: Sold 20.08.24 | P9: claim open
A10: 7 | B10: P82142 | C10: KHI/HO/D/MO/PC TPP/P/82142/01/2024 | D10: AHW-18-688 | E10: H/C/N | F10: 2018 | G10: White | H10: 2932139 | I10: 35577 | J10: Mystic Tours PVT LTD | K10: 2627500 | L10: =K10*1.65/100 -> 43353.75 | M10: 92 | N10: =L10*M10/366 -> 10897.664
A11: 8 | B11: P82142 | C11: KHI/HO/D/MO/PC TPP/P/82142/01/2024 | D11: BMJ-977 | E11: H/C/N | F11: 2018 | G11: White | H11: 2932149 | I11: 35566 | J11: Mystic Tours PVT LTD | K11: 2627500 | L11: =K11*1.65/100 -> 43353.75 | M11: 92 | N11: =L11*M11/366 -> 10897.664
A12: 9 | B12: P82142 | C12: KHI/HO/D/MO/PC TPP/P/82142/01/2024 | D12: AHW-799 | E12: T/C/Gli | F12: 2018 | G12: Silver | H12: 520186 | I12: 4147671 | J12: Mystic Tours PVT LTD | K12: 2600000 | L12: =K12*1.65/100 -> 42900 | M12: 92 | N12: =L12*M12/366 -> 10783.607
A13: 10 | B13: P82142 | C13: KHI/HO/D/MO/PC TPP/P/82142/01/2024 | D13: BMJ-877 | E13: T/C/Gli | F13: 2018 | G13: Silver | H13: 521672 | I13: 4147524 | J13: Mystic Tours PVT LTD | K13: 2600000 | L13: =K13*1.65/100 -> 42900 | M13: 92 | N13: =L13*M13/366 -> 10783.607
A14: 11 | B14: P82072 | C14: KHI/HO/D/MO/PC TPP/P/82072/01/2024 | D14: AHX-466 | E14: T/C/Gli | F14: 2018 | G14: Silver | H14: 521914 | I14: 4147647 | J14: MUHAMMAD HUSSAIN | K14: 2600000 | L14: =K14*1.65/100 -> 42900 | M14: 92 | N14: =L14*M14/366 -> 10783.607
A15: 12 | B15: P82142 | C15: KHI/HO/D/MO/PC TPP/P/82142/01/2024 | D15: BMJ-855 | E15: T/C/Gli | F15: 2018 | G15: Silver | H15: 521971 | I15: 4147672 | J15: Mystic Tours PVT LTD | K15: 2600000 | L15: =K15*1.65/100 -> 42900 | M15: 92 | N15: =L15*M15/366 -> 10783.607
A16: 13 | B16: P82142 | C16: KHI/HO/D/MO/PC TPP/P/82142/01/2024 | D16: AHX-744 | E16: T/C/Gli | F16: 2018 | G16: White | H16: 521864 | I16: 4147451 | J16: Mystic Tours PVT LTD | K16: 2600000 | L16: =K16*1.65/100 -> 42900 | M16: 92 | N16: =L16*M16/366 -> 10783.607
A17: 14 | B17: P82142 | C17: KHI/HO/D/MO/PC TPP/P/82142/01/2024 | D17: BMK-822 | E17: T/C/Gli | F17: 2018 | G17: White | H17: 5203641 | I17: 4147453 | J17: Mystic Tours PVT LTD | K17: 2600000 | L17: =K17*1.65/100 -> 42900 | M17: 92 | N17: =L17*M17/366 -> 10783.607
A18: 15 | B18: P82142 | C18: KHI/HO/D/MO/PC TPP/P/82142/01/2024 | D18: LEF-18-2977 | E18: H/C/N | F18: 2018 | G18: White | H18: 12932715 | I18: 36561 | J18: Mystic Tours PVT LTD | K18: 2627500 | L18: =K18*1.65/100 -> 43353.75 | M18: 92 | N18: =L18*M18/366 -> 10897.664
A19: 16 | B19: P82142 | C19: KHI/HO/D/MO/PC TPP/P/82142/01/2024 | D19: BMN-922 | E19: T/C/Gli | F19: 2018 | G19: White | H19: 521565 | I19: 4147452 | J19: Mystic Tours PVT LTD | K19: 2600000 | L19: =K19*1.65/100 -> 42900 | M19: 92 | N19: =L19*M19/366 -> 10783.607
A20: 17 | B20: P82142 | C20: KHI/HO/D/MO/PC TPP/P/82142/01/2024 | D20: BMN-588 | E20: T/C/Gli | F20: 2018 | G20: White | H20: 522096 | I20: 4148707 | J20: Mystic Tours PVT LTD | K20: 2600000 | L20: =K20*1.65/100 -> 42900 | M20: 92 | N20: =L20*M20/366 -> 10783.607
A21: 18 | B21: P82142 | C21: KHI/HO/D/MO/PC TPP/P/82142/01/2024 | D21: BMP-255 | E21: T/C/Gli | F21: 2018 | G21: Silver | H21: 522118 | I21: 4148582 | J21: Mystic Tours PVT LTD | K21: 2600000 | L21: =K21*1.65/100 -> 42900 | M21: 92 | N21: =L21*M21/366 -> 10783.607
A22: 19 | B22: P82142 | C22: KHI/HO/D/MO/PC TPP/P/82142/01/2024 | D22: LEF-18-3177 | E22: T/C/Gli | F22: 2018 | G22: Silver | H22: 522593 | I22: 4148563 | J22: Mystic Tours PVT LTD | K22: 2600000 | L22: =K22*1.65/100 -> 42900 | M22: 92 | N22: =L22*M22/366 -> 10783.607
A23: 20 | B23: P82142 | C23: KHI/HO/D/MO/PC TPP/P/82142/01/2024 | D23: LEF-18-1455 | E23: T/C/Gli | F23: 2018 | G23: Silver | H23: 523162 | I23: 4148951 | J23: Mystic Tours PVT LTD | K23: 2600000 | L23: =K23*1.65/100 -> 42900 | M23: 92 | N23: =L23*M23/366 -> 10783.607
A24: 21 | B24: P82142 | C24: KHI/HO/D/MO/PC TPP/P/82142/01/2024 | D24: AHK-988 | E24: T/C/GLI | F24: 2018 | G24: White | H24: 522399 | I24: 4148708 | J24: Mystic Tours PVT LTD | K24: 2600000 | L24: =K24*1.65/100 -> 42900 | M24: 92 | N24: =L24*M24/366 -> 10783.607
A25: 22 | B25: P82142 | C25: KHI/HO/D/MO/PC TPP/P/82142/01/2024 | D25: LEF-18-4077 | E25: T/C/GLI | F25: 2018 | G25: White | H25: 523328 | I25: 4149099 | J25: Mystic Tours PVT LTD | K25: 2600000 | L25: =K25*1.65/100 -> 42900 | M25: 92 | N25: =L25*M25/366 -> 10783.607
A26: 23 | B26: P82142 | C26: KHI/HO/D/MO/PC TPP/P/82142/01/2024 | D26: LEF-18-3877 | E26: T/C/GLI | F26: 2018 | G26: White | H26: 522715 | I26: 4148581 | J26: Mystic Tours PVT LTD | K26: 2600000 | L26: =K26*1.65/100 -> 42900 | M26: 92 | N26: =L26*M26/366 -> 10783.607
A27: 24 | B27: P82142 | C27: KHI/HO/D/MO/PC TPP/P/82142/01/2024 | D27: LEF-18-4177 | E27: T/C/GLI | F27: 2018 | G27: White | H27: 4149098 | I27: 522882 | J27: Mystic Tours PVT LTD | K27: 2600000 | L27: =K27*1.65/100 -> 42900 | M27: 92 | N27: =L27*M27/366 -> 10783.607
A28: 25 | B28: P82142 | C28: KHI/HO/D/MO/PC TPP/P/82142/01/2024 | D28: AJF-955 | E28: T/C/GLI | F28: 2018 | G28: White | H28: 523361 | I28: 4149127 | J28: Mystic Tours PVT LTD | K28: 2600000 | L28: =K28*1.65/100 -> 42900 | M28: 92 | N28: =L28*M28/366 -> 10783.607
A29: 26 | B29: P82142 | C29: KHI/HO/D/MO/PC TPP/P/82142/01/2024 | D29: AJD-577 | E29: T/C/GLI | F29: 2018 | G29: White | H29: 523447 | I29: 4149289 | J29: Mystic Tours PVT LTD | K29: 2600000 | L29: =K29*1.65/100 -> 42900 | M29: 92 | N29: =L29*M29/366 -> 10783.607
A30: 27 | B30: P82142 | C30: KHI/HO/D/MO/PC TPP/P/82142/01/2024 | D30: AJF-944 | E30: T/C/GLI | F30: 2018 | G30: White | H30: 523155 | I30: 4149079 | J30: Mystic Tours PVT LTD | K30: 2600000 | L30: =K30*1.65/100 -> 42900 | M30: 92 | N30: =L30*M30/366 -> 10783.607
A31: 28 | B31: P82142 | C31: KHI/HO/D/MO/PC TPP/P/82142/01/2024 | D31: LEF-18-6577 | E31: T/C/GLI | F31: 2018 | G31: White | H31: 522692 | I31: 4149097 | J31: Mystic Tours PVT LTD | K31: 2600000 | L31: =K31*1.65/100 -> 42900 | M31: 92 | N31: =L31*M31/366 -> 10783.607
A32: 29 | B32: P82142 | C32: KHI/HO/D/MO/PC TPP/P/82142/01/2024 | D32: LEF-18-6277 | E32: T/C/GLI | F32: 2018 | G32: White | H32: 523152 | I32: 4149100 | J32: Mystic Tours PVT LTD | K32: 2600000 | L32: =K32*1.65/100 -> 42900 | M32: 92 | N32: =L32*M32/366 -> 10783.607
A33: 30 | B33: P82142 | C33: KHI/HO/D/MO/PC TPP/P/82142/01/2024 | D33: AMX-001 | E33: FORTUNER | F33: 2020 | G33: White | H33: 828738 | I33: 1093495 | J33: Mystic Tours PVT LTD | K33: 9189000 | L33: =K33*1.65/100 -> 151618.5 | M33: 92 | N33: =L33*M33/366 -> 38111.754
A34: 31 | B34: P82142 | C34: KHI/HO/D/MO/PC TPP/P/82142/01/2024 | D34: ASW-293 | E34: Yaris 1.3 | F34: 2021 | G34: White | H34: 18277 | I34: 7010909 | J34: Mystic Tours PVT LTD | K34: 2753000 | L34: =K34*1.65/100 -> 45424.5 | M34: 92 | N34: =L34*M34/366 -> 11418.18
A35: 32 | B35: P82142 | C35: KHI/HO/D/MO/PC TPP/P/82142/01/2024 | D35: ASW-296 | E35: Yaris 1.3 | F35: 2021 | G35: Black | H35: 18780 | I35: 7011084 | J35: Mystic Tours PVT LTD | K35: 2753000 | L35: =K35*1.65/100 -> 45424.5 | M35: 92 | N35: =L35*M35/366 -> 11418.18
... A40: 37 | B40: P82142 | C40: KHI/HO/D/MO/CV/P/82154/01/2024 | D40: LES-20-9355 | E40: T/HT/D | F40: 2020 | G40: White | H40: 8440786 | I40: 906004775 | J40: Mystic Tours PVT LTD | K40: 8100000 | L40: =K40*1.65/100 -> 133650 | M40: 92 | N40: =L40*M40/366 -> 33595.082
A41: 38 | B41: P82142 | C41: KHI/HO/D/MO/PC TPP/P/82206/01/2024 | D41: ALD-001 | E41: Mercedes | F41: 2019 | G41: Black | H41: 274920-31-727865 | I41: WDD-213042-2A-593548 | J41: Mystic Tours PVT LTD | K41: 22000000 | L41: =K41*1.65/100 -> 363000 | M41: 92 | N41: =L41*M41/366 -> 91245.902
A42: 39 | B42: P82142 | C42: KHI/HO/D/MO/PC TPP/P/82142/01/2024 | D42: KX-8577 | E42: Vigo | F42: 2018 | G42: White | H42: 1GD0545900 | I42: 5533330 | J42: Mystic Tours PVT LTD | K42: 4565000 | L42: =K42*1.65/100 -> 75322.5 | M42: 92 | N42: =L42*M42/366 -> 18933.525
A43: 40 | B43: P82142 | C43: KHI/HO/D/MO/PC TPP/P/82142/01/2024 | D43: KX-7277 | E43: Vigo | F43: 2018 | G43: White | H43: 1GD0545919 | I43: 5533331 | J43: Mystic Tours PVT LTD | K43: 4565000 | L43: =K43*1.65/100 -> 75322.5 | M43: 92 | N43: =L43*M43/366 -> 18933.525
A44: 41 | B44: P82142 | C44: KHI/HO/D/MO/PC TPP/P/82142/01/2024 | D44: KX-7355 | E44: Vigo | F44: 2018 | G44: White | H44: 1GD0545855 | I44: 5533283 | J44: Mystic Tours PVT LTD | K44: 4565000 | L44: =K44*1.65/100 -> 75322.5 | M44: 92 | N44: =L44*M44/366 -> 18933.525
...

Sheet 4th
A1: Salaam Takaful 4th Quarter 2024 | O1: 92 DAYS
A2: 1st October to 31 December 2024
A3: Sr. # | B3: PMD# | C3: Policy # 2024 | D3: Reg. # | E3: Make | F3: Model | G3: Colour | H3: Engine # | J3: Chassis # | K3: Owner | L3: Sum Insured | M3: Ins Rat 1.65% | N3: Days | O3: 4th Installment
A4: 1 | B4: P82142 | C4: KHI/HO/D/MO/PC TPP/P/82142/01/2024 | D4: LED-18-6255 | E4: T/C/Gli | F4: 2018 | G4: White | H4: 518514 | J4: 4144559 | K4: Mystic Tours PVT LTD | L4: 2600000 | M4: =L4*1.65/100 -> 42900 | N4: 92 | O4: 10783.607
A5: 2 | B5: P82142 | C5: KHI/HO/D/MO/PC TPP/P/82142/01/2024 | D5: LED-18-4855 | E5: T/C/Gli | F5: 2018 | G5: White | H5: 518965 | J5: 4144935 | K5: Mystic Tours PVT LTD | L5: 2600000 | M5: =L5*1.65/100 -> 42900 | N5: 92 | O5: 10783.607
A6: 3 | B6: P82142 | C6: KHI/HO/D/MO/CV/P/82154/01/2024 | D6: LES-18-7055 | E6: T/H/VAN | F6: 2018 | G6: Beig | H6: 8691439 | J6: 13577 | K6: Mystic Tours PVT LTD | L6: 3832000 | M6: =L6*1.65/100 -> 63228 | N6: 92 | O6: 15893.377
A7: 4 | B7: P82142 | C7: KHI/HO/D/MO/CV/P/82154/01/2024 | D7: LES-18-9655 | E7: T/H/VAN | F7: 2018 | G7: Beig Golden | J7: 13563 | K7: Mystic Tours PVT LTD | L7: 3840000 | M7: =L7*1.65/100 -> 63360 | N7: 92 | O7: 15926.557
A8: 5 | B8: P82142 | C8: KHI/HO/D/MO/PC TPP/P/82142/01/2024 | D8: LEE-18-5655 | E8: H/C/N | F8: 2018 | G8: White | H8: 2932026 | J8: 35453 | K8: Mystic Tours PVT LTD | L8: 2627500 | M8: =L8*1.65/100 -> 43353.75 | N8: 92 | O8: 10897.664 | P8: Sold 20.08.24 | Q8: claim open
A9: 6 | B9: P82142 | C9: KHI/HO/D/MO/PC TPP/P/82142/01/2024 | D9: AHW-18-688 | E9: H/C/N | F9: 2018 | G9: White | H9: 2932139 | J9: 35577 | K9: Mystic Tours PVT LTD | L9: 2627500 | M9: =L9*1.65/100 -> 43353.75 | N9: 92 | O9: 10897.664
A10: 7 | B10: P82142 | C10: KHI/HO/D/MO/PC TPP/P/82142/01/2024 | D10: BMJ-977 | E10: H/C/N | F10: 2018 | G10: White | H10: 2932149 | J10: 35566 | K10: Mystic Tours PVT LTD | L10: 2627500 | M10: =L10*1.65/100 -> 43353.75 | N10: 92 | O10: 10897.664
A11: 8 | B11: P82142 | C11: KHI/HO/D/MO/PC TPP/P/82142/01/2024 | D11: AHW-799 | E11: T/C/Gli | F11: 2018 | G11: Silver | H11: 520186 | J11: 4147671 | K11: Mystic Tours PVT LTD | L11: 2600000 | M11: =L11*1.65/100 -> 42900 | N11: 92 | O11: 10783.607
A12: 9 | B12: P82142 | C12: KHI/HO/D/MO/PC TPP/P/82142/01/2024 | D12: BMJ-877 | E12: T/C/Gli | F12: 2018 | G12: Silver | H12: 521672 | J12: 4147524 | K12: Mystic Tours PVT LTD | L12: 2600000 | M12: =L12*1.65/100 -> 42900 | N12: 92 | O12: 10783.607
A13: 10 | B13: P82072 | C13: KHI/HO/D/MO/PC TPP/P/82072/01/2024 | D13: AHX-466 | E13: T/C/Gli | F13: 2018 | G13: Silver | H13: 521914 | J13: 4147647 | K13: MUHAMMAD HUSSAIN | L13: 2600000 | M13: =L13*1.65/100 -> 42900 | N13: 92 | O13: 10783.607
A14: 11 | B14: P82142 | C14: KHI/HO/D/MO/PC TPP/P/82142/01/2024 | D14: BMJ-855 | E14: T/C/Gli | F14: 2018 | G14: Silver | H14: 521971 | J14: 4147672 | K14: Mystic Tours PVT LTD | L14: 2600000 | M14: =L14*1.65/100 -> 42900 | N14: 92 | O14: 10783.607
A15: 12 | B15: P82142 | C15: KHI/HO/D/MO/PC TPP/P/82142/01/2024 | D15: AHX-744 | E15: T/C/Gli | F15: 2018 | G15: White | H15: 521864 | J15: 4147451 | K15: Mystic Tours PVT LTD | L15: 2600000 | M15: =L15*1.65/100 -> 42900 | N15: 92 | O15: 10783.607
A16: 13 | B16: P82142 | C16: KHI/HO/D/MO/PC TPP/P/82142/01/2024 | D16: BMK-822 | E16: T/C/Gli | F16: 2018 | G16: White | H16: 5203641 | J16: 4147453 | K16: Mystic Tours PVT LTD | L16: 2600000 | M16: =L16*1.65/100 -> 42900 | N16: 92 | O16: 10783.607
A17: 14 | B17: P82142 | C17: KHI/HO/D/MO/PC TPP/P/82142/01/2024 | D17: LEF-18-2977 | E17: H/C/N | F17: 2018 | G17: White | H17: 12932715 | J17: 36561 | K17: Mystic Tours PVT LTD | L17: 2627500 | M17: =L17*1.65/100 -> 43353.75 | N17: 92 | O17: 10897.664
A18: 15 | B18: P82142 | C18: KHI/HO/D/MO/PC TPP/P/82142/01/2024 | D18: BMN-922 | E18: T/C/Gli | F18: 2018 | G18: White | H18: 521565 | J18: 4147452 | K18: Mystic Tours PVT LTD | L18: 2600000 | M18: =L18*1.65/100 -> 42900 | N18: 92 | O18: 10783.607
A19: 16 | B19: P82142 | C19: KHI/HO/D/MO/PC TPP/P/82142/01/2024 | D19: BMN-588 | E19: T/C/Gli | F19: 2018 | G19: White | H19: 522096 | J19: 4148707 | K19: Mystic Tours PVT LTD | L19: 2600000 | M19: =L19*1.65/100 -> 42900 | N19: 92 | O19: 10783.607
A20: 17 | B20: P82142 | C20: KHI/HO/D/MO/PC TPP/P/82142/01/2024 | D20: BMP-255 | E20: T/C/Gli | F20: 2018 | G20: Silver | H20: 522118 | J20: 4148582 | K20: Mystic Tours PVT LTD | L20: 2600000 | M20: =L20*1.65/100 -> 42900 | N20: 92 | O20: 10783.607
A21: 18 | B21: P82142 | C21: KHI/HO/D/MO/PC TPP/P/82142/01/2024 | D21: LEF-18-3177 | E21: T/C/Gli | F21: 2018 | G21: Silver | H21: 522593 | J21: 4148563 | K21: Mystic Tours PVT LTD | L21: 2600000 | M21: =L21*1.65/100 -> 42900 | N21: 92 | O21: 10783.607
A22: 19 | B22: P82142 | C22: KHI/HO/D/MO/PC TPP/P/82142/01/2024 | D22: LEF-18-1455 | E22: T/C/Gli | F22: 2018 | G22: Silver | H22: 523162 | J22: 4148951 | K22: Mystic Tours PVT LTD | L22: 2600000 | M22: =L22*1.65/100 -> 42900 | N22: 92 | O22: 10783.607
A23: 20 | B23: P82142 | C23: KHI/HO/D/MO/PC TPP/P/82142/01/2024 | D23: AHK-988 | E23: T/C/GLI | F23: 2018 | G23: White | H23: 522399 | J23: 4148708 | K23: Mystic Tours PVT LTD | L23: 2600000 | M23: =L23*1.65/100 -> 42900 | N23: 92 | O23: 10783.607
A24: 21 | B24: P82142 | C24: KHI/HO/D/MO/PC TPP/P/82142/01/2024 | D24: LEF-18-4077 | E24: T/C/GLI | F24: 2018 | G24: White | H24: 523328 | J24: 4149099 | K24: Mystic Tours PVT LTD | L24: 2600000 | M24: =L24*1.65/100 -> 42900 | N24: 92 | O24: 10783.607
A25: 22 | B25: P82142 | C25: KHI/HO/D/MO/PC TPP/P/82142/01/2024 | D25: LEF-18-3877 | E25: T/C/GLI | F25: 2018 | G25: White | H25: 522715 | J25: 4148581 | K25: Mystic Tours PVT LTD | L25: 2600000 | M25: =L25*1.65/100 -> 42900 | N25: 92 | O25: 10783.607
A26: 23 | B26: P82142 | C26: KHI/HO/D/MO/PC TPP/P/82142/01/2024 | D26: LEF-18-4177 | E26: T/C/GLI | F26: 2018 | G26: White | H26: 4149098 | J26: 522882 | K26: Mystic Tours PVT LTD | L26: 2600000 | M26: =L26*1.65/100 -> 42900 | N26: 92 | O26: 10783.607
A27: 24 | B27: P82142 | C27: KHI/HO/D/MO/PC TPP/P/82142/01/2024 | D27: AJF-955 | E27: T/C/GLI | F27: 2018 | G27: White | H27: 523361 | J27: 4149127 | K27: Mystic Tours PVT LTD | L27: 2600000 | M27: =L27*1.65/100 -> 42900 | N27: 92 | O27: 10783.607
A28: 25 | B28: P82142 | C28: KHI/HO/D/MO/PC TPP/P/82142/01/2024 | D28: AJD-577 | E28: T/C/GLI | F28: 2018 | G28: White | H28: 523447 | J28: 4149289 | K28: Mystic Tours PVT LTD | L28: 2600000 | M28: =L28*1.65/100 -> 42900 | N28: 92 | O28: 10783.607
A29: 26 | B29: P82142 | C29: KHI/HO/D/MO/PC TPP/P/82142/01/2024 | D29: AJF-944 | E29: T/C/GLI | F29: 2018 | G29: White | H29: 523155 | J29: 4149079 | K29: Mystic Tours PVT LTD | L29: 2600000 | M29: =L29*1.65/100 -> 42900 | N29: 92 | O29: 10783.607
A30: 27 | B30: P82142 | C30: KHI/HO/D/MO/PC TPP/P/82142/01/2024 | D30: LEF-18-6577 | E30: T/C/GLI | F30: 2018 | G30: White | H30: 522692 | J30: 4149097 | K30: Mystic Tours PVT LTD | L30: 2600000 | M30: =L30*1.65/100 -> 42900 | N30: 92 | O30: 10783.607
A31: 28 | B31: P82142 | C31: KHI/HO/D/MO/PC TPP/P/82142/01/2024 | D31: LEF-18-6277 | E31: T/C/GLI | F31: 2018 | G31: White | H31: 523152 | J31: 4149100 | K31: Mystic Tours PVT LTD | L31: 2600000 | M31: =L31*1.65/100 -> 42900 | N31: 92 | O31: 10783.607
A32: 29 | B32: P82142 | C32: KHI/HO/D/MO/PC TPP/P/82142/01/2024 | D32: AMX-001 | E32: FORTUNER | F32: 2020 | G32: White | H32: 828738 | J32: 1093495 | K32: Mystic Tours PVT LTD | L32: 9189000 | M32: =L32*1.65/100 -> 151618.5 | N32: 92 | O32: 38111.754
A33: 30 | B33: P82142 | C33: KHI/HO/D/MO/PC TPP/P/82142/01/2024 | D33: ASW-293 | E33: Yaris 1.3 | F33: 2021 | G33: White | H33: 18277 | J33: 7010909 | K33: Mystic Tours PVT LTD | L33: 2753000 | M33: =L33*1.65/100 -> 45424.5 | N33: 92 | O33: 11418.18
A34: 31 | B34: P82142 | C34: KHI/HO/D/MO/PC TPP/P/82142/01/2024 | D34: ASW-296 | E34: Yaris 1.3 | F34: 2021 | G34: Black | H34: 18780 | J34: 7011084 | K34: Mystic Tours PVT LTD | L34: 2753000 | M34: =L34*1.65/100 -> 45424.5 | N34: 92 | O34: 11418.18
A35: 32 | B35: P82142 | C35: KHI/HO/D/MO/PC TPP/P/82142/01/2024 | D35: ASW-289 | E35: Yaris 1.3 | F35: 2021 | G35: White | H35: 18255 | J35: 7010908 | K35: Mystic Tours PVT LTD | L35: 2753000 | M35: =L35*1.65/100 -> 45424.5 | N35: 92 | O35: 11418.18
A36: 33 | B36: P82078 | C36: KHI/HO/D/MO/PC TPP/P/82078/01/2024 | D36: AJH-989 | E36: T/C/GLI | F36: 2018 | G36: White | H36: 523251 | J36: 4149080 | K36: Ayaz Hussain | L36: 2600000 | M36: =L36*1.65/100 -> 42900 | N36: 92 | O36: 10783.607 | P36: SOLD 16.12.24
A37: 34 | B37: P82068 | C37: KHI/HO/D/MO/PC TPP/P/82068/01/2024 | D37: LEF-18-8377 | E37: T/C/GLI | F37: 2018 | G37: White | H37: 522458 | J37: 4148953 | K37: Nosheen Mudasar | L37: 2600000 | M37: =L37*1.65/100 -> 42900 | N37: 92 | O37: 10783.607
A38: 35 | B38: P82142 | C38: KHI/HO/D/MO/CV/P/82154/01/2024 | D38: LES-20-8955 | E38: T/HT/D | F38: 2020 | G38: White | H38: 8413639 | J38: 306003637 | K38: Mystic Tours PVT LTD | L38: 8100000 | M38: =L38*1.65/100 -> 133650 | N38: 92 | O38: 33595.082
A39: 36 | B39: P82142 | C39: KHI/HO/D/MO/CV/P/82154/01/2024 | D39: LES-20-9355 | E39: T/HT/D | F39: 2020 | G39: White | H39: 8440786 | J39: 906004775 | K39: Mystic Tours PVT LTD | L39: 8100000 | M39: =L39*1.65/100 -> 133650 | N39: 92 | O39: 33595.082
A40: 37 | B40: P82142 | C40: KHI/HO/D/MO/PC TPP/P/82206/01/2024 | D40: ALD-001 | E40: Mercedes | F40: 2019 | G40: Black | H40: 274920-31-727865 | J40: WDD-213042-2A-593548 | K40: Mystic Tours PVT LTD | L40: 22000000 | M40: =L40*1.65/100 -> 363000 | N40: 92 | O40: 91245.902
...

Sheet working
A1: POLICY NO. | B1: Assorted_code | D1: Premium | E1: 20Jan250035
A2: KHI/HO/D/MO/PC TPP/P/82142/01/2024 | B2: =VLOOKUP(A2,policy!B:C,2,0) -> 040000163656 | C2: 10783.607 | D2: =ROUND(C2,0) -> 10784 | E2: 20Jan250035 | F2: ="insert into ins_premium_det (premium_rcv_code,assorted_code, rec_amount,premium_rcv_detail_code,remaining_amt, payrec, mode_code,coinsurance_code,class_cd,it_remarks) values" -> insert into ins_premium_det (premium_rcv_code,assorted_code, rec_amount,premium_rcv_detail_code,remaining_amt, payrec, mode_code,coinsurance_code,class_cd,it_remarks) values | G2: ="('"&E2&"','"&B2&"','"&D2&"',(select max(to_number(i.premium_rcv_detail_code))+1 from ins_premium_det i),'"&D2&"','"&D2&"','02', '11000003','00','Request by Mr. Saqib Saleem 21-Jan-2025');" -> ('20Jan250035','040000163656','10784',(select max(to_number(i.premium_rcv_detail_code))+1 from ins_premium_det i),'10784','10784','02', '11000003','00','Request by Mr. Saqib Saleem 21-Jan-2025'); | H2: =F2&G2 -> insert into ins_premium_det (premium_rcv_code,assorted_code, rec_amount,premium_rcv_detail_code,remaining_amt, payrec, mode_code,coinsurance_code,class_cd,it_remarks) values('20Jan250035','040000163656','10784',(select max(to_number(i.premium_rcv_detail_code))+1 from ins_premium_det i),'10784','10784','02', '11000003','00','Request by Mr. Saqib Saleem 21-Jan-2025');
A3: KHI/HO/D/MO/PC TPP/P/82142/01/2024 | B3: =VLOOKUP(A3,policy!B:C,2,0) -> 040000163656 | C3: 10783.607 | D3: =ROUND(C3,0) -> 10784 | E3: 20Jan250035 | F3: ="insert into ins_premium_det (premium_rcv_code,assorted_code, rec_amount,premium_rcv_detail_code,remaining_amt, payrec, mode_code,coinsurance_code,class_cd,it_remarks) values" -> insert into ins_premium_det (premium_rcv_code,assorted_code, rec_amount,premium_rcv_detail_code,remaining_amt, payrec, mode_code,coinsurance_code,class_cd,it_remarks) values | G3: ="('"&E3&"','"&B3&"','"&D3&"',(select max(to_number(i.premium_rcv_detail_code))+1 from ins_premium_det i),'"&D3&"','"&D3&"','02', '11000003','00','Request by Mr. Saqib Saleem 21-Jan-2025');" -> ('20Jan250035','040000163656','10784',(select max(to_number(i.premium_rcv_detail_code))+1 from ins_premium_det i),'10784','10784','02', '11000003','00','Request by Mr. Saqib Saleem 21-Jan-2025'); | H3: =F3&G3 -> insert into ins_premium_det (premium_rcv_code,assorted_code, rec_amount,premium_rcv_detail_code,remaining_amt, payrec, mode_code,coinsurance_code,class_cd,it_remarks) values('20Jan250035','040000163656','10784',(select max(to_number(i.premium_rcv_detail_code))+1 from ins_premium_det i),'10784','10784','02', '11000003','00','Request by Mr. Saqib Saleem 21-Jan-2025');
A4: KHI/HO/D/MO/CV/P/82154/01/2024 | B4: =VLOOKUP(A4,policy!B:C,2,0) -> 040000163671 | C4: 15893.377 | D4: =ROUND(C4,0) -> 15893 | E4: 20Jan250035 | F4: ="insert into ins_premium_det (premium_rcv_code,assorted_code, rec_amount,premium_rcv_detail_code,remaining_amt, payrec, mode_code,coinsurance_code,class_cd,it_remarks) values" -> insert into ins_premium_det (premium_rcv_code,assorted_code, rec_amount,premium_rcv_detail_code,remaining_amt, payrec, mode_code,coinsurance_code,class_cd,it_remarks) values | G4: ="('"&E4&"','"&B4&"','"&D4&"',(select max(to_number(i.premium_rcv_detail_code))+1 from ins_premium_det i),'"&D4&"','"&D4&"','02', '11000003','00','Request by Mr. Saqib Saleem 21-Jan-2025');" -> ('20Jan250035','040000163671','15893',(select max(to_number(i.premium_rcv_detail_code))+1 from ins_premium_det i),'15893','15893','02', '11000003','00','Request by Mr. Saqib Saleem 21-Jan-2025'); | H4: =F4&G4 -> insert into ins_premium_det (premium_rcv_code,assorted_code, rec_amount,premium_rcv_detail_code,remaining_amt, payrec, mode_code,coinsurance_code,class_cd,it_remarks) values('20Jan250035','040000163671','15893',(select max(to_number(i.premium_rcv_detail_code))+1 from ins_premium_det i),'15893','15893','02', '11000003','00','Request by Mr. Saqib Saleem 21-Jan-2025');
A5: KHI/HO/D/MO/CV/P/82154/01/2024 | B5: =VLOOKUP(A5,policy!B:C,2,0) -> 040000163671 | C5: 15926.557 | D5: =ROUND(C5,0) -> 15927 | E5: 20Jan250035 | F5: ="insert into ins_premium_det (premium_rcv_code,assorted_code, rec_amount,premium_rcv_detail_code,remaining_amt, payrec, mode_code,coinsurance_code,class_cd,it_remarks) values" -> insert into ins_premium_det (premium_rcv_code,assorted_code, rec_amount,premium_rcv_detail_code,remaining_amt, payrec, mode_code,coinsurance_code,class_cd,it_remarks) values | G5: ="('"&E5&"','"&B5&"','"&D5&"',(select max(to_number(i.premium_rcv_detail_code))+1 from ins_premium_det i),'"&D5&"','"&D5&"','02', '11000003','00','Request by Mr. Saqib Saleem 21-Jan-2025');" -> ('20Jan250035','040000163671','15927',(select max(to_number(i.premium_rcv_detail_code))+1 from ins_premium_det i),'15927','15927','02', '11000003','00','Request by Mr. Saqib Saleem 21-Jan-2025'); | H5: =F5&G5 -> insert into ins_premium_det (premium_rcv_code,assorted_code, rec_amount,premium_rcv_detail_code,remaining_amt, payrec, mode_code,coinsurance_code,class_cd,it_remarks) values('20Jan250035','040000163671','15927',(select max(to_number(i.premium_rcv_detail_code))+1 from ins_premium_det i),'15927','15927','02', '11000003','00','Request by Mr. Saqib Saleem 21-Jan-2025');
A6: KHI/HO/D/MO/PC TPP/P/82142/01/2024 | B6: =VLOOKUP(A6,policy!B:C,2,0) -> 040000163656 | C6: 10897.664 | D6: =ROUND(C6,0) -> 10898 | E6: 20Jan250035 | F6: ="insert into ins_premium_det (premium_rcv_code,assorted_code, rec_amount,premium_rcv_detail_code,remaining_amt, payrec, mode_code,coinsurance_code,class_cd,it_remarks) values" -> insert into ins_premium_det (premium_rcv_code,assorted_code, rec_amount,premium_rcv_detail_code,remaining_amt, payrec, mode_code,coinsurance_code,class_cd,it_remarks) values | G6: ="('"&E6&"','"&B6&"','"&D6&"',(select max(to_number(i.premium_rcv_detail_code))+1 from ins_premium_det i),'"&D6&"','"&D6&"','02', '11000003','00','Request by Mr. Saqib Saleem 21-Jan-2025');" -> ('20Jan250035','040000163656','10898',(select max(to_number(i.premium_rcv_detail_code))+1 from ins_premium_det i),'10898','10898','02', '11000003','00','Request by Mr. Saqib Saleem 21-Jan-2025'); | H6: =F6&G6 -> insert into ins_premium_det (premium_rcv_code,assorted_code, rec_amount,premium_rcv_detail_code,remaining_amt, payrec, mode_code,coinsurance_code,class_cd,it_remarks) values('20Jan250035','040000163656','10898',(select max(to_number(i.premium_rcv_detail_code))+1 from ins_premium_det i),'10898','10898','02', '11000003','00','Request by Mr. Saqib Saleem 21-Jan-2025');
A7: KHI/HO/D/MO/PC TPP/P/82142/01/2024 | B7: =VLOOKUP(A7,policy!B:C,2,0) -> 040000163656 | C7: 10897.664 | D7: =ROUND(C7,0) -> 10898 | E7: 20Jan250035 | F7: ="insert into ins_premium_det (premium_rcv_code,assorted_code, rec_amount,premium_rcv_detail_code,remaining_amt, payrec, mode_code,coinsurance_code,class_cd,it_remarks) values" -> insert into ins_premium_det (premium_rcv_code,assorted_code, rec_amount,premium_rcv_detail_code,remaining_amt, payrec, mode_code,coinsurance_code,class_cd,it_remarks) values | G7: ="('"&E7&"','"&B7&"','"&D7&"',(select max(to_number(i.premium_rcv_detail_code))+1 from ins_premium_det i),'"&D7&"','"&D7&"','02', '11000003','00','Request by Mr. Saqib Saleem 21-Jan-2025');" -> ('20Jan250035','040000163656','10898',(select max(to_number(i.premium_rcv_detail_code))+1 from ins_premium_det i),'10898','10898','02', '11000003','00','Request by Mr. Saqib Saleem 21-Jan-2025'); | H7: =F7&G7 -> insert into ins_premium_det (premium_rcv_code,assorted_code, rec_amount,premium_rcv_detail_code,remaining_amt, payrec, mode_code,coinsurance_code,class_cd,it_remarks) values('20Jan250035','040000163656','10898',(select max(to_number(i.premium_rcv_detail_code))+1 from ins_premium_det i),'10898','10898','02', '11000003','00','Request by Mr. Saqib Saleem 21-Jan-2025');
A8: KHI/HO/D/MO/PC TPP/P/82142/01/2024 | B8: =VLOOKUP(A8,policy!B:C,2,0) -> 040000163656 | C8: 10897.664 | D8: =ROUND(C8,0) -> 10898 | E8: 20Jan250035 | F8: ="insert into ins_premium_det (premium_rcv_code,assorted_code, rec_amount,premium_rcv_detail_code,remaining_amt, payrec, mode_code,coinsurance_code,class_cd,it_remarks) values" -> insert into ins_premium_det (premium_rcv_code,assorted_code, rec_amount,premium_rcv_detail_code,remaining_amt, payrec, mode_code,coinsurance_code,class_cd,it_remarks) values | G8: ="('"&E8&"','"&B8&"','"&D8&"',(select max(to_number(i.premium_rcv_detail_code))+1 from ins_premium_det i),'"&D8&"','"&D8&"','02', '11000003','00','Request by Mr. Saqib Saleem 21-Jan-2025');" -> ('20Jan250035','040000163656','10898',(select max(to_number(i.premium_rcv_detail_code))+1 from ins_premium_det i),'10898','10898','02', '11000003','00','Request by Mr. Saqib Saleem 21-Jan-2025'); | H8: =F8&G8 -> insert into ins_premium_det (premium_rcv_code,assorted_code, rec_amount,premium_rcv_detail_code,remaining_amt, payrec, mode_code,coinsurance_code,class_cd,it_remarks) values('20Jan250035','040000163656','10898',(select max(to_number(i.premium_rcv_detail_code))+1 from ins_premium_det i),'10898','10898','02', '11000003','00','Request by Mr. Saqib Saleem 21-Jan-2025');
A9: KHI/HO/D/MO/PC TPP/P/82142/01/2024 | B9: =VLOOKUP(A9,policy!B:C,2,0) -> 040000163656 | C9: 10783.607 | D9: =ROUND(C9,0) -> 10784 | E9: 20Jan250035 | F9: ="insert into ins_premium_det (premium_rcv_code,assorted_code, rec_amount,premium_rcv_detail_code,remaining_amt, payrec, mode_code,coinsurance_code,class_cd,it_remarks) values" -> insert into ins_premium_det (premium_rcv_code,assorted_code, rec_amount,premium_rcv_detail_code,remaining_amt, payrec, mode_code,coinsurance_code,class_cd,it_remarks) values | G9: ="('"&E9&"','"&B9&"','"&D9&"',(select max(to_number(i.premium_rcv_detail_code))+1 from ins_premium_det i),'"&D9&"','"&D9&"','02', '11000003','00','Request by Mr. Saqib Saleem 21-Jan-2025');" -> ('20Jan250035','040000163656','10784',(select max(to_number(i.premium_rcv_detail_code))+1 from ins_premium_det i),'10784','10784','02', '11000003','00','Request by Mr. Saqib Saleem 21-Jan-2025'); | H9: =F9&G9 -> insert into ins_premium_det (premium_rcv_code,assorted_code, rec_amount,premium_rcv_detail_code,remaining_amt, payrec, mode_code,coinsurance_code,class_cd,it_remarks) values('20Jan250035','040000163656','10784',(select max(to_number(i.premium_rcv_detail_code))+1 from ins_premium_det i),'10784','10784','02', '11000003','00','Request by Mr. Saqib Saleem 21-Jan-2025');
A10: KHI/HO/D/MO/PC TPP/P/82142/01/2024 | B10: =VLOOKUP(A10,policy!B:C,2,0) -> 040000163656 | C10: 10783.607 | D10: =ROUND(C10,0) -> 10784 | E10: 20Jan250035 | F10: ="insert into ins_premium_det (premium_rcv_code,assorted_code, rec_amount,premium_rcv_detail_code,remaining_amt, payrec, mode_code,coinsurance_code,class_cd,it_remarks) values" -> insert into ins_premium_det (premium_rcv_code,assorted_code, rec_amount,premium_rcv_detail_code,remaining_amt, payrec, mode_code,coinsurance_code,class_cd,it_remarks) values | G10: ="('"&E10&"','"&B10&"','"&D10&"',(select max(to_number(i.premium_rcv_detail_code))+1 from ins_premium_det i),'"&D10&"','"&D10&"','02', '11000003','00','Request by Mr. Saqib Saleem 21-Jan-2025');" -> ('20Jan250035','040000163656','10784',(select max(to_number(i.premium_rcv_detail_code))+1 from ins_premium_det i),'10784','10784','02', '11000003','00','Request by Mr. Saqib Saleem 21-Jan-2025'); | H10: =F10&G10 -> insert into ins_premium_det (premium_rcv_code,assorted_code, rec_amount,premium_rcv_detail_code,remaining_amt, payrec, mode_code,coinsurance_code,class_cd,it_remarks) values('20Jan250035','040000163656','10784',(select max(to_number(i.premium_rcv_detail_code))+1 from ins_premium_det i),'10784','10784','02', '11000003','00','Request by Mr. Saqib Saleem 21-Jan-2025');
A11: KHI/HO/D/MO/PC TPP/P/82072/01/2024 | B11: =VLOOKUP(A11,policy!B:C,2,0) -> 040000163414 | C11: 10783.607 | D11: =ROUND(C11,0) -> 10784 | E11: 20Jan250035 | F11: ="insert into ins_premium_det (premium_rcv_code,assorted_code, rec_amount,premium_rcv_detail_code,remaining_amt, payrec, mode_code,coinsurance_code,class_cd,it_remarks) values" -> insert into ins_premium_det (premium_rcv_code,assorted_code, rec_amount,premium_rcv_detail_code,remaining_amt, payrec, mode_code,coinsurance_code,class_cd,it_remarks) values | G11: ="('"&E11&"','"&B11&"','"&D11&"',(select max(to_number(i.premium_rcv_detail_code))+1 from ins_premium_det i),'"&D11&"','"&D11&"','02', '11000003','00','Request by Mr. Saqib Saleem 21-Jan-2025');" -> ('20Jan250035','040000163414','10784',(select max(to_number(i.premium_rcv_detail_code))+1 from ins_premium_det i),'10784','10784','02', '11000003','00','Request by Mr. Saqib Saleem 21-Jan-2025'); | H11: =F11&G11 -> insert into ins_premium_det (premium_rcv_code,assorted_code, rec_amount,premium_rcv_detail_code,remaining_amt, payrec, mode_code,coinsurance_code,class_cd,it_remarks) values('20Jan250035','040000163414','10784',(select max(to_number(i.premium_rcv_detail_code))+1 from ins_premium_det i),'10784','10784','02', '11000003','00','Request by Mr. Saqib Saleem 21-Jan-2025');
A12: KHI/HO/D/MO/PC TPP/P/82142/01/2024 | B12: =VLOOKUP(A12,policy!B:C,2,0) -> 040000163656 | C12: 10783.607 | D12: =ROUND(C12,0) -> 10784 | E12: 20Jan250035 | F12: ="insert into ins_premium_det (premium_rcv_code,assorted_code, rec_amount,premium_rcv_detail_code,remaining_amt, payrec, mode_code,coinsurance_code,class_cd,it_remarks) values" -> insert into ins_premium_det (premium_rcv_code,assorted_code, rec_amount,premium_rcv_detail_code,remaining_amt, payrec, mode_code,coinsurance_code,class_cd,it_remarks) values | G12: ="('"&E12&"','"&B12&"','"&D12&"',(select max(to_number(i.premium_rcv_detail_code))+1 from ins_premium_det i),'"&D12&"','"&D12&"','02', '11000003','00','Request by Mr. Saqib Saleem 21-Jan-2025');" -> ('20Jan250035','040000163656','10784',(select max(to_number(i.premium_rcv_detail_code))+1 from ins_premium_det i),'10784','10784','02', '11000003','00','Request by Mr. Saqib Saleem 21-Jan-2025'); | H12: =F12&G12 -> insert into ins_premium_det (premium_rcv_code,assorted_code, rec_amount,premium_rcv_detail_code,remaining_amt, payrec, mode_code,coinsurance_code,class_cd,it_remarks) values('20Jan250035','040000163656','10784',(select max(to_number(i.premium_rcv_detail_code))+1 from ins_premium_det i),'10784','10784','02', '11000003','00','Request by Mr. Saqib Saleem 21-Jan-2025');
A13: KHI/HO/D/MO/PC TPP/P/82142/01/2024 | B13: =VLOOKUP(A13,policy!B:C,2,0) -> 040000163656 | C13: 10783.607 | D13: =ROUND(C13,0) -> 10784 | E13: 20Jan250035 | F13: ="insert into ins_premium_det (premium_rcv_code,assorted_code, rec_amount,premium_rcv_detail_code,remaining_amt, payrec, mode_code,coinsurance_code,class_cd,it_remarks) values" -> insert into ins_premium_det (premium_rcv_code,assorted_code, rec_amount,premium_rcv_detail_code,remaining_amt, payrec, mode_code,coinsurance_code,class_cd,it_remarks) values | G13: ="('"&E13&"','"&B13&"','"&D13&"',(select max(to_number(i.premium_rcv_detail_code))+1 from ins_premium_det i),'"&D13&"','"&D13&"','02', '11000003','00','Request by Mr. Saqib Saleem 21-Jan-2025');" -> ('20Jan250035','040000163656','10784',(select max(to_number(i.premium_rcv_detail_code))+1 from ins_premium_det i),'10784','10784','02', '11000003','00','Request by Mr. Saqib Saleem 21-Jan-2025'); | H13: =F13&G13 -> insert into ins_premium_det (premium_rcv_code,assorted_code, rec_amount,premium_rcv_detail_code,remaining_amt, payrec, mode_code,coinsurance_code,class_cd,it_remarks) values('20Jan250035','040000163656','10784',(select max(to_number(i.premium_rcv_detail_code))+1 from ins_premium_det i),'10784','10784','02', '11000003','00','Request by Mr. Saqib Saleem 21-Jan-2025');
... A501: KHI/HO/D/MO/PC TPP/E/50308/12/2024 | B501: =VLOOKUP(A501,policy!B:C,2,0) -> 050000835997 | C501: 2447.6217 | D501: =ROUND(C501,0) -> 2448 | E501: 20Jan250035 | F501: ="insert into ins_premium_det (premium_rcv_code,assorted_code, rec_amount,premium_rcv_detail_code,remaining_amt, payrec, mode_code,coinsurance_code,class_cd,it_remarks) values" -> insert into ins_premium_det (premium_rcv_code,assorted_code, rec_amount,premium_rcv_detail_code,remaining_amt, payrec, mode_code,coinsurance_code,class_cd,it_remarks) values | G501: ="('"&E501&"','"&B501&"','"&D501&"',(select max(to_number(i.premium_rcv_detail_code))+1 from ins_premium_det i),'"&D501&"','"&D501&"','02', '11000003','00','Request by Mr. Saqib Saleem 21-Jan-2025');" -> ('20Jan250035','050000835997','2448',(select max(to_number(i.premium_rcv_detail_code))+1 from ins_premium_det i),'2448','2448','02', '11000003','00','Request by Mr. Saqib Saleem 21-Jan-2025'); | H501: =F501&G501 -> insert into ins_premium_det (premium_rcv_code,assorted_code, rec_amount,premium_rcv_detail_code,remaining_amt, payrec, mode_code,coinsurance_code,class_cd,it_remarks) values('20Jan250035','050000835997','2448',(select max(to_number(i.premium_rcv_detail_code))+1 from ins_premium_det i),'2448','2448','02', '11000003','00','Request by Mr. Saqib Saleem 21-Jan-2025');

Sheet Sheet2
A1: KHI/HO/D/MO/PC TPP/P/82142/01/2024 | B1: -01-2024 | D1: 82142 | E1: ="ia.assorted_string like '%"&D1&B1&"%' or" -> ia.assorted_string like '%82142-01-2024%' or
A2: KHI/HO/D/MO/PC TPP/P/82142/01/2024 | B2: -01-2024 | D2: 82142 | E2: ="ia.assorted_string like '%"&D2&B2&"%' or" -> ia.assorted_string like '%82142-01-2024%' or
A3: KHI/HO/D/MO/CV/P/82154/01/2024 | B3: -01-2024 | D3: 82154 | E3: ="ia.assorted_string like '%"&D3&B3&"%' or" -> ia.assorted_string like '%82154-01-2024%' or
A4: KHI/HO/D/MO/CV/P/82154/01/2024 | B4: -01-2024 | D4: 82154 | E4: ="ia.assorted_string like '%"&D4&B4&"%' or" -> ia.assorted_string like '%82154-01-2024%' or
A5: KHI/HO/D/MO/PC TPP/P/82142/01/2024 | B5: -01-2024 | D5: 82142 | E5: ="ia.assorted_string like '%"&D5&B5&"%' or" -> ia.assorted_string like '%82142-01-2024%' or
A6: KHI/HO/D/MO/PC TPP/P/82142/01/2024 | B6: -01-2024 | D6: 82142 | E6: ="ia.assorted_string like '%"&D6&B6&"%' or" -> ia.assorted_string like '%82142-01-2024%' or
A7: KHI/HO/D/MO/PC TPP/P/82142/01/2024 | B7: -01-2024 | D7: 82142 | E7: ="ia.assorted_string like '%"&D7&B7&"%' or" -> ia.assorted_string like '%82142-01-2024%' or
A8: KHI/HO/D/MO/PC TPP/P/82142/01/2024 | B8: -01-2024 | D8: 82142 | E8: ="ia.assorted_string like '%"&D8&B8&"%' or" -> ia.assorted_string like '%82142-01-2024%' or
A9: KHI/HO/D/MO/PC TPP/P/82142/01/2024 | B9: -01-2024 | D9: 82142 | E9: ="ia.assorted_string like '%"&D9&B9&"%' or" -> ia.assorted_string like '%82142-01-2024%' or
A10: KHI/HO/D/MO/PC TPP/P/82072/01/2024 | B10: -01-2024 | D10: 82072 | E10: ="ia.assorted_string like '%"&D10&B10&"%' or" -> ia.assorted_string like '%82072-01-2024%' or
A11: KHI/HO/D/MO/PC TPP/P/82142/01/2024 | B11: -01-2024 | D11: 82142 | E11: ="ia.assorted_string like '%"&D11&B11&"%' or" -> ia.assorted_string like '%82142-01-2024%' or
A12: KHI/HO/D/MO/PC TPP/P/82142/01/2024 | B12: -01-2024 | D12: 82142 | E12: ="ia.assorted_string like '%"&D12&B12&"%' or" -> ia.assorted_string like '%82142-01-2024%' or
... A500: KHI/HO/D/MO/PC TPP/E/50308/12/2024 | B500: -12-2024 | D500: 50308 | E500: ="ia.assorted_string like '%"&D500&B500&"%' or" -> ia.assorted_string like '%50308-12-2024%' or

Sheet policy
B1: FUNC_ASSORTED_STRING(IA.ASSORTED_CODE) | C1: ASSORTED_CODE
A2: 1 | B2: KHI/HO/D/MO/PC TPP/P/82142/01/2024 | C2: 040000163656
A3: 2 | B3: KHI/HO/D/MO/CV/P/82239/01/2024 | C3: 040000163783
A4: 3 | B4: KHI/HO/D/MO/CV/P/82211/01/2024 | C4: 040000163740
A5: 4 | B5: KHI/HO/D/MO/PC TPP/P/82109/01/2024 | C5: 040000163593
A6: 5 | B6: KHI/HO/D/MO/PC TPP/P/85095/03/2024 | C6: 040000168011
A7: 6 | B7: KHI/HO/D/MO/PC TPP/P/82107/01/2024 | C7: 040000163591
A8: 7 | B8: KHI/HO/D/MO/PC TPP/P/82111/01/2024 | C8: 040000163595
A9: 8 | B9: KHI/HO/D/MO/PC TPP/P/84974/03/2024 | C9: 040000167849
A10: 9 | B10: KHI/HO/D/MO/PC TPP/P/82210/01/2024 | C10: 040000163738
A11: 10 | B11: KHI/HO/D/MO/PC TPP/P/82118/01/2024 | C11: 040000163604
A12: 11 | B12: KHI/HO/D/MO/PC TPP/P/82068/01/2024 | C12: 040000163406
A13: 12 | B13: KHI/HO/D/MO/PC TPP/P/82072/01/2024 | C13: 040000163414
... A40: 39 | B40: KHI/HO/D/MO/PC TPP/E/50308/12/2024 | C40: 050000835997
