Workbook

Sheet MBL RENEWAL
A1: Loan ID | B1: Hub Code | C1: Name of Lessee | D1: Vehicle Description | E1: Engine | F1: Chasis | G1: Registration | H1: Start Date | I1: Expiry Date | J1: TENURE | K1: SUM COVERED | L1: Bank Ins Premium | M1: Bank Premium Rate | N1: New Takaful Company | O1: Policy No. | P1: Endorment No. | Q1: Differnence Amount | R1: TMS Premium
A2: CI-2021-0132-3574 | B2: PK0010002 | C2: MUHAMMAD NAVEED | D2: Civic 1.8 i-VTEC CVT Oriel | E2: Z16926541 | F2: 079124 | G2: - | H2: 45570 | I2: 45935 | J2: 12 MONTHS | K2: 2933496 | L2: 44002 | M2: 1.50 | N2: SALAM TAKAFUL PAKISTAN LITD | O2: KHI/HO/D/MO/PC COMP/C/100194/7/10/2024 | P2: KHI/HO/D/MO/PC COMP/E/48845/00007/11/2024 | Q2: 0 | R2: 44002
A3: CI-2021-0182-3131 | B3: PK0010002 | C3: UZMA SHAHID | D3: Picanto AT | E3: P024903 | F3: AZKP702040 | G3: BRY-456 | H3: 45590 | I3: 45955 | J3: 12 MONTHS | K3: 1447065 | L3: 21706 | M3: 1.50 | N3: SALAM TAKAFUL PAKISTAN LITD | O3: KHI/HO/D/MO/PC COMP/P/100194/10/2024 | Q3: 0 | R3: 21706
A4: CI-2021-0185-1199 | B4: PK0010002 | C4: MUHAMMAD YOUSUF | D4: Yaris 1.3ATIV AT | E4: 2A38037 | F4: R-7023781 | G4: - | H4: 45580 | I4: 45945 | J4: 12 MONTHS | K4: 1950075 | L4: 29251 | M4: 1.50 | N4: SALAM TAKAFUL PAKISTAN LITD | O4: KHI/HO/D/MO/PC COMP/C/100194/1/10/2024 | Q4: 0 | R4: 29251
A5: CI-2021-0193-1219 | B5: PK0010002 | C5: NAVEED AHMED | D5: KIA SPORTAGE ALPHA | E5: G4NAMH312640 | F5: AZLP102230 | G5: - | H5: 45580 | I5: 45945 | J5: 12 MONTHS | K5: 3134700 | L5: 47021 | M5: 1.50 | N5: SALAM TAKAFUL PAKISTAN LITD | O5: KHI/HO/D/MO/PC COMP/C/100194/6/10/2024 | Q5: 0 | R5: 47021
A6: CI-2021-8501-0368 | B6: PK0010002 | C6: SAJID HUSSAIN | D6: SUZUKI CULTUS VXL AGS | E6: K182830 | F6: H10082845 | G6: - | H6: 45585 | I6: 45950 | J6: 12 MONTHS | K6: 1439775 | L6: 21597 | M6: 1.50 | N6: SALAM TAKAFUL PAKISTAN LITD | O6: KHI/HO/D/MO/PC COMP/C/100194/5/10/2024 | Q6: 0 | R6: 21597
A7: CI-2021-9972-4103 | B7: PK0010002 | C7: MUHAMMAD SHAHID | D7: Prince Pearl | E7: M05605341W | F7: M21102801 | G7: - | H7: 45601 | I7: 45966 | J7: 12 MONTHS | K7: 817209 | L7: 12258 | M7: 1.50 | N7: SALAM TAKAFUL PAKISTAN LITD | O7: KHI/HO/D/MO/PC COMP/C/100194/2/10/2024 | Q7: 0 | R7: 12258
A8: CI-2021-9979-4118 | B8: PK0010002 | C8: SUNNY RAZA | D8: Alto VXL AGS | E8: R252985 | F8: H1152996 | G8: - | H8: 45606 | I8: 45971 | J8: 12 MONTHS | K8: 1580310 | L8: 23705 | M8: 1.50 | N8: SALAM TAKAFUL PAKISTAN LITD | O8: KHI/HO/D/MO/PC COMP/C/100033/5/10/2024 | Q8: 0 | R8: 23705
A9: CI-2021-9981-3280 | B9: PK0010002 | C9: SYED TAQI HAIDER RIZVI | D9: Alto VXR | E9: 6R184462 | F9: H1084516 | G9: - | H9: 45585 | I9: 45950 | J9: 12 MONTHS | K9: 973215 | L9: 14598 | M9: 1.50 | N9: SALAM TAKAFUL PAKISTAN LITD | O9: KHI/HO/D/MO/PC COMP/C/100194/3/10/2024 | Q9: 0 | R9: 14598
A10: CI-2022-0000-1282 | B10: PK0010002 | C10: SYED ASIM ALI JAFFARY | D10: KIA Sorento 3.5 FWD | E10: S315132 | F10: P701305 | G10: BK-9138 | H10: 45590 | I10: 45955 | J10: 12 MONTHS | K10: 6891480 | L10: 86144 | M10: 1.25 | N10: SALAM TAKAFUL PAKISTAN LITD | O10: KHI/HO/D/MO/PC COMP/C/100033/3/10/2024 | Q10: 0 | R10: 86144
A11: CI-2022-0125-0018 | B11: PK0010002 | C11: MUHAMMAD UMAIR | D11: Cultus VXR | E11: 604774 | F11: 511653 | G11: BDC-341 | H11: 45601 | I11: 45966 | J11: 12 MONTHS | K11: 891000 | L11: 13365 | M11: 1.50 | N11: SALAM TAKAFUL PAKISTAN LITD | O11: KHI/HO/D/MO/PC COMP/C/100033/9/10/2024 | Q11: 0 | R11: 13365
A12: CI-2022-5501-0004 | B12: PK0010002 | C12: QURAT UL AIN USMAN | D12: Alto VXL | E12: R251419 | F12: H1151338 | G12: BXT-732 | H12: 45601 | I12: 45966 | J12: 12 MONTHS | K12: 1527660 | L12: 22915 | M12: 1.50 | N12: SALAM TAKAFUL PAKISTAN LITD | O12: KHI/HO/D/MO/PC COMP/C/100033/6/10/2024 | Q12: 0 | R12: 22915
A13: CI-2022-6901-0005 | B13: PK0010002 | C13: KHALIL ULLAH | D13: Alto VXR | E13: R250505 | F13: H1150503 | G13: BXS-467 | H13: 45590 | I13: 45955 | J13: 12 MONTHS | K13: 1356750 | L13: 20351 | M13: 1.50 | N13: SALAM TAKAFUL PAKISTAN LITD | O13: KHI/HO/D/MO/PC COMP/C/100033/2/10/2024 | Q13: 0 | R13: 20351
A14: CI-2022-9889-0011 | B14: PK0010002 | C14: REHANA - | D14: Alto VXR | E14: R252605 | F14: H1152519 | G14: BXT-120 | H14: 45590 | I14: 45955 | J14: 12 MONTHS | K14: 1356750 | L14: 20351 | M14: 1.50 | N14: SALAM TAKAFUL PAKISTAN LITD | O14: KHI/HO/D/MO/PC COMP/C/100033/4/10/2024 | Q14: 0 | R14: 20351
... A18: CI-2023-0176-0032 | B18: PK0010002 | C18: SARA ALI | D18: Civic 1.8 i VTEC CVT Oriel | E18: Z12932925 | F18: R036349 | G18: BMJ-923 | H18: 45601 | I18: 45966 | J18: 12 MONTHS | K18: 4680000 | L18: 70200 | M18: 1.50 | N18: SALAM TAKAFUL PAKISTAN LITD | O18: KHI/HO/D/MO/PC COMP/C/100027/5/10/2024 | Q18: 0 | R18: 70200
A19: CI-2023-1027-0007 | B19: PK0010002 | C19: MUHAMMAD KAMRAN | D19: Oshan X7 Future Sense | E19: P1004075 | F19: XMR079124 | G19: - | H19: 45590 | I19: 45955 | J19: 12 MONTHS | K19: 8189100 | L19: 122837 | M19: 1.50 | N19: SALAM TAKAFUL PAKISTAN LITD | O19: KHI/HO/D/MO/PC COMP/C/100194/7/10/2024 | P19: KHI/HO/D/MO/PC COMP/E/48845/00007/11/2024 | Q19: -78835 | R19: 44002
A20: CI-2023-1028-0004 | B20: PK0010002 | C20: MUNEER AHMAD SHAIKH | D20: City PT Aspire 1.5L | E20: A79799652 | F20: R263750 | G20: BSG-810 | H20: 45590 | I20: 45955 | J20: 12 MONTHS | K20: 3600000 | L20: 54000 | M20: 1.50 | N20: SALAM TAKAFUL PAKISTAN LITD | O20: KHI/HO/D/MO/PC COMP/C/100027/1/10/2024 | Q20: 0 | R20: 54000
A21: CI-2023-1602-0007 | B21: PK0010002 | C21: ABDUL SAMAD | D21: Alto VXR | E21: H1115610 | F21: R215614 | G21: BWA-775 | H21: 45590 | I21: 45955 | J21: 12 MONTHS | K21: 2115000 | L21: 31725 | M21: 1.50 | N21: SALAM TAKAFUL PAKISTAN LITD | O21: KHI/HO/D/MO/PC COMP/C/100027/4/10/2024 | Q21: 0 | R21: 31725
A22: CI-2023-9925-0004 | B22: PK0010002 | C22: ZUBAIR ABDULLAH | D22: Wagon R AGS | E22: B246529 | F22: K10146520 | G22: - | H22: 45606 | I22: 45971 | J22: 12 MONTHS | K22: 3258045 | L22: 48871 | M22: 1.50 | N22: SALAM TAKAFUL PAKISTAN LITD | O22: KHI/HO/D/MO/PC COMP/C/100053/2/10/2024 | Q22: 0 | R22: 48871
A23: CI-2023-9952-0008 | B23: PK0010002 | C23: HUMAIRA ZAFAR | D23: Swift NAV AT | E23: S13040620 | F23: K10040620 | G23: BMD-239 | H23: 45611 | I23: 45976 | J23: 12 MONTHS | K23: 2250000 | L23: 33750 | M23: 1.50 | N23: SALAM TAKAFUL PAKISTAN LITD | O23: KHI/HO/D/MO/PC COMP/C/100053/1/10/2024 | Q23: 0 | R23: 33750
A24: CI-2023-9972-0004 | B24: PK0010002 | C24: WASEEM AKRAM | D24: Alto VXL AGS | E24: H1184850 | F24: R284880 | G24: - | H24: 45590 | I24: 45955 | J24: 12 MONTHS | K24: 2641500 | L24: 39623 | M24: 1.50 | N24: SALAM TAKAFUL PAKISTAN LITD | O24: KHI/HO/D/MO/PC COMP/C/100027/3/10/2024 | Q24: 0 | R24: 39623
A25: CM-2018-0117-1163 | B25: PK0010002 | C25: TALHA BIN RIZWAN | D25: HONDA CITY PROSMATEC | E25: L13Z17516702 | F25: JR231607 | G25: BNS-609 | H25: 45601 | I25: 45966 | J25: 12 MONTHS | K25: 1000703 | L25: 33023 | M25: 3.3 | N25: SALAM TAKAFUL PAKISTAN LITD | O25: KHI/HO/D/MO/PC COMP/C/100049/1/10/2024 | Q25: 0 | R25: 33023
A26: CM-2020-0167-1397 | B26: PK0010002 | C26: GHULAM ASGHAR MIRANI | D26: SUZUKI ALTO AGS | E26: 6R141226 | F26: NF1AET306H1041192 | G26: BSG-142 | H26: 45575 | I26: 45940 | J26: 12 MONTHS | K26: 1048448 | L26: 20969 | M26: 2 | N26: SALAM TAKAFUL PAKISTAN LITD | O26: KHI/HO/D/MO/PC COMP/C/100046/1/10/2024 | Q26: 0 | R26: 20969
A27: CM-2020-0192-1310 | B27: PK0010002 | C27: HASSAN JAWAID | D27: SUZUKI ALTO VXR | E27: 6R140189 | F27: NF1AET306H1040181 | G27: BSG-931 | H27: 45580 | I27: 45945 | J27: 12 MONTHS | K27: 917228 | L27: 18345 | M27: 2 | N27: SALAM TAKAFUL PAKISTAN LITD | O27: KHI/HO/D/MO/PC COMP/C/100046/3/10/2024 | Q27: 0 | R27: 18345
A28: CM-2020-8601-0576 | B28: PK0010002 | C28: ASIF ALI | D28: SUZUKI ALTO VXR | E28: 6R142432 | F28: NF1AET306H1042433 | H28: 45575 | I28: 45940 | J28: 12 MONTHS | K28: 917228 | L28: 18345 | M28: 2 | N28: SALAM TAKAFUL PAKISTAN LITD | O28: KHI/HO/D/MO/PC COMP/C/100046/4/10/2024 | Q28: 0 | R28: 18345
A29: CI-2022-1606-0009 | B29: PK0010002 | C29: SHOKAT ALI KEERIO | D29: Alto VXL | E29: 1152558 | F29: 252652 | G29: BXT-756 | H29: 45601 | I29: 45966 | J29: 12 MONTHS | K29: 1527660 | L29: 22915 | M29: 1.50 | N29: SALAM TAKAFUL PAKISTAN LITD | O29: KHI/HO/D/MO/PC COMP/C/100033/8/10/2024 | Q29: 0 | R29: 22915
A30: CM-2020-1606-0693 | B30: PK0010002 | C30: SOOFIA | D30: KIA PICANTO A/T | E30: G3LALP702909 | F30: NNATA52AZKP058927 | H30: 45575 | I30: 45940 | J30: 12 MONTHS | K30: 1359439 | L30: 27189 | M30: 2 | N30: SALAM TAKAFUL PAKISTAN LITD | O30: KHI/HO/D/MO/PC COMP/C/100046/2/10/2024 | Q30: 0 | R30: 27189
A31: CI-2021-0000-0696 | B31: PK0010002 | C31: Salman Ahmed | D31: CULTUS VXR | E31: K187789 | F31: H10087774 | G31: BUX-828 | H31: 45601 | I31: 45966 | J31: 12 MONTHS | K31: 1206495 | L31: 18097 | M31: 1.50 | N31: SALAM TAKAFUL PAKISTAN LITD | O31: KHI/HO/D/MO/PC COMP/C/100050/1/10/2024 | Q31: 0 | R31: 18097
A32: CI-2023-1503-0006 | B32: PK0010007 | C32: SAJID KHAN | D32: Swift GLX CVT | E32: K12MR1016960 | F32: NF1SZC63S00116960 | G32: BCU-636 | H32: 45580 | I32: 45945 | J32: 12 MONTHS | K32: 4464000 | L32: 66960 | M32: 1.50 | N32: SALAM TAKAFUL PAKISTAN LITD | O32: KHI/HO/D/MO/PC COMP/C/100113/1/10/2024 | Q32: 0 | R32: 66960
A33: CM-2021-0701-0004 | B33: PK0010007 | C33: ZAHID NADEEM | D33: PRINCE GLORY 580 | E33: SFG15T-21012101 | F33: PDF580PALR21H1456 | G33: AVH-407 | H33: 45585 | I33: 45950 | J33: 12 MONTHS | K33: 3265920 | L33: 48989 | M33: 1.50 | N33: SALAM TAKAFUL PAKISTAN LITD | O33: KHI/HO/D/MO/PC COMP/C/100112/1/10/2024 | Q33: 0 | R33: 48989
A34: CM-2021-0701-0035 | B34: PK0010007 | C34: GOHAR AMAN | D34: HONDA CIVIC I VTEC PROMATEC | E34: R18Z16925498 | F34: NFBFC666XMR077969 | G34: AVJ-081 | H34: 45590 | I34: 45955 | J34: 12 MONTHS | K34: 2933132 | L34: 43997 | M34: 1.50 | N34: SALAM TAKAFUL PAKISTAN LITD | O34: KHI/HO/D/MO/PC COMP/C/100112/3/10/2024 | Q34: 0 | R34: 43997
A35: CM-2021-3901-0688 | B35: PK0010007 | C35: FAZAL AKBAR | D35: HONDA CIVIC I VTEC PROMATEC | E35: R18Z16926460 | F35: NFBFC6666MR079024 | G35: UW-022 | H35: 45585 | I35: 45950 | J35: 12 MONTHS | K35: 2932038 | L35: 43981 | M35: 1.5 | N35: SALAM TAKAFUL PAKISTAN LITD | O35: KHI/HO/D/MO/PC COMP/C/100112/2/10/2024 | Q35: 0 | R35: 43981
A36: CI-2023-2301-0001 | B36: PK0010008 | C36: WASIM AKRAM | D36: PRINCE PEARL 800CC | E36: N05604012W | F36: RAILPPM23E04414 | G36: AQC-944-PUNJAB | H36: 45606 | I36: 45971 | J36: 12 MONTHS | K36: 1679400 | L36: 25191 | M36: 1.50 | N36: SALAM TAKAFUL PAKISTAN LITD | O36: KHI/HO/D/MO/PC COMP/C/100062/1/10/2024 | Q36: 0 | R36: 25191
A37: CI-2022-0000-1262 | B37: PK0010011 | C37: NASREEN KHALIDA | D37: Wagon R VXR | E37: PK10B241064 | F37: AIJ310PK10141037 | G37: AMA-840 | H37: 45590 | I37: 45955 | J37: 12 MONTHS | K37: 1961010 | L37: 29415 | M37: 1.50 | N37: SALAM TAKAFUL PAKISTAN LITD | O37: KHI/HO/D/MO/PC COMP/C/100067/4/10/2024 | Q37: 0 | R37: 29415
A38: CI-2022-0503-0035 | B38: PK0010011 | C38: TAHIR ASLAM | D38: Changan Alsvin Lumiere 1.5L DCT | E38: JL473QFM3CAD502889 | F38: NKMA2ASE5M1000999 | G38: ADR-181 | H38: 45601 | I38: 45966 | J38: 12 MONTHS | K38: 2592000 | L38: 38880 | M38: 1.50 | N38: SALAM TAKAFUL PAKISTAN LITD | O38: KHI/HO/D/MO/PC COMP/C/100067/6/10/2024 | Q38: 0 | R38: 38880
A39: CI-2022-0513-0007 | B39: PK0010011 | C39: MUHAMMAD ABU BAKAR SADDIQUE | D39: Alto VXR | E39: 6R252596 | F39: NF1AET306H1152602 | G39: AME-480 | H39: 45601 | I39: 45966 | J39: 12 MONTHS | K39: 1356750 | L39: 20351 | M39: 1.50 | N39: SALAM TAKAFUL PAKISTAN LITD | O39: KHI/HO/D/MO/PC COMP/C/100067/8/10/2024 | Q39: 0 | R39: 20351
A40: CI-2022-1270-0012 | B40: PK0010011 | C40: QAISER HAMEED KHATTAK | D40: Wagon R VXL | E40: PK10B240341 | F40: A1J310PK10140334 | G40: AMA-779 | H40: 45590 | I40: 45955 | J40: 12 MONTHS | K40: 2076840 | L40: 31153 | M40: 1.50 | N40: SALAM TAKAFUL PAKISTAN LITD | O40: KHI/HO/D/MO/PC COMP/C/100067/2/10/2024 | Q40: 0 | R40: 31153
A41: CI-2022-1301-0007 | B41: PK0010011 | C41: MUHAMMAD TAHIR | D41: Alto VX | E41: 6R250683 | F41: NF1AET306H1150675 | G41: AMA-359 | H41: 45590 | I41: 45955 | J41: 12 MONTHS | K41: 1057860 | L41: 15868 | M41: 1.50 | N41: SALAM TAKAFUL PAKISTAN LITD | O41: KHI/HO/D/MO/PC COMP/C/100067/5/10/2024 | Q41: 0 | R41: 15868
A42: CI-2022-2102-0009 | B42: PK0010011 | C42: GUL MUHAMMAD | D42: Wagon R VXR | E42: PK10B238517 | F42: A1J310PK10138505 | G42: AMB-339 | H42: 45590 | I42: 45955 | J42: 12 MONTHS | K42: 1961010 | L42: 29415 | M42: 1.50 | N42: SALAM TAKAFUL PAKISTAN LITD | O42: KHI/HO/D/MO/PC COMP/C/100067/3/10/2024 | Q42: 0 | R42: 29415
... A57: CM-2021-0509-1952 | B57: PK0010011 | C57: KHURSHID AHMED | D57: SUZUKI WAGAN R VXL | E57: PK10B221859 | F57: A1J310PK10121852 | G57: PUN-AFD-947 | H57: 45585 | I57: 45950 | J57: 12 MONTHS | K57: 1173690 | L57: 17605 | M57: 1.5 | N57: SALAM TAKAFUL PAKISTAN LITD | O57: KHI/HO/D/MO/PC COMP/C/100068/1/10/2024 | Q57: 0 | R57: 17605
...

Sheet working
A1: POLICY NO. | B1: Assorted_code | D1: Premium | E1: 20Nov240019
A2: KHI/HO/D/MO/PC COMP/C/100194/7/10/2024 | B2: =VLOOKUP(A2,Policy!B:C,2,0) -> 070000167887 | C2: 44002 | D2: =ROUND(C2,0) -> 44002 | E2: 20Nov240019 | F2: ="insert into ins_premium_det (premium_rcv_code,assorted_code, rec_amount,premium_rcv_detail_code,remaining_amt, payrec, mode_code,coinsurance_code,class_cd,it_remarks) values" -> insert into ins_premium_det (premium_rcv_code,assorted_code, rec_amount,premium_rcv_detail_code,remaining_amt, payrec, mode_code,coinsurance_code,class_cd,it_remarks) values | G2: ="('"&E2&"','"&B2&"','"&D2&"',(select max(to_number(i.premium_rcv_detail_code))+1 from ins_premium_det i),'"&D2&"','"&D2&"','02', '11000003','00','Request by Mr. Saqib Saleem 21-Nov-2024');" -> ('20Nov240019','070000167887','44002',(select max(to_number(i.premium_rcv_detail_code))+1 from ins_premium_det i),'44002','44002','02', '11000003','00','Request by Mr. Saqib Saleem 21-Nov-2024'); | H2: =F2&G2 -> insert into ins_premium_det (premium_rcv_code,assorted_code, rec_amount,premium_rcv_detail_code,remaining_amt, payrec, mode_code,coinsurance_code,class_cd,it_remarks) values('20Nov240019','070000167887','44002',(select max(to_number(i.premium_rcv_detail_code))+1 from ins_premium_det i),'44002','44002','02', '11000003','00','Request by Mr. Saqib Saleem 21-Nov-2024');
A3: KHI/HO/D/MO/PC COMP/P/100194/10/2024 | B3: =VLOOKUP(A3,Policy!B:C,2,0) -> 040000187317 | C3: 21706 | D3: =ROUND(C3,0) -> 21706 | E3: 20Nov240019 | F3: ="insert into ins_premium_det (premium_rcv_code,assorted_code, rec_amount,premium_rcv_detail_code,remaining_amt, payrec, mode_code,coinsurance_code,class_cd,it_remarks) values" -> insert into ins_premium_det (premium_rcv_code,assorted_code, rec_amount,premium_rcv_detail_code,remaining_amt, payrec, mode_code,coinsurance_code,class_cd,it_remarks) values | G3: ="('"&E3&"','"&B3&"','"&D3&"',(select max(to_number(i.premium_rcv_detail_code))+1 from ins_premium_det i),'"&D3&"','"&D3&"','02', '11000003','00','Request by Mr. Saqib Saleem 21-Nov-2024');" -> ('20Nov240019','040000187317','21706',(select max(to_number(i.premium_rcv_detail_code))+1 from ins_premium_det i),'21706','21706','02', '11000003','00','Request by Mr. Saqib Saleem 21-Nov-2024'); | H3: =F3&G3 -> insert into ins_premium_det (premium_rcv_code,assorted_code, rec_amount,premium_rcv_detail_code,remaining_amt, payrec, mode_code,coinsurance_code,class_cd,it_remarks) values('20Nov240019','040000187317','21706',(select max(to_number(i.premium_rcv_detail_code))+1 from ins_premium_det i),'21706','21706','02', '11000003','00','Request by Mr. Saqib Saleem 21-Nov-2024');
A4: KHI/HO/D/MO/PC COMP/C/100194/1/10/2024 | B4: =VLOOKUP(A4,Policy!B:C,2,0) -> 070000167880 | C4: 29251 | D4: =ROUND(C4,0) -> 29251 | E4: 20Nov240019 | F4: ="insert into ins_premium_det (premium_rcv_code,assorted_code, rec_amount,premium_rcv_detail_code,remaining_amt, payrec, mode_code,coinsurance_code,class_cd,it_remarks) values" -> insert into ins_premium_det (premium_rcv_code,assorted_code, rec_amount,premium_rcv_detail_code,remaining_amt, payrec, mode_code,coinsurance_code,class_cd,it_remarks) values | G4: ="('"&E4&"','"&B4&"','"&D4&"',(select max(to_number(i.premium_rcv_detail_code))+1 from ins_premium_det i),'"&D4&"','"&D4&"','02', '11000003','00','Request by Mr. Saqib Saleem 21-Nov-2024');" -> ('20Nov240019','070000167880','29251',(select max(to_number(i.premium_rcv_detail_code))+1 from ins_premium_det i),'29251','29251','02', '11000003','00','Request by Mr. Saqib Saleem 21-Nov-2024'); | H4: =F4&G4 -> insert into ins_premium_det (premium_rcv_code,assorted_code, rec_amount,premium_rcv_detail_code,remaining_amt, payrec, mode_code,coinsurance_code,class_cd,it_remarks) values('20Nov240019','070000167880','29251',(select max(to_number(i.premium_rcv_detail_code))+1 from ins_premium_det i),'29251','29251','02', '11000003','00','Request by Mr. Saqib Saleem 21-Nov-2024');
A5: KHI/HO/D/MO/PC COMP/C/100194/6/10/2024 | B5: =VLOOKUP(A5,Policy!B:C,2,0) -> 070000167886 | C5: 47021 | D5: =ROUND(C5,0) -> 47021 | E5: 20Nov240019 | F5: ="insert into ins_premium_det (premium_rcv_code,assorted_code, rec_amount,premium_rcv_detail_code,remaining_amt, payrec, mode_code,coinsurance_code,class_cd,it_remarks) values" -> insert into ins_premium_det (premium_rcv_code,assorted_code, rec_amount,premium_rcv_detail_code,remaining_amt, payrec, mode_code,coinsurance_code,class_cd,it_remarks) values | G5: ="('"&E5&"','"&B5&"','"&D5&"',(select max(to_number(i.premium_rcv_detail_code))+1 from ins_premium_det i),'"&D5&"','"&D5&"','02', '11000003','00','Request by Mr. Saqib Saleem 21-Nov-2024');" -> ('20Nov240019','070000167886','47021',(select max(to_number(i.premium_rcv_detail_code))+1 from ins_premium_det i),'47021','47021','02', '11000003','00','Request by Mr. Saqib Saleem 21-Nov-2024'); | H5: =F5&G5 -> insert into ins_premium_det (premium_rcv_code,assorted_code, rec_amount,premium_rcv_detail_code,remaining_amt, payrec, mode_code,coinsurance_code,class_cd,it_remarks) values('20Nov240019','070000167886','47021',(select max(to_number(i.premium_rcv_detail_code))+1 from ins_premium_det i),'47021','47021','02', '11000003','00','Request by Mr. Saqib Saleem 21-Nov-2024');
A6: KHI/HO/D/MO/PC COMP/C/100194/5/10/2024 | B6: =VLOOKUP(A6,Policy!B:C,2,0) -> 070000167885 | C6: 21597 | D6: =ROUND(C6,0) -> 21597 | E6: 20Nov240019 | F6: ="insert into ins_premium_det (premium_rcv_code,assorted_code, rec_amount,premium_rcv_detail_code,remaining_amt, payrec, mode_code,coinsurance_code,class_cd,it_remarks) values" -> insert into ins_premium_det (premium_rcv_code,assorted_code, rec_amount,premium_rcv_detail_code,remaining_amt, payrec, mode_code,coinsurance_code,class_cd,it_remarks) values | G6: ="('"&E6&"','"&B6&"','"&D6&"',(select max(to_number(i.premium_rcv_detail_code))+1 from ins_premium_det i),'"&D6&"','"&D6&"','02', '11000003','00','Request by Mr. Saqib Saleem 21-Nov-2024');" -> ('20Nov240019','070000167885','21597',(select max(to_number(i.premium_rcv_detail_code))+1 from ins_premium_det i),'21597','21597','02', '11000003','00','Request by Mr. Saqib Saleem 21-Nov-2024'); | H6: =F6&G6 -> insert into ins_premium_det (premium_rcv_code,assorted_code, rec_amount,premium_rcv_detail_code,remaining_amt, payrec, mode_code,coinsurance_code,class_cd,it_remarks) values('20Nov240019','070000167885','21597',(select max(to_number(i.premium_rcv_detail_code))+1 from ins_premium_det i),'21597','21597','02', '11000003','00','Request by Mr. Saqib Saleem 21-Nov-2024');
A7: KHI/HO/D/MO/PC COMP/C/100194/2/10/2024 | B7: =VLOOKUP(A7,Policy!B:C,2,0) -> 070000167881 | C7: 12258 | D7: =ROUND(C7,0) -> 12258 | E7: 20Nov240019 | F7: ="insert into ins_premium_det (premium_rcv_code,assorted_code, rec_amount,premium_rcv_detail_code,remaining_amt, payrec, mode_code,coinsurance_code,class_cd,it_remarks) values" -> insert into ins_premium_det (premium_rcv_code,assorted_code, rec_amount,premium_rcv_detail_code,remaining_amt, payrec, mode_code,coinsurance_code,class_cd,it_remarks) values | G7: ="('"&E7&"','"&B7&"','"&D7&"',(select max(to_number(i.premium_rcv_detail_code))+1 from ins_premium_det i),'"&D7&"','"&D7&"','02', '11000003','00','Request by Mr. Saqib Saleem 21-Nov-2024');" -> ('20Nov240019','070000167881','12258',(select max(to_number(i.premium_rcv_detail_code))+1 from ins_premium_det i),'12258','12258','02', '11000003','00','Request by Mr. Saqib Saleem 21-Nov-2024'); | H7: =F7&G7 -> insert into ins_premium_det (premium_rcv_code,assorted_code, rec_amount,premium_rcv_detail_code,remaining_amt, payrec, mode_code,coinsurance_code,class_cd,it_remarks) values('20Nov240019','070000167881','12258',(select max(to_number(i.premium_rcv_detail_code))+1 from ins_premium_det i),'12258','12258','02', '11000003','00','Request by Mr. Saqib Saleem 21-Nov-2024');
A8: KHI/HO/D/MO/PC COMP/C/100033/5/10/2024 | B8: =VLOOKUP(A8,Policy!B:C,2,0) -> 070000167653 | C8: 23705 | D8: =ROUND(C8,0) -> 23705 | E8: 20Nov240019 | F8: ="insert into ins_premium_det (premium_rcv_code,assorted_code, rec_amount,premium_rcv_detail_code,remaining_amt, payrec, mode_code,coinsurance_code,class_cd,it_remarks) values" -> insert into ins_premium_det (premium_rcv_code,assorted_code, rec_amount,premium_rcv_detail_code,remaining_amt, payrec, mode_code,coinsurance_code,class_cd,it_remarks) values | G8: ="('"&E8&"','"&B8&"','"&D8&"',(select max(to_number(i.premium_rcv_detail_code))+1 from ins_premium_det i),'"&D8&"','"&D8&"','02', '11000003','00','Request by Mr. Saqib Saleem 21-Nov-2024');" -> ('20Nov240019','070000167653','23705',(select max(to_number(i.premium_rcv_detail_code))+1 from ins_premium_det i),'23705','23705','02', '11000003','00','Request by Mr. Saqib Saleem 21-Nov-2024'); | H8: =F8&G8 -> insert into ins_premium_det (premium_rcv_code,assorted_code, rec_amount,premium_rcv_detail_code,remaining_amt, payrec, mode_code,coinsurance_code,class_cd,it_remarks) values('20Nov240019','070000167653','23705',(select max(to_number(i.premium_rcv_detail_code))+1 from ins_premium_det i),'23705','23705','02', '11000003','00','Request by Mr. Saqib Saleem 21-Nov-2024');
A9: KHI/HO/D/MO/PC COMP/C/100194/3/10/2024 | B9: =VLOOKUP(A9,Policy!B:C,2,0) -> 070000167882 | C9: 14598 | D9: =ROUND(C9,0) -> 14598 | E9: 20Nov240019 | F9: ="insert into ins_premium_det (premium_rcv_code,assorted_code, rec_amount,premium_rcv_detail_code,remaining_amt, payrec, mode_code,coinsurance_code,class_cd,it_remarks) values" -> insert into ins_premium_det (premium_rcv_code,assorted_code, rec_amount,premium_rcv_detail_code,remaining_amt, payrec, mode_code,coinsurance_code,class_cd,it_remarks) values | G9: ="('"&E9&"','"&B9&"','"&D9&"',(select max(to_number(i.premium_rcv_detail_code))+1 from ins_premium_det i),'"&D9&"','"&D9&"','02', '11000003','00','Request by Mr. Saqib Saleem 21-Nov-2024');" -> ('20Nov240019','070000167882','14598',(select max(to_number(i.premium_rcv_detail_code))+1 from ins_premium_det i),'14598','14598','02', '11000003','00','Request by Mr. Saqib Saleem 21-Nov-2024'); | H9: =F9&G9 -> insert into ins_premium_det (premium_rcv_code,assorted_code, rec_amount,premium_rcv_detail_code,remaining_amt, payrec, mode_code,coinsurance_code,class_cd,it_remarks) values('20Nov240019','070000167882','14598',(select max(to_number(i.premium_rcv_detail_code))+1 from ins_premium_det i),'14598','14598','02', '11000003','00','Request by Mr. Saqib Saleem 21-Nov-2024');
A10: KHI/HO/D/MO/PC COMP/C/100033/3/10/2024 | B10: =VLOOKUP(A10,Policy!B:C,2,0) -> 070000167651 | C10: 86144 | D10: =ROUND(C10,0) -> 86144 | E10: 20Nov240019 | F10: ="insert into ins_premium_det (premium_rcv_code,assorted_code, rec_amount,premium_rcv_detail_code,remaining_amt, payrec, mode_code,coinsurance_code,class_cd,it_remarks) values" -> insert into ins_premium_det (premium_rcv_code,assorted_code, rec_amount,premium_rcv_detail_code,remaining_amt, payrec, mode_code,coinsurance_code,class_cd,it_remarks) values | G10: ="('"&E10&"','"&B10&"','"&D10&"',(select max(to_number(i.premium_rcv_detail_code))+1 from ins_premium_det i),'"&D10&"','"&D10&"','02', '11000003','00','Request by Mr. Saqib Saleem 21-Nov-2024');" -> ('20Nov240019','070000167651','86144',(select max(to_number(i.premium_rcv_detail_code))+1 from ins_premium_det i),'86144','86144','02', '11000003','00','Request by Mr. Saqib Saleem 21-Nov-2024'); | H10: =F10&G10 -> insert into ins_premium_det (premium_rcv_code,assorted_code, rec_amount,premium_rcv_detail_code,remaining_amt, payrec, mode_code,coinsurance_code,class_cd,it_remarks) values('20Nov240019','070000167651','86144',(select max(to_number(i.premium_rcv_detail_code))+1 from ins_premium_det i),'86144','86144','02', '11000003','00','Request by Mr. Saqib Saleem 21-Nov-2024');
A11: KHI/HO/D/MO/PC COMP/C/100033/9/10/2024 | B11: =VLOOKUP(A11,Policy!B:C,2,0) -> 070000167657 | C11: 13365 | D11: =ROUND(C11,0) -> 13365 | E11: 20Nov240019 | F11: ="insert into ins_premium_det (premium_rcv_code,assorted_code, rec_amount,premium_rcv_detail_code,remaining_amt, payrec, mode_code,coinsurance_code,class_cd,it_remarks) values" -> insert into ins_premium_det (premium_rcv_code,assorted_code, rec_amount,premium_rcv_detail_code,remaining_amt, payrec, mode_code,coinsurance_code,class_cd,it_remarks) values | G11: ="('"&E11&"','"&B11&"','"&D11&"',(select max(to_number(i.premium_rcv_detail_code))+1 from ins_premium_det i),'"&D11&"','"&D11&"','02', '11000003','00','Request by Mr. Saqib Saleem 21-Nov-2024');" -> ('20Nov240019','070000167657','13365',(select max(to_number(i.premium_rcv_detail_code))+1 from ins_premium_det i),'13365','13365','02', '11000003','00','Request by Mr. Saqib Saleem 21-Nov-2024'); | H11: =F11&G11 -> insert into ins_premium_det (premium_rcv_code,assorted_code, rec_amount,premium_rcv_detail_code,remaining_amt, payrec, mode_code,coinsurance_code,class_cd,it_remarks) values('20Nov240019','070000167657','13365',(select max(to_number(i.premium_rcv_detail_code))+1 from ins_premium_det i),'13365','13365','02', '11000003','00','Request by Mr. Saqib Saleem 21-Nov-2024');
A12: KHI/HO/D/MO/PC COMP/C/100033/6/10/2024 | B12: =VLOOKUP(A12,Policy!B:C,2,0) -> 070000167654 | C12: 22915 | D12: =ROUND(C12,0) -> 22915 | E12: 20Nov240019 | F12: ="insert into ins_premium_det (premium_rcv_code,assorted_code, rec_amount,premium_rcv_detail_code,remaining_amt, payrec, mode_code,coinsurance_code,class_cd,it_remarks) values" -> insert into ins_premium_det (premium_rcv_code,assorted_code, rec_amount,premium_rcv_detail_code,remaining_amt, payrec, mode_code,coinsurance_code,class_cd,it_remarks) values | G12: ="('"&E12&"','"&B12&"','"&D12&"',(select max(to_number(i.premium_rcv_detail_code))+1 from ins_premium_det i),'"&D12&"','"&D12&"','02', '11000003','00','Request by Mr. Saqib Saleem 21-Nov-2024');" -> ('20Nov240019','070000167654','22915',(select max(to_number(i.premium_rcv_detail_code))+1 from ins_premium_det i),'22915','22915','02', '11000003','00','Request by Mr. Saqib Saleem 21-Nov-2024'); | H12: =F12&G12 -> insert into ins_premium_det (premium_rcv_code,assorted_code, rec_amount,premium_rcv_detail_code,remaining_amt, payrec, mode_code,coinsurance_code,class_cd,it_remarks) values('20Nov240019','070000167654','22915',(select max(to_number(i.premium_rcv_detail_code))+1 from ins_premium_det i),'22915','22915','02', '11000003','00','Request by Mr. Saqib Saleem 21-Nov-2024');
A13: KHI/HO/D/MO/PC COMP/C/100033/2/10/2024 | B13: =VLOOKUP(A13,Policy!B:C,2,0) -> 070000167649 | C13: 20351 | D13: =ROUND(C13,0) -> 20351 | E13: 20Nov240019 | F13: ="insert into ins_premium_det (premium_rcv_code,assorted_code, rec_amount,premium_rcv_detail_code,remaining_amt, payrec, mode_code,coinsurance_code,class_cd,it_remarks) values" -> insert into ins_premium_det (premium_rcv_code,assorted_code, rec_amount,premium_rcv_detail_code,remaining_amt, payrec, mode_code,coinsurance_code,class_cd,it_remarks) values | G13: ="('"&E13&"','"&B13&"','"&D13&"',(select max(to_number(i.premium_rcv_detail_code))+1 from ins_premium_det i),'"&D13&"','"&D13&"','02', '11000003','00','Request by Mr. Saqib Saleem 21-Nov-2024');" -> ('20Nov240019','070000167649','20351',(select max(to_number(i.premium_rcv_detail_code))+1 from ins_premium_det i),'20351','20351','02', '11000003','00','Request by Mr. Saqib Saleem 21-Nov-2024'); | H13: =F13&G13 -> insert into ins_premium_det (premium_rcv_code,assorted_code, rec_amount,premium_rcv_detail_code,remaining_amt, payrec, mode_code,coinsurance_code,class_cd,it_remarks) values('20Nov240019','070000167649','20351',(select max(to_number(i.premium_rcv_detail_code))+1 from ins_premium_det i),'20351','20351','02', '11000003','00','Request by Mr. Saqib Saleem 21-Nov-2024');
... A50: KHI/HO/D/MO/PC COMP/C/100066/1/10/2024 | B50: =VLOOKUP(A50,Policy!B:C,2,0) -> 070000167712 | C50: 29700 | D50: =ROUND(C50,0) -> 29700 | E50: 20Nov240019 | F50: ="insert into ins_premium_det (premium_rcv_code,assorted_code, rec_amount,premium_rcv_detail_code,remaining_amt, payrec, mode_code,coinsurance_code,class_cd,it_remarks) values" -> insert into ins_premium_det (premium_rcv_code,assorted_code, rec_amount,premium_rcv_detail_code,remaining_amt, payrec, mode_code,coinsurance_code,class_cd,it_remarks) values | G50: ="('"&E50&"','"&B50&"','"&D50&"',(select max(to_number(i.premium_rcv_detail_code))+1 from ins_premium_det i),'"&D50&"','"&D50&"','02', '11000003','00','Request by Mr. Saqib Saleem 21-Nov-2024');" -> ('20Nov240019','070000167712','29700',(select max(to_number(i.premium_rcv_detail_code))+1 from ins_premium_det i),'29700','29700','02', '11000003','00','Request by Mr. Saqib Saleem 21-Nov-2024'); | H50: =F50&G50 -> insert into ins_premium_det (premium_rcv_code,assorted_code, rec_amount,premium_rcv_detail_code,remaining_amt, payrec, mode_code,coinsurance_code,class_cd,it_remarks) values('20Nov240019','070000167712','29700',(select max(to_number(i.premium_rcv_detail_code))+1 from ins_premium_det i),'29700','29700','02', '11000003','00','Request by Mr. Saqib Saleem 21-Nov-2024');
A51: KHI/HO/D/MO/PC COMP/P/102358/1/11/2024 | B51: 040000189796 | C51: 14621 | D51: =ROUND(C51,0) -> 14621 | E51: 20Nov240019 | F51: ="insert into ins_premium_det (premium_rcv_code,assorted_code, rec_amount,premium_rcv_detail_code,remaining_amt, payrec, mode_code,coinsurance_code,class_cd,it_remarks) values" -> insert into ins_premium_det (premium_rcv_code,assorted_code, rec_amount,premium_rcv_detail_code,remaining_amt, payrec, mode_code,coinsurance_code,class_cd,it_remarks) values | G51: ="('"&E51&"','"&B51&"','"&D51&"',(select max(to_number(i.premium_rcv_detail_code))+1 from ins_premium_det i),'"&D51&"','"&D51&"','02', '11000003','00','Request by Mr. Saqib Saleem 21-Nov-2024');" -> ('20Nov240019','040000189796','14621',(select max(to_number(i.premium_rcv_detail_code))+1 from ins_premium_det i),'14621','14621','02', '11000003','00','Request by Mr. Saqib Saleem 21-Nov-2024'); | H51: =F51&G51 -> insert into ins_premium_det (premium_rcv_code,assorted_code, rec_amount,premium_rcv_detail_code,remaining_amt, payrec, mode_code,coinsurance_code,class_cd,it_remarks) values('20Nov240019','040000189796','14621',(select max(to_number(i.premium_rcv_detail_code))+1 from ins_premium_det i),'14621','14621','02', '11000003','00','Request by Mr. Saqib Saleem 21-Nov-2024');
A52: KHI/HO/D/MO/PC COMP/C/100069/2/10/2024 | B52: =VLOOKUP(A52,Policy!B:C,2,0) -> 070000167691 | C52: 58065 | D52: =ROUND(C52,0) -> 58065 | E52: 20Nov240019 | F52: ="insert into ins_premium_det (premium_rcv_code,assorted_code, rec_amount,premium_rcv_detail_code,remaining_amt, payrec, mode_code,coinsurance_code,class_cd,it_remarks) values" -> insert into ins_premium_det (premium_rcv_code,assorted_code, rec_amount,premium_rcv_detail_code,remaining_amt, payrec, mode_code,coinsurance_code,class_cd,it_remarks) values | G52: ="('"&E52&"','"&B52&"','"&D52&"',(select max(to_number(i.premium_rcv_detail_code))+1 from ins_premium_det i),'"&D52&"','"&D52&"','02', '11000003','00','Request by Mr. Saqib Saleem 21-Nov-2024');" -> ('20Nov240019','070000167691','58065',(select max(to_number(i.premium_rcv_detail_code))+1 from ins_premium_det i),'58065','58065','02', '11000003','00','Request by Mr. Saqib Saleem 21-Nov-2024'); | H52: =F52&G52 -> insert into ins_premium_det (premium_rcv_code,assorted_code, rec_amount,premium_rcv_detail_code,remaining_amt, payrec, mode_code,coinsurance_code,class_cd,it_remarks) values('20Nov240019','070000167691','58065',(select max(to_number(i.premium_rcv_detail_code))+1 from ins_premium_det i),'58065','58065','02', '11000003','00','Request by Mr. Saqib Saleem 21-Nov-2024');
A53: KHI/HO/D/MO/PC COMP/C/100069/1/10/2024 | B53: =VLOOKUP(A53,Policy!B:C,2,0) -> 070000167690 | C53: 21061 | D53: =ROUND(C53,0) -> 21061 | E53: 20Nov240019 | F53: ="insert into ins_premium_det (premium_rcv_code,assorted_code, rec_amount,premium_rcv_detail_code,remaining_amt, payrec, mode_code,coinsurance_code,class_cd,it_remarks) values" -> insert into ins_premium_det (premium_rcv_code,assorted_code, rec_amount,premium_rcv_detail_code,remaining_amt, payrec, mode_code,coinsurance_code,class_cd,it_remarks) values | G53: ="('"&E53&"','"&B53&"','"&D53&"',(select max(to_number(i.premium_rcv_detail_code))+1 from ins_premium_det i),'"&D53&"','"&D53&"','02', '11000003','00','Request by Mr. Saqib Saleem 21-Nov-2024');" -> ('20Nov240019','070000167690','21061',(select max(to_number(i.premium_rcv_detail_code))+1 from ins_premium_det i),'21061','21061','02', '11000003','00','Request by Mr. Saqib Saleem 21-Nov-2024'); | H53: =F53&G53 -> insert into ins_premium_det (premium_rcv_code,assorted_code, rec_amount,premium_rcv_detail_code,remaining_amt, payrec, mode_code,coinsurance_code,class_cd,it_remarks) values('20Nov240019','070000167690','21061',(select max(to_number(i.premium_rcv_detail_code))+1 from ins_premium_det i),'21061','21061','02', '11000003','00','Request by Mr. Saqib Saleem 21-Nov-2024');
A54: KHI/HO/D/MO/PC COMP/C/100069/3/10/2024 | B54: =VLOOKUP(A54,Policy!B:C,2,0) -> 070000167692 | C54: 21061 | D54: =ROUND(C54,0) -> 21061 | E54: 20Nov240019 | F54: ="insert into ins_premium_det (premium_rcv_code,assorted_code, rec_amount,premium_rcv_detail_code,remaining_amt, payrec, mode_code,coinsurance_code,class_cd,it_remarks) values" -> insert into ins_premium_det (premium_rcv_code,assorted_code, rec_amount,premium_rcv_detail_code,remaining_amt, payrec, mode_code,coinsurance_code,class_cd,it_remarks) values | G54: ="('"&E54&"','"&B54&"','"&D54&"',(select max(to_number(i.premium_rcv_detail_code))+1 from ins_premium_det i),'"&D54&"','"&D54&"','02', '11000003','00','Request by Mr. Saqib Saleem 21-Nov-2024');" -> ('20Nov240019','070000167692','21061',(select max(to_number(i.premium_rcv_detail_code))+1 from ins_premium_det i),'21061','21061','02', '11000003','00','Request by Mr. Saqib Saleem 21-Nov-2024'); | H54: =F54&G54 -> insert into ins_premium_det (premium_rcv_code,assorted_code, rec_amount,premium_rcv_detail_code,remaining_amt, payrec, mode_code,coinsurance_code,class_cd,it_remarks) values('20Nov240019','070000167692','21061',(select max(to_number(i.premium_rcv_detail_code))+1 from ins_premium_det i),'21061','21061','02', '11000003','00','Request by Mr. Saqib Saleem 21-Nov-2024');
A55: KHI/HO/D/MO/PC COMP/C/100069/4/10/2024 | B55: =VLOOKUP(A55,Policy!B:C,2,0) -> 070000167693 | C55: 64639 | D55: =ROUND(C55,0) -> 64639 | E55: 20Nov240019 | F55: ="insert into ins_premium_det (premium_rcv_code,assorted_code, rec_amount,premium_rcv_detail_code,remaining_amt, payrec, mode_code,coinsurance_code,class_cd,it_remarks) values" -> insert into ins_premium_det (premium_rcv_code,assorted_code, rec_amount,premium_rcv_detail_code,remaining_amt, payrec, mode_code,coinsurance_code,class_cd,it_remarks) values | G55: ="('"&E55&"','"&B55&"','"&D55&"',(select max(to_number(i.premium_rcv_detail_code))+1 from ins_premium_det i),'"&D55&"','"&D55&"','02', '11000003','00','Request by Mr. Saqib Saleem 21-Nov-2024');" -> ('20Nov240019','070000167693','64639',(select max(to_number(i.premium_rcv_detail_code))+1 from ins_premium_det i),'64639','64639','02', '11000003','00','Request by Mr. Saqib Saleem 21-Nov-2024'); | H55: =F55&G55 -> insert into ins_premium_det (premium_rcv_code,assorted_code, rec_amount,premium_rcv_detail_code,remaining_amt, payrec, mode_code,coinsurance_code,class_cd,it_remarks) values('20Nov240019','070000167693','64639',(select max(to_number(i.premium_rcv_detail_code))+1 from ins_premium_det i),'64639','64639','02', '11000003','00','Request by Mr. Saqib Saleem 21-Nov-2024');
A56: KHI/HO/D/MO/PC COMP/C/100068/2/10/2024 | B56: =VLOOKUP(A56,Policy!B:C,2,0) -> 070000167696 | C56: 30755 | D56: =ROUND(C56,0) -> 30755 | E56: 20Nov240019 | F56: ="insert into ins_premium_det (premium_rcv_code,assorted_code, rec_amount,premium_rcv_detail_code,remaining_amt, payrec, mode_code,coinsurance_code,class_cd,it_remarks) values" -> insert into ins_premium_det (premium_rcv_code,assorted_code, rec_amount,premium_rcv_detail_code,remaining_amt, payrec, mode_code,coinsurance_code,class_cd,it_remarks) values | G56: ="('"&E56&"','"&B56&"','"&D56&"',(select max(to_number(i.premium_rcv_detail_code))+1 from ins_premium_det i),'"&D56&"','"&D56&"','02', '11000003','00','Request by Mr. Saqib Saleem 21-Nov-2024');" -> ('20Nov240019','070000167696','30755',(select max(to_number(i.premium_rcv_detail_code))+1 from ins_premium_det i),'30755','30755','02', '11000003','00','Request by Mr. Saqib Saleem 21-Nov-2024'); | H56: =F56&G56 -> insert into ins_premium_det (premium_rcv_code,assorted_code, rec_amount,premium_rcv_detail_code,remaining_amt, payrec, mode_code,coinsurance_code,class_cd,it_remarks) values('20Nov240019','070000167696','30755',(select max(to_number(i.premium_rcv_detail_code))+1 from ins_premium_det i),'30755','30755','02', '11000003','00','Request by Mr. Saqib Saleem 21-Nov-2024');
A57: KHI/HO/D/MO/PC COMP/C/100068/1/10/2024 | B57: =VLOOKUP(A57,Policy!B:C,2,0) -> 070000167695 | C57: 17605 | D57: =ROUND(C57,0) -> 17605 | E57: 20Nov240019 | F57: ="insert into ins_premium_det (premium_rcv_code,assorted_code, rec_amount,premium_rcv_detail_code,remaining_amt, payrec, mode_code,coinsurance_code,class_cd,it_remarks) values" -> insert into ins_premium_det (premium_rcv_code,assorted_code, rec_amount,premium_rcv_detail_code,remaining_amt, payrec, mode_code,coinsurance_code,class_cd,it_remarks) values | G57: ="('"&E57&"','"&B57&"','"&D57&"',(select max(to_number(i.premium_rcv_detail_code))+1 from ins_premium_det i),'"&D57&"','"&D57&"','02', '11000003','00','Request by Mr. Saqib Saleem 21-Nov-2024');" -> ('20Nov240019','070000167695','17605',(select max(to_number(i.premium_rcv_detail_code))+1 from ins_premium_det i),'17605','17605','02', '11000003','00','Request by Mr. Saqib Saleem 21-Nov-2024'); | H57: =F57&G57 -> insert into ins_premium_det (premium_rcv_code,assorted_code, rec_amount,premium_rcv_detail_code,remaining_amt, payrec, mode_code,coinsurance_code,class_cd,it_remarks) values('20Nov240019','070000167695','17605',(select max(to_number(i.premium_rcv_detail_code))+1 from ins_premium_det i),'17605','17605','02', '11000003','00','Request by Mr. Saqib Saleem 21-Nov-2024');
A58: KHI/HO/D/MO/PC COMP/C/100068/4/10/2024 | B58: =VLOOKUP(A58,Policy!B:C,2,0) -> 070000167699 | C58: 47793 | D58: =ROUND(C58,0) -> 47793 | E58: 20Nov240019 | F58: ="insert into ins_premium_det (premium_rcv_code,assorted_code, rec_amount,premium_rcv_detail_code,remaining_amt, payrec, mode_code,coinsurance_code,class_cd,it_remarks) values" -> insert into ins_premium_det (premium_rcv_code,assorted_code, rec_amount,premium_rcv_detail_code,remaining_amt, payrec, mode_code,coinsurance_code,class_cd,it_remarks) values | G58: ="('"&E58&"','"&B58&"','"&D58&"',(select max(to_number(i.premium_rcv_detail_code))+1 from ins_premium_det i),'"&D58&"','"&D58&"','02', '11000003','00','Request by Mr. Saqib Saleem 21-Nov-2024');" -> ('20Nov240019','070000167699','47793',(select max(to_number(i.premium_rcv_detail_code))+1 from ins_premium_det i),'47793','47793','02', '11000003','00','Request by Mr. Saqib Saleem 21-Nov-2024'); | H58: =F58&G58 -> insert into ins_premium_det (premium_rcv_code,assorted_code, rec_amount,premium_rcv_detail_code,remaining_amt, payrec, mode_code,coinsurance_code,class_cd,it_remarks) values('20Nov240019','070000167699','47793',(select max(to_number(i.premium_rcv_detail_code))+1 from ins_premium_det i),'47793','47793','02', '11000003','00','Request by Mr. Saqib Saleem 21-Nov-2024');
A59: KHI/HO/D/MO/PC COMP/C/100068/7/10/2024 | B59: =VLOOKUP(A59,Policy!B:C,2,0) -> 070000167703 | C59: 16829 | D59: =ROUND(C59,0) -> 16829 | E59: 20Nov240019 | F59: ="insert into ins_premium_det (premium_rcv_code,assorted_code, rec_amount,premium_rcv_detail_code,remaining_amt, payrec, mode_code,coinsurance_code,class_cd,it_remarks) values" -> insert into ins_premium_det (premium_rcv_code,assorted_code, rec_amount,premium_rcv_detail_code,remaining_amt, payrec, mode_code,coinsurance_code,class_cd,it_remarks) values | G59: ="('"&E59&"','"&B59&"','"&D59&"',(select max(to_number(i.premium_rcv_detail_code))+1 from ins_premium_det i),'"&D59&"','"&D59&"','02', '11000003','00','Request by Mr. Saqib Saleem 21-Nov-2024');" -> ('20Nov240019','070000167703','16829',(select max(to_number(i.premium_rcv_detail_code))+1 from ins_premium_det i),'16829','16829','02', '11000003','00','Request by Mr. Saqib Saleem 21-Nov-2024'); | H59: =F59&G59 -> insert into ins_premium_det (premium_rcv_code,assorted_code, rec_amount,premium_rcv_detail_code,remaining_amt, payrec, mode_code,coinsurance_code,class_cd,it_remarks) values('20Nov240019','070000167703','16829',(select max(to_number(i.premium_rcv_detail_code))+1 from ins_premium_det i),'16829','16829','02', '11000003','00','Request by Mr. Saqib Saleem 21-Nov-2024');
A60: KHI/HO/D/MO/PC COMP/C/100068/5/10/2024 | B60: =VLOOKUP(A60,Policy!B:C,2,0) -> 070000167700 | C60: 28486 | D60: =ROUND(C60,0) -> 28486 | E60: 20Nov240019 | F60: ="insert into ins_premium_det (premium_rcv_code,assorted_code, rec_amount,premium_rcv_detail_code,remaining_amt, payrec, mode_code,coinsurance_code,class_cd,it_remarks) values" -> insert into ins_premium_det (premium_rcv_code,assorted_code, rec_amount,premium_rcv_detail_code,remaining_amt, payrec, mode_code,coinsurance_code,class_cd,it_remarks) values | G60: ="('"&E60&"','"&B60&"','"&D60&"',(select max(to_number(i.premium_rcv_detail_code))+1 from ins_premium_det i),'"&D60&"','"&D60&"','02', '11000003','00','Request by Mr. Saqib Saleem 21-Nov-2024');" -> ('20Nov240019','070000167700','28486',(select max(to_number(i.premium_rcv_detail_code))+1 from ins_premium_det i),'28486','28486','02', '11000003','00','Request by Mr. Saqib Saleem 21-Nov-2024'); | H60: =F60&G60 -> insert into ins_premium_det (premium_rcv_code,assorted_code, rec_amount,premium_rcv_detail_code,remaining_amt, payrec, mode_code,coinsurance_code,class_cd,it_remarks) values('20Nov240019','070000167700','28486',(select max(to_number(i.premium_rcv_detail_code))+1 from ins_premium_det i),'28486','28486','02', '11000003','00','Request by Mr. Saqib Saleem 21-Nov-2024');
A61: KHI/HO/D/MO/PC COMP/C/100068/3/10/2024 | B61: =VLOOKUP(A61,Policy!B:C,2,0) -> 070000167697 | C61: 17605 | D61: =ROUND(C61,0) -> 17605 | E61: 20Nov240019 | F61: ="insert into ins_premium_det (premium_rcv_code,assorted_code, rec_amount,premium_rcv_detail_code,remaining_amt, payrec, mode_code,coinsurance_code,class_cd,it_remarks) values" -> insert into ins_premium_det (premium_rcv_code,assorted_code, rec_amount,premium_rcv_detail_code,remaining_amt, payrec, mode_code,coinsurance_code,class_cd,it_remarks) values | G61: ="('"&E61&"','"&B61&"','"&D61&"',(select max(to_number(i.premium_rcv_detail_code))+1 from ins_premium_det i),'"&D61&"','"&D61&"','02', '11000003','00','Request by Mr. Saqib Saleem 21-Nov-2024');" -> ('20Nov240019','070000167697','17605',(select max(to_number(i.premium_rcv_detail_code))+1 from ins_premium_det i),'17605','17605','02', '11000003','00','Request by Mr. Saqib Saleem 21-Nov-2024'); | H61: =F61&G61 -> insert into ins_premium_det (premium_rcv_code,assorted_code, rec_amount,premium_rcv_detail_code,remaining_amt, payrec, mode_code,coinsurance_code,class_cd,it_remarks) values('20Nov240019','070000167697','17605',(select max(to_number(i.premium_rcv_detail_code))+1 from ins_premium_det i),'17605','17605','02', '11000003','00','Request by Mr. Saqib Saleem 21-Nov-2024');
A62: KHI/HO/D/MO/PC COMP/C/100068/6/10/2024 | B62: =VLOOKUP(A62,Policy!B:C,2,0) -> 070000167701 | C62: 19738 | D62: =ROUND(C62,0) -> 19738 | E62: 20Nov240019 | F62: ="insert into ins_premium_det (premium_rcv_code,assorted_code, rec_amount,premium_rcv_detail_code,remaining_amt, payrec, mode_code,coinsurance_code,class_cd,it_remarks) values" -> insert into ins_premium_det (premium_rcv_code,assorted_code, rec_amount,premium_rcv_detail_code,remaining_amt, payrec, mode_code,coinsurance_code,class_cd,it_remarks) values | G62: ="('"&E62&"','"&B62&"','"&D62&"',(select max(to_number(i.premium_rcv_detail_code))+1 from ins_premium_det i),'"&D62&"','"&D62&"','02', '11000003','00','Request by Mr. Saqib Saleem 21-Nov-2024');" -> ('20Nov240019','070000167701','19738',(select max(to_number(i.premium_rcv_detail_code))+1 from ins_premium_det i),'19738','19738','02', '11000003','00','Request by Mr. Saqib Saleem 21-Nov-2024'); | H62: =F62&G62 -> insert into ins_premium_det (premium_rcv_code,assorted_code, rec_amount,premium_rcv_detail_code,remaining_amt, payrec, mode_code,coinsurance_code,class_cd,it_remarks) values('20Nov240019','070000167701','19738',(select max(to_number(i.premium_rcv_detail_code))+1 from ins_premium_det i),'19738','19738','02', '11000003','00','Request by Mr. Saqib Saleem 21-Nov-2024');
A63: KHI/HO/D/MO/PC COMP/C/100091/10/10/2024 | B63: =VLOOKUP(A63,Policy!B:C,2,0) -> 070000167758 | C63: 17605 | D63: =ROUND(C63,0) -> 17605 | E63: 20Nov240019 | F63: ="insert into ins_premium_det (premium_rcv_code,assorted_code, rec_amount,premium_rcv_detail_code,remaining_amt, payrec, mode_code,coinsurance_code,class_cd,it_remarks) values" -> insert into ins_premium_det (premium_rcv_code,assorted_code, rec_amount,premium_rcv_detail_code,remaining_amt, payrec, mode_code,coinsurance_code,class_cd,it_remarks) values | G63: ="('"&E63&"','"&B63&"','"&D63&"',(select max(to_number(i.premium_rcv_detail_code))+1 from ins_premium_det i),'"&D63&"','"&D63&"','02', '11000003','00','Request by Mr. Saqib Saleem 21-Nov-2024');" -> ('20Nov240019','070000167758','17605',(select max(to_number(i.premium_rcv_detail_code))+1 from ins_premium_det i),'17605','17605','02', '11000003','00','Request by Mr. Saqib Saleem 21-Nov-2024'); | H63: =F63&G63 -> insert into ins_premium_det (premium_rcv_code,assorted_code, rec_amount,premium_rcv_detail_code,remaining_amt, payrec, mode_code,coinsurance_code,class_cd,it_remarks) values('20Nov240019','070000167758','17605',(select max(to_number(i.premium_rcv_detail_code))+1 from ins_premium_det i),'17605','17605','02', '11000003','00','Request by Mr. Saqib Saleem 21-Nov-2024');
... A147: KHI/HO/D/MO/PC COMP/C/100129/3/10/2024 | B147: =VLOOKUP(A147,Policy!B:C,2,0) -> 070000167840 | C147: 14598 | D147: =ROUND(C147,0) -> 14598 | E147: 20Nov240019 | F147: ="insert into ins_premium_det (premium_rcv_code,assorted_code, rec_amount,premium_rcv_detail_code,remaining_amt, payrec, mode_code,coinsurance_code,class_cd,it_remarks) values" -> insert into ins_premium_det (premium_rcv_code,assorted_code, rec_amount,premium_rcv_detail_code,remaining_amt, payrec, mode_code,coinsurance_code,class_cd,it_remarks) values | G147: ="('"&E147&"','"&B147&"','"&D147&"',(select max(to_number(i.premium_rcv_detail_code))+1 from ins_premium_det i),'"&D147&"','"&D147&"','02', '11000003','00','Request by Mr. Saqib Saleem 21-Nov-2024');" -> ('20Nov240019','070000167840','14598',(select max(to_number(i.premium_rcv_detail_code))+1 from ins_premium_det i),'14598','14598','02', '11000003','00','Request by Mr. Saqib Saleem 21-Nov-2024'); | H147: =F147&G147 -> insert into ins_premium_det (premium_rcv_code,assorted_code, rec_amount,premium_rcv_detail_code,remaining_amt, payrec, mode_code,coinsurance_code,class_cd,it_remarks) values('20Nov240019','070000167840','14598',(select max(to_number(i.premium_rcv_detail_code))+1 from ins_premium_det i),'14598','14598','02', '11000003','00','Request by Mr. Saqib Saleem 21-Nov-2024');

Sheet Sheet2
I1: L
A2: KHI/HO/D/MO/PC COMP/C/100194/7/10/2024 | B2: -10-2024 | H2: 100194 | I2: 00007 | J2: ="ia.assorted_string like '%"&H2&"-"&I2&B2&"%' or" -> ia.assorted_string like '%100194-00007-10-2024%' or
A3: KHI/HO/D/MO/PC COMP/P/100194/10/2024 | B3: -10-2024 | H3: 100194 | I3: 00010 | J3: ="ia.assorted_string like '%"&H3&"-"&I3&B3&"%' or" -> ia.assorted_string like '%100194-00010-10-2024%' or
A4: KHI/HO/D/MO/PC COMP/C/100194/1/10/2024 | B4: -10-2024 | H4: 100194 | I4: 00001 | J4: ="ia.assorted_string like '%"&H4&"-"&I4&B4&"%' or" -> ia.assorted_string like '%100194-00001-10-2024%' or
A5: KHI/HO/D/MO/PC COMP/C/100194/6/10/2024 | B5: -10-2024 | H5: 100194 | I5: 00006 | J5: ="ia.assorted_string like '%"&H5&"-"&I5&B5&"%' or" -> ia.assorted_string like '%100194-00006-10-2024%' or
A6: KHI/HO/D/MO/PC COMP/C/100194/5/10/2024 | B6: -10-2024 | H6: 100194 | I6: 00005 | J6: ="ia.assorted_string like '%"&H6&"-"&I6&B6&"%' or" -> ia.assorted_string like '%100194-00005-10-2024%' or
A7: KHI/HO/D/MO/PC COMP/C/100194/2/10/2024 | B7: -10-2024 | H7: 100194 | I7: 00002 | J7: ="ia.assorted_string like '%"&H7&"-"&I7&B7&"%' or" -> ia.assorted_string like '%100194-00002-10-2024%' or
A8: KHI/HO/D/MO/PC COMP/C/100033/5/10/2024 | B8: -10-2024 | H8: 100033 | I8: 00005 | J8: ="ia.assorted_string like '%"&H8&"-"&I8&B8&"%' or" -> ia.assorted_string like '%100033-00005-10-2024%' or
A9: KHI/HO/D/MO/PC COMP/C/100194/3/10/2024 | B9: -10-2024 | H9: 100194 | I9: 00003 | J9: ="ia.assorted_string like '%"&H9&"-"&I9&B9&"%' or" -> ia.assorted_string like '%100194-00003-10-2024%' or
A10: KHI/HO/D/MO/PC COMP/C/100033/3/10/2024 | B10: -10-2024 | H10: 100033 | I10: 00003 | J10: ="ia.assorted_string like '%"&H10&"-"&I10&B10&"%' or" -> ia.assorted_string like '%100033-00003-10-2024%' or
A11: KHI/HO/D/MO/PC COMP/C/100033/9/10/2024 | B11: -10-2024 | H11: 100033 | I11: 00009 | J11: ="ia.assorted_string like '%"&H11&"-"&I11&B11&"%' or" -> ia.assorted_string like '%100033-00009-10-2024%' or
A12: KHI/HO/D/MO/PC COMP/C/100033/6/10/2024 | B12: -10-2024 | H12: 100033 | I12: 00006 | J12: ="ia.assorted_string like '%"&H12&"-"&I12&B12&"%' or" -> ia.assorted_string like '%100033-00006-10-2024%' or
A13: KHI/HO/D/MO/PC COMP/C/100033/2/10/2024 | B13: -10-2024 | H13: 100033 | I13: 00002 | J13: ="ia.assorted_string like '%"&H13&"-"&I13&B13&"%' or" -> ia.assorted_string like '%100033-00002-10-2024%' or
... A147: KHI/HO/D/MO/PC COMP/C/100129/3/10/2024 | B147: -10-2024 | H147: 100129 | I147: 00003 | J147: ="ia.assorted_string like '%"&H147&"-"&I147&B147&"%' or" -> ia.assorted_string like '%100129-00003-10-2024%' or

Sheet Policy
B1: FUNC_ASSORTED_STRING(IA.ASSORTED_CODE) | C1: ASSORTED_CODE
A2: 1 | B2: KHI/HO/D/MO/PC COMP/C/100228/5/10/2024 | C2: 070000167914
A3: 2 | B3: KHI/HO/D/MO/PC COMP/C/100120/1/10/2024 | C3: 070000167818
A4: 3 | B4: KHI/HO/D/MO/PC COMP/C/100120/2/10/2024 | C4: 070000167823
A5: 4 | B5: KHI/HO/D/MO/PC COMP/C/100120/3/10/2024 | C5: 070000167825
A6: 5 | B6: KHI/HO/D/MO/PC COMP/C/100228/6/10/2024 | C6: 070000167915
A7: 6 | B7: KHI/HO/D/MO/PC COMP/C/100100/2/10/2024 | C7: 070000167793
A8: 7 | B8: KHI/HO/D/MO/PC COMP/C/100100/3/10/2024 | C8: 070000167794
A9: 8 | B9: KHI/HO/D/MO/PC COMP/C/100242/1/10/2024 | C9: 070000167942
A10: 9 | B10: KHI/HO/D/MO/PC COMP/C/100242/2/10/2024 | C10: 070000167943
A11: 10 | B11: KHI/HO/D/MO/PC COMP/C/100242/3/10/2024 | C11: 070000167944
A12: 11 | B12: KHI/HO/D/MO/PC COMP/C/100094/6/10/2024 | C12: 070000167768
A13: 12 | B13: KHI/HO/D/MO/PC COMP/C/100118/1/10/2024 | C13: 070000167813
... A147: 1 | B147: KHI/HO/D/MO/PC COMP/P/102358/11/2024 | C147: 040000189796
