Workbook

Sheet BSPL
A1: Br. Code | B1: Branch Name | C1: Document No. | D1: Type Code | E1: Business Type | F1: Class | G1: Leader Ref. No | H1: Code | I1: Insurance Company | J1: STL POLICY NO | K1: Client Code | L1: Client Name | M1: Insurance | N1: Base No. | O1: Base date | P1: Date | Q1: Premium Payable as per OS report | R1: Premium Payable as per OS report | S1: Paid on Collection | T1: Claim Receivable | U1: S. Charges Receivable | V1: Commission Receivable | W1: Net
A2: 220 | B2: GROUP UNIT | C2: 2024/01/GUEBPOP00003 | D2: E025 | E2: BOILER PRESSURE VESSEL | F2: Engineering | H2: 3114700001 | I2: SALAM TAKAFUL LIMITED | J2: LHR/LHR/F/EG/BPV/P/1176/04/2024 | K2: 1110100035 | L2: BULLEH SHAH PACKAGING (PRIVATE) LIMITED | N2: 2024/01/GUEBPOT00004 | P2: 45322 | Q2: 80760 | R2: 94483 | S2: 94483 | T2: 0 | U2: 2019 | V2: 12111 | W2: 80353 | X2: -2019 | Y2: (2019)
A3: 220 | B3: GROUP UNIT | C3: 2024/01/GUEBPOP00004 | D3: E025 | E3: BOILER PRESSURE VESSEL | F3: Engineering | H3: 3114700001 | I3: SALAM TAKAFUL LIMITED | J3: LHR/LHR/F/EG/BPV/P/1177/04/2024 | K3: 1110100035 | L3: BULLEH SHAH PACKAGING (PRIVATE) LIMITED | N3: 2024/01/GUEBPOT00005 | P3: 45322 | Q3: 400 | R3: 502 | S3: 502 | T3: 0 | U3: 10 | V3: 51 | W3: 441 | X3: -10 | Y3: (10)
A4: 220 | B4: GROUP UNIT | C4: 2024/01/GUEBPOP00005 | D4: E025 | E4: BOILER PRESSURE VESSEL | F4: Engineering | H4: 3114700001 | I4: SALAM TAKAFUL LIMITED | J4: LHR/LHR/F/EG/BPV/P/1178/04/2024 | K4: 1110100035 | L4: BULLEH SHAH PACKAGING (PRIVATE) LIMITED | N4: 2024/01/GUEBPOT00006 | P4: 45322 | Q4: 4520 | R4: 5298 | S4: 5298 | T4: 0 | U4: 113 | V4: 564 | W4: 4621 | X4: -113 | Y4: (113)
A5: 220 | B5: GROUP UNIT | C5: 2024/01/GUFFDOP00005 | D5: F02 | E5: Fire Declaration Policy | F5: Fire | H5: 3114700001 | I5: SALAM TAKAFUL LIMITED | J5: LHR/LHR/F/FR/D/P/21853/03/2024 | K5: 1110100035 | L5: BULLEH SHAH PACKAGING (PRIVATE) LIMITED | N5: 2024/01/GUFFDOT00007 | P5: 45320 | Q5: 16640 | R5: 19503 | S5: 19503 | T5: 0 | U5: 416 | V5: 2498 | W5: 16589 | X5: -416 | Y5: (416)
A6: 220 | B6: GROUP UNIT | C6: 2024/01/GUFFDOP00006 | D6: F02 | E6: Fire Declaration Policy | F6: Fire | H6: 3114700001 | I6: SALAM TAKAFUL LIMITED | J6: LHR/LHR/F/FR/D/P/21854/03/2024 | K6: 1110100035 | L6: BULLEH SHAH PACKAGING (PRIVATE) LIMITED | N6: 2024/01/GUFFDOT00008 | P6: 45320 | Q6: 178200 | R6: 208516 | S6: 208516 | T6: 0 | U6: 4455 | V6: 26731 | W6: 177330 | X6: -4455 | Y6: (4455)
A7: 220 | B7: GROUP UNIT | C7: 2024/01/GUFFDOP00015 | D7: F02 | E7: Fire Declaration Policy | F7: Fire | H7: 3114700001 | I7: SALAM TAKAFUL LIMITED | J7: LHR/LHR/F/FR/D/P/22062/04/2024 | K7: 1110100040 | L7: PACKAGES CONVERTORS LIMITED | N7: 2024/01/GUFFDOT00012 | P7: 45321 | Q7: 55080 | R7: 64460 | S7: 64460 | T7: 0 | U7: 1377 | V7: 8262 | W7: 54821 | X7: -1377 | Y7: (1377)
A8: 220 | B8: GROUP UNIT | C8: 2024/01/GUFFNOP00004 | D8: F01 | E8: Normal Fire Policy | F8: Fire | H8: 3114700001 | I8: SALAM TAKAFUL LIMITED | J8: LHR/LHR/F/FR/ND/P/21852/03/2024 | K8: 1110100035 | L8: BULLEH SHAH PACKAGING (PRIVATE) LIMITED | N8: 2024/01/GUFFNOT00006 | P8: 45320 | Q8: 1064960 | R8: 1245998 | S8: 1245998 | T8: 0 | U8: 26624 | V8: 159741 | W8: 1059633 | X8: -26624 | Y8: (26624)
A9: 220 | B9: GROUP UNIT | C9: 2024/01/GUFFNOP00012 | D9: F01 | E9: Normal Fire Policy | F9: Fire | H9: 3114700001 | I9: SALAM TAKAFUL LIMITED | J9: LHR/LHR/F/FR/ND/P/22059/04/2024 | K9: 1110100040 | L9: PACKAGES CONVERTORS LIMITED | N9: 2024/01/GUFFNOT00009 | P9: 45321 | Q9: 4640 | R9: 5446 | S9: 5446 | T9: 0 | U9: 116 | V9: 696 | W9: 4634 | X9: -116 | Y9: (116)
A10: 220 | B10: GROUP UNIT | C10: 2024/01/GUFFNOP00014 | D10: F01 | E10: Normal Fire Policy | F10: Fire | H10: 3114700001 | I10: SALAM TAKAFUL LIMITED | J10: LHR/LHR/F/FR/ND/P/22061/04/2024 | K10: 1110100040 | L10: PACKAGES CONVERTORS LIMITED | N10: 2024/01/GUFFNOT00011 | P10: 45321 | Q10: 216960 | R10: 253846 | S10: 253846 | T10: 0 | U10: 5424 | V10: 32542 | W10: 215880 | X10: -5424 | Y10: (5424)
A11: 220 | B11: GROUP UNIT | C11: 2024/01/GUFFNOP00017 | D11: F01 | E11: Normal Fire Policy | F11: Fire | H11: 3114700001 | I11: SALAM TAKAFUL LIMITED | J11: LHR/LHR/F/FR/ND/P/22063/04/2024 | K11: 1110100020 | L11: PACKAGES LIMITED | N11: 2024/01/GUFFNOT00014 | P11: 45321 | Q11: 21080 | R11: 24695 | S11: 24695 | T11: 0 | U11: 527 | V11: 3164 | W11: 21004 | X11: -527 | Y11: (527)
A12: 220 | B12: GROUP UNIT | C12: 2024/01/GUFLOOP00003 | D12: F03 | E12: Loss of Profit | F12: Fire | H12: 3114700001 | I12: SALAM TAKAFUL LIMITED | J12: LHR/LHR/F/FR/LOP/P/21851/03/2024 | K12: 1110100035 | L12: BULLEH SHAH PACKAGING (PRIVATE) LIMITED | N12: 2024/01/GUFLOOT00005 | P12: 45320 | Q12: 164080 | R12: 192000 | S12: 192000 | T12: 0 | U12: 4102 | V12: 24613 | W12: 163285 | X12: -4102 | Y12: (4102)
A13: 220 | B13: GROUP UNIT | C13: 2024/01/GUFLOOP00013 | D13: F03 | E13: Loss of Profit | F13: Fire | H13: 3114700001 | I13: SALAM TAKAFUL LIMITED | J13: LHR/LHR/F/FR/LOP/P/22060/04/2024 | K13: 1110100040 | L13: PACKAGES CONVERTORS LIMITED | N13: 2024/01/GUFLOOT00010 | P13: 45321 | Q13: 79640 | R13: 93206 | S13: 93206 | T13: 0 | U13: 1991 | V13: 11947 | W13: 79268 | X13: -1991 | Y13: (1991)
... A17: 220 | B17: GROUP UNIT | C17: 2024/05/GUFFDOE00036 | D17: F02 | E17: Fire Declaration Policy | F17: Fire | H17: 3114700001 | I17: SALAM TAKAFUL LIMITED | J17: LHR/LHR/F/FR/D/P/21853/03/2024 | K17: 1110100035 | L17: BULLEH SHAH PACKAGING (PRIVATE) LIMITED | N17: 2024/01/GUFFDOP00005 | P17: 45444 | Q17: 49480 | R17: 57894 | S17: 57894 | T17: 0 | U17: 1237 | V17: 7422 | W17: 49235 | X17: -1237 | Y17: (1237)
A18: 220 | B18: GROUP UNIT | C18: 2024/05/GUFFDOE00037 | D18: F02 | E18: Fire Declaration Policy | F18: Fire | H18: 3114700001 | I18: SALAM TAKAFUL LIMITED | J18: LHR/LHR/F/FR/D/P/21854/03/2024 | K18: 1110100035 | L18: BULLEH SHAH PACKAGING (PRIVATE) LIMITED | N18: 2024/01/GUFFDOP00006 | P18: 45444 | Q18: -61800 | R18: -62432 | S18: -62432 | T18: 0 | U18: -1545 | V18: -9272 | W18: -51615 | X18: 1545 | Y18: 1545
A19: 220 | B19: GROUP UNIT | C19: 2024/06/GUFFDOE00042 | D19: F02 | E19: Fire Declaration Policy | F19: Fire | H19: 3114700001 | I19: SALAM TAKAFUL LIMITED | J19: LHR/LHR/F/FR/D/P/22062/04/2024 | K19: 1110100040 | L19: PACKAGES CONVERTORS LIMITED | N19: 2024/01/GUFFDOP00015 | P19: 45448 | Q19: -6040 | R19: -6085 | S19: -6085 | T19: 0 | U19: -151 | V19: -904 | W19: -5030 | X19: 151 | Y19: 151
A20: 220 | B20: GROUP UNIT | C20: 2024/06/GUFFDOE00044 | D20: F02 | E20: Fire Declaration Policy | F20: Fire | H20: 3114700001 | I20: SALAM TAKAFUL LIMITED | J20: LHR/LHR/F/FR/D/E/10307/07/2024 | K20: 1110100035 | L20: BULLEH SHAH PACKAGING (PRIVATE) LIMITED | N20: 2024/01/GUFFDOP00005 | P20: 45450 | Q20: 10800 | R20: 12641 | S20: 12641 | T20: 0 | U20: 270 | V20: 1621 | W20: 10750 | X20: -270 | Y20: (270)
A21: 220 | B21: GROUP UNIT | C21: 2024/06/GUFFDOE00045 | D21: F02 | E21: Fire Declaration Policy | F21: Fire | H21: 3114700001 | I21: SALAM TAKAFUL LIMITED | J21: LHR/LHR/F/FR/D/P/21854/03/2024 | K21: 1110100035 | L21: BULLEH SHAH PACKAGING (PRIVATE) LIMITED | N21: 2024/01/GUFFDOP00006 | P21: 45450 | Q21: -160040 | R21: -161648 | S21: -161648 | T21: 0 | U21: -4001 | V21: -24007 | W21: -133640 | X21: 4001 | Y21: 4001
A22: 220 | B22: GROUP UNIT | C22: 2024/06/GUFFDOE00051 | D22: F02 | E22: Fire Declaration Policy | F22: Fire | H22: 3114700001 | I22: SALAM TAKAFUL LIMITED | J22: LHR/LHR/F/FR/D/E/10792/11/2024 | K22: 1110100040 | L22: PACKAGES CONVERTORS LIMITED | N22: 2024/01/GUFFDOP00015 | P22: 45471 | Q22: 10800 | R22: 12634 | S22: 12634 | T22: 0 | U22: 270 | V22: 1620 | W22: 10744 | X22: -270 | Y22: (270)
A23: 220 | B23: GROUP UNIT | C23: 2024/06/GUFFNOE00041 | D23: F01 | E23: Normal Fire Policy | F23: Fire | H23: 3114700001 | I23: SALAM TAKAFUL LIMITED | J23: LHR/LHR/F/FR/ND/E/10619/09/2024 | K23: 1110100040 | L23: PACKAGES CONVERTORS LIMITED | N23: 2024/01/GUFFNOP00012 | P23: 45448 | Q23: 1600 | R23: 1886 | S23: 1886 | T23: 0 | U23: 40 | V23: 242 | W23: 1604 | X23: -40 | Y23: (40)
A24: 220 | B24: GROUP UNIT | C24: 2024/06/GUFFNOE00043 | D24: F01 | E24: Normal Fire Policy | F24: Fire | H24: 3114700001 | I24: SALAM TAKAFUL LIMITED | J24: LHR/LHR/F/FR/ND/E/10615/09/2024 | K24: 1110100040 | L24: PACKAGES CONVERTORS LIMITED | N24: 2024/01/GUFFNOP00014 | P24: 45449 | Q24: 17000 | R24: 19873 | S24: 19873 | T24: 0 | U24: 425 | V24: 2548 | W24: 16900 | X24: -425 | Y24: (425)
A25: 220 | B25: GROUP UNIT | C25: 2024/06/GUFFNOE00047 | D25: F01 | E25: Normal Fire Policy | F25: Fire | H25: 3114700001 | I25: SALAM TAKAFUL LIMITED | J25: LHR/LHR/F/FR/ND/E/10616/09/2024 | K25: 1110100040 | L25: PACKAGES CONVERTORS LIMITED | N25: 2024/01/GUFFNOP00014 | P25: 45463 | Q25: -16040 | R25: -16386 | S25: -16386 | T25: 0 | U25: -401 | V25: -2407 | W25: -13578 | X25: 401 | Y25: 401
A26: 220 | B26: GROUP UNIT | C26: 2024/06/GUFFNOE00048 | D26: F01 | E26: Normal Fire Policy | F26: Fire | H26: 3114700001 | I26: SALAM TAKAFUL LIMITED | J26: LHR/LHR/F/FR/ND/E/10617/09/2024 | K26: 1110100040 | L26: PACKAGES CONVERTORS LIMITED | N26: 2024/01/GUFFNOP00014 | P26: 45463 | Q26: 3920 | R26: 4582 | S26: 4582 | T26: 0 | U26: 98 | V26: 587 | W26: 3897 | X26: -98 | Y26: (98)
A27: 220 | B27: GROUP UNIT | C27: 2024/06/GUFFNOE00049 | D27: F01 | E27: Normal Fire Policy | F27: Fire | H27: 3114700001 | I27: SALAM TAKAFUL LIMITED | J27: LHR/LHR/F/FR/ND/E/10618/09/2024 | K27: 1110100040 | L27: PACKAGES CONVERTORS LIMITED | N27: 2024/01/GUFFNOP00014 | P27: 45467 | Q27: 3400 | R27: 4163 | S27: 4163 | T27: 0 | U27: 85 | V27: 508 | W27: 3570 | X27: -85 | Y27: (85)
A28: 220 | B28: GROUP UNIT | C28: 2024/07/GUFFDOE00052 | D28: F02 | E28: Fire Declaration Policy | F28: Fire | H28: 3114700001 | I28: SALAM TAKAFUL LIMITED | J28: LHR/LHR/F/FR/D/E/10768/10/2024 | K28: 1110100035 | L28: BULLEH SHAH PACKAGING (PRIVATE) LIMITED | N28: 2024/01/GUFFDOP00005 | P28: 45484 | Q28: -11760 | R28: -11862 | S28: -11862 | T28: 0 | U28: -294 | V28: -1762 | W28: -9806 | X28: 294 | Y28: 294
A29: 220 | B29: GROUP UNIT | C29: 2024/07/GUFFDOE00053 | D29: F02 | E29: Fire Declaration Policy | F29: Fire | H29: 3114700001 | I29: SALAM TAKAFUL LIMITED | J29: LHR/LHR/F/FR/D/E/10769/10/2024 | K29: 1110100035 | L29: BULLEH SHAH PACKAGING (PRIVATE) LIMITED | N29: 2024/01/GUFFDOP00006 | P29: 45484 | Q29: -76880 | R29: -77664 | S29: -77664 | T29: 0 | U29: -1922 | V29: -11534 | W29: -64208 | X29: 1922 | Y29: 1922
A30: 220 | B30: GROUP UNIT | C30: 2024/07/GUFFDOE00057 | D30: F02 | E30: Fire Declaration Policy | F30: Fire | H30: 3114700001 | I30: SALAM TAKAFUL LIMITED | J30: LHR/LHR/F/FR/D/E/10795/11/2024 | K30: 1110100040 | L30: PACKAGES CONVERTORS LIMITED | N30: 2024/01/GUFFDOP00015 | P30: 45499 | Q30: -22520 | R30: -22759 | S30: -22759 | T30: 0 | U30: -563 | V30: -3380 | W30: -18816 | X30: 563 | Y30: 563
A31: 220 | B31: GROUP UNIT | C31: 2024/07/GUFFNOE00055 | D31: F01 | E31: Normal Fire Policy | F31: Fire | H31: 3114700001 | I31: SALAM TAKAFUL LIMITED | J31: LHR/LHR/F/FR/ND/E/10796/11/2024 | K31: 1110100040 | L31: PACKAGES CONVERTORS LIMITED | N31: 2024/01/GUFFNOP00012 | P31: 45499 | Q31: 40 | R31: 38 | S31: 38 | T31: 0 | U31: 1 | V31: 5 | W31: 32 | X31: -1 | Y31: (1)
A32: 220 | B32: GROUP UNIT | C32: 2024/07/GUFFNOE00056 | D32: F01 | E32: Normal Fire Policy | F32: Fire | H32: 3114700001 | I32: SALAM TAKAFUL LIMITED | J32: LHR/LHR/F/FR/ND/P/22061/04/2024 | K32: 1110100040 | L32: PACKAGES CONVERTORS LIMITED | N32: 2024/01/GUFFNOP00014 | P32: 45499 | Q32: -40520 | R32: -40914 | S32: -40914 | T32: 0 | U32: -1013 | V32: -6076 | W32: -33825 | X32: 1013 | Y32: 1013
A33: 220 | B33: GROUP UNIT | C33: 2024/07/GUFFNOE00061 | D33: F01 | E33: Normal Fire Policy | F33: Fire | H33: 3114700001 | I33: SALAM TAKAFUL LIMITED | J33: LHR/LHR/F/FR/ND/E/10798/11/2024 | K33: 1110100040 | L33: PACKAGES CONVERTORS LIMITED | N33: 2024/01/GUFFNOP00012 | P33: 45502 | Q33: 1240 | R33: 1435 | S33: 1435 | T33: 0 | U33: 31 | V33: 184 | W33: 1220 | X33: -31 | Y33: (31)
A34: 220 | B34: GROUP UNIT | C34: 2024/07/GUFFNOE00062 | D34: F01 | E34: Normal Fire Policy | F34: Fire | H34: 3114700001 | I34: SALAM TAKAFUL LIMITED | J34: LHR/LHR/F/FR/ND/E/10791/11/2024 | K34: 1110100040 | L34: PACKAGES CONVERTORS LIMITED | N34: 2024/01/GUFFNOP00014 | P34: 45502 | Q34: 24000 | R34: 28085 | S34: 28085 | T34: 0 | U34: 600 | V34: 3599 | W34: 23886 | X34: -600 | Y34: (600)
A35: 220 | B35: GROUP UNIT | C35: 2024/08/GUFFDOE00067 | D35: F02 | E35: Fire Declaration Policy | F35: Fire | H35: 3114700001 | I35: SALAM TAKAFUL LIMITED | J35: LHR/LHR/F/FR/D/E/10770/10/2024 | K35: 1110100035 | L35: BULLEH SHAH PACKAGING (PRIVATE) LIMITED | N35: 2024/01/GUFFDOP00005 | P35: 45513 | Q35: -14520 | R35: -14670 | S35: -14670 | T35: 0 | U35: -363 | V35: -2179 | W35: -12128 | X35: 363 | Y35: 363
A36: 220 | B36: GROUP UNIT | C36: 2024/08/GUFFDOE00068 | D36: F02 | E36: Fire Declaration Policy | F36: Fire | H36: 3114700001 | I36: SALAM TAKAFUL LIMITED | J36: LHR/LHR/F/FR/D/E/10772/10/2024 | K36: 1110100035 | L36: BULLEH SHAH PACKAGING (PRIVATE) LIMITED | N36: 2024/01/GUFFDOP00006 | P36: 45513 | Q36: -95720 | R36: -96674 | S36: -96674 | T36: 0 | U36: -2393 | V36: -14358 | W36: -79923 | X36: 2393 | Y36: 2393
A37: 220 | B37: GROUP UNIT | C37: 2024/08/GUFFDOE00071 | D37: F02 | E37: Fire Declaration Policy | F37: Fire | H37: 3114700001 | I37: SALAM TAKAFUL LIMITED | J37: LHR/LHR/F/FR/D/E/10804/11/2024 | K37: 1110100040 | L37: PACKAGES CONVERTORS LIMITED | N37: 2024/01/GUFFDOP00015 | P37: 45517 | Q37: -34320 | R37: -34678 | S37: -34678 | T37: 0 | U37: -858 | V37: -5150 | W37: -28670 | X37: 858 | Y37: 858
A38: 220 | B38: GROUP UNIT | C38: 2024/08/GUFFNOE00069 | D38: F01 | E38: Normal Fire Policy | F38: Fire | H38: 3114700001 | I38: SALAM TAKAFUL LIMITED | J38: LHR/LHR/F/FR/ND/E/10801/11/2024 | K38: 1110100040 | L38: PACKAGES CONVERTORS LIMITED | N38: 2024/01/GUFFNOP00014 | P38: 45517 | Q38: 3840 | R38: 4479 | S38: 4479 | T38: 0 | U38: 96 | V38: 574 | W38: 3809 | X38: -96 | Y38: (96)
A39: 220 | B39: GROUP UNIT | C39: 2024/08/GUFFNOE00070 | D39: F01 | E39: Normal Fire Policy | F39: Fire | H39: 3114700001 | I39: SALAM TAKAFUL LIMITED | J39: LHR/LHR/F/FR/ND/E/10803/11/2024 | K39: 1110100040 | L39: PACKAGES CONVERTORS LIMITED | N39: 2024/01/GUFFNOP00012 | P39: 45517 | Q39: 40 | R39: 36 | S39: 36 | T39: 0 | U39: 1 | V39: 5 | W39: 30 | X39: -1 | Y39: (1)
A40: 220 | B40: GROUP UNIT | C40: 2024/09/GUEBPOE00019 | D40: E025 | E40: BOILER PRESSURE VESSEL | F40: Engineering | H40: 3114700001 | I40: SALAM TAKAFUL LIMITED | J40: LHR/LHR/F/EG/BPV/P/1176/04/2024 | K40: 1110100035 | L40: BULLEH SHAH PACKAGING (PRIVATE) LIMITED | N40: 2024/01/GUEBPOP00003 | P40: 45560 | Q40: 24640 | R40: 28823 | S40: 28823 | T40: 0 | U40: 616 | V40: 2464 | W40: 25743 | X40: -616 | Y40: (616)
A41: 220 | B41: GROUP UNIT | C41: 2024/09/GUFFDOE00074 | D41: F02 | E41: Fire Declaration Policy | F41: Fire | H41: 3114700001 | I41: SALAM TAKAFUL LIMITED | J41: LHR/LHR/F/FR/D/E/10773/10/2024 | K41: 1110100035 | L41: BULLEH SHAH PACKAGING (PRIVATE) LIMITED | N41: 2024/01/GUFFDOP00005 | P41: 45540 | Q41: -8680 | R41: -8781 | S41: -8781 | T41: 0 | U41: -217 | V41: -1304 | W41: -7260 | X41: 217 | Y41: 217
A42: 220 | B42: GROUP UNIT | C42: 2024/09/GUFFDOE00075 | D42: F02 | E42: Fire Declaration Policy | F42: Fire | H42: 3114700001 | I42: SALAM TAKAFUL LIMITED | J42: LHR/LHR/F/FR/D/E/10774/10/2024 | K42: 1110100035 | L42: BULLEH SHAH PACKAGING (PRIVATE) LIMITED | N42: 2024/01/GUFFDOP00006 | P42: 45544 | Q42: 48920 | R42: 57242 | S42: 57242 | T42: 0 | U42: 1223 | V42: 7339 | W42: 48680 | X42: 1223 | Y42: (1223)
A43: 220 | B43: GROUP UNIT | C43: 2024/09/GUFFDOE00079 | D43: F02 | E43: Fire Declaration Policy | F43: Fire | H43: 3114700001 | I43: SALAM TAKAFUL LIMITED | J43: LHR/LHR/F/FR/D/E/10806/11/2024 | K43: 1110100040 | L43: PACKAGES CONVERTORS LIMITED | N43: 2024/01/GUFFDOP00015 | P43: 45553 | Q43: 2720 | R43: 3194 | S43: 3194 | T43: 0 | U43: 68 | V43: 410 | W43: 2716 | X43: -68 | Y43: (68)
...

Sheet working Premium
A1: POLICY NO. | B1: Assorted_code | D1: Premium | E1: 07Nov240059
A2: LHR/LHR/F/EG/BPV/P/1176/04/2024 | B2: =VLOOKUP(A2,Policy!B:D,2,0) -> 040000171025 | C2: 94483 | D2: =ROUND(C2,0) -> 94483 | E2: 07Nov240059 | F2: ="insert into ins_premium_det (premium_rcv_code,assorted_code, rec_amount,premium_rcv_detail_code,remaining_amt, payrec, mode_code,coinsurance_code,class_cd,it_remarks) values" -> insert into ins_premium_det (premium_rcv_code,assorted_code, rec_amount,premium_rcv_detail_code,remaining_amt, payrec, mode_code,coinsurance_code,class_cd,it_remarks) values | G2: ="('"&E2&"','"&B2&"','"&D2&"',(select max(to_number(i.premium_rcv_detail_code))+1 from ins_premium_det i),'"&D2&"','"&D2&"','02', '11000003','00','Request by Mr. Saqib Saleem 08-Nov-2024 Added Premium');" -> ('07Nov240059','040000171025','94483',(select max(to_number(i.premium_rcv_detail_code))+1 from ins_premium_det i),'94483','94483','02', '11000003','00','Request by Mr. Saqib Saleem 08-Nov-2024 Added Premium'); | H2: =F2&G2 -> insert into ins_premium_det (premium_rcv_code,assorted_code, rec_amount,premium_rcv_detail_code,remaining_amt, payrec, mode_code,coinsurance_code,class_cd,it_remarks) values('07Nov240059','040000171025','94483',(select max(to_number(i.premium_rcv_detail_code))+1 from ins_premium_det i),'94483','94483','02', '11000003','00','Request by Mr. Saqib Saleem 08-Nov-2024 Added Premium');
A3: LHR/LHR/F/EG/BPV/P/1177/04/2024 | B3: =VLOOKUP(A3,Policy!B:D,2,0) -> 040000171029 | C3: 502 | D3: =ROUND(C3,0) -> 502 | E3: 07Nov240059 | F3: ="insert into ins_premium_det (premium_rcv_code,assorted_code, rec_amount,premium_rcv_detail_code,remaining_amt, payrec, mode_code,coinsurance_code,class_cd,it_remarks) values" -> insert into ins_premium_det (premium_rcv_code,assorted_code, rec_amount,premium_rcv_detail_code,remaining_amt, payrec, mode_code,coinsurance_code,class_cd,it_remarks) values | G3: ="('"&E3&"','"&B3&"','"&D3&"',(select max(to_number(i.premium_rcv_detail_code))+1 from ins_premium_det i),'"&D3&"','"&D3&"','02', '11000003','00','Request by Mr. Saqib Saleem 08-Nov-2024 Added Premium');" -> ('07Nov240059','040000171029','502',(select max(to_number(i.premium_rcv_detail_code))+1 from ins_premium_det i),'502','502','02', '11000003','00','Request by Mr. Saqib Saleem 08-Nov-2024 Added Premium'); | H3: =F3&G3 -> insert into ins_premium_det (premium_rcv_code,assorted_code, rec_amount,premium_rcv_detail_code,remaining_amt, payrec, mode_code,coinsurance_code,class_cd,it_remarks) values('07Nov240059','040000171029','502',(select max(to_number(i.premium_rcv_detail_code))+1 from ins_premium_det i),'502','502','02', '11000003','00','Request by Mr. Saqib Saleem 08-Nov-2024 Added Premium');
A4: LHR/LHR/F/EG/BPV/P/1178/04/2024 | B4: =VLOOKUP(A4,Policy!B:D,2,0) -> 040000171031 | C4: 5298 | D4: =ROUND(C4,0) -> 5298 | E4: 07Nov240059 | F4: ="insert into ins_premium_det (premium_rcv_code,assorted_code, rec_amount,premium_rcv_detail_code,remaining_amt, payrec, mode_code,coinsurance_code,class_cd,it_remarks) values" -> insert into ins_premium_det (premium_rcv_code,assorted_code, rec_amount,premium_rcv_detail_code,remaining_amt, payrec, mode_code,coinsurance_code,class_cd,it_remarks) values | G4: ="('"&E4&"','"&B4&"','"&D4&"',(select max(to_number(i.premium_rcv_detail_code))+1 from ins_premium_det i),'"&D4&"','"&D4&"','02', '11000003','00','Request by Mr. Saqib Saleem 08-Nov-2024 Added Premium');" -> ('07Nov240059','040000171031','5298',(select max(to_number(i.premium_rcv_detail_code))+1 from ins_premium_det i),'5298','5298','02', '11000003','00','Request by Mr. Saqib Saleem 08-Nov-2024 Added Premium'); | H4: =F4&G4 -> insert into ins_premium_det (premium_rcv_code,assorted_code, rec_amount,premium_rcv_detail_code,remaining_amt, payrec, mode_code,coinsurance_code,class_cd,it_remarks) values('07Nov240059','040000171031','5298',(select max(to_number(i.premium_rcv_detail_code))+1 from ins_premium_det i),'5298','5298','02', '11000003','00','Request by Mr. Saqib Saleem 08-Nov-2024 Added Premium');
A5: LHR/LHR/F/FR/D/P/21853/03/2024 | B5: =VLOOKUP(A5,Policy!B:D,2,0) -> 040000169361 | C5: 19503 | D5: =ROUND(C5,0) -> 19503 | E5: 07Nov240059 | F5: ="insert into ins_premium_det (premium_rcv_code,assorted_code, rec_amount,premium_rcv_detail_code,remaining_amt, payrec, mode_code,coinsurance_code,class_cd,it_remarks) values" -> insert into ins_premium_det (premium_rcv_code,assorted_code, rec_amount,premium_rcv_detail_code,remaining_amt, payrec, mode_code,coinsurance_code,class_cd,it_remarks) values | G5: ="('"&E5&"','"&B5&"','"&D5&"',(select max(to_number(i.premium_rcv_detail_code))+1 from ins_premium_det i),'"&D5&"','"&D5&"','02', '11000003','00','Request by Mr. Saqib Saleem 08-Nov-2024 Added Premium');" -> ('07Nov240059','040000169361','19503',(select max(to_number(i.premium_rcv_detail_code))+1 from ins_premium_det i),'19503','19503','02', '11000003','00','Request by Mr. Saqib Saleem 08-Nov-2024 Added Premium'); | H5: =F5&G5 -> insert into ins_premium_det (premium_rcv_code,assorted_code, rec_amount,premium_rcv_detail_code,remaining_amt, payrec, mode_code,coinsurance_code,class_cd,it_remarks) values('07Nov240059','040000169361','19503',(select max(to_number(i.premium_rcv_detail_code))+1 from ins_premium_det i),'19503','19503','02', '11000003','00','Request by Mr. Saqib Saleem 08-Nov-2024 Added Premium');
A6: LHR/LHR/F/FR/D/P/21854/03/2024 | B6: =VLOOKUP(A6,Policy!B:D,2,0) -> 040000169362 | C6: 208516 | D6: =ROUND(C6,0) -> 208516 | E6: 07Nov240059 | F6: ="insert into ins_premium_det (premium_rcv_code,assorted_code, rec_amount,premium_rcv_detail_code,remaining_amt, payrec, mode_code,coinsurance_code,class_cd,it_remarks) values" -> insert into ins_premium_det (premium_rcv_code,assorted_code, rec_amount,premium_rcv_detail_code,remaining_amt, payrec, mode_code,coinsurance_code,class_cd,it_remarks) values | G6: ="('"&E6&"','"&B6&"','"&D6&"',(select max(to_number(i.premium_rcv_detail_code))+1 from ins_premium_det i),'"&D6&"','"&D6&"','02', '11000003','00','Request by Mr. Saqib Saleem 08-Nov-2024 Added Premium');" -> ('07Nov240059','040000169362','208516',(select max(to_number(i.premium_rcv_detail_code))+1 from ins_premium_det i),'208516','208516','02', '11000003','00','Request by Mr. Saqib Saleem 08-Nov-2024 Added Premium'); | H6: =F6&G6 -> insert into ins_premium_det (premium_rcv_code,assorted_code, rec_amount,premium_rcv_detail_code,remaining_amt, payrec, mode_code,coinsurance_code,class_cd,it_remarks) values('07Nov240059','040000169362','208516',(select max(to_number(i.premium_rcv_detail_code))+1 from ins_premium_det i),'208516','208516','02', '11000003','00','Request by Mr. Saqib Saleem 08-Nov-2024 Added Premium');
A7: LHR/LHR/F/FR/D/P/22062/04/2024 | B7: =VLOOKUP(A7,Policy!B:D,2,0) -> 040000170920 | C7: 64460 | D7: =ROUND(C7,0) -> 64460 | E7: 07Nov240059 | F7: ="insert into ins_premium_det (premium_rcv_code,assorted_code, rec_amount,premium_rcv_detail_code,remaining_amt, payrec, mode_code,coinsurance_code,class_cd,it_remarks) values" -> insert into ins_premium_det (premium_rcv_code,assorted_code, rec_amount,premium_rcv_detail_code,remaining_amt, payrec, mode_code,coinsurance_code,class_cd,it_remarks) values | G7: ="('"&E7&"','"&B7&"','"&D7&"',(select max(to_number(i.premium_rcv_detail_code))+1 from ins_premium_det i),'"&D7&"','"&D7&"','02', '11000003','00','Request by Mr. Saqib Saleem 08-Nov-2024 Added Premium');" -> ('07Nov240059','040000170920','64460',(select max(to_number(i.premium_rcv_detail_code))+1 from ins_premium_det i),'64460','64460','02', '11000003','00','Request by Mr. Saqib Saleem 08-Nov-2024 Added Premium'); | H7: =F7&G7 -> insert into ins_premium_det (premium_rcv_code,assorted_code, rec_amount,premium_rcv_detail_code,remaining_amt, payrec, mode_code,coinsurance_code,class_cd,it_remarks) values('07Nov240059','040000170920','64460',(select max(to_number(i.premium_rcv_detail_code))+1 from ins_premium_det i),'64460','64460','02', '11000003','00','Request by Mr. Saqib Saleem 08-Nov-2024 Added Premium');
A8: LHR/LHR/F/FR/ND/P/21852/03/2024 | B8: =VLOOKUP(A8,Policy!B:D,2,0) -> 040000169360 | C8: 1245998 | D8: =ROUND(C8,0) -> 1245998 | E8: 07Nov240059 | F8: ="insert into ins_premium_det (premium_rcv_code,assorted_code, rec_amount,premium_rcv_detail_code,remaining_amt, payrec, mode_code,coinsurance_code,class_cd,it_remarks) values" -> insert into ins_premium_det (premium_rcv_code,assorted_code, rec_amount,premium_rcv_detail_code,remaining_amt, payrec, mode_code,coinsurance_code,class_cd,it_remarks) values | G8: ="('"&E8&"','"&B8&"','"&D8&"',(select max(to_number(i.premium_rcv_detail_code))+1 from ins_premium_det i),'"&D8&"','"&D8&"','02', '11000003','00','Request by Mr. Saqib Saleem 08-Nov-2024 Added Premium');" -> ('07Nov240059','040000169360','1245998',(select max(to_number(i.premium_rcv_detail_code))+1 from ins_premium_det i),'1245998','1245998','02', '11000003','00','Request by Mr. Saqib Saleem 08-Nov-2024 Added Premium'); | H8: =F8&G8 -> insert into ins_premium_det (premium_rcv_code,assorted_code, rec_amount,premium_rcv_detail_code,remaining_amt, payrec, mode_code,coinsurance_code,class_cd,it_remarks) values('07Nov240059','040000169360','1245998',(select max(to_number(i.premium_rcv_detail_code))+1 from ins_premium_det i),'1245998','1245998','02', '11000003','00','Request by Mr. Saqib Saleem 08-Nov-2024 Added Premium');
A9: LHR/LHR/F/FR/ND/P/22059/04/2024 | B9: =VLOOKUP(A9,Policy!B:D,2,0) -> 040000170889 | C9: 5446 | D9: =ROUND(C9,0) -> 5446 | E9: 07Nov240059 | F9: ="insert into ins_premium_det (premium_rcv_code,assorted_code, rec_amount,premium_rcv_detail_code,remaining_amt, payrec, mode_code,coinsurance_code,class_cd,it_remarks) values" -> insert into ins_premium_det (premium_rcv_code,assorted_code, rec_amount,premium_rcv_detail_code,remaining_amt, payrec, mode_code,coinsurance_code,class_cd,it_remarks) values | G9: ="('"&E9&"','"&B9&"','"&D9&"',(select max(to_number(i.premium_rcv_detail_code))+1 from ins_premium_det i),'"&D9&"','"&D9&"','02', '11000003','00','Request by Mr. Saqib Saleem 08-Nov-2024 Added Premium');" -> ('07Nov240059','040000170889','5446',(select max(to_number(i.premium_rcv_detail_code))+1 from ins_premium_det i),'5446','5446','02', '11000003','00','Request by Mr. Saqib Saleem 08-Nov-2024 Added Premium'); | H9: =F9&G9 -> insert into ins_premium_det (premium_rcv_code,assorted_code, rec_amount,premium_rcv_detail_code,remaining_amt, payrec, mode_code,coinsurance_code,class_cd,it_remarks) values('07Nov240059','040000170889','5446',(select max(to_number(i.premium_rcv_detail_code))+1 from ins_premium_det i),'5446','5446','02', '11000003','00','Request by Mr. Saqib Saleem 08-Nov-2024 Added Premium');
A10: LHR/LHR/F/FR/ND/P/22061/04/2024 | B10: =VLOOKUP(A10,Policy!B:D,2,0) -> 040000170918 | C10: 253846 | D10: =ROUND(C10,0) -> 253846 | E10: 07Nov240059 | F10: ="insert into ins_premium_det (premium_rcv_code,assorted_code, rec_amount,premium_rcv_detail_code,remaining_amt, payrec, mode_code,coinsurance_code,class_cd,it_remarks) values" -> insert into ins_premium_det (premium_rcv_code,assorted_code, rec_amount,premium_rcv_detail_code,remaining_amt, payrec, mode_code,coinsurance_code,class_cd,it_remarks) values | G10: ="('"&E10&"','"&B10&"','"&D10&"',(select max(to_number(i.premium_rcv_detail_code))+1 from ins_premium_det i),'"&D10&"','"&D10&"','02', '11000003','00','Request by Mr. Saqib Saleem 08-Nov-2024 Added Premium');" -> ('07Nov240059','040000170918','253846',(select max(to_number(i.premium_rcv_detail_code))+1 from ins_premium_det i),'253846','253846','02', '11000003','00','Request by Mr. Saqib Saleem 08-Nov-2024 Added Premium'); | H10: =F10&G10 -> insert into ins_premium_det (premium_rcv_code,assorted_code, rec_amount,premium_rcv_detail_code,remaining_amt, payrec, mode_code,coinsurance_code,class_cd,it_remarks) values('07Nov240059','040000170918','253846',(select max(to_number(i.premium_rcv_detail_code))+1 from ins_premium_det i),'253846','253846','02', '11000003','00','Request by Mr. Saqib Saleem 08-Nov-2024 Added Premium');
A11: LHR/LHR/F/FR/ND/P/22063/04/2024 | B11: =VLOOKUP(A11,Policy!B:D,2,0) -> 040000170923 | C11: 24695 | D11: =ROUND(C11,0) -> 24695 | E11: 07Nov240059 | F11: ="insert into ins_premium_det (premium_rcv_code,assorted_code, rec_amount,premium_rcv_detail_code,remaining_amt, payrec, mode_code,coinsurance_code,class_cd,it_remarks) values" -> insert into ins_premium_det (premium_rcv_code,assorted_code, rec_amount,premium_rcv_detail_code,remaining_amt, payrec, mode_code,coinsurance_code,class_cd,it_remarks) values | G11: ="('"&E11&"','"&B11&"','"&D11&"',(select max(to_number(i.premium_rcv_detail_code))+1 from ins_premium_det i),'"&D11&"','"&D11&"','02', '11000003','00','Request by Mr. Saqib Saleem 08-Nov-2024 Added Premium');" -> ('07Nov240059','040000170923','24695',(select max(to_number(i.premium_rcv_detail_code))+1 from ins_premium_det i),'24695','24695','02', '11000003','00','Request by Mr. Saqib Saleem 08-Nov-2024 Added Premium'); | H11: =F11&G11 -> insert into ins_premium_det (premium_rcv_code,assorted_code, rec_amount,premium_rcv_detail_code,remaining_amt, payrec, mode_code,coinsurance_code,class_cd,it_remarks) values('07Nov240059','040000170923','24695',(select max(to_number(i.premium_rcv_detail_code))+1 from ins_premium_det i),'24695','24695','02', '11000003','00','Request by Mr. Saqib Saleem 08-Nov-2024 Added Premium');
A12: LHR/LHR/F/FR/LOP/P/21851/03/2024 | B12: =VLOOKUP(A12,Policy!B:D,2,0) -> 040000169359 | C12: 192000 | D12: =ROUND(C12,0) -> 192000 | E12: 07Nov240059 | F12: ="insert into ins_premium_det (premium_rcv_code,assorted_code, rec_amount,premium_rcv_detail_code,remaining_amt, payrec, mode_code,coinsurance_code,class_cd,it_remarks) values" -> insert into ins_premium_det (premium_rcv_code,assorted_code, rec_amount,premium_rcv_detail_code,remaining_amt, payrec, mode_code,coinsurance_code,class_cd,it_remarks) values | G12: ="('"&E12&"','"&B12&"','"&D12&"',(select max(to_number(i.premium_rcv_detail_code))+1 from ins_premium_det i),'"&D12&"','"&D12&"','02', '11000003','00','Request by Mr. Saqib Saleem 08-Nov-2024 Added Premium');" -> ('07Nov240059','040000169359','192000',(select max(to_number(i.premium_rcv_detail_code))+1 from ins_premium_det i),'192000','192000','02', '11000003','00','Request by Mr. Saqib Saleem 08-Nov-2024 Added Premium'); | H12: =F12&G12 -> insert into ins_premium_det (premium_rcv_code,assorted_code, rec_amount,premium_rcv_detail_code,remaining_amt, payrec, mode_code,coinsurance_code,class_cd,it_remarks) values('07Nov240059','040000169359','192000',(select max(to_number(i.premium_rcv_detail_code))+1 from ins_premium_det i),'192000','192000','02', '11000003','00','Request by Mr. Saqib Saleem 08-Nov-2024 Added Premium');
A13: LHR/LHR/F/FR/LOP/P/22060/04/2024 | B13: =VLOOKUP(A13,Policy!B:D,2,0) -> 040000170892 | C13: 93206 | D13: =ROUND(C13,0) -> 93206 | E13: 07Nov240059 | F13: ="insert into ins_premium_det (premium_rcv_code,assorted_code, rec_amount,premium_rcv_detail_code,remaining_amt, payrec, mode_code,coinsurance_code,class_cd,it_remarks) values" -> insert into ins_premium_det (premium_rcv_code,assorted_code, rec_amount,premium_rcv_detail_code,remaining_amt, payrec, mode_code,coinsurance_code,class_cd,it_remarks) values | G13: ="('"&E13&"','"&B13&"','"&D13&"',(select max(to_number(i.premium_rcv_detail_code))+1 from ins_premium_det i),'"&D13&"','"&D13&"','02', '11000003','00','Request by Mr. Saqib Saleem 08-Nov-2024 Added Premium');" -> ('07Nov240059','040000170892','93206',(select max(to_number(i.premium_rcv_detail_code))+1 from ins_premium_det i),'93206','93206','02', '11000003','00','Request by Mr. Saqib Saleem 08-Nov-2024 Added Premium'); | H13: =F13&G13 -> insert into ins_premium_det (premium_rcv_code,assorted_code, rec_amount,premium_rcv_detail_code,remaining_amt, payrec, mode_code,coinsurance_code,class_cd,it_remarks) values('07Nov240059','040000170892','93206',(select max(to_number(i.premium_rcv_detail_code))+1 from ins_premium_det i),'93206','93206','02', '11000003','00','Request by Mr. Saqib Saleem 08-Nov-2024 Added Premium');
... A45: LHR/LHR/F/FR/ND/E/10813/11/2024 | B45: =VLOOKUP(A45,Policy!B:D,2,0) -> 050000822555 | C45: 1265 | D45: =ROUND(C45,0) -> 1265 | E45: 07Nov240059 | F45: ="insert into ins_premium_det (premium_rcv_code,assorted_code, rec_amount,premium_rcv_detail_code,remaining_amt, payrec, mode_code,coinsurance_code,class_cd,it_remarks) values" -> insert into ins_premium_det (premium_rcv_code,assorted_code, rec_amount,premium_rcv_detail_code,remaining_amt, payrec, mode_code,coinsurance_code,class_cd,it_remarks) values | G45: ="('"&E45&"','"&B45&"','"&D45&"',(select max(to_number(i.premium_rcv_detail_code))+1 from ins_premium_det i),'"&D45&"','"&D45&"','02', '11000003','00','Request by Mr. Saqib Saleem 08-Nov-2024 Added Premium');" -> ('07Nov240059','050000822555','1265',(select max(to_number(i.premium_rcv_detail_code))+1 from ins_premium_det i),'1265','1265','02', '11000003','00','Request by Mr. Saqib Saleem 08-Nov-2024 Added Premium'); | H45: =F45&G45 -> insert into ins_premium_det (premium_rcv_code,assorted_code, rec_amount,premium_rcv_detail_code,remaining_amt, payrec, mode_code,coinsurance_code,class_cd,it_remarks) values('07Nov240059','050000822555','1265',(select max(to_number(i.premium_rcv_detail_code))+1 from ins_premium_det i),'1265','1265','02', '11000003','00','Request by Mr. Saqib Saleem 08-Nov-2024 Added Premium');
C46: =SUM(C2:C45) -> 2007373 | D46: =SUM(D2:D45) -> 2007373

Sheet working commission
A1: POLICY NO. | B1: Assorted_code | C1: Commission | D1: 07Nov240059
A2: LHR/LHR/F/EG/BPV/P/1176/04/2024 | B2: =VLOOKUP(A2,Policy!B:C,2,0) -> 040000171025 | C2: 12111 | D2: 07Nov240059 | E2: =VLOOKUP(A2,Policy!B:D,3,0) -> 09000397 | F2: ="insert into ins_premium_det (premium_rcv_code,assorted_code, rec_amount,premium_rcv_detail_code,remaining_amt, payrec, mode_code,paid_to_code,class_cd) values" -> insert into ins_premium_det (premium_rcv_code,assorted_code, rec_amount,premium_rcv_detail_code,remaining_amt, payrec, mode_code,paid_to_code,class_cd) values | G2: ="('"&D1&"','"&B2&"','"&C2&"',(select max(to_number(i.premium_rcv_detail_code))+1 from ins_premium_det i),'"&C2&"','"&C2&"','03', '"&E2&"','00');" -> ('07Nov240059','040000171025','12111',(select max(to_number(i.premium_rcv_detail_code))+1 from ins_premium_det i),'12111','12111','03', '09000397','00'); | H2: =F2&G2 -> insert into ins_premium_det (premium_rcv_code,assorted_code, rec_amount,premium_rcv_detail_code,remaining_amt, payrec, mode_code,paid_to_code,class_cd) values('07Nov240059','040000171025','12111',(select max(to_number(i.premium_rcv_detail_code))+1 from ins_premium_det i),'12111','12111','03', '09000397','00');
A3: LHR/LHR/F/EG/BPV/P/1177/04/2024 | B3: =VLOOKUP(A3,Policy!B:C,2,0) -> 040000171029 | C3: 51 | D3: 07Nov240059 | E3: =VLOOKUP(A3,Policy!B:D,3,0) -> 09000397 | F3: ="insert into ins_premium_det (premium_rcv_code,assorted_code, rec_amount,premium_rcv_detail_code,remaining_amt, payrec, mode_code,paid_to_code,class_cd) values" -> insert into ins_premium_det (premium_rcv_code,assorted_code, rec_amount,premium_rcv_detail_code,remaining_amt, payrec, mode_code,paid_to_code,class_cd) values | G3: ="('"&D2&"','"&B3&"','"&C3&"',(select max(to_number(i.premium_rcv_detail_code))+1 from ins_premium_det i),'"&C3&"','"&C3&"','03', '"&E3&"','00');" -> ('07Nov240059','040000171029','51',(select max(to_number(i.premium_rcv_detail_code))+1 from ins_premium_det i),'51','51','03', '09000397','00'); | H3: =F3&G3 -> insert into ins_premium_det (premium_rcv_code,assorted_code, rec_amount,premium_rcv_detail_code,remaining_amt, payrec, mode_code,paid_to_code,class_cd) values('07Nov240059','040000171029','51',(select max(to_number(i.premium_rcv_detail_code))+1 from ins_premium_det i),'51','51','03', '09000397','00');
A4: LHR/LHR/F/EG/BPV/P/1178/04/2024 | B4: =VLOOKUP(A4,Policy!B:C,2,0) -> 040000171031 | C4: 564 | D4: 07Nov240059 | E4: =VLOOKUP(A4,Policy!B:D,3,0) -> 09000397 | F4: ="insert into ins_premium_det (premium_rcv_code,assorted_code, rec_amount,premium_rcv_detail_code,remaining_amt, payrec, mode_code,paid_to_code,class_cd) values" -> insert into ins_premium_det (premium_rcv_code,assorted_code, rec_amount,premium_rcv_detail_code,remaining_amt, payrec, mode_code,paid_to_code,class_cd) values | G4: ="('"&D3&"','"&B4&"','"&C4&"',(select max(to_number(i.premium_rcv_detail_code))+1 from ins_premium_det i),'"&C4&"','"&C4&"','03', '"&E4&"','00');" -> ('07Nov240059','040000171031','564',(select max(to_number(i.premium_rcv_detail_code))+1 from ins_premium_det i),'564','564','03', '09000397','00'); | H4: =F4&G4 -> insert into ins_premium_det (premium_rcv_code,assorted_code, rec_amount,premium_rcv_detail_code,remaining_amt, payrec, mode_code,paid_to_code,class_cd) values('07Nov240059','040000171031','564',(select max(to_number(i.premium_rcv_detail_code))+1 from ins_premium_det i),'564','564','03', '09000397','00');
A5: LHR/LHR/F/FR/D/P/21853/03/2024 | B5: =VLOOKUP(A5,Policy!B:C,2,0) -> 040000169361 | C5: 2498 | D5: 07Nov240059 | E5: =VLOOKUP(A5,Policy!B:D,3,0) -> 09000397 | F5: ="insert into ins_premium_det (premium_rcv_code,assorted_code, rec_amount,premium_rcv_detail_code,remaining_amt, payrec, mode_code,paid_to_code,class_cd) values" -> insert into ins_premium_det (premium_rcv_code,assorted_code, rec_amount,premium_rcv_detail_code,remaining_amt, payrec, mode_code,paid_to_code,class_cd) values | G5: ="('"&D4&"','"&B5&"','"&C5&"',(select max(to_number(i.premium_rcv_detail_code))+1 from ins_premium_det i),'"&C5&"','"&C5&"','03', '"&E5&"','00');" -> ('07Nov240059','040000169361','2498',(select max(to_number(i.premium_rcv_detail_code))+1 from ins_premium_det i),'2498','2498','03', '09000397','00'); | H5: =F5&G5 -> insert into ins_premium_det (premium_rcv_code,assorted_code, rec_amount,premium_rcv_detail_code,remaining_amt, payrec, mode_code,paid_to_code,class_cd) values('07Nov240059','040000169361','2498',(select max(to_number(i.premium_rcv_detail_code))+1 from ins_premium_det i),'2498','2498','03', '09000397','00');
A6: LHR/LHR/F/FR/D/P/21854/03/2024 | B6: =VLOOKUP(A6,Policy!B:C,2,0) -> 040000169362 | C6: 26731 | D6: 07Nov240059 | E6: =VLOOKUP(A6,Policy!B:D,3,0) -> 09000397 | F6: ="insert into ins_premium_det (premium_rcv_code,assorted_code, rec_amount,premium_rcv_detail_code,remaining_amt, payrec, mode_code,paid_to_code,class_cd) values" -> insert into ins_premium_det (premium_rcv_code,assorted_code, rec_amount,premium_rcv_detail_code,remaining_amt, payrec, mode_code,paid_to_code,class_cd) values | G6: ="('"&D5&"','"&B6&"','"&C6&"',(select max(to_number(i.premium_rcv_detail_code))+1 from ins_premium_det i),'"&C6&"','"&C6&"','03', '"&E6&"','00');" -> ('07Nov240059','040000169362','26731',(select max(to_number(i.premium_rcv_detail_code))+1 from ins_premium_det i),'26731','26731','03', '09000397','00'); | H6: =F6&G6 -> insert into ins_premium_det (premium_rcv_code,assorted_code, rec_amount,premium_rcv_detail_code,remaining_amt, payrec, mode_code,paid_to_code,class_cd) values('07Nov240059','040000169362','26731',(select max(to_number(i.premium_rcv_detail_code))+1 from ins_premium_det i),'26731','26731','03', '09000397','00');
A7: LHR/LHR/F/FR/D/P/22062/04/2024 | B7: =VLOOKUP(A7,Policy!B:C,2,0) -> 040000170920 | C7: 8262 | D7: 07Nov240059 | E7: =VLOOKUP(A7,Policy!B:D,3,0) -> 09000397 | F7: ="insert into ins_premium_det (premium_rcv_code,assorted_code, rec_amount,premium_rcv_detail_code,remaining_amt, payrec, mode_code,paid_to_code,class_cd) values" -> insert into ins_premium_det (premium_rcv_code,assorted_code, rec_amount,premium_rcv_detail_code,remaining_amt, payrec, mode_code,paid_to_code,class_cd) values | G7: ="('"&D6&"','"&B7&"','"&C7&"',(select max(to_number(i.premium_rcv_detail_code))+1 from ins_premium_det i),'"&C7&"','"&C7&"','03', '"&E7&"','00');" -> ('07Nov240059','040000170920','8262',(select max(to_number(i.premium_rcv_detail_code))+1 from ins_premium_det i),'8262','8262','03', '09000397','00'); | H7: =F7&G7 -> insert into ins_premium_det (premium_rcv_code,assorted_code, rec_amount,premium_rcv_detail_code,remaining_amt, payrec, mode_code,paid_to_code,class_cd) values('07Nov240059','040000170920','8262',(select max(to_number(i.premium_rcv_detail_code))+1 from ins_premium_det i),'8262','8262','03', '09000397','00');
A8: LHR/LHR/F/FR/ND/P/21852/03/2024 | B8: =VLOOKUP(A8,Policy!B:C,2,0) -> 040000169360 | C8: 159741 | D8: 07Nov240059 | E8: =VLOOKUP(A8,Policy!B:D,3,0) -> 09000397 | F8: ="insert into ins_premium_det (premium_rcv_code,assorted_code, rec_amount,premium_rcv_detail_code,remaining_amt, payrec, mode_code,paid_to_code,class_cd) values" -> insert into ins_premium_det (premium_rcv_code,assorted_code, rec_amount,premium_rcv_detail_code,remaining_amt, payrec, mode_code,paid_to_code,class_cd) values | G8: ="('"&D7&"','"&B8&"','"&C8&"',(select max(to_number(i.premium_rcv_detail_code))+1 from ins_premium_det i),'"&C8&"','"&C8&"','03', '"&E8&"','00');" -> ('07Nov240059','040000169360','159741',(select max(to_number(i.premium_rcv_detail_code))+1 from ins_premium_det i),'159741','159741','03', '09000397','00'); | H8: =F8&G8 -> insert into ins_premium_det (premium_rcv_code,assorted_code, rec_amount,premium_rcv_detail_code,remaining_amt, payrec, mode_code,paid_to_code,class_cd) values('07Nov240059','040000169360','159741',(select max(to_number(i.premium_rcv_detail_code))+1 from ins_premium_det i),'159741','159741','03', '09000397','00');
A9: LHR/LHR/F/FR/ND/P/22059/04/2024 | B9: =VLOOKUP(A9,Policy!B:C,2,0) -> 040000170889 | C9: 696 | D9: 07Nov240059 | E9: =VLOOKUP(A9,Policy!B:D,3,0) -> 09000397 | F9: ="insert into ins_premium_det (premium_rcv_code,assorted_code, rec_amount,premium_rcv_detail_code,remaining_amt, payrec, mode_code,paid_to_code,class_cd) values" -> insert into ins_premium_det (premium_rcv_code,assorted_code, rec_amount,premium_rcv_detail_code,remaining_amt, payrec, mode_code,paid_to_code,class_cd) values | G9: ="('"&D8&"','"&B9&"','"&C9&"',(select max(to_number(i.premium_rcv_detail_code))+1 from ins_premium_det i),'"&C9&"','"&C9&"','03', '"&E9&"','00');" -> ('07Nov240059','040000170889','696',(select max(to_number(i.premium_rcv_detail_code))+1 from ins_premium_det i),'696','696','03', '09000397','00'); | H9: =F9&G9 -> insert into ins_premium_det (premium_rcv_code,assorted_code, rec_amount,premium_rcv_detail_code,remaining_amt, payrec, mode_code,paid_to_code,class_cd) values('07Nov240059','040000170889','696',(select max(to_number(i.premium_rcv_detail_code))+1 from ins_premium_det i),'696','696','03', '09000397','00');
A10: LHR/LHR/F/FR/ND/P/22061/04/2024 | B10: =VLOOKUP(A10,Policy!B:C,2,0) -> 040000170918 | C10: 32542 | D10: 07Nov240059 | E10: =VLOOKUP(A10,Policy!B:D,3,0) -> 09000397 | F10: ="insert into ins_premium_det (premium_rcv_code,assorted_code, rec_amount,premium_rcv_detail_code,remaining_amt, payrec, mode_code,paid_to_code,class_cd) values" -> insert into ins_premium_det (premium_rcv_code,assorted_code, rec_amount,premium_rcv_detail_code,remaining_amt, payrec, mode_code,paid_to_code,class_cd) values | G10: ="('"&D9&"','"&B10&"','"&C10&"',(select max(to_number(i.premium_rcv_detail_code))+1 from ins_premium_det i),'"&C10&"','"&C10&"','03', '"&E10&"','00');" -> ('07Nov240059','040000170918','32542',(select max(to_number(i.premium_rcv_detail_code))+1 from ins_premium_det i),'32542','32542','03', '09000397','00'); | H10: =F10&G10 -> insert into ins_premium_det (premium_rcv_code,assorted_code, rec_amount,premium_rcv_detail_code,remaining_amt, payrec, mode_code,paid_to_code,class_cd) values('07Nov240059','040000170918','32542',(select max(to_number(i.premium_rcv_detail_code))+1 from ins_premium_det i),'32542','32542','03', '09000397','00');
A11: LHR/LHR/F/FR/ND/P/22063/04/2024 | B11: =VLOOKUP(A11,Policy!B:C,2,0) -> 040000170923 | C11: 3164 | D11: 07Nov240059 | E11: =VLOOKUP(A11,Policy!B:D,3,0) -> 09000397 | F11: ="insert into ins_premium_det (premium_rcv_code,assorted_code, rec_amount,premium_rcv_detail_code,remaining_amt, payrec, mode_code,paid_to_code,class_cd) values" -> insert into ins_premium_det (premium_rcv_code,assorted_code, rec_amount,premium_rcv_detail_code,remaining_amt, payrec, mode_code,paid_to_code,class_cd) values | G11: ="('"&D10&"','"&B11&"','"&C11&"',(select max(to_number(i.premium_rcv_detail_code))+1 from ins_premium_det i),'"&C11&"','"&C11&"','03', '"&E11&"','00');" -> ('07Nov240059','040000170923','3164',(select max(to_number(i.premium_rcv_detail_code))+1 from ins_premium_det i),'3164','3164','03', '09000397','00'); | H11: =F11&G11 -> insert into ins_premium_det (premium_rcv_code,assorted_code, rec_amount,premium_rcv_detail_code,remaining_amt, payrec, mode_code,paid_to_code,class_cd) values('07Nov240059','040000170923','3164',(select max(to_number(i.premium_rcv_detail_code))+1 from ins_premium_det i),'3164','3164','03', '09000397','00');
A12: LHR/LHR/F/FR/LOP/P/21851/03/2024 | B12: =VLOOKUP(A12,Policy!B:C,2,0) -> 040000169359 | C12: 24613 | D12: 07Nov240059 | E12: =VLOOKUP(A12,Policy!B:D,3,0) -> 09000397 | F12: ="insert into ins_premium_det (premium_rcv_code,assorted_code, rec_amount,premium_rcv_detail_code,remaining_amt, payrec, mode_code,paid_to_code,class_cd) values" -> insert into ins_premium_det (premium_rcv_code,assorted_code, rec_amount,premium_rcv_detail_code,remaining_amt, payrec, mode_code,paid_to_code,class_cd) values | G12: ="('"&D11&"','"&B12&"','"&C12&"',(select max(to_number(i.premium_rcv_detail_code))+1 from ins_premium_det i),'"&C12&"','"&C12&"','03', '"&E12&"','00');" -> ('07Nov240059','040000169359','24613',(select max(to_number(i.premium_rcv_detail_code))+1 from ins_premium_det i),'24613','24613','03', '09000397','00'); | H12: =F12&G12 -> insert into ins_premium_det (premium_rcv_code,assorted_code, rec_amount,premium_rcv_detail_code,remaining_amt, payrec, mode_code,paid_to_code,class_cd) values('07Nov240059','040000169359','24613',(select max(to_number(i.premium_rcv_detail_code))+1 from ins_premium_det i),'24613','24613','03', '09000397','00');
A13: LHR/LHR/F/FR/LOP/P/22060/04/2024 | B13: =VLOOKUP(A13,Policy!B:C,2,0) -> 040000170892 | C13: 11947 | D13: 07Nov240059 | E13: =VLOOKUP(A13,Policy!B:D,3,0) -> 09000397 | F13: ="insert into ins_premium_det (premium_rcv_code,assorted_code, rec_amount,premium_rcv_detail_code,remaining_amt, payrec, mode_code,paid_to_code,class_cd) values" -> insert into ins_premium_det (premium_rcv_code,assorted_code, rec_amount,premium_rcv_detail_code,remaining_amt, payrec, mode_code,paid_to_code,class_cd) values | G13: ="('"&D12&"','"&B13&"','"&C13&"',(select max(to_number(i.premium_rcv_detail_code))+1 from ins_premium_det i),'"&C13&"','"&C13&"','03', '"&E13&"','00');" -> ('07Nov240059','040000170892','11947',(select max(to_number(i.premium_rcv_detail_code))+1 from ins_premium_det i),'11947','11947','03', '09000397','00'); | H13: =F13&G13 -> insert into ins_premium_det (premium_rcv_code,assorted_code, rec_amount,premium_rcv_detail_code,remaining_amt, payrec, mode_code,paid_to_code,class_cd) values('07Nov240059','040000170892','11947',(select max(to_number(i.premium_rcv_detail_code))+1 from ins_premium_det i),'11947','11947','03', '09000397','00');
... A45: LHR/LHR/F/FR/ND/E/10813/11/2024 | B45: =VLOOKUP(A45,Policy!B:C,2,0) -> 050000822555 | C45: 162 | D45: 07Nov240059 | E45: =VLOOKUP(A45,Policy!B:D,3,0) -> 09000397 | F45: ="insert into ins_premium_det (premium_rcv_code,assorted_code, rec_amount,premium_rcv_detail_code,remaining_amt, payrec, mode_code,paid_to_code,class_cd) values" -> insert into ins_premium_det (premium_rcv_code,assorted_code, rec_amount,premium_rcv_detail_code,remaining_amt, payrec, mode_code,paid_to_code,class_cd) values | G45: ="('"&D44&"','"&B45&"','"&C45&"',(select max(to_number(i.premium_rcv_detail_code))+1 from ins_premium_det i),'"&C45&"','"&C45&"','03', '"&E45&"','00');" -> ('07Nov240059','050000822555','162',(select max(to_number(i.premium_rcv_detail_code))+1 from ins_premium_det i),'162','162','03', '09000397','00'); | H45: =F45&G45 -> insert into ins_premium_det (premium_rcv_code,assorted_code, rec_amount,premium_rcv_detail_code,remaining_amt, payrec, mode_code,paid_to_code,class_cd) values('07Nov240059','050000822555','162',(select max(to_number(i.premium_rcv_detail_code))+1 from ins_premium_det i),'162','162','03', '09000397','00');
C47: =SUM(C2:C45) -> 244670

Sheet working Service Charges
A1: POLICY NO. | B1: Assorted_code | C1: Commission | D1: 07Nov240059
A2: LHR/LHR/F/EG/BPV/P/1176/04/2024 | B2: 040000171025 | C2: -2019 | D2: 07Nov240059 | E2: =VLOOKUP(A2,Policy!B:D,3,0) -> 09000397 | F2: ="insert into ins_premium_det (premium_rcv_code,assorted_code, rec_amount,premium_rcv_detail_code,remaining_amt, payrec, mode_code,paid_to_code,class_cd) values" -> insert into ins_premium_det (premium_rcv_code,assorted_code, rec_amount,premium_rcv_detail_code,remaining_amt, payrec, mode_code,paid_to_code,class_cd) values | G2: ="('"&D1&"','"&B2&"','"&C2&"',(select max(to_number(i.premium_rcv_detail_code))+1 from ins_premium_det i),'"&C2&"','"&C2&"','05', '"&E2&"','00');" -> ('07Nov240059','040000171025','-2019',(select max(to_number(i.premium_rcv_detail_code))+1 from ins_premium_det i),'-2019','-2019','05', '09000397','00'); | H2: =F2&G2 -> insert into ins_premium_det (premium_rcv_code,assorted_code, rec_amount,premium_rcv_detail_code,remaining_amt, payrec, mode_code,paid_to_code,class_cd) values('07Nov240059','040000171025','-2019',(select max(to_number(i.premium_rcv_detail_code))+1 from ins_premium_det i),'-2019','-2019','05', '09000397','00');
A3: LHR/LHR/F/EG/BPV/P/1177/04/2024 | B3: 040000171029 | C3: -10 | D3: 07Nov240059 | E3: =VLOOKUP(A3,Policy!B:D,3,0) -> 09000397 | F3: ="insert into ins_premium_det (premium_rcv_code,assorted_code, rec_amount,premium_rcv_detail_code,remaining_amt, payrec, mode_code,paid_to_code,class_cd) values" -> insert into ins_premium_det (premium_rcv_code,assorted_code, rec_amount,premium_rcv_detail_code,remaining_amt, payrec, mode_code,paid_to_code,class_cd) values | G3: ="('"&D2&"','"&B3&"','"&C3&"',(select max(to_number(i.premium_rcv_detail_code))+1 from ins_premium_det i),'"&C3&"','"&C3&"','05', '"&E3&"','00');" -> ('07Nov240059','040000171029','-10',(select max(to_number(i.premium_rcv_detail_code))+1 from ins_premium_det i),'-10','-10','05', '09000397','00'); | H3: =F3&G3 -> insert into ins_premium_det (premium_rcv_code,assorted_code, rec_amount,premium_rcv_detail_code,remaining_amt, payrec, mode_code,paid_to_code,class_cd) values('07Nov240059','040000171029','-10',(select max(to_number(i.premium_rcv_detail_code))+1 from ins_premium_det i),'-10','-10','05', '09000397','00');
A4: LHR/LHR/F/EG/BPV/P/1178/04/2024 | B4: 040000171031 | C4: -113 | D4: 07Nov240059 | E4: =VLOOKUP(A4,Policy!B:D,3,0) -> 09000397 | F4: ="insert into ins_premium_det (premium_rcv_code,assorted_code, rec_amount,premium_rcv_detail_code,remaining_amt, payrec, mode_code,paid_to_code,class_cd) values" -> insert into ins_premium_det (premium_rcv_code,assorted_code, rec_amount,premium_rcv_detail_code,remaining_amt, payrec, mode_code,paid_to_code,class_cd) values | G4: ="('"&D3&"','"&B4&"','"&C4&"',(select max(to_number(i.premium_rcv_detail_code))+1 from ins_premium_det i),'"&C4&"','"&C4&"','05', '"&E4&"','00');" -> ('07Nov240059','040000171031','-113',(select max(to_number(i.premium_rcv_detail_code))+1 from ins_premium_det i),'-113','-113','05', '09000397','00'); | H4: =F4&G4 -> insert into ins_premium_det (premium_rcv_code,assorted_code, rec_amount,premium_rcv_detail_code,remaining_amt, payrec, mode_code,paid_to_code,class_cd) values('07Nov240059','040000171031','-113',(select max(to_number(i.premium_rcv_detail_code))+1 from ins_premium_det i),'-113','-113','05', '09000397','00');
A5: LHR/LHR/F/FR/D/P/21853/03/2024 | B5: 040000169361 | C5: -416 | D5: 07Nov240059 | E5: =VLOOKUP(A5,Policy!B:D,3,0) -> 09000397 | F5: ="insert into ins_premium_det (premium_rcv_code,assorted_code, rec_amount,premium_rcv_detail_code,remaining_amt, payrec, mode_code,paid_to_code,class_cd) values" -> insert into ins_premium_det (premium_rcv_code,assorted_code, rec_amount,premium_rcv_detail_code,remaining_amt, payrec, mode_code,paid_to_code,class_cd) values | G5: ="('"&D4&"','"&B5&"','"&C5&"',(select max(to_number(i.premium_rcv_detail_code))+1 from ins_premium_det i),'"&C5&"','"&C5&"','05', '"&E5&"','00');" -> ('07Nov240059','040000169361','-416',(select max(to_number(i.premium_rcv_detail_code))+1 from ins_premium_det i),'-416','-416','05', '09000397','00'); | H5: =F5&G5 -> insert into ins_premium_det (premium_rcv_code,assorted_code, rec_amount,premium_rcv_detail_code,remaining_amt, payrec, mode_code,paid_to_code,class_cd) values('07Nov240059','040000169361','-416',(select max(to_number(i.premium_rcv_detail_code))+1 from ins_premium_det i),'-416','-416','05', '09000397','00');
A6: LHR/LHR/F/FR/D/P/21854/03/2024 | B6: 040000169362 | C6: -4455 | D6: 07Nov240059 | E6: =VLOOKUP(A6,Policy!B:D,3,0) -> 09000397 | F6: ="insert into ins_premium_det (premium_rcv_code,assorted_code, rec_amount,premium_rcv_detail_code,remaining_amt, payrec, mode_code,paid_to_code,class_cd) values" -> insert into ins_premium_det (premium_rcv_code,assorted_code, rec_amount,premium_rcv_detail_code,remaining_amt, payrec, mode_code,paid_to_code,class_cd) values | G6: ="('"&D5&"','"&B6&"','"&C6&"',(select max(to_number(i.premium_rcv_detail_code))+1 from ins_premium_det i),'"&C6&"','"&C6&"','05', '"&E6&"','00');" -> ('07Nov240059','040000169362','-4455',(select max(to_number(i.premium_rcv_detail_code))+1 from ins_premium_det i),'-4455','-4455','05', '09000397','00'); | H6: =F6&G6 -> insert into ins_premium_det (premium_rcv_code,assorted_code, rec_amount,premium_rcv_detail_code,remaining_amt, payrec, mode_code,paid_to_code,class_cd) values('07Nov240059','040000169362','-4455',(select max(to_number(i.premium_rcv_detail_code))+1 from ins_premium_det i),'-4455','-4455','05', '09000397','00');
A7: LHR/LHR/F/FR/D/P/22062/04/2024 | B7: 040000170920 | C7: -1377 | D7: 07Nov240059 | E7: =VLOOKUP(A7,Policy!B:D,3,0) -> 09000397 | F7: ="insert into ins_premium_det (premium_rcv_code,assorted_code, rec_amount,premium_rcv_detail_code,remaining_amt, payrec, mode_code,paid_to_code,class_cd) values" -> insert into ins_premium_det (premium_rcv_code,assorted_code, rec_amount,premium_rcv_detail_code,remaining_amt, payrec, mode_code,paid_to_code,class_cd) values | G7: ="('"&D6&"','"&B7&"','"&C7&"',(select max(to_number(i.premium_rcv_detail_code))+1 from ins_premium_det i),'"&C7&"','"&C7&"','05', '"&E7&"','00');" -> ('07Nov240059','040000170920','-1377',(select max(to_number(i.premium_rcv_detail_code))+1 from ins_premium_det i),'-1377','-1377','05', '09000397','00'); | H7: =F7&G7 -> insert into ins_premium_det (premium_rcv_code,assorted_code, rec_amount,premium_rcv_detail_code,remaining_amt, payrec, mode_code,paid_to_code,class_cd) values('07Nov240059','040000170920','-1377',(select max(to_number(i.premium_rcv_detail_code))+1 from ins_premium_det i),'-1377','-1377','05', '09000397','00');
A8: LHR/LHR/F/FR/ND/P/21852/03/2024 | B8: 040000169360 | C8: -26624 | D8: 07Nov240059 | E8: =VLOOKUP(A8,Policy!B:D,3,0) -> 09000397 | F8: ="insert into ins_premium_det (premium_rcv_code,assorted_code, rec_amount,premium_rcv_detail_code,remaining_amt, payrec, mode_code,paid_to_code,class_cd) values" -> insert into ins_premium_det (premium_rcv_code,assorted_code, rec_amount,premium_rcv_detail_code,remaining_amt, payrec, mode_code,paid_to_code,class_cd) values | G8: ="('"&D7&"','"&B8&"','"&C8&"',(select max(to_number(i.premium_rcv_detail_code))+1 from ins_premium_det i),'"&C8&"','"&C8&"','05', '"&E8&"','00');" -> ('07Nov240059','040000169360','-26624',(select max(to_number(i.premium_rcv_detail_code))+1 from ins_premium_det i),'-26624','-26624','05', '09000397','00'); | H8: =F8&G8 -> insert into ins_premium_det (premium_rcv_code,assorted_code, rec_amount,premium_rcv_detail_code,remaining_amt, payrec, mode_code,paid_to_code,class_cd) values('07Nov240059','040000169360','-26624',(select max(to_number(i.premium_rcv_detail_code))+1 from ins_premium_det i),'-26624','-26624','05', '09000397','00');
A9: LHR/LHR/F/FR/ND/P/22059/04/2024 | B9: 040000170889 | C9: -116 | D9: 07Nov240059 | E9: =VLOOKUP(A9,Policy!B:D,3,0) -> 09000397 | F9: ="insert into ins_premium_det (premium_rcv_code,assorted_code, rec_amount,premium_rcv_detail_code,remaining_amt, payrec, mode_code,paid_to_code,class_cd) values" -> insert into ins_premium_det (premium_rcv_code,assorted_code, rec_amount,premium_rcv_detail_code,remaining_amt, payrec, mode_code,paid_to_code,class_cd) values | G9: ="('"&D8&"','"&B9&"','"&C9&"',(select max(to_number(i.premium_rcv_detail_code))+1 from ins_premium_det i),'"&C9&"','"&C9&"','05', '"&E9&"','00');" -> ('07Nov240059','040000170889','-116',(select max(to_number(i.premium_rcv_detail_code))+1 from ins_premium_det i),'-116','-116','05', '09000397','00'); | H9: =F9&G9 -> insert into ins_premium_det (premium_rcv_code,assorted_code, rec_amount,premium_rcv_detail_code,remaining_amt, payrec, mode_code,paid_to_code,class_cd) values('07Nov240059','040000170889','-116',(select max(to_number(i.premium_rcv_detail_code))+1 from ins_premium_det i),'-116','-116','05', '09000397','00');
A10: LHR/LHR/F/FR/ND/P/22061/04/2024 | B10: 040000170918 | C10: -5424 | D10: 07Nov240059 | E10: =VLOOKUP(A10,Policy!B:D,3,0) -> 09000397 | F10: ="insert into ins_premium_det (premium_rcv_code,assorted_code, rec_amount,premium_rcv_detail_code,remaining_amt, payrec, mode_code,paid_to_code,class_cd) values" -> insert into ins_premium_det (premium_rcv_code,assorted_code, rec_amount,premium_rcv_detail_code,remaining_amt, payrec, mode_code,paid_to_code,class_cd) values | G10: ="('"&D9&"','"&B10&"','"&C10&"',(select max(to_number(i.premium_rcv_detail_code))+1 from ins_premium_det i),'"&C10&"','"&C10&"','05', '"&E10&"','00');" -> ('07Nov240059','040000170918','-5424',(select max(to_number(i.premium_rcv_detail_code))+1 from ins_premium_det i),'-5424','-5424','05', '09000397','00'); | H10: =F10&G10 -> insert into ins_premium_det (premium_rcv_code,assorted_code, rec_amount,premium_rcv_detail_code,remaining_amt, payrec, mode_code,paid_to_code,class_cd) values('07Nov240059','040000170918','-5424',(select max(to_number(i.premium_rcv_detail_code))+1 from ins_premium_det i),'-5424','-5424','05', '09000397','00');
A11: LHR/LHR/F/FR/ND/P/22063/04/2024 | B11: 040000170923 | C11: -527 | D11: 07Nov240059 | E11: =VLOOKUP(A11,Policy!B:D,3,0) -> 09000397 | F11: ="insert into ins_premium_det (premium_rcv_code,assorted_code, rec_amount,premium_rcv_detail_code,remaining_amt, payrec, mode_code,paid_to_code,class_cd) values" -> insert into ins_premium_det (premium_rcv_code,assorted_code, rec_amount,premium_rcv_detail_code,remaining_amt, payrec, mode_code,paid_to_code,class_cd) values | G11: ="('"&D10&"','"&B11&"','"&C11&"',(select max(to_number(i.premium_rcv_detail_code))+1 from ins_premium_det i),'"&C11&"','"&C11&"','05', '"&E11&"','00');" -> ('07Nov240059','040000170923','-527',(select max(to_number(i.premium_rcv_detail_code))+1 from ins_premium_det i),'-527','-527','05', '09000397','00'); | H11: =F11&G11 -> insert into ins_premium_det (premium_rcv_code,assorted_code, rec_amount,premium_rcv_detail_code,remaining_amt, payrec, mode_code,paid_to_code,class_cd) values('07Nov240059','040000170923','-527',(select max(to_number(i.premium_rcv_detail_code))+1 from ins_premium_det i),'-527','-527','05', '09000397','00');
