Workbook

Sheet Park in advance
A1: S.No | B1: Contract No. | C1: Customer Name | D1: CNIC No. | E1: Engine No. | F1: Chassis No. | G1: Premium | H1: ACC Number | I1: ACC Branch | J1: INSURANCE CO. | K1: Policy # | L1: Endorsement No. | M1: Tms premium | N1: Difference
A2: 1 | B2: 9976AD1243620007 | C2: NAFEESA SHABBAR | D2: 42201-0642598-6 | E2: 1GD1684167 | F2: GUN126R-5567644 | G2: 242620 | H2: 0006437055 | I2: 106 | J2: SALAAM TAKAFUL PAKISTAN | K2: 0 | M2: #N/A | N2: #N/A
A3: 2 | B3: 997AFRR250310025 | C3: MUHAMMAD AKBAR | D3: 33100-2595054-7 | E3: R06AR1002363 | F3: NF1ADE17V00102377 | G3: 48983 | H3: 0006437055 | I3: 106 | J3: SALAAM TAKAFUL PAKISTAN | K3: 0 | M3: #N/A | N3: #N/A
A4: 3 | B4: 997AFRR250310026 | C4: AZIM FAISAL | D4: 42401-8323701-5 | E4: 51030529 | F4: 047597 | G4: 89565 | H4: 0006437055 | I4: 106 | J4: SALAAM TAKAFUL PAKISTAN | K4: 0 | M4: #N/A | N4: #N/A
G5: =SUM(G2:G4) -> 381168
G9: 381168

Sheet PAYMENT ON MONTH OF JAN-2025
A1: S.No. | B1: Contract No. | C1: Customer Name | D1: CNIC No. | E1: Engine No. | F1: Chassis No. | G1: Premium | H1: ACC Number | I1: ACC Branch | J1: INSURANCE CO. | K1: Policy # | L1: Endorsement No. | M1: Tms premium | N1: Difference
A2: 1 | B2: 9976AD1243300002 | C2: MOZZAM MEHMOOD ALI | D2: 42101-4127287-5 | E2: 6R332326 | F2: 1232363 | G2: 54140 | H2: 0006437055 | I2: 106 | J2: SALAAM TAKAFUL PAKISTAN | K2: KHI/HO/D/MO/PC COMP/C/105332/1/01/2025 | L2: KHI/HO/D/MO/PC COMP/E/52321/00001/02/2025 | M2: 47373 | N2: =G2-M2 -> 6767
A3: 2 | B3: 9976AD1250220003 | C3: MUHAMMAD USMAN YAQOOB | D3: 37405-9697482-1 | E3: 244H0007907 | F3: 2013250 | G3: 188919 | H3: 0006437055 | I3: 106 | J3: SALAAM TAKAFUL PAKISTAN | K3: KHI/HO/D/MO/PC COMP/C/105332/97/01/2025 | L3: KHI/HO/D/MO/PC COMP/C/105332/97/01/2025 | M3: 188919 | N3: 0
A4: 3 | B4: 9976AD2250270003 | C4: GHAZNFAR ALI | D4: 36602-3276971-9 | E4: 6R337147 | F4: 1237192 | G4: 60900 | H4: 0006437055 | I4: 106 | J4: SALAAM TAKAFUL PAKISTAN | K4: KHI/HO/D/MO/PC COMP/C/105332/118/01/2025 | L4: KHI/HO/D/MO/PC COMP/E/52321/00118/02/2025 | M4: 53288 | N4: =G4-M4 -> 7612
A5: 4 | B5: 9976AP1250080006 | C5: SHUMAILA QURESHI | D5: 42501-5237561-2 | E5: G3LAKP168992 | F5: 700774 | G5: 42000 | H5: 0006437055 | I5: 106 | J5: SALAAM TAKAFUL PAKISTAN | K5: KHI/HO/D/MO/PC COMP/C/105332/5/01/2025 | L5: KHI/HO/D/MO/PC COMP/C/105332/5/01/2025 | M5: 42000 | N5: 0
A6: 5 | B6: 9976AP1250080007 | C6: HAFIZ MUHAMMAD YOOSUF | D6: 35202-2957078-9 | E6: L12B51029644 | F6: NFBGN8620RR046857 | G6: 82583 | H6: 0006437055 | I6: 106 | J6: SALAAM TAKAFUL PAKISTAN | K6: KHI/HO/D/MO/PC COMP/C/105332/2/01/2025 | L6: KHI/HO/D/MO/PC COMP/C/105332/2/01/2025 | M6: 82583 | N6: 0
A7: 6 | B7: 9976AP1250090013 | C7: MOHSIN TARIQ | D7: 35202-7819761-7 | E7: 10229402 | F7: RR046334 | G7: 70785 | H7: 0006437055 | I7: 106 | J7: SALAAM TAKAFUL PAKISTAN | K7: KHI/HO/D/MO/PC COMP/C/105332/9/01/2025 | L7: KHI/HO/D/MO/PC COMP/E/52321/00009/02/2025 | M7: 82583 | N7: =G7-M7 -> -11798
A8: 7 | B8: 9976AP1250090016 | C8: SALEHA WAJAHAT | D8: 42201-5538754-0 | E8: 2A71687 | F8: 7048908 | G8: 83300 | H8: 0006437055 | I8: 106 | J8: SALAAM TAKAFUL PAKISTAN | K8: KHI/HO/D/MO/PC COMP/C/105332/11/01/2025 | L8: KHI/HO/D/MO/PC COMP/C/105332/11/01/2025 | M8: 83300 | N8: 0
A9: 8 | B9: 9976AP1250100001 | C9: AWAIS SAFDAR | D9: 35202-2784905-3 | E9: PKF630879 | F9: SF410PK537749 | G9: 28875 | H9: 0006437055 | I9: 106 | J9: SALAAM TAKAFUL PAKISTAN | K9: KHI/HO/D/MO/PC COMP/C/105332/12/01/2025 | L9: KHI/HO/D/MO/PC COMP/C/105332/12/01/2025 | M9: 28875 | N9: 0
A10: 9 | B10: 9976AP1250100002 | C10: ARISH WASEEM | D10: 35202-3887272-1 | E10: 1029959 | F10: 047059 | G10: 82583 | H10: 0006437055 | I10: 106 | J10: SALAAM TAKAFUL PAKISTAN | K10: KHI/HO/D/MO/PC COMP/C/105332/13/01/2025 | L10: KHI/HO/D/MO/PC COMP/C/105332/13/01/2025 | M10: 82583 | N10: 0
A11: 10 | B11: 9976AP1250100005 | C11: SHEHARYAR HASSAN QADRI | D11: 35202-2689819-5 | E11: 9Z01206 | F11: ZVG10R0900248 | G11: 173250 | H11: 0006437055 | I11: 106 | J11: SALAAM TAKAFUL PAKISTAN | K11: KHI/HO/D/MO/PC COMP/C/105332/6/01/2025 | L11: KHI/HO/D/MO/PC COMP/C/105332/6/01/2025 | M11: 173250 | N11: 0
A12: 11 | B12: 9976AP1250130009 | C12: RABIA WAHAB | D12: 35201-5264118-2 | E12: 6R298313 | F12: NF1AET306H1198313 | G12: 43400 | H12: 0006437055 | I12: 106 | J12: SALAAM TAKAFUL PAKISTAN | K12: KHI/HO/D/MO/PC COMP/C/105332/20/01/2025 | L12: KHI/HO/D/MO/PC COMP/C/105332/20/01/2025 | M12: 43400 | N12: 0
A13: 12 | B13: 9976AP1250140001 | C13: MUHAMMAD IRFAN | D13: 35201-1549704-1 | E13: 335098 | F13: 1234919 | G13: 47373 | H13: 0006437055 | I13: 106 | J13: SALAAM TAKAFUL PAKISTAN | K13: KHI/HO/D/MO/PC COMP/C/105332/25/01/2025 | L13: KHI/HO/D/MO/PC COMP/C/105332/25/01/2025 | M13: 47373 | N13: 0
A14: 13 | B14: 9976AP1250150003 | C14: ISHFAQ AHMAD | D14: 14301-7912654-7 | E14: PK10K141282 | F14: NF1AVK31H10042141 | G14: 41125 | H14: 0006437055 | I14: 106 | J14: SALAAM TAKAFUL PAKISTAN | K14: KHI/HO/D/MO/PC COMP/C/105332/30/01/2025 | L14: KHI/HO/D/MO/PC COMP/C/105332/30/01/2025 | M14: 41125 | N14: 0
A15: 14 | B15: 9976AP1250160005 | C15: SYED HAMEED UDDIN-ASAAN ACCOUNT | D15: 42201-6761440-7 | E15: 6R116188 | F15: H1016195 | G15: 35000 | H15: 0006437055 | I15: 106 | J15: SALAAM TAKAFUL PAKISTAN | K15: KHI/HO/D/MO/PC COMP/C/105332/28/01/2025 | L15: KHI/HO/D/MO/PC COMP/C/105332/28/01/2025 | M15: 35000 | N15: 0
A16: 15 | B16: 9976AP1250160006 | C16: SYLVESTER JOHN | D16: 42301-5363287-7 | E16: 6R129136 | F16: H1029131 | G16: 43575 | H16: 0006437055 | I16: 106 | J16: SALAAM TAKAFUL PAKISTAN | K16: KHI/HO/D/MO/PC COMP/C/105332/21/01/2025 | L16: KHI/HO/D/MO/PC COMP/C/105332/21/01/2025 | M16: 43575 | N16: 0
A17: 16 | B17: 9976AP1250160009 | C17: MUHAMMAD BILAL KHALI | D17: 35201-9133356-5 | E17: 6R297664 | F17: NF1AET306H1197660 | G17: 40775 | H17: 0006437055 | I17: 106 | J17: SALAAM TAKAFUL PAKISTAN | K17: KHI/HO/D/MO/PC COMP/C/105332/39/01/2025 | L17: KHI/HO/D/MO/PC COMP/C/105332/39/01/2025 | M17: 40775 | N17: 0
A18: 17 | B18: 9976AP1250170011 | C18: KASHIF BILAL AHMED | D18: 61101-1884641-1 | E18: 6R334765 | F18: 1234879 | G18: 53288 | H18: 0006437055 | I18: 106 | J18: SALAAM TAKAFUL PAKISTAN | K18: KHI/HO/D/MO/PC COMP/C/105332/50/01/2025 | L18: KHI/HO/D/MO/PC COMP/C/105332/50/01/2025 | M18: 53288 | N18: 0
A19: 18 | B19: 9976AP1250170013 | C19: AHMAR ARIF | D19: 35201-5783712-5 | E19: 6R335479 | F19: NF1AET306H1235343 | G19: 47373 | H19: 0006437055 | I19: 106 | J19: SALAAM TAKAFUL PAKISTAN | K19: KHI/HO/D/MO/PC COMP/C/105332/35/01/2025 | L19: KHI/HO/D/MO/PC COMP/C/105332/35/01/2025 | M19: 47373 | N19: 0
... A57: 56 | B57: 9976AP1250310094 | C57: ZEESHAN SAEED | D57: 42201-9673343-9 | E57: 657264 | F57: 1001947 | G57: 127733 | H57: 0006437055 | I57: 106 | J57: SALAAM TAKAFUL PAKISTAN | K57: KHI/HO/D/MO/PC COMP/C/105332/130/01/2025 | L57: KHI/HO/D/MO/PC COMP/C/105332/130/01/2025 | M57: 127733 | N57: 0
A58: 57 | B58: 9976AP1250310095 | C58: MAQBOOL AHMED | D58: 41301-0609394-1 | E58: 321063 | F58: 1001923 | G58: 133485 | H58: 0006437055 | I58: 106 | J58: SALAAM TAKAFUL PAKISTAN | K58: KHI/HO/D/MO/PC COMP/C/105332/143/01/2025 | L58: KHI/HO/D/MO/PC COMP/E/52321/00143/02/2025 | M58: 155733 | N58: =G58-M58 -> -22248
A59: 58 | B59: 9976AP1250310096 | C59: FAHAD YOUNUS | D59: 42101-4113518-1 | E59: 6R244421 | F59: H1144418 | G59: 42000 | H59: 0006437055 | I59: 106 | J59: SALAAM TAKAFUL PAKISTAN | K59: KHI/HO/D/MO/PC COMP/C/105332/137/01/2025 | L59: KHI/HO/D/MO/PC COMP/C/105332/137/01/2025 | M59: 42000 | N59: 0
A60: 59 | B60: 9976AP1250310098 | C60: SAQIB ALI | D60: 42101-1813587-7 | E60: 6R118693 | F60: 1018707 | G60: 35875 | H60: 0006437055 | I60: 106 | J60: SALAAM TAKAFUL PAKISTAN | K60: KHI/HO/D/MO/PC COMP/C/105332/139/01/2025 | L60: KHI/HO/D/MO/PC COMP/C/105332/139/01/2025 | M60: 35875 | N60: 0
A61: 60 | B61: 9976AP1250310099 | C61: HASEEB TAHIR | D61: 42201-2244878-7 | E61: Q093358 | F61: 70832 | G61: 96250 | H61: 0006437055 | I61: 106 | J61: SALAAM TAKAFUL PAKISTAN | K61: KHI/HO/D/MO/PC COMP/C/105332/141/01/2025 | L61: KHI/HO/D/MO/PC COMP/C/105332/141/01/2025 | M61: 96250 | N61: 0
A62: 61 | B62: 9976AP1250310100 | C62: MUHAMMAD RIZWAN | D62: 42101-6296168-7 | E62: 337177 | F62: 1237197 | G62: 53288 | H62: 0006437055 | I62: 106 | J62: SALAAM TAKAFUL PAKISTAN | K62: KHI/HO/D/MO/PC COMP/C/105332/147/01/2025 | L62: KHI/HO/D/MO/PC COMP/C/105332/147/01/2025 | M62: 53288 | N62: 0
A63: 62 | B63: 9976AP1250310102 | C63: MUHAMMAD QADEER | D63: 42301-2656104-1 | E63: 035686 | F63: 714345 | G63: 67375 | H63: 0006437055 | I63: 106 | J63: SALAAM TAKAFUL PAKISTAN | K63: KHI/HO/D/MO/PC COMP/C/105332/159/01/2025 | L63: KHI/HO/D/MO/PC COMP/C/105332/159/01/2025 | M63: 67375 | N63: 0
A64: 63 | B64: 9976AP1250310103 | C64: MUHAMMAD IMRAN MATEEN | D64: 42000-0555403-9 | E64: 6R236806 | F64: 1226860 | G64: 50750 | H64: 0006437055 | I64: 106 | J64: SALAAM TAKAFUL PAKISTAN | K64: KHI/HO/D/MO/PC COMP/C/105332/150/01/2025 | L64: KHI/HO/D/MO/PC COMP/C/105332/150/01/2025 | M64: 50750 | N64: 0
A65: 64 | B65: 9976AP1250310104 | C65: SYED RAHEEM SHAH | D65: 42401-2016090-9 | E65: A101949 | F65: 6079449 | G65: 96250 | H65: 0006437055 | I65: 106 | J65: SALAAM TAKAFUL PAKISTAN | K65: KHI/HO/D/MO/PC COMP/C/105332/153/01/2025 | L65: KHI/HO/D/MO/PC COMP/C/105332/153/01/2025 | M65: 96250 | N65: 0
A66: 65 | B66: 9976AP1250310105 | C66: NAVEED ASGHAR | D66: 31302-2875667-5 | E66: 338104 | F66: 1238063 | G66: 53288 | H66: 0006437055 | I66: 106 | J66: SALAAM TAKAFUL PAKISTAN | K66: KHI/HO/D/MO/PC COMP/C/105332/149/01/2025 | L66: KHI/HO/D/MO/PC COMP/C/105332/149/01/2025 | M66: 53288 | N66: 0
A67: 66 | B67: 9976AP2250060001 | C67: NOMAN JAMAL | D67: 42401-2041909-5 | E67: 6R317840 | F67: 1217842 | G67: 42000 | H67: 0006437055 | I67: 106 | J67: SALAAM TAKAFUL PAKISTAN | K67: KHI/HO/D/MO/PC COMP/C/105332/3/01/2025 | L67: KHI/HO/D/MO/PC COMP/C/105332/3/01/2025 | M67: 42000 | N67: 0
A68: 67 | B68: 9976AP2250090005 | C68: KASHIF ALI | D68: 42501-6752298-5 | E68: PK10K125689 | F68: NF1AV31H10025655 | G68: 36750 | H68: 0006437055 | I68: 106 | J68: SALAAM TAKAFUL PAKISTAN | K68: KHI/HO/D/MO/PC COMP/C/105332/7/01/2025 | L68: KHI/HO/D/MO/PC COMP/C/105332/7/01/2025 | M68: 36750 | N68: 0
A69: 68 | B69: 9976AP2250130002 | C69: FAIZAN ZAHID | D69: 35202-6412030-7 | E69: L15Z14800667 | F69: NFBDG1831KR017349 | G69: 77875 | H69: 0006437055 | I69: 106 | J69: SALAAM TAKAFUL PAKISTAN | K69: KHI/HO/D/MO/PC COMP/C/105332/16/01/2025 | L69: KHI/HO/D/MO/PC COMP/C/105332/16/01/2025 | M69: 77875 | N69: 0
A70: 69 | B70: 9976AP2250130003 | C70: ABDUL RAZZAQ | D70: 35201-6912917-9 | E70: 6R335248 | F70: NF1AET306H1235114 | G70: 47373 | H70: 0006437055 | I70: 106 | J70: SALAAM TAKAFUL PAKISTAN | K70: KHI/HO/D/MO/PC COMP/C/105332/18/01/2025 | L70: KHI/HO/D/MO/PC COMP/C/105332/18/01/2025 | M70: 47373 | N70: 0
... A107: 106 | B107: 997AFRA243470003 | C107: NADEEM NAYAR | D107: 33100-8814208-5 | E107: L12B51030054 | F107: NFBGN625SR047167 | G107: 94380 | H107: 0006437055 | I107: 106 | J107: SALAAM TAKAFUL PAKISTAN | K107: KHI/HO/D/MO/PC COMP/C/105332/41/01/2025 | L107: KHI/HO/D/MO/PC COMP/C/105332/41/01/2025 | M107: 94380 | N107: 0
A108: 107 | B108: 997AFRA243610006 | C108: AHMED RAZA | D108: 38402-8124185-3 | E108: 503732 | F108: 1002426 | G108: 75980 | H108: 0006437055 | I108: 106 | J108: SALAAM TAKAFUL PAKISTAN | K108: KHI/HO/D/MO/PC COMP/C/105332/40/01/2025 | L108: KHI/HO/D/MO/PC COMP/E/52321/00040/02/2025 | M108: 66483 | N108: =G108-M108 -> 9497
A109: 108 | B109: 997AFRR250070003 | C109: KHALID MAHMOOD | D109: 34502-4098589-1 | E109: L12B51010990 | F109: NFBGN8620NR018955 | G109: 75250 | H109: 0006437055 | I109: 106 | J109: SALAAM TAKAFUL PAKISTAN | K109: KHI/HO/D/MO/PC COMP/C/105332/4/01/2025 | L109: KHI/HO/D/MO/PC COMP/C/105332/4/01/2025 | M109: 75250 | N109: 0
A110: 109 | B110: 997AFRR250100001 | C110: HAMZA SHAFQAT | D110: 34201-6330283-5 | E110: 638416 | F110: 545264 | G110: 34000 | H110: 0006437055 | I110: 106 | J110: SALAAM TAKAFUL PAKISTAN | K110: KHI/HO/D/MO/PC COMP/C/105332/14/01/2025 | L110: KHI/HO/D/MO/PC COMP/C/105332/14/01/2025 | M110: 34000 | N110: 0
A111: 110 | B111: 997AFRR250130002 | C111: SYED ALI RAZA SHAH | D111: 35202-5088705-9 | E111: JL473QFM3CAD517891 | F111: NKMA2ASE5M1003785 | G111: 70000 | H111: 0006437055 | I111: 106 | J111: SALAAM TAKAFUL PAKISTAN | K111: KHI/HO/D/MO/PC COMP/C/105332/17/01/2025 | L111: KHI/HO/D/MO/PC COMP/C/105332/17/01/2025 | M111: 70000 | N111: 0
A112: 111 | B112: 997AFRR250130003 | C112: MUHAMMAD HASSAN ABDULLAH | D112: 42101-0204122-5 | E112: Q334194 | F112: 7033403 | G112: 68700 | H112: 0006437055 | I112: 106 | J112: SALAAM TAKAFUL PAKISTAN | K112: KHI/HO/D/MO/PC COMP/C/105332/10/01/2025 | L112: KHI/HO/D/MO/PC COMP/C/105332/10/01/2025 | M112: 68700 | N112: 0
A113: 112 | B113: 997AFRR250150001 | C113: MUHAMMAD AHSAN | D113: 35202-7042221-5 | E113: L15Z13508351 | F113: NFBDG1838JR008355 | G113: 62125 | H113: 0006437055 | I113: 106 | J113: SALAAM TAKAFUL PAKISTAN | K113: KHI/HO/D/MO/PC COMP/C/105332/32/01/2025 | L113: KHI/HO/D/MO/PC COMP/C/105332/32/01/2025 | M113: 62125 | N113: 0
...

Sheet woking
A1: POLICY NO. | B1: Assorted_code | D1: Premium | E1: 20Feb250031
A2: KHI/HO/D/MO/PC COMP/C/105332/1/01/2025 | B2: 070000173661 | C2: 47373 | D2: =ROUND(C2,0) -> 47373 | E2: 20Feb250031 | F2: ="insert into ins_premium_det (premium_rcv_code,assorted_code, rec_amount,premium_rcv_detail_code,remaining_amt, payrec, mode_code,coinsurance_code,class_cd,it_remarks) values" -> insert into ins_premium_det (premium_rcv_code,assorted_code, rec_amount,premium_rcv_detail_code,remaining_amt, payrec, mode_code,coinsurance_code,class_cd,it_remarks) values | G2: ="('"&E2&"','"&B2&"','"&D2&"',(select max(to_number(i.premium_rcv_detail_code))+1 from ins_premium_det i),'"&D2&"','"&D2&"','02', '11000003','00','Request by Mr.Saqib Saleem 20-Feb-2025');" -> ('20Feb250031','070000173661','47373',(select max(to_number(i.premium_rcv_detail_code))+1 from ins_premium_det i),'47373','47373','02', '11000003','00','Request by Mr.Saqib Saleem 20-Feb-2025'); | H2: =F2&G2 -> insert into ins_premium_det (premium_rcv_code,assorted_code, rec_amount,premium_rcv_detail_code,remaining_amt, payrec, mode_code,coinsurance_code,class_cd,it_remarks) values('20Feb250031','070000173661','47373',(select max(to_number(i.premium_rcv_detail_code))+1 from ins_premium_det i),'47373','47373','02', '11000003','00','Request by Mr.Saqib Saleem 20-Feb-2025');
A3: KHI/HO/D/MO/PC COMP/C/105332/97/01/2025 | B3: =VLOOKUP(A3,policy!B:C,2,0) -> 070000174830 | C3: 188919 | D3: =ROUND(C3,0) -> 188919 | E3: 20Feb250031 | F3: ="insert into ins_premium_det (premium_rcv_code,assorted_code, rec_amount,premium_rcv_detail_code,remaining_amt, payrec, mode_code,coinsurance_code,class_cd,it_remarks) values" -> insert into ins_premium_det (premium_rcv_code,assorted_code, rec_amount,premium_rcv_detail_code,remaining_amt, payrec, mode_code,coinsurance_code,class_cd,it_remarks) values | G3: ="('"&E3&"','"&B3&"','"&D3&"',(select max(to_number(i.premium_rcv_detail_code))+1 from ins_premium_det i),'"&D3&"','"&D3&"','02', '11000003','00','Request by Mr.Saqib Saleem 20-Feb-2025');" -> ('20Feb250031','070000174830','188919',(select max(to_number(i.premium_rcv_detail_code))+1 from ins_premium_det i),'188919','188919','02', '11000003','00','Request by Mr.Saqib Saleem 20-Feb-2025'); | H3: =F3&G3 -> insert into ins_premium_det (premium_rcv_code,assorted_code, rec_amount,premium_rcv_detail_code,remaining_amt, payrec, mode_code,coinsurance_code,class_cd,it_remarks) values('20Feb250031','070000174830','188919',(select max(to_number(i.premium_rcv_detail_code))+1 from ins_premium_det i),'188919','188919','02', '11000003','00','Request by Mr.Saqib Saleem 20-Feb-2025');
A4: KHI/HO/D/MO/PC COMP/C/105332/118/01/2025 | B4: 070000175366 | C4: 53288 | D4: =ROUND(C4,0) -> 53288 | E4: 20Feb250031 | F4: ="insert into ins_premium_det (premium_rcv_code,assorted_code, rec_amount,premium_rcv_detail_code,remaining_amt, payrec, mode_code,coinsurance_code,class_cd,it_remarks) values" -> insert into ins_premium_det (premium_rcv_code,assorted_code, rec_amount,premium_rcv_detail_code,remaining_amt, payrec, mode_code,coinsurance_code,class_cd,it_remarks) values | G4: ="('"&E4&"','"&B4&"','"&D4&"',(select max(to_number(i.premium_rcv_detail_code))+1 from ins_premium_det i),'"&D4&"','"&D4&"','02', '11000003','00','Request by Mr.Saqib Saleem 20-Feb-2025');" -> ('20Feb250031','070000175366','53288',(select max(to_number(i.premium_rcv_detail_code))+1 from ins_premium_det i),'53288','53288','02', '11000003','00','Request by Mr.Saqib Saleem 20-Feb-2025'); | H4: =F4&G4 -> insert into ins_premium_det (premium_rcv_code,assorted_code, rec_amount,premium_rcv_detail_code,remaining_amt, payrec, mode_code,coinsurance_code,class_cd,it_remarks) values('20Feb250031','070000175366','53288',(select max(to_number(i.premium_rcv_detail_code))+1 from ins_premium_det i),'53288','53288','02', '11000003','00','Request by Mr.Saqib Saleem 20-Feb-2025');
A5: KHI/HO/D/MO/PC COMP/C/105332/5/01/2025 | B5: =VLOOKUP(A5,policy!B:C,2,0) -> 070000173685 | C5: 42000 | D5: =ROUND(C5,0) -> 42000 | E5: 20Feb250031 | F5: ="insert into ins_premium_det (premium_rcv_code,assorted_code, rec_amount,premium_rcv_detail_code,remaining_amt, payrec, mode_code,coinsurance_code,class_cd,it_remarks) values" -> insert into ins_premium_det (premium_rcv_code,assorted_code, rec_amount,premium_rcv_detail_code,remaining_amt, payrec, mode_code,coinsurance_code,class_cd,it_remarks) values | G5: ="('"&E5&"','"&B5&"','"&D5&"',(select max(to_number(i.premium_rcv_detail_code))+1 from ins_premium_det i),'"&D5&"','"&D5&"','02', '11000003','00','Request by Mr.Saqib Saleem 20-Feb-2025');" -> ('20Feb250031','070000173685','42000',(select max(to_number(i.premium_rcv_detail_code))+1 from ins_premium_det i),'42000','42000','02', '11000003','00','Request by Mr.Saqib Saleem 20-Feb-2025'); | H5: =F5&G5 -> insert into ins_premium_det (premium_rcv_code,assorted_code, rec_amount,premium_rcv_detail_code,remaining_amt, payrec, mode_code,coinsurance_code,class_cd,it_remarks) values('20Feb250031','070000173685','42000',(select max(to_number(i.premium_rcv_detail_code))+1 from ins_premium_det i),'42000','42000','02', '11000003','00','Request by Mr.Saqib Saleem 20-Feb-2025');
A6: KHI/HO/D/MO/PC COMP/C/105332/2/01/2025 | B6: =VLOOKUP(A6,policy!B:C,2,0) -> 070000173665 | C6: 82583 | D6: =ROUND(C6,0) -> 82583 | E6: 20Feb250031 | F6: ="insert into ins_premium_det (premium_rcv_code,assorted_code, rec_amount,premium_rcv_detail_code,remaining_amt, payrec, mode_code,coinsurance_code,class_cd,it_remarks) values" -> insert into ins_premium_det (premium_rcv_code,assorted_code, rec_amount,premium_rcv_detail_code,remaining_amt, payrec, mode_code,coinsurance_code,class_cd,it_remarks) values | G6: ="('"&E6&"','"&B6&"','"&D6&"',(select max(to_number(i.premium_rcv_detail_code))+1 from ins_premium_det i),'"&D6&"','"&D6&"','02', '11000003','00','Request by Mr.Saqib Saleem 20-Feb-2025');" -> ('20Feb250031','070000173665','82583',(select max(to_number(i.premium_rcv_detail_code))+1 from ins_premium_det i),'82583','82583','02', '11000003','00','Request by Mr.Saqib Saleem 20-Feb-2025'); | H6: =F6&G6 -> insert into ins_premium_det (premium_rcv_code,assorted_code, rec_amount,premium_rcv_detail_code,remaining_amt, payrec, mode_code,coinsurance_code,class_cd,it_remarks) values('20Feb250031','070000173665','82583',(select max(to_number(i.premium_rcv_detail_code))+1 from ins_premium_det i),'82583','82583','02', '11000003','00','Request by Mr.Saqib Saleem 20-Feb-2025');
A7: KHI/HO/D/MO/PC COMP/C/105332/9/01/2025 | B7: 070000173818 | C7: 82583 | D7: =ROUND(C7,0) -> 82583 | E7: 20Feb250031 | F7: ="insert into ins_premium_det (premium_rcv_code,assorted_code, rec_amount,premium_rcv_detail_code,remaining_amt, payrec, mode_code,coinsurance_code,class_cd,it_remarks) values" -> insert into ins_premium_det (premium_rcv_code,assorted_code, rec_amount,premium_rcv_detail_code,remaining_amt, payrec, mode_code,coinsurance_code,class_cd,it_remarks) values | G7: ="('"&E7&"','"&B7&"','"&D7&"',(select max(to_number(i.premium_rcv_detail_code))+1 from ins_premium_det i),'"&D7&"','"&D7&"','02', '11000003','00','Request by Mr.Saqib Saleem 20-Feb-2025');" -> ('20Feb250031','070000173818','82583',(select max(to_number(i.premium_rcv_detail_code))+1 from ins_premium_det i),'82583','82583','02', '11000003','00','Request by Mr.Saqib Saleem 20-Feb-2025'); | H7: =F7&G7 -> insert into ins_premium_det (premium_rcv_code,assorted_code, rec_amount,premium_rcv_detail_code,remaining_amt, payrec, mode_code,coinsurance_code,class_cd,it_remarks) values('20Feb250031','070000173818','82583',(select max(to_number(i.premium_rcv_detail_code))+1 from ins_premium_det i),'82583','82583','02', '11000003','00','Request by Mr.Saqib Saleem 20-Feb-2025');
A8: KHI/HO/D/MO/PC COMP/C/105332/11/01/2025 | B8: =VLOOKUP(A8,policy!B:C,2,0) -> 070000173829 | C8: 83300 | D8: =ROUND(C8,0) -> 83300 | E8: 20Feb250031 | F8: ="insert into ins_premium_det (premium_rcv_code,assorted_code, rec_amount,premium_rcv_detail_code,remaining_amt, payrec, mode_code,coinsurance_code,class_cd,it_remarks) values" -> insert into ins_premium_det (premium_rcv_code,assorted_code, rec_amount,premium_rcv_detail_code,remaining_amt, payrec, mode_code,coinsurance_code,class_cd,it_remarks) values | G8: ="('"&E8&"','"&B8&"','"&D8&"',(select max(to_number(i.premium_rcv_detail_code))+1 from ins_premium_det i),'"&D8&"','"&D8&"','02', '11000003','00','Request by Mr.Saqib Saleem 20-Feb-2025');" -> ('20Feb250031','070000173829','83300',(select max(to_number(i.premium_rcv_detail_code))+1 from ins_premium_det i),'83300','83300','02', '11000003','00','Request by Mr.Saqib Saleem 20-Feb-2025'); | H8: =F8&G8 -> insert into ins_premium_det (premium_rcv_code,assorted_code, rec_amount,premium_rcv_detail_code,remaining_amt, payrec, mode_code,coinsurance_code,class_cd,it_remarks) values('20Feb250031','070000173829','83300',(select max(to_number(i.premium_rcv_detail_code))+1 from ins_premium_det i),'83300','83300','02', '11000003','00','Request by Mr.Saqib Saleem 20-Feb-2025');
A9: KHI/HO/D/MO/PC COMP/C/105332/12/01/2025 | B9: =VLOOKUP(A9,policy!B:C,2,0) -> 070000173834 | C9: 28875 | D9: =ROUND(C9,0) -> 28875 | E9: 20Feb250031 | F9: ="insert into ins_premium_det (premium_rcv_code,assorted_code, rec_amount,premium_rcv_detail_code,remaining_amt, payrec, mode_code,coinsurance_code,class_cd,it_remarks) values" -> insert into ins_premium_det (premium_rcv_code,assorted_code, rec_amount,premium_rcv_detail_code,remaining_amt, payrec, mode_code,coinsurance_code,class_cd,it_remarks) values | G9: ="('"&E9&"','"&B9&"','"&D9&"',(select max(to_number(i.premium_rcv_detail_code))+1 from ins_premium_det i),'"&D9&"','"&D9&"','02', '11000003','00','Request by Mr.Saqib Saleem 20-Feb-2025');" -> ('20Feb250031','070000173834','28875',(select max(to_number(i.premium_rcv_detail_code))+1 from ins_premium_det i),'28875','28875','02', '11000003','00','Request by Mr.Saqib Saleem 20-Feb-2025'); | H9: =F9&G9 -> insert into ins_premium_det (premium_rcv_code,assorted_code, rec_amount,premium_rcv_detail_code,remaining_amt, payrec, mode_code,coinsurance_code,class_cd,it_remarks) values('20Feb250031','070000173834','28875',(select max(to_number(i.premium_rcv_detail_code))+1 from ins_premium_det i),'28875','28875','02', '11000003','00','Request by Mr.Saqib Saleem 20-Feb-2025');
A10: KHI/HO/D/MO/PC COMP/C/105332/13/01/2025 | B10: =VLOOKUP(A10,policy!B:C,2,0) -> 070000173844 | C10: 82583 | D10: =ROUND(C10,0) -> 82583 | E10: 20Feb250031 | F10: ="insert into ins_premium_det (premium_rcv_code,assorted_code, rec_amount,premium_rcv_detail_code,remaining_amt, payrec, mode_code,coinsurance_code,class_cd,it_remarks) values" -> insert into ins_premium_det (premium_rcv_code,assorted_code, rec_amount,premium_rcv_detail_code,remaining_amt, payrec, mode_code,coinsurance_code,class_cd,it_remarks) values | G10: ="('"&E10&"','"&B10&"','"&D10&"',(select max(to_number(i.premium_rcv_detail_code))+1 from ins_premium_det i),'"&D10&"','"&D10&"','02', '11000003','00','Request by Mr.Saqib Saleem 20-Feb-2025');" -> ('20Feb250031','070000173844','82583',(select max(to_number(i.premium_rcv_detail_code))+1 from ins_premium_det i),'82583','82583','02', '11000003','00','Request by Mr.Saqib Saleem 20-Feb-2025'); | H10: =F10&G10 -> insert into ins_premium_det (premium_rcv_code,assorted_code, rec_amount,premium_rcv_detail_code,remaining_amt, payrec, mode_code,coinsurance_code,class_cd,it_remarks) values('20Feb250031','070000173844','82583',(select max(to_number(i.premium_rcv_detail_code))+1 from ins_premium_det i),'82583','82583','02', '11000003','00','Request by Mr.Saqib Saleem 20-Feb-2025');
A11: KHI/HO/D/MO/PC COMP/C/105332/6/01/2025 | B11: =VLOOKUP(A11,policy!B:C,2,0) -> 070000173811 | C11: 173250 | D11: =ROUND(C11,0) -> 173250 | E11: 20Feb250031 | F11: ="insert into ins_premium_det (premium_rcv_code,assorted_code, rec_amount,premium_rcv_detail_code,remaining_amt, payrec, mode_code,coinsurance_code,class_cd,it_remarks) values" -> insert into ins_premium_det (premium_rcv_code,assorted_code, rec_amount,premium_rcv_detail_code,remaining_amt, payrec, mode_code,coinsurance_code,class_cd,it_remarks) values | G11: ="('"&E11&"','"&B11&"','"&D11&"',(select max(to_number(i.premium_rcv_detail_code))+1 from ins_premium_det i),'"&D11&"','"&D11&"','02', '11000003','00','Request by Mr.Saqib Saleem 20-Feb-2025');" -> ('20Feb250031','070000173811','173250',(select max(to_number(i.premium_rcv_detail_code))+1 from ins_premium_det i),'173250','173250','02', '11000003','00','Request by Mr.Saqib Saleem 20-Feb-2025'); | H11: =F11&G11 -> insert into ins_premium_det (premium_rcv_code,assorted_code, rec_amount,premium_rcv_detail_code,remaining_amt, payrec, mode_code,coinsurance_code,class_cd,it_remarks) values('20Feb250031','070000173811','173250',(select max(to_number(i.premium_rcv_detail_code))+1 from ins_premium_det i),'173250','173250','02', '11000003','00','Request by Mr.Saqib Saleem 20-Feb-2025');
A12: KHI/HO/D/MO/PC COMP/C/105332/20/01/2025 | B12: =VLOOKUP(A12,policy!B:C,2,0) -> 070000173898 | C12: 43400 | D12: =ROUND(C12,0) -> 43400 | E12: 20Feb250031 | F12: ="insert into ins_premium_det (premium_rcv_code,assorted_code, rec_amount,premium_rcv_detail_code,remaining_amt, payrec, mode_code,coinsurance_code,class_cd,it_remarks) values" -> insert into ins_premium_det (premium_rcv_code,assorted_code, rec_amount,premium_rcv_detail_code,remaining_amt, payrec, mode_code,coinsurance_code,class_cd,it_remarks) values | G12: ="('"&E12&"','"&B12&"','"&D12&"',(select max(to_number(i.premium_rcv_detail_code))+1 from ins_premium_det i),'"&D12&"','"&D12&"','02', '11000003','00','Request by Mr.Saqib Saleem 20-Feb-2025');" -> ('20Feb250031','070000173898','43400',(select max(to_number(i.premium_rcv_detail_code))+1 from ins_premium_det i),'43400','43400','02', '11000003','00','Request by Mr.Saqib Saleem 20-Feb-2025'); | H12: =F12&G12 -> insert into ins_premium_det (premium_rcv_code,assorted_code, rec_amount,premium_rcv_detail_code,remaining_amt, payrec, mode_code,coinsurance_code,class_cd,it_remarks) values('20Feb250031','070000173898','43400',(select max(to_number(i.premium_rcv_detail_code))+1 from ins_premium_det i),'43400','43400','02', '11000003','00','Request by Mr.Saqib Saleem 20-Feb-2025');
A13: KHI/HO/D/MO/PC COMP/C/105332/25/01/2025 | B13: =VLOOKUP(A13,policy!B:C,2,0) -> 070000173926 | C13: 47373 | D13: =ROUND(C13,0) -> 47373 | E13: 20Feb250031 | F13: ="insert into ins_premium_det (premium_rcv_code,assorted_code, rec_amount,premium_rcv_detail_code,remaining_amt, payrec, mode_code,coinsurance_code,class_cd,it_remarks) values" -> insert into ins_premium_det (premium_rcv_code,assorted_code, rec_amount,premium_rcv_detail_code,remaining_amt, payrec, mode_code,coinsurance_code,class_cd,it_remarks) values | G13: ="('"&E13&"','"&B13&"','"&D13&"',(select max(to_number(i.premium_rcv_detail_code))+1 from ins_premium_det i),'"&D13&"','"&D13&"','02', '11000003','00','Request by Mr.Saqib Saleem 20-Feb-2025');" -> ('20Feb250031','070000173926','47373',(select max(to_number(i.premium_rcv_detail_code))+1 from ins_premium_det i),'47373','47373','02', '11000003','00','Request by Mr.Saqib Saleem 20-Feb-2025'); | H13: =F13&G13 -> insert into ins_premium_det (premium_rcv_code,assorted_code, rec_amount,premium_rcv_detail_code,remaining_amt, payrec, mode_code,coinsurance_code,class_cd,it_remarks) values('20Feb250031','070000173926','47373',(select max(to_number(i.premium_rcv_detail_code))+1 from ins_premium_det i),'47373','47373','02', '11000003','00','Request by Mr.Saqib Saleem 20-Feb-2025');
A14: KHI/HO/D/MO/PC COMP/C/105332/30/01/2025 | B14: =VLOOKUP(A14,policy!B:C,2,0) -> 070000173989 | C14: 41125 | D14: =ROUND(C14,0) -> 41125 | E14: 20Feb250031 | F14: ="insert into ins_premium_det (premium_rcv_code,assorted_code, rec_amount,premium_rcv_detail_code,remaining_amt, payrec, mode_code,coinsurance_code,class_cd,it_remarks) values" -> insert into ins_premium_det (premium_rcv_code,assorted_code, rec_amount,premium_rcv_detail_code,remaining_amt, payrec, mode_code,coinsurance_code,class_cd,it_remarks) values | G14: ="('"&E14&"','"&B14&"','"&D14&"',(select max(to_number(i.premium_rcv_detail_code))+1 from ins_premium_det i),'"&D14&"','"&D14&"','02', '11000003','00','Request by Mr.Saqib Saleem 20-Feb-2025');" -> ('20Feb250031','070000173989','41125',(select max(to_number(i.premium_rcv_detail_code))+1 from ins_premium_det i),'41125','41125','02', '11000003','00','Request by Mr.Saqib Saleem 20-Feb-2025'); | H14: =F14&G14 -> insert into ins_premium_det (premium_rcv_code,assorted_code, rec_amount,premium_rcv_detail_code,remaining_amt, payrec, mode_code,coinsurance_code,class_cd,it_remarks) values('20Feb250031','070000173989','41125',(select max(to_number(i.premium_rcv_detail_code))+1 from ins_premium_det i),'41125','41125','02', '11000003','00','Request by Mr.Saqib Saleem 20-Feb-2025');
A15: KHI/HO/D/MO/PC COMP/C/105332/28/01/2025 | B15: =VLOOKUP(A15,policy!B:C,2,0) -> 070000173931 | C15: 35000 | D15: =ROUND(C15,0) -> 35000 | E15: 20Feb250031 | F15: ="insert into ins_premium_det (premium_rcv_code,assorted_code, rec_amount,premium_rcv_detail_code,remaining_amt, payrec, mode_code,coinsurance_code,class_cd,it_remarks) values" -> insert into ins_premium_det (premium_rcv_code,assorted_code, rec_amount,premium_rcv_detail_code,remaining_amt, payrec, mode_code,coinsurance_code,class_cd,it_remarks) values | G15: ="('"&E15&"','"&B15&"','"&D15&"',(select max(to_number(i.premium_rcv_detail_code))+1 from ins_premium_det i),'"&D15&"','"&D15&"','02', '11000003','00','Request by Mr.Saqib Saleem 20-Feb-2025');" -> ('20Feb250031','070000173931','35000',(select max(to_number(i.premium_rcv_detail_code))+1 from ins_premium_det i),'35000','35000','02', '11000003','00','Request by Mr.Saqib Saleem 20-Feb-2025'); | H15: =F15&G15 -> insert into ins_premium_det (premium_rcv_code,assorted_code, rec_amount,premium_rcv_detail_code,remaining_amt, payrec, mode_code,coinsurance_code,class_cd,it_remarks) values('20Feb250031','070000173931','35000',(select max(to_number(i.premium_rcv_detail_code))+1 from ins_premium_det i),'35000','35000','02', '11000003','00','Request by Mr.Saqib Saleem 20-Feb-2025');
A16: KHI/HO/D/MO/PC COMP/C/105332/21/01/2025 | B16: =VLOOKUP(A16,policy!B:C,2,0) -> 070000173917 | C16: 43575 | D16: =ROUND(C16,0) -> 43575 | E16: 20Feb250031 | F16: ="insert into ins_premium_det (premium_rcv_code,assorted_code, rec_amount,premium_rcv_detail_code,remaining_amt, payrec, mode_code,coinsurance_code,class_cd,it_remarks) values" -> insert into ins_premium_det (premium_rcv_code,assorted_code, rec_amount,premium_rcv_detail_code,remaining_amt, payrec, mode_code,coinsurance_code,class_cd,it_remarks) values | G16: ="('"&E16&"','"&B16&"','"&D16&"',(select max(to_number(i.premium_rcv_detail_code))+1 from ins_premium_det i),'"&D16&"','"&D16&"','02', '11000003','00','Request by Mr.Saqib Saleem 20-Feb-2025');" -> ('20Feb250031','070000173917','43575',(select max(to_number(i.premium_rcv_detail_code))+1 from ins_premium_det i),'43575','43575','02', '11000003','00','Request by Mr.Saqib Saleem 20-Feb-2025'); | H16: =F16&G16 -> insert into ins_premium_det (premium_rcv_code,assorted_code, rec_amount,premium_rcv_detail_code,remaining_amt, payrec, mode_code,coinsurance_code,class_cd,it_remarks) values('20Feb250031','070000173917','43575',(select max(to_number(i.premium_rcv_detail_code))+1 from ins_premium_det i),'43575','43575','02', '11000003','00','Request by Mr.Saqib Saleem 20-Feb-2025');
A17: KHI/HO/D/MO/PC COMP/C/105332/39/01/2025 | B17: =VLOOKUP(A17,policy!B:C,2,0) -> 070000174037 | C17: 40775 | D17: =ROUND(C17,0) -> 40775 | E17: 20Feb250031 | F17: ="insert into ins_premium_det (premium_rcv_code,assorted_code, rec_amount,premium_rcv_detail_code,remaining_amt, payrec, mode_code,coinsurance_code,class_cd,it_remarks) values" -> insert into ins_premium_det (premium_rcv_code,assorted_code, rec_amount,premium_rcv_detail_code,remaining_amt, payrec, mode_code,coinsurance_code,class_cd,it_remarks) values | G17: ="('"&E17&"','"&B17&"','"&D17&"',(select max(to_number(i.premium_rcv_detail_code))+1 from ins_premium_det i),'"&D17&"','"&D17&"','02', '11000003','00','Request by Mr.Saqib Saleem 20-Feb-2025');" -> ('20Feb250031','070000174037','40775',(select max(to_number(i.premium_rcv_detail_code))+1 from ins_premium_det i),'40775','40775','02', '11000003','00','Request by Mr.Saqib Saleem 20-Feb-2025'); | H17: =F17&G17 -> insert into ins_premium_det (premium_rcv_code,assorted_code, rec_amount,premium_rcv_detail_code,remaining_amt, payrec, mode_code,coinsurance_code,class_cd,it_remarks) values('20Feb250031','070000174037','40775',(select max(to_number(i.premium_rcv_detail_code))+1 from ins_premium_det i),'40775','40775','02', '11000003','00','Request by Mr.Saqib Saleem 20-Feb-2025');
A18: KHI/HO/D/MO/PC COMP/C/105332/50/01/2025 | B18: =VLOOKUP(A18,policy!B:C,2,0) -> 070000174064 | C18: 53288 | D18: =ROUND(C18,0) -> 53288 | E18: 20Feb250031 | F18: ="insert into ins_premium_det (premium_rcv_code,assorted_code, rec_amount,premium_rcv_detail_code,remaining_amt, payrec, mode_code,coinsurance_code,class_cd,it_remarks) values" -> insert into ins_premium_det (premium_rcv_code,assorted_code, rec_amount,premium_rcv_detail_code,remaining_amt, payrec, mode_code,coinsurance_code,class_cd,it_remarks) values | G18: ="('"&E18&"','"&B18&"','"&D18&"',(select max(to_number(i.premium_rcv_detail_code))+1 from ins_premium_det i),'"&D18&"','"&D18&"','02', '11000003','00','Request by Mr.Saqib Saleem 20-Feb-2025');" -> ('20Feb250031','070000174064','53288',(select max(to_number(i.premium_rcv_detail_code))+1 from ins_premium_det i),'53288','53288','02', '11000003','00','Request by Mr.Saqib Saleem 20-Feb-2025'); | H18: =F18&G18 -> insert into ins_premium_det (premium_rcv_code,assorted_code, rec_amount,premium_rcv_detail_code,remaining_amt, payrec, mode_code,coinsurance_code,class_cd,it_remarks) values('20Feb250031','070000174064','53288',(select max(to_number(i.premium_rcv_detail_code))+1 from ins_premium_det i),'53288','53288','02', '11000003','00','Request by Mr.Saqib Saleem 20-Feb-2025');
A19: KHI/HO/D/MO/PC COMP/C/105332/35/01/2025 | B19: =VLOOKUP(A19,policy!B:C,2,0) -> 070000174006 | C19: 47373 | D19: =ROUND(C19,0) -> 47373 | E19: 20Feb250031 | F19: ="insert into ins_premium_det (premium_rcv_code,assorted_code, rec_amount,premium_rcv_detail_code,remaining_amt, payrec, mode_code,coinsurance_code,class_cd,it_remarks) values" -> insert into ins_premium_det (premium_rcv_code,assorted_code, rec_amount,premium_rcv_detail_code,remaining_amt, payrec, mode_code,coinsurance_code,class_cd,it_remarks) values | G19: ="('"&E19&"','"&B19&"','"&D19&"',(select max(to_number(i.premium_rcv_detail_code))+1 from ins_premium_det i),'"&D19&"','"&D19&"','02', '11000003','00','Request by Mr.Saqib Saleem 20-Feb-2025');" -> ('20Feb250031','070000174006','47373',(select max(to_number(i.premium_rcv_detail_code))+1 from ins_premium_det i),'47373','47373','02', '11000003','00','Request by Mr.Saqib Saleem 20-Feb-2025'); | H19: =F19&G19 -> insert into ins_premium_det (premium_rcv_code,assorted_code, rec_amount,premium_rcv_detail_code,remaining_amt, payrec, mode_code,coinsurance_code,class_cd,it_remarks) values('20Feb250031','070000174006','47373',(select max(to_number(i.premium_rcv_detail_code))+1 from ins_premium_det i),'47373','47373','02', '11000003','00','Request by Mr.Saqib Saleem 20-Feb-2025');
... A57: KHI/HO/D/MO/PC COMP/C/105332/130/01/2025 | B57: =VLOOKUP(A57,policy!B:C,2,0) -> 070000176236 | C57: 127733 | D57: =ROUND(C57,0) -> 127733 | E57: 20Feb250031 | F57: ="insert into ins_premium_det (premium_rcv_code,assorted_code, rec_amount,premium_rcv_detail_code,remaining_amt, payrec, mode_code,coinsurance_code,class_cd,it_remarks) values" -> insert into ins_premium_det (premium_rcv_code,assorted_code, rec_amount,premium_rcv_detail_code,remaining_amt, payrec, mode_code,coinsurance_code,class_cd,it_remarks) values | G57: ="('"&E57&"','"&B57&"','"&D57&"',(select max(to_number(i.premium_rcv_detail_code))+1 from ins_premium_det i),'"&D57&"','"&D57&"','02', '11000003','00','Request by Mr.Saqib Saleem 20-Feb-2025');" -> ('20Feb250031','070000176236','127733',(select max(to_number(i.premium_rcv_detail_code))+1 from ins_premium_det i),'127733','127733','02', '11000003','00','Request by Mr.Saqib Saleem 20-Feb-2025'); | H57: =F57&G57 -> insert into ins_premium_det (premium_rcv_code,assorted_code, rec_amount,premium_rcv_detail_code,remaining_amt, payrec, mode_code,coinsurance_code,class_cd,it_remarks) values('20Feb250031','070000176236','127733',(select max(to_number(i.premium_rcv_detail_code))+1 from ins_premium_det i),'127733','127733','02', '11000003','00','Request by Mr.Saqib Saleem 20-Feb-2025');
A58: KHI/HO/D/MO/PC COMP/C/105332/143/01/2025 | B58: 070000176328 | C58: 155733 | D58: =ROUND(C58,0) -> 155733 | E58: 20Feb250031 | F58: ="insert into ins_premium_det (premium_rcv_code,assorted_code, rec_amount,premium_rcv_detail_code,remaining_amt, payrec, mode_code,coinsurance_code,class_cd,it_remarks) values" -> insert into ins_premium_det (premium_rcv_code,assorted_code, rec_amount,premium_rcv_detail_code,remaining_amt, payrec, mode_code,coinsurance_code,class_cd,it_remarks) values | G58: ="('"&E58&"','"&B58&"','"&D58&"',(select max(to_number(i.premium_rcv_detail_code))+1 from ins_premium_det i),'"&D58&"','"&D58&"','02', '11000003','00','Request by Mr.Saqib Saleem 20-Feb-2025');" -> ('20Feb250031','070000176328','155733',(select max(to_number(i.premium_rcv_detail_code))+1 from ins_premium_det i),'155733','155733','02', '11000003','00','Request by Mr.Saqib Saleem 20-Feb-2025'); | H58: =F58&G58 -> insert into ins_premium_det (premium_rcv_code,assorted_code, rec_amount,premium_rcv_detail_code,remaining_amt, payrec, mode_code,coinsurance_code,class_cd,it_remarks) values('20Feb250031','070000176328','155733',(select max(to_number(i.premium_rcv_detail_code))+1 from ins_premium_det i),'155733','155733','02', '11000003','00','Request by Mr.Saqib Saleem 20-Feb-2025');
A59: KHI/HO/D/MO/PC COMP/C/105332/137/01/2025 | B59: =VLOOKUP(A59,policy!B:C,2,0) -> 070000176314 | C59: 42000 | D59: =ROUND(C59,0) -> 42000 | E59: 20Feb250031 | F59: ="insert into ins_premium_det (premium_rcv_code,assorted_code, rec_amount,premium_rcv_detail_code,remaining_amt, payrec, mode_code,coinsurance_code,class_cd,it_remarks) values" -> insert into ins_premium_det (premium_rcv_code,assorted_code, rec_amount,premium_rcv_detail_code,remaining_amt, payrec, mode_code,coinsurance_code,class_cd,it_remarks) values | G59: ="('"&E59&"','"&B59&"','"&D59&"',(select max(to_number(i.premium_rcv_detail_code))+1 from ins_premium_det i),'"&D59&"','"&D59&"','02', '11000003','00','Request by Mr.Saqib Saleem 20-Feb-2025');" -> ('20Feb250031','070000176314','42000',(select max(to_number(i.premium_rcv_detail_code))+1 from ins_premium_det i),'42000','42000','02', '11000003','00','Request by Mr.Saqib Saleem 20-Feb-2025'); | H59: =F59&G59 -> insert into ins_premium_det (premium_rcv_code,assorted_code, rec_amount,premium_rcv_detail_code,remaining_amt, payrec, mode_code,coinsurance_code,class_cd,it_remarks) values('20Feb250031','070000176314','42000',(select max(to_number(i.premium_rcv_detail_code))+1 from ins_premium_det i),'42000','42000','02', '11000003','00','Request by Mr.Saqib Saleem 20-Feb-2025');
A60: KHI/HO/D/MO/PC COMP/C/105332/139/01/2025 | B60: =VLOOKUP(A60,policy!B:C,2,0) -> 070000176320 | C60: 35875 | D60: =ROUND(C60,0) -> 35875 | E60: 20Feb250031 | F60: ="insert into ins_premium_det (premium_rcv_code,assorted_code, rec_amount,premium_rcv_detail_code,remaining_amt, payrec, mode_code,coinsurance_code,class_cd,it_remarks) values" -> insert into ins_premium_det (premium_rcv_code,assorted_code, rec_amount,premium_rcv_detail_code,remaining_amt, payrec, mode_code,coinsurance_code,class_cd,it_remarks) values | G60: ="('"&E60&"','"&B60&"','"&D60&"',(select max(to_number(i.premium_rcv_detail_code))+1 from ins_premium_det i),'"&D60&"','"&D60&"','02', '11000003','00','Request by Mr.Saqib Saleem 20-Feb-2025');" -> ('20Feb250031','070000176320','35875',(select max(to_number(i.premium_rcv_detail_code))+1 from ins_premium_det i),'35875','35875','02', '11000003','00','Request by Mr.Saqib Saleem 20-Feb-2025'); | H60: =F60&G60 -> insert into ins_premium_det (premium_rcv_code,assorted_code, rec_amount,premium_rcv_detail_code,remaining_amt, payrec, mode_code,coinsurance_code,class_cd,it_remarks) values('20Feb250031','070000176320','35875',(select max(to_number(i.premium_rcv_detail_code))+1 from ins_premium_det i),'35875','35875','02', '11000003','00','Request by Mr.Saqib Saleem 20-Feb-2025');
A61: KHI/HO/D/MO/PC COMP/C/105332/141/01/2025 | B61: =VLOOKUP(A61,policy!B:C,2,0) -> 070000176324 | C61: 96250 | D61: =ROUND(C61,0) -> 96250 | E61: 20Feb250031 | F61: ="insert into ins_premium_det (premium_rcv_code,assorted_code, rec_amount,premium_rcv_detail_code,remaining_amt, payrec, mode_code,coinsurance_code,class_cd,it_remarks) values" -> insert into ins_premium_det (premium_rcv_code,assorted_code, rec_amount,premium_rcv_detail_code,remaining_amt, payrec, mode_code,coinsurance_code,class_cd,it_remarks) values | G61: ="('"&E61&"','"&B61&"','"&D61&"',(select max(to_number(i.premium_rcv_detail_code))+1 from ins_premium_det i),'"&D61&"','"&D61&"','02', '11000003','00','Request by Mr.Saqib Saleem 20-Feb-2025');" -> ('20Feb250031','070000176324','96250',(select max(to_number(i.premium_rcv_detail_code))+1 from ins_premium_det i),'96250','96250','02', '11000003','00','Request by Mr.Saqib Saleem 20-Feb-2025'); | H61: =F61&G61 -> insert into ins_premium_det (premium_rcv_code,assorted_code, rec_amount,premium_rcv_detail_code,remaining_amt, payrec, mode_code,coinsurance_code,class_cd,it_remarks) values('20Feb250031','070000176324','96250',(select max(to_number(i.premium_rcv_detail_code))+1 from ins_premium_det i),'96250','96250','02', '11000003','00','Request by Mr.Saqib Saleem 20-Feb-2025');
A62: KHI/HO/D/MO/PC COMP/C/105332/147/01/2025 | B62: =VLOOKUP(A62,policy!B:C,2,0) -> 070000176340 | C62: 53288 | D62: =ROUND(C62,0) -> 53288 | E62: 20Feb250031 | F62: ="insert into ins_premium_det (premium_rcv_code,assorted_code, rec_amount,premium_rcv_detail_code,remaining_amt, payrec, mode_code,coinsurance_code,class_cd,it_remarks) values" -> insert into ins_premium_det (premium_rcv_code,assorted_code, rec_amount,premium_rcv_detail_code,remaining_amt, payrec, mode_code,coinsurance_code,class_cd,it_remarks) values | G62: ="('"&E62&"','"&B62&"','"&D62&"',(select max(to_number(i.premium_rcv_detail_code))+1 from ins_premium_det i),'"&D62&"','"&D62&"','02', '11000003','00','Request by Mr.Saqib Saleem 20-Feb-2025');" -> ('20Feb250031','070000176340','53288',(select max(to_number(i.premium_rcv_detail_code))+1 from ins_premium_det i),'53288','53288','02', '11000003','00','Request by Mr.Saqib Saleem 20-Feb-2025'); | H62: =F62&G62 -> insert into ins_premium_det (premium_rcv_code,assorted_code, rec_amount,premium_rcv_detail_code,remaining_amt, payrec, mode_code,coinsurance_code,class_cd,it_remarks) values('20Feb250031','070000176340','53288',(select max(to_number(i.premium_rcv_detail_code))+1 from ins_premium_det i),'53288','53288','02', '11000003','00','Request by Mr.Saqib Saleem 20-Feb-2025');
A63: KHI/HO/D/MO/PC COMP/C/105332/159/01/2025 | B63: =VLOOKUP(A63,policy!B:C,2,0) -> 070000176363 | C63: 67375 | D63: =ROUND(C63,0) -> 67375 | E63: 20Feb250031 | F63: ="insert into ins_premium_det (premium_rcv_code,assorted_code, rec_amount,premium_rcv_detail_code,remaining_amt, payrec, mode_code,coinsurance_code,class_cd,it_remarks) values" -> insert into ins_premium_det (premium_rcv_code,assorted_code, rec_amount,premium_rcv_detail_code,remaining_amt, payrec, mode_code,coinsurance_code,class_cd,it_remarks) values | G63: ="('"&E63&"','"&B63&"','"&D63&"',(select max(to_number(i.premium_rcv_detail_code))+1 from ins_premium_det i),'"&D63&"','"&D63&"','02', '11000003','00','Request by Mr.Saqib Saleem 20-Feb-2025');" -> ('20Feb250031','070000176363','67375',(select max(to_number(i.premium_rcv_detail_code))+1 from ins_premium_det i),'67375','67375','02', '11000003','00','Request by Mr.Saqib Saleem 20-Feb-2025'); | H63: =F63&G63 -> insert into ins_premium_det (premium_rcv_code,assorted_code, rec_amount,premium_rcv_detail_code,remaining_amt, payrec, mode_code,coinsurance_code,class_cd,it_remarks) values('20Feb250031','070000176363','67375',(select max(to_number(i.premium_rcv_detail_code))+1 from ins_premium_det i),'67375','67375','02', '11000003','00','Request by Mr.Saqib Saleem 20-Feb-2025');
A64: KHI/HO/D/MO/PC COMP/C/105332/150/01/2025 | B64: =VLOOKUP(A64,policy!B:C,2,0) -> 070000176351 | C64: 50750 | D64: =ROUND(C64,0) -> 50750 | E64: 20Feb250031 | F64: ="insert into ins_premium_det (premium_rcv_code,assorted_code, rec_amount,premium_rcv_detail_code,remaining_amt, payrec, mode_code,coinsurance_code,class_cd,it_remarks) values" -> insert into ins_premium_det (premium_rcv_code,assorted_code, rec_amount,premium_rcv_detail_code,remaining_amt, payrec, mode_code,coinsurance_code,class_cd,it_remarks) values | G64: ="('"&E64&"','"&B64&"','"&D64&"',(select max(to_number(i.premium_rcv_detail_code))+1 from ins_premium_det i),'"&D64&"','"&D64&"','02', '11000003','00','Request by Mr.Saqib Saleem 20-Feb-2025');" -> ('20Feb250031','070000176351','50750',(select max(to_number(i.premium_rcv_detail_code))+1 from ins_premium_det i),'50750','50750','02', '11000003','00','Request by Mr.Saqib Saleem 20-Feb-2025'); | H64: =F64&G64 -> insert into ins_premium_det (premium_rcv_code,assorted_code, rec_amount,premium_rcv_detail_code,remaining_amt, payrec, mode_code,coinsurance_code,class_cd,it_remarks) values('20Feb250031','070000176351','50750',(select max(to_number(i.premium_rcv_detail_code))+1 from ins_premium_det i),'50750','50750','02', '11000003','00','Request by Mr.Saqib Saleem 20-Feb-2025');
A65: KHI/HO/D/MO/PC COMP/C/105332/153/01/2025 | B65: =VLOOKUP(A65,policy!B:C,2,0) -> 070000176355 | C65: 96250 | D65: =ROUND(C65,0) -> 96250 | E65: 20Feb250031 | F65: ="insert into ins_premium_det (premium_rcv_code,assorted_code, rec_amount,premium_rcv_detail_code,remaining_amt, payrec, mode_code,coinsurance_code,class_cd,it_remarks) values" -> insert into ins_premium_det (premium_rcv_code,assorted_code, rec_amount,premium_rcv_detail_code,remaining_amt, payrec, mode_code,coinsurance_code,class_cd,it_remarks) values | G65: ="('"&E65&"','"&B65&"','"&D65&"',(select max(to_number(i.premium_rcv_detail_code))+1 from ins_premium_det i),'"&D65&"','"&D65&"','02', '11000003','00','Request by Mr.Saqib Saleem 20-Feb-2025');" -> ('20Feb250031','070000176355','96250',(select max(to_number(i.premium_rcv_detail_code))+1 from ins_premium_det i),'96250','96250','02', '11000003','00','Request by Mr.Saqib Saleem 20-Feb-2025'); | H65: =F65&G65 -> insert into ins_premium_det (premium_rcv_code,assorted_code, rec_amount,premium_rcv_detail_code,remaining_amt, payrec, mode_code,coinsurance_code,class_cd,it_remarks) values('20Feb250031','070000176355','96250',(select max(to_number(i.premium_rcv_detail_code))+1 from ins_premium_det i),'96250','96250','02', '11000003','00','Request by Mr.Saqib Saleem 20-Feb-2025');
A66: KHI/HO/D/MO/PC COMP/C/105332/149/01/2025 | B66: =VLOOKUP(A66,policy!B:C,2,0) -> 070000176350 | C66: 53288 | D66: =ROUND(C66,0) -> 53288 | E66: 20Feb250031 | F66: ="insert into ins_premium_det (premium_rcv_code,assorted_code, rec_amount,premium_rcv_detail_code,remaining_amt, payrec, mode_code,coinsurance_code,class_cd,it_remarks) values" -> insert into ins_premium_det (premium_rcv_code,assorted_code, rec_amount,premium_rcv_detail_code,remaining_amt, payrec, mode_code,coinsurance_code,class_cd,it_remarks) values | G66: ="('"&E66&"','"&B66&"','"&D66&"',(select max(to_number(i.premium_rcv_detail_code))+1 from ins_premium_det i),'"&D66&"','"&D66&"','02', '11000003','00','Request by Mr.Saqib Saleem 20-Feb-2025');" -> ('20Feb250031','070000176350','53288',(select max(to_number(i.premium_rcv_detail_code))+1 from ins_premium_det i),'53288','53288','02', '11000003','00','Request by Mr.Saqib Saleem 20-Feb-2025'); | H66: =F66&G66 -> insert into ins_premium_det (premium_rcv_code,assorted_code, rec_amount,premium_rcv_detail_code,remaining_amt, payrec, mode_code,coinsurance_code,class_cd,it_remarks) values('20Feb250031','070000176350','53288',(select max(to_number(i.premium_rcv_detail_code))+1 from ins_premium_det i),'53288','53288','02', '11000003','00','Request by Mr.Saqib Saleem 20-Feb-2025');
A67: KHI/HO/D/MO/PC COMP/C/105332/3/01/2025 | B67: =VLOOKUP(A67,policy!B:C,2,0) -> 070000173679 | C67: 42000 | D67: =ROUND(C67,0) -> 42000 | E67: 20Feb250031 | F67: ="insert into ins_premium_det (premium_rcv_code,assorted_code, rec_amount,premium_rcv_detail_code,remaining_amt, payrec, mode_code,coinsurance_code,class_cd,it_remarks) values" -> insert into ins_premium_det (premium_rcv_code,assorted_code, rec_amount,premium_rcv_detail_code,remaining_amt, payrec, mode_code,coinsurance_code,class_cd,it_remarks) values | G67: ="('"&E67&"','"&B67&"','"&D67&"',(select max(to_number(i.premium_rcv_detail_code))+1 from ins_premium_det i),'"&D67&"','"&D67&"','02', '11000003','00','Request by Mr.Saqib Saleem 20-Feb-2025');" -> ('20Feb250031','070000173679','42000',(select max(to_number(i.premium_rcv_detail_code))+1 from ins_premium_det i),'42000','42000','02', '11000003','00','Request by Mr.Saqib Saleem 20-Feb-2025'); | H67: =F67&G67 -> insert into ins_premium_det (premium_rcv_code,assorted_code, rec_amount,premium_rcv_detail_code,remaining_amt, payrec, mode_code,coinsurance_code,class_cd,it_remarks) values('20Feb250031','070000173679','42000',(select max(to_number(i.premium_rcv_detail_code))+1 from ins_premium_det i),'42000','42000','02', '11000003','00','Request by Mr.Saqib Saleem 20-Feb-2025');
A68: KHI/HO/D/MO/PC COMP/C/105332/7/01/2025 | B68: =VLOOKUP(A68,policy!B:C,2,0) -> 070000173812 | C68: 36750 | D68: =ROUND(C68,0) -> 36750 | E68: 20Feb250031 | F68: ="insert into ins_premium_det (premium_rcv_code,assorted_code, rec_amount,premium_rcv_detail_code,remaining_amt, payrec, mode_code,coinsurance_code,class_cd,it_remarks) values" -> insert into ins_premium_det (premium_rcv_code,assorted_code, rec_amount,premium_rcv_detail_code,remaining_amt, payrec, mode_code,coinsurance_code,class_cd,it_remarks) values | G68: ="('"&E68&"','"&B68&"','"&D68&"',(select max(to_number(i.premium_rcv_detail_code))+1 from ins_premium_det i),'"&D68&"','"&D68&"','02', '11000003','00','Request by Mr.Saqib Saleem 20-Feb-2025');" -> ('20Feb250031','070000173812','36750',(select max(to_number(i.premium_rcv_detail_code))+1 from ins_premium_det i),'36750','36750','02', '11000003','00','Request by Mr.Saqib Saleem 20-Feb-2025'); | H68: =F68&G68 -> insert into ins_premium_det (premium_rcv_code,assorted_code, rec_amount,premium_rcv_detail_code,remaining_amt, payrec, mode_code,coinsurance_code,class_cd,it_remarks) values('20Feb250031','070000173812','36750',(select max(to_number(i.premium_rcv_detail_code))+1 from ins_premium_det i),'36750','36750','02', '11000003','00','Request by Mr.Saqib Saleem 20-Feb-2025');
A69: KHI/HO/D/MO/PC COMP/C/105332/16/01/2025 | B69: =VLOOKUP(A69,policy!B:C,2,0) -> 070000173874 | C69: 77875 | D69: =ROUND(C69,0) -> 77875 | E69: 20Feb250031 | F69: ="insert into ins_premium_det (premium_rcv_code,assorted_code, rec_amount,premium_rcv_detail_code,remaining_amt, payrec, mode_code,coinsurance_code,class_cd,it_remarks) values" -> insert into ins_premium_det (premium_rcv_code,assorted_code, rec_amount,premium_rcv_detail_code,remaining_amt, payrec, mode_code,coinsurance_code,class_cd,it_remarks) values | G69: ="('"&E69&"','"&B69&"','"&D69&"',(select max(to_number(i.premium_rcv_detail_code))+1 from ins_premium_det i),'"&D69&"','"&D69&"','02', '11000003','00','Request by Mr.Saqib Saleem 20-Feb-2025');" -> ('20Feb250031','070000173874','77875',(select max(to_number(i.premium_rcv_detail_code))+1 from ins_premium_det i),'77875','77875','02', '11000003','00','Request by Mr.Saqib Saleem 20-Feb-2025'); | H69: =F69&G69 -> insert into ins_premium_det (premium_rcv_code,assorted_code, rec_amount,premium_rcv_detail_code,remaining_amt, payrec, mode_code,coinsurance_code,class_cd,it_remarks) values('20Feb250031','070000173874','77875',(select max(to_number(i.premium_rcv_detail_code))+1 from ins_premium_det i),'77875','77875','02', '11000003','00','Request by Mr.Saqib Saleem 20-Feb-2025');
A70: KHI/HO/D/MO/PC COMP/C/105332/18/01/2025 | B70: =VLOOKUP(A70,policy!B:C,2,0) -> 070000173893 | C70: 47373 | D70: =ROUND(C70,0) -> 47373 | E70: 20Feb250031 | F70: ="insert into ins_premium_det (premium_rcv_code,assorted_code, rec_amount,premium_rcv_detail_code,remaining_amt, payrec, mode_code,coinsurance_code,class_cd,it_remarks) values" -> insert into ins_premium_det (premium_rcv_code,assorted_code, rec_amount,premium_rcv_detail_code,remaining_amt, payrec, mode_code,coinsurance_code,class_cd,it_remarks) values | G70: ="('"&E70&"','"&B70&"','"&D70&"',(select max(to_number(i.premium_rcv_detail_code))+1 from ins_premium_det i),'"&D70&"','"&D70&"','02', '11000003','00','Request by Mr.Saqib Saleem 20-Feb-2025');" -> ('20Feb250031','070000173893','47373',(select max(to_number(i.premium_rcv_detail_code))+1 from ins_premium_det i),'47373','47373','02', '11000003','00','Request by Mr.Saqib Saleem 20-Feb-2025'); | H70: =F70&G70 -> insert into ins_premium_det (premium_rcv_code,assorted_code, rec_amount,premium_rcv_detail_code,remaining_amt, payrec, mode_code,coinsurance_code,class_cd,it_remarks) values('20Feb250031','070000173893','47373',(select max(to_number(i.premium_rcv_detail_code))+1 from ins_premium_det i),'47373','47373','02', '11000003','00','Request by Mr.Saqib Saleem 20-Feb-2025');
... A107: KHI/HO/D/MO/PC COMP/C/105332/41/01/2025 | B107: =VLOOKUP(A107,policy!B:C,2,0) -> 070000174042 | C107: 94380 | D107: =ROUND(C107,0) -> 94380 | E107: 20Feb250031 | F107: ="insert into ins_premium_det (premium_rcv_code,assorted_code, rec_amount,premium_rcv_detail_code,remaining_amt, payrec, mode_code,coinsurance_code,class_cd,it_remarks) values" -> insert into ins_premium_det (premium_rcv_code,assorted_code, rec_amount,premium_rcv_detail_code,remaining_amt, payrec, mode_code,coinsurance_code,class_cd,it_remarks) values | G107: ="('"&E107&"','"&B107&"','"&D107&"',(select max(to_number(i.premium_rcv_detail_code))+1 from ins_premium_det i),'"&D107&"','"&D107&"','02', '11000003','00','Request by Mr.Saqib Saleem 20-Feb-2025');" -> ('20Feb250031','070000174042','94380',(select max(to_number(i.premium_rcv_detail_code))+1 from ins_premium_det i),'94380','94380','02', '11000003','00','Request by Mr.Saqib Saleem 20-Feb-2025'); | H107: =F107&G107 -> insert into ins_premium_det (premium_rcv_code,assorted_code, rec_amount,premium_rcv_detail_code,remaining_amt, payrec, mode_code,coinsurance_code,class_cd,it_remarks) values('20Feb250031','070000174042','94380',(select max(to_number(i.premium_rcv_detail_code))+1 from ins_premium_det i),'94380','94380','02', '11000003','00','Request by Mr.Saqib Saleem 20-Feb-2025');
A108: KHI/HO/D/MO/PC COMP/C/105332/40/01/2025 | B108: 070000174041 | C108: 66483 | D108: =ROUND(C108,0) -> 66483 | E108: 20Feb250031 | F108: ="insert into ins_premium_det (premium_rcv_code,assorted_code, rec_amount,premium_rcv_detail_code,remaining_amt, payrec, mode_code,coinsurance_code,class_cd,it_remarks) values" -> insert into ins_premium_det (premium_rcv_code,assorted_code, rec_amount,premium_rcv_detail_code,remaining_amt, payrec, mode_code,coinsurance_code,class_cd,it_remarks) values | G108: ="('"&E108&"','"&B108&"','"&D108&"',(select max(to_number(i.premium_rcv_detail_code))+1 from ins_premium_det i),'"&D108&"','"&D108&"','02', '11000003','00','Request by Mr.Saqib Saleem 20-Feb-2025');" -> ('20Feb250031','070000174041','66483',(select max(to_number(i.premium_rcv_detail_code))+1 from ins_premium_det i),'66483','66483','02', '11000003','00','Request by Mr.Saqib Saleem 20-Feb-2025'); | H108: =F108&G108 -> insert into ins_premium_det (premium_rcv_code,assorted_code, rec_amount,premium_rcv_detail_code,remaining_amt, payrec, mode_code,coinsurance_code,class_cd,it_remarks) values('20Feb250031','070000174041','66483',(select max(to_number(i.premium_rcv_detail_code))+1 from ins_premium_det i),'66483','66483','02', '11000003','00','Request by Mr.Saqib Saleem 20-Feb-2025');
A109: KHI/HO/D/MO/PC COMP/C/105332/4/01/2025 | B109: =VLOOKUP(A109,policy!B:C,2,0) -> 070000173680 | C109: 75250 | D109: =ROUND(C109,0) -> 75250 | E109: 20Feb250031 | F109: ="insert into ins_premium_det (premium_rcv_code,assorted_code, rec_amount,premium_rcv_detail_code,remaining_amt, payrec, mode_code,coinsurance_code,class_cd,it_remarks) values" -> insert into ins_premium_det (premium_rcv_code,assorted_code, rec_amount,premium_rcv_detail_code,remaining_amt, payrec, mode_code,coinsurance_code,class_cd,it_remarks) values | G109: ="('"&E109&"','"&B109&"','"&D109&"',(select max(to_number(i.premium_rcv_detail_code))+1 from ins_premium_det i),'"&D109&"','"&D109&"','02', '11000003','00','Request by Mr.Saqib Saleem 20-Feb-2025');" -> ('20Feb250031','070000173680','75250',(select max(to_number(i.premium_rcv_detail_code))+1 from ins_premium_det i),'75250','75250','02', '11000003','00','Request by Mr.Saqib Saleem 20-Feb-2025'); | H109: =F109&G109 -> insert into ins_premium_det (premium_rcv_code,assorted_code, rec_amount,premium_rcv_detail_code,remaining_amt, payrec, mode_code,coinsurance_code,class_cd,it_remarks) values('20Feb250031','070000173680','75250',(select max(to_number(i.premium_rcv_detail_code))+1 from ins_premium_det i),'75250','75250','02', '11000003','00','Request by Mr.Saqib Saleem 20-Feb-2025');
