Workbook

Sheet sheet
A1: Sr. | B1: Status | C1: Contract No. | D1: Contract Status | E1: Insurance Agency | F1: Customer Name | G1: City | H1: CNIC No. | I1: Home Phone# | J1: Mobile Number | K1: Business Phone# | L1: Mail Address | M1: Finance Amount | N1: Car Price | O1: Ins. Policy | P1: Ins. Expiry Date | Q1: Engine No. | R1: Chassis No. | S1: Car Category | T1: Reg. No. | U1: Car Name | V1: Model | W1: Contract Booking Date | X1: Contract Value Date | Y1: Contract Maturity Date | Z1: Purchase Order No. | AA1: Tenor#2 | AB1: Tracker Company | AC1: Tracker Reference Number | AD1: Tracker Installation Date | AE1: Insurance Rate | AF1: Sum Insured | AG1: Premium | AH1: OLD Contract Ref | AI1: Remarks-I | AJ1: Remarks-II | AK1: Policy # | AL1: Tms Prem | AM1: Issue Date | AN1: End. # | AO1: Difference
A2: 5 | B2: NORM | C2: 9976AD1220110005 | D2: A | E2: T-PAK | F2: MALIK ADNAN YAQOOB | G2: Islamabad | H2: 37405-7616612-3 | I2: 03335142774 | K2: 0 | L2: H # 5-A ST # 24 SECTOR F-7/2 ISLAMABAD PK | M2: 1807500 | N2: 3615000 | O2: 59294/0004/03/2022 | P2: 45717 | Q2: 14808473 | R2: 025239 | U2: HONDA BRV-IVTEC-S | V2: 2022 | W2: 11-JAN-2022 | X2: 11-MAR-2022 | Y2: 11-Mar-2027 | Z2: OLAISD300083024 | AA2: 5 | AB2: ITECL | AC2: 6520/03/2022 | AD2: 02-MAR-2022 | AE2: 2% | AF2: 2892000 | AG2: 57840 | AJ2: T-PAK | AK2: KHI/HO/D/MO/PC COMP/C/108044/5/03/2025 | AL2: 57840 | AM2: 45733 | AO2: =AG2-AL2 -> 0
A3: 8 | B3: NORM | C3: 9976AD1210300105 | D3: A | E3: T-PAK | F3: MUHAMMAD AAMIR | G3: Rawalpindi | H3: 35200-1536704-3 | J3: 03334001278 | K3: 0512283654 | L3: HOUSE NO 125 STREET NO 71 SECTOR G-9/3 ISLAMABAD | M3: 2472600 | N3: 4121000 | O3: 53968/00001/03/2021 | P3: 45717 | Q3: Z16918554 | R3: 070717 | U3: HONDA CIVIC VTI ORIEL P/T | V3: 2021 | W3: 30-JAN-2021 | X3: 21-MAR-2021 | Y3: 21-Mar-2026 | Z3: OLARWP300065591 | AA3: 5 | AB3: CTRK | AC3: DIB0029769 | AD3: 03-MAR-2021 | AE3: 2% | AF3: 3296800 | AG3: 65936 | AJ3: T-PAK | AK3: KHI/HO/D/MO/PC COMP/C/108044/6/03/2025 | AL3: 65936 | AM3: 45733 | AO3: =AG3-AL3 -> 0
A4: 22 | B4: NORM | C4: 9976AD1212730065 | D4: A | E4: T-PAK | F4: FARHAN MANZOOR | G4: Faisalabad | H4: 33100-4587597-7 | I4: 03006640592 | J4: 03006640592, 03006640592 | K4: 0418787931 | L4: H NO P-154 ST NO 05 KHALID ABAD NO 01 FAISALABAD PK | M4: 885500 | N4: 1610000 | O4: 58470/00291/02/2022 | P4: 45718 | Q4: 230730 | R4: 10130728 | U4: SUZUKI WAGON R VXL | V4: 2021 | W4: 30-SEP-2021 | X4: 11-MAR-2022 | Y4: 11-Mar-2026 | Z4: OLAFSD300074293 | AA4: 4 | AB4: CTRK | AC4: DIB0033650 | AD4: 02-MAR-2022 | AE4: 2% | AF4: 1288000 | AG4: 25760 | AJ4: T-PAK | AK4: KHI/HO/D/MO/PC COMP/C/108044/20/03/2025 | AL4: 25760 | AM4: 45733 | AO4: =AG4-AL4 -> 0
A5: 25 | B5: NORM | C5: 9976AP1220660001 | D5: A | E5: T-PAK | F5: ZAHEER ASGHAR | G5: Gujranwala | H5: 34104-5573816-3 | I5: 03317777139 | J5: 03317777139 | K5: 03317777139 | L5: KOT NOORA ROAD MOH SIKANDAR PURA GH AKHAR MANDI GUJRANWALA PK | M5: 1100000 | N5: 2000000 | O5: 59294/00015/03/2022 | P5: 45718 | Q5: 17441653 | R5: R181898 | S5: LEC-16-4453 | T5: LEC-16-4453 | U5: HONDA CITY I-VTEC | V5: 2016 | W5: 07-MAR-2022 | X5: 11-MAR-2022 | Y5: 11-Mar-2027 | Z5: OLAGWL300085054 | AA5: 5 | AB5: CTRK | AC5: DIB0033723 | AD5: 04-MAR-2022 | AE5: 1.5% | AF5: 1600000 | AG5: 24000 | AJ5: T-PAK | AK5: KHI/HO/D/MO/PC COMP/C/108044/22/03/2025 | AL5: 24000 | AM5: 45733 | AO5: =AG5-AL5 -> 0
A6: 29 | B6: NORM | C6: 9976AD1213290019 | D6: A | E6: T-PAK | F6: SOFIA OWAIS | G6: Karachi | H6: 42201-0660881-2 | I6: 03333666848 | J6: 03333666848 | K6: 0 | L6: HOUSE NO 54 B/1 KHAYABAN-E- BAHRIA DHA PHASE 7 SHEEL PETROL PUMP KARACHI PK | M6: 2173500 | N6: 3105000 | O6: 59294/00016/03/2022 | P6: 45718 | Q6: 2A47420 | R6: 9517702 | U6: TOYOTA YARIS ATIV X 1.5 AT | V6: 2022 | W6: 25-NOV-2021 | X6: 11-MAR-2022 | Y6: 11-Mar-2027 | Z6: OLAKHI300080262 | AA6: 5 | AB6: FLCN | AC6: 108748/03/2022 | AD6: 03-MAR-2022 | AE6: 2% | AF6: 2484000 | AG6: 49680 | AJ6: T-PAK | AK6: KHI/HO/D/MO/PC COMP/C/108044/30/03/2025 | AL6: 49680 | AM6: 45733 | AO6: =AG6-AL6 -> 0
A7: 31 | B7: NORM | C7: 9976AP1210140002 | D7: A | E7: T-PAK | F7: BILAL AHMAD | G7: Lahore | H7: 35202-8138215-5 | I7: 3361908430 | J7: 3361908430 | K7: 4235111188 | L7: OFFICE NO 13 1ST FLOOR GLAMAR ONE P LAZA MAIN PECO ROAD MOCHIPURA LAHORE | M7: 2072250 | N7: 2763000 | O7: 2524/02288/00040/01/2021 | P7: 45669 | Q7: 2A09535 | R7: 7005411 | S7: NEW | U7: YARIS ATIV CVT 1.3 | V7: 2021 | W7: 44210 | X7: 21-JAN-2021 | Y7: 46043 | Z7: OLDLHR300064859 | AA7: 5 | AB7: CTRK | AC7: DIB0029335 | AD7: 44209 | AE7: 2% | AF7: 2072250 | AG7: 41445 | AJ7: EFU-TW | AK7: KHI/HO/D/MO/PC COMP/C/106590/214/01/2025 | AL7: 41445 | AM7: 45681 | AO7: =AG7-AL7 -> 0
A8: 32 | B8: NORM | C8: 9976AD2210300042 | D8: A | E8: T-PAK | F8: HAFEEZ UR REHMAN NASIR | G8: Lahore | H8: 35202-3344491-1 | I8: 042-7845338 0321-4121057 | J8: 0321-4121057 | K8: 042-35783219 | L8: H NO 124 JASMEEN BLOCK PARK VIEW VILLAGE OPPSITE EME SOCIETY MULTAN ROAD LAHORE | M8: 2884700 | N8: 4121000 | O8: 53968/00005/03/2021 | P8: 45718 | Q8: R18Z16918627 | R8: NFBFC6660MR070786 | U8: HONDA CIVIC | V8: 2021 | W8: 30-JAN-2021 | X8: 21-MAR-2021 | Y8: 21-Mar-2026 | Z8: OLALHR300065597 | AA8: 5 | AB8: CTRK | AC8: DIB0029772 | AD8: 03-MAR-2021 | AE8: 2% | AF8: 3090750 | AG8: 61815 | AJ8: T-PAK | AK8: KHI/HO/D/MO/PC COMP/C/108044/32/03/2025 | AL8: 61815 | AM8: 45733 | AO8: =AG8-AL8 -> 0
A9: 33 | B9: WACH | C9: 9976AP1220320087 | D9: A | E9: T-PAK | F9: MUHAMMAD NAVEED SHAIKH | G9: Hyderabad | H9: 41303-7851664-7 | I9: 03363082992 | J9: 03363082992 | K9: 03363082992 | L9: HOUSE # 75/A BLOCK A-1 BISMILLAH CI TY UNIT # 10 LATIFABAD NEAR ABDUL G HYDERABAD PK | M9: 1500000 | N9: 2000000 | O9: 57872/00288/01/2022 | P9: 45687 | Q9: 135929 | R9: 10035925 | S9: USD | T9: BPJ-276 | U9: SUZUKI CULTUS VXL | V9: 2019 | W9: 44593 | X9: 03-FEB-2022 | Y9: 47152 | Z9: OLUHYD300083841 | AA9: 7 | AB9: CTRK | AC9: DIB0033348 | AD9: 31-JAN-2022 | AE9: 1.5% | AF9: 1600000 | AG9: 24000 | AJ9: IGI-TW | AK9: KHI/HO/D/MO/PC COMP/P/108413/1/03/2025 | AL9: 24000 | AM9: 45743 | AO9: =AG9-AL9 -> 0
A10: 34 | B10: NORM | C10: 9976AD1201790028 | D10: A | E10: T-PAK | F10: MISBAH BASHIR | G10: Lahore | H10: 35202-3770201-2 | I10: 03060475045 | J10: 03060475045 | K10: 03060475045 | L10: OFF# 120 3 D 2 GREEN TOWN LAHORE | M10: 976575 | N10: 1274000 | O10: 50255/00026/01/2019 | P10: 45680 | Q10: 180335 | R10: 10080342 | S10: NEW | T10: LEA-19-4251 | U10: WAGONR VXL | V10: 2018 | W10: 44009 | X10: 27-SEP-2020 | Y10: 46230 | Z10: POALHR300040075 | AA10: 7 | AB10: CTRK | AC10: TDIDIB0026279 | AD10: 24-JAN-2019 | AE10: 3.1% | AF10: 764400 | AG10: 23696 | AH10: 9976AD1183120002 | AI10: CO19 Relief Principal Deferment Cases | AJ10: T-PAK | AK10: KHI/HO/D/MO/PC COMP/C/106590/7/01/2025 | AL10: 23696 | AM10: 45681 | AO10: =AG10-AL10 -> 0
A11: 35 | B11: NORM | C11: 9976AD2233520001 | D11: A | E11: T-PAK | F11: MUHAMMAD FAREED | G11: Faisalabad | H11: 33102-7009350-1 | I11: 03120000592 | J11: 03120000592, 03120000592 | K11: 03120000592 | L11: P-137 ST NO 01 ISLAM NAGAR FSD NEAR SOFIA MASJID FAISALABAD PK | M11: 2846800 | N11: 5176000 | O11: 81032/00026/01/2024 | P11: 45680 | Q11: 2A64781 | R11: 7042414 | S11: NEW | U11: TOYOTA YARIS AERO 1.3 | V11: 2023 | W11: 45278 | X11: 03-FEB-2024 | Y11: 46421 | Z11: OLAFSD300098610 | AA11: 3 | AB11: CTRK | AC11: DIB0035556 | AD11: 24-JAN-2024 | AE11: 1.75% | AF11: 4658400 | AG11: 81522 | AJ11: T-PAK | AK11: KHI/HO/D/MO/PC COMP/C/106590/197/01/2025 | AL11: 76993 | AM11: 45681 | AN11: KHI/HO/D/MO/PC COMP/E/52918/00197/03/2025 | AO11: =AG11-AL11 -> 4529
A12: 36 | B12: NORM | C12: 9976AD1213330059 | D12: A | E12: T-PAK | F12: MUHAMMAD ADNAN BUTT | G12: Rawalpindi | H12: 37405-0137234-5 | I12: 03215050004 | K12: 0 | L12: H # 1-A ST # 1 SECTOR G PHASE 8 BAH RIA TOWN ISLAMABAD PK | M12: 1746400 | N12: 2183000 | O12: 66406/00048/01/2023 | P12: 45680 | Q12: 174463 | R12: 711781 | S12: NEW | U12: KIA PICANTO 1.0 L A/T | V12: 2023 | W12: 44529 | X12: 27-JAN-2023 | Y12: 46779 | Z12: OLARWP300060642 | AA12: 5 | AB12: ITECL | AC12: 9877/01/2023 | AD12: 25-JAN-2023 | AE12: 2% | AF12: 1855550 | AG12: 37111 | AJ12: T-PAK | AK12: KHI/HO/D/MO/PC COMP/C/106590/200/01/2025 | AL12: 32745 | AM12: 45681 | AN12: KHI/HO/D/MO/PC COMP/E/52918/00200/03/2025 | AO12: =AG12-AL12 -> 4366
A13: 37 | B13: NORM | C13: 9976AD1223550010 | D13: A | E13: T-PAK | F13: MAHBOOB AHMED | G13: Karachi | H13: 31301-4548937-7 | J13: 00971547194644 | L13: FLAT NO318 U04 ITALY CLUSTER INTERNATIONAL CITY DUBAI 506003 UNITED ARAB EMIRATES | M13: 3970200 | N13: 6108000 | O13: DIB/T/39825/KHI/0123 | P13: 45674 | Q13: 90000618 | R13: 501475 | S13: RDA | U13: PEUGEOT 2008 ALLURE | V13: 2023 | W13: 44916 | X13: 21-JAN-2023 | Y13: 46408 | Z13: OLAKHI300091275 | AA13: 4 | AB13: ITFT | AC13: 9758/01/2023/ITFM | AD13: 09-JAN-2023 | AE13: 1.4% | AF13: 4886400 | AG13: 68410 | AJ13: T-PAK | AK13: KHI/HO/D/MO/PC COMP/C/106590/268/01/2025 | AL13: 68410 | AM13: 45681 | AO13: =AG13-AL13 -> 0
A14: 38 | B14: NORM | C14: 9976AP1220670005 | D14: A | E14: T-PAK | F14: FAIZAN AHMED | G14: Faisalabad | H14: 35501-0352057-3 | I14: 03229999968 | J14: 03229999968, 03229999968 | K14: 03229999968 | L14: P-49 ST NO 6 AL NOOR GARDENS FSD FAISALABAD PK | M14: 2145000 | N14: 3300000 | O14: 59294/00014/03/2022 | P14: 45718 | Q14: 71402490 | R14: 008498 | S14: AAF-400 | T14: AAF-400 | U14: HONDA CIVIC 1.5L TURBO | V14: 2016 | W14: 08-MAR-2022 | X14: 11-MAR-2022 | Y14: 11-Mar-2027 | Z14: OLUFSD300085052 | AA14: 5 | AB14: CTRK | AC14: DIB0033722 | AD14: 08-MAR-2022 | AE14: 1.5% | AF14: 2640000 | AG14: 39600 | AJ14: T-PAK | AK14: KHI/HO/D/MO/PC COMP/C/108044/39/03/2025 | AL14: 39600 | AM14: 45733 | AO14: =AG14-AL14 -> 0
A15: 39 | B15: NORM | C15: 9976AD1212420025 | D15: A | E15: T-PAK | F15: MUHMMAD HUSSAIN AFZAL | G15: Lahore | H15: 35201-7016546-3 | I15: 03474357791 | J15: 03474357791 | K15: 04236311747 | L15: 509,510,515,516 NATIONAL TOWER 28 E GERTON ROAD LAHORE | M15: 993000 | N15: 1655000 | O15: 57872/00115/01/2022 | P15: 45674 | Q15: 189873 | R15: 10089868 | S15: NEW | U15: SUZUKI CULTUS VXR EURO II | V15: 2021 | W15: 44438 | X15: 27-JAN-2022 | Y15: 46779 | Z15: OLALHR300072668 | AA15: 6 | AB15: CTRK | AC15: DIB0033202 | AD15: 19-JAN-2022 | AE15: 2% | AF15: 1324000 | AG15: 26480 | AJ15: T-PAK | AK15: KHI/HO/D/MO/PC COMP/C/106590/281/01/2025 | AL15: 24825 | AM15: 45681 | AN15: KHI/HO/D/MO/PC COMP/E/52918/00281/03/2025 | AO15: =AG15-AL15 -> 1655
A16: 40 | B16: NORM | C16: 997APD2201790054 | D16: A | E16: T-PAK | F16: MUHAMMAD ABDULLAH AWAN | G16: Lahore | H16: 35201-5582150-9 | I16: 03219484109 | J16: 03009484109 03219484109 | K16: 04235600244 | L16: VILLAGE HAYER P O KHAS BEDIAN ROAD LHR | M16: 1179969 | N16: 1855000 | O16: 51671/00047/01/2020 | P16: 45687 | Q16: 154342 | R16: 10054330 | S16: NEW | T16: LEA-20-2894 | U16: SUZUKI CULTUS VXL | V16: 2020 | W16: 44009 | X16: 27-SEP-2020 | Y16: 45865 | Z16: PODLHR300053053 | AA16: 5 | AB16: CTRK | AC16: DIB0028161 | AD16: 31-JAN-2020 | AE16: 2.5% | AF16: 1391250 | AG16: 34781 | AH16: 997APD2200310017 | AI16: CO19 Relief Principal Deferment Cases | AJ16: T-PAK | AK16: KHI/HO/D/MO/PC COMP/C/106590/3/01/2025 | AL16: 34781 | AM16: 45681 | AO16: =AG16-AL16 -> 0
A17: 41 | B17: WACH | C17: 9976AD2212720023 | D17: A | E17: T-PAK | F17: SAQIB SARWAR | G17: Karachi | H17: 42101-9970985-1 | I17: 03432480513 | J17: 03432480513 | K17: 03432480513 | L17: SCHEME # 33 H # A-743 AHSANABAD NEW KARACHI KARACHI PK | M17: 1001250 | N17: 1335000 | O17: 59294/00017/03/2022 | P17: 45718 | Q17: 215049 | R17: 1115064 | U17: SUZUKI ALTO VXR EURO II | V17: 2022 | W17: 29-SEP-2021 | X17: 11-MAR-2022 | Y17: 11-Mar-2029 | Z17: OLAKHI300074288 | AA17: 7 | AB17: CTRK | AC17: DIB0033700 | AD17: 03-MAR-2022 | AE17: 2% | AF17: 1068000 | AG17: 21360 | AJ17: T-PAK | AK17: KHI/HO/D/MO/PC COMP/C/108044/42/03/2025 | AL17: 21360 | AM17: 45733 | AO17: =AG17-AL17 -> 0
A18: 42 | B18: NORM | C18: 997APD1201790099 | D18: A | E18: T-PAK | F18: MUHAMMAD BILAL ASHIQ | G18: Lahore | H18: 35202-1989362-7 | J18: 03004621267 | L18: H NO 18/A, MOHALLAH RAVI COLONY 2 BUND ROAD LAHORE | M18: 1243716 | N18: 1695000 | O18: 51671/00042/01/2020 | P18: 45686 | Q18: 202053 | R18: 10101882 | S18: NEW | T18: LEA-20-2840 | U18: WAGON R VXL | V18: 2020 | W18: 44009 | X18: 27-SEP-2020 | Y18: 45865 | Z18: PODLHR300053036 | AA18: 5 | AB18: CTRK | AC18: DIB0028149 | AD18: 30-JAN-2020 | AE18: 2% | AF18: 1017000 | AG18: 18647 | AH18: 997APD1200310007 | AI18: CO19 Relief Principal Deferment Cases | AJ18: T-PAK | AK18: KHI/HO/D/MO/PC COMP/C/106590/5/01/2025 | AL18: 18647 | AM18: 45681 | AO18: =AG18-AL18 -> 0
A19: 43 | B19: WACH | C19: 9976AP2201810001 | D19: A | E19: T-PAK | F19: SULTAN GHAZI | G19: Karachi | H19: 42201-0574561-7 | I19: 34387070 | J19: 03211466533 | K19: 34893635 | L19: FLAT NO 3 AND 4 1ST FLOOR 825 C IMRAN APPT BLOCK 2 PECHS OPP JHEEL PARK KARACHI | M19: 1512095 | N19: 2554500 | O19: DIB/T/19765/KHI/0118 | P19: 45660 | Q19: 327032 | R19: 7026147 | S19: NEW | T19: BLK-228 | U19: TOYOTA COROLLA ALTIS GRANDE CVT | V19: 2017 | W19: 44011 | X19: 03-OCT-2020 | Y19: 45841 | Z19: PODKHI300028960 | AA19: 7 | AB19: FLCN | AC19: 14460/01/2018 | AD19: 04-JAN-2018 | AE19: 3.2% | AF19: 1532700 | AG19: 39852 | AH19: 9976AP2180050003 | AI19: CO19 Relief Principal Deferment Cases | AJ19: TDI-TW | AK19: KHI/HO/D/MO/PC COMP/C/106590/6/01/2025 | AL19: 39852 | AM19: 45681 | AO19: =AG19-AL19 -> 0
A20: 44 | B20: WACH | C20: 9976AP1220310042 | D20: A | E20: T-PAK | F20: WASEEM YOUNIS | G20: Karachi | H20: 42101-7965884-9 | I20: 03432555365 | K20: 02199012719 | L20: FLAT # 202 JINNAH COMPLEX BLOCK A- M.A JINNAH ROAD KARACHI KARACHI PK | M20: 1024000 | N20: 1280000 | O20: DIB/T/35492/KHI/0122 | P20: 45687 | Q20: B-110096 | R20: PK10010085 | S20: USD | T20: BEW-828 | U20: SUZUKI WAGNOR VXL | V20: 2015 | W20: 44592 | X20: 03-FEB-2022 | Y20: 46056 | Z20: OLUKHI300083734 | AA20: 4 | AB20: CTRK | AC20: TDIDIB0030017 | AD20: 31-JAN-2022 | AE20: 1.5% | AF20: 1024000 | AG20: 15360 | AJ20: TDI-TW | AK20: KHI/HO/D/MO/PC COMP/P/108413/2/03/2025 | AL20: 15360 | AM20: 45743 | AO20: =AG20-AL20 -> 0
A21: 45 | B21: NORM | C21: 9976AP2220310051 | D21: A | E21: T-PAK | F21: HAFIZ UMAIR UL HASSAN HASHMI | G21: Karachi | H21: 42101-2139260-7 | I21: 03219473373 | J21: 3219473373, 3219473373 | K21: 3219473373 | L21: PLOT # 2B2 FLAT # A-2 1ST FLOOR BAS HIR MARKET FLATS BASHIR MARKET COMM KARACHI PK | M21: 1190000 | N21: 1700000 | O21: DIB/T/35490/KHI/0122 | P21: 45687 | Q21: 13025787 | R21: 10025768 | S21: USD | T21: BCC-937 | U21: SUZUKI SWIFT A/T NAVIGATION | V21: 2014 | W21: 44592 | X21: 03-FEB-2022 | Y21: 46056 | Z21: OLUKHI300083746 | AA21: 4 | AB21: CTRK | AC21: TDIDIB0030016 | AD21: 31-JAN-2022 | AE21: 1.5% | AF21: 1360000 | AG21: 20400 | AJ21: TDI-TW | AK21: KHI/HO/D/MO/PC COMP/P/108413/3/03/2025 | AL21: 20400 | AM21: 45743 | AO21: =AG21-AL21 -> 0
A22: 46 | B22: NORM | C22: 9976AP2220310064 | D22: A | E22: T-PAK | F22: MUHAMMAD FAROOQ MEMON | G22: Hyderabad | H22: 41306-5546166-9 | I22: N/A | J22: 03008372488 | K22: 0321-8372488 | L22: H # A-13 MEMON CO OPERATIVE HOUSING SOCIETY QASIMABAD NEAR MARYAM MASJID HYDARABAD | M22: 2730000 | N22: 3900000 | O22: DIB/T/35499/HYD/0122 | P22: 45687 | Q22: Q326880 | R22: 7056048 | S22: NEW | U22: TOYOTA COROLLA ALTIS GRANDE CVT | V22: 2022 | W22: 44592 | X22: 03-FEB-2022 | Y22: 46056 | Z22: OLDHYD300083842 | AA22: 4 | AB22: CTRK | AC22: TDIDIB0030022 | AD22: 31-JAN-2022 | AE22: 1.5% | AF22: 3120000 | AG22: 46800 | AJ22: TDI-TW | AK22: KHI/HO/D/MO/PC COMP/P/108413/4/03/2025 | AL22: 46800 | AM22: 45743 | AO22: =AG22-AL22 -> 0
A23: 47 | B23: NORM | C23: 9976AP2220310056 | D23: A | E23: T-PAK | F23: MUHAMMAD ALI JAMAL | G23: Karachi | H23: 42301-5689797-5 | I23: 35841843 | J23: 0321-8230113 | K23: 111-565-565 | L23: HOUSE NO 65/1 6TH STREET KHAYABAN-E-BADBAN PHASE 5 DHA SAUDI CONSULATE KARACHI | M23: 2256800 | N23: 3472000 | O23: DIB/T/35493/KHI/0122 | P23: 45687 | Q23: 615Z81004146 | R23: 011408 | S23: NEW | U23: HONDA CITY ASPIRE A/T | V23: 2022 | W23: 44592 | X23: 03-FEB-2022 | Y23: 46056 | Z23: OLDKHI300083800 | AA23: 4 | AB23: CTRK | AC23: TDIDIB0030019 | AD23: 31-JAN-2022 | AE23: 2% | AF23: 2777600 | AG23: 55552 | AJ23: TDI-TW | AK23: KHI/HO/D/MO/PC COMP/P/108413/5/03/2025 | AL23: 55552 | AM23: 45743 | AO23: =AG23-AL23 -> 0
A24: 48 | B24: NORM | C24: 9976AP2220320076 | D24: A | E24: T-PAK | F24: RAHEEL | G24: Karachi | H24: 42301-8907342-3 | I24: 03332426655 | J24: 03332426655 | K24: 0 | L24: FLAT # 202 2ND FLOOR BAKSHI ROYAL R ESIDENCY PLOT # JM 71 NEAR HUSSAIN KARACHI PK | M24: 1179500 | N24: 1685000 | O24: 57872/00301/01/2022 | P24: 45687 | Q24: 6R164957 | R24: H1064913 | S24: USD | T24: BTY-884 | U24: SUZUKI ALTO VXR | V24: 2021 | W24: 44593 | X24: 03-FEB-2022 | Y24: 46786 | Z24: OLUKHI300083943 | AA24: 6 | AB24: CTRK | AC24: DIB0033352 | AD24: 31-JAN-2022 | AE24: 1.5% | AF24: 1348000 | AG24: 20220 | AJ24: T-PAK | AK24: KHI/HO/D/MO/PC COMP/C/106590/56/01/2025 | AL24: 21484 | AM24: 45681 | AN24: KHI/HO/D/MO/PC COMP/E/52918/00056/03/2025 | AO24: =AG24-AL24 -> -1264
A25: 49 | B25: NORM | C25: 9976AP2220320092 | D25: A | E25: T-PAK | F25: AMAN ULLAH SOOMRO | G25: Hyderabad | H25: 41306-9665808-7 | I25: 03083303122 | J25: 03083303122 | K25: 03083303122 | L25: HOUSE # 17-A LAB E MEHRAN HOUSING S OCIETY QASIMABAD HYDERABAD PK | M25: 1098000 | N25: 1830000 | O25: 57872/00302/01/2022 | P25: 45687 | Q25: 188996 | R25: 10088975 | S25: USD | T25: BVA-874 | U25: SUZUKI CULTUS VXL | V25: 2021 | W25: 44593 | X25: 03-FEB-2022 | Y25: 46056 | Z25: OLUHYD300083919 | AA25: 4 | AB25: CTRK | AC25: DIB0033360 | AD25: 01-FEB-2022 | AE25: 1.5% | AF25: 1464000 | AG25: 21960 | AJ25: T-PAK | AK25: KHI/HO/D/MO/PC COMP/C/106590/58/01/2025 | AL25: 23333 | AM25: 45681 | AN25: KHI/HO/D/MO/PC COMP/E/52918/00058/03/2025 | AO25: =AG25-AL25 -> -1373
A26: 50 | B26: NORM | C26: 9976AD2212710002 | D26: A | E26: T-PAK | F26: KAMRAN KHAN | G26: Lahore | H26: 42101-6108385-9 | I26: 03172050500 | J26: 03172050500 | K26: 03172050500 | L26: OFFICE B-293 SABZAZAR MULTAN ROAD N EAR DARE ARQAM SCHOOL LAHORE | M26: 934500 | N26: 1335000 | O26: 59294/00024/03/2022 | P26: 45719 | Q26: 215242 | R26: 1115222 | U26: SUZUKI ALTO VXR EURO II | V26: 2022 | W26: 28-SEP-2021 | X26: 11-MAR-2022 | Y26: 11-Mar-2027 | Z26: OLALHR300073782 | AA26: 5 | AB26: CTRK | AC26: DIB0033732 | AD26: 07-MAR-2022 | AE26: 2% | AF26: 1068000 | AG26: 21360 | AJ26: T-PAK | AK26: KHI/HO/D/MO/PC COMP/C/108044/49/03/2025 | AL26: 21360 | AM26: 45733 | AO26: =AG26-AL26 -> 0
A27: 51 | B27: NORM | C27: 9976AP1220310058 | D27: A | E27: T-PAK | F27: ASIM NADEEM | G27: Faisalabad | H27: 33100-4949629-7 | I27: 03019200098 | J27: 03019200098, 03019200098 | K27: 03019200098 | L27: 2967 ST NO 5 ROZA PARK MANSOOR ABAD FSD FAISALABAD PK | M27: 675000 | N27: 900000 | O27: 57872/00263/01/2022 | P27: 45687 | Q27: PKT935823 | R27: SV308PK01052310 | S27: USD | T27: CV-8837 | U27: SUZUKI BOLAN VX | V27: 2016 | W27: 44592 | X27: 03-FEB-2022 | Y27: 46056 | Z27: OLUFSD300083794 | AA27: 4 | AB27: ITECL | AC27: 6231/01/2022 | AD27: 31-JAN-2022 | AE27: 1.5% | AF27: 720000 | AG27: 10800 | AJ27: T-PAK | AK27: KHI/HO/D/MO/PC COMP/C/106590/68/01/2025 | AL27: 11475 | AM27: 45681 | AN27: KHI/HO/D/MO/PC COMP/E/52918/00068/03/2025 | AO27: =AG27-AL27 -> -675
A28: 52 | B28: NORM | C28: 997AAD1203210013 | D28: A | E28: T-PAK | F28: MUHAMMAD AZHAR NAEEM | G28: Lahore | H28: 35201-8239659-7 | I28: 3214776571 | J28: 3214776571 | K28: 35230650-54 | L28: H# 83-D TARIQ GARDEN NEAR WAPDA TOWN NR USMANIA TOWER LAHORE | M28: 4072500 | N28: 5430000 | O28: 53545/00128/01/2021 | P28: 45685 | Q28: G4NALH34202 | R28: NNAQL51AZKP508418 | S28: NEW | U28: SPORTAGE AWD | V28: 2021 | W28: 44151 | X28: 03-FEB-2021 | Y28: 46786 | Z28: POALHR300060961 | AA28: 7 | AB28: Tracker Not Install | AE28: 1.5% | AF28: 4344000 | AG28: 61088 | AJ28: T-PAK | AK28: KHI/HO/D/MO/PC COMP/C/106590/93/01/2025 | AL28: 65160 | AM28: 45681 | AN28: KHI/HO/D/MO/PC COMP/E/52918/00093/03/2025 | AO28: =AG28-AL28 -> -4072
A29: 53 | B29: NORM | C29: 9976AP2220310052 | D29: A | E29: T-PAK | F29: AHMED SHAH | G29: Karachi | H29: 42201-0727539-3 | J29: 03008231124 | K29: 03008231124 | L29: G-9 AND G-48 GOLD LINE HARBOUR NEAR ABL BANK JACKSON MARKET KEMARI KARACHI | M29: 2729300 | N29: 3899000 | O29: 57872/00245/01/2022 | P29: 45685 | Q29: Q088739 | R29: 6066183 | S29: NEW | U29: TOYOTA COROLLA ALTIS 1.6 SPECIAL EDITION | V29: 2022 | W29: 44592 | X29: 03-FEB-2022 | Y29: 46056 | Z29: OLDKHI300083768 | AA29: 4 | AB29: CTRK | AC29: DIB0033333 | AD29: 31-JAN-2022 | AE29: 1.5% | AF29: 3119200 | AG29: 46788 | AJ29: T-PAK | AK29: KHI/HO/D/MO/PC COMP/C/106590/96/01/2025 | AL29: 49712 | AM29: 45681 | AN29: KHI/HO/D/MO/PC COMP/E/52918/00096/03/2025 | AO29: =AG29-AL29 -> -2924
A30: 54 | B30: NORM | C30: 9976AD1212940032 | D30: A | E30: T-PAK | F30: WAJID ZAKIR | G30: Islamabad | H30: 82303-6957909-3 | J30: 03138586926 | K30: 0512201256 | L30: DANISH ENTERPRISES SHOP NO 4 ZAKIA PLAZA NEAR CHINA CHOWK FAZAL E HAQ ROAD BLUE AREA ISLAMABAD | M30: 1068000 | N30: 1335000 | O30: 59294/00026/03/2022 | P30: 45719 | Q30: 197795 | R30: 1097766 | U30: SUZUKI ALTO VXR EURO II | V30: 2022 | W30: 21-OCT-2021 | X30: 11-MAR-2022 | Y30: 11-Mar-2027 | Z30: OLAISD300075525 | AA30: 5 | AB30: CTRK | AC30: DIB0033731 | AD30: 07-MAR-2022 | AE30: 2% | AF30: 1068000 | AG30: 21360 | AJ30: T-PAK | AK30: KHI/HO/D/MO/PC COMP/C/108044/55/03/2025 | AL30: 21360 | AM30: 45733 | AO30: =AG30-AL30 -> 0
A31: 55 | B31: NORM | C31: 9976AP1220320079 | D31: A | E31: T-PAK | F31: MUHAMMAD RIZWAN YOUSAF | G31: Lahore | H31: 35202-2174987-9 | I31: 03219808888 | J31: 03219808888 | K31: 03219808888 | L31: OPPOSITE GATE # 1 , MANSOORA HOSPIT AL , MULTAN ROAD LHR LAHORE PK | M31: 2240000 | N31: 3200000 | O31: 57872/00235/01/2022 | P31: 45685 | Q31: R18Z12901668 | R31: NFBFC6666GR002223 | S31: USD | T31: LE-16A-2324 | U31: HONDA CIVIC VTI ORIEL P/T | V31: 2016 | W31: 44593 | X31: 03-FEB-2022 | Y31: 46421 | Z31: OLULHR300083771 | AA31: 5 | AB31: ITECL | AC31: 6205/01/2022 | AD31: 29-JAN-2022 | AE31: 1.5% | AF31: 2560000 | AG31: 38400 | AJ31: T-PAK | AK31: KHI/HO/D/MO/PC COMP/C/106590/99/01/2025 | AL31: 38400 | AM31: 45681 | AO31: =AG31-AL31 -> 0
A32: 56 | B32: NORM | C32: 9976AP1210300060 | D32: A | E32: T-PAK | F32: KIRAN AKIF | G32: Lahore | H32: 35202-2647195-2 | I32: 3217510045 | J32: 3217510045 | K32: 4235750205 | L32: 31-FCC GULBERG 4 LAHORE | M32: 1687500 | N32: 2250000 | O32: 53545/00118/01/2021 | P32: 45685 | Q32: Z399031 | R32: 4063646 | S32: USD | T32: AAE-524 | U32: TOYOTA COROLLA GLI A/T | V32: 2016 | W32: 44226 | X32: 03-FEB-2021 | Y32: 46421 | Z32: OLULHR300065474 | AA32: 6 | AB32: ITFM | AC32: 4175/01/2021/ITFM | AD32: 44224 | AE32: 2% | AF32: 1687500 | AG32: 33750 | AJ32: T-PAK | AK32: KHI/HO/D/MO/PC COMP/C/106590/102/01/2025 | AL32: 36000 | AM32: 45681 | AN32: KHI/HO/D/MO/PC COMP/E/52918/00102/03/2025 | AO32: =AG32-AL32 -> -2250
A33: 57 | B33: NORM | C33: 9976AD1212940026 | D33: A | E33: T-PAK | F33: UMAIR ASLAM | G33: Islamabad | H33: 37405-0721570-1 | I33: 03028985224 | K33: 0514499159 | L33: H # 12 ST # 10 KORANG TOWN ISLAMABAD PK | M33: 1134750 | N33: 1335000 | O33: 59294/00022/03/2022 | P33: 45719 | Q33: 216143 | R33: 1116111 | U33: SUZUKI ALTO VXR EURO II | V33: 2022 | W33: 21-OCT-2021 | X33: 11-MAR-2022 | Y33: 11-Mar-2027 | Z33: OLAISD300075532 | AA33: 5 | AB33: CTRK | AC33: DIB0033726 | AD33: 07-MAR-2022 | AE33: 2% | AF33: 1068000 | AG33: 21360 | AJ33: T-PAK | AK33: KHI/HO/D/MO/PC COMP/C/108044/59/03/2025 | AL33: 21360 | AM33: 45733 | AO33: =AG33-AL33 -> 0
A34: 58 | B34: NORM | C34: 9976AP1220670007 | D34: A | E34: T-PAK | F34: ARSLAN TARIQ | G34: Gujranwala | H34: 34101-9277897-1 | I34: 03216426800 | J34: 03216426800 | K34: 03216426800 | L34: HOUSE NO 2 UMAR MANZIL MOHALLAH SHA HEEN ABAD GT ROAD NEAR DARAZ OFFICE GUJRANWALA PK | M34: 1155000 | N34: 1650000 | O34: 59294/00031/03/2022 | P34: 45719 | Q34: PK10K100061 | R34: 10000059 | S34: LEF-17-3060 | T34: LEF-17-3060 | U34: SUZUKI CULTUS VXL EURO II | V34: 2017 | W34: 08-MAR-2022 | X34: 11-MAR-2022 | Y34: 11-Mar-2027 | Z34: OLUGWL300085053 | AA34: 5 | AB34: CTRK | AC34: DIB0033741 | AD34: 07-MAR-2022 | AE34: 1.5% | AF34: 1320000 | AG34: 19800 | AJ34: T-PAK | AK34: KHI/HO/D/MO/PC COMP/C/108044/60/03/2025 | AL34: 19800 | AM34: 45733 | AO34: =AG34-AL34 -> 0
A35: 59 | B35: NORM | C35: 9976AP1210300093 | D35: A | E35: T-PAK | F35: ARSALAN MALICK | G35: Karachi | H35: 42101-8138874-9 | I35: 3453992990 | J35: 3453992990 | K35: 2135899641 | L35: ICON HOUS E# 83-C 12TH COMMERICIAL STREET DHAH PHASE 2 EXT KHI NEAR SI LK BANK KARACHI | M35: 1031250 | N35: 1375000 | O35: 53545/00105/01/2021 | P35: 45684 | Q35: KQ9788 | R35: 312097 | S35: RCN | T35: BNE-425 | U35: NISSAN DAYS | V35: 2015 | W35: 44226 | X35: 03-FEB-2021 | Y35: 46421 | Z35: OLUKHI300065404 | AA35: 6 | AB35: ITFT | AC35: 4166/01/2021/ITFM | AD35: 44224 | AE35: 2% | AF35: 1031250 | AG35: 20625 | AJ35: T-PAK | AK35: KHI/HO/D/MO/PC COMP/C/106590/116/01/2025 | AL35: 22000 | AM35: 45681 | AN35: KHI/HO/D/MO/PC COMP/E/52918/00116/03/2025 | AO35: =AG35-AL35 -> -1375
A36: 60 | B36: NORM | C36: 9976AP1220310016 | D36: A | E36: T-PAK | F36: MUHAMMAD SHOAIB | G36: Islamabad | H36: 36501-9075847-7 | I36: 03406823500 | K36: 0 | L36: HOUSE # 697 ST # 44 SECTOR G-14/4 ISLAMABAD PK | M36: 1088000 | N36: 1360000 | O36: 57872/00215/01/2022 | P36: 45684 | Q36: 620622 | R36: 527510 | S36: USD | T36: AAV-334 | U36: SUZUKI CULTUS VXR | V36: 2016 | W36: 44592 | X36: 03-FEB-2022 | Y36: 46786 | Z36: OLDISD300083716 | AA36: 6 | AB36: ITECL | AC36: 6191/01/2022 | AD36: 28-JAN-2022 | AE36: 1.5% | AF36: 1088000 | AG36: 16320 | AJ36: T-PAK | AK36: KHI/HO/D/MO/PC COMP/C/106590/130/01/2025 | AL36: 17340 | AM36: 45681 | AN36: KHI/HO/D/MO/PC COMP/E/52918/00130/03/2025 | AO36: =AG36-AL36 -> -1020
A37: 61 | B37: NORM | C37: 997AAD1203210015 | D37: A | E37: T-PAK | F37: NASIR AZIZ | G37: Lahore | H37: 35201-7980017-1 | I37: 3028404050 | J37: 3028404050 | K37: 4235230508 | L37: 550 C OPF HOUSING SCHEME KHYABAN E JINNAH LAHORE | M37: 4072500 | N37: 5430000 | O37: 53545/00097/01/2021 | P37: 45683 | Q37: G4NALH342669 | R37: `NNAQL51AZKP509022 | S37: NEW | U37: SPORTAGE AWD | V37: 2021 | W37: 44151 | X37: 03-FEB-2021 | Y37: 46786 | Z37: POALHR300060951 | AA37: 7 | AB37: Tracker Not Install | AE37: 1.5% | AF37: 4344000 | AG37: 61088 | AJ37: T-PAK | AK37: KHI/HO/D/MO/PC COMP/C/106590/140/01/2025 | AL37: 65160 | AM37: 45681 | AN37: KHI/HO/D/MO/PC COMP/E/52918/00140/03/2025 | AO37: =AG37-AL37 -> -4072
A38: 62 | B38: NORM | C38: 997AAD1202830012 | D38: A | E38: T-PAK | F38: SALMA REHMAN | G38: Lahore | H38: 35202-2622285-3 | I38: 3334254938 | J38: 3334254938 | K38: 3334254938 | L38: 80 BABAR BLOCK NEW GARDEN TOWN LAHORE | M38: 3801000 | N38: 5430000 | O38: 53545/00098/01/2021 | P38: 45683 | Q38: G4NALH341884 | R38: NNAQL51AZKP508429 | S38: NEW | U38: SPORTAGE AWD | V38: 2021 | W38: 44113 | X38: 03-FEB-2021 | Y38: 46786 | Z38: POALHR300058252 | AA38: 7 | AB38: Tracker Not Install | AE38: 1.5% | AF38: 4344000 | AG38: 61088 | AJ38: T-PAK | AK38: KHI/HO/D/MO/PC COMP/C/106590/141/01/2025 | AL38: 65160 | AM38: 45681 | AN38: KHI/HO/D/MO/PC COMP/E/52918/00141/03/2025 | AO38: =AG38-AL38 -> -4072
A39: 63 | B39: NORM | C39: 9976AP2220280031 | D39: A | E39: T-PAK | F39: AHMED SALMAN MIRZA | G39: Islamabad | H39: 34603-1889697-5 | I39: 0515958880 | K39: 0519215192 | L39: H # 395 NEAR STREET 65/A PAKISTAN T OWN ISLAMABAD PK | M39: 1175600 | N39: 2939000 | O39: 57872/00209/01/2022 | P39: 45683 | Q39: 529113 | R39: 1006006 | S39: NEW | U39: CHANGAN ALSVIN 1.5 | V39: 2022 | W39: 44589 | X39: 03-FEB-2022 | Y39: 46056 | Z39: OLDISD300083655 | AA39: 4 | AB39: ITECL | AC39: 6173/01/2022 | AD39: 27-JAN-2022 | AE39: 2% | AF39: 2351200 | AG39: 47024 | AJ39: T-PAK | AK39: KHI/HO/D/MO/PC COMP/C/106590/151/01/2025 | AL39: 49963 | AM39: 45681 | AN39: KHI/HO/D/MO/PC COMP/E/52918/00151/03/2025 | AO39: =AG39-AL39 -> -2939
A40: 64 | B40: NORM | C40: 9976AP2220670003 | D40: A | E40: T-PAK | F40: ABDUL REHMAN JATOI | G40: Karachi | H40: 42201-5145490-9 | J40: 03003451042 | L40: APARTMENT # 005 TOWER 08 PRECINCT-19 BAAHIRA TOWN KARACHI 0300-3451042 | M40: 2040000 | N40: 3400000 | O40: 59294/00020/03/2022 | P40: 45719 | Q40: Q331456 | R40: 7030565 | S40: BNJ-507 | T40: BNJ-507 | U40: TOYOTA COROLLA ALTI GRANDE | V40: 2018 | W40: 08-MAR-2022 | X40: 11-MAR-2022 | Y40: 11-Mar-2027 | Z40: OLUKHI300085032 | AA40: 5 | AB40: CTRK | AC40: DIB0033725 | AD40: 07-MAR-2022 | AE40: 1.5% | AF40: 2720000 | AG40: 40800 | AJ40: T-PAK | AK40: KHI/HO/D/MO/PC COMP/C/108044/66/03/2025 | AL40: 40800 | AM40: 45733 | AO40: =AG40-AL40 -> 0
...

Sheet working
A1: KHI/HO/D/MO/PC COMP/C/108044/5/03/2025 | B1: -03-2025 | H1: 108044 | I1: 00005 | J1: ="ia.assorted_string like '%"&H1&"-"&I1&B1&"%' or" -> ia.assorted_string like '%108044-00005-03-2025%' or
A2: KHI/HO/D/MO/PC COMP/C/108044/6/03/2025 | B2: -03-2025 | H2: 108044 | I2: 00006 | J2: ="ia.assorted_string like '%"&H2&"-"&I2&B2&"%' or" -> ia.assorted_string like '%108044-00006-03-2025%' or
A3: KHI/HO/D/MO/PC COMP/C/108044/20/03/2025 | B3: -03-2025 | H3: 108044 | I3: 00020 | J3: ="ia.assorted_string like '%"&H3&"-"&I3&B3&"%' or" -> ia.assorted_string like '%108044-00020-03-2025%' or
A4: KHI/HO/D/MO/PC COMP/C/108044/22/03/2025 | B4: -03-2025 | H4: 108044 | I4: 00022 | J4: ="ia.assorted_string like '%"&H4&"-"&I4&B4&"%' or" -> ia.assorted_string like '%108044-00022-03-2025%' or
A5: KHI/HO/D/MO/PC COMP/C/108044/30/03/2025 | B5: -03-2025 | H5: 108044 | I5: 00030 | J5: ="ia.assorted_string like '%"&H5&"-"&I5&B5&"%' or" -> ia.assorted_string like '%108044-00030-03-2025%' or
A6: KHI/HO/D/MO/PC COMP/C/106590/214/01/2025 | B6: -01-2025 | H6: 106590 | I6: 00214 | J6: ="ia.assorted_string like '%"&H6&"-"&I6&B6&"%' or" -> ia.assorted_string like '%106590-00214-01-2025%' or
A7: KHI/HO/D/MO/PC COMP/C/108044/32/03/2025 | B7: -03-2025 | H7: 108044 | I7: 00032 | J7: ="ia.assorted_string like '%"&H7&"-"&I7&B7&"%' or" -> ia.assorted_string like '%108044-00032-03-2025%' or
A8: KHI/HO/D/MO/PC COMP/P/108413/1/03/2025 | B8: -03-2025 | H8: 108413 | I8: 00001 | J8: ="ia.assorted_string like '%"&H8&"-"&I8&B8&"%' or" -> ia.assorted_string like '%108413-00001-03-2025%' or
A9: KHI/HO/D/MO/PC COMP/C/106590/7/01/2025 | B9: -01-2025 | H9: 106590 | I9: 00007 | J9: ="ia.assorted_string like '%"&H9&"-"&I9&B9&"%' or" -> ia.assorted_string like '%106590-00007-01-2025%' or
A10: KHI/HO/D/MO/PC COMP/C/106590/197/01/2025 | B10: -01-2025 | H10: 106590 | I10: 00197 | J10: ="ia.assorted_string like '%"&H10&"-"&I10&B10&"%' or" -> ia.assorted_string like '%106590-00197-01-2025%' or
A11: KHI/HO/D/MO/PC COMP/C/106590/200/01/2025 | B11: -01-2025 | H11: 106590 | I11: 00200 | J11: ="ia.assorted_string like '%"&H11&"-"&I11&B11&"%' or" -> ia.assorted_string like '%106590-00200-01-2025%' or
A12: KHI/HO/D/MO/PC COMP/C/106590/268/01/2025 | B12: -01-2025 | H12: 106590 | I12: 00268 | J12: ="ia.assorted_string like '%"&H12&"-"&I12&B12&"%' or" -> ia.assorted_string like '%106590-00268-01-2025%' or
... A269: KHI/HO/D/MO/PC COMP/C/107623/206/02/2025 | B269: -02-2025 | H269: 107623 | I269: 00206 | J269: ="ia.assorted_string like '%"&H269&"-"&I269&B269&"%' or" -> ia.assorted_string like '%107623-00206-02-2025%' or
A270: KHI/HO/D/MO/PC COMP/P/108422/03/2025 | B270: 45717 | H270: 108422 | I270: 00003 | J270: ="ia.assorted_string like '%"&H270&"-"&I270&B270&"%' or" -> ia.assorted_string like '%108422-0000345717%' or
A271: KHI/HO/D/MO/PC COMP/C/107623/207/02/2025 | B271: -02-2025 | H271: 107623 | I271: 00207 | J271: ="ia.assorted_string like '%"&H271&"-"&I271&B271&"%' or" -> ia.assorted_string like '%107623-00207-02-2025%' or
A272: KHI/HO/D/MO/PC COMP/C/108044/241/03/2025 | B272: -03-2025 | H272: 108044 | I272: 00241 | J272: ="ia.assorted_string like '%"&H272&"-"&I272&B272&"%' or" -> ia.assorted_string like '%108044-00241-03-2025%' or
A273: KHI/HO/D/MO/PC COMP/C/107623/208/02/2025 | B273: -02-2025 | H273: 107623 | I273: 00208 | J273: ="ia.assorted_string like '%"&H273&"-"&I273&B273&"%' or" -> ia.assorted_string like '%107623-00208-02-2025%' or
A274: KHI/HO/D/MO/PC COMP/C/108044/240/03/2025 | B274: -03-2025 | H274: 108044 | I274: 00240 | J274: ="ia.assorted_string like '%"&H274&"-"&I274&B274&"%' or" -> ia.assorted_string like '%108044-00240-03-2025%' or
A275: KHI/HO/D/MO/PC COMP/C/107623/209/02/2025 | B275: -02-2025 | H275: 107623 | I275: 00209 | J275: ="ia.assorted_string like '%"&H275&"-"&I275&B275&"%' or" -> ia.assorted_string like '%107623-00209-02-2025%' or
A276: KHI/HO/D/MO/PC COMP/C/108044/238/03/2025 | B276: -03-2025 | H276: 108044 | I276: 00238 | J276: ="ia.assorted_string like '%"&H276&"-"&I276&B276&"%' or" -> ia.assorted_string like '%108044-00238-03-2025%' or
A277: KHI/HO/D/MO/PC COMP/C/108044/237/03/2025 | B277: -03-2025 | H277: 108044 | I277: 00237 | J277: ="ia.assorted_string like '%"&H277&"-"&I277&B277&"%' or" -> ia.assorted_string like '%108044-00237-03-2025%' or
A278: KHI/HO/D/MO/PC COMP/C/107623/210/02/2025 | B278: -02-2025 | H278: 107623 | I278: 00210 | J278: ="ia.assorted_string like '%"&H278&"-"&I278&B278&"%' or" -> ia.assorted_string like '%107623-00210-02-2025%' or
A279: KHI/HO/D/MO/PC COMP/C/108044/236/03/2025 | B279: -03-2025 | H279: 108044 | I279: 00236 | J279: ="ia.assorted_string like '%"&H279&"-"&I279&B279&"%' or" -> ia.assorted_string like '%108044-00236-03-2025%' or
A280: KHI/HO/D/MO/PC COMP/C/108044/235/03/2025 | B280: -03-2025 | H280: 108044 | I280: 00235 | J280: ="ia.assorted_string like '%"&H280&"-"&I280&B280&"%' or" -> ia.assorted_string like '%108044-00235-03-2025%' or
A281: KHI/HO/D/MO/PC COMP/C/107623/211/02/2025 | B281: -02-2025 | H281: 107623 | I281: 00211 | J281: ="ia.assorted_string like '%"&H281&"-"&I281&B281&"%' or" -> ia.assorted_string like '%107623-00211-02-2025%' or
A282: KHI/HO/D/MO/PC COMP/C/107623/212/02/2025 | B282: -02-2025 | H282: 107623 | I282: 00212 | J282: ="ia.assorted_string like '%"&H282&"-"&I282&B282&"%' or" -> ia.assorted_string like '%107623-00212-02-2025%' or
... A416: KHI/HO/D/MO/PC COMP/C/107623/45/02/2025 | B416: -02-2025 | H416: 107623 | I416: 00045 | J416: ="ia.assorted_string like '%"&H416&"-"&I416&B416&"%' or" -> ia.assorted_string like '%107623-00045-02-2025%' or

Sheet Sheet2
A1: POLICY NO. | B1: Assorted_code | D1: Premium | E1: 27Mar250028
A2: KHI/HO/D/MO/PC COMP/C/108044/5/03/2025 | B2: =VLOOKUP(A2,policy!B:C,2,0) -> 070000178695 | C2: 57840 | D2: =ROUND(C2,0) -> 57840 | E2: 27Mar250028 | F2: ="insert into ins_premium_det (premium_rcv_code,assorted_code, rec_amount,premium_rcv_detail_code,remaining_amt, payrec, mode_code,coinsurance_code,class_cd,it_remarks) values" -> insert into ins_premium_det (premium_rcv_code,assorted_code, rec_amount,premium_rcv_detail_code,remaining_amt, payrec, mode_code,coinsurance_code,class_cd,it_remarks) values | G2: ="('"&E2&"','"&B2&"','"&D2&"',(select max(to_number(i.premium_rcv_detail_code))+1 from ins_premium_det i),'"&D2&"','"&D2&"','02', '11000003','00','Request by Mr. Saqib Saleem 28-Mar-2025');" -> ('27Mar250028','070000178695','57840',(select max(to_number(i.premium_rcv_detail_code))+1 from ins_premium_det i),'57840','57840','02', '11000003','00','Request by Mr. Saqib Saleem 28-Mar-2025'); | H2: =F2&G2 -> insert into ins_premium_det (premium_rcv_code,assorted_code, rec_amount,premium_rcv_detail_code,remaining_amt, payrec, mode_code,coinsurance_code,class_cd,it_remarks) values('27Mar250028','070000178695','57840',(select max(to_number(i.premium_rcv_detail_code))+1 from ins_premium_det i),'57840','57840','02', '11000003','00','Request by Mr. Saqib Saleem 28-Mar-2025');
A3: KHI/HO/D/MO/PC COMP/C/108044/6/03/2025 | B3: =VLOOKUP(A3,policy!B:C,2,0) -> 070000178696 | C3: 65936 | D3: =ROUND(C3,0) -> 65936 | E3: 27Mar250028 | F3: ="insert into ins_premium_det (premium_rcv_code,assorted_code, rec_amount,premium_rcv_detail_code,remaining_amt, payrec, mode_code,coinsurance_code,class_cd,it_remarks) values" -> insert into ins_premium_det (premium_rcv_code,assorted_code, rec_amount,premium_rcv_detail_code,remaining_amt, payrec, mode_code,coinsurance_code,class_cd,it_remarks) values | G3: ="('"&E3&"','"&B3&"','"&D3&"',(select max(to_number(i.premium_rcv_detail_code))+1 from ins_premium_det i),'"&D3&"','"&D3&"','02', '11000003','00','Request by Mr. Saqib Saleem 28-Mar-2025');" -> ('27Mar250028','070000178696','65936',(select max(to_number(i.premium_rcv_detail_code))+1 from ins_premium_det i),'65936','65936','02', '11000003','00','Request by Mr. Saqib Saleem 28-Mar-2025'); | H3: =F3&G3 -> insert into ins_premium_det (premium_rcv_code,assorted_code, rec_amount,premium_rcv_detail_code,remaining_amt, payrec, mode_code,coinsurance_code,class_cd,it_remarks) values('27Mar250028','070000178696','65936',(select max(to_number(i.premium_rcv_detail_code))+1 from ins_premium_det i),'65936','65936','02', '11000003','00','Request by Mr. Saqib Saleem 28-Mar-2025');
A4: KHI/HO/D/MO/PC COMP/C/108044/20/03/2025 | B4: =VLOOKUP(A4,policy!B:C,2,0) -> 070000178710 | C4: 25760 | D4: =ROUND(C4,0) -> 25760 | E4: 27Mar250028 | F4: ="insert into ins_premium_det (premium_rcv_code,assorted_code, rec_amount,premium_rcv_detail_code,remaining_amt, payrec, mode_code,coinsurance_code,class_cd,it_remarks) values" -> insert into ins_premium_det (premium_rcv_code,assorted_code, rec_amount,premium_rcv_detail_code,remaining_amt, payrec, mode_code,coinsurance_code,class_cd,it_remarks) values | G4: ="('"&E4&"','"&B4&"','"&D4&"',(select max(to_number(i.premium_rcv_detail_code))+1 from ins_premium_det i),'"&D4&"','"&D4&"','02', '11000003','00','Request by Mr. Saqib Saleem 28-Mar-2025');" -> ('27Mar250028','070000178710','25760',(select max(to_number(i.premium_rcv_detail_code))+1 from ins_premium_det i),'25760','25760','02', '11000003','00','Request by Mr. Saqib Saleem 28-Mar-2025'); | H4: =F4&G4 -> insert into ins_premium_det (premium_rcv_code,assorted_code, rec_amount,premium_rcv_detail_code,remaining_amt, payrec, mode_code,coinsurance_code,class_cd,it_remarks) values('27Mar250028','070000178710','25760',(select max(to_number(i.premium_rcv_detail_code))+1 from ins_premium_det i),'25760','25760','02', '11000003','00','Request by Mr. Saqib Saleem 28-Mar-2025');
A5: KHI/HO/D/MO/PC COMP/C/108044/22/03/2025 | B5: =VLOOKUP(A5,policy!B:C,2,0) -> 070000178712 | C5: 24000 | D5: =ROUND(C5,0) -> 24000 | E5: 27Mar250028 | F5: ="insert into ins_premium_det (premium_rcv_code,assorted_code, rec_amount,premium_rcv_detail_code,remaining_amt, payrec, mode_code,coinsurance_code,class_cd,it_remarks) values" -> insert into ins_premium_det (premium_rcv_code,assorted_code, rec_amount,premium_rcv_detail_code,remaining_amt, payrec, mode_code,coinsurance_code,class_cd,it_remarks) values | G5: ="('"&E5&"','"&B5&"','"&D5&"',(select max(to_number(i.premium_rcv_detail_code))+1 from ins_premium_det i),'"&D5&"','"&D5&"','02', '11000003','00','Request by Mr. Saqib Saleem 28-Mar-2025');" -> ('27Mar250028','070000178712','24000',(select max(to_number(i.premium_rcv_detail_code))+1 from ins_premium_det i),'24000','24000','02', '11000003','00','Request by Mr. Saqib Saleem 28-Mar-2025'); | H5: =F5&G5 -> insert into ins_premium_det (premium_rcv_code,assorted_code, rec_amount,premium_rcv_detail_code,remaining_amt, payrec, mode_code,coinsurance_code,class_cd,it_remarks) values('27Mar250028','070000178712','24000',(select max(to_number(i.premium_rcv_detail_code))+1 from ins_premium_det i),'24000','24000','02', '11000003','00','Request by Mr. Saqib Saleem 28-Mar-2025');
A6: KHI/HO/D/MO/PC COMP/C/108044/30/03/2025 | B6: =VLOOKUP(A6,policy!B:C,2,0) -> 070000178720 | C6: 49680 | D6: =ROUND(C6,0) -> 49680 | E6: 27Mar250028 | F6: ="insert into ins_premium_det (premium_rcv_code,assorted_code, rec_amount,premium_rcv_detail_code,remaining_amt, payrec, mode_code,coinsurance_code,class_cd,it_remarks) values" -> insert into ins_premium_det (premium_rcv_code,assorted_code, rec_amount,premium_rcv_detail_code,remaining_amt, payrec, mode_code,coinsurance_code,class_cd,it_remarks) values | G6: ="('"&E6&"','"&B6&"','"&D6&"',(select max(to_number(i.premium_rcv_detail_code))+1 from ins_premium_det i),'"&D6&"','"&D6&"','02', '11000003','00','Request by Mr. Saqib Saleem 28-Mar-2025');" -> ('27Mar250028','070000178720','49680',(select max(to_number(i.premium_rcv_detail_code))+1 from ins_premium_det i),'49680','49680','02', '11000003','00','Request by Mr. Saqib Saleem 28-Mar-2025'); | H6: =F6&G6 -> insert into ins_premium_det (premium_rcv_code,assorted_code, rec_amount,premium_rcv_detail_code,remaining_amt, payrec, mode_code,coinsurance_code,class_cd,it_remarks) values('27Mar250028','070000178720','49680',(select max(to_number(i.premium_rcv_detail_code))+1 from ins_premium_det i),'49680','49680','02', '11000003','00','Request by Mr. Saqib Saleem 28-Mar-2025');
A7: KHI/HO/D/MO/PC COMP/C/106590/214/01/2025 | B7: =VLOOKUP(A7,policy!B:C,2,0) -> 070000174720 | C7: 41445 | D7: =ROUND(C7,0) -> 41445 | E7: 27Mar250028 | F7: ="insert into ins_premium_det (premium_rcv_code,assorted_code, rec_amount,premium_rcv_detail_code,remaining_amt, payrec, mode_code,coinsurance_code,class_cd,it_remarks) values" -> insert into ins_premium_det (premium_rcv_code,assorted_code, rec_amount,premium_rcv_detail_code,remaining_amt, payrec, mode_code,coinsurance_code,class_cd,it_remarks) values | G7: ="('"&E7&"','"&B7&"','"&D7&"',(select max(to_number(i.premium_rcv_detail_code))+1 from ins_premium_det i),'"&D7&"','"&D7&"','02', '11000003','00','Request by Mr. Saqib Saleem 28-Mar-2025');" -> ('27Mar250028','070000174720','41445',(select max(to_number(i.premium_rcv_detail_code))+1 from ins_premium_det i),'41445','41445','02', '11000003','00','Request by Mr. Saqib Saleem 28-Mar-2025'); | H7: =F7&G7 -> insert into ins_premium_det (premium_rcv_code,assorted_code, rec_amount,premium_rcv_detail_code,remaining_amt, payrec, mode_code,coinsurance_code,class_cd,it_remarks) values('27Mar250028','070000174720','41445',(select max(to_number(i.premium_rcv_detail_code))+1 from ins_premium_det i),'41445','41445','02', '11000003','00','Request by Mr. Saqib Saleem 28-Mar-2025');
A8: KHI/HO/D/MO/PC COMP/C/108044/32/03/2025 | B8: =VLOOKUP(A8,policy!B:C,2,0) -> 070000178722 | C8: 61815 | D8: =ROUND(C8,0) -> 61815 | E8: 27Mar250028 | F8: ="insert into ins_premium_det (premium_rcv_code,assorted_code, rec_amount,premium_rcv_detail_code,remaining_amt, payrec, mode_code,coinsurance_code,class_cd,it_remarks) values" -> insert into ins_premium_det (premium_rcv_code,assorted_code, rec_amount,premium_rcv_detail_code,remaining_amt, payrec, mode_code,coinsurance_code,class_cd,it_remarks) values | G8: ="('"&E8&"','"&B8&"','"&D8&"',(select max(to_number(i.premium_rcv_detail_code))+1 from ins_premium_det i),'"&D8&"','"&D8&"','02', '11000003','00','Request by Mr. Saqib Saleem 28-Mar-2025');" -> ('27Mar250028','070000178722','61815',(select max(to_number(i.premium_rcv_detail_code))+1 from ins_premium_det i),'61815','61815','02', '11000003','00','Request by Mr. Saqib Saleem 28-Mar-2025'); | H8: =F8&G8 -> insert into ins_premium_det (premium_rcv_code,assorted_code, rec_amount,premium_rcv_detail_code,remaining_amt, payrec, mode_code,coinsurance_code,class_cd,it_remarks) values('27Mar250028','070000178722','61815',(select max(to_number(i.premium_rcv_detail_code))+1 from ins_premium_det i),'61815','61815','02', '11000003','00','Request by Mr. Saqib Saleem 28-Mar-2025');
A9: KHI/HO/D/MO/PC COMP/P/108413/1/03/2025 | B9: =VLOOKUP(A9,policy!B:C,2,0) -> #N/A | E9: 27Mar250028 | F9: ="insert into ins_premium_det (premium_rcv_code,assorted_code, rec_amount,premium_rcv_detail_code,remaining_amt, payrec, mode_code,coinsurance_code,class_cd,it_remarks) values" -> insert into ins_premium_det (premium_rcv_code,assorted_code, rec_amount,premium_rcv_detail_code,remaining_amt, payrec, mode_code,coinsurance_code,class_cd,it_remarks) values | G9: ="('"&E9&"','"&B9&"','"&D9&"',(select max(to_number(i.premium_rcv_detail_code))+1 from ins_premium_det i),'"&D9&"','"&D9&"','02', '11000003','00','Request by Mr. Saqib Saleem 28-Mar-2025');" -> #N/A | H9: =F9&G9 -> #N/A
A10: KHI/HO/D/MO/PC COMP/C/106590/7/01/2025 | B10: =VLOOKUP(A10,policy!B:C,2,0) -> 070000174513 | C10: 23696 | D10: =ROUND(C10,0) -> 23696 | E10: 27Mar250028 | F10: ="insert into ins_premium_det (premium_rcv_code,assorted_code, rec_amount,premium_rcv_detail_code,remaining_amt, payrec, mode_code,coinsurance_code,class_cd,it_remarks) values" -> insert into ins_premium_det (premium_rcv_code,assorted_code, rec_amount,premium_rcv_detail_code,remaining_amt, payrec, mode_code,coinsurance_code,class_cd,it_remarks) values | G10: ="('"&E10&"','"&B10&"','"&D10&"',(select max(to_number(i.premium_rcv_detail_code))+1 from ins_premium_det i),'"&D10&"','"&D10&"','02', '11000003','00','Request by Mr. Saqib Saleem 28-Mar-2025');" -> ('27Mar250028','070000174513','23696',(select max(to_number(i.premium_rcv_detail_code))+1 from ins_premium_det i),'23696','23696','02', '11000003','00','Request by Mr. Saqib Saleem 28-Mar-2025'); | H10: =F10&G10 -> insert into ins_premium_det (premium_rcv_code,assorted_code, rec_amount,premium_rcv_detail_code,remaining_amt, payrec, mode_code,coinsurance_code,class_cd,it_remarks) values('27Mar250028','070000174513','23696',(select max(to_number(i.premium_rcv_detail_code))+1 from ins_premium_det i),'23696','23696','02', '11000003','00','Request by Mr. Saqib Saleem 28-Mar-2025');
A11: KHI/HO/D/MO/PC COMP/C/106590/197/01/2025 | B11: =VLOOKUP(A11,policy!B:C,2,0) -> 070000174703 | C11: 76993 | D11: =ROUND(C11,0) -> 76993 | E11: 27Mar250028 | F11: ="insert into ins_premium_det (premium_rcv_code,assorted_code, rec_amount,premium_rcv_detail_code,remaining_amt, payrec, mode_code,coinsurance_code,class_cd,it_remarks) values" -> insert into ins_premium_det (premium_rcv_code,assorted_code, rec_amount,premium_rcv_detail_code,remaining_amt, payrec, mode_code,coinsurance_code,class_cd,it_remarks) values | G11: ="('"&E11&"','"&B11&"','"&D11&"',(select max(to_number(i.premium_rcv_detail_code))+1 from ins_premium_det i),'"&D11&"','"&D11&"','02', '11000003','00','Request by Mr. Saqib Saleem 28-Mar-2025');" -> ('27Mar250028','070000174703','76993',(select max(to_number(i.premium_rcv_detail_code))+1 from ins_premium_det i),'76993','76993','02', '11000003','00','Request by Mr. Saqib Saleem 28-Mar-2025'); | H11: =F11&G11 -> insert into ins_premium_det (premium_rcv_code,assorted_code, rec_amount,premium_rcv_detail_code,remaining_amt, payrec, mode_code,coinsurance_code,class_cd,it_remarks) values('27Mar250028','070000174703','76993',(select max(to_number(i.premium_rcv_detail_code))+1 from ins_premium_det i),'76993','76993','02', '11000003','00','Request by Mr. Saqib Saleem 28-Mar-2025');
A12: KHI/HO/D/MO/PC COMP/C/106590/200/01/2025 | B12: =VLOOKUP(A12,policy!B:C,2,0) -> 070000174706 | C12: 32745 | D12: =ROUND(C12,0) -> 32745 | E12: 27Mar250028 | F12: ="insert into ins_premium_det (premium_rcv_code,assorted_code, rec_amount,premium_rcv_detail_code,remaining_amt, payrec, mode_code,coinsurance_code,class_cd,it_remarks) values" -> insert into ins_premium_det (premium_rcv_code,assorted_code, rec_amount,premium_rcv_detail_code,remaining_amt, payrec, mode_code,coinsurance_code,class_cd,it_remarks) values | G12: ="('"&E12&"','"&B12&"','"&D12&"',(select max(to_number(i.premium_rcv_detail_code))+1 from ins_premium_det i),'"&D12&"','"&D12&"','02', '11000003','00','Request by Mr. Saqib Saleem 28-Mar-2025');" -> ('27Mar250028','070000174706','32745',(select max(to_number(i.premium_rcv_detail_code))+1 from ins_premium_det i),'32745','32745','02', '11000003','00','Request by Mr. Saqib Saleem 28-Mar-2025'); | H12: =F12&G12 -> insert into ins_premium_det (premium_rcv_code,assorted_code, rec_amount,premium_rcv_detail_code,remaining_amt, payrec, mode_code,coinsurance_code,class_cd,it_remarks) values('27Mar250028','070000174706','32745',(select max(to_number(i.premium_rcv_detail_code))+1 from ins_premium_det i),'32745','32745','02', '11000003','00','Request by Mr. Saqib Saleem 28-Mar-2025');
A13: KHI/HO/D/MO/PC COMP/C/106590/268/01/2025 | B13: =VLOOKUP(A13,policy!B:C,2,0) -> 070000174774 | C13: 68410 | D13: =ROUND(C13,0) -> 68410 | E13: 27Mar250028 | F13: ="insert into ins_premium_det (premium_rcv_code,assorted_code, rec_amount,premium_rcv_detail_code,remaining_amt, payrec, mode_code,coinsurance_code,class_cd,it_remarks) values" -> insert into ins_premium_det (premium_rcv_code,assorted_code, rec_amount,premium_rcv_detail_code,remaining_amt, payrec, mode_code,coinsurance_code,class_cd,it_remarks) values | G13: ="('"&E13&"','"&B13&"','"&D13&"',(select max(to_number(i.premium_rcv_detail_code))+1 from ins_premium_det i),'"&D13&"','"&D13&"','02', '11000003','00','Request by Mr. Saqib Saleem 28-Mar-2025');" -> ('27Mar250028','070000174774','68410',(select max(to_number(i.premium_rcv_detail_code))+1 from ins_premium_det i),'68410','68410','02', '11000003','00','Request by Mr. Saqib Saleem 28-Mar-2025'); | H13: =F13&G13 -> insert into ins_premium_det (premium_rcv_code,assorted_code, rec_amount,premium_rcv_detail_code,remaining_amt, payrec, mode_code,coinsurance_code,class_cd,it_remarks) values('27Mar250028','070000174774','68410',(select max(to_number(i.premium_rcv_detail_code))+1 from ins_premium_det i),'68410','68410','02', '11000003','00','Request by Mr. Saqib Saleem 28-Mar-2025');
A14: KHI/HO/D/MO/PC COMP/C/108044/39/03/2025 | B14: =VLOOKUP(A14,policy!B:C,2,0) -> 070000178729 | C14: 39600 | D14: =ROUND(C14,0) -> 39600 | E14: 27Mar250028 | F14: ="insert into ins_premium_det (premium_rcv_code,assorted_code, rec_amount,premium_rcv_detail_code,remaining_amt, payrec, mode_code,coinsurance_code,class_cd,it_remarks) values" -> insert into ins_premium_det (premium_rcv_code,assorted_code, rec_amount,premium_rcv_detail_code,remaining_amt, payrec, mode_code,coinsurance_code,class_cd,it_remarks) values | G14: ="('"&E14&"','"&B14&"','"&D14&"',(select max(to_number(i.premium_rcv_detail_code))+1 from ins_premium_det i),'"&D14&"','"&D14&"','02', '11000003','00','Request by Mr. Saqib Saleem 28-Mar-2025');" -> ('27Mar250028','070000178729','39600',(select max(to_number(i.premium_rcv_detail_code))+1 from ins_premium_det i),'39600','39600','02', '11000003','00','Request by Mr. Saqib Saleem 28-Mar-2025'); | H14: =F14&G14 -> insert into ins_premium_det (premium_rcv_code,assorted_code, rec_amount,premium_rcv_detail_code,remaining_amt, payrec, mode_code,coinsurance_code,class_cd,it_remarks) values('27Mar250028','070000178729','39600',(select max(to_number(i.premium_rcv_detail_code))+1 from ins_premium_det i),'39600','39600','02', '11000003','00','Request by Mr. Saqib Saleem 28-Mar-2025');
A15: KHI/HO/D/MO/PC COMP/C/106590/281/01/2025 | B15: =VLOOKUP(A15,policy!B:C,2,0) -> 070000174787 | C15: 24825 | D15: =ROUND(C15,0) -> 24825 | E15: 27Mar250028 | F15: ="insert into ins_premium_det (premium_rcv_code,assorted_code, rec_amount,premium_rcv_detail_code,remaining_amt, payrec, mode_code,coinsurance_code,class_cd,it_remarks) values" -> insert into ins_premium_det (premium_rcv_code,assorted_code, rec_amount,premium_rcv_detail_code,remaining_amt, payrec, mode_code,coinsurance_code,class_cd,it_remarks) values | G15: ="('"&E15&"','"&B15&"','"&D15&"',(select max(to_number(i.premium_rcv_detail_code))+1 from ins_premium_det i),'"&D15&"','"&D15&"','02', '11000003','00','Request by Mr. Saqib Saleem 28-Mar-2025');" -> ('27Mar250028','070000174787','24825',(select max(to_number(i.premium_rcv_detail_code))+1 from ins_premium_det i),'24825','24825','02', '11000003','00','Request by Mr. Saqib Saleem 28-Mar-2025'); | H15: =F15&G15 -> insert into ins_premium_det (premium_rcv_code,assorted_code, rec_amount,premium_rcv_detail_code,remaining_amt, payrec, mode_code,coinsurance_code,class_cd,it_remarks) values('27Mar250028','070000174787','24825',(select max(to_number(i.premium_rcv_detail_code))+1 from ins_premium_det i),'24825','24825','02', '11000003','00','Request by Mr. Saqib Saleem 28-Mar-2025');
A16: KHI/HO/D/MO/PC COMP/C/106590/3/01/2025 | B16: =VLOOKUP(A16,policy!B:C,2,0) -> 070000174509 | C16: 34781 | D16: =ROUND(C16,0) -> 34781 | E16: 27Mar250028 | F16: ="insert into ins_premium_det (premium_rcv_code,assorted_code, rec_amount,premium_rcv_detail_code,remaining_amt, payrec, mode_code,coinsurance_code,class_cd,it_remarks) values" -> insert into ins_premium_det (premium_rcv_code,assorted_code, rec_amount,premium_rcv_detail_code,remaining_amt, payrec, mode_code,coinsurance_code,class_cd,it_remarks) values | G16: ="('"&E16&"','"&B16&"','"&D16&"',(select max(to_number(i.premium_rcv_detail_code))+1 from ins_premium_det i),'"&D16&"','"&D16&"','02', '11000003','00','Request by Mr. Saqib Saleem 28-Mar-2025');" -> ('27Mar250028','070000174509','34781',(select max(to_number(i.premium_rcv_detail_code))+1 from ins_premium_det i),'34781','34781','02', '11000003','00','Request by Mr. Saqib Saleem 28-Mar-2025'); | H16: =F16&G16 -> insert into ins_premium_det (premium_rcv_code,assorted_code, rec_amount,premium_rcv_detail_code,remaining_amt, payrec, mode_code,coinsurance_code,class_cd,it_remarks) values('27Mar250028','070000174509','34781',(select max(to_number(i.premium_rcv_detail_code))+1 from ins_premium_det i),'34781','34781','02', '11000003','00','Request by Mr. Saqib Saleem 28-Mar-2025');
A17: KHI/HO/D/MO/PC COMP/C/108044/42/03/2025 | B17: =VLOOKUP(A17,policy!B:C,2,0) -> 070000178732 | C17: 21360 | D17: =ROUND(C17,0) -> 21360 | E17: 27Mar250028 | F17: ="insert into ins_premium_det (premium_rcv_code,assorted_code, rec_amount,premium_rcv_detail_code,remaining_amt, payrec, mode_code,coinsurance_code,class_cd,it_remarks) values" -> insert into ins_premium_det (premium_rcv_code,assorted_code, rec_amount,premium_rcv_detail_code,remaining_amt, payrec, mode_code,coinsurance_code,class_cd,it_remarks) values | G17: ="('"&E17&"','"&B17&"','"&D17&"',(select max(to_number(i.premium_rcv_detail_code))+1 from ins_premium_det i),'"&D17&"','"&D17&"','02', '11000003','00','Request by Mr. Saqib Saleem 28-Mar-2025');" -> ('27Mar250028','070000178732','21360',(select max(to_number(i.premium_rcv_detail_code))+1 from ins_premium_det i),'21360','21360','02', '11000003','00','Request by Mr. Saqib Saleem 28-Mar-2025'); | H17: =F17&G17 -> insert into ins_premium_det (premium_rcv_code,assorted_code, rec_amount,premium_rcv_detail_code,remaining_amt, payrec, mode_code,coinsurance_code,class_cd,it_remarks) values('27Mar250028','070000178732','21360',(select max(to_number(i.premium_rcv_detail_code))+1 from ins_premium_det i),'21360','21360','02', '11000003','00','Request by Mr. Saqib Saleem 28-Mar-2025');
A18: KHI/HO/D/MO/PC COMP/C/106590/5/01/2025 | B18: =VLOOKUP(A18,policy!B:C,2,0) -> 070000174511 | C18: 18647 | D18: =ROUND(C18,0) -> 18647 | E18: 27Mar250028 | F18: ="insert into ins_premium_det (premium_rcv_code,assorted_code, rec_amount,premium_rcv_detail_code,remaining_amt, payrec, mode_code,coinsurance_code,class_cd,it_remarks) values" -> insert into ins_premium_det (premium_rcv_code,assorted_code, rec_amount,premium_rcv_detail_code,remaining_amt, payrec, mode_code,coinsurance_code,class_cd,it_remarks) values | G18: ="('"&E18&"','"&B18&"','"&D18&"',(select max(to_number(i.premium_rcv_detail_code))+1 from ins_premium_det i),'"&D18&"','"&D18&"','02', '11000003','00','Request by Mr. Saqib Saleem 28-Mar-2025');" -> ('27Mar250028','070000174511','18647',(select max(to_number(i.premium_rcv_detail_code))+1 from ins_premium_det i),'18647','18647','02', '11000003','00','Request by Mr. Saqib Saleem 28-Mar-2025'); | H18: =F18&G18 -> insert into ins_premium_det (premium_rcv_code,assorted_code, rec_amount,premium_rcv_detail_code,remaining_amt, payrec, mode_code,coinsurance_code,class_cd,it_remarks) values('27Mar250028','070000174511','18647',(select max(to_number(i.premium_rcv_detail_code))+1 from ins_premium_det i),'18647','18647','02', '11000003','00','Request by Mr. Saqib Saleem 28-Mar-2025');
A19: KHI/HO/D/MO/PC COMP/C/106590/6/01/2025 | B19: =VLOOKUP(A19,policy!B:C,2,0) -> 070000174512 | C19: 39852 | D19: =ROUND(C19,0) -> 39852 | E19: 27Mar250028 | F19: ="insert into ins_premium_det (premium_rcv_code,assorted_code, rec_amount,premium_rcv_detail_code,remaining_amt, payrec, mode_code,coinsurance_code,class_cd,it_remarks) values" -> insert into ins_premium_det (premium_rcv_code,assorted_code, rec_amount,premium_rcv_detail_code,remaining_amt, payrec, mode_code,coinsurance_code,class_cd,it_remarks) values | G19: ="('"&E19&"','"&B19&"','"&D19&"',(select max(to_number(i.premium_rcv_detail_code))+1 from ins_premium_det i),'"&D19&"','"&D19&"','02', '11000003','00','Request by Mr. Saqib Saleem 28-Mar-2025');" -> ('27Mar250028','070000174512','39852',(select max(to_number(i.premium_rcv_detail_code))+1 from ins_premium_det i),'39852','39852','02', '11000003','00','Request by Mr. Saqib Saleem 28-Mar-2025'); | H19: =F19&G19 -> insert into ins_premium_det (premium_rcv_code,assorted_code, rec_amount,premium_rcv_detail_code,remaining_amt, payrec, mode_code,coinsurance_code,class_cd,it_remarks) values('27Mar250028','070000174512','39852',(select max(to_number(i.premium_rcv_detail_code))+1 from ins_premium_det i),'39852','39852','02', '11000003','00','Request by Mr. Saqib Saleem 28-Mar-2025');
A20: KHI/HO/D/MO/PC COMP/P/108413/2/03/2025 | B20: =VLOOKUP(A20,policy!B:C,2,0) -> #N/A | E20: 27Mar250028 | F20: ="insert into ins_premium_det (premium_rcv_code,assorted_code, rec_amount,premium_rcv_detail_code,remaining_amt, payrec, mode_code,coinsurance_code,class_cd,it_remarks) values" -> insert into ins_premium_det (premium_rcv_code,assorted_code, rec_amount,premium_rcv_detail_code,remaining_amt, payrec, mode_code,coinsurance_code,class_cd,it_remarks) values | G20: ="('"&E20&"','"&B20&"','"&D20&"',(select max(to_number(i.premium_rcv_detail_code))+1 from ins_premium_det i),'"&D20&"','"&D20&"','02', '11000003','00','Request by Mr. Saqib Saleem 28-Mar-2025');" -> #N/A | H20: =F20&G20 -> #N/A
A21: KHI/HO/D/MO/PC COMP/P/108413/3/03/2025 | B21: =VLOOKUP(A21,policy!B:C,2,0) -> #N/A | E21: 27Mar250028 | F21: ="insert into ins_premium_det (premium_rcv_code,assorted_code, rec_amount,premium_rcv_detail_code,remaining_amt, payrec, mode_code,coinsurance_code,class_cd,it_remarks) values" -> insert into ins_premium_det (premium_rcv_code,assorted_code, rec_amount,premium_rcv_detail_code,remaining_amt, payrec, mode_code,coinsurance_code,class_cd,it_remarks) values | G21: ="('"&E21&"','"&B21&"','"&D21&"',(select max(to_number(i.premium_rcv_detail_code))+1 from ins_premium_det i),'"&D21&"','"&D21&"','02', '11000003','00','Request by Mr. Saqib Saleem 28-Mar-2025');" -> #N/A | H21: =F21&G21 -> #N/A
A22: KHI/HO/D/MO/PC COMP/P/108413/4/03/2025 | B22: =VLOOKUP(A22,policy!B:C,2,0) -> #N/A | E22: 27Mar250028 | F22: ="insert into ins_premium_det (premium_rcv_code,assorted_code, rec_amount,premium_rcv_detail_code,remaining_amt, payrec, mode_code,coinsurance_code,class_cd,it_remarks) values" -> insert into ins_premium_det (premium_rcv_code,assorted_code, rec_amount,premium_rcv_detail_code,remaining_amt, payrec, mode_code,coinsurance_code,class_cd,it_remarks) values | G22: ="('"&E22&"','"&B22&"','"&D22&"',(select max(to_number(i.premium_rcv_detail_code))+1 from ins_premium_det i),'"&D22&"','"&D22&"','02', '11000003','00','Request by Mr. Saqib Saleem 28-Mar-2025');" -> #N/A | H22: =F22&G22 -> #N/A
