Workbook

Sheet PAY ON MONTH OF FEB & MAR-2025
A1: Contract No. | B1: Customer Name | C1: CNIC No. | D1: Engine No. | E1: Chassis No. | F1: Premium | G1: ACC Number | H1: ACC Branch | I1: INSURANCE CO. | J1: Policy # | K1: Tms Prem | L1: Difference | M1: End. #
A2: 9976AD1243310001 | B2: MOHSIN KHALID | C2: 42101-6893856-7 | D2: 6R335988 | E2: H1236061 | F2: 60900 | G2: 0006437055 | H2: 106 | I2: SALAAM TAKAFUL PAKISTAN | J2: KHI/HO/D/MO/PC COMP/C/105332/102/01/2025 | K2: 60900 | L2: =F2-K2 -> 0
A3: 9976AD1243340003 | B3: WAQAS AHMED | C3: 42101-3861248-5 | D3: 1025691 | E3: 00208361 | F3: 94380 | G3: 0006437055 | H3: 106 | I3: SALAAM TAKAFUL PAKISTAN | J3: KHI/HO/D/MO/PC COMP/C/107044/18/02/2025 | K3: 94380 | L3: =F3-K3 -> 0
A4: 9976AD1243350001 | B4: SHAHAB UD DIN | C4: 33100-2695781-3 | D4: 1025871 | E4: 208533 | F4: 82583 | G4: 0006437055 | H4: 106 | I4: SALAAM TAKAFUL PAKISTAN | J4: KHI/HO/D/MO/PC COMP/C/107044/20/02/2025 | K4: 82583 | L4: =F4-K4 -> 0
A5: 9976AD1243650003 | B5: MUHAMMAD AMIR | C5: 42000-0525169-3 | D5: 330089 | E5: 1230119 | F5: 54140 | G5: 0006437055 | H5: 106 | I5: SALAAM TAKAFUL PAKISTAN | J5: KHI/HO/D/MO/PC COMP/C/105332/92/01/2025 | K5: 54140 | L5: =F5-K5 -> 0
A6: 9976AD1250020002 | B6: NAUMAN SHAHZAD QURESHI | C6: 91509-0156584-5 | D6: 341763 | E6: 1241558 | F6: 53288 | G6: 0006437055 | H6: 106 | I6: SALAAM TAKAFUL PAKISTAN | J6: KHI/HO/D/MO/PC COMP/C/107830/13/03/2025 | K6: 53288 | L6: =F6-K6 -> 0
A7: 9976AD1250070002 | B7: MUHAMMAD RAMEEZ ZAHID | C7: 42301-4610830-3 | D7: Q109561 | E7: 6087073 | F7: 131440 | G7: 0006437055 | H7: 106 | I7: SALAAM TAKAFUL PAKISTAN | J7: KHI/HO/D/MO/PC COMP/C/107044/33/02/2025 | K7: 131440 | L7: =F7-K7 -> 0
A8: 9976AD1250090005 | B8: MUHAMMAD AWAIS ABID | C8: 35202-9944831-3 | D8: 523359 | E8: 1000415 | F8: 91480 | G8: 0006437055 | H8: 106 | I8: SALAAM TAKAFUL PAKISTAN | J8: KHI/HO/D/MO/PC COMP/C/107044/3/02/2025 | K8: 91480 | L8: =F8-K8 -> 0
A9: 9976AD1250170001 | B9: FARYAD ALI | C9: 33100-7816923-9 | D9: Q372623 | E9: 7071864 | F9: 152620 | G9: 0006437055 | H9: 106 | I9: SALAAM TAKAFUL PAKISTAN | J9: KHI/HO/D/MO/PC COMP/C/107830/5/03/2025 | K9: 152620 | L9: =F9-K9 -> 0
A10: 9976AD1250450007 | B10: MUHAMMAD SOHAIL | C10: 33102-5807711-5 | D10: 51032075 | E10: 049606 | F10: 94380 | G10: 0006437055 | H10: 106 | I10: SALAAM TAKAFUL PAKISTAN | J10: KHI/HO/D/MO/PC COMP/C/107044/45/02/2025 | K10: 82583 | L10: =F10-K10 -> 11797 | M10: KHI/HO/D/MO/PC COMP/E/58990/00045/03/2025
A11: 9976AD2243610002 | B11: ABDUL RAUF | C11: 42301-0988438-9 | D11: 336566 | E11: 1236492 | F11: 60900 | G11: 0006437055 | H11: 106 | I11: SALAAM TAKAFUL PAKISTAN | J11: KHI/HO/D/MO/PC COMP/C/107044/44/02/2025 | K11: 60900 | L11: =F11-K11 -> 0
A12: 9976AD2250230002 | B12: MUHAMMAD ADNAN | C12: 33100-5309327-7 | D12: 2A72689 | E12: 9522906 | F12: 128020 | G12: 0006437055 | H12: 106 | I12: SALAAM TAKAFUL PAKISTAN | J12: KHI/HO/D/MO/PC COMP/C/107044/2/02/2025 | K12: 128020 | L12: =F12-K12 -> 0
A13: 9976AD2250280001 | B13: FARRUKH JAMAL | C13: 42000-0557097-3 | D13: 383118 | E13: 1002464 | F13: 177980 | G13: 0006437055 | H13: 106 | I13: SALAAM TAKAFUL PAKISTAN | J13: KHI/HO/D/MO/PC COMP/C/107830/11/03/2025 | K13: 177980 | L13: =F13-K13 -> 0
A14: 9976AD2250310002 | B14: IMRAN BIN MURTAZA | C14: 35201-1604546-3 | D14: 24499066106 | E14: 2013121 | F14: 161390 | G14: 0006437055 | H14: 106 | I14: SALAAM TAKAFUL PAKISTAN | J14: KHI/HO/D/MO/PC COMP/C/107044/1/02/2025 | K14: 141216 | L14: =F14-K14 -> 20174 | M14: KHI/HO/D/MO/PC COMP/E/58990/00001/03/2025
A15: 9976AD2250310005 | B15: ZUBAIR IQBAL | C15: 32303-9130100-5 | D15: 364387 | E15: 218986 | F15: 161780 | G15: 0006437055 | H15: 106 | I15: SALAAM TAKAFUL PAKISTAN | J15: KHI/HO/D/MO/PC COMP/C/107044/24/02/2025 | K15: 161780 | L15: =F15-K15 -> 0
A16: 9976AP1250300057 | B16: ADNAN HUSSAIN MIR | C16: 54303-4090283-1 | D16: 092039 | E16: 6069578 | F16: 120000 | G16: 0006437055 | H16: 106 | I16: SALAAM TAKAFUL PAKISTAN | J16: KHI/HO/D/MO/PC COMP/C/105332/115/01/2025 | K16: 120000 | L16: =F16-K16 -> 0
A17: 9976AP1250430008 | B17: MUHAMMAD MUNIR | C17: 34602-7507574-3 | D17: 51031235 | E17: 048521 | F17: 82583 | G17: 0006437055 | H17: 106 | I17: SALAAM TAKAFUL PAKISTAN | J17: KHI/HO/D/MO/PC COMP/C/107044/11/02/2025 | K17: 82583 | L17: =F17-K17 -> 0
A18: 9976AP1250430009 | B18: JAVED ASHRAF | C18: 35201-9565818-1 | D18: 51030926 | E18: 048258 | F18: 82583 | G18: 0006437055 | H18: 106 | I18: SALAAM TAKAFUL PAKISTAN | J18: KHI/HO/D/MO/PC COMP/C/107044/14/02/2025 | K18: 82583 | L18: =F18-K18 -> 0
A19: 9976AP1250440019 | B19: ZEESHAN ALI | C19: 34302-8345088-9 | D19: 17542977 | E19: 266642 | F19: 56875 | G19: 0006437055 | H19: 106 | I19: SALAAM TAKAFUL PAKISTAN | J19: KHI/HO/D/MO/PC COMP/C/107044/9/02/2025 | K19: 56875 | L19: =F19-K19 -> 0
A20: 9976AP1250440022 | B20: MUHAMMAD ARSHAD | C20: 33100-0729014-5 | D20: Q048861 | E20: 6026330 | F20: 77000 | G20: 0006437055 | H20: 106 | I20: SALAAM TAKAFUL PAKISTAN | J20: KHI/HO/D/MO/PC COMP/C/107044/15/02/2025 | K20: 77000 | L20: =F20-K20 -> 0
A21: 9976AP1250490012 | B21: MUHAMMAD WAQAS RAFIQUE | C21: 38303-7473710-5 | D21: 1025881 | E21: 00208544 | F21: 82583 | G21: 0006437055 | H21: 106 | I21: SALAAM TAKAFUL PAKISTAN | J21: KHI/HO/D/MO/PC COMP/C/107044/21/02/2025 | K21: 82583 | L21: =F21-K21 -> 0
A22: 9976AP1250550041 | B22: SHAMA KANWAL | C22: 32203-2398377-2 | D22: 118429 | E22: 10018417 | F22: 37625 | G22: 0006437055 | H22: 106 | I22: SALAAM TAKAFUL PAKISTAN | J22: KHI/HO/D/MO/PC COMP/C/107044/30/02/2025 | K22: 37625 | L22: =F22-K22 -> 0
A23: 9976AP1250550051 | B23: MAIRA TAYYAB | C23: 36601-6374578-0 | D23: 17460194 | E23: 202992 | F23: 50750 | G23: 0006437055 | H23: 106 | I23: SALAAM TAKAFUL PAKISTAN | J23: KHI/HO/D/MO/PC COMP/C/107044/37/02/2025 | K23: 50750 | L23: =F23-K23 -> 0
A24: 9976AP1250570007 | B24: KHAWAJA MUHAMMAD MOAZZAM | C24: 33100-9302999-7 | D24: 340782 | E24: 1241224 | F24: 53288 | G24: 0006437055 | H24: 106 | I24: SALAAM TAKAFUL PAKISTAN | J24: KHI/HO/D/MO/PC COMP/C/107044/34/02/2025 | K24: 53288 | L24: =F24-K24 -> 0
A25: 9976AP1250580018 | B25: MUHAMMAD USMAN | C25: 33100-8611256-1 | D25: 695103 | E25: 01233616 | F25: 22750 | G25: 0006437055 | H25: 106 | I25: SALAAM TAKAFUL PAKISTAN | J25: KHI/HO/D/MO/PC COMP/C/107044/46/02/2025 | K25: 22750 | L25: =F25-K25 -> 0
A26: 9976AP1250580019 | B26: ALI SIKANDAR | C26: 33100-2472616-9 | D26: 377030 | E26: 1002138 | F26: 143483 | G26: 0006437055 | H26: 106 | I26: SALAAM TAKAFUL PAKISTAN | J26: KHI/HO/D/MO/PC COMP/C/107044/36/02/2025 | K26: 143483 | L26: =F26-K26 -> 0
... A64: 997AFRA243330004 | B64: KHIZAR ANSAR | C64: 41302-3587668-9 | D64: 1025775 | E64: 00208453 | F64: 94380 | G64: 0006437055 | H64: 106 | I64: SALAAM TAKAFUL PAKISTAN | J64: KHI/HO/D/MO/PC COMP/C/107044/48/02/2025 | K64: 94380 | L64: =F64-K64 -> 0
A65: 997AFRA243350008 | B65: ZEESHAN AHMED ZIAEE | C65: 42101-6085357-3 | D65: 1025403 | E65: 208073 | F65: 94380 | G65: 0006437055 | H65: 106 | I65: SALAAM TAKAFUL PAKISTAN | J65: KHI/HO/D/MO/PC COMP/C/107044/10/02/2025 | K65: 82583 | L65: =F65-K65 -> 11797 | M65: KHI/HO/D/MO/PC COMP/E/58990/00010/03/2025
A66: 997AFRA243510003 | B66: AWAIS QAISAR | C66: 33100-0525595-5 | D66: 2A72822 | E66: 7049945 | F66: 95200 | G66: 0006437055 | H66: 106 | I66: SALAAM TAKAFUL PAKISTAN | J66: KHI/HO/D/MO/PC COMP/C/107044/13/02/2025 | K66: 95200 | L66: =F66-K66 -> 0
A67: 997AFRA243590002 | B67: NAJAM UDDIN SHAIKH | C67: 45202-2470647-5 | D67: 340399 | E67: 1240253 | F67: 60900 | G67: 0006437055 | H67: 106 | I67: SALAAM TAKAFUL PAKISTAN | J67: KHI/HO/D/MO/PC COMP/C/107044/53/02/2025 | K67: 53288 | L67: =F67-K67 -> 7612 | M67: KHI/HO/D/MO/PC COMP/E/58990/00053/03/2025
A68: 997AFRA243590004 | B68: MUHAMMAD HASSAN KHAN | C68: 42201-5464188-3 | D68: 51030632 | E68: 047861 | F68: 94380 | G68: 0006437055 | H68: 106 | I68: SALAAM TAKAFUL PAKISTAN | J68: KHI/HO/D/MO/PC COMP/C/107044/4/02/2025 | K68: 94380 | L68: =F68-K68 -> 0
A69: 997AFRA243590005 | B69: MUHAMMAD MUTBASSAM AHMAD | C69: 35404-9028426-3 | D69: 523400 | E69: 1000368 | F69: 80045 | G69: 0006437055 | H69: 106 | I69: SALAAM TAKAFUL PAKISTAN | J69: KHI/HO/D/MO/PC COMP/C/107044/5/02/2025 | K69: 80045 | L69: =F69-K69 -> 0
A70: 997AFRA243650002 | B70: MOHAMMAD KAZIM RAZA | C70: 90403-0116242-3 | D70: 1029488 | E70: 046341 | F70: 94380 | G70: 0006437055 | H70: 106 | I70: SALAAM TAKAFUL PAKISTAN | J70: KHI/HO/D/MO/PC COMP/C/105332/65/01/2025 | K70: 94380 | L70: =F70-K70 -> 0
A71: 997AFRA250150001 | B71: FAIZAN SHERGILL | C71: 13101-5150745-3 | D71: 51031731 | E71: 049191 | F71: 96740 | G71: 0006437055 | H71: 106 | I71: SALAAM TAKAFUL PAKISTAN | J71: KHI/HO/D/MO/PC COMP/C/107830/1/03/2025 | K71: 96740 | L71: =F71-K71 -> 0
A72: 997AFRA250290001 | B72: MUHAMMAD TALHA KHAN | C72: 61101-0209256-3 | D72: 25B4596 | E72: 04603406W | F72: 37000 | G72: 0006437055 | H72: 106 | I72: SALAAM TAKAFUL PAKISTAN | J72: KHI/HO/D/MO/PC COMP/C/107830/8/03/2025 | K72: 37000 | L72: =F72-K72 -> 0
A73: 997AFRR250430008 | B73: SAMAD AYUB KHAN | C73: 35202-5215024-7 | D73: 453481 | E73: 600316 | F73: 170135 | G73: 0006437055 | H73: 106 | I73: SALAAM TAKAFUL PAKISTAN | J73: KHI/HO/D/MO/PC COMP/C/107044/6/02/2025 | K73: 170135 | L73: =F73-K73 -> 0
A74: 997AFRR250430010 | B74: SAJID JAVID | C74: 33100-2337466-1 | D74: 17524485 | E74: 241620 | F74: 64750 | G74: 0006437055 | H74: 106 | I74: SALAAM TAKAFUL PAKISTAN | J74: KHI/HO/D/MO/PC COMP/C/107044/16/02/2025 | K74: 64750 | L74: =F74-K74 -> 0
A75: 997AFRR250450004 | B75: MUHAMMAD MEHBOOB | C75: 33100-1279207-3 | D75: 503784 | E75: 1002319 | F75: 67358 | G75: 0006437055 | H75: 106 | I75: SALAAM TAKAFUL PAKISTAN | J75: KHI/HO/D/MO/PC COMP/C/107044/17/02/2025 | K75: 67358 | L75: =F75-K75 -> 0
A76: 997AFRR250480004 | B76: NAVEEDA ANWAR | C76: 33100-0886824-6 | D76: 81014973 | E76: 035366 | F76: 91000 | G76: 0006437055 | H76: 106 | I76: SALAAM TAKAFUL PAKISTAN | J76: KHI/HO/D/MO/PC COMP/C/107044/22/02/2025 | K76: 91000 | L76: =F76-K76 -> 0
A77: 997AFRR250490012 | B77: MUHAMMAD IRFAN AKRAM | C77: 38401-4988211-9 | D77: 136728 | E77: 10036730 | F77: 35000 | G77: 0006437055 | H77: 106 | I77: SALAAM TAKAFUL PAKISTAN | J77: KHI/HO/D/MO/PC COMP/C/107044/25/02/2025 | K77: 35000 | L77: =F77-K77 -> 0
...

Sheet working
A1: POLICY NO. | B1: Assorted_code | D1: Premium | E1: 27Mar250025
A2: KHI/HO/D/MO/PC COMP/C/105332/102/01/2025 | B2: =VLOOKUP(A2,policy!B:C,2,) -> 070000174986 | C2: 60900 | D2: =ROUND(C2,0) -> 60900 | E2: 27Mar250025 | F2: ="insert into ins_premium_det (premium_rcv_code,assorted_code, rec_amount,premium_rcv_detail_code,remaining_amt, payrec, mode_code,coinsurance_code,class_cd,it_remarks) values" -> insert into ins_premium_det (premium_rcv_code,assorted_code, rec_amount,premium_rcv_detail_code,remaining_amt, payrec, mode_code,coinsurance_code,class_cd,it_remarks) values | G2: ="('"&E2&"','"&B2&"','"&D2&"',(select max(to_number(i.premium_rcv_detail_code))+1 from ins_premium_det i),'"&D2&"','"&D2&"','02', '11000003','00','Request by Mr. Saqib Saleem 27-Mar-2025');" -> ('27Mar250025','070000174986','60900',(select max(to_number(i.premium_rcv_detail_code))+1 from ins_premium_det i),'60900','60900','02', '11000003','00','Request by Mr. Saqib Saleem 27-Mar-2025'); | H2: =F2&G2 -> insert into ins_premium_det (premium_rcv_code,assorted_code, rec_amount,premium_rcv_detail_code,remaining_amt, payrec, mode_code,coinsurance_code,class_cd,it_remarks) values('27Mar250025','070000174986','60900',(select max(to_number(i.premium_rcv_detail_code))+1 from ins_premium_det i),'60900','60900','02', '11000003','00','Request by Mr. Saqib Saleem 27-Mar-2025');
A3: KHI/HO/D/MO/PC COMP/C/107044/18/02/2025 | B3: =VLOOKUP(A3,policy!B:C,2,) -> 070000176611 | C3: 94380 | D3: =ROUND(C3,0) -> 94380 | E3: 27Mar250025 | F3: ="insert into ins_premium_det (premium_rcv_code,assorted_code, rec_amount,premium_rcv_detail_code,remaining_amt, payrec, mode_code,coinsurance_code,class_cd,it_remarks) values" -> insert into ins_premium_det (premium_rcv_code,assorted_code, rec_amount,premium_rcv_detail_code,remaining_amt, payrec, mode_code,coinsurance_code,class_cd,it_remarks) values | G3: ="('"&E3&"','"&B3&"','"&D3&"',(select max(to_number(i.premium_rcv_detail_code))+1 from ins_premium_det i),'"&D3&"','"&D3&"','02', '11000003','00','Request by Mr. Saqib Saleem 27-Mar-2025');" -> ('27Mar250025','070000176611','94380',(select max(to_number(i.premium_rcv_detail_code))+1 from ins_premium_det i),'94380','94380','02', '11000003','00','Request by Mr. Saqib Saleem 27-Mar-2025'); | H3: =F3&G3 -> insert into ins_premium_det (premium_rcv_code,assorted_code, rec_amount,premium_rcv_detail_code,remaining_amt, payrec, mode_code,coinsurance_code,class_cd,it_remarks) values('27Mar250025','070000176611','94380',(select max(to_number(i.premium_rcv_detail_code))+1 from ins_premium_det i),'94380','94380','02', '11000003','00','Request by Mr. Saqib Saleem 27-Mar-2025');
A4: KHI/HO/D/MO/PC COMP/C/107044/20/02/2025 | B4: =VLOOKUP(A4,policy!B:C,2,) -> 070000176629 | C4: 82583 | D4: =ROUND(C4,0) -> 82583 | E4: 27Mar250025 | F4: ="insert into ins_premium_det (premium_rcv_code,assorted_code, rec_amount,premium_rcv_detail_code,remaining_amt, payrec, mode_code,coinsurance_code,class_cd,it_remarks) values" -> insert into ins_premium_det (premium_rcv_code,assorted_code, rec_amount,premium_rcv_detail_code,remaining_amt, payrec, mode_code,coinsurance_code,class_cd,it_remarks) values | G4: ="('"&E4&"','"&B4&"','"&D4&"',(select max(to_number(i.premium_rcv_detail_code))+1 from ins_premium_det i),'"&D4&"','"&D4&"','02', '11000003','00','Request by Mr. Saqib Saleem 27-Mar-2025');" -> ('27Mar250025','070000176629','82583',(select max(to_number(i.premium_rcv_detail_code))+1 from ins_premium_det i),'82583','82583','02', '11000003','00','Request by Mr. Saqib Saleem 27-Mar-2025'); | H4: =F4&G4 -> insert into ins_premium_det (premium_rcv_code,assorted_code, rec_amount,premium_rcv_detail_code,remaining_amt, payrec, mode_code,coinsurance_code,class_cd,it_remarks) values('27Mar250025','070000176629','82583',(select max(to_number(i.premium_rcv_detail_code))+1 from ins_premium_det i),'82583','82583','02', '11000003','00','Request by Mr. Saqib Saleem 27-Mar-2025');
A5: KHI/HO/D/MO/PC COMP/C/105332/92/01/2025 | B5: =VLOOKUP(A5,policy!B:C,2,) -> 070000174818 | C5: 54140 | D5: =ROUND(C5,0) -> 54140 | E5: 27Mar250025 | F5: ="insert into ins_premium_det (premium_rcv_code,assorted_code, rec_amount,premium_rcv_detail_code,remaining_amt, payrec, mode_code,coinsurance_code,class_cd,it_remarks) values" -> insert into ins_premium_det (premium_rcv_code,assorted_code, rec_amount,premium_rcv_detail_code,remaining_amt, payrec, mode_code,coinsurance_code,class_cd,it_remarks) values | G5: ="('"&E5&"','"&B5&"','"&D5&"',(select max(to_number(i.premium_rcv_detail_code))+1 from ins_premium_det i),'"&D5&"','"&D5&"','02', '11000003','00','Request by Mr. Saqib Saleem 27-Mar-2025');" -> ('27Mar250025','070000174818','54140',(select max(to_number(i.premium_rcv_detail_code))+1 from ins_premium_det i),'54140','54140','02', '11000003','00','Request by Mr. Saqib Saleem 27-Mar-2025'); | H5: =F5&G5 -> insert into ins_premium_det (premium_rcv_code,assorted_code, rec_amount,premium_rcv_detail_code,remaining_amt, payrec, mode_code,coinsurance_code,class_cd,it_remarks) values('27Mar250025','070000174818','54140',(select max(to_number(i.premium_rcv_detail_code))+1 from ins_premium_det i),'54140','54140','02', '11000003','00','Request by Mr. Saqib Saleem 27-Mar-2025');
A6: KHI/HO/D/MO/PC COMP/C/107830/13/03/2025 | B6: =VLOOKUP(A6,policy!B:C,2,) -> 070000178650 | C6: 53288 | D6: =ROUND(C6,0) -> 53288 | E6: 27Mar250025 | F6: ="insert into ins_premium_det (premium_rcv_code,assorted_code, rec_amount,premium_rcv_detail_code,remaining_amt, payrec, mode_code,coinsurance_code,class_cd,it_remarks) values" -> insert into ins_premium_det (premium_rcv_code,assorted_code, rec_amount,premium_rcv_detail_code,remaining_amt, payrec, mode_code,coinsurance_code,class_cd,it_remarks) values | G6: ="('"&E6&"','"&B6&"','"&D6&"',(select max(to_number(i.premium_rcv_detail_code))+1 from ins_premium_det i),'"&D6&"','"&D6&"','02', '11000003','00','Request by Mr. Saqib Saleem 27-Mar-2025');" -> ('27Mar250025','070000178650','53288',(select max(to_number(i.premium_rcv_detail_code))+1 from ins_premium_det i),'53288','53288','02', '11000003','00','Request by Mr. Saqib Saleem 27-Mar-2025'); | H6: =F6&G6 -> insert into ins_premium_det (premium_rcv_code,assorted_code, rec_amount,premium_rcv_detail_code,remaining_amt, payrec, mode_code,coinsurance_code,class_cd,it_remarks) values('27Mar250025','070000178650','53288',(select max(to_number(i.premium_rcv_detail_code))+1 from ins_premium_det i),'53288','53288','02', '11000003','00','Request by Mr. Saqib Saleem 27-Mar-2025');
A7: KHI/HO/D/MO/PC COMP/C/107044/33/02/2025 | B7: =VLOOKUP(A7,policy!B:C,2,) -> 070000177312 | C7: 131440 | D7: =ROUND(C7,0) -> 131440 | E7: 27Mar250025 | F7: ="insert into ins_premium_det (premium_rcv_code,assorted_code, rec_amount,premium_rcv_detail_code,remaining_amt, payrec, mode_code,coinsurance_code,class_cd,it_remarks) values" -> insert into ins_premium_det (premium_rcv_code,assorted_code, rec_amount,premium_rcv_detail_code,remaining_amt, payrec, mode_code,coinsurance_code,class_cd,it_remarks) values | G7: ="('"&E7&"','"&B7&"','"&D7&"',(select max(to_number(i.premium_rcv_detail_code))+1 from ins_premium_det i),'"&D7&"','"&D7&"','02', '11000003','00','Request by Mr. Saqib Saleem 27-Mar-2025');" -> ('27Mar250025','070000177312','131440',(select max(to_number(i.premium_rcv_detail_code))+1 from ins_premium_det i),'131440','131440','02', '11000003','00','Request by Mr. Saqib Saleem 27-Mar-2025'); | H7: =F7&G7 -> insert into ins_premium_det (premium_rcv_code,assorted_code, rec_amount,premium_rcv_detail_code,remaining_amt, payrec, mode_code,coinsurance_code,class_cd,it_remarks) values('27Mar250025','070000177312','131440',(select max(to_number(i.premium_rcv_detail_code))+1 from ins_premium_det i),'131440','131440','02', '11000003','00','Request by Mr. Saqib Saleem 27-Mar-2025');
A8: KHI/HO/D/MO/PC COMP/C/107044/3/02/2025 | B8: =VLOOKUP(A8,policy!B:C,2,) -> 070000176419 | C8: 91480 | D8: =ROUND(C8,0) -> 91480 | E8: 27Mar250025 | F8: ="insert into ins_premium_det (premium_rcv_code,assorted_code, rec_amount,premium_rcv_detail_code,remaining_amt, payrec, mode_code,coinsurance_code,class_cd,it_remarks) values" -> insert into ins_premium_det (premium_rcv_code,assorted_code, rec_amount,premium_rcv_detail_code,remaining_amt, payrec, mode_code,coinsurance_code,class_cd,it_remarks) values | G8: ="('"&E8&"','"&B8&"','"&D8&"',(select max(to_number(i.premium_rcv_detail_code))+1 from ins_premium_det i),'"&D8&"','"&D8&"','02', '11000003','00','Request by Mr. Saqib Saleem 27-Mar-2025');" -> ('27Mar250025','070000176419','91480',(select max(to_number(i.premium_rcv_detail_code))+1 from ins_premium_det i),'91480','91480','02', '11000003','00','Request by Mr. Saqib Saleem 27-Mar-2025'); | H8: =F8&G8 -> insert into ins_premium_det (premium_rcv_code,assorted_code, rec_amount,premium_rcv_detail_code,remaining_amt, payrec, mode_code,coinsurance_code,class_cd,it_remarks) values('27Mar250025','070000176419','91480',(select max(to_number(i.premium_rcv_detail_code))+1 from ins_premium_det i),'91480','91480','02', '11000003','00','Request by Mr. Saqib Saleem 27-Mar-2025');
A9: KHI/HO/D/MO/PC COMP/C/107830/5/03/2025 | B9: =VLOOKUP(A9,policy!B:C,2,) -> 070000178398 | C9: 152620 | D9: =ROUND(C9,0) -> 152620 | E9: 27Mar250025 | F9: ="insert into ins_premium_det (premium_rcv_code,assorted_code, rec_amount,premium_rcv_detail_code,remaining_amt, payrec, mode_code,coinsurance_code,class_cd,it_remarks) values" -> insert into ins_premium_det (premium_rcv_code,assorted_code, rec_amount,premium_rcv_detail_code,remaining_amt, payrec, mode_code,coinsurance_code,class_cd,it_remarks) values | G9: ="('"&E9&"','"&B9&"','"&D9&"',(select max(to_number(i.premium_rcv_detail_code))+1 from ins_premium_det i),'"&D9&"','"&D9&"','02', '11000003','00','Request by Mr. Saqib Saleem 27-Mar-2025');" -> ('27Mar250025','070000178398','152620',(select max(to_number(i.premium_rcv_detail_code))+1 from ins_premium_det i),'152620','152620','02', '11000003','00','Request by Mr. Saqib Saleem 27-Mar-2025'); | H9: =F9&G9 -> insert into ins_premium_det (premium_rcv_code,assorted_code, rec_amount,premium_rcv_detail_code,remaining_amt, payrec, mode_code,coinsurance_code,class_cd,it_remarks) values('27Mar250025','070000178398','152620',(select max(to_number(i.premium_rcv_detail_code))+1 from ins_premium_det i),'152620','152620','02', '11000003','00','Request by Mr. Saqib Saleem 27-Mar-2025');
A10: KHI/HO/D/MO/PC COMP/C/107044/45/02/2025 | B10: =VLOOKUP(A10,policy!B:C,2,) -> 070000177650 | C10: 82583 | D10: =ROUND(C10,0) -> 82583 | E10: 27Mar250025 | F10: ="insert into ins_premium_det (premium_rcv_code,assorted_code, rec_amount,premium_rcv_detail_code,remaining_amt, payrec, mode_code,coinsurance_code,class_cd,it_remarks) values" -> insert into ins_premium_det (premium_rcv_code,assorted_code, rec_amount,premium_rcv_detail_code,remaining_amt, payrec, mode_code,coinsurance_code,class_cd,it_remarks) values | G10: ="('"&E10&"','"&B10&"','"&D10&"',(select max(to_number(i.premium_rcv_detail_code))+1 from ins_premium_det i),'"&D10&"','"&D10&"','02', '11000003','00','Request by Mr. Saqib Saleem 27-Mar-2025');" -> ('27Mar250025','070000177650','82583',(select max(to_number(i.premium_rcv_detail_code))+1 from ins_premium_det i),'82583','82583','02', '11000003','00','Request by Mr. Saqib Saleem 27-Mar-2025'); | H10: =F10&G10 -> insert into ins_premium_det (premium_rcv_code,assorted_code, rec_amount,premium_rcv_detail_code,remaining_amt, payrec, mode_code,coinsurance_code,class_cd,it_remarks) values('27Mar250025','070000177650','82583',(select max(to_number(i.premium_rcv_detail_code))+1 from ins_premium_det i),'82583','82583','02', '11000003','00','Request by Mr. Saqib Saleem 27-Mar-2025');
A11: KHI/HO/D/MO/PC COMP/C/107044/44/02/2025 | B11: =VLOOKUP(A11,policy!B:C,2,) -> 070000177649 | C11: 60900 | D11: =ROUND(C11,0) -> 60900 | E11: 27Mar250025 | F11: ="insert into ins_premium_det (premium_rcv_code,assorted_code, rec_amount,premium_rcv_detail_code,remaining_amt, payrec, mode_code,coinsurance_code,class_cd,it_remarks) values" -> insert into ins_premium_det (premium_rcv_code,assorted_code, rec_amount,premium_rcv_detail_code,remaining_amt, payrec, mode_code,coinsurance_code,class_cd,it_remarks) values | G11: ="('"&E11&"','"&B11&"','"&D11&"',(select max(to_number(i.premium_rcv_detail_code))+1 from ins_premium_det i),'"&D11&"','"&D11&"','02', '11000003','00','Request by Mr. Saqib Saleem 27-Mar-2025');" -> ('27Mar250025','070000177649','60900',(select max(to_number(i.premium_rcv_detail_code))+1 from ins_premium_det i),'60900','60900','02', '11000003','00','Request by Mr. Saqib Saleem 27-Mar-2025'); | H11: =F11&G11 -> insert into ins_premium_det (premium_rcv_code,assorted_code, rec_amount,premium_rcv_detail_code,remaining_amt, payrec, mode_code,coinsurance_code,class_cd,it_remarks) values('27Mar250025','070000177649','60900',(select max(to_number(i.premium_rcv_detail_code))+1 from ins_premium_det i),'60900','60900','02', '11000003','00','Request by Mr. Saqib Saleem 27-Mar-2025');
A12: KHI/HO/D/MO/PC COMP/C/107044/2/02/2025 | B12: =VLOOKUP(A12,policy!B:C,2,) -> 070000176415 | C12: 128020 | D12: =ROUND(C12,0) -> 128020 | E12: 27Mar250025 | F12: ="insert into ins_premium_det (premium_rcv_code,assorted_code, rec_amount,premium_rcv_detail_code,remaining_amt, payrec, mode_code,coinsurance_code,class_cd,it_remarks) values" -> insert into ins_premium_det (premium_rcv_code,assorted_code, rec_amount,premium_rcv_detail_code,remaining_amt, payrec, mode_code,coinsurance_code,class_cd,it_remarks) values | G12: ="('"&E12&"','"&B12&"','"&D12&"',(select max(to_number(i.premium_rcv_detail_code))+1 from ins_premium_det i),'"&D12&"','"&D12&"','02', '11000003','00','Request by Mr. Saqib Saleem 27-Mar-2025');" -> ('27Mar250025','070000176415','128020',(select max(to_number(i.premium_rcv_detail_code))+1 from ins_premium_det i),'128020','128020','02', '11000003','00','Request by Mr. Saqib Saleem 27-Mar-2025'); | H12: =F12&G12 -> insert into ins_premium_det (premium_rcv_code,assorted_code, rec_amount,premium_rcv_detail_code,remaining_amt, payrec, mode_code,coinsurance_code,class_cd,it_remarks) values('27Mar250025','070000176415','128020',(select max(to_number(i.premium_rcv_detail_code))+1 from ins_premium_det i),'128020','128020','02', '11000003','00','Request by Mr. Saqib Saleem 27-Mar-2025');
A13: KHI/HO/D/MO/PC COMP/C/107830/11/03/2025 | B13: =VLOOKUP(A13,policy!B:C,2,) -> 070000178647 | C13: 177980 | D13: =ROUND(C13,0) -> 177980 | E13: 27Mar250025 | F13: ="insert into ins_premium_det (premium_rcv_code,assorted_code, rec_amount,premium_rcv_detail_code,remaining_amt, payrec, mode_code,coinsurance_code,class_cd,it_remarks) values" -> insert into ins_premium_det (premium_rcv_code,assorted_code, rec_amount,premium_rcv_detail_code,remaining_amt, payrec, mode_code,coinsurance_code,class_cd,it_remarks) values | G13: ="('"&E13&"','"&B13&"','"&D13&"',(select max(to_number(i.premium_rcv_detail_code))+1 from ins_premium_det i),'"&D13&"','"&D13&"','02', '11000003','00','Request by Mr. Saqib Saleem 27-Mar-2025');" -> ('27Mar250025','070000178647','177980',(select max(to_number(i.premium_rcv_detail_code))+1 from ins_premium_det i),'177980','177980','02', '11000003','00','Request by Mr. Saqib Saleem 27-Mar-2025'); | H13: =F13&G13 -> insert into ins_premium_det (premium_rcv_code,assorted_code, rec_amount,premium_rcv_detail_code,remaining_amt, payrec, mode_code,coinsurance_code,class_cd,it_remarks) values('27Mar250025','070000178647','177980',(select max(to_number(i.premium_rcv_detail_code))+1 from ins_premium_det i),'177980','177980','02', '11000003','00','Request by Mr. Saqib Saleem 27-Mar-2025');
... A81: KHI/HO/D/MO/PC COMP/C/107044/7/02/2025 | B81: =VLOOKUP(A81,policy!B:C,2,) -> 070000176519 | C81: 49000 | D81: =ROUND(C81,0) -> 49000 | E81: 27Mar250025 | F81: ="insert into ins_premium_det (premium_rcv_code,assorted_code, rec_amount,premium_rcv_detail_code,remaining_amt, payrec, mode_code,coinsurance_code,class_cd,it_remarks) values" -> insert into ins_premium_det (premium_rcv_code,assorted_code, rec_amount,premium_rcv_detail_code,remaining_amt, payrec, mode_code,coinsurance_code,class_cd,it_remarks) values | G81: ="('"&E81&"','"&B81&"','"&D81&"',(select max(to_number(i.premium_rcv_detail_code))+1 from ins_premium_det i),'"&D81&"','"&D81&"','02', '11000003','00','Request by Mr. Saqib Saleem 27-Mar-2025');" -> ('27Mar250025','070000176519','49000',(select max(to_number(i.premium_rcv_detail_code))+1 from ins_premium_det i),'49000','49000','02', '11000003','00','Request by Mr. Saqib Saleem 27-Mar-2025'); | H81: =F81&G81 -> insert into ins_premium_det (premium_rcv_code,assorted_code, rec_amount,premium_rcv_detail_code,remaining_amt, payrec, mode_code,coinsurance_code,class_cd,it_remarks) values('27Mar250025','070000176519','49000',(select max(to_number(i.premium_rcv_detail_code))+1 from ins_premium_det i),'49000','49000','02', '11000003','00','Request by Mr. Saqib Saleem 27-Mar-2025');
C82: =SUM(C2:C81) -> 5981860 | D82: =SUM(D2:D81) -> 5981860

Sheet sheet
A1: KHI/HO/D/MO/PC COMP/C/105332/102/01/2025 | B1: -01-2025 | H1: 105332 | I1: 00102 | J1: ="ia.assorted_string like '%"&H1&"-"&I1&B1&"%' or" -> ia.assorted_string like '%105332-00102-01-2025%' or
A2: KHI/HO/D/MO/PC COMP/C/107044/18/02/2025 | B2: -02-2025 | H2: 107044 | I2: 00018 | J2: ="ia.assorted_string like '%"&H2&"-"&I2&B2&"%' or" -> ia.assorted_string like '%107044-00018-02-2025%' or
A3: KHI/HO/D/MO/PC COMP/C/107044/20/02/2025 | B3: -02-2025 | H3: 107044 | I3: 00020 | J3: ="ia.assorted_string like '%"&H3&"-"&I3&B3&"%' or" -> ia.assorted_string like '%107044-00020-02-2025%' or
A4: KHI/HO/D/MO/PC COMP/C/105332/92/01/2025 | B4: -01-2025 | H4: 105332 | I4: 00092 | J4: ="ia.assorted_string like '%"&H4&"-"&I4&B4&"%' or" -> ia.assorted_string like '%105332-00092-01-2025%' or
A5: KHI/HO/D/MO/PC COMP/C/107830/13/03/2025 | B5: -03-2025 | H5: 107830 | I5: 00013 | J5: ="ia.assorted_string like '%"&H5&"-"&I5&B5&"%' or" -> ia.assorted_string like '%107830-00013-03-2025%' or
A6: KHI/HO/D/MO/PC COMP/C/107044/33/02/2025 | B6: -02-2025 | H6: 107044 | I6: 00033 | J6: ="ia.assorted_string like '%"&H6&"-"&I6&B6&"%' or" -> ia.assorted_string like '%107044-00033-02-2025%' or
A7: KHI/HO/D/MO/PC COMP/C/107044/3/02/2025 | B7: -02-2025 | H7: 107044 | I7: 00003 | J7: ="ia.assorted_string like '%"&H7&"-"&I7&B7&"%' or" -> ia.assorted_string like '%107044-00003-02-2025%' or
A8: KHI/HO/D/MO/PC COMP/C/107830/5/03/2025 | B8: -03-2025 | H8: 107830 | I8: 00005 | J8: ="ia.assorted_string like '%"&H8&"-"&I8&B8&"%' or" -> ia.assorted_string like '%107830-00005-03-2025%' or
A9: KHI/HO/D/MO/PC COMP/C/107044/45/02/2025 | B9: -02-2025 | H9: 107044 | I9: 00045 | J9: ="ia.assorted_string like '%"&H9&"-"&I9&B9&"%' or" -> ia.assorted_string like '%107044-00045-02-2025%' or
A10: KHI/HO/D/MO/PC COMP/C/107044/44/02/2025 | B10: -02-2025 | H10: 107044 | I10: 00044 | J10: ="ia.assorted_string like '%"&H10&"-"&I10&B10&"%' or" -> ia.assorted_string like '%107044-00044-02-2025%' or
A11: KHI/HO/D/MO/PC COMP/C/107044/2/02/2025 | B11: -02-2025 | H11: 107044 | I11: 00002 | J11: ="ia.assorted_string like '%"&H11&"-"&I11&B11&"%' or" -> ia.assorted_string like '%107044-00002-02-2025%' or
A12: KHI/HO/D/MO/PC COMP/C/107830/11/03/2025 | B12: -03-2025 | H12: 107830 | I12: 00011 | J12: ="ia.assorted_string like '%"&H12&"-"&I12&B12&"%' or" -> ia.assorted_string like '%107830-00011-03-2025%' or
... A80: KHI/HO/D/MO/PC COMP/C/107044/7/02/2025 | B80: -02-2025 | H80: 107044 | I80: 00007 | J80: ="ia.assorted_string like '%"&H80&"-"&I80&B80&"%' or" -> ia.assorted_string like '%107044-00007-02-2025%' or

Sheet policy
B1: FUNC_ASSORTED_STRING(IA.ASSORTED_CODE) | C1: ASSORTED_CODE
A2: 1 | B2: KHI/HO/D/MO/PC COMP/C/107044/55/02/2025 | C2: 070000177762
A3: 2 | B3: KHI/HO/D/MO/PC COMP/C/107044/59/02/2025 | C3: 070000177768
A4: 3 | B4: KHI/HO/D/MO/PC COMP/C/107044/60/02/2025 | C4: 070000177771
A5: 4 | B5: KHI/HO/D/MO/PC COMP/C/107044/29/02/2025 | C5: 070000177167
A6: 5 | B6: KHI/HO/D/MO/PC COMP/C/107044/10/02/2025 | C6: 070000176533
A7: 6 | B7: KHI/HO/D/MO/PC COMP/C/107044/11/02/2025 | C7: 070000176534
A8: 7 | B8: KHI/HO/D/MO/PC COMP/C/107044/17/02/2025 | C8: 070000176591
A9: 8 | B9: KHI/HO/D/MO/PC COMP/C/107044/2/02/2025 | C9: 070000176415
A10: 9 | B10: KHI/HO/D/MO/PC COMP/C/107044/3/02/2025 | C10: 070000176419
A11: 10 | B11: KHI/HO/D/MO/PC COMP/C/105332/65/01/2025 | C11: 070000174130
A12: 11 | B12: KHI/HO/D/MO/PC COMP/C/107830/7/03/2025 | C12: 070000178408
A13: 12 | B13: KHI/HO/D/MO/PC COMP/C/107830/9/03/2025 | C13: 070000178592
... A81: 80 | B81: KHI/HO/D/MO/PC COMP/C/107830/20/03/2025 | C81: 070000179021
