Workbook

Sheet Fresh
A1: S.No | B1: Fresh | C1: Proposal No. | D1: Billing Month | E1: Takaful Company | F1: PMD / Cert | G1: Takaful Start Date | H1: Takaful End Date | I1: Customer Name | J1: CNIC | K1: Vehicle Make | L1: Reg. No | M1: Engine No | N1: Chassis No | O1: Proposal No. | P1: Region | Q1: Unit ID | R1: BR # | S1: Financing Date | T1: Maturity Date | U1: Asset Value | V1: Dep. % | W1: Dep. Amount | X1: New Sum Cover Amount | Y1: Takaful Rate | Z1: New Premium Amount | AA1: ALBARAKA Status | AB1: For Takaful Company Rectifications | AC1: For COD Status | AD1: PO No. | AE1: PO Dates | AF1: Proposal Status | AG1: DPD | AH1: GL Balance | AI1: Differences | AJ1: Remarks | AK1: Policy No. | AL1: TMS Premium | AM1: Difference Amount | AN1: Tagging
A2: 1 | B2: Fresh | C2: 75117/1 | D2: 45658 | E2: Salam Takaful | F2: KHI/HO/D/MO/PC COMP/C/105285/10/01/2025 | G2: 45670 | H2: 46034 | I2: MUHAMMAD ARIF | J2: 3220283082719 | K2: TOYOTA YARIS ATIV AT | L2: UN - REG | M2: 71678 | N2: 7048855 | O2: 75117/1 | P2: Central | Q2: 0804 | R2: 657913 | S2: 45673 | T2: 46788 | U2: 4760000 | V2: - | W2: - | X2: 4760000 | Y2: 1.5 | Z2: 71400 | AC2: Paid | AD2: 1141072848 | AE2: 45722 | AF2: DISBURSED | AG2: 0 | AH2: 71400 | AI2: 0 | AK2: KHI/HO/D/MO/PC COMP/C/105285/10/01/2025 | AL2: 71400 | AM2: 0 | AN2: FRE
A3: 2 | B3: Fresh | C3: 75401/1 | D3: 45658 | E3: Salam Takaful | F3: KHI/HO/D/MO/PC COMP/C/105285/11/01/2025 | G3: 45670 | H3: 46034 | I3: MUHAMMAD BILAL | J3: 3520108337157 | K3: SUZUKI Swift GLX CVT | L3: UN - REG | M3: R1024729 | N3: S00207455 | O3: 75401/1 | P3: Central | Q3: 0329 | R3: 658773 | S3: 45672 | T3: 46757 | U3: 4719000 | V3: - | W3: - | X3: 4719000 | Y3: 1.5 | Z3: 70785 | AC3: Paid | AD3: 1141072848 | AE3: 45722 | AF3: DISBURSED | AG3: 0 | AH3: 70785 | AI3: 0 | AK3: KHI/HO/D/MO/PC COMP/C/105285/11/01/2025 | AL3: 70785 | AM3: 0 | AN3: FRE
A4: 3 | B4: Fresh | C4: 75574/1 | D4: 45658 | E4: Salam Takaful | F4: KHI/HO/D/MO/PC COMP/C/105285/28/01/2025 | G4: 45680 | H4: 46044 | I4: SYED ABDUL RASHEED | J4: 5440178704131 | K4: HONDA CITY 1.2 LS CVT | L4: AXT-238 | M4: 51008287 | N4: 013265 | O4: 75574/1 | P4: Central | Q4: 0804 | R4: 660920 | S4: 45701 | T4: 46788 | U4: 4200000 | V4: - | W4: - | X4: 4200000 | Y4: 1.5 | Z4: 63000 | AC4: Paid | AD4: 1141072848 | AE4: 45722 | AF4: DISBURSED | AG4: 0 | AH4: 63000 | AI4: 0 | AK4: KHI/HO/D/MO/PC COMP/C/105285/28/01/2025 | AL4: 63000 | AM4: 0 | AN4: FRE
A5: 4 | B5: Fresh | C5: 76370/1 | D5: 45658 | E5: Salam Takaful | F5: KHI/HO/D/MO/PC COMP/C/105285/25/01/2025 | G5: 45678 | H5: 46042 | I5: SARMAD KAMAL KHAN | J5: 3460374244523 | K5: HONDA CITY I-VTEC 1.2 | L5: - | M5: 1030592 | N5: SR047669 | O5: 76370/1 | P5: Central | Q5: 0329 | R5: 662358 | S5: 45686 | T5: 46788 | U5: 5118000 | V5: - | W5: - | X5: 5118000 | Y5: 1.5 | Z5: 76770 | AC5: Paid | AD5: 1141072848 | AE5: 45722 | AF5: DISBURSED | AG5: 0 | AH5: 76770 | AI5: 0 | AK5: KHI/HO/D/MO/PC COMP/C/105285/25/01/2025 | AL5: 76770 | AM5: 0 | AN5: FRE
A6: 5 | B6: Fresh | C6: 76610/1 | D6: 45658 | E6: Salam Takaful | F6: KHI/HO/D/MO/PC COMP/C/105285/46/01/2025 | G6: 45688 | H6: 46052 | I6: SUHAIB MANZOOR | J6: 3520209006119 | K6: HONDA CITY 1.2 LS CVT | L6: AGR-229 | M6: B51002558 | N6: R003404 | O6: 76610/1 | P6: Central | Q6: 0329 | R6: 33177 | S6: 45692 | T6: 46788 | U6: 4200000 | V6: - | W6: - | X6: 4200000 | Y6: 1.5 | Z6: 63000 | AC6: Paid | AD6: 1141072848 | AE6: 45722 | AF6: DISBURSED | AG6: 0 | AH6: 63000 | AI6: 0 | AK6: KHI/HO/D/MO/PC COMP/C/105285/46/01/2025 | AL6: 63000 | AM6: 0 | AN6: FRE
A7: 6 | B7: Fresh | C7: 76986/1 | D7: 45658 | E7: Salam Takaful | F7: KHI/HO/D/MO/PC COMP/C/105285/2/01/2025 | G7: 45664 | H7: 46028 | I7: RIFFAT SALEEM | J7: 3310098725370 | K7: HYUNDAI TUCSON | L7: BBZ-884 | M7: G4NANU207232 | N7: PMHJ2813SNN207452 | O7: 76986/1 | P7: Central | Q7: 0423 | R7: 665158 | S7: 45665 | T7: 46757 | U7: 7500000 | V7: - | W7: - | X7: 7500000 | Y7: 1.5 | Z7: 112500 | AC7: Paid | AD7: 1141072848 | AE7: 45722 | AF7: DISBURSED | AG7: 0 | AH7: 112500 | AI7: 0 | AK7: KHI/HO/D/MO/PC COMP/C/105285/2/01/2025 | AL7: 112500 | AM7: 0 | AN7: FRE
A8: 7 | B8: Fresh | C8: 77006/1 | D8: 45658 | E8: Salam Takaful | F8: KHI/HO/D/MO/PC COMP/C/105285/6/01/2025 | G8: 45666 | H8: 46030 | I8: KINZA SHAHZAD | J8: 3420267725644 | K8: CHANGAN KARVAAN PLUS VAN | L8: 0 | M8: 504207 | N8: 1002163 | O8: 77006/1 | P8: Central | Q8: 0804 | R8: 665476 | S8: 45694 | T8: 46788 | U8: 3049000 | V8: - | W8: - | X8: 3049000 | Y8: 2 | Z8: 60980 | AC8: Paid | AD8: 1141072848 | AE8: 45722 | AF8: DISBURSED | AG8: 0 | AH8: 60980 | AI8: 0 | AK8: KHI/HO/D/MO/PC COMP/C/105285/6/01/2025 | AL8: 60980 | AM8: 0 | AN8: FRE
A9: 8 | B9: Fresh | C9: 77010/1 | D9: 45658 | E9: Salam Takaful | F9: KHI/HO/D/MO/PC COMP/C/105285/57/01/2025 | G9: 45688 | H9: 46052 | I9: MALIK AZHAR | J9: 3520278263717 | K9: TOYOTA COROLLA GLI M/T 1. | L9: LED-19-1502 | M9: Z552788 | N9: 4178527 | O9: 77010/1 | P9: Central | Q9: 0329 | R9: 665142 | S9: 45694 | T9: 46788 | U9: 4100000 | V9: - | W9: - | X9: 4100000 | Y9: 1.5 | Z9: 61500 | AC9: Paid | AD9: 1141072848 | AE9: 45722 | AF9: DISBURSED | AG9: 0 | AH9: 61500 | AI9: 0 | AK9: KHI/HO/D/MO/PC COMP/C/105285/57/01/2025 | AL9: 61500 | AM9: 0 | AN9: FRE
A10: 9 | B10: Fresh | C10: 77119/1 | D10: 45658 | E10: Salam Takaful | F10: KHI/HO/D/MO/PC COMP/C/105285/20/01/2025 | G10: 45678 | H10: 46042 | I10: MUHAMMAD TALHA SHAH | J10: 3120223099979 | K10: SUZUKI ALTO VXR E-2 | L10: BQS-174 | M10: 6R104122 | N10: 6H1004091 | O10: 77119/1 | P10: Central | Q10: 0471 | R10: 665522 | S10: 45684 | T10: 47519 | U10: 2150000 | V10: - | W10: - | X10: 2150000 | Y10: 2 | Z10: 43000 | AC10: Paid | AD10: 1141072848 | AE10: 45722 | AF10: DISBURSED | AG10: 0 | AH10: 43000 | AI10: 0 | AK10: KHI/HO/D/MO/PC COMP/C/105285/20/01/2025 | AL10: 43000 | AM10: 0 | AN10: FRE
A11: 10 | B11: Fresh | C11: 77135/1 | D11: 45658 | E11: Salam Takaful | F11: KHI/HO/D/MO/PC COMP/C/105285/21/01/2025 | G11: 45678 | H11: 46042 | I11: NAEEM KHAN | J11: 4250115035545 | K11: SUZUKI ALTO VXR E-2 | L11: BRY-548 | M11: 133318 | N11: 1033294 | O11: 77135/1 | P11: South | Q11: 0144 | R11: 548733 | S11: 45679 | T11: 46788 | U11: 2150000 | V11: - | W11: - | X11: 2150000 | Y11: 2 | Z11: 43000 | AC11: Paid | AD11: 1141072848 | AE11: 45722 | AF11: DISBURSED | AG11: 0 | AH11: 43000 | AI11: 0 | AK11: KHI/HO/D/MO/PC COMP/C/105285/21/01/2025 | AL11: 43000 | AM11: 0 | AN11: FRE
A12: 11 | B12: Fresh | C12: 77166/1 | D12: 45658 | E12: Salam Takaful | F12: KHI/HO/D/MO/PC COMP/C/105285/1/01/2025 | G12: 45660 | H12: 46024 | I12: MUHAMMAD UMAR ALI | J12: 6110109660143 | K12: SUZUKI WAGON-R VXL E2 | L12: LEF-19-2912 | M12: 194777 | N12: 10094786 | O12: 77166/1 | P12: Central | Q12: 0804 | R12: 666037 | S12: 45665 | T12: 47488 | U12: 2200000 | V12: - | W12: - | X12: 2200000 | Y12: 2 | Z12: 44000 | AC12: Paid | AD12: 1141072848 | AE12: 45722 | AF12: DISBURSED | AG12: 0 | AH12: 44000 | AI12: 0 | AK12: KHI/HO/D/MO/PC COMP/C/105285/1/01/2025 | AL12: 44000 | AM12: 0 | AN12: FRE
A13: 12 | B13: Fresh | C13: 77221/1 | D13: 45658 | E13: Salam Takaful | F13: KHI/HO/D/MO/PC COMP/C/105285/16/01/2025 | G13: 45674 | H13: 46038 | I13: RANA ISHTIAQ AHMAD PRINCE | J13: 3520222297649 | K13: SUZUKI ALTO VXR E-2 | L13: UN - REG | M13: 334056 | N13: 1233870 | O13: 77221/1 | P13: Central | Q13: 0329 | R13: 668205 | S13: 45678 | T13: 47519 | U13: 2707000 | V13: - | W13: - | X13: 2707000 | Y13: 2 | Z13: 54140 | AC13: Paid | AD13: 1141072848 | AE13: 45722 | AF13: DISBURSED | AG13: 0 | AH13: 54140 | AI13: 0 | AK13: KHI/HO/D/MO/PC COMP/C/105285/16/01/2025 | AL13: 54140 | AM13: 0 | AN13: FRE
A14: 13 | B14: Fresh | C14: 77248/1 | D14: 45658 | E14: Salam Takaful | F14: KHI/HO/D/MO/PC COMP/C/105285/44/01/2025 | G14: 45688 | H14: 46052 | I14: MUHAMMAD AZHAR HUSSAIN | J14: 3410187852147 | K14: TOYOTA COROLLA GLI M/T 1. | L14: LED-18-9941 | M14: Z517064 | N14: 4143165 | O14: 77248/1 | P14: Central | Q14: 0401 | R14: 666177 | S14: 45691 | T14: 46788 | U14: 3500000 | V14: - | W14: - | X14: 3500000 | Y14: 1.5 | Z14: 52500 | AC14: Paid | AD14: 1141072848 | AE14: 45722 | AF14: DISBURSED | AG14: 0 | AH14: 52500 | AI14: 0 | AK14: KHI/HO/D/MO/PC COMP/C/105285/44/01/2025 | AL14: 52500 | AM14: 0 | AN14: FRE
A15: 14 | B15: Fresh | C15: 77269/1 | D15: 45658 | E15: Salam Takaful | F15: KHI/HO/D/MO/PC COMP/C/105285/9/01/2025 | G15: 45667 | H15: 46031 | I15: HUMA FAISAL | J15: 3520014636046 | K15: HYUNDAI TUCSON 6A/T AWD | L15: - | M15: 700017 | N15: 218301 | O15: 77269/1 | P15: Central | Q15: 0329 | R15: 521457 | S15: 45667 | T15: 46757 | U15: 8809000 | V15: - | W15: - | X15: 8809000 | Y15: 1.5 | Z15: 132135 | AC15: Paid | AD15: 1141072848 | AE15: 45722 | AF15: DISBURSED | AG15: 0 | AH15: 132135 | AI15: 0 | AK15: KHI/HO/D/MO/PC COMP/C/105285/9/01/2025 | AL15: 132135 | AM15: 0 | AN15: FRE
A16: 15 | B16: Fresh | C16: 77312/1 | D16: 45658 | E16: Salam Takaful | F16: KHI/HO/D/MO/PC COMP/C/105285/7/01/2025 | G16: 45667 | H16: 46031 | I16: MUHAMMAD HASSAN | J16: 3520193005593 | K16: SUZUKI Swift GLX CVT | L16: ASU-688 | M16: 1015227 | N16: S00115217 | O16: 77312/1 | P16: Central | Q16: 0329 | R16: 666485 | S16: 45670 | T16: 46392 | U16: 4300000 | V16: - | W16: - | X16: 4300000 | Y16: 1.5 | Z16: 64500 | AC16: Paid | AD16: 1141072848 | AE16: 45722 | AF16: DISBURSED | AG16: 0 | AH16: 64500 | AI16: 0 | AK16: KHI/HO/D/MO/PC COMP/C/105285/7/01/2025 | AL16: 64500 | AM16: 0 | AN16: FRE
A17: 16 | B17: Fresh | C17: 77352/1 | D17: 45658 | E17: Salam Takaful | F17: KHI/HO/D/MO/PC COMP/C/105285/8/01/2025 | G17: 45667 | H17: 46031 | I17: ZAKI ULLAH DANISH | J17: 8210186450695 | K17: SUZUKI ALTO VXR E-2 | L17: 0 | M17: 334460 | N17: 1234509 | O17: 77352/1 | P17: Central | Q17: 0804 | R17: 666671 | S17: 45672 | T17: 47488 | U17: 2707000 | V17: - | W17: - | X17: 2707000 | Y17: 2 | Z17: 54140 | AC17: Paid | AD17: 1141072848 | AE17: 45722 | AF17: DISBURSED | AG17: 0 | AH17: 54140 | AI17: 0 | AK17: KHI/HO/D/MO/PC COMP/C/105285/8/01/2025 | AL17: 54140 | AM17: 0 | AN17: FRE
A18: 17 | B18: Fresh | C18: 77464/1 | D18: 45658 | E18: Salam Takaful | F18: KHI/HO/D/MO/PC COMP/C/105285/13/01/2025 | G18: 45672 | H18: 46036 | I18: SIKANDAR NAWAZ | J18: 3520224892035 | K18: HONDA CITY 1.2 LS CVT | L18: UN - REG | M18: 51030322 | N18: SR047426 | O18: 77464/1 | P18: Central | Q18: 0329 | R18: 667242 | S18: 45673 | T18: 46788 | U18: 4719000 | V18: - | W18: - | X18: 4719000 | Y18: 1.5 | Z18: 70785 | AC18: Paid | AD18: 1141072848 | AE18: 45722 | AF18: DISBURSED | AG18: 0 | AH18: 70785 | AI18: 0 | AK18: KHI/HO/D/MO/PC COMP/C/105285/13/01/2025 | AL18: 70785 | AM18: 0 | AN18: FRE
A19: 18 | B19: Fresh | C19: 77516/1 | D19: 45658 | E19: Salam Takaful | F19: KHI/HO/D/MO/PC COMP/C/105285/30/01/2025 | G19: 45681 | H19: 46045 | I19: KHURRAM SHAHZAD | J19: 3520278934135 | K19: SUZUKI Every VXR | L19: UN - REG | M19: R1001909 | N19: V00101872 | O19: 77516/1 | P19: Central | Q19: 0329 | R19: 537131 | S19: 45686 | T19: 47519 | U19: 2799000 | V19: - | W19: - | X19: 2799000 | Y19: 2 | Z19: 55980 | AC19: Paid | AD19: 1141072848 | AE19: 45722 | AF19: DISBURSED | AG19: 0 | AH19: 55980 | AI19: 0 | AK19: KHI/HO/D/MO/PC COMP/C/105285/30/01/2025 | AL19: 55980 | AM19: 0 | AN19: FRE
A20: 19 | B20: Fresh | C20: 77523/1 | D20: 45658 | E20: Salam Takaful | F20: KHI/HO/D/MO/PC COMP/C/105285/3/01/2025 | G20: 45666 | H20: 46030 | I20: SHAHZAD FAROOQ | J20: 3310007023373 | K20: HONDA CITY ASPIRE P/T I-V | L20: UN - REG | M20: 51029957 | N20: RR047049 | O20: 77523/1 | P20: Central | Q20: 0329 | R20: 576524 | S20: 45667 | T20: 46757 | U20: 4719000 | V20: - | W20: - | X20: 4719000 | Y20: 1.5 | Z20: 70785 | AC20: Paid | AD20: 1141072848 | AE20: 45722 | AF20: DISBURSED | AG20: 0 | AH20: 70785 | AI20: 0 | AK20: KHI/HO/D/MO/PC COMP/C/105285/3/01/2025 | AL20: 70785 | AM20: 0 | AN20: FRE
A21: 20 | B21: Fresh | C21: 77544/1 | D21: 45658 | E21: Salam Takaful | F21: KHI/HO/D/MO/PC COMP/C/105285/31/01/2025 | G21: 45681 | H21: 46045 | I21: ARSHAD ALI | J21: 6110117815033 | K21: TOYOTA COROLLA ALTIS GRAN | L21: AMJ-080 | M21: 345423 | N21: 7044607 | O21: 77544/1 | P21: Central | Q21: 0804 | R21: 667171 | S21: 45687 | T21: 46788 | U21: 5600000 | V21: - | W21: - | X21: 5600000 | Y21: 1.5 | Z21: 84000 | AC21: Paid | AD21: 1141072848 | AE21: 45722 | AF21: DISBURSED | AG21: 0 | AH21: 84000 | AI21: 0 | AK21: KHI/HO/D/MO/PC COMP/C/105285/31/01/2025 | AL21: 84000 | AM21: 0 | AN21: FRE
A22: 21 | B22: Fresh | C22: 77763/1 | D22: 45658 | E22: Salam Takaful | F22: KHI/HO/D/MO/CV/C/106061/1/01/2025 | G22: 45672 | H22: 46036 | I22: TOUQEER TAYYAB | J22: 4250107176711 | K22: SUZUKI RAVI VX EURO II | L22: UN - REG | M22: PKT393671 | N22: PK498330 | O22: 77763/1 | P22: South | Q22: 0144 | R22: 667756 | S22: 45674 | T22: 46423 | U22: 1856000 | V22: - | W22: - | X22: 1856000 | Y22: 2 | Z22: 37120 | AC22: Paid | AD22: 1141072848 | AE22: 45722 | AF22: DISBURSED | AG22: 0 | AH22: 37120 | AI22: 0 | AK22: KHI/HO/D/MO/CV/C/106061/1/01/2025 | AL22: 37120 | AM22: 0 | AN22: FRE
A23: 22 | B23: Fresh | C23: 77764/1 | D23: 45658 | E23: Salam Takaful | F23: KHI/HO/D/MO/CV/C/106061/2/01/2025 | G23: 45673 | H23: 46037 | I23: TOUQEER TAYYAB | J23: 4250107176711 | K23: SUZUKI RAVI VX EURO II | L23: UN - REG | M23: PKT392467 | N23: PK497134 | O23: 77764/1 | P23: South | Q23: 0144 | R23: 667756 | S23: 45686 | T23: 46423 | U23: 1856000 | V23: - | W23: - | X23: 1856000 | Y23: 2 | Z23: 37120 | AC23: Paid | AD23: 1141072848 | AE23: 45722 | AF23: DISBURSED | AG23: 0 | AH23: 37120 | AI23: 0 | AK23: KHI/HO/D/MO/CV/C/106061/2/01/2025 | AL23: 37120 | AM23: 0 | AN23: FRE
A24: 23 | B24: Fresh | C24: 77787/1 | D24: 45658 | E24: Salam Takaful | F24: KHI/HO/D/MO/PC COMP/C/105285/19/01/2025 | G24: 45677 | H24: 46041 | I24: WAQAR AHMED | J24: 1350310525897 | K24: SUZUKI ALTO VXR E-2 | L24: BXH-484 | M24: R-245807 | N24: 1145808 | O24: 77787/1 | P24: South | Q24: 0144 | R24: 665064 | S24: 45684 | T24: 47519 | U24: 2450000 | V24: - | W24: - | X24: 2450000 | Y24: 2 | Z24: 49000 | AC24: Paid | AD24: 1141072848 | AE24: 45722 | AF24: DISBURSED | AG24: 0 | AH24: 49000 | AI24: 0 | AK24: KHI/HO/D/MO/PC COMP/C/105285/19/01/2025 | AL24: 49000 | AM24: 0 | AN24: FRE
A25: 24 | B25: Fresh | C25: 77799/1 | D25: 45658 | E25: Salam Takaful | F25: KHI/HO/D/MO/PC COMP/C/105285/18/01/2025 | G25: 45674 | H25: 46038 | I25: IRFAN JAMEEL | J25: 3740209769535 | K25: SUZUKI ALTO VXR E-2 | L25: UN - REG | M25: 6R336691 | N25: NF1AET306H1236709 | O25: 77799/1 | P25: Central | Q25: 0423 | R25: 667662 | S25: 45685 | T25: 46788 | U25: 2707000 | V25: - | W25: - | X25: 2707000 | Y25: 2 | Z25: 54140 | AC25: Paid | AD25: 1141072848 | AE25: 45722 | AF25: DISBURSED | AG25: 0 | AH25: 54140 | AI25: 0 | AK25: KHI/HO/D/MO/PC COMP/C/105285/18/01/2025 | AL25: 54140 | AM25: 0 | AN25: FRE
A26: 25 | B26: Fresh | C26: 77800/1 | D26: 45658 | E26: Salam Takaful | F26: KHI/HO/D/MO/PC COMP/C/105285/38/01/2025 | G26: 45685 | H26: 46049 | I26: MUHAMMAD TAYYAB HASSAN | J26: 3310010166423 | K26: HONDA CIVIC VTI ORIEL PT | L26: ABT-309 | M26: R18Z12902011 | N26: NFBFC6659GR002529 | O26: 77800/1 | P26: Central | Q26: 0423 | R26: 667666 | S26: 45688 | T26: 46788 | U26: 3500000 | V26: - | W26: - | X26: 3500000 | Y26: 1.5 | Z26: 52500 | AC26: Paid | AD26: 1141072848 | AE26: 45722 | AF26: DISBURSED | AG26: 0 | AH26: 52500 | AI26: 0 | AK26: KHI/HO/D/MO/PC COMP/C/105285/38/01/2025 | AL26: 52500 | AM26: 0 | AN26: FRE
A27: 26 | B27: Fresh | C27: 77811/1 | D27: 45658 | E27: Salam Takaful | F27: KHI/HO/D/MO/PC COMP/C/105285/22/01/2025 | G27: 45678 | H27: 46042 | I27: MUHAMMAD ASIF | J27: 3310004908327 | K27: SUZUKI WAGON-R VXL E2 | L27: ACD-877 | M27: PK10B210852 | N27: A1J310PK10110822 | O27: 77811/1 | P27: Central | Q27: 0423 | R27: 667645 | S27: 45685 | T27: 47519 | U27: 2700000 | V27: - | W27: - | X27: 2700000 | Y27: 2 | Z27: 54000 | AC27: Paid | AD27: 1141072848 | AE27: 45722 | AF27: DISBURSED | AG27: 0 | AH27: 54000 | AI27: 0 | AK27: KHI/HO/D/MO/PC COMP/C/105285/22/01/2025 | AL27: 54000 | AM27: 0 | AN27: FRE
A28: 27 | B28: Fresh | C28: 77860/1 | D28: 45658 | E28: Salam Takaful | F28: KHI/HO/D/MO/PC COMP/C/105285/17/01/2025 | G28: 45674 | H28: 46038 | I28: SHUMAILA . | J28: 4220191667720 | K28: SUZUKI ALTO VXR E-2 | L28: BVG-492 | M28: 6R176132 | N28: H1076109 | O28: 77860/1 | P28: South | Q28: 0144 | R28: 667187 | S28: 45679 | T28: 47519 | U28: 2200000 | V28: - | W28: - | X28: 2200000 | Y28: 2 | Z28: 44000 | AC28: Paid | AD28: 1141072848 | AE28: 45722 | AF28: DISBURSED | AG28: 0 | AH28: 44000 | AI28: 0 | AK28: KHI/HO/D/MO/PC COMP/C/105285/17/01/2025 | AL28: 44000 | AM28: 0 | AN28: FRE
A29: 28 | B29: Fresh | C29: 77862/1 | D29: 45658 | E29: Salam Takaful | F29: KHI/HO/D/MO/PC COMP/C/105285/56/01/2025 | G29: 45688 | H29: 46052 | I29: MUHAMMAD ABID | J29: 3310044039339 | K29: HONDA CIVIC | L29: ADY-122 | M29: R18Z 12913247 | N29: NFBFC6654HR016484 | O29: 77862/1 | P29: Central | Q29: 0423 | R29: 667659 | S29: 45692 | T29: 46788 | U29: 3200000 | V29: - | W29: - | X29: 3200000 | Y29: 2 | Z29: 64000 | AC29: Paid | AD29: 1141072848 | AE29: 45722 | AF29: DISBURSED | AG29: 0 | AH29: 64000 | AI29: 0 | AK29: KHI/HO/D/MO/PC COMP/C/105285/56/01/2025 | AL29: 64000 | AM29: 0 | AN29: FRE
... A42: 41 | B42: Fresh | C42: 78141/1 | D42: 45658 | E42: Salam Takaful | F42: KHI/HO/D/MO/PC COMP/C/105285/49/01/2025 | G42: 45688 | H42: 46052 | I42: WASEEM RIAZ | J42: 3630242290221 | K42: SUZUKI CULTUS VXL | L42: LEE-19-9167 | M42: 140203 | N42: 10040182 | O42: 78141/1 | P42: Central | Q42: 0431 | R42: 598685 | S42: 45694 | T42: 47519 | U42: 2800000 | V42: - | W42: - | X42: 2800000 | Y42: 2 | Z42: 56000 | AC42: Paid | AD42: 1141072848 | AE42: 45722 | AF42: DISBURSED | AG42: 0 | AH42: 56000 | AI42: 0 | AK42: KHI/HO/D/MO/PC COMP/C/105285/49/01/2025 | AL42: 56000 | AM42: 0 | AN42: FRE
A43: 42 | B43: Fresh | C43: 78178/1 | D43: 45658 | E43: Salam Takaful | F43: KHI/HO/D/MO/PC COMP/C/105285/50/01/2025 | G43: 45688 | H43: 46052 | I43: ASIF NISAR | J43: 3720142700407 | K43: HONDA CITY 1.2 LS CVT | L43: 0 | M43: 030860 | N43: 048197 | O43: 78178/1 | P43: Central | Q43: 0804 | R43: 668624 | S43: 45692 | T43: 46788 | U43: 4719000 | V43: - | W43: - | X43: 4719000 | Y43: 1.5 | Z43: 70785 | AC43: Paid | AD43: 1141072848 | AE43: 45722 | AF43: DISBURSED | AG43: 0 | AH43: 70785 | AI43: 0 | AK43: KHI/HO/D/MO/PC COMP/C/105285/50/01/2025 | AL43: 70785 | AM43: 0 | AN43: FRE
A44: 43 | B44: Fresh | C44: 78194/1 | D44: 45658 | E44: Salam Takaful | F44: KHI/HO/D/MO/PC COMP/C/105285/52/01/2025 | G44: 45688 | H44: 46052 | I44: MUHAMMAD MUDASSAR | J44: 3520288534553 | K44: SUZUKI Every VXR | L44: 0 | M44: 1002364 | N44: 102387 | O44: 78194/1 | P44: Central | Q44: 0329 | R44: 668642 | S44: 45691 | T44: 47519 | U44: 2799000 | V44: - | W44: - | X44: 2799000 | Y44: 2 | Z44: 55980 | AC44: Paid | AD44: 1141072848 | AE44: 45722 | AF44: DISBURSED | AG44: 0 | AH44: 55980 | AI44: 0 | AK44: KHI/HO/D/MO/PC COMP/C/105285/52/01/2025 | AL44: 55980 | AM44: 0 | AN44: FRE
A45: 44 | B45: Fresh | C45: 78201/1 | D45: 45658 | E45: Salam Takaful | F45: KHI/HO/D/MO/PC COMP/C/105285/37/01/2025 | G45: 45685 | H45: 46049 | I45: QAMER JAVED HAYAT | J45: 3610457238279 | K45: TOYOTA COROLLA ALTIS 1.6 | L45: 0 | M45: Q109346 | N45: 6086857 | O45: 78201/1 | P45: Central | Q45: 0329 | R45: 668646 | S45: 45691 | T45: 46788 | U45: 6641000 | V45: - | W45: - | X45: 6641000 | Y45: 1.5 | Z45: 99615 | AC45: Paid | AD45: 1141072848 | AE45: 45722 | AF45: DISBURSED | AG45: 0 | AH45: 99615 | AI45: 0 | AK45: KHI/HO/D/MO/PC COMP/C/105285/37/01/2025 | AL45: 99615 | AM45: 0 | AN45: FRE
A46: 45 | B46: Fresh | C46: 78257/1 | D46: 45658 | E46: Salam Takaful | F46: KHI/HO/D/MO/PC COMP/C/105285/43/01/2025 | G46: 45687 | H46: 46051 | I46: MUHAMMAD MASOOD AHMAD | J46: 3120211456571 | K46: HONDA CITY M/T | L46: LEA-16-9706 | M46: 17437150 | N46: FR176612 | O46: 78257/1 | P46: Central | Q46: 0471 | R46: 349485 | S46: 45691 | T46: 46423 | U46: 3000000 | V46: - | W46: - | X46: 3000000 | Y46: 2 | Z46: 60000 | AC46: Paid | AD46: 1141072848 | AE46: 45722 | AF46: DISBURSED | AG46: 0 | AH46: 60000 | AI46: 0 | AK46: KHI/HO/D/MO/PC COMP/C/105285/43/01/2025 | AL46: 60000 | AM46: 0 | AN46: FRE
A47: 46 | B47: Fresh | C47: 78286/1 | D47: 45658 | E47: Salam Takaful | F47: KHI/HO/D/MO/PC COMP/C/105285/36/01/2025 | G47: 45685 | H47: 46049 | I47: MUHAMMAD EJAZ KHAN | J47: 3630289484855 | K47: HONDA CITY 1.2 LS CVT | L47: 0 | M47: 1030307 | N47: 047408 | O47: 78286/1 | P47: Central | Q47: 0431 | R47: 587613 | S47: 45691 | T47: 46423 | U47: 4719000 | V47: - | W47: - | X47: 4719000 | Y47: 1.5 | Z47: 70785 | AC47: Paid | AD47: 1141072848 | AE47: 45722 | AF47: DISBURSED | AG47: 0 | AH47: 70785 | AI47: 0 | AK47: KHI/HO/D/MO/PC COMP/C/105285/36/01/2025 | AL47: 70785 | AM47: 0 | AN47: FRE
A48: 47 | B48: Fresh | C48: 78300/1 | D48: 45658 | E48: Salam Takaful | F48: KHI/HO/D/MO/PC COMP/C/105285/47/01/2025 | G48: 45688 | H48: 46052 | I48: MALIK ZEESHAN ALI | J48: 3720359937317 | K48: CHANGAN KARVAAN PLUS | L48: 0 | M48: 505729 | N48: 1002785 | O48: 78300/1 | P48: Central | Q48: 0804 | R48: 669095 | S48: 45692 | T48: 46788 | U48: 3049000 | V48: - | W48: - | X48: 3049000 | Y48: 2 | Z48: 60980 | AC48: Paid | AD48: 1141072848 | AE48: 45722 | AF48: DISBURSED | AG48: 0 | AH48: 60980 | AI48: 0 | AK48: KHI/HO/D/MO/PC COMP/C/105285/47/01/2025 | AL48: 60980 | AM48: 0 | AN48: FRE
A49: 48 | B49: Fresh | C49: 78347/1 | D49: 45658 | E49: Salam Takaful | F49: KHI/HO/D/MO/PC COMP/C/105285/54/01/2025 | G49: 45688 | H49: 46052 | I49: HASSAN KHALID | J49: 3120229042731 | K49: HONDA CIVIC | L49: LEC-18-4261 | M49: 12928021 | N49: R031301 | O49: 78347/1 | P49: Central | Q49: 0329 | R49: 668873 | S49: 45692 | T49: 46788 | U49: 4500000 | V49: - | W49: - | X49: 4500000 | Y49: 1.5 | Z49: 67500 | AC49: Paid | AD49: 1141072848 | AE49: 45722 | AF49: DISBURSED | AG49: 0 | AH49: 67500 | AI49: 0 | AK49: KHI/HO/D/MO/PC COMP/C/105285/54/01/2025 | AL49: 67500 | AM49: 0 | AN49: FRE
A50: 49 | B50: Fresh | C50: 78354/1 | D50: 45658 | E50: Salam Takaful | F50: KHI/HO/D/MO/PC COMP/C/105285/53/01/2025 | G50: 45688 | H50: 46052 | I50: MUHAMMAD NAVEED ASLAM | J50: 3310013529273 | K50: SUZUKI WAGON-R VXL E2 | L50: AHC-789 | M50: PK10B226253 | N50: A1J310PK10126253 | O50: 78354/1 | P50: Central | Q50: 0423 | R50: 669993 | S50: 45692 | T50: 46423 | U50: 2400000 | V50: - | W50: - | X50: 2400000 | Y50: 2 | Z50: 48000 | AC50: Paid | AD50: 1141072848 | AE50: 45722 | AF50: DISBURSED | AG50: 0 | AH50: 48000 | AI50: 0 | AK50: KHI/HO/D/MO/PC COMP/C/105285/53/01/2025 | AL50: 48000 | AM50: 0 | AN50: FRE
A51: 50 | B51: Fresh | C51: 78414/1 | D51: 45658 | E51: Salam Takaful | F51: KHI/HO/D/MO/PC COMP/C/105285/32/01/2025 | G51: 45684 | H51: 46048 | I51: SHAYAN ZAFAR QAZI | J51: 4210103032329 | K51: SUZUKI ALTO VXL AGS E-2 | L51: UN - REG | M51: 337664 | N51: 1237681 | O51: 78414/1 | P51: South | Q51: 0144 | R51: 669392 | S51: 45686 | T51: 47519 | U51: 3045000 | V51: - | W51: - | X51: 3045000 | Y51: 2 | Z51: 60900 | AC51: Paid | AD51: 1141072848 | AE51: 45722 | AF51: DISBURSED | AG51: 0 | AH51: 60900 | AI51: 0 | AK51: KHI/HO/D/MO/PC COMP/C/105285/32/01/2025 | AL51: 60900 | AM51: 0 | AN51: FRE
A52: 51 | B52: Fresh | C52: 78432/1 | D52: 45658 | E52: Salam Takaful | F52: KHI/HO/D/MO/PC COMP/C/105285/51/01/2025 | G52: 45688 | H52: 46052 | I52: SAMAMA BUKHARI | J52: 4210167686789 | K52: TOYOTA Yaris ATIV X 1.5 ( | L52: BSW-520 | M52: 16691 | N52: 9506751 | O52: 78432/1 | P52: South | Q52: 0150 | R52: 669128 | S52: 45691 | T52: 46788 | U52: 4150000 | V52: - | W52: - | X52: 4150000 | Y52: 1.5 | Z52: 62250 | AC52: Paid | AD52: 1141072848 | AE52: 45722 | AF52: DISBURSED | AG52: 0 | AH52: 62250 | AI52: 0 | AK52: KHI/HO/D/MO/PC COMP/C/105285/51/01/2025 | AL52: 62250 | AM52: 0 | AN52: FRE
...

Sheet Renewal
A1: S.No. | B1: Renewal | C1: Proposal No. | D1: Billing Month | E1: Takaful Company | F1: PMD / Cert | G1: Takaful Start Date | H1: Takaful End Date | I1: Customer Name | J1: CNIC | K1: Vehicle Make | L1: Reg. No | M1: Engine No | N1: Chassis No | O1: Proposal No. | P1: Region | Q1: Unit ID | R1: BR # | S1: Financing Date | T1: Maturity Date | U1: Asset Value | V1: Dep. % | W1: Dep. Amount | X1: New Sum Cover Amount | Y1: Takaful Rate | Z1: New Premium Amount | AA1: ALBARAKA Status | AB1: For Takaful Company Rectifications | AC1: For COD Status | AD1: PO No. | AE1: PO Dates | AF1: Proposal Status | AG1: DPD | AH1: Policy No. | AI1: TMS Premium | AJ1: Difference Amount | AK1: Tagging
A2: 1 | B2: Renewal | C2: 34942/1 | D2: 45627 | E2: SALAAM TAKAFUL LTD | F2: KHI/HO/D/MO/PC COMP/C/103764/162/12/2024 | G2: 45657 | H2: 46021 | I2: CHAUDHRY SHUJA ABBAS | J2: 3540117990095 | K2: SUZUKI CULTUS VXL | L2: LEA-19-5564 | M2: 132250 | N2: 10032251 | O2: 34942/1 | P2: Central | Q2: 0318 | R2: 429367 | S2: 43481 | T2: 46058 | U2: 1531000 | V2: 35 | W2: 535850 | X2: 995150 | Y2: 3.75 | Z2: 37318.125 | AC2: paid | AD2: 1141072794 | AE2: 45720 | AF2: DISBURSED | AG2: 0 | AH2: KHI/HO/D/MO/PC COMP/C/103764/162/12/2024 | AI2: 37318 | AJ2: -0.125 | AK2: REN
A3: 2 | B3: Renewal | C3: 34765/1 | D3: 45627 | E3: Salam Takaful | F3: KHI/HO/D/MO/PC COMP/C/103764/161/12/2024 | G3: 45657 | H3: 46021 | I3: MUHAMMAD YOUSUF | J3: 4130871473665 | K3: SUZUKI MEHRAN VXR | L3: BPM-320 | M3: 761900 | N3: 1300430 | O3: 34765/1 | P3: South | Q3: 0251 | R3: 433701 | S3: 43502 | T3: 46058 | U3: 840000 | V3: 35 | W3: 294000 | X3: 546000 | Y3: 3.75 | Z3: 20475 | AC3: paid | AD3: 1141072794 | AE3: 45720 | AF3: DISBURSED | AG3: 0 | AH3: KHI/HO/D/MO/PC COMP/C/103764/161/12/2024 | AI3: 20475 | AJ3: 0 | AK3: REN
A4: 3 | B4: Renewal | C4: 39968/1 | D4: 45658 | E4: Salam Takaful | F4: KHI/HO/D/MO/PC COMP/C/105499/92/01/2025 | G4: 45682 | H4: 46046 | I4: AMIR ZEB | J4: 1560264311279 | K4: TOYOTA COROLLA ALTIS CVTI | L4: ALG-026 | M4: Q342909 | N4: 7042083 | O4: 39968/1 | P4: North | Q4: 0611 | R4: 458287 | S4: 43860 | T4: 46058 | U4: 3736500 | V4: 30 | W4: 1120950 | X4: 2615550 | Y4: 1.5 | Z4: 39233.25 | AC4: paid | AD4: 1141072794 | AE4: 45720 | AF4: DISBURSED | AG4: 12 | AH4: KHI/HO/D/MO/PC COMP/C/105499/92/01/2025 | AI4: 39233 | AJ4: -0.25 | AK4: REN
A5: 4 | B5: Renewal | C5: 42492/1 | D5: 45658 | E5: Salam Takaful | F5: KHI/HO/D/MO/PC COMP/C/105499/112/01/2025 | G5: 45662 | H5: 46026 | I5: AAMIR AHMED | J5: 4210178656269 | K5: TOYOTA HILUX REVO | L5: KZ-4681 | M5: 1GD0905565 | N5: 5542349 | O5: 42492/1 | P5: South | Q5: 0144 | R5: 246846 | S5: 44202 | T5: 46027 | U5: 7048500 | V5: 25 | W5: 1762125 | X5: 5286375 | Y5: 1.5 | Z5: 79295.625 | AC5: paid | AD5: 1141072794 | AE5: 45720 | AF5: DISBURSED | AG5: 0 | AH5: KHI/HO/D/MO/PC COMP/C/105499/112/01/2025 | AI5: 79296 | AJ5: 0.375 | AK5: REN
A6: 5 | B6: Renewal | C6: 44126/1 | D6: 45658 | E6: Salam Takaful | F6: KHI/HO/D/MO/PC COMP/C/105499/95/01/2025 | G6: 45661 | H6: 46025 | I6: RAFAQAT ALI | J6: 3520132084129 | K6: SUZUKI WAGON-R VXL E2 | L6: ABL-644 | M6: 208908 | N6: 10108874 | O6: 44126/1 | P6: Central | Q6: 0329 | R6: 506416 | S6: 44201 | T6: 46027 | U6: 1730000 | V6: 25 | W6: 432500 | X6: 1297500 | Y6: 2.5 | Z6: 32437.5 | AC6: paid | AD6: 1141072794 | AE6: 45720 | AF6: DISBURSED | AG6: 0 | AH6: KHI/HO/D/MO/PC COMP/C/105499/95/01/2025 | AI6: 32438 | AJ6: 0.5 | AK6: REN
A7: 6 | B7: Renewal | C7: 45647/1 | D7: 45658 | E7: Salam Takaful | F7: KHI/HO/D/MO/PC COMP/C/105499/128/01/2025 | G7: 45665 | H7: 46029 | I7: MUHAMMAD FAHIM | J7: 6110118124727 | K7: SUZUKI ALTO VXR | L7: ASE-266 | M7: 150841 | N7: 1050819 | O7: 45647/1 | P7: North | Q7: 0804 | R7: 451846 | S7: 44214 | T7: 46058 | U7: 1433000 | V7: 25 | W7: 358250 | X7: 1074750 | Y7: 2.5 | Z7: 26868.75 | AC7: paid | AD7: 1141072794 | AE7: 45720 | AF7: DISBURSED | AG7: 42 | AH7: KHI/HO/D/MO/PC COMP/C/105499/128/01/2025 | AI7: 26869 | AJ7: 0.25 | AK7: REN
A8: 7 | B8: Renewal | C8: 45658/1 | D8: 45658 | E8: Salam Takaful | F8: KHI/HO/D/MO/PC COMP/C/105499/127/01/2025 | G8: 45665 | H8: 46029 | I8: SHAHZAD RASOOL | J8: 3520251570147 | K8: TOYOTA YARIS ATIV X CVT | L8: LEB-20-345 | M8: 2A01581 | N8: R9501162 | O8: 45658/1 | P8: Central | Q8: 0329 | R8: 516625 | S8: 44208 | T8: 46027 | U8: 2950000 | V8: 25 | W8: 737500 | X8: 2212500 | Y8: 2.5 | Z8: 55312.5 | AC8: paid | AD8: 1141072794 | AE8: 45720 | AF8: DISBURSED | AG8: 12 | AH8: KHI/HO/D/MO/PC COMP/C/105499/127/01/2025 | AI8: 55313 | AJ8: 0.5 | AK8: REN
A9: 8 | B9: Renewal | C9: 45768/1 | D9: 45658 | E9: Salam Takaful | F9: KHI/HO/D/MO/PC COMP/C/105499/130/01/2025 | G9: 45675 | H9: 46039 | I9: WAQAR KHAN | J9: 3740552187743 | K9: SUZUKI MEHRAN VXR EURO-II | L9: RIC-201 | M9: 763116 | N9: 01301665 | O9: 45768/1 | P9: North | Q9: 0804 | R9: 424831 | S9: 44228 | T9: 46058 | U9: 950000 | V9: 25 | W9: 237500 | X9: 712500 | Y9: 2.5 | Z9: 17812.5 | AC9: paid | AD9: 1141072794 | AE9: 45720 | AF9: DISBURSED | AG9: 74 | AH9: KHI/HO/D/MO/PC COMP/C/105499/130/01/2025 | AI9: 17813 | AJ9: 0.5 | AK9: REN
A10: 9 | B10: Renewal | C10: 45831/1 | D10: 45658 | E10: Salam Takaful | F10: KHI/HO/D/MO/PC COMP/C/105499/129/01/2025 | G10: 45675 | H10: 46039 | I10: EJAZ AHMED | J10: 3520112694847 | K10: TOYOTA COROLLA GLI M/T 1. | L10: LEA-20-5910 | M10: 570005 | N10: 4198301 | O10: 45831/1 | P10: Central | Q10: 0329 | R10: 518248 | S10: 44218 | T10: 46058 | U10: 3170000 | V10: 25 | W10: 792500 | X10: 2377500 | Y10: 2.5 | Z10: 59437.5 | AC10: paid | AD10: 1141072794 | AE10: 45720 | AF10: DISBURSED | AG10: 0 | AH10: KHI/HO/D/MO/PC COMP/C/105499/129/01/2025 | AI10: 59438 | AJ10: 0.5 | AK10: REN
A11: 10 | B11: Renewal | C11: 45872/1 | D11: 45658 | E11: Salam Takaful | F11: KHI/HO/D/MO/PC COMP/C/105499/131/01/2025 | G11: 45677 | H11: 46041 | I11: RAFAQAT MASIH | J11: 3520299931739 | K11: SUZUKI BOLAN STD VX EURO | L11: ABV-211 | M11: 1008524 | N11: 1125039 | O11: 45872/1 | P11: Central | Q11: 0321 | R11: 490749 | S11: 44224 | T11: 46058 | U11: 1134000 | V11: 25 | W11: 283500 | X11: 850500 | Y11: 2.5 | Z11: 21262.5 | AC11: paid | AD11: 1141072794 | AE11: 45720 | AF11: DISBURSED | AG11: 12 | AH11: KHI/HO/D/MO/PC COMP/C/105499/131/01/2025 | AI11: 21263 | AJ11: 0.5 | AK11: REN
A12: 11 | B12: Renewal | C12: 45930/1 | D12: 45658 | E12: Salam Takaful | F12: KHI/HO/D/MO/PC COMP/C/105499/96/01/2025 | G12: 45682 | H12: 46046 | I12: NADEEM ABBAS | J12: 3520134949549 | K12: SUZUKI ALTO VXR | L12: ABV-556 | M12: 150925 | N12: 1050908 | O12: 45930/1 | P12: Central | Q12: 0329 | R12: 517834 | S12: 44224 | T12: 46788 | U12: 1433000 | V12: 25 | W12: 358250 | X12: 1074750 | Y12: 2.5 | Z12: 26868.75 | AC12: paid | AD12: 1141072794 | AE12: 45720 | AF12: DISBURSED | AG12: 42 | AH12: KHI/HO/D/MO/PC COMP/C/105499/96/01/2025 | AI12: 26869 | AJ12: 0.25 | AK12: REN
A13: 12 | B13: Renewal | C13: 45932/1 | D13: 45658 | E13: Salam Takaful | F13: KHI/HO/D/MO/PC COMP/C/105499/99/01/2025 | G13: 45683 | H13: 46047 | I13: NADEEM YOUNAS | J13: 3520228530955 | K13: HONDA CITY I-VTEC A/T PT | L13: LEH-14-1041 | M13: 7420945 | N13: R-157341 | O13: 45932/1 | P13: Central | Q13: 0329 | R13: 516469 | S13: 44224 | T13: 46058 | U13: 1850000 | V13: 25 | W13: 462500 | X13: 1387500 | Y13: 2.5 | Z13: 34687.5 | AC13: paid | AD13: 1141072794 | AE13: 45720 | AF13: DISBURSED | AG13: 0 | AH13: KHI/HO/D/MO/PC COMP/C/105499/99/01/2025 | AI13: 34688 | AJ13: 0.5 | AK13: REN
... A194: 193 | B194: Renewal | C194: 70207/3 | D194: 45658 | E194: Salam Takaful | F194: KHI/HO/D/MO/PC COMP/C/105499/23/01/2025 | G194: 45687 | H194: 46051 | I194: AHMAD BILAL | J194: 3520229215671 | K194: HAVAL GWM | L194: LEB-17A-612 | M194: Z12923041 | N194: HR026296 | O194: 70207/3 | P194: Central | Q194: 0329 | R194: 635140 | S194: 45328 | T194: 46788 | U194: 4900000 | V194: 10 | W194: 490000 | X194: 4410000 | Y194: 1.5 | Z194: 66150 | AC194: paid | AD194: 1141072794 | AE194: 45720 | AF194: DISBURSED | AG194: 12 | AH194: KHI/HO/D/MO/PC COMP/C/105499/23/01/2025 | AI194: 66150 | AJ194: 0 | AK194: REN
AH195: KHI/HO/D/MO/PC COMP/C/105285/10/01/2025 | AI195: 71400 | AJ195: 0 | AK195: FRE
AH196: KHI/HO/D/MO/PC COMP/C/105285/11/01/2025 | AI196: 70785 | AJ196: 0 | AK196: FRE
AH197: KHI/HO/D/MO/PC COMP/C/105285/28/01/2025 | AI197: 63000 | AJ197: 0 | AK197: FRE
AH198: KHI/HO/D/MO/PC COMP/C/105285/25/01/2025 | AI198: 76770 | AJ198: 0 | AK198: FRE
AH199: KHI/HO/D/MO/PC COMP/C/105285/46/01/2025 | AI199: 63000 | AJ199: 0 | AK199: FRE
AH200: KHI/HO/D/MO/PC COMP/C/105285/2/01/2025 | AI200: 112500 | AJ200: 0 | AK200: FRE
AH201: KHI/HO/D/MO/PC COMP/C/105285/6/01/2025 | AI201: 60980 | AJ201: 0 | AK201: FRE
AH202: KHI/HO/D/MO/PC COMP/C/105285/57/01/2025 | AI202: 61500 | AJ202: 0 | AK202: FRE
AH203: KHI/HO/D/MO/PC COMP/C/105285/20/01/2025 | AI203: 43000 | AJ203: 0 | AK203: FRE
AH204: KHI/HO/D/MO/PC COMP/C/105285/21/01/2025 | AI204: 43000 | AJ204: 0 | AK204: FRE
AH205: KHI/HO/D/MO/PC COMP/C/105285/1/01/2025 | AI205: 44000 | AJ205: 0 | AK205: FRE
AH206: KHI/HO/D/MO/PC COMP/C/105285/16/01/2025 | AI206: 54140 | AJ206: 0 | AK206: FRE
... AH250: KHI/HO/D/MO/PC COMP/C/105285/55/01/2025 | AI250: 52000 | AJ250: 0 | AK250: FRE
AI251: =SUM(AI2:AI250) -> 11390231

Sheet working
A1: POLICY NO. | B1: Assorted_code | D1: Premium | E1: 06Mar250008
A2: KHI/HO/D/MO/PC COMP/C/103764/162/12/2024 | B2: =VLOOKUP(A2,policy!B:C,2,0) -> 070000172495 | C2: 37318 | D2: =ROUND(C2,0) -> 37318 | E2: 06Mar250008 | F2: ="insert into ins_premium_det (premium_rcv_code,assorted_code, rec_amount,premium_rcv_detail_code,remaining_amt, payrec, mode_code,coinsurance_code,class_cd,it_remarks) values" -> insert into ins_premium_det (premium_rcv_code,assorted_code, rec_amount,premium_rcv_detail_code,remaining_amt, payrec, mode_code,coinsurance_code,class_cd,it_remarks) values | G2: ="('"&E2&"','"&B2&"','"&D2&"',(select max(to_number(i.premium_rcv_detail_code))+1 from ins_premium_det i),'"&D2&"','"&D2&"','02', '11000003','00','Request by Mr. Saqib Saleem 06-Mar-2024');" -> ('06Mar250008','070000172495','37318',(select max(to_number(i.premium_rcv_detail_code))+1 from ins_premium_det i),'37318','37318','02', '11000003','00','Request by Mr. Saqib Saleem 06-Mar-2024'); | H2: =F2&G2 -> insert into ins_premium_det (premium_rcv_code,assorted_code, rec_amount,premium_rcv_detail_code,remaining_amt, payrec, mode_code,coinsurance_code,class_cd,it_remarks) values('06Mar250008','070000172495','37318',(select max(to_number(i.premium_rcv_detail_code))+1 from ins_premium_det i),'37318','37318','02', '11000003','00','Request by Mr. Saqib Saleem 06-Mar-2024');
A3: KHI/HO/D/MO/PC COMP/C/103764/161/12/2024 | B3: =VLOOKUP(A3,policy!B:C,2,0) -> 070000172494 | C3: 20475 | D3: =ROUND(C3,0) -> 20475 | E3: 06Mar250008 | F3: ="insert into ins_premium_det (premium_rcv_code,assorted_code, rec_amount,premium_rcv_detail_code,remaining_amt, payrec, mode_code,coinsurance_code,class_cd,it_remarks) values" -> insert into ins_premium_det (premium_rcv_code,assorted_code, rec_amount,premium_rcv_detail_code,remaining_amt, payrec, mode_code,coinsurance_code,class_cd,it_remarks) values | G3: ="('"&E3&"','"&B3&"','"&D3&"',(select max(to_number(i.premium_rcv_detail_code))+1 from ins_premium_det i),'"&D3&"','"&D3&"','02', '11000003','00','Request by Mr. Saqib Saleem 06-Mar-2024');" -> ('06Mar250008','070000172494','20475',(select max(to_number(i.premium_rcv_detail_code))+1 from ins_premium_det i),'20475','20475','02', '11000003','00','Request by Mr. Saqib Saleem 06-Mar-2024'); | H3: =F3&G3 -> insert into ins_premium_det (premium_rcv_code,assorted_code, rec_amount,premium_rcv_detail_code,remaining_amt, payrec, mode_code,coinsurance_code,class_cd,it_remarks) values('06Mar250008','070000172494','20475',(select max(to_number(i.premium_rcv_detail_code))+1 from ins_premium_det i),'20475','20475','02', '11000003','00','Request by Mr. Saqib Saleem 06-Mar-2024');
A4: KHI/HO/D/MO/PC COMP/C/105499/92/01/2025 | B4: =VLOOKUP(A4,policy!B:C,2,0) -> 070000174295 | C4: 39233 | D4: =ROUND(C4,0) -> 39233 | E4: 06Mar250008 | F4: ="insert into ins_premium_det (premium_rcv_code,assorted_code, rec_amount,premium_rcv_detail_code,remaining_amt, payrec, mode_code,coinsurance_code,class_cd,it_remarks) values" -> insert into ins_premium_det (premium_rcv_code,assorted_code, rec_amount,premium_rcv_detail_code,remaining_amt, payrec, mode_code,coinsurance_code,class_cd,it_remarks) values | G4: ="('"&E4&"','"&B4&"','"&D4&"',(select max(to_number(i.premium_rcv_detail_code))+1 from ins_premium_det i),'"&D4&"','"&D4&"','02', '11000003','00','Request by Mr. Saqib Saleem 06-Mar-2024');" -> ('06Mar250008','070000174295','39233',(select max(to_number(i.premium_rcv_detail_code))+1 from ins_premium_det i),'39233','39233','02', '11000003','00','Request by Mr. Saqib Saleem 06-Mar-2024'); | H4: =F4&G4 -> insert into ins_premium_det (premium_rcv_code,assorted_code, rec_amount,premium_rcv_detail_code,remaining_amt, payrec, mode_code,coinsurance_code,class_cd,it_remarks) values('06Mar250008','070000174295','39233',(select max(to_number(i.premium_rcv_detail_code))+1 from ins_premium_det i),'39233','39233','02', '11000003','00','Request by Mr. Saqib Saleem 06-Mar-2024');
A5: KHI/HO/D/MO/PC COMP/C/105499/112/01/2025 | B5: =VLOOKUP(A5,policy!B:C,2,0) -> 070000174315 | C5: 79296 | D5: =ROUND(C5,0) -> 79296 | E5: 06Mar250008 | F5: ="insert into ins_premium_det (premium_rcv_code,assorted_code, rec_amount,premium_rcv_detail_code,remaining_amt, payrec, mode_code,coinsurance_code,class_cd,it_remarks) values" -> insert into ins_premium_det (premium_rcv_code,assorted_code, rec_amount,premium_rcv_detail_code,remaining_amt, payrec, mode_code,coinsurance_code,class_cd,it_remarks) values | G5: ="('"&E5&"','"&B5&"','"&D5&"',(select max(to_number(i.premium_rcv_detail_code))+1 from ins_premium_det i),'"&D5&"','"&D5&"','02', '11000003','00','Request by Mr. Saqib Saleem 06-Mar-2024');" -> ('06Mar250008','070000174315','79296',(select max(to_number(i.premium_rcv_detail_code))+1 from ins_premium_det i),'79296','79296','02', '11000003','00','Request by Mr. Saqib Saleem 06-Mar-2024'); | H5: =F5&G5 -> insert into ins_premium_det (premium_rcv_code,assorted_code, rec_amount,premium_rcv_detail_code,remaining_amt, payrec, mode_code,coinsurance_code,class_cd,it_remarks) values('06Mar250008','070000174315','79296',(select max(to_number(i.premium_rcv_detail_code))+1 from ins_premium_det i),'79296','79296','02', '11000003','00','Request by Mr. Saqib Saleem 06-Mar-2024');
A6: KHI/HO/D/MO/PC COMP/C/105499/95/01/2025 | B6: =VLOOKUP(A6,policy!B:C,2,0) -> 070000174298 | C6: 32438 | D6: =ROUND(C6,0) -> 32438 | E6: 06Mar250008 | F6: ="insert into ins_premium_det (premium_rcv_code,assorted_code, rec_amount,premium_rcv_detail_code,remaining_amt, payrec, mode_code,coinsurance_code,class_cd,it_remarks) values" -> insert into ins_premium_det (premium_rcv_code,assorted_code, rec_amount,premium_rcv_detail_code,remaining_amt, payrec, mode_code,coinsurance_code,class_cd,it_remarks) values | G6: ="('"&E6&"','"&B6&"','"&D6&"',(select max(to_number(i.premium_rcv_detail_code))+1 from ins_premium_det i),'"&D6&"','"&D6&"','02', '11000003','00','Request by Mr. Saqib Saleem 06-Mar-2024');" -> ('06Mar250008','070000174298','32438',(select max(to_number(i.premium_rcv_detail_code))+1 from ins_premium_det i),'32438','32438','02', '11000003','00','Request by Mr. Saqib Saleem 06-Mar-2024'); | H6: =F6&G6 -> insert into ins_premium_det (premium_rcv_code,assorted_code, rec_amount,premium_rcv_detail_code,remaining_amt, payrec, mode_code,coinsurance_code,class_cd,it_remarks) values('06Mar250008','070000174298','32438',(select max(to_number(i.premium_rcv_detail_code))+1 from ins_premium_det i),'32438','32438','02', '11000003','00','Request by Mr. Saqib Saleem 06-Mar-2024');
A7: KHI/HO/D/MO/PC COMP/C/105499/128/01/2025 | B7: =VLOOKUP(A7,policy!B:C,2,0) -> 070000174331 | C7: 26869 | D7: =ROUND(C7,0) -> 26869 | E7: 06Mar250008 | F7: ="insert into ins_premium_det (premium_rcv_code,assorted_code, rec_amount,premium_rcv_detail_code,remaining_amt, payrec, mode_code,coinsurance_code,class_cd,it_remarks) values" -> insert into ins_premium_det (premium_rcv_code,assorted_code, rec_amount,premium_rcv_detail_code,remaining_amt, payrec, mode_code,coinsurance_code,class_cd,it_remarks) values | G7: ="('"&E7&"','"&B7&"','"&D7&"',(select max(to_number(i.premium_rcv_detail_code))+1 from ins_premium_det i),'"&D7&"','"&D7&"','02', '11000003','00','Request by Mr. Saqib Saleem 06-Mar-2024');" -> ('06Mar250008','070000174331','26869',(select max(to_number(i.premium_rcv_detail_code))+1 from ins_premium_det i),'26869','26869','02', '11000003','00','Request by Mr. Saqib Saleem 06-Mar-2024'); | H7: =F7&G7 -> insert into ins_premium_det (premium_rcv_code,assorted_code, rec_amount,premium_rcv_detail_code,remaining_amt, payrec, mode_code,coinsurance_code,class_cd,it_remarks) values('06Mar250008','070000174331','26869',(select max(to_number(i.premium_rcv_detail_code))+1 from ins_premium_det i),'26869','26869','02', '11000003','00','Request by Mr. Saqib Saleem 06-Mar-2024');
A8: KHI/HO/D/MO/PC COMP/C/105499/127/01/2025 | B8: =VLOOKUP(A8,policy!B:C,2,0) -> 070000174330 | C8: 55313 | D8: =ROUND(C8,0) -> 55313 | E8: 06Mar250008 | F8: ="insert into ins_premium_det (premium_rcv_code,assorted_code, rec_amount,premium_rcv_detail_code,remaining_amt, payrec, mode_code,coinsurance_code,class_cd,it_remarks) values" -> insert into ins_premium_det (premium_rcv_code,assorted_code, rec_amount,premium_rcv_detail_code,remaining_amt, payrec, mode_code,coinsurance_code,class_cd,it_remarks) values | G8: ="('"&E8&"','"&B8&"','"&D8&"',(select max(to_number(i.premium_rcv_detail_code))+1 from ins_premium_det i),'"&D8&"','"&D8&"','02', '11000003','00','Request by Mr. Saqib Saleem 06-Mar-2024');" -> ('06Mar250008','070000174330','55313',(select max(to_number(i.premium_rcv_detail_code))+1 from ins_premium_det i),'55313','55313','02', '11000003','00','Request by Mr. Saqib Saleem 06-Mar-2024'); | H8: =F8&G8 -> insert into ins_premium_det (premium_rcv_code,assorted_code, rec_amount,premium_rcv_detail_code,remaining_amt, payrec, mode_code,coinsurance_code,class_cd,it_remarks) values('06Mar250008','070000174330','55313',(select max(to_number(i.premium_rcv_detail_code))+1 from ins_premium_det i),'55313','55313','02', '11000003','00','Request by Mr. Saqib Saleem 06-Mar-2024');
A9: KHI/HO/D/MO/PC COMP/C/105499/130/01/2025 | B9: =VLOOKUP(A9,policy!B:C,2,0) -> 070000174333 | C9: 17813 | D9: =ROUND(C9,0) -> 17813 | E9: 06Mar250008 | F9: ="insert into ins_premium_det (premium_rcv_code,assorted_code, rec_amount,premium_rcv_detail_code,remaining_amt, payrec, mode_code,coinsurance_code,class_cd,it_remarks) values" -> insert into ins_premium_det (premium_rcv_code,assorted_code, rec_amount,premium_rcv_detail_code,remaining_amt, payrec, mode_code,coinsurance_code,class_cd,it_remarks) values | G9: ="('"&E9&"','"&B9&"','"&D9&"',(select max(to_number(i.premium_rcv_detail_code))+1 from ins_premium_det i),'"&D9&"','"&D9&"','02', '11000003','00','Request by Mr. Saqib Saleem 06-Mar-2024');" -> ('06Mar250008','070000174333','17813',(select max(to_number(i.premium_rcv_detail_code))+1 from ins_premium_det i),'17813','17813','02', '11000003','00','Request by Mr. Saqib Saleem 06-Mar-2024'); | H9: =F9&G9 -> insert into ins_premium_det (premium_rcv_code,assorted_code, rec_amount,premium_rcv_detail_code,remaining_amt, payrec, mode_code,coinsurance_code,class_cd,it_remarks) values('06Mar250008','070000174333','17813',(select max(to_number(i.premium_rcv_detail_code))+1 from ins_premium_det i),'17813','17813','02', '11000003','00','Request by Mr. Saqib Saleem 06-Mar-2024');
A10: KHI/HO/D/MO/PC COMP/C/105499/129/01/2025 | B10: =VLOOKUP(A10,policy!B:C,2,0) -> 070000174332 | C10: 59438 | D10: =ROUND(C10,0) -> 59438 | E10: 06Mar250008 | F10: ="insert into ins_premium_det (premium_rcv_code,assorted_code, rec_amount,premium_rcv_detail_code,remaining_amt, payrec, mode_code,coinsurance_code,class_cd,it_remarks) values" -> insert into ins_premium_det (premium_rcv_code,assorted_code, rec_amount,premium_rcv_detail_code,remaining_amt, payrec, mode_code,coinsurance_code,class_cd,it_remarks) values | G10: ="('"&E10&"','"&B10&"','"&D10&"',(select max(to_number(i.premium_rcv_detail_code))+1 from ins_premium_det i),'"&D10&"','"&D10&"','02', '11000003','00','Request by Mr. Saqib Saleem 06-Mar-2024');" -> ('06Mar250008','070000174332','59438',(select max(to_number(i.premium_rcv_detail_code))+1 from ins_premium_det i),'59438','59438','02', '11000003','00','Request by Mr. Saqib Saleem 06-Mar-2024'); | H10: =F10&G10 -> insert into ins_premium_det (premium_rcv_code,assorted_code, rec_amount,premium_rcv_detail_code,remaining_amt, payrec, mode_code,coinsurance_code,class_cd,it_remarks) values('06Mar250008','070000174332','59438',(select max(to_number(i.premium_rcv_detail_code))+1 from ins_premium_det i),'59438','59438','02', '11000003','00','Request by Mr. Saqib Saleem 06-Mar-2024');
A11: KHI/HO/D/MO/PC COMP/C/105499/131/01/2025 | B11: =VLOOKUP(A11,policy!B:C,2,0) -> 070000174334 | C11: 21263 | D11: =ROUND(C11,0) -> 21263 | E11: 06Mar250008 | F11: ="insert into ins_premium_det (premium_rcv_code,assorted_code, rec_amount,premium_rcv_detail_code,remaining_amt, payrec, mode_code,coinsurance_code,class_cd,it_remarks) values" -> insert into ins_premium_det (premium_rcv_code,assorted_code, rec_amount,premium_rcv_detail_code,remaining_amt, payrec, mode_code,coinsurance_code,class_cd,it_remarks) values | G11: ="('"&E11&"','"&B11&"','"&D11&"',(select max(to_number(i.premium_rcv_detail_code))+1 from ins_premium_det i),'"&D11&"','"&D11&"','02', '11000003','00','Request by Mr. Saqib Saleem 06-Mar-2024');" -> ('06Mar250008','070000174334','21263',(select max(to_number(i.premium_rcv_detail_code))+1 from ins_premium_det i),'21263','21263','02', '11000003','00','Request by Mr. Saqib Saleem 06-Mar-2024'); | H11: =F11&G11 -> insert into ins_premium_det (premium_rcv_code,assorted_code, rec_amount,premium_rcv_detail_code,remaining_amt, payrec, mode_code,coinsurance_code,class_cd,it_remarks) values('06Mar250008','070000174334','21263',(select max(to_number(i.premium_rcv_detail_code))+1 from ins_premium_det i),'21263','21263','02', '11000003','00','Request by Mr. Saqib Saleem 06-Mar-2024');
A12: KHI/HO/D/MO/PC COMP/C/105499/96/01/2025 | B12: =VLOOKUP(A12,policy!B:C,2,0) -> 070000174299 | C12: 26869 | D12: =ROUND(C12,0) -> 26869 | E12: 06Mar250008 | F12: ="insert into ins_premium_det (premium_rcv_code,assorted_code, rec_amount,premium_rcv_detail_code,remaining_amt, payrec, mode_code,coinsurance_code,class_cd,it_remarks) values" -> insert into ins_premium_det (premium_rcv_code,assorted_code, rec_amount,premium_rcv_detail_code,remaining_amt, payrec, mode_code,coinsurance_code,class_cd,it_remarks) values | G12: ="('"&E12&"','"&B12&"','"&D12&"',(select max(to_number(i.premium_rcv_detail_code))+1 from ins_premium_det i),'"&D12&"','"&D12&"','02', '11000003','00','Request by Mr. Saqib Saleem 06-Mar-2024');" -> ('06Mar250008','070000174299','26869',(select max(to_number(i.premium_rcv_detail_code))+1 from ins_premium_det i),'26869','26869','02', '11000003','00','Request by Mr. Saqib Saleem 06-Mar-2024'); | H12: =F12&G12 -> insert into ins_premium_det (premium_rcv_code,assorted_code, rec_amount,premium_rcv_detail_code,remaining_amt, payrec, mode_code,coinsurance_code,class_cd,it_remarks) values('06Mar250008','070000174299','26869',(select max(to_number(i.premium_rcv_detail_code))+1 from ins_premium_det i),'26869','26869','02', '11000003','00','Request by Mr. Saqib Saleem 06-Mar-2024');
A13: KHI/HO/D/MO/PC COMP/C/105499/99/01/2025 | B13: =VLOOKUP(A13,policy!B:C,2,0) -> 070000174302 | C13: 34688 | D13: =ROUND(C13,0) -> 34688 | E13: 06Mar250008 | F13: ="insert into ins_premium_det (premium_rcv_code,assorted_code, rec_amount,premium_rcv_detail_code,remaining_amt, payrec, mode_code,coinsurance_code,class_cd,it_remarks) values" -> insert into ins_premium_det (premium_rcv_code,assorted_code, rec_amount,premium_rcv_detail_code,remaining_amt, payrec, mode_code,coinsurance_code,class_cd,it_remarks) values | G13: ="('"&E13&"','"&B13&"','"&D13&"',(select max(to_number(i.premium_rcv_detail_code))+1 from ins_premium_det i),'"&D13&"','"&D13&"','02', '11000003','00','Request by Mr. Saqib Saleem 06-Mar-2024');" -> ('06Mar250008','070000174302','34688',(select max(to_number(i.premium_rcv_detail_code))+1 from ins_premium_det i),'34688','34688','02', '11000003','00','Request by Mr. Saqib Saleem 06-Mar-2024'); | H13: =F13&G13 -> insert into ins_premium_det (premium_rcv_code,assorted_code, rec_amount,premium_rcv_detail_code,remaining_amt, payrec, mode_code,coinsurance_code,class_cd,it_remarks) values('06Mar250008','070000174302','34688',(select max(to_number(i.premium_rcv_detail_code))+1 from ins_premium_det i),'34688','34688','02', '11000003','00','Request by Mr. Saqib Saleem 06-Mar-2024');
... A250: KHI/HO/D/MO/PC COMP/C/105285/55/01/2025 | B250: =VLOOKUP(A250,policy!B:C,2,0) -> 070000176346 | C250: 52000 | D250: =ROUND(C250,0) -> 52000 | E250: 06Mar250008 | F250: ="insert into ins_premium_det (premium_rcv_code,assorted_code, rec_amount,premium_rcv_detail_code,remaining_amt, payrec, mode_code,coinsurance_code,class_cd,it_remarks) values" -> insert into ins_premium_det (premium_rcv_code,assorted_code, rec_amount,premium_rcv_detail_code,remaining_amt, payrec, mode_code,coinsurance_code,class_cd,it_remarks) values | G250: ="('"&E250&"','"&B250&"','"&D250&"',(select max(to_number(i.premium_rcv_detail_code))+1 from ins_premium_det i),'"&D250&"','"&D250&"','02', '11000003','00','Request by Mr. Saqib Saleem 06-Mar-2024');" -> ('06Mar250008','070000176346','52000',(select max(to_number(i.premium_rcv_detail_code))+1 from ins_premium_det i),'52000','52000','02', '11000003','00','Request by Mr. Saqib Saleem 06-Mar-2024'); | H250: =F250&G250 -> insert into ins_premium_det (premium_rcv_code,assorted_code, rec_amount,premium_rcv_detail_code,remaining_amt, payrec, mode_code,coinsurance_code,class_cd,it_remarks) values('06Mar250008','070000176346','52000',(select max(to_number(i.premium_rcv_detail_code))+1 from ins_premium_det i),'52000','52000','02', '11000003','00','Request by Mr. Saqib Saleem 06-Mar-2024');

Sheet Sheet2
A1: KHI/HO/D/MO/PC COMP/C/103764/162/12/2024 | B1: -12-2024 | H1: 103764 | I1: 00162 | J1: ="ia.assorted_string like '%"&H1&"-"&I1&B1&"%' or" -> ia.assorted_string like '%103764-00162-12-2024%' or
A2: KHI/HO/D/MO/PC COMP/C/103764/161/12/2024 | B2: -12-2024 | H2: 103764 | I2: 00161 | J2: ="ia.assorted_string like '%"&H2&"-"&I2&B2&"%' or" -> ia.assorted_string like '%103764-00161-12-2024%' or
A3: KHI/HO/D/MO/PC COMP/C/105499/92/01/2025 | B3: -01-2025 | H3: 105499 | I3: 00092 | J3: ="ia.assorted_string like '%"&H3&"-"&I3&B3&"%' or" -> ia.assorted_string like '%105499-00092-01-2025%' or
A4: KHI/HO/D/MO/PC COMP/C/105499/112/01/2025 | B4: -01-2025 | H4: 105499 | I4: 00112 | J4: ="ia.assorted_string like '%"&H4&"-"&I4&B4&"%' or" -> ia.assorted_string like '%105499-00112-01-2025%' or
A5: KHI/HO/D/MO/PC COMP/C/105499/95/01/2025 | B5: -01-2025 | H5: 105499 | I5: 00095 | J5: ="ia.assorted_string like '%"&H5&"-"&I5&B5&"%' or" -> ia.assorted_string like '%105499-00095-01-2025%' or
A6: KHI/HO/D/MO/PC COMP/C/105499/128/01/2025 | B6: -01-2025 | H6: 105499 | I6: 00128 | J6: ="ia.assorted_string like '%"&H6&"-"&I6&B6&"%' or" -> ia.assorted_string like '%105499-00128-01-2025%' or
A7: KHI/HO/D/MO/PC COMP/C/105499/127/01/2025 | B7: -01-2025 | H7: 105499 | I7: 00127 | J7: ="ia.assorted_string like '%"&H7&"-"&I7&B7&"%' or" -> ia.assorted_string like '%105499-00127-01-2025%' or
A8: KHI/HO/D/MO/PC COMP/C/105499/130/01/2025 | B8: -01-2025 | H8: 105499 | I8: 00130 | J8: ="ia.assorted_string like '%"&H8&"-"&I8&B8&"%' or" -> ia.assorted_string like '%105499-00130-01-2025%' or
A9: KHI/HO/D/MO/PC COMP/C/105499/129/01/2025 | B9: -01-2025 | H9: 105499 | I9: 00129 | J9: ="ia.assorted_string like '%"&H9&"-"&I9&B9&"%' or" -> ia.assorted_string like '%105499-00129-01-2025%' or
A10: KHI/HO/D/MO/PC COMP/C/105499/131/01/2025 | B10: -01-2025 | H10: 105499 | I10: 00131 | J10: ="ia.assorted_string like '%"&H10&"-"&I10&B10&"%' or" -> ia.assorted_string like '%105499-00131-01-2025%' or
A11: KHI/HO/D/MO/PC COMP/C/105499/96/01/2025 | B11: -01-2025 | H11: 105499 | I11: 00096 | J11: ="ia.assorted_string like '%"&H11&"-"&I11&B11&"%' or" -> ia.assorted_string like '%105499-00096-01-2025%' or
A12: KHI/HO/D/MO/PC COMP/C/105499/99/01/2025 | B12: -01-2025 | H12: 105499 | I12: 00099 | J12: ="ia.assorted_string like '%"&H12&"-"&I12&B12&"%' or" -> ia.assorted_string like '%105499-00099-01-2025%' or
... A249: KHI/HO/D/MO/PC COMP/C/105285/55/01/2025 | B249: -01-2025 | H249: 105285 | I249: 00055 | J249: ="ia.assorted_string like '%"&H249&"-"&I249&B249&"%' or" -> ia.assorted_string like '%105285-00055-01-2025%' or

Sheet policy
B1: FUNC_ASSORTED_STRING(IA.ASSORTED_CODE) | C1: ASSORTED_CODE
A2: 1 | B2: KHI/HO/D/MO/PC COMP/C/105285/56/01/2025 | C2: 070000176357
A3: 2 | B3: KHI/HO/D/MO/PC COMP/C/105285/19/01/2025 | C3: 070000174115
A4: 3 | B4: KHI/HO/D/MO/PC COMP/C/105285/10/01/2025 | C4: 070000173925
A5: 4 | B5: KHI/HO/D/MO/PC COMP/C/105285/28/01/2025 | C5: 070000174438
A6: 5 | B6: KHI/HO/D/MO/PC COMP/C/105285/17/01/2025 | C6: 070000174112
A7: 6 | B7: KHI/HO/D/MO/CV/C/106061/2/01/2025 | C7: 070000174088
A8: 7 | B8: KHI/HO/D/MO/PC COMP/C/105285/15/01/2025 | C8: 070000174089
A9: 8 | B9: KHI/HO/D/MO/PC COMP/C/105285/46/01/2025 | C9: 070000176316
A10: 9 | B10: KHI/HO/D/MO/PC COMP/C/105285/33/01/2025 | C10: 070000174984
A11: 10 | B11: KHI/HO/D/MO/PC COMP/C/105285/23/01/2025 | C11: 070000174182
A12: 11 | B12: KHI/HO/D/MO/PC COMP/C/105285/31/01/2025 | C12: 070000174501
A13: 12 | B13: KHI/HO/D/MO/PC COMP/C/105285/52/01/2025 | C13: 070000176332
... A250: 249 | B250: KHI/HO/D/MO/PC COMP/C/105285/35/01/2025 | C250: 070000174996
