Workbook

Sheet Sheet1
A1: KHI/HO/D/HLGRP HEALTH/P/1732/08/2022
A2: KHI/HO/D/HLGRP HEALTH/P/2716/09/2023
A3: KHI/HO/D/HLGRP HEALTH/P/3311/09/2024

Sheet Sheet2
A2: ITECKNOLOGI TRACKING SERVICES (PVT) LIMITED | I2: Received Amount | J2: 3446810
A3: OUTSTANDING SUMMARY FOR KNOCK OFF AGAINST PAYABLE AMOUNT Email Dated: Fri 16-May-2025 4:21 pm (Raheel Malik) | I3: For Knock off: | J3: =+SUBTOTAL(9,J6:J48) -> 3446810
A5: S. NO. | B5: POLICY NUMBER | C5: ENDORSEMENT NUMBER | D5: ISSUE DATE | E5: PERIOD FROM | F5: PERIOD TO | G5: GROSS CONTRIBUTION | H5: NET CONTRIBUTION | I5: OUTSTANDNG CONTRIBUTION | J5: KNOCK OFF | K5: TYPE
A6: 1 | B6: KHI/HO/D/HLGRP HEALTH/P/1732/08/2022 | C6: KHI/HO/D/HLGRP HEALTH/E/16491/09/2022 | D6: 44832 | E6: 44805 | F6: 45169 | G6: -7748 | H6: -7825 | I6: -7825 | J6: -7825 | K6: ENDORSEMENT
A7: 2 | B7: KHI/HO/D/HLGRP HEALTH/P/1732/08/2022 | C7: KHI/HO/D/HLGRP HEALTH/E/19975/05/2023 | D7: 45077 | E7: 44805 | F7: 45169 | G7: -2525 | H7: -2550 | I7: -2550 | J7: -2550 | K7: ENDORSEMENT
A8: 3 | B8: KHI/HO/D/HLGRP HEALTH/P/1732/08/2022 | C8: KHI/HO/D/HLGRP HEALTH/E/20799/07/2023 | D8: 45134 | E8: 44805 | F8: 45169 | G8: 809 | H8: 817 | I8: 817 | J8: 817 | K8: ENDORSEMENT
A9: 1 | B9: KHI/HO/D/HLGRP HEALTH/P/2716/09/2023 | C9: 0 | D9: 45195 | E9: 45170 | F9: 45535 | G9: 4257376 | H9: 4300000 | I9: 1492388 | J9: 1492388 | K9: POLICY
A10: 2 | B10: KHI/HO/D/HLGRP HEALTH/P/2716/09/2023 | C10: KHI/HO/D/HLGRP HEALTH/E/21933/10/2023 | D10: 45205 | E10: 45170 | F10: 45535 | G10: -3387 | H10: -3421 | I10: -3421 | J10: -3421 | K10: ENDORSEMENT
A11: 3 | B11: KHI/HO/D/HLGRP HEALTH/P/2716/09/2023 | C11: KHI/HO/D/HLGRP HEALTH/E/21951/10/2023 | D11: 45208 | E11: 45170 | F11: 45535 | G11: -60317 | H11: -60920 | I11: -60920 | J11: -60920 | K11: ENDORSEMENT
A12: 4 | B12: KHI/HO/D/HLGRP HEALTH/P/2716/09/2023 | C12: KHI/HO/D/HLGRP HEALTH/E/22065/10/2023 | D12: 45215 | E12: 45170 | F12: 45535 | G12: 6083 | H12: 6144 | I12: 6144 | J12: 6144 | K12: ENDORSEMENT
A13: 5 | B13: KHI/HO/D/HLGRP HEALTH/P/2716/09/2023 | C13: KHI/HO/D/HLGRP HEALTH/E/22205/10/2023 | D13: 45223 | E13: 45170 | F13: 45535 | G13: -22350 | H13: -22574 | I13: -22574 | J13: -22574 | K13: ENDORSEMENT
A14: 6 | B14: KHI/HO/D/HLGRP HEALTH/P/2716/09/2023 | C14: KHI/HO/D/HLGRP HEALTH/E/22263/10/2023 | D14: 45226 | E14: 45170 | F14: 45535 | G14: -43670 | H14: -44107 | I14: -44107 | J14: -44107 | K14: ENDORSEMENT
A15: 7 | B15: KHI/HO/D/HLGRP HEALTH/P/2716/09/2023 | C15: KHI/HO/D/HLGRP HEALTH/E/22444/11/2023 | D15: 45237 | E15: 45170 | F15: 45535 | G15: -3070 | H15: -3101 | I15: -3101 | J15: -3101 | K15: ENDORSEMENT
A16: 8 | B16: KHI/HO/D/HLGRP HEALTH/P/2716/09/2023 | C16: KHI/HO/D/HLGRP HEALTH/E/22547/11/2023 | D16: 45244 | E16: 45170 | F16: 45535 | G16: -3697 | H16: -3734 | I16: -3734 | J16: -3734 | K16: ENDORSEMENT
A17: 9 | B17: KHI/HO/D/HLGRP HEALTH/P/2716/09/2023 | C17: KHI/HO/D/HLGRP HEALTH/E/22585/11/2023 | D17: 45245 | E17: 45170 | F17: 45535 | G17: 4087 | H17: 4128 | I17: 4128 | J17: 4128 | K17: ENDORSEMENT
A18: 10 | B18: KHI/HO/D/HLGRP HEALTH/P/2716/09/2023 | C18: KHI/HO/D/HLGRP HEALTH/E/22718/11/2023 | D18: 45252 | E18: 45170 | F18: 45535 | G18: -3121 | H18: -3152 | I18: -3152 | J18: -3152 | K18: ENDORSEMENT
A19: 11 | B19: KHI/HO/D/HLGRP HEALTH/P/2716/09/2023 | C19: KHI/HO/D/HLGRP HEALTH/E/22752/11/2023 | D19: 45254 | E19: 45170 | F19: 45535 | G19: 4570 | H19: 4616 | I19: 4616 | J19: 4616 | K19: ENDORSEMENT
A20: 12 | B20: KHI/HO/D/HLGRP HEALTH/P/2716/09/2023 | C20: KHI/HO/D/HLGRP HEALTH/E/23018/12/2023 | D20: 45272 | E20: 45170 | F20: 45535 | G20: -57576 | H20: -58152 | I20: -58152 | J20: -58152 | K20: ENDORSEMENT
A21: 13 | B21: KHI/HO/D/HLGRP HEALTH/P/2716/09/2023 | C21: KHI/HO/D/HLGRP HEALTH/E/23162/12/2023 | D21: 45280 | E21: 45170 | F21: 45535 | G21: -24679 | H21: -24926 | I21: -24926 | J21: -24926 | K21: ENDORSEMENT
... A47: 39 | B47: KHI/HO/D/HLGRP HEALTH/P/2716/09/2023 | C47: KHI/HO/D/HLGRP HEALTH/E/26581/08/2024 | D47: 45518 | E47: 45170 | F47: 45535 | G47: -318 | H47: -321 | I47: -321 | J47: -321 | K47: ENDORSEMENT
A48: 1 | B48: KHI/HO/D/HLGRP HEALTH/P/3311/09/2024 | C48: 0 | D48: 45537 | E48: 45536 | F48: 45900 | G48: 4256931 | H48: 4300000 | I48: 4300000 | J48: 2150687 | K48: POLICY
G49: =SUM(G6:G48) -> 8324059 | H49: =SUM(H6:H48) -> 8407850 | I49: =SUM(I6:I48) -> 5596123 | J49: =SUM(J6:J48) -> 3446810

Sheet Sheet3
B2: TRACKER | C2: KHI/HO/D/MO/CV/P/104956/12/2024 | D2: 16210 | F2: ITECKNOLOGI (TRACKER)
B3: TRACKER | C3: KHI/HO/D/MO/CV/P/104945/12/2024 | D3: 24315 | F3: ITECKNOLOGI (TRACKER)
B4: TRACKER | C4: KHI/HO/D/MO/PC COMP/P/104949/12/2024 | D4: 72945 | F4: ITECKNOLOGI (TRACKER)
B5: TRACKER | C5: KHI/HO/D/MO/PC COMP/P/104960/12/2024 | D5: 8105 | F5: ITECKNOLOGI (TRACKER)
B6: TRACKER | C6: KHI/HO/D/MO/PC COMP/P/104963/12/2024 | D6: 8105 | F6: ITECKNOLOGI (TRACKER)
B7: TRACKER | C7: LHR/LHR/D/MO/PC COMP/P/105385/01/2025 | D7: 8105 | F7: ITECKNOLOGI (TRACKER)
B8: TRACKER | C8: KHI/HO/D/MO/PC COMP/P/105528/01/2025 | D8: 8105 | F8: ITECKNOLOGI (TRACKER)
B9: TRACKER | C9: KHI/HO/D/MO/PC TPP/P/105545/01/2025 | D9: 8105 | F9: ITECKNOLOGI (TRACKER)
B10: TRACKER | C10: KHI/HO/D/MO/PC COMP/P/105631/01/2025 | D10: 8105 | F10: ITECKNOLOGI (TRACKER)
B11: TRACKER | C11: KHI/HO/D/MO/PC COMP/P/105921/01/2025 | D11: 8105 | F11: ITECKNOLOGI (TRACKER)
B12: TRACKER | C12: KHI/HO/D/MO/PC COMP/P/106039/01/2025 | D12: 8105 | F12: ITECKNOLOGI (TRACKER)
B13: TRACKER | C13: KHI/HO/D/MO/PC COMP/P/106111/01/2025 | D13: 8105 | F13: ITECKNOLOGI (TRACKER)
... B33: TRACKER | C33: KHI/HO/D/MO/PC COMP/E/52322/02/2025 | D33: 8105 | F33: ITECKNOLOGI (TRACKER)
B34: PREMIUM | C34: KHI/HO/D/HLGRP HEALTH/E/22444/11/2023 | D34: -3101 | E34: SALAAM TAKAFUL LTD
B35: PREMIUM | C35: KHI/HO/D/HLGRP HEALTH/E/22718/11/2023 | D35: -3152 | E35: SALAAM TAKAFUL LTD
B36: PREMIUM | C36: KHI/HO/D/HLGRP HEALTH/E/24203/02/2024 | D36: -2026 | E36: SALAAM TAKAFUL LTD
B37: TRACKER | C37: KHI/HO/D/MO/PC COMP/P/105594/01/2025 | D37: 8105 | F37: ITECKNOLOGI (TRACKER)
B38: TRACKER | C38: KHI/HO/D/MO/PC COMP/E/52337/02/2025 | D38: 8105 | F38: ITECKNOLOGI (TRACKER)
B39: TRACKER | C39: KHI/HO/D/MO/PC COMP/C/106033/2/01/2025 | D39: 7540 | F39: ITECKNOLOGI (TRACKER)
B40: PREMIUM | C40: KHI/HO/D/HLGRP HEALTH/E/21951/10/2023 | D40: -60920 | E40: SALAAM TAKAFUL LTD
B41: PREMIUM | C41: KHI/HO/D/HLGRP HEALTH/E/22205/10/2023 | D41: -22574 | E41: SALAAM TAKAFUL LTD
B42: PREMIUM | C42: KHI/HO/D/HLGRP HEALTH/E/22547/11/2023 | D42: -3734 | E42: SALAAM TAKAFUL LTD
B43: PREMIUM | C43: KHI/HO/D/HLGRP HEALTH/E/22585/11/2023 | D43: 4128 | E43: SALAAM TAKAFUL LTD
B44: TRACKER | C44: KHI/HO/D/MO/PC COMP/P/84616/02/2024 | D44: 8105 | F44: ITECKNOLOGI (TRACKER)
B45: TRACKER | C45: KHI/HO/D/MO/CV/P/86492/04/2024 | D45: 8105 | F45: ITECKNOLOGI (TRACKER)
B46: TRACKER | C46: KHI/HO/D/MO/CV/P/86495/04/2024 | D46: 8105 | F46: ITECKNOLOGI (TRACKER)
B47: TRACKER | C47: KHI/HO/D/MO/CV/P/86585/04/2024 | D47: 8105 | F47: ITECKNOLOGI (TRACKER)
B48: TRACKER | C48: KHI/HO/D/MO/PC COMP/P/90692/06/2024 | D48: 8105 | F48: ITECKNOLOGI (TRACKER)
B49: TRACKER | C49: KHI/HO/D/MO/PC COMP/P/100672/10/2024 | D49: 8105 | F49: ITECKNOLOGI (TRACKER)
B50: TRACKER | C50: KHI/HO/D/MO/CV/P/103497/12/2024 | D50: 8105 | F50: ITECKNOLOGI (TRACKER)
B51: TRACKER | C51: KHI/HO/D/MO/PD COMP/P/79741/12/2023 | D51: 8105 | F51: ITECKNOLOGI (TRACKER)
B52: TRACKER | C52: KHI/HO/D/MO/PD COMP/P/87622/04/2024 | D52: 8105 | F52: ITECKNOLOGI (TRACKER)
B53: TRACKER | C53: KHI/HO/D/MO/PD COMP/P/87822/04/2024 | D53: 8105 | F53: ITECKNOLOGI (TRACKER)
B54: TRACKER | C54: KHI/HO/D/MO/PD COMP/P/88008/04/2024 | D54: 8105 | F54: ITECKNOLOGI (TRACKER)
B55: TRACKER | C55: KHI/HO/D/MO/PD COMP/P/88119/04/2024 | D55: 8105 | F55: ITECKNOLOGI (TRACKER)
... B145: TRACKER | C145: KHI/HO/D/MO/PD COMP/P/103552/12/2024 | D145: 7540 | F145: ITECKNOLOGI (TRACKER)
B146: PREMIUM | C146: KHI/HO/D/HLGRP HEALTH/E/22065/10/2023 | D146: 6144 | E146: SALAAM TAKAFUL LTD
B147: PREMIUM | C147: KHI/HO/D/HLGRP HEALTH/E/22263/10/2023 | D147: -44107 | E147: SALAAM TAKAFUL LTD
B148: PREMIUM | C148: KHI/HO/D/HLGRP HEALTH/E/23018/12/2023 | D148: -58152 | E148: SALAAM TAKAFUL LTD
B149: PREMIUM | C149: KHI/HO/D/HLGRP HEALTH/E/23305/12/2023 | D149: -3506 | E149: SALAAM TAKAFUL LTD
...

Sheet working
A1: POLICY NO. | B1: Assorted_code | D1: Premium | E1: 23May250004
A2: KHI/HO/D/MO/CV/P/104956/12/2024 | B2: =VLOOKUP(A2,policy!B:C,2,0) -> 040000192961 | C2: 16210 | D2: =ROUND(C2,0) -> 16210 | E2: 23May250004 | F2: ="insert into ins_premium_det (premium_rcv_code,assorted_code, rec_amount,premium_rcv_detail_code,remaining_amt, payrec, mode_code,coinsurance_code,class_cd,it_remarks) values" -> insert into ins_premium_det (premium_rcv_code,assorted_code, rec_amount,premium_rcv_detail_code,remaining_amt, payrec, mode_code,coinsurance_code,class_cd,it_remarks) values | G2: ="('"&E2&"','"&B2&"','"&C2&"',(select max(to_number(i.premium_rcv_detail_code))+1 from ins_premium_det i),'"&C2&"','"&C2&"','09', '11000003','00','Request by Mr. reheel malik 23-may-2025');" -> ('23May250004','040000192961','16210',(select max(to_number(i.premium_rcv_detail_code))+1 from ins_premium_det i),'16210','16210','09', '11000003','00','Request by Mr. reheel malik 23-may-2025'); | H2: =F2&G2 -> insert into ins_premium_det (premium_rcv_code,assorted_code, rec_amount,premium_rcv_detail_code,remaining_amt, payrec, mode_code,coinsurance_code,class_cd,it_remarks) values('23May250004','040000192961','16210',(select max(to_number(i.premium_rcv_detail_code))+1 from ins_premium_det i),'16210','16210','09', '11000003','00','Request by Mr. reheel malik 23-may-2025');
A3: KHI/HO/D/MO/CV/P/104945/12/2024 | B3: =VLOOKUP(A3,policy!B:C,2,0) -> 040000192948 | C3: 24315 | D3: =ROUND(C3,0) -> 24315 | E3: 23May250004 | F3: ="insert into ins_premium_det (premium_rcv_code,assorted_code, rec_amount,premium_rcv_detail_code,remaining_amt, payrec, mode_code,coinsurance_code,class_cd,it_remarks) values" -> insert into ins_premium_det (premium_rcv_code,assorted_code, rec_amount,premium_rcv_detail_code,remaining_amt, payrec, mode_code,coinsurance_code,class_cd,it_remarks) values | G3: ="('"&E3&"','"&B3&"','"&C3&"',(select max(to_number(i.premium_rcv_detail_code))+1 from ins_premium_det i),'"&C3&"','"&C3&"','09', '11000003','00','Request by Mr. reheel malik 23-may-2025');" -> ('23May250004','040000192948','24315',(select max(to_number(i.premium_rcv_detail_code))+1 from ins_premium_det i),'24315','24315','09', '11000003','00','Request by Mr. reheel malik 23-may-2025'); | H3: =F3&G3 -> insert into ins_premium_det (premium_rcv_code,assorted_code, rec_amount,premium_rcv_detail_code,remaining_amt, payrec, mode_code,coinsurance_code,class_cd,it_remarks) values('23May250004','040000192948','24315',(select max(to_number(i.premium_rcv_detail_code))+1 from ins_premium_det i),'24315','24315','09', '11000003','00','Request by Mr. reheel malik 23-may-2025');
A4: KHI/HO/D/MO/PC COMP/P/104949/12/2024 | B4: =VLOOKUP(A4,policy!B:C,2,0) -> 040000192952 | C4: 72945 | D4: =ROUND(C4,0) -> 72945 | E4: 23May250004 | F4: ="insert into ins_premium_det (premium_rcv_code,assorted_code, rec_amount,premium_rcv_detail_code,remaining_amt, payrec, mode_code,coinsurance_code,class_cd,it_remarks) values" -> insert into ins_premium_det (premium_rcv_code,assorted_code, rec_amount,premium_rcv_detail_code,remaining_amt, payrec, mode_code,coinsurance_code,class_cd,it_remarks) values | G4: ="('"&E4&"','"&B4&"','"&C4&"',(select max(to_number(i.premium_rcv_detail_code))+1 from ins_premium_det i),'"&C4&"','"&C4&"','09', '11000003','00','Request by Mr. reheel malik 23-may-2025');" -> ('23May250004','040000192952','72945',(select max(to_number(i.premium_rcv_detail_code))+1 from ins_premium_det i),'72945','72945','09', '11000003','00','Request by Mr. reheel malik 23-may-2025'); | H4: =F4&G4 -> insert into ins_premium_det (premium_rcv_code,assorted_code, rec_amount,premium_rcv_detail_code,remaining_amt, payrec, mode_code,coinsurance_code,class_cd,it_remarks) values('23May250004','040000192952','72945',(select max(to_number(i.premium_rcv_detail_code))+1 from ins_premium_det i),'72945','72945','09', '11000003','00','Request by Mr. reheel malik 23-may-2025');
A5: KHI/HO/D/MO/PC COMP/P/104960/12/2024 | B5: =VLOOKUP(A5,policy!B:C,2,0) -> 040000192966 | C5: 8105 | D5: =ROUND(C5,0) -> 8105 | E5: 23May250004 | F5: ="insert into ins_premium_det (premium_rcv_code,assorted_code, rec_amount,premium_rcv_detail_code,remaining_amt, payrec, mode_code,coinsurance_code,class_cd,it_remarks) values" -> insert into ins_premium_det (premium_rcv_code,assorted_code, rec_amount,premium_rcv_detail_code,remaining_amt, payrec, mode_code,coinsurance_code,class_cd,it_remarks) values | G5: ="('"&E5&"','"&B5&"','"&C5&"',(select max(to_number(i.premium_rcv_detail_code))+1 from ins_premium_det i),'"&C5&"','"&C5&"','09', '11000003','00','Request by Mr. reheel malik 23-may-2025');" -> ('23May250004','040000192966','8105',(select max(to_number(i.premium_rcv_detail_code))+1 from ins_premium_det i),'8105','8105','09', '11000003','00','Request by Mr. reheel malik 23-may-2025'); | H5: =F5&G5 -> insert into ins_premium_det (premium_rcv_code,assorted_code, rec_amount,premium_rcv_detail_code,remaining_amt, payrec, mode_code,coinsurance_code,class_cd,it_remarks) values('23May250004','040000192966','8105',(select max(to_number(i.premium_rcv_detail_code))+1 from ins_premium_det i),'8105','8105','09', '11000003','00','Request by Mr. reheel malik 23-may-2025');
A6: KHI/HO/D/MO/PC COMP/P/104963/12/2024 | B6: =VLOOKUP(A6,policy!B:C,2,0) -> 040000192969 | C6: 8105 | D6: =ROUND(C6,0) -> 8105 | E6: 23May250004 | F6: ="insert into ins_premium_det (premium_rcv_code,assorted_code, rec_amount,premium_rcv_detail_code,remaining_amt, payrec, mode_code,coinsurance_code,class_cd,it_remarks) values" -> insert into ins_premium_det (premium_rcv_code,assorted_code, rec_amount,premium_rcv_detail_code,remaining_amt, payrec, mode_code,coinsurance_code,class_cd,it_remarks) values | G6: ="('"&E6&"','"&B6&"','"&C6&"',(select max(to_number(i.premium_rcv_detail_code))+1 from ins_premium_det i),'"&C6&"','"&C6&"','09', '11000003','00','Request by Mr. reheel malik 23-may-2025');" -> ('23May250004','040000192969','8105',(select max(to_number(i.premium_rcv_detail_code))+1 from ins_premium_det i),'8105','8105','09', '11000003','00','Request by Mr. reheel malik 23-may-2025'); | H6: =F6&G6 -> insert into ins_premium_det (premium_rcv_code,assorted_code, rec_amount,premium_rcv_detail_code,remaining_amt, payrec, mode_code,coinsurance_code,class_cd,it_remarks) values('23May250004','040000192969','8105',(select max(to_number(i.premium_rcv_detail_code))+1 from ins_premium_det i),'8105','8105','09', '11000003','00','Request by Mr. reheel malik 23-may-2025');
A7: LHR/LHR/D/MO/PC COMP/P/105385/01/2025 | B7: =VLOOKUP(A7,policy!B:C,2,0) -> 040000193525 | C7: 8105 | D7: =ROUND(C7,0) -> 8105 | E7: 23May250004 | F7: ="insert into ins_premium_det (premium_rcv_code,assorted_code, rec_amount,premium_rcv_detail_code,remaining_amt, payrec, mode_code,coinsurance_code,class_cd,it_remarks) values" -> insert into ins_premium_det (premium_rcv_code,assorted_code, rec_amount,premium_rcv_detail_code,remaining_amt, payrec, mode_code,coinsurance_code,class_cd,it_remarks) values | G7: ="('"&E7&"','"&B7&"','"&C7&"',(select max(to_number(i.premium_rcv_detail_code))+1 from ins_premium_det i),'"&C7&"','"&C7&"','09', '11000003','00','Request by Mr. reheel malik 23-may-2025');" -> ('23May250004','040000193525','8105',(select max(to_number(i.premium_rcv_detail_code))+1 from ins_premium_det i),'8105','8105','09', '11000003','00','Request by Mr. reheel malik 23-may-2025'); | H7: =F7&G7 -> insert into ins_premium_det (premium_rcv_code,assorted_code, rec_amount,premium_rcv_detail_code,remaining_amt, payrec, mode_code,coinsurance_code,class_cd,it_remarks) values('23May250004','040000193525','8105',(select max(to_number(i.premium_rcv_detail_code))+1 from ins_premium_det i),'8105','8105','09', '11000003','00','Request by Mr. reheel malik 23-may-2025');
A8: KHI/HO/D/MO/PC COMP/P/105528/01/2025 | B8: =VLOOKUP(A8,policy!B:C,2,0) -> 040000193693 | C8: 8105 | D8: =ROUND(C8,0) -> 8105 | E8: 23May250004 | F8: ="insert into ins_premium_det (premium_rcv_code,assorted_code, rec_amount,premium_rcv_detail_code,remaining_amt, payrec, mode_code,coinsurance_code,class_cd,it_remarks) values" -> insert into ins_premium_det (premium_rcv_code,assorted_code, rec_amount,premium_rcv_detail_code,remaining_amt, payrec, mode_code,coinsurance_code,class_cd,it_remarks) values | G8: ="('"&E8&"','"&B8&"','"&C8&"',(select max(to_number(i.premium_rcv_detail_code))+1 from ins_premium_det i),'"&C8&"','"&C8&"','09', '11000003','00','Request by Mr. reheel malik 23-may-2025');" -> ('23May250004','040000193693','8105',(select max(to_number(i.premium_rcv_detail_code))+1 from ins_premium_det i),'8105','8105','09', '11000003','00','Request by Mr. reheel malik 23-may-2025'); | H8: =F8&G8 -> insert into ins_premium_det (premium_rcv_code,assorted_code, rec_amount,premium_rcv_detail_code,remaining_amt, payrec, mode_code,coinsurance_code,class_cd,it_remarks) values('23May250004','040000193693','8105',(select max(to_number(i.premium_rcv_detail_code))+1 from ins_premium_det i),'8105','8105','09', '11000003','00','Request by Mr. reheel malik 23-may-2025');
A9: KHI/HO/D/MO/PC TPP/P/105545/01/2025 | B9: =VLOOKUP(A9,policy!B:C,2,0) -> 040000193719 | C9: 8105 | D9: =ROUND(C9,0) -> 8105 | E9: 23May250004 | F9: ="insert into ins_premium_det (premium_rcv_code,assorted_code, rec_amount,premium_rcv_detail_code,remaining_amt, payrec, mode_code,coinsurance_code,class_cd,it_remarks) values" -> insert into ins_premium_det (premium_rcv_code,assorted_code, rec_amount,premium_rcv_detail_code,remaining_amt, payrec, mode_code,coinsurance_code,class_cd,it_remarks) values | G9: ="('"&E9&"','"&B9&"','"&C9&"',(select max(to_number(i.premium_rcv_detail_code))+1 from ins_premium_det i),'"&C9&"','"&C9&"','09', '11000003','00','Request by Mr. reheel malik 23-may-2025');" -> ('23May250004','040000193719','8105',(select max(to_number(i.premium_rcv_detail_code))+1 from ins_premium_det i),'8105','8105','09', '11000003','00','Request by Mr. reheel malik 23-may-2025'); | H9: =F9&G9 -> insert into ins_premium_det (premium_rcv_code,assorted_code, rec_amount,premium_rcv_detail_code,remaining_amt, payrec, mode_code,coinsurance_code,class_cd,it_remarks) values('23May250004','040000193719','8105',(select max(to_number(i.premium_rcv_detail_code))+1 from ins_premium_det i),'8105','8105','09', '11000003','00','Request by Mr. reheel malik 23-may-2025');
A10: KHI/HO/D/MO/PC COMP/P/105631/01/2025 | B10: =VLOOKUP(A10,policy!B:C,2,0) -> 040000193810 | C10: 8105 | D10: =ROUND(C10,0) -> 8105 | E10: 23May250004 | F10: ="insert into ins_premium_det (premium_rcv_code,assorted_code, rec_amount,premium_rcv_detail_code,remaining_amt, payrec, mode_code,coinsurance_code,class_cd,it_remarks) values" -> insert into ins_premium_det (premium_rcv_code,assorted_code, rec_amount,premium_rcv_detail_code,remaining_amt, payrec, mode_code,coinsurance_code,class_cd,it_remarks) values | G10: ="('"&E10&"','"&B10&"','"&C10&"',(select max(to_number(i.premium_rcv_detail_code))+1 from ins_premium_det i),'"&C10&"','"&C10&"','09', '11000003','00','Request by Mr. reheel malik 23-may-2025');" -> ('23May250004','040000193810','8105',(select max(to_number(i.premium_rcv_detail_code))+1 from ins_premium_det i),'8105','8105','09', '11000003','00','Request by Mr. reheel malik 23-may-2025'); | H10: =F10&G10 -> insert into ins_premium_det (premium_rcv_code,assorted_code, rec_amount,premium_rcv_detail_code,remaining_amt, payrec, mode_code,coinsurance_code,class_cd,it_remarks) values('23May250004','040000193810','8105',(select max(to_number(i.premium_rcv_detail_code))+1 from ins_premium_det i),'8105','8105','09', '11000003','00','Request by Mr. reheel malik 23-may-2025');
A11: KHI/HO/D/MO/PC COMP/P/105921/01/2025 | B11: =VLOOKUP(A11,policy!B:C,2,0) -> 040000194147 | C11: 8105 | D11: =ROUND(C11,0) -> 8105 | E11: 23May250004 | F11: ="insert into ins_premium_det (premium_rcv_code,assorted_code, rec_amount,premium_rcv_detail_code,remaining_amt, payrec, mode_code,coinsurance_code,class_cd,it_remarks) values" -> insert into ins_premium_det (premium_rcv_code,assorted_code, rec_amount,premium_rcv_detail_code,remaining_amt, payrec, mode_code,coinsurance_code,class_cd,it_remarks) values | G11: ="('"&E11&"','"&B11&"','"&C11&"',(select max(to_number(i.premium_rcv_detail_code))+1 from ins_premium_det i),'"&C11&"','"&C11&"','09', '11000003','00','Request by Mr. reheel malik 23-may-2025');" -> ('23May250004','040000194147','8105',(select max(to_number(i.premium_rcv_detail_code))+1 from ins_premium_det i),'8105','8105','09', '11000003','00','Request by Mr. reheel malik 23-may-2025'); | H11: =F11&G11 -> insert into ins_premium_det (premium_rcv_code,assorted_code, rec_amount,premium_rcv_detail_code,remaining_amt, payrec, mode_code,coinsurance_code,class_cd,it_remarks) values('23May250004','040000194147','8105',(select max(to_number(i.premium_rcv_detail_code))+1 from ins_premium_det i),'8105','8105','09', '11000003','00','Request by Mr. reheel malik 23-may-2025');
A12: KHI/HO/D/MO/PC COMP/P/106039/01/2025 | B12: =VLOOKUP(A12,policy!B:C,2,0) -> 040000194281 | C12: 8105 | D12: =ROUND(C12,0) -> 8105 | E12: 23May250004 | F12: ="insert into ins_premium_det (premium_rcv_code,assorted_code, rec_amount,premium_rcv_detail_code,remaining_amt, payrec, mode_code,coinsurance_code,class_cd,it_remarks) values" -> insert into ins_premium_det (premium_rcv_code,assorted_code, rec_amount,premium_rcv_detail_code,remaining_amt, payrec, mode_code,coinsurance_code,class_cd,it_remarks) values | G12: ="('"&E12&"','"&B12&"','"&C12&"',(select max(to_number(i.premium_rcv_detail_code))+1 from ins_premium_det i),'"&C12&"','"&C12&"','09', '11000003','00','Request by Mr. reheel malik 23-may-2025');" -> ('23May250004','040000194281','8105',(select max(to_number(i.premium_rcv_detail_code))+1 from ins_premium_det i),'8105','8105','09', '11000003','00','Request by Mr. reheel malik 23-may-2025'); | H12: =F12&G12 -> insert into ins_premium_det (premium_rcv_code,assorted_code, rec_amount,premium_rcv_detail_code,remaining_amt, payrec, mode_code,coinsurance_code,class_cd,it_remarks) values('23May250004','040000194281','8105',(select max(to_number(i.premium_rcv_detail_code))+1 from ins_premium_det i),'8105','8105','09', '11000003','00','Request by Mr. reheel malik 23-may-2025');
A13: KHI/HO/D/MO/PC COMP/P/106111/01/2025 | B13: =VLOOKUP(A13,policy!B:C,2,0) -> 040000194383 | C13: 8105 | D13: =ROUND(C13,0) -> 8105 | E13: 23May250004 | F13: ="insert into ins_premium_det (premium_rcv_code,assorted_code, rec_amount,premium_rcv_detail_code,remaining_amt, payrec, mode_code,coinsurance_code,class_cd,it_remarks) values" -> insert into ins_premium_det (premium_rcv_code,assorted_code, rec_amount,premium_rcv_detail_code,remaining_amt, payrec, mode_code,coinsurance_code,class_cd,it_remarks) values | G13: ="('"&E13&"','"&B13&"','"&C13&"',(select max(to_number(i.premium_rcv_detail_code))+1 from ins_premium_det i),'"&C13&"','"&C13&"','09', '11000003','00','Request by Mr. reheel malik 23-may-2025');" -> ('23May250004','040000194383','8105',(select max(to_number(i.premium_rcv_detail_code))+1 from ins_premium_det i),'8105','8105','09', '11000003','00','Request by Mr. reheel malik 23-may-2025'); | H13: =F13&G13 -> insert into ins_premium_det (premium_rcv_code,assorted_code, rec_amount,premium_rcv_detail_code,remaining_amt, payrec, mode_code,coinsurance_code,class_cd,it_remarks) values('23May250004','040000194383','8105',(select max(to_number(i.premium_rcv_detail_code))+1 from ins_premium_det i),'8105','8105','09', '11000003','00','Request by Mr. reheel malik 23-may-2025');
... A35: KHI/HO/D/MO/PC COMP/E/52337/02/2025 | B35: =VLOOKUP(A35,policy!B:C,2,0) -> 050000854472 | C35: 8105 | D35: =ROUND(C35,0) -> 8105 | E35: 23May250004 | F35: ="insert into ins_premium_det (premium_rcv_code,assorted_code, rec_amount,premium_rcv_detail_code,remaining_amt, payrec, mode_code,coinsurance_code,class_cd,it_remarks) values" -> insert into ins_premium_det (premium_rcv_code,assorted_code, rec_amount,premium_rcv_detail_code,remaining_amt, payrec, mode_code,coinsurance_code,class_cd,it_remarks) values | G35: ="('"&E35&"','"&B35&"','"&C35&"',(select max(to_number(i.premium_rcv_detail_code))+1 from ins_premium_det i),'"&C35&"','"&C35&"','09', '11000003','00','Request by Mr. reheel malik 23-may-2025');" -> ('23May250004','050000854472','8105',(select max(to_number(i.premium_rcv_detail_code))+1 from ins_premium_det i),'8105','8105','09', '11000003','00','Request by Mr. reheel malik 23-may-2025'); | H35: =F35&G35 -> insert into ins_premium_det (premium_rcv_code,assorted_code, rec_amount,premium_rcv_detail_code,remaining_amt, payrec, mode_code,coinsurance_code,class_cd,it_remarks) values('23May250004','050000854472','8105',(select max(to_number(i.premium_rcv_detail_code))+1 from ins_premium_det i),'8105','8105','09', '11000003','00','Request by Mr. reheel malik 23-may-2025');
A36: KHI/HO/D/MO/PC COMP/C/106033/2/01/2025 | B36: 070000174019 | C36: 7540 | D36: =ROUND(C36,0) -> 7540 | E36: 23May250004 | F36: ="insert into ins_premium_det (premium_rcv_code,assorted_code, rec_amount,premium_rcv_detail_code,remaining_amt, payrec, mode_code,coinsurance_code,class_cd,it_remarks) values" -> insert into ins_premium_det (premium_rcv_code,assorted_code, rec_amount,premium_rcv_detail_code,remaining_amt, payrec, mode_code,coinsurance_code,class_cd,it_remarks) values | G36: ="('"&E36&"','"&B36&"','"&C36&"',(select max(to_number(i.premium_rcv_detail_code))+1 from ins_premium_det i),'"&C36&"','"&C36&"','09', '11000003','00','Request by Mr. reheel malik 23-may-2025');" -> ('23May250004','070000174019','7540',(select max(to_number(i.premium_rcv_detail_code))+1 from ins_premium_det i),'7540','7540','09', '11000003','00','Request by Mr. reheel malik 23-may-2025'); | H36: =F36&G36 -> insert into ins_premium_det (premium_rcv_code,assorted_code, rec_amount,premium_rcv_detail_code,remaining_amt, payrec, mode_code,coinsurance_code,class_cd,it_remarks) values('23May250004','070000174019','7540',(select max(to_number(i.premium_rcv_detail_code))+1 from ins_premium_det i),'7540','7540','09', '11000003','00','Request by Mr. reheel malik 23-may-2025');
A37: KHI/HO/D/MO/PC COMP/P/84616/02/2024 | B37: =VLOOKUP(A37,policy!B:C,2,0) -> 040000167354 | C37: 8105 | D37: =ROUND(C37,0) -> 8105 | E37: 23May250004 | F37: ="insert into ins_premium_det (premium_rcv_code,assorted_code, rec_amount,premium_rcv_detail_code,remaining_amt, payrec, mode_code,coinsurance_code,class_cd,it_remarks) values" -> insert into ins_premium_det (premium_rcv_code,assorted_code, rec_amount,premium_rcv_detail_code,remaining_amt, payrec, mode_code,coinsurance_code,class_cd,it_remarks) values | G37: ="('"&E37&"','"&B37&"','"&C37&"',(select max(to_number(i.premium_rcv_detail_code))+1 from ins_premium_det i),'"&C37&"','"&C37&"','09', '11000003','00','Request by Mr. reheel malik 23-may-2025');" -> ('23May250004','040000167354','8105',(select max(to_number(i.premium_rcv_detail_code))+1 from ins_premium_det i),'8105','8105','09', '11000003','00','Request by Mr. reheel malik 23-may-2025'); | H37: =F37&G37 -> insert into ins_premium_det (premium_rcv_code,assorted_code, rec_amount,premium_rcv_detail_code,remaining_amt, payrec, mode_code,coinsurance_code,class_cd,it_remarks) values('23May250004','040000167354','8105',(select max(to_number(i.premium_rcv_detail_code))+1 from ins_premium_det i),'8105','8105','09', '11000003','00','Request by Mr. reheel malik 23-may-2025');
A38: KHI/HO/D/MO/CV/P/86492/04/2024 | B38: =VLOOKUP(A38,policy!B:C,2,0) -> 040000170045 | C38: 8105 | D38: =ROUND(C38,0) -> 8105 | E38: 23May250004 | F38: ="insert into ins_premium_det (premium_rcv_code,assorted_code, rec_amount,premium_rcv_detail_code,remaining_amt, payrec, mode_code,coinsurance_code,class_cd,it_remarks) values" -> insert into ins_premium_det (premium_rcv_code,assorted_code, rec_amount,premium_rcv_detail_code,remaining_amt, payrec, mode_code,coinsurance_code,class_cd,it_remarks) values | G38: ="('"&E38&"','"&B38&"','"&C38&"',(select max(to_number(i.premium_rcv_detail_code))+1 from ins_premium_det i),'"&C38&"','"&C38&"','09', '11000003','00','Request by Mr. reheel malik 23-may-2025');" -> ('23May250004','040000170045','8105',(select max(to_number(i.premium_rcv_detail_code))+1 from ins_premium_det i),'8105','8105','09', '11000003','00','Request by Mr. reheel malik 23-may-2025'); | H38: =F38&G38 -> insert into ins_premium_det (premium_rcv_code,assorted_code, rec_amount,premium_rcv_detail_code,remaining_amt, payrec, mode_code,coinsurance_code,class_cd,it_remarks) values('23May250004','040000170045','8105',(select max(to_number(i.premium_rcv_detail_code))+1 from ins_premium_det i),'8105','8105','09', '11000003','00','Request by Mr. reheel malik 23-may-2025');
A39: KHI/HO/D/MO/CV/P/86495/04/2024 | B39: =VLOOKUP(A39,policy!B:C,2,0) -> 040000170051 | C39: 8105 | D39: =ROUND(C39,0) -> 8105 | E39: 23May250004 | F39: ="insert into ins_premium_det (premium_rcv_code,assorted_code, rec_amount,premium_rcv_detail_code,remaining_amt, payrec, mode_code,coinsurance_code,class_cd,it_remarks) values" -> insert into ins_premium_det (premium_rcv_code,assorted_code, rec_amount,premium_rcv_detail_code,remaining_amt, payrec, mode_code,coinsurance_code,class_cd,it_remarks) values | G39: ="('"&E39&"','"&B39&"','"&C39&"',(select max(to_number(i.premium_rcv_detail_code))+1 from ins_premium_det i),'"&C39&"','"&C39&"','09', '11000003','00','Request by Mr. reheel malik 23-may-2025');" -> ('23May250004','040000170051','8105',(select max(to_number(i.premium_rcv_detail_code))+1 from ins_premium_det i),'8105','8105','09', '11000003','00','Request by Mr. reheel malik 23-may-2025'); | H39: =F39&G39 -> insert into ins_premium_det (premium_rcv_code,assorted_code, rec_amount,premium_rcv_detail_code,remaining_amt, payrec, mode_code,coinsurance_code,class_cd,it_remarks) values('23May250004','040000170051','8105',(select max(to_number(i.premium_rcv_detail_code))+1 from ins_premium_det i),'8105','8105','09', '11000003','00','Request by Mr. reheel malik 23-may-2025');
A40: KHI/HO/D/MO/CV/P/86585/04/2024 | B40: =VLOOKUP(A40,policy!B:C,2,0) -> 040000170158 | C40: 8105 | D40: =ROUND(C40,0) -> 8105 | E40: 23May250004 | F40: ="insert into ins_premium_det (premium_rcv_code,assorted_code, rec_amount,premium_rcv_detail_code,remaining_amt, payrec, mode_code,coinsurance_code,class_cd,it_remarks) values" -> insert into ins_premium_det (premium_rcv_code,assorted_code, rec_amount,premium_rcv_detail_code,remaining_amt, payrec, mode_code,coinsurance_code,class_cd,it_remarks) values | G40: ="('"&E40&"','"&B40&"','"&C40&"',(select max(to_number(i.premium_rcv_detail_code))+1 from ins_premium_det i),'"&C40&"','"&C40&"','09', '11000003','00','Request by Mr. reheel malik 23-may-2025');" -> ('23May250004','040000170158','8105',(select max(to_number(i.premium_rcv_detail_code))+1 from ins_premium_det i),'8105','8105','09', '11000003','00','Request by Mr. reheel malik 23-may-2025'); | H40: =F40&G40 -> insert into ins_premium_det (premium_rcv_code,assorted_code, rec_amount,premium_rcv_detail_code,remaining_amt, payrec, mode_code,coinsurance_code,class_cd,it_remarks) values('23May250004','040000170158','8105',(select max(to_number(i.premium_rcv_detail_code))+1 from ins_premium_det i),'8105','8105','09', '11000003','00','Request by Mr. reheel malik 23-may-2025');
A41: KHI/HO/D/MO/PC COMP/P/90692/06/2024 | B41: =VLOOKUP(A41,policy!B:C,2,0) -> 040000175713 | C41: 8105 | D41: =ROUND(C41,0) -> 8105 | E41: 23May250004 | F41: ="insert into ins_premium_det (premium_rcv_code,assorted_code, rec_amount,premium_rcv_detail_code,remaining_amt, payrec, mode_code,coinsurance_code,class_cd,it_remarks) values" -> insert into ins_premium_det (premium_rcv_code,assorted_code, rec_amount,premium_rcv_detail_code,remaining_amt, payrec, mode_code,coinsurance_code,class_cd,it_remarks) values | G41: ="('"&E41&"','"&B41&"','"&C41&"',(select max(to_number(i.premium_rcv_detail_code))+1 from ins_premium_det i),'"&C41&"','"&C41&"','09', '11000003','00','Request by Mr. reheel malik 23-may-2025');" -> ('23May250004','040000175713','8105',(select max(to_number(i.premium_rcv_detail_code))+1 from ins_premium_det i),'8105','8105','09', '11000003','00','Request by Mr. reheel malik 23-may-2025'); | H41: =F41&G41 -> insert into ins_premium_det (premium_rcv_code,assorted_code, rec_amount,premium_rcv_detail_code,remaining_amt, payrec, mode_code,coinsurance_code,class_cd,it_remarks) values('23May250004','040000175713','8105',(select max(to_number(i.premium_rcv_detail_code))+1 from ins_premium_det i),'8105','8105','09', '11000003','00','Request by Mr. reheel malik 23-may-2025');
A42: KHI/HO/D/MO/PC COMP/P/100672/10/2024 | B42: =VLOOKUP(A42,policy!B:C,2,0) -> 040000187846 | C42: 8105 | D42: =ROUND(C42,0) -> 8105 | E42: 23May250004 | F42: ="insert into ins_premium_det (premium_rcv_code,assorted_code, rec_amount,premium_rcv_detail_code,remaining_amt, payrec, mode_code,coinsurance_code,class_cd,it_remarks) values" -> insert into ins_premium_det (premium_rcv_code,assorted_code, rec_amount,premium_rcv_detail_code,remaining_amt, payrec, mode_code,coinsurance_code,class_cd,it_remarks) values | G42: ="('"&E42&"','"&B42&"','"&C42&"',(select max(to_number(i.premium_rcv_detail_code))+1 from ins_premium_det i),'"&C42&"','"&C42&"','09', '11000003','00','Request by Mr. reheel malik 23-may-2025');" -> ('23May250004','040000187846','8105',(select max(to_number(i.premium_rcv_detail_code))+1 from ins_premium_det i),'8105','8105','09', '11000003','00','Request by Mr. reheel malik 23-may-2025'); | H42: =F42&G42 -> insert into ins_premium_det (premium_rcv_code,assorted_code, rec_amount,premium_rcv_detail_code,remaining_amt, payrec, mode_code,coinsurance_code,class_cd,it_remarks) values('23May250004','040000187846','8105',(select max(to_number(i.premium_rcv_detail_code))+1 from ins_premium_det i),'8105','8105','09', '11000003','00','Request by Mr. reheel malik 23-may-2025');
A43: KHI/HO/D/MO/CV/P/103497/12/2024 | B43: =VLOOKUP(A43,policy!B:C,2,0) -> 040000191122 | C43: 8105 | D43: =ROUND(C43,0) -> 8105 | E43: 23May250004 | F43: ="insert into ins_premium_det (premium_rcv_code,assorted_code, rec_amount,premium_rcv_detail_code,remaining_amt, payrec, mode_code,coinsurance_code,class_cd,it_remarks) values" -> insert into ins_premium_det (premium_rcv_code,assorted_code, rec_amount,premium_rcv_detail_code,remaining_amt, payrec, mode_code,coinsurance_code,class_cd,it_remarks) values | G43: ="('"&E43&"','"&B43&"','"&C43&"',(select max(to_number(i.premium_rcv_detail_code))+1 from ins_premium_det i),'"&C43&"','"&C43&"','09', '11000003','00','Request by Mr. reheel malik 23-may-2025');" -> ('23May250004','040000191122','8105',(select max(to_number(i.premium_rcv_detail_code))+1 from ins_premium_det i),'8105','8105','09', '11000003','00','Request by Mr. reheel malik 23-may-2025'); | H43: =F43&G43 -> insert into ins_premium_det (premium_rcv_code,assorted_code, rec_amount,premium_rcv_detail_code,remaining_amt, payrec, mode_code,coinsurance_code,class_cd,it_remarks) values('23May250004','040000191122','8105',(select max(to_number(i.premium_rcv_detail_code))+1 from ins_premium_det i),'8105','8105','09', '11000003','00','Request by Mr. reheel malik 23-may-2025');
A44: KHI/HO/D/MO/PD COMP/P/79741/12/2023 | B44: =VLOOKUP(A44,policy!B:C,2,0) -> 040000159957 | C44: 8105 | D44: =ROUND(C44,0) -> 8105 | E44: 23May250004 | F44: ="insert into ins_premium_det (premium_rcv_code,assorted_code, rec_amount,premium_rcv_detail_code,remaining_amt, payrec, mode_code,coinsurance_code,class_cd,it_remarks) values" -> insert into ins_premium_det (premium_rcv_code,assorted_code, rec_amount,premium_rcv_detail_code,remaining_amt, payrec, mode_code,coinsurance_code,class_cd,it_remarks) values | G44: ="('"&E44&"','"&B44&"','"&C44&"',(select max(to_number(i.premium_rcv_detail_code))+1 from ins_premium_det i),'"&C44&"','"&C44&"','09', '11000003','00','Request by Mr. reheel malik 23-may-2025');" -> ('23May250004','040000159957','8105',(select max(to_number(i.premium_rcv_detail_code))+1 from ins_premium_det i),'8105','8105','09', '11000003','00','Request by Mr. reheel malik 23-may-2025'); | H44: =F44&G44 -> insert into ins_premium_det (premium_rcv_code,assorted_code, rec_amount,premium_rcv_detail_code,remaining_amt, payrec, mode_code,coinsurance_code,class_cd,it_remarks) values('23May250004','040000159957','8105',(select max(to_number(i.premium_rcv_detail_code))+1 from ins_premium_det i),'8105','8105','09', '11000003','00','Request by Mr. reheel malik 23-may-2025');
A45: KHI/HO/D/MO/PD COMP/P/87622/04/2024 | B45: =VLOOKUP(A45,policy!B:C,2,0) -> 040000171542 | C45: 8105 | D45: =ROUND(C45,0) -> 8105 | E45: 23May250004 | F45: ="insert into ins_premium_det (premium_rcv_code,assorted_code, rec_amount,premium_rcv_detail_code,remaining_amt, payrec, mode_code,coinsurance_code,class_cd,it_remarks) values" -> insert into ins_premium_det (premium_rcv_code,assorted_code, rec_amount,premium_rcv_detail_code,remaining_amt, payrec, mode_code,coinsurance_code,class_cd,it_remarks) values | G45: ="('"&E45&"','"&B45&"','"&C45&"',(select max(to_number(i.premium_rcv_detail_code))+1 from ins_premium_det i),'"&C45&"','"&C45&"','09', '11000003','00','Request by Mr. reheel malik 23-may-2025');" -> ('23May250004','040000171542','8105',(select max(to_number(i.premium_rcv_detail_code))+1 from ins_premium_det i),'8105','8105','09', '11000003','00','Request by Mr. reheel malik 23-may-2025'); | H45: =F45&G45 -> insert into ins_premium_det (premium_rcv_code,assorted_code, rec_amount,premium_rcv_detail_code,remaining_amt, payrec, mode_code,coinsurance_code,class_cd,it_remarks) values('23May250004','040000171542','8105',(select max(to_number(i.premium_rcv_detail_code))+1 from ins_premium_det i),'8105','8105','09', '11000003','00','Request by Mr. reheel malik 23-may-2025');
A46: KHI/HO/D/MO/PD COMP/P/87822/04/2024 | B46: =VLOOKUP(A46,policy!B:C,2,0) -> 040000171786 | C46: 8105 | D46: =ROUND(C46,0) -> 8105 | E46: 23May250004 | F46: ="insert into ins_premium_det (premium_rcv_code,assorted_code, rec_amount,premium_rcv_detail_code,remaining_amt, payrec, mode_code,coinsurance_code,class_cd,it_remarks) values" -> insert into ins_premium_det (premium_rcv_code,assorted_code, rec_amount,premium_rcv_detail_code,remaining_amt, payrec, mode_code,coinsurance_code,class_cd,it_remarks) values | G46: ="('"&E46&"','"&B46&"','"&C46&"',(select max(to_number(i.premium_rcv_detail_code))+1 from ins_premium_det i),'"&C46&"','"&C46&"','09', '11000003','00','Request by Mr. reheel malik 23-may-2025');" -> ('23May250004','040000171786','8105',(select max(to_number(i.premium_rcv_detail_code))+1 from ins_premium_det i),'8105','8105','09', '11000003','00','Request by Mr. reheel malik 23-may-2025'); | H46: =F46&G46 -> insert into ins_premium_det (premium_rcv_code,assorted_code, rec_amount,premium_rcv_detail_code,remaining_amt, payrec, mode_code,coinsurance_code,class_cd,it_remarks) values('23May250004','040000171786','8105',(select max(to_number(i.premium_rcv_detail_code))+1 from ins_premium_det i),'8105','8105','09', '11000003','00','Request by Mr. reheel malik 23-may-2025');
A47: KHI/HO/D/MO/PD COMP/P/88008/04/2024 | B47: =VLOOKUP(A47,policy!B:C,2,0) -> 040000172000 | C47: 8105 | D47: =ROUND(C47,0) -> 8105 | E47: 23May250004 | F47: ="insert into ins_premium_det (premium_rcv_code,assorted_code, rec_amount,premium_rcv_detail_code,remaining_amt, payrec, mode_code,coinsurance_code,class_cd,it_remarks) values" -> insert into ins_premium_det (premium_rcv_code,assorted_code, rec_amount,premium_rcv_detail_code,remaining_amt, payrec, mode_code,coinsurance_code,class_cd,it_remarks) values | G47: ="('"&E47&"','"&B47&"','"&C47&"',(select max(to_number(i.premium_rcv_detail_code))+1 from ins_premium_det i),'"&C47&"','"&C47&"','09', '11000003','00','Request by Mr. reheel malik 23-may-2025');" -> ('23May250004','040000172000','8105',(select max(to_number(i.premium_rcv_detail_code))+1 from ins_premium_det i),'8105','8105','09', '11000003','00','Request by Mr. reheel malik 23-may-2025'); | H47: =F47&G47 -> insert into ins_premium_det (premium_rcv_code,assorted_code, rec_amount,premium_rcv_detail_code,remaining_amt, payrec, mode_code,coinsurance_code,class_cd,it_remarks) values('23May250004','040000172000','8105',(select max(to_number(i.premium_rcv_detail_code))+1 from ins_premium_det i),'8105','8105','09', '11000003','00','Request by Mr. reheel malik 23-may-2025');
A48: KHI/HO/D/MO/PD COMP/P/88119/04/2024 | B48: =VLOOKUP(A48,policy!B:C,2,0) -> 040000172240 | C48: 8105 | D48: =ROUND(C48,0) -> 8105 | E48: 23May250004 | F48: ="insert into ins_premium_det (premium_rcv_code,assorted_code, rec_amount,premium_rcv_detail_code,remaining_amt, payrec, mode_code,coinsurance_code,class_cd,it_remarks) values" -> insert into ins_premium_det (premium_rcv_code,assorted_code, rec_amount,premium_rcv_detail_code,remaining_amt, payrec, mode_code,coinsurance_code,class_cd,it_remarks) values | G48: ="('"&E48&"','"&B48&"','"&C48&"',(select max(to_number(i.premium_rcv_detail_code))+1 from ins_premium_det i),'"&C48&"','"&C48&"','09', '11000003','00','Request by Mr. reheel malik 23-may-2025');" -> ('23May250004','040000172240','8105',(select max(to_number(i.premium_rcv_detail_code))+1 from ins_premium_det i),'8105','8105','09', '11000003','00','Request by Mr. reheel malik 23-may-2025'); | H48: =F48&G48 -> insert into ins_premium_det (premium_rcv_code,assorted_code, rec_amount,premium_rcv_detail_code,remaining_amt, payrec, mode_code,coinsurance_code,class_cd,it_remarks) values('23May250004','040000172240','8105',(select max(to_number(i.premium_rcv_detail_code))+1 from ins_premium_det i),'8105','8105','09', '11000003','00','Request by Mr. reheel malik 23-may-2025');
... A232: KHI/HO/D/MO/PC COMP/E/53222/03/2025 | B232: =VLOOKUP(A232,policy!B:C,2,0) -> 050000864515 | C232: 8105 | D232: =ROUND(C232,0) -> 8105 | E232: 23May250004 | F232: ="insert into ins_premium_det (premium_rcv_code,assorted_code, rec_amount,premium_rcv_detail_code,remaining_amt, payrec, mode_code,coinsurance_code,class_cd,it_remarks) values" -> insert into ins_premium_det (premium_rcv_code,assorted_code, rec_amount,premium_rcv_detail_code,remaining_amt, payrec, mode_code,coinsurance_code,class_cd,it_remarks) values | G232: ="('"&E232&"','"&B232&"','"&C232&"',(select max(to_number(i.premium_rcv_detail_code))+1 from ins_premium_det i),'"&C232&"','"&C232&"','09', '11000003','00','Request by Mr. reheel malik 23-may-2025');" -> ('23May250004','050000864515','8105',(select max(to_number(i.premium_rcv_detail_code))+1 from ins_premium_det i),'8105','8105','09', '11000003','00','Request by Mr. reheel malik 23-may-2025'); | H232: =F232&G232 -> insert into ins_premium_det (premium_rcv_code,assorted_code, rec_amount,premium_rcv_detail_code,remaining_amt, payrec, mode_code,coinsurance_code,class_cd,it_remarks) values('23May250004','050000864515','8105',(select max(to_number(i.premium_rcv_detail_code))+1 from ins_premium_det i),'8105','8105','09', '11000003','00','Request by Mr. reheel malik 23-may-2025');
A233: KHI/HO/D/MO/PC COMP/C/106254/1/01/2025 | B233: =VLOOKUP(A233,Sheet7!B:C,2,0) -> 070000174100 | C233: 8105 | D233: =ROUND(C233,0) -> 8105 | E233: 23May250004 | F233: ="insert into ins_premium_det (premium_rcv_code,assorted_code, rec_amount,premium_rcv_detail_code,remaining_amt, payrec, mode_code,coinsurance_code,class_cd,it_remarks) values" -> insert into ins_premium_det (premium_rcv_code,assorted_code, rec_amount,premium_rcv_detail_code,remaining_amt, payrec, mode_code,coinsurance_code,class_cd,it_remarks) values | G233: ="('"&E233&"','"&B233&"','"&C233&"',(select max(to_number(i.premium_rcv_detail_code))+1 from ins_premium_det i),'"&C233&"','"&C233&"','09', '11000003','00','Request by Mr. reheel malik 23-may-2025');" -> ('23May250004','070000174100','8105',(select max(to_number(i.premium_rcv_detail_code))+1 from ins_premium_det i),'8105','8105','09', '11000003','00','Request by Mr. reheel malik 23-may-2025'); | H233: =F233&G233 -> insert into ins_premium_det (premium_rcv_code,assorted_code, rec_amount,premium_rcv_detail_code,remaining_amt, payrec, mode_code,coinsurance_code,class_cd,it_remarks) values('23May250004','070000174100','8105',(select max(to_number(i.premium_rcv_detail_code))+1 from ins_premium_det i),'8105','8105','09', '11000003','00','Request by Mr. reheel malik 23-may-2025');
A234: KHI/HO/D/MO/PC COMP/P/92860/07/2024 | B234: =VLOOKUP(A234,policy!B:C,2,0) -> 040000178584 | C234: 30160 | D234: =ROUND(C234,0) -> 30160 | E234: 23May250004 | F234: ="insert into ins_premium_det (premium_rcv_code,assorted_code, rec_amount,premium_rcv_detail_code,remaining_amt, payrec, mode_code,coinsurance_code,class_cd,it_remarks) values" -> insert into ins_premium_det (premium_rcv_code,assorted_code, rec_amount,premium_rcv_detail_code,remaining_amt, payrec, mode_code,coinsurance_code,class_cd,it_remarks) values | G234: ="('"&E234&"','"&B234&"','"&C234&"',(select max(to_number(i.premium_rcv_detail_code))+1 from ins_premium_det i),'"&C234&"','"&C234&"','09', '11000003','00','Request by Mr. reheel malik 23-may-2025');" -> ('23May250004','040000178584','30160',(select max(to_number(i.premium_rcv_detail_code))+1 from ins_premium_det i),'30160','30160','09', '11000003','00','Request by Mr. reheel malik 23-may-2025'); | H234: =F234&G234 -> insert into ins_premium_det (premium_rcv_code,assorted_code, rec_amount,premium_rcv_detail_code,remaining_amt, payrec, mode_code,coinsurance_code,class_cd,it_remarks) values('23May250004','040000178584','30160',(select max(to_number(i.premium_rcv_detail_code))+1 from ins_premium_det i),'30160','30160','09', '11000003','00','Request by Mr. reheel malik 23-may-2025');
A235: KHI/HO/D/MO/PC COMP/P/94025/07/2024 | B235: =VLOOKUP(A235,policy!B:C,2,0) -> 040000179996 | C235: 7540 | D235: =ROUND(C235,0) -> 7540 | E235: 23May250004 | F235: ="insert into ins_premium_det (premium_rcv_code,assorted_code, rec_amount,premium_rcv_detail_code,remaining_amt, payrec, mode_code,coinsurance_code,class_cd,it_remarks) values" -> insert into ins_premium_det (premium_rcv_code,assorted_code, rec_amount,premium_rcv_detail_code,remaining_amt, payrec, mode_code,coinsurance_code,class_cd,it_remarks) values | G235: ="('"&E235&"','"&B235&"','"&C235&"',(select max(to_number(i.premium_rcv_detail_code))+1 from ins_premium_det i),'"&C235&"','"&C235&"','09', '11000003','00','Request by Mr. reheel malik 23-may-2025');" -> ('23May250004','040000179996','7540',(select max(to_number(i.premium_rcv_detail_code))+1 from ins_premium_det i),'7540','7540','09', '11000003','00','Request by Mr. reheel malik 23-may-2025'); | H235: =F235&G235 -> insert into ins_premium_det (premium_rcv_code,assorted_code, rec_amount,premium_rcv_detail_code,remaining_amt, payrec, mode_code,coinsurance_code,class_cd,it_remarks) values('23May250004','040000179996','7540',(select max(to_number(i.premium_rcv_detail_code))+1 from ins_premium_det i),'7540','7540','09', '11000003','00','Request by Mr. reheel malik 23-may-2025');
A236: KHI/HO/D/MO/PC COMP/P/107200/02/2025 | B236: =VLOOKUP(A236,policy!B:C,2,0) -> 040000195813 | C236: 7540 | D236: =ROUND(C236,0) -> 7540 | E236: 23May250004 | F236: ="insert into ins_premium_det (premium_rcv_code,assorted_code, rec_amount,premium_rcv_detail_code,remaining_amt, payrec, mode_code,coinsurance_code,class_cd,it_remarks) values" -> insert into ins_premium_det (premium_rcv_code,assorted_code, rec_amount,premium_rcv_detail_code,remaining_amt, payrec, mode_code,coinsurance_code,class_cd,it_remarks) values | G236: ="('"&E236&"','"&B236&"','"&C236&"',(select max(to_number(i.premium_rcv_detail_code))+1 from ins_premium_det i),'"&C236&"','"&C236&"','09', '11000003','00','Request by Mr. reheel malik 23-may-2025');" -> ('23May250004','040000195813','7540',(select max(to_number(i.premium_rcv_detail_code))+1 from ins_premium_det i),'7540','7540','09', '11000003','00','Request by Mr. reheel malik 23-may-2025'); | H236: =F236&G236 -> insert into ins_premium_det (premium_rcv_code,assorted_code, rec_amount,premium_rcv_detail_code,remaining_amt, payrec, mode_code,coinsurance_code,class_cd,it_remarks) values('23May250004','040000195813','7540',(select max(to_number(i.premium_rcv_detail_code))+1 from ins_premium_det i),'7540','7540','09', '11000003','00','Request by Mr. reheel malik 23-may-2025');
A237: KHI/HO/D/MO/PC COMP/P/107222/02/2025 | B237: =VLOOKUP(A237,policy!B:C,2,0) -> 040000195848 | C237: 7540 | D237: =ROUND(C237,0) -> 7540 | E237: 23May250004 | F237: ="insert into ins_premium_det (premium_rcv_code,assorted_code, rec_amount,premium_rcv_detail_code,remaining_amt, payrec, mode_code,coinsurance_code,class_cd,it_remarks) values" -> insert into ins_premium_det (premium_rcv_code,assorted_code, rec_amount,premium_rcv_detail_code,remaining_amt, payrec, mode_code,coinsurance_code,class_cd,it_remarks) values | G237: ="('"&E237&"','"&B237&"','"&C237&"',(select max(to_number(i.premium_rcv_detail_code))+1 from ins_premium_det i),'"&C237&"','"&C237&"','09', '11000003','00','Request by Mr. reheel malik 23-may-2025');" -> ('23May250004','040000195848','7540',(select max(to_number(i.premium_rcv_detail_code))+1 from ins_premium_det i),'7540','7540','09', '11000003','00','Request by Mr. reheel malik 23-may-2025'); | H237: =F237&G237 -> insert into ins_premium_det (premium_rcv_code,assorted_code, rec_amount,premium_rcv_detail_code,remaining_amt, payrec, mode_code,coinsurance_code,class_cd,it_remarks) values('23May250004','040000195848','7540',(select max(to_number(i.premium_rcv_detail_code))+1 from ins_premium_det i),'7540','7540','09', '11000003','00','Request by Mr. reheel malik 23-may-2025');
A238: KHI/HO/D/MO/PC COMP/P/107553/02/2025 | B238: =VLOOKUP(A238,policy!B:C,2,0) -> 040000196289 | C238: 7540 | D238: =ROUND(C238,0) -> 7540 | E238: 23May250004 | F238: ="insert into ins_premium_det (premium_rcv_code,assorted_code, rec_amount,premium_rcv_detail_code,remaining_amt, payrec, mode_code,coinsurance_code,class_cd,it_remarks) values" -> insert into ins_premium_det (premium_rcv_code,assorted_code, rec_amount,premium_rcv_detail_code,remaining_amt, payrec, mode_code,coinsurance_code,class_cd,it_remarks) values | G238: ="('"&E238&"','"&B238&"','"&C238&"',(select max(to_number(i.premium_rcv_detail_code))+1 from ins_premium_det i),'"&C238&"','"&C238&"','09', '11000003','00','Request by Mr. reheel malik 23-may-2025');" -> ('23May250004','040000196289','7540',(select max(to_number(i.premium_rcv_detail_code))+1 from ins_premium_det i),'7540','7540','09', '11000003','00','Request by Mr. reheel malik 23-may-2025'); | H238: =F238&G238 -> insert into ins_premium_det (premium_rcv_code,assorted_code, rec_amount,premium_rcv_detail_code,remaining_amt, payrec, mode_code,coinsurance_code,class_cd,it_remarks) values('23May250004','040000196289','7540',(select max(to_number(i.premium_rcv_detail_code))+1 from ins_premium_det i),'7540','7540','09', '11000003','00','Request by Mr. reheel malik 23-may-2025');
A239: FSD/FSD/D/MO/PC COMP/P/107621/02/2025 | B239: =VLOOKUP(A239,policy!B:C,2,0) -> 040000196389 | C239: 7540 | D239: =ROUND(C239,0) -> 7540 | E239: 23May250004 | F239: ="insert into ins_premium_det (premium_rcv_code,assorted_code, rec_amount,premium_rcv_detail_code,remaining_amt, payrec, mode_code,coinsurance_code,class_cd,it_remarks) values" -> insert into ins_premium_det (premium_rcv_code,assorted_code, rec_amount,premium_rcv_detail_code,remaining_amt, payrec, mode_code,coinsurance_code,class_cd,it_remarks) values | G239: ="('"&E239&"','"&B239&"','"&C239&"',(select max(to_number(i.premium_rcv_detail_code))+1 from ins_premium_det i),'"&C239&"','"&C239&"','09', '11000003','00','Request by Mr. reheel malik 23-may-2025');" -> ('23May250004','040000196389','7540',(select max(to_number(i.premium_rcv_detail_code))+1 from ins_premium_det i),'7540','7540','09', '11000003','00','Request by Mr. reheel malik 23-may-2025'); | H239: =F239&G239 -> insert into ins_premium_det (premium_rcv_code,assorted_code, rec_amount,premium_rcv_detail_code,remaining_amt, payrec, mode_code,coinsurance_code,class_cd,it_remarks) values('23May250004','040000196389','7540',(select max(to_number(i.premium_rcv_detail_code))+1 from ins_premium_det i),'7540','7540','09', '11000003','00','Request by Mr. reheel malik 23-may-2025');
A240: KHI/HO/D/MO/PC COMP/P/107667/02/2025 | B240: =VLOOKUP(A240,policy!B:C,2,0) -> 040000196467 | C240: 7540 | D240: =ROUND(C240,0) -> 7540 | E240: 23May250004 | F240: ="insert into ins_premium_det (premium_rcv_code,assorted_code, rec_amount,premium_rcv_detail_code,remaining_amt, payrec, mode_code,coinsurance_code,class_cd,it_remarks) values" -> insert into ins_premium_det (premium_rcv_code,assorted_code, rec_amount,premium_rcv_detail_code,remaining_amt, payrec, mode_code,coinsurance_code,class_cd,it_remarks) values | G240: ="('"&E240&"','"&B240&"','"&C240&"',(select max(to_number(i.premium_rcv_detail_code))+1 from ins_premium_det i),'"&C240&"','"&C240&"','09', '11000003','00','Request by Mr. reheel malik 23-may-2025');" -> ('23May250004','040000196467','7540',(select max(to_number(i.premium_rcv_detail_code))+1 from ins_premium_det i),'7540','7540','09', '11000003','00','Request by Mr. reheel malik 23-may-2025'); | H240: =F240&G240 -> insert into ins_premium_det (premium_rcv_code,assorted_code, rec_amount,premium_rcv_detail_code,remaining_amt, payrec, mode_code,coinsurance_code,class_cd,it_remarks) values('23May250004','040000196467','7540',(select max(to_number(i.premium_rcv_detail_code))+1 from ins_premium_det i),'7540','7540','09', '11000003','00','Request by Mr. reheel malik 23-may-2025');
A241: KHI/HO/D/MO/PC COMP/P/107960/03/2025 | B241: =VLOOKUP(A241,policy!B:C,2,0) -> 040000196831 | C241: 7540 | D241: =ROUND(C241,0) -> 7540 | E241: 23May250004 | F241: ="insert into ins_premium_det (premium_rcv_code,assorted_code, rec_amount,premium_rcv_detail_code,remaining_amt, payrec, mode_code,coinsurance_code,class_cd,it_remarks) values" -> insert into ins_premium_det (premium_rcv_code,assorted_code, rec_amount,premium_rcv_detail_code,remaining_amt, payrec, mode_code,coinsurance_code,class_cd,it_remarks) values | G241: ="('"&E241&"','"&B241&"','"&C241&"',(select max(to_number(i.premium_rcv_detail_code))+1 from ins_premium_det i),'"&C241&"','"&C241&"','09', '11000003','00','Request by Mr. reheel malik 23-may-2025');" -> ('23May250004','040000196831','7540',(select max(to_number(i.premium_rcv_detail_code))+1 from ins_premium_det i),'7540','7540','09', '11000003','00','Request by Mr. reheel malik 23-may-2025'); | H241: =F241&G241 -> insert into ins_premium_det (premium_rcv_code,assorted_code, rec_amount,premium_rcv_detail_code,remaining_amt, payrec, mode_code,coinsurance_code,class_cd,it_remarks) values('23May250004','040000196831','7540',(select max(to_number(i.premium_rcv_detail_code))+1 from ins_premium_det i),'7540','7540','09', '11000003','00','Request by Mr. reheel malik 23-may-2025');
A242: KHI/HO/D/MO/PC COMP/E/52647/00004/02/2025 | B242: =VLOOKUP(A242,Sheet8!B:C,2,0) -> 050000858775 | C242: 7540 | D242: =ROUND(C242,0) -> 7540 | E242: 23May250004 | F242: ="insert into ins_premium_det (premium_rcv_code,assorted_code, rec_amount,premium_rcv_detail_code,remaining_amt, payrec, mode_code,coinsurance_code,class_cd,it_remarks) values" -> insert into ins_premium_det (premium_rcv_code,assorted_code, rec_amount,premium_rcv_detail_code,remaining_amt, payrec, mode_code,coinsurance_code,class_cd,it_remarks) values | G242: ="('"&E242&"','"&B242&"','"&C242&"',(select max(to_number(i.premium_rcv_detail_code))+1 from ins_premium_det i),'"&C242&"','"&C242&"','09', '11000003','00','Request by Mr. reheel malik 23-may-2025');" -> ('23May250004','050000858775','7540',(select max(to_number(i.premium_rcv_detail_code))+1 from ins_premium_det i),'7540','7540','09', '11000003','00','Request by Mr. reheel malik 23-may-2025'); | H242: =F242&G242 -> insert into ins_premium_det (premium_rcv_code,assorted_code, rec_amount,premium_rcv_detail_code,remaining_amt, payrec, mode_code,coinsurance_code,class_cd,it_remarks) values('23May250004','050000858775','7540',(select max(to_number(i.premium_rcv_detail_code))+1 from ins_premium_det i),'7540','7540','09', '11000003','00','Request by Mr. reheel malik 23-may-2025');
A243: KHI/HO/D/MO/CV/C/107155/1/02/2025 | B243: =VLOOKUP(A243,Sheet7!B:C,2,0) -> 070000176514 | C243: 7540 | D243: =ROUND(C243,0) -> 7540 | E243: 23May250004 | F243: ="insert into ins_premium_det (premium_rcv_code,assorted_code, rec_amount,premium_rcv_detail_code,remaining_amt, payrec, mode_code,coinsurance_code,class_cd,it_remarks) values" -> insert into ins_premium_det (premium_rcv_code,assorted_code, rec_amount,premium_rcv_detail_code,remaining_amt, payrec, mode_code,coinsurance_code,class_cd,it_remarks) values | G243: ="('"&E243&"','"&B243&"','"&C243&"',(select max(to_number(i.premium_rcv_detail_code))+1 from ins_premium_det i),'"&C243&"','"&C243&"','09', '11000003','00','Request by Mr. reheel malik 23-may-2025');" -> ('23May250004','070000176514','7540',(select max(to_number(i.premium_rcv_detail_code))+1 from ins_premium_det i),'7540','7540','09', '11000003','00','Request by Mr. reheel malik 23-may-2025'); | H243: =F243&G243 -> insert into ins_premium_det (premium_rcv_code,assorted_code, rec_amount,premium_rcv_detail_code,remaining_amt, payrec, mode_code,coinsurance_code,class_cd,it_remarks) values('23May250004','070000176514','7540',(select max(to_number(i.premium_rcv_detail_code))+1 from ins_premium_det i),'7540','7540','09', '11000003','00','Request by Mr. reheel malik 23-may-2025');
A244: KHI/HO/D/MO/PC COMP/C/107260/1/02/2025 | B244: =VLOOKUP(A244,Sheet7!B:C,2,0) -> 070000176594 | C244: 7540 | D244: =ROUND(C244,0) -> 7540 | E244: 23May250004 | F244: ="insert into ins_premium_det (premium_rcv_code,assorted_code, rec_amount,premium_rcv_detail_code,remaining_amt, payrec, mode_code,coinsurance_code,class_cd,it_remarks) values" -> insert into ins_premium_det (premium_rcv_code,assorted_code, rec_amount,premium_rcv_detail_code,remaining_amt, payrec, mode_code,coinsurance_code,class_cd,it_remarks) values | G244: ="('"&E244&"','"&B244&"','"&C244&"',(select max(to_number(i.premium_rcv_detail_code))+1 from ins_premium_det i),'"&C244&"','"&C244&"','09', '11000003','00','Request by Mr. reheel malik 23-may-2025');" -> ('23May250004','070000176594','7540',(select max(to_number(i.premium_rcv_detail_code))+1 from ins_premium_det i),'7540','7540','09', '11000003','00','Request by Mr. reheel malik 23-may-2025'); | H244: =F244&G244 -> insert into ins_premium_det (premium_rcv_code,assorted_code, rec_amount,premium_rcv_detail_code,remaining_amt, payrec, mode_code,coinsurance_code,class_cd,it_remarks) values('23May250004','070000176594','7540',(select max(to_number(i.premium_rcv_detail_code))+1 from ins_premium_det i),'7540','7540','09', '11000003','00','Request by Mr. reheel malik 23-may-2025');
...

Sheet Sheet5
A1: KHI/HO/D/MO/PC COMP/C/106033/2/01/2025 | B1: -01-2025 | H1: 106033 | I1: 00002 | J1: ="ia.assorted_string like '%"&H1&"-"&I1&B1&"%' or" -> ia.assorted_string like '%106033-00002-01-2025%' or
A2: KHI/HO/D/MO/PC COMP/C/106254/1/01/2025 | B2: -01-2025 | H2: 106254 | I2: 00001 | J2: ="ia.assorted_string like '%"&H2&"-"&I2&B2&"%' or" -> ia.assorted_string like '%106254-00001-01-2025%' or
A3: KHI/HO/D/MO/PC COMP/E/52647/00004/02/2025 | B3: -02-2025 | H3: 52647 | I3: 00004 | J3: ="ia.assorted_string like '%"&H3&"-"&I3&B3&"%' or" -> ia.assorted_string like '%52647-00004-02-2025%' or
A4: KHI/HO/D/MO/CV/C/107155/1/02/2025 | B4: -02-2025 | H4: 107155 | I4: 00001 | J4: ="ia.assorted_string like '%"&H4&"-"&I4&B4&"%' or" -> ia.assorted_string like '%107155-00001-02-2025%' or
