Workbook

Sheet Invoice
C9: FOR THE MONTH OF September-24
C11: INVOICE # 0018
C13: Policy | E13: As Per Schedule | G13: Risk Covered | I13: MOTORCYCLE COMPREHENSIVE
C15: Participant Name | E15: PAK SUZUKI MOTOR COMPANY LIMITED.
C17: Address | E17: DSU-13 PAKISTAN STEEL INDUSTRIAL ESTATE, BIN QASIM, KARACHI -75000.
C20: Expiry Date : | E20: To be advised | H20: Make: | J20: Suzuki Motorcycle
C21: Effective Date: | E21: To be advised | H21: No of Bikes | J21: =Detail!A1 -> 958
C22: Date Of Issue: | E22: To be advised
C25: Computation
C27: Gross Contribution | K27: =Detail!J1 -> 10619930
C28: SST 15% | K28: =Detail!P1 -> 1004359.4
C29: F.I.F 1% | K29: =Detail!Q1 -> 66957.29
C30: Stamp Duty | K30: =Detail!R1 -> 311500
C31: Net Contribution | K31: =Detail!I1 -> 12797941
C34: =CONCATENATE(C36,F36,C37) -> Payment Of PKR. Rs. 12,797,941/- be cheque in favour of M/s. Salaam Takaful Limited.
C36: Payment Of PKR. Rs. | F36: =TEXT(K31,"##,###,###") -> 12,797,941
C37: /- be cheque in favour of M/s. Salaam Takaful Limited.

Sheet Summary
A3: Showroom | B3: No. Of Policies | C3: Net Premium
A4: Suzuki Defence Motors | B4: 20 | C4: 347015
A5: A R Suzuki | B5: 70 | C5: 1141556
A6: FSD Suzuki | B6: 100 | C6: 942850
A7: GT Suzuki | B7: 45 | C7: 432975
A8: Khalil Motor | B8: 59 | C8: 974062
A9: South | B9: 52 | C9: 877758
A10: Suzuki Mandviwalla Motors | B10: 50 | C10: 834195
A11: TR Suzuki | B11: 74 | C11: 1220962
A12: UP Suzuki | B12: 63 | C12: 1049077
A13: UR Suzuki | B13: 109 | C13: 1775912
A14: KR Suzuki | B14: 8 | C14: 80150
A15: GR Suzuki | B15: 16 | C15: 156550
... A32: Grand Total | B32: 958 | C32: 12797941

Sheet Detail
A1: =COUNTIFS(R3:R1048576,">=0") -> 958 | I1: =SUBTOTAL(9,I3:I960) -> 12797941 | J1: =SUBTOTAL(9,J3:J960) -> 10619930 | P1: =SUBTOTAL(9,P3:P625) -> 1004359.4 | Q1: =SUBTOTAL(9,Q3:Q625) -> 66957.29 | R1: =SUBTOTAL(9,R3:R625) -> 311500
A2: Policy # | B2: Endorsement | C2: Dealer | D2: Branch | E2: Period From | F2: Period To | G2: Insured Name | H2: Vehicle Info | I2: Net | J2: Gross | K2: Rate | L2: Engine | M2: Issue date | N2: Policy Name | O2: SumCovered | P2: SST 15% | Q2: F.I.F 1% | R2: Stamp Duty
A3: KHI/HO/D/MO/MC COMP/P/96539/09/2024 | C3: Suzuki R.Y.Khan | D3: Punjab | E3: 45537 | F3: 45902 | G3: AMIR SOHAIL | H3: SUZUKI-GD-110S | I3: 8800 | J3: 7155 | K3: =I3/O3 -> 0.025 | L3: 146592 | M3: 45537 | N3: MOTORCYCLE COMPREHENSIVE | O3: 352000 | P3: =J3*15/100 -> 1073.25 | Q3: =J3*1/100 -> 71.55 | R3: 500
A4: KHI/HO/D/MO/MC COMP/P/96540/09/2024 | C4: UP Suzuki | D4: South | E4: 45537 | F4: 45902 | G4: FARRUKH KHAN | H4: SUZUKI-GR150 EURO II | I4: 23248 | J4: 19610 | K4: =I4/O4 -> 0.042500914 | L4: 113678 | M4: 45537 | N4: MOTORCYCLE COMPREHENSIVE | O4: 547000 | P4: =J4*15/100 -> 2941.5 | Q4: =J4*1/100 -> 196.1 | R4: 500
A5: KHI/HO/D/MO/MC COMP/P/96541/09/2024 | C5: UP Suzuki | D5: South | E5: 45903 | F5: 46268 | G5: FARRUKH KHAN | H5: SUZUKI-GR150 EURO II | I5: 23248 | J5: 19610 | K5: =I5/O5 -> 0.042500914 | L5: 113678 | M5: 45537 | N5: MOTORCYCLE COMPREHENSIVE | O5: 547000 | P5: =J5*15/100 -> 2941.5 | Q5: =J5*1/100 -> 196.1 | R5: 500
A6: KHI/HO/D/MO/MC COMP/P/96550/09/2024 | B6: UR | C6: South | D6: South | E6: 45537 | F6: 45902 | G6: MUHAMMAD USMAN RASHEED | H6: SUZUKI-GS 150 | I6: 16235 | J6: 13565 | K6: =I6/O6 -> 0.0425 | L6: 30092818 | M6: 45537 | N6: MOTORCYCLE COMPREHENSIVE | O6: 382000 | P6: =J6*15/100 -> 2034.75 | Q6: =J6*1/100 -> 135.65 | R6: 500
A7: KHI/HO/D/MO/MC COMP/P/96551/09/2024 | B7: AR | C7: South | D7: South | E7: 45903 | F7: 46268 | G7: MUHAMMAD USMAN RASHEED | H7: SUZUKI-GS 150 | I7: 16235 | J7: 13565 | K7: =I7/O7 -> 0.0425 | L7: 30092818 | M7: 45537 | N7: MOTORCYCLE COMPREHENSIVE | O7: 382000 | P7: =J7*15/100 -> 2034.75 | Q7: =J7*1/100 -> 135.65 | R7: 500
A8: KHI/HO/D/MO/MC COMP/P/96553/09/2024 | B8: TR | C8: Suzuki R.Y.Khan | D8: Punjab | E8: 45537 | F8: 45902 | G8: MAHBOOB SATTAR | H8: SUZUKI-GS 150 | I8: 9550 | J8: 7802 | K8: =I8/O8 -> 0.025 | L8: 30092452 | M8: 45537 | N8: MOTORCYCLE COMPREHENSIVE | O8: 382000 | P8: =J8*15/100 -> 1170.3 | Q8: =J8*1/100 -> 78.02 | R8: 500
A9: KHI/HO/D/MO/MC COMP/P/96560/09/2024 | B9: UP | C9: Suzuki R.Y.Khan | D9: Punjab | E9: 45537 | F9: 45902 | G9: MUHAMMAD USMAN ASHRAF TAHIR | H9: SUZUKI-GD-110S | I9: 8800 | J9: 7155 | K9: =I9/O9 -> 0.025 | L9: 146583 | M9: 45537 | N9: MOTORCYCLE COMPREHENSIVE | O9: 352000 | P9: =J9*15/100 -> 1073.25 | Q9: =J9*1/100 -> 71.55 | R9: 500
A10: KHI/HO/D/MO/MC COMP/P/96581/09/2024 | B10: KHALIL | C10: A R Suzuki | D10: South | E10: 45537 | F10: 45902 | G10: ASIF SHAHZAD | H10: SUZUKI-GD-110S | I10: 14960 | J10: 12466 | K10: =I10/O10 -> 0.0425 | L10: 147698 | M10: 45537 | N10: MOTORCYCLE COMPREHENSIVE | O10: 352000 | P10: =J10*15/100 -> 1869.9 | Q10: =J10*1/100 -> 124.66 | R10: 500
A11: KHI/HO/D/MO/MC COMP/P/96585/09/2024 | B11: MANDIVALA | C11: A R Suzuki | D11: South | E11: 45537 | F11: 45902 | G11: WASEEM AKHTAR | H11: SUZUKI-GD-110S | I11: 14960 | J11: 12466 | K11: =I11/O11 -> 0.0425 | L11: 147671 | M11: 45537 | N11: MOTORCYCLE COMPREHENSIVE | O11: 352000 | P11: =J11*15/100 -> 1869.9 | Q11: =J11*1/100 -> 124.66 | R11: 500
A12: KHI/HO/D/MO/MC COMP/P/96587/09/2024 | B12: SOIUTH | C12: Khalil Motor | D12: South | E12: 45537 | F12: 45902 | G12: MEHTAB AHMED KHAN | H12: SUZUKI-GD-110S | I12: 14960 | J12: 12466 | K12: =I12/O12 -> 0.0425 | L12: 146190 | M12: 45537 | N12: MOTORCYCLE COMPREHENSIVE | O12: 352000 | P12: =J12*15/100 -> 1869.9 | Q12: =J12*1/100 -> 124.66 | R12: 500
A13: KHI/HO/D/MO/MC COMP/P/96589/09/2024 | B13: ZEESHAN | C13: Khalil Motor | D13: South | E13: 45537 | F13: 45902 | G13: ABDUL HAMEED | H13: SUZUKI-GD-110S | I13: 14960 | J13: 12466 | K13: =I13/O13 -> 0.0425 | L13: 147710 | M13: 45537 | N13: MOTORCYCLE COMPREHENSIVE | O13: 352000 | P13: =J13*15/100 -> 1869.9 | Q13: =J13*1/100 -> 124.66 | R13: 500
A14: KHI/HO/D/MO/MC COMP/P/96590/09/2024 | B14: DEFFENCE | C14: Khalil Motor | D14: South | E14: 45537 | F14: 45902 | G14: S SHAMSHAD HUSSAIN | H14: SUZUKI-GD-110S | I14: 14960 | J14: 12466 | K14: =I14/O14 -> 0.0425 | L14: 147709 | M14: 45537 | N14: MOTORCYCLE COMPREHENSIVE | O14: 352000 | P14: =J14*15/100 -> 1869.9 | Q14: =J14*1/100 -> 124.66 | R14: 500
A15: KHI/HO/D/MO/MC COMP/P/96611/09/2024 | C15: UR Suzuki | D15: South | E15: 45903 | F15: 46268 | G15: FAHIM KHAN | H15: SUZUKI-GS 150 | I15: 16235 | J15: 13565 | K15: =I15/O15 -> 0.0425 | L15: 30092769 | M15: 45537 | N15: MOTORCYCLE COMPREHENSIVE | O15: 382000 | P15: =J15*15/100 -> 2034.75 | Q15: =J15*1/100 -> 135.65 | R15: 500
A16: KHI/HO/D/MO/MC COMP/P/96612/09/2024 | C16: Suzuki R.Y.Khan | D16: Punjab | E16: 45537 | F16: 45902 | G16: MUHAMMAD ALI AMIN | H16: SUZUKI-GD-110S | I16: 8800 | J16: 7155 | K16: =I16/O16 -> 0.025 | L16: 147895 | M16: 45537 | N16: MOTORCYCLE COMPREHENSIVE | O16: 352000 | P16: =J16*15/100 -> 1073.25 | Q16: =J16*1/100 -> 71.55 | R16: 500
A17: KHI/HO/D/MO/MC COMP/P/96613/09/2024 | C17: Suzuki R.Y.Khan | D17: Punjab | E17: 45537 | F17: 45902 | G17: MUHAMMAD TAYYAB NAWAZ | H17: SUZUKI-GD-110S | I17: 8800 | J17: 7155 | K17: =I17/O17 -> 0.025 | L17: 146424 | M17: 45537 | N17: MOTORCYCLE COMPREHENSIVE | O17: 352000 | P17: =J17*15/100 -> 1073.25 | Q17: =J17*1/100 -> 71.55 | R17: 500
A18: KHI/HO/D/MO/MC COMP/P/96626/09/2024 | C18: TR Suzuki | D18: South | E18: 45538 | F18: 45903 | G18: MUHAMMAD IMRAN | H18: SUZUKI-GD-110S | I18: 14960 | J18: 12466 | K18: =I18/O18 -> 0.0425 | L18: 147697 | M18: 45538 | N18: MOTORCYCLE COMPREHENSIVE | O18: 352000 | P18: =J18*15/100 -> 1869.9 | Q18: =J18*1/100 -> 124.66 | R18: 500
A19: KHI/HO/D/MO/MC COMP/P/96630/09/2024 | C19: Suzuki Defence Motors | D19: South | E19: 45538 | F19: 45903 | G19: HASSAN HUSSAIN KHAN | H19: SUZUKI-GD-110S | I19: 14960 | J19: 12466 | K19: =I19/O19 -> 0.0425 | L19: 147837 | M19: 45538 | N19: MOTORCYCLE COMPREHENSIVE | O19: 352000 | P19: =J19*15/100 -> 1869.9 | Q19: =J19*1/100 -> 124.66 | R19: 500
A20: KHI/HO/D/MO/MC COMP/P/96636/09/2024 | C20: Suzuki Canal Motors Faisalabad Branch | D20: Punjab | E20: 45538 | F20: 45903 | G20: AWAIS ALI | H20: SUZUKI-GS 150 | I20: 9550 | J20: 7802 | K20: =I20/O20 -> 0.025 | L20: 30092650 | M20: 45538 | N20: MOTORCYCLE COMPREHENSIVE | O20: 382000 | P20: =J20*15/100 -> 1170.3 | Q20: =J20*1/100 -> 78.02 | R20: 500
A21: KHI/HO/D/MO/MC COMP/P/96642/09/2024 | C21: Suzuki Canal Motors Faisalabad Branch | D21: Punjab | E21: 45538 | F21: 45903 | G21: MUHAMMAD HAROON | H21: SUZUKI-GD-110S | I21: 8800 | J21: 7155 | K21: =I21/O21 -> 0.025 | L21: 146568 | M21: 45538 | N21: MOTORCYCLE COMPREHENSIVE | O21: 352000 | P21: =J21*15/100 -> 1073.25 | Q21: =J21*1/100 -> 71.55 | R21: 500
A22: KHI/HO/D/MO/MC COMP/P/96651/09/2024 | C22: TR Suzuki | D22: South | E22: 45904 | F22: 46269 | G22: MUHAMMAD FARHAN | H22: SUZUKI-GR150 EURO II | I22: 23248 | J22: 19610 | K22: =I22/O22 -> 0.042500914 | L22: 113647 | M22: 45538 | N22: MOTORCYCLE COMPREHENSIVE | O22: 547000 | P22: =J22*15/100 -> 2941.5 | Q22: =J22*1/100 -> 196.1 | R22: 500
A23: KHI/HO/D/MO/MC COMP/P/96659/09/2024 | C23: TR Suzuki | D23: South | E23: 45538 | F23: 45903 | G23: MUHAMMAD UBAID | H23: SUZUKI-GR150 EURO II | I23: 23248 | J23: 19610 | K23: =I23/O23 -> 0.042500914 | L23: 113663 | M23: 45538 | N23: MOTORCYCLE COMPREHENSIVE | O23: 547000 | P23: =J23*15/100 -> 2941.5 | Q23: =J23*1/100 -> 196.1 | R23: 500
A24: KHI/HO/D/MO/MC COMP/P/96671/09/2024 | C24: WR Suzuki | D24: Punjab | E24: 45538 | F24: 45903 | G24: Rehman ALi | H24: SUZUKI-GD-110S | I24: 8800 | J24: 7155 | K24: =I24/O24 -> 0.025 | L24: 147603 | M24: 45538 | N24: MOTORCYCLE COMPREHENSIVE | O24: 352000 | P24: =J24*15/100 -> 1073.25 | Q24: =J24*1/100 -> 71.55 | R24: 500
A25: KHI/HO/D/MO/MC COMP/P/96673/09/2024 | C25: GR Suzuki | D25: Punjab | E25: 45538 | F25: 45903 | G25: RANA ASHFAQ MANZOOR | H25: SUZUKI-GD-110S | I25: 8800 | J25: 7155 | K25: =I25/O25 -> 0.025 | L25: 144807 | M25: 45538 | N25: MOTORCYCLE COMPREHENSIVE | O25: 352000 | P25: =J25*15/100 -> 1073.25 | Q25: =J25*1/100 -> 71.55 | R25: 500
A26: KHI/HO/D/MO/MC COMP/P/96679/09/2024 | C26: TR Suzuki | D26: South | E26: 45538 | F26: 45903 | G26: AYAZ HUSSAIN | H26: SUZUKI-GD-110S | I26: 14960 | J26: 12466 | K26: =I26/O26 -> 0.0425 | L26: 146487 | M26: 45538 | N26: MOTORCYCLE COMPREHENSIVE | O26: 352000 | P26: =J26*15/100 -> 1869.9 | Q26: =J26*1/100 -> 124.66 | R26: 500
... A72: KHI/HO/D/MO/MC COMP/P/96820/09/2024 | C72: FSD Suzuki | D72: Punjab | E72: 45540 | F72: 45905 | G72: SAQIB NASEEM AKBAR | H72: SUZUKI-GSX 125 | I72: 12475 | J72: 10323 | K72: =I72/O72 -> 0.025 | L72: 23102476 | M72: 45540 | N72: MOTORCYCLE COMPREHENSIVE | O72: 499000 | P72: =J72*15/100 -> 1548.45 | Q72: =J72*1/100 -> 103.23 | R72: 500
A73: KHI/HO/D/MO/MC COMP/P/96821/09/2024 | C73: TR Suzuki | D73: South | E73: 45849 | F73: 46214 | G73: MUHAMMAD SHUJAAT HUSSAIN | H73: SUZUKI-GR150 EURO II | I73: 13615 | J73: 11306 | K73: =I73/O73 -> 0.035363636 | L73: 110777 | M73: 45540 | N73: MOTORCYCLE COMPREHENSIVE | O73: 385000 | P73: =J73*15/100 -> 1695.9 | Q73: =J73*1/100 -> 113.06 | R73: 500 | S73: RATE ISSUE
A74: KHI/HO/D/MO/MC COMP/P/96822/09/2024 | C74: TR Suzuki | D74: South | E74: 45540 | F74: 45905 | G74: MUHAMMAD WAQAS SADIQ | H74: SUZUKI-GD-110S | I74: 14960 | J74: 12466 | K74: =I74/O74 -> 0.0425 | L74: 147975 | M74: 45540 | N74: MOTORCYCLE COMPREHENSIVE | O74: 352000 | P74: =J74*15/100 -> 1869.9 | Q74: =J74*1/100 -> 124.66 | R74: 500
A75: KHI/HO/D/MO/MC COMP/P/96823/09/2024 | C75: TR Suzuki | D75: South | E75: 45906 | F75: 46271 | G75: MUHAMMAD WAQAS SADIQ | H75: SUZUKI-GD-110S | I75: 14960 | J75: 12466 | K75: =I75/O75 -> 0.0425 | L75: 147975 | M75: 45540 | N75: MOTORCYCLE COMPREHENSIVE | O75: 352000 | P75: =J75*15/100 -> 1869.9 | Q75: =J75*1/100 -> 124.66 | R75: 500
A76: KHI/HO/D/MO/MC COMP/P/96825/09/2024 | C76: FSD Suzuki | D76: Punjab | E76: 45540 | F76: 45905 | G76: MUHAMMAD YASEEN SHAHID | H76: SUZUKI-GD-110S | I76: 8800 | J76: 7155 | K76: =I76/O76 -> 0.025 | L76: 145171 | M76: 45540 | N76: MOTORCYCLE COMPREHENSIVE | O76: 352000 | P76: =J76*15/100 -> 1073.25 | Q76: =J76*1/100 -> 71.55 | R76: 500
A77: KHI/HO/D/MO/MC COMP/P/96828/09/2024 | C77: FSD Suzuki | D77: Punjab | E77: 45540 | F77: 45905 | G77: MATEEN BIN TARIQ | H77: SUZUKI-GD-110S | I77: 8800 | J77: 7155 | K77: =I77/O77 -> 0.025 | L77: 146418 | M77: 45540 | N77: MOTORCYCLE COMPREHENSIVE | O77: 352000 | P77: =J77*15/100 -> 1073.25 | Q77: =J77*1/100 -> 71.55 | R77: 500
A78: KHI/HO/D/MO/MC COMP/P/96829/09/2024 | C78: FSD Suzuki | D78: Punjab | E78: 45540 | F78: 45905 | G78: MUHAMMAD NADEEM ASHRAF | H78: SUZUKI-GD-110S | I78: 8800 | J78: 7155 | K78: =I78/O78 -> 0.025 | L78: 146429 | M78: 45540 | N78: MOTORCYCLE COMPREHENSIVE | O78: 352000 | P78: =J78*15/100 -> 1073.25 | Q78: =J78*1/100 -> 71.55 | R78: 500
A79: KHI/HO/D/MO/MC COMP/P/96830/09/2024 | C79: FSD Suzuki | D79: Punjab | E79: 45540 | F79: 45905 | G79: ABDUL WADOOD | H79: SUZUKI-GD-110S | I79: 8800 | J79: 7155 | K79: =I79/O79 -> 0.025 | L79: 146351 | M79: 45540 | N79: MOTORCYCLE COMPREHENSIVE | O79: 352000 | P79: =J79*15/100 -> 1073.25 | Q79: =J79*1/100 -> 71.55 | R79: 500
A80: KHI/HO/D/MO/MC COMP/P/96831/09/2024 | C80: FSD Suzuki | D80: Punjab | E80: 45540 | F80: 45905 | G80: ABDUL WADOOD | H80: SUZUKI-GD-110S | I80: 8800 | J80: 7155 | K80: =I80/O80 -> 0.025 | L80: 146351 | M80: 45540 | N80: MOTORCYCLE COMPREHENSIVE | O80: 352000 | P80: =J80*15/100 -> 1073.25 | Q80: =J80*1/100 -> 71.55 | R80: 500
A81: KHI/HO/D/MO/MC COMP/P/96833/09/2024 | C81: FSD Suzuki | D81: Punjab | E81: 45540 | F81: 45905 | G81: MUHAMMAD SAQLAIN SHAH | H81: SUZUKI-GD-110S | I81: 8800 | J81: 7155 | K81: =I81/O81 -> 0.025 | L81: 146433 | M81: 45540 | N81: MOTORCYCLE COMPREHENSIVE | O81: 352000 | P81: =J81*15/100 -> 1073.25 | Q81: =J81*1/100 -> 71.55 | R81: 500
A82: KHI/HO/D/MO/MC COMP/P/96834/09/2024 | C82: FSD Suzuki | D82: Punjab | E82: 45540 | F82: 45905 | G82: BILAL NAEEM | H82: SUZUKI-GD-110S | I82: 8800 | J82: 7155 | K82: =I82/O82 -> 0.025 | L82: 146420 | M82: 45540 | N82: MOTORCYCLE COMPREHENSIVE | O82: 352000 | P82: =J82*15/100 -> 1073.25 | Q82: =J82*1/100 -> 71.55 | R82: 500
A83: KHI/HO/D/MO/MC COMP/P/96835/09/2024 | C83: FSD Suzuki | D83: Punjab | E83: 45540 | F83: 45905 | G83: MUHAMMAD ABID | H83: SUZUKI-GD-110S | I83: 8800 | J83: 7155 | K83: =I83/O83 -> 0.025 | L83: 146419 | M83: 45540 | N83: MOTORCYCLE COMPREHENSIVE | O83: 352000 | P83: =J83*15/100 -> 1073.25 | Q83: =J83*1/100 -> 71.55 | R83: 500
A84: KHI/HO/D/MO/MC COMP/P/96836/09/2024 | C84: Suzuki R.Y.Khan | D84: Punjab | E84: 45540 | F84: 45905 | G84: MUHAMMAD HASSAN | H84: SUZUKI-GD-110S | I84: 8800 | J84: 7155 | K84: =I84/O84 -> 0.025 | L84: 147899 | M84: 45540 | N84: MOTORCYCLE COMPREHENSIVE | O84: 352000 | P84: =J84*15/100 -> 1073.25 | Q84: =J84*1/100 -> 71.55 | R84: 500
A85: KHI/HO/D/MO/MC COMP/P/96838/09/2024 | C85: TR Suzuki | D85: South | E85: 45540 | F85: 45905 | G85: NISAR AKHTAR | H85: SUZUKI-GD-110S | I85: 14960 | J85: 12466 | K85: =I85/O85 -> 0.0425 | L85: 147916 | M85: 45540 | N85: MOTORCYCLE COMPREHENSIVE | O85: 352000 | P85: =J85*15/100 -> 1869.9 | Q85: =J85*1/100 -> 124.66 | R85: 500
...

Sheet PKSUZ PREM OCT 2
A1: Policy # | B1: PREM
A2: KHI/HO/D/MO/MC COMP/P/96539/09/2024 | B2: 8800
A3: KHI/HO/D/MO/MC COMP/P/96540/09/2024 | B3: 23248
A4: KHI/HO/D/MO/MC COMP/P/96541/09/2024 | B4: 23248
A5: KHI/HO/D/MO/MC COMP/P/96550/09/2024 | B5: 16235
A6: KHI/HO/D/MO/MC COMP/P/96551/09/2024 | B6: 16235
A7: KHI/HO/D/MO/MC COMP/P/96553/09/2024 | B7: 9550
A8: KHI/HO/D/MO/MC COMP/P/96560/09/2024 | B8: 8800
A9: KHI/HO/D/MO/MC COMP/P/96581/09/2024 | B9: 14960
A10: KHI/HO/D/MO/MC COMP/P/96585/09/2024 | B10: 14960
A11: KHI/HO/D/MO/MC COMP/P/96587/09/2024 | B11: 14960
A12: KHI/HO/D/MO/MC COMP/P/96589/09/2024 | B12: 14960
A13: KHI/HO/D/MO/MC COMP/P/96590/09/2024 | B13: 14960
... A71: KHI/HO/D/MO/MC COMP/P/96820/09/2024 | B71: 12475
A72: KHI/HO/D/MO/MC COMP/P/96821/09/2024 | B72: 13615 | C72: RATE ISSUE
A73: KHI/HO/D/MO/MC COMP/P/96822/09/2024 | B73: 14960
A74: KHI/HO/D/MO/MC COMP/P/96823/09/2024 | B74: 14960
A75: KHI/HO/D/MO/MC COMP/P/96825/09/2024 | B75: 8800
A76: KHI/HO/D/MO/MC COMP/P/96828/09/2024 | B76: 8800
A77: KHI/HO/D/MO/MC COMP/P/96829/09/2024 | B77: 8800
A78: KHI/HO/D/MO/MC COMP/P/96830/09/2024 | B78: 8800
A79: KHI/HO/D/MO/MC COMP/P/96831/09/2024 | B79: 8800
A80: KHI/HO/D/MO/MC COMP/P/96833/09/2024 | B80: 8800
A81: KHI/HO/D/MO/MC COMP/P/96834/09/2024 | B81: 8800
A82: KHI/HO/D/MO/MC COMP/P/96835/09/2024 | B82: 8800
A83: KHI/HO/D/MO/MC COMP/P/96836/09/2024 | B83: 8800
A84: KHI/HO/D/MO/MC COMP/P/96838/09/2024 | B84: 14960
... A397: KHI/HO/D/MO/MC COMP/P/97619/09/2024 | B397: 8800
A398: KHI/HO/D/MO/MC COMP/P/97620/09/2024 | B398: 8800 | C398: sum covered chn
A399: KHI/HO/D/MO/MC COMP/P/97621/09/2024 | B399: 12475
A400: KHI/HO/D/MO/MC COMP/P/97623/09/2024 | B400: 8800
A401: KHI/HO/D/MO/MC COMP/P/97624/09/2024 | B401: 14960
A402: KHI/HO/D/MO/MC COMP/P/97625/09/2024 | B402: 8800
A403: KHI/HO/D/MO/MC COMP/P/97626/09/2024 | B403: 14960
A404: KHI/HO/D/MO/MC COMP/P/97633/09/2024 | B404: 9550
A405: KHI/HO/D/MO/MC COMP/P/97636/09/2024 | B405: 9550
A406: KHI/HO/D/MO/MC COMP/P/97638/09/2024 | B406: 8800
A407: KHI/HO/D/MO/MC COMP/P/97639/09/2024 | B407: 8800
A408: KHI/HO/D/MO/MC COMP/P/97641/09/2024 | B408: 8800
A409: KHI/HO/D/MO/MC COMP/P/97642/09/2024 | B409: 8800
...

Sheet working
A1: POLICY NO. | B1: Assorted_code | D1: Premium | E1: 29Oct240071
A2: KHI/HO/D/MO/MC COMP/P/96539/09/2024 | B2: =VLOOKUP(A2,policy!B:C,2,0) -> 040000183086 | C2: 8800 | D2: =ROUND(C2,0) -> 8800 | E2: 29Oct240071 | F2: ="insert into ins_premium_det (premium_rcv_code,assorted_code, rec_amount,premium_rcv_detail_code,remaining_amt, payrec, mode_code,coinsurance_code,class_cd,it_remarks) values" -> insert into ins_premium_det (premium_rcv_code,assorted_code, rec_amount,premium_rcv_detail_code,remaining_amt, payrec, mode_code,coinsurance_code,class_cd,it_remarks) values | G2: ="('"&E2&"','"&B2&"','"&D2&"',(select max(to_number(i.premium_rcv_detail_code))+1 from ins_premium_det i),'"&D2&"','"&D2&"','02', '11000003','00','Request by Mr. Omair Ali 30-Aug-2024');" -> ('29Oct240071','040000183086','8800',(select max(to_number(i.premium_rcv_detail_code))+1 from ins_premium_det i),'8800','8800','02', '11000003','00','Request by Mr. Omair Ali 30-Aug-2024'); | H2: =F2&G2 -> insert into ins_premium_det (premium_rcv_code,assorted_code, rec_amount,premium_rcv_detail_code,remaining_amt, payrec, mode_code,coinsurance_code,class_cd,it_remarks) values('29Oct240071','040000183086','8800',(select max(to_number(i.premium_rcv_detail_code))+1 from ins_premium_det i),'8800','8800','02', '11000003','00','Request by Mr. Omair Ali 30-Aug-2024');
A3: KHI/HO/D/MO/MC COMP/P/96540/09/2024 | B3: =VLOOKUP(A3,policy!B:C,2,0) -> 040000183087 | C3: 23248 | D3: =ROUND(C3,0) -> 23248 | E3: 29Oct240071 | F3: ="insert into ins_premium_det (premium_rcv_code,assorted_code, rec_amount,premium_rcv_detail_code,remaining_amt, payrec, mode_code,coinsurance_code,class_cd,it_remarks) values" -> insert into ins_premium_det (premium_rcv_code,assorted_code, rec_amount,premium_rcv_detail_code,remaining_amt, payrec, mode_code,coinsurance_code,class_cd,it_remarks) values | G3: ="('"&E3&"','"&B3&"','"&D3&"',(select max(to_number(i.premium_rcv_detail_code))+1 from ins_premium_det i),'"&D3&"','"&D3&"','02', '11000003','00','Request by Mr. Omair Ali 30-Aug-2024');" -> ('29Oct240071','040000183087','23248',(select max(to_number(i.premium_rcv_detail_code))+1 from ins_premium_det i),'23248','23248','02', '11000003','00','Request by Mr. Omair Ali 30-Aug-2024'); | H3: =F3&G3 -> insert into ins_premium_det (premium_rcv_code,assorted_code, rec_amount,premium_rcv_detail_code,remaining_amt, payrec, mode_code,coinsurance_code,class_cd,it_remarks) values('29Oct240071','040000183087','23248',(select max(to_number(i.premium_rcv_detail_code))+1 from ins_premium_det i),'23248','23248','02', '11000003','00','Request by Mr. Omair Ali 30-Aug-2024');
A4: KHI/HO/D/MO/MC COMP/P/96541/09/2024 | B4: =VLOOKUP(A4,policy!B:C,2,0) -> 040000183088 | C4: 23248 | D4: =ROUND(C4,0) -> 23248 | E4: 29Oct240071 | F4: ="insert into ins_premium_det (premium_rcv_code,assorted_code, rec_amount,premium_rcv_detail_code,remaining_amt, payrec, mode_code,coinsurance_code,class_cd,it_remarks) values" -> insert into ins_premium_det (premium_rcv_code,assorted_code, rec_amount,premium_rcv_detail_code,remaining_amt, payrec, mode_code,coinsurance_code,class_cd,it_remarks) values | G4: ="('"&E4&"','"&B4&"','"&D4&"',(select max(to_number(i.premium_rcv_detail_code))+1 from ins_premium_det i),'"&D4&"','"&D4&"','02', '11000003','00','Request by Mr. Omair Ali 30-Aug-2024');" -> ('29Oct240071','040000183088','23248',(select max(to_number(i.premium_rcv_detail_code))+1 from ins_premium_det i),'23248','23248','02', '11000003','00','Request by Mr. Omair Ali 30-Aug-2024'); | H4: =F4&G4 -> insert into ins_premium_det (premium_rcv_code,assorted_code, rec_amount,premium_rcv_detail_code,remaining_amt, payrec, mode_code,coinsurance_code,class_cd,it_remarks) values('29Oct240071','040000183088','23248',(select max(to_number(i.premium_rcv_detail_code))+1 from ins_premium_det i),'23248','23248','02', '11000003','00','Request by Mr. Omair Ali 30-Aug-2024');
A5: KHI/HO/D/MO/MC COMP/P/96550/09/2024 | B5: =VLOOKUP(A5,policy!B:C,2,0) -> 040000183099 | C5: 16235 | D5: =ROUND(C5,0) -> 16235 | E5: 29Oct240071 | F5: ="insert into ins_premium_det (premium_rcv_code,assorted_code, rec_amount,premium_rcv_detail_code,remaining_amt, payrec, mode_code,coinsurance_code,class_cd,it_remarks) values" -> insert into ins_premium_det (premium_rcv_code,assorted_code, rec_amount,premium_rcv_detail_code,remaining_amt, payrec, mode_code,coinsurance_code,class_cd,it_remarks) values | G5: ="('"&E5&"','"&B5&"','"&D5&"',(select max(to_number(i.premium_rcv_detail_code))+1 from ins_premium_det i),'"&D5&"','"&D5&"','02', '11000003','00','Request by Mr. Omair Ali 30-Aug-2024');" -> ('29Oct240071','040000183099','16235',(select max(to_number(i.premium_rcv_detail_code))+1 from ins_premium_det i),'16235','16235','02', '11000003','00','Request by Mr. Omair Ali 30-Aug-2024'); | H5: =F5&G5 -> insert into ins_premium_det (premium_rcv_code,assorted_code, rec_amount,premium_rcv_detail_code,remaining_amt, payrec, mode_code,coinsurance_code,class_cd,it_remarks) values('29Oct240071','040000183099','16235',(select max(to_number(i.premium_rcv_detail_code))+1 from ins_premium_det i),'16235','16235','02', '11000003','00','Request by Mr. Omair Ali 30-Aug-2024');
A6: KHI/HO/D/MO/MC COMP/P/96551/09/2024 | B6: =VLOOKUP(A6,policy!B:C,2,0) -> 040000183100 | C6: 16235 | D6: =ROUND(C6,0) -> 16235 | E6: 29Oct240071 | F6: ="insert into ins_premium_det (premium_rcv_code,assorted_code, rec_amount,premium_rcv_detail_code,remaining_amt, payrec, mode_code,coinsurance_code,class_cd,it_remarks) values" -> insert into ins_premium_det (premium_rcv_code,assorted_code, rec_amount,premium_rcv_detail_code,remaining_amt, payrec, mode_code,coinsurance_code,class_cd,it_remarks) values | G6: ="('"&E6&"','"&B6&"','"&D6&"',(select max(to_number(i.premium_rcv_detail_code))+1 from ins_premium_det i),'"&D6&"','"&D6&"','02', '11000003','00','Request by Mr. Omair Ali 30-Aug-2024');" -> ('29Oct240071','040000183100','16235',(select max(to_number(i.premium_rcv_detail_code))+1 from ins_premium_det i),'16235','16235','02', '11000003','00','Request by Mr. Omair Ali 30-Aug-2024'); | H6: =F6&G6 -> insert into ins_premium_det (premium_rcv_code,assorted_code, rec_amount,premium_rcv_detail_code,remaining_amt, payrec, mode_code,coinsurance_code,class_cd,it_remarks) values('29Oct240071','040000183100','16235',(select max(to_number(i.premium_rcv_detail_code))+1 from ins_premium_det i),'16235','16235','02', '11000003','00','Request by Mr. Omair Ali 30-Aug-2024');
A7: KHI/HO/D/MO/MC COMP/P/96553/09/2024 | B7: =VLOOKUP(A7,policy!B:C,2,0) -> 040000183102 | C7: 9550 | D7: =ROUND(C7,0) -> 9550 | E7: 29Oct240071 | F7: ="insert into ins_premium_det (premium_rcv_code,assorted_code, rec_amount,premium_rcv_detail_code,remaining_amt, payrec, mode_code,coinsurance_code,class_cd,it_remarks) values" -> insert into ins_premium_det (premium_rcv_code,assorted_code, rec_amount,premium_rcv_detail_code,remaining_amt, payrec, mode_code,coinsurance_code,class_cd,it_remarks) values | G7: ="('"&E7&"','"&B7&"','"&D7&"',(select max(to_number(i.premium_rcv_detail_code))+1 from ins_premium_det i),'"&D7&"','"&D7&"','02', '11000003','00','Request by Mr. Omair Ali 30-Aug-2024');" -> ('29Oct240071','040000183102','9550',(select max(to_number(i.premium_rcv_detail_code))+1 from ins_premium_det i),'9550','9550','02', '11000003','00','Request by Mr. Omair Ali 30-Aug-2024'); | H7: =F7&G7 -> insert into ins_premium_det (premium_rcv_code,assorted_code, rec_amount,premium_rcv_detail_code,remaining_amt, payrec, mode_code,coinsurance_code,class_cd,it_remarks) values('29Oct240071','040000183102','9550',(select max(to_number(i.premium_rcv_detail_code))+1 from ins_premium_det i),'9550','9550','02', '11000003','00','Request by Mr. Omair Ali 30-Aug-2024');
A8: KHI/HO/D/MO/MC COMP/P/96560/09/2024 | B8: =VLOOKUP(A8,policy!B:C,2,0) -> 040000183110 | C8: 8800 | D8: =ROUND(C8,0) -> 8800 | E8: 29Oct240071 | F8: ="insert into ins_premium_det (premium_rcv_code,assorted_code, rec_amount,premium_rcv_detail_code,remaining_amt, payrec, mode_code,coinsurance_code,class_cd,it_remarks) values" -> insert into ins_premium_det (premium_rcv_code,assorted_code, rec_amount,premium_rcv_detail_code,remaining_amt, payrec, mode_code,coinsurance_code,class_cd,it_remarks) values | G8: ="('"&E8&"','"&B8&"','"&D8&"',(select max(to_number(i.premium_rcv_detail_code))+1 from ins_premium_det i),'"&D8&"','"&D8&"','02', '11000003','00','Request by Mr. Omair Ali 30-Aug-2024');" -> ('29Oct240071','040000183110','8800',(select max(to_number(i.premium_rcv_detail_code))+1 from ins_premium_det i),'8800','8800','02', '11000003','00','Request by Mr. Omair Ali 30-Aug-2024'); | H8: =F8&G8 -> insert into ins_premium_det (premium_rcv_code,assorted_code, rec_amount,premium_rcv_detail_code,remaining_amt, payrec, mode_code,coinsurance_code,class_cd,it_remarks) values('29Oct240071','040000183110','8800',(select max(to_number(i.premium_rcv_detail_code))+1 from ins_premium_det i),'8800','8800','02', '11000003','00','Request by Mr. Omair Ali 30-Aug-2024');
A9: KHI/HO/D/MO/MC COMP/P/96581/09/2024 | B9: =VLOOKUP(A9,policy!B:C,2,0) -> 040000183132 | C9: 14960 | D9: =ROUND(C9,0) -> 14960 | E9: 29Oct240071 | F9: ="insert into ins_premium_det (premium_rcv_code,assorted_code, rec_amount,premium_rcv_detail_code,remaining_amt, payrec, mode_code,coinsurance_code,class_cd,it_remarks) values" -> insert into ins_premium_det (premium_rcv_code,assorted_code, rec_amount,premium_rcv_detail_code,remaining_amt, payrec, mode_code,coinsurance_code,class_cd,it_remarks) values | G9: ="('"&E9&"','"&B9&"','"&D9&"',(select max(to_number(i.premium_rcv_detail_code))+1 from ins_premium_det i),'"&D9&"','"&D9&"','02', '11000003','00','Request by Mr. Omair Ali 30-Aug-2024');" -> ('29Oct240071','040000183132','14960',(select max(to_number(i.premium_rcv_detail_code))+1 from ins_premium_det i),'14960','14960','02', '11000003','00','Request by Mr. Omair Ali 30-Aug-2024'); | H9: =F9&G9 -> insert into ins_premium_det (premium_rcv_code,assorted_code, rec_amount,premium_rcv_detail_code,remaining_amt, payrec, mode_code,coinsurance_code,class_cd,it_remarks) values('29Oct240071','040000183132','14960',(select max(to_number(i.premium_rcv_detail_code))+1 from ins_premium_det i),'14960','14960','02', '11000003','00','Request by Mr. Omair Ali 30-Aug-2024');
A10: KHI/HO/D/MO/MC COMP/P/96585/09/2024 | B10: =VLOOKUP(A10,policy!B:C,2,0) -> 040000183136 | C10: 14960 | D10: =ROUND(C10,0) -> 14960 | E10: 29Oct240071 | F10: ="insert into ins_premium_det (premium_rcv_code,assorted_code, rec_amount,premium_rcv_detail_code,remaining_amt, payrec, mode_code,coinsurance_code,class_cd,it_remarks) values" -> insert into ins_premium_det (premium_rcv_code,assorted_code, rec_amount,premium_rcv_detail_code,remaining_amt, payrec, mode_code,coinsurance_code,class_cd,it_remarks) values | G10: ="('"&E10&"','"&B10&"','"&D10&"',(select max(to_number(i.premium_rcv_detail_code))+1 from ins_premium_det i),'"&D10&"','"&D10&"','02', '11000003','00','Request by Mr. Omair Ali 30-Aug-2024');" -> ('29Oct240071','040000183136','14960',(select max(to_number(i.premium_rcv_detail_code))+1 from ins_premium_det i),'14960','14960','02', '11000003','00','Request by Mr. Omair Ali 30-Aug-2024'); | H10: =F10&G10 -> insert into ins_premium_det (premium_rcv_code,assorted_code, rec_amount,premium_rcv_detail_code,remaining_amt, payrec, mode_code,coinsurance_code,class_cd,it_remarks) values('29Oct240071','040000183136','14960',(select max(to_number(i.premium_rcv_detail_code))+1 from ins_premium_det i),'14960','14960','02', '11000003','00','Request by Mr. Omair Ali 30-Aug-2024');
A11: KHI/HO/D/MO/MC COMP/P/96587/09/2024 | B11: =VLOOKUP(A11,policy!B:C,2,0) -> 040000183138 | C11: 14960 | D11: =ROUND(C11,0) -> 14960 | E11: 29Oct240071 | F11: ="insert into ins_premium_det (premium_rcv_code,assorted_code, rec_amount,premium_rcv_detail_code,remaining_amt, payrec, mode_code,coinsurance_code,class_cd,it_remarks) values" -> insert into ins_premium_det (premium_rcv_code,assorted_code, rec_amount,premium_rcv_detail_code,remaining_amt, payrec, mode_code,coinsurance_code,class_cd,it_remarks) values | G11: ="('"&E11&"','"&B11&"','"&D11&"',(select max(to_number(i.premium_rcv_detail_code))+1 from ins_premium_det i),'"&D11&"','"&D11&"','02', '11000003','00','Request by Mr. Omair Ali 30-Aug-2024');" -> ('29Oct240071','040000183138','14960',(select max(to_number(i.premium_rcv_detail_code))+1 from ins_premium_det i),'14960','14960','02', '11000003','00','Request by Mr. Omair Ali 30-Aug-2024'); | H11: =F11&G11 -> insert into ins_premium_det (premium_rcv_code,assorted_code, rec_amount,premium_rcv_detail_code,remaining_amt, payrec, mode_code,coinsurance_code,class_cd,it_remarks) values('29Oct240071','040000183138','14960',(select max(to_number(i.premium_rcv_detail_code))+1 from ins_premium_det i),'14960','14960','02', '11000003','00','Request by Mr. Omair Ali 30-Aug-2024');
A12: KHI/HO/D/MO/MC COMP/P/96589/09/2024 | B12: =VLOOKUP(A12,policy!B:C,2,0) -> 040000183140 | C12: 14960 | D12: =ROUND(C12,0) -> 14960 | E12: 29Oct240071 | F12: ="insert into ins_premium_det (premium_rcv_code,assorted_code, rec_amount,premium_rcv_detail_code,remaining_amt, payrec, mode_code,coinsurance_code,class_cd,it_remarks) values" -> insert into ins_premium_det (premium_rcv_code,assorted_code, rec_amount,premium_rcv_detail_code,remaining_amt, payrec, mode_code,coinsurance_code,class_cd,it_remarks) values | G12: ="('"&E12&"','"&B12&"','"&D12&"',(select max(to_number(i.premium_rcv_detail_code))+1 from ins_premium_det i),'"&D12&"','"&D12&"','02', '11000003','00','Request by Mr. Omair Ali 30-Aug-2024');" -> ('29Oct240071','040000183140','14960',(select max(to_number(i.premium_rcv_detail_code))+1 from ins_premium_det i),'14960','14960','02', '11000003','00','Request by Mr. Omair Ali 30-Aug-2024'); | H12: =F12&G12 -> insert into ins_premium_det (premium_rcv_code,assorted_code, rec_amount,premium_rcv_detail_code,remaining_amt, payrec, mode_code,coinsurance_code,class_cd,it_remarks) values('29Oct240071','040000183140','14960',(select max(to_number(i.premium_rcv_detail_code))+1 from ins_premium_det i),'14960','14960','02', '11000003','00','Request by Mr. Omair Ali 30-Aug-2024');
A13: KHI/HO/D/MO/MC COMP/P/96590/09/2024 | B13: =VLOOKUP(A13,policy!B:C,2,0) -> 040000183141 | C13: 14960 | D13: =ROUND(C13,0) -> 14960 | E13: 29Oct240071 | F13: ="insert into ins_premium_det (premium_rcv_code,assorted_code, rec_amount,premium_rcv_detail_code,remaining_amt, payrec, mode_code,coinsurance_code,class_cd,it_remarks) values" -> insert into ins_premium_det (premium_rcv_code,assorted_code, rec_amount,premium_rcv_detail_code,remaining_amt, payrec, mode_code,coinsurance_code,class_cd,it_remarks) values | G13: ="('"&E13&"','"&B13&"','"&D13&"',(select max(to_number(i.premium_rcv_detail_code))+1 from ins_premium_det i),'"&D13&"','"&D13&"','02', '11000003','00','Request by Mr. Omair Ali 30-Aug-2024');" -> ('29Oct240071','040000183141','14960',(select max(to_number(i.premium_rcv_detail_code))+1 from ins_premium_det i),'14960','14960','02', '11000003','00','Request by Mr. Omair Ali 30-Aug-2024'); | H13: =F13&G13 -> insert into ins_premium_det (premium_rcv_code,assorted_code, rec_amount,premium_rcv_detail_code,remaining_amt, payrec, mode_code,coinsurance_code,class_cd,it_remarks) values('29Oct240071','040000183141','14960',(select max(to_number(i.premium_rcv_detail_code))+1 from ins_premium_det i),'14960','14960','02', '11000003','00','Request by Mr. Omair Ali 30-Aug-2024');
... A959: KHI/HO/D/MO/MC COMP/P/98710/09/2024 | B959: =VLOOKUP(A959,policy!B:C,2,0) -> 040000185570 | C959: 23062 | D959: =ROUND(C959,0) -> 23062 | E959: 29Oct240071 | F959: ="insert into ins_premium_det (premium_rcv_code,assorted_code, rec_amount,premium_rcv_detail_code,remaining_amt, payrec, mode_code,coinsurance_code,class_cd,it_remarks) values" -> insert into ins_premium_det (premium_rcv_code,assorted_code, rec_amount,premium_rcv_detail_code,remaining_amt, payrec, mode_code,coinsurance_code,class_cd,it_remarks) values | G959: ="('"&E959&"','"&B959&"','"&D959&"',(select max(to_number(i.premium_rcv_detail_code))+1 from ins_premium_det i),'"&D959&"','"&D959&"','02', '11000003','00','Request by Mr. Omair Ali 30-Aug-2024');" -> ('29Oct240071','040000185570','23062',(select max(to_number(i.premium_rcv_detail_code))+1 from ins_premium_det i),'23062','23062','02', '11000003','00','Request by Mr. Omair Ali 30-Aug-2024'); | H959: =F959&G959 -> insert into ins_premium_det (premium_rcv_code,assorted_code, rec_amount,premium_rcv_detail_code,remaining_amt, payrec, mode_code,coinsurance_code,class_cd,it_remarks) values('29Oct240071','040000185570','23062',(select max(to_number(i.premium_rcv_detail_code))+1 from ins_premium_det i),'23062','23062','02', '11000003','00','Request by Mr. Omair Ali 30-Aug-2024');
D961: =SUM(D2:D959) -> 12797755

Sheet Sheet2
A1: KHI/HO/D/MO/MC COMP/P/96539/09/2024 | B1: -09-2024 | D1: 96539 | E1: ="ia.assorted_string like '%"&D1&B1&"%' or" -> ia.assorted_string like '%96539-09-2024%' or
A2: KHI/HO/D/MO/MC COMP/P/96540/09/2024 | B2: -09-2024 | D2: 96540 | E2: ="ia.assorted_string like '%"&D2&B2&"%' or" -> ia.assorted_string like '%96540-09-2024%' or
A3: KHI/HO/D/MO/MC COMP/P/96541/09/2024 | B3: -09-2024 | D3: 96541 | E3: ="ia.assorted_string like '%"&D3&B3&"%' or" -> ia.assorted_string like '%96541-09-2024%' or
A4: KHI/HO/D/MO/MC COMP/P/96550/09/2024 | B4: -09-2024 | D4: 96550 | E4: ="ia.assorted_string like '%"&D4&B4&"%' or" -> ia.assorted_string like '%96550-09-2024%' or
A5: KHI/HO/D/MO/MC COMP/P/96551/09/2024 | B5: -09-2024 | D5: 96551 | E5: ="ia.assorted_string like '%"&D5&B5&"%' or" -> ia.assorted_string like '%96551-09-2024%' or
A6: KHI/HO/D/MO/MC COMP/P/96553/09/2024 | B6: -09-2024 | D6: 96553 | E6: ="ia.assorted_string like '%"&D6&B6&"%' or" -> ia.assorted_string like '%96553-09-2024%' or
A7: KHI/HO/D/MO/MC COMP/P/96560/09/2024 | B7: -09-2024 | D7: 96560 | E7: ="ia.assorted_string like '%"&D7&B7&"%' or" -> ia.assorted_string like '%96560-09-2024%' or
A8: KHI/HO/D/MO/MC COMP/P/96581/09/2024 | B8: -09-2024 | D8: 96581 | E8: ="ia.assorted_string like '%"&D8&B8&"%' or" -> ia.assorted_string like '%96581-09-2024%' or
A9: KHI/HO/D/MO/MC COMP/P/96585/09/2024 | B9: -09-2024 | D9: 96585 | E9: ="ia.assorted_string like '%"&D9&B9&"%' or" -> ia.assorted_string like '%96585-09-2024%' or
A10: KHI/HO/D/MO/MC COMP/P/96587/09/2024 | B10: -09-2024 | D10: 96587 | E10: ="ia.assorted_string like '%"&D10&B10&"%' or" -> ia.assorted_string like '%96587-09-2024%' or
A11: KHI/HO/D/MO/MC COMP/P/96589/09/2024 | B11: -09-2024 | D11: 96589 | E11: ="ia.assorted_string like '%"&D11&B11&"%' or" -> ia.assorted_string like '%96589-09-2024%' or
A12: KHI/HO/D/MO/MC COMP/P/96590/09/2024 | B12: -09-2024 | D12: 96590 | E12: ="ia.assorted_string like '%"&D12&B12&"%' or" -> ia.assorted_string like '%96590-09-2024%' or
... A958: KHI/HO/D/MO/MC COMP/P/98710/09/2024 | B958: -09-2024 | D958: 98710 | E958: ="ia.assorted_string like '%"&D958&B958&"%' or" -> ia.assorted_string like '%98710-09-2024%' or

Sheet policy
B1: FUNC_ASSORTED_STRING(IA.ASSORTED_CODE) | C1: ASSORTED_CODE
A2: 1 | B2: KHI/HO/D/MO/MC COMP/P/97773/09/2024 | C2: 040000184528
A3: 2 | B3: KHI/HO/D/MO/MC COMP/P/98618/09/2024 | C3: 040000185471
A4: 3 | B4: KHI/HO/D/MO/MC COMP/P/98378/09/2024 | C4: 040000185201
A5: 4 | B5: KHI/HO/D/MO/MC COMP/P/98379/09/2024 | C5: 040000185202
A6: 5 | B6: KHI/HO/D/MO/MC COMP/P/96585/09/2024 | C6: 040000183136
A7: 6 | B7: KHI/HO/D/MO/MC COMP/P/96587/09/2024 | C7: 040000183138
A8: 7 | B8: KHI/HO/D/MO/MC COMP/P/97450/09/2024 | C8: 040000184165
A9: 8 | B9: KHI/HO/D/MO/MC COMP/P/97804/09/2024 | C9: 040000184561
A10: 9 | B10: KHI/HO/D/MO/MC COMP/P/96642/09/2024 | C10: 040000183198
A11: 10 | B11: KHI/HO/D/MO/MC COMP/P/97771/09/2024 | C11: 040000184526
A12: 11 | B12: KHI/HO/D/MO/MC COMP/P/97772/09/2024 | C12: 040000184527
A13: 12 | B13: KHI/HO/D/MO/MC COMP/P/96611/09/2024 | C13: 040000183164
... A960: 959 | B960: KHI/HO/D/MO/MC COMP/P/98141/09/2024 | C960: 040000184929
