Workbook

Sheet T-PAK
A1: Sr. | B1: Status | C1: Contract No. | D1: Insurance Agency | E1: Customer Name | F1: City | G1: CNIC No. | H1: Home Phone# | I1: Mobile Number | J1: Business Phone# | K1: Mail Address | L1: Finance Amount | M1: Car Price | N1: Ins. Policy | O1: Ins. Expiry Date | P1: Engine No. | Q1: Chassis No. | R1: Car Category | S1: Reg. No. | T1: Car Name | U1: Model | V1: Contract Booking Date | W1: Contract Value Date | X1: Contract Maturity Date | Y1: Purchase Order No. | Z1: Tenor#2 | AA1: Tracker Company | AB1: Tracker Reference Number | AC1: Tracker Installation Date | AD1: Rate | AE1: Sum Insured | AF1: Premium | AG1: OLD Contract Ref | AH1: Remarks-I | AI1: Remarks-II | AJ1: Policy # | AK1: Tms prem
A2: 1 | B2: ACTIVE | C2: 9976AD1211970001 | D2: T-PAK | E2: SOHAIL NASIR | F2: Faisalabad | G2: 33100-7633385-9 | H2: 03222227879 | I2: 03222227879, 03222227879 | J2: 03222227879 | K2: H NO 155 B-BLOCK GALIB CITY FAISALABAD PK | L2: 1001250 | M2: 1335000 | N2: 2021/10/CLFFTPCDP01207 | O2: 45597 | P2: 191006 | Q2: 1091022 | R2: NEW | T2: SUZUKI ALTO VXR EURO-II | U2: 2021 | V2: 16-JUL-2021 | W2: 11-NOV-2021 | X2: 11-Nov-2026 | Y2: OLAFSD300070753 | Z2: 5 | AA2: CTRK | AB2: DIB0032363 | AC2: 02-NOV-2021 | AD2: 2% | AE2: 1068000 | AF2: 21360 | AJ2: =_xlfn.XLOOKUP(Table9[[#This Row],[Engine No.]],'[1]Dubai Islamic Consumer'!$Q$3:$Q$1176,'[1]Dubai Islamic Consumer'!$B$3:$B$1176,,,) -> KHI/HO/D/MO/PC COMP/C/102086/2/11/2024
A3: 2 | B3: ACTIVE | C3: 9976AD1212090016 | D3: T-PAK | E3: IKHLAQ HUSSAIN | F3: Faisalabad | G3: 33100-0642718-5 | I3: 03006660309 | K3: SHOP NO 1891 AL MADINA COMMERCIAL MARKET NEAR MAIN CENTER GANESH MILLS FACTORY AREA FAISALABAD | L3: 1098000 | M3: 1830000 | N3: DIB/T/34267/LHR/1121 | O3: 45597 | P3: 187626 | Q3: 10087599 | R3: NEW | T3: CULTUS VXL | U3: 2021 | V3: 28-JUL-2021 | W3: 11-NOV-2021 | X3: 11-Nov-2026 | Y3: OLAFSD300071229 | Z3: 5 | AA3: CTRK | AB3: DIB0032361 | AC3: 02-NOV-2021 | AD3: 2% | AE3: 1464000 | AF3: 29280 | AJ3: =_xlfn.XLOOKUP(Table9[[#This Row],[Engine No.]],'[1]Dubai Islamic Consumer'!$Q$3:$Q$1176,'[1]Dubai Islamic Consumer'!$B$3:$B$1176,,,) -> KHI/HO/D/MO/PC COMP/C/102086/3/11/2024
A4: 3 | B4: ACTIVE | C4: 9976AD1212560009 | D4: T-PAK | E4: SELMAN RASHID IQBAL | F4: Sialkot | G4: 34603-2315200-3 | H4: 92524295927 | I4: 03018718899 | J4: 92523241923 | K4: HOUSE NO 127/24 HAIDAR ROAD SIALKOT CANTT TEHSIL AND DISTT SIALKOT | L4: 2027250 | M4: 2703000 | N4: UWT/D/T002/0000001124/1121/109-0 | O4: 45597 | P4: 2A39606 | Q4: 7024780 | R4: NEW | T4: COROLLA YARIS 1.3 AT | U4: 2021 | V4: 13-SEP-2021 | W4: 11-NOV-2021 | X4: 11-Nov-2026 | Y4: OLASKT300073113 | Z4: 5 | AA4: CTRK | AB4: DIB0032370 | AC4: 02-NOV-2021 | AD4: 1.75% | AE4: 2162400 | AF4: 37842 | AJ4: =_xlfn.XLOOKUP(Table9[[#This Row],[Engine No.]],'[1]Dubai Islamic Consumer'!$Q$3:$Q$1176,'[1]Dubai Islamic Consumer'!$B$3:$B$1176,,,) -> KHI/HO/D/MO/PC COMP/C/102086/5/11/2024
A5: 4 | B5: ACTIVE | C5: 997AAD1203050109 | D5: T-PAK | E5: ASAD MEHMOOD | F5: Rawalpindi | G5: 37405-0550285-5 | H5: 03345931343 | J5: 03005305187 | K5: KHASRA # 209 RAJA ASAD STREET ST # 37/8 MOHALLAH MILLATABAD BARAF KHAN RAWALPINDI PK | L5: 2986125 | M5: 3981500 | N5: 2524/02150/00177/11/2020 | O5: 45597 | P5: 914453 | Q5: 066325 | R5: NEW | T5: CIVIC VTI ORIEL P/T | U5: 2020 | V5: 31-OCT-2020 | W5: 11-NOV-2020 | X5: 11-Nov-2025 | Y5: POARWP300059795 | Z5: 5 | AA5: CTRK | AB5: DIB0028990 | AC5: 03-NOV-2020 | AD5: 2% | AE5: 2986125 | AF5: 59723 | AJ5: =_xlfn.XLOOKUP(Table9[[#This Row],[Engine No.]],'[1]Dubai Islamic Consumer'!$Q$3:$Q$1176,'[1]Dubai Islamic Consumer'!$B$3:$B$1176,,,) -> KHI/HO/D/MO/PC COMP/C/102086/6/11/2024
A6: 5 | B6: ACTIVE | C6: 9976AD1212120085 | D6: T-PAK | E6: ASIF MAHMOOD | F6: Lahore | G6: 35201-1571249-5 | H6: 03214765797 | I6: 03214765797 | J6: 04236520393 | K6: 5-A USMAN BLOCK CANAL BANK SCHEME H ARBANSPURA LAHORE | L6: 3952500 | M6: 5270000 | N6: DIB/T/34275/LHR/1121 | O6: 45597 | P6: 318580 | Q6: 513459 | R6: NEW | T6: KIA SPORTAGE AWD | U6: 2021 | V6: 31-JUL-2021 | W6: 11-NOV-2021 | X6: 11-Nov-2026 | Y6: OLALHR300071474 | Z6: 5 | AA6: ITECL | AB6: 5568/11/2021 | AC6: 02-NOV-2021 | AD6: 1.75% | AE6: 4216000 | AF6: 73780 | AJ6: =_xlfn.XLOOKUP(Table9[[#This Row],[Engine No.]],'[1]Dubai Islamic Consumer'!$Q$3:$Q$1176,'[1]Dubai Islamic Consumer'!$B$3:$B$1176,,,) -> KHI/HO/D/MO/PC COMP/C/102086/7/11/2024
A7: 6 | B7: ACTIVE | C7: 9976AD1211650002 | D7: T-PAK | E7: USAMA SHAFIQ | F7: Faisalabad | G7: 33102-6906523-3 | H7: 8777818 | I7: 03119999595, 03119999595 | J7: 03119999595 | K7: 46-A, TECH TOWN, NEAR SATYANA ROAD FAISALABAD PK | L7: 6516300 | M7: 9309000 | N7: 01-2110-PO-MTR-PCCM-D-001497 | O7: 45597 | P7: 1GD-5077748 | Q7: R-1097037 | R7: NEW | T7: FORTUNER A/T | U7: 2021 | V7: 14-JUN-2021 | W7: 03-DEC-2021 | X7: 03-Dec-2026 | Y7: OLAFSD300069468 | Z7: 5 | AA7: CTRK | AB7: DIB0032371 | AC7: 02-NOV-2021 | AD7: 1.75% | AE7: 7447200 | AF7: 130326 | AJ7: =_xlfn.XLOOKUP(Table9[[#This Row],[Engine No.]],'[1]Dubai Islamic Consumer'!$Q$3:$Q$1176,'[1]Dubai Islamic Consumer'!$B$3:$B$1176,,,) -> KHI/HO/D/MO/PC COMP/C/102086/8/11/2024
A8: 7 | B8: ACTIVE | C8: 9976AP1223080006 | D8: T-PAK | E8: MUHAMMAD SAMEER KAZI | F8: Karachi | G8: 42201-1431273-3 | H8: 03043615125 | I8: 03043615125 | J8: 0 | K8: H # R- 18 SUPARCO CO OPERATIVE HOUS ING SCOIETY SCHEEM 33 MAYMAR MORE KARACHI PK | L8: 922500 | M8: 2050000 | N8: 64794/00001/11/2022 | O8: 45597 | P8: 246433 | Q8: 1146470 | R8: USD | S8: BXP-407 | T8: SUZUKI ALTO VXR EURO-II | U8: 2022 | V8: 04-NOV-2022 | W8: 11-NOV-2022 | X8: 11-Nov-2025 | Y8: OLUKHI30009013 | Z8: 3 | AA8: ITFT | AB8: 9285/11/2022/ITFM | AC8: 02-NOV-2022 | AD8: 1.75% | AE8: 1742500 | AF8: 30494 | AJ8: =_xlfn.XLOOKUP(Table9[[#This Row],[Engine No.]],'[1]Dubai Islamic Consumer'!$Q$3:$Q$1176,'[1]Dubai Islamic Consumer'!$B$3:$B$1176,,,) -> KHI/HO/D/MO/PC COMP/C/102086/10/11/2024
A9: 8 | B9: ACTIVE | C9: 997AAD1201950001 | D9: T-PAK | E9: ZAHID SAMUEL | F9: JHELUM | G9: 37301-9691544-9 | H9: 03325922916 | J9: 0544275675 | K9: ROHTAS ROAD , MUHALLAH CHRISTAN COL ONY NEAR QASIR CHOWK JHELUM PK | L9: 1959750 | M9: 2613000 | N9: DIB/T/BT/29418/ISB/1120 | O9: 45597 | P9: 2A10639 | Q9: 7006139 | R9: NEW | T9: YARIS ATIV MT 1.3 | U9: 2020 | V9: 13-JUL-2020 | W9: 21-NOV-2020 | X9: 21-Nov-2027 | Y9: POAJHM300055111 | Z9: 7 | AA9: CTRK | AB9: DIB0028988 | AC9: 03-NOV-2020 | AD9: 2.5% | AE9: 1959750 | AF9: 48994 | AJ9: =_xlfn.XLOOKUP(Table9[[#This Row],[Engine No.]],'[1]Dubai Islamic Consumer'!$Q$3:$Q$1176,'[1]Dubai Islamic Consumer'!$B$3:$B$1176,,,) -> KHI/HO/D/MO/PC COMP/C/102086/11/11/2024
A10: 9 | B10: ACTIVE | C10: 9976AD1212350014 | D10: T-PAK | E10: MUHAMMAD ARIF | F10: Rawalpindi | G10: 37405-2017815-9 | H10: 03360573213 | J10: 0519268147 | K10: H # G-1 BLOCK C GHAZI COLONY TIPU R OAD NEAR GO CNG PUMP RAWALPINDI PK | L10: 744750 | M10: 1655000 | N10: DIB/T/34281/ISB/1121 | O10: 45598 | P10: 188029 | Q10: 10088024 | R10: NEW | T10: SUZUKI CULTUS VXR EURO II | U10: 2021 | V10: 23-AUG-2021 | W10: 11-NOV-2021 | X10: 11-Nov-2026 | Y10: OLARWP300072176 | Z10: 5 | AA10: CTRK | AB10: TDIDIB0029793 | AC10: 05-NOV-2021 | AD10: 2% | AE10: 1324000 | AF10: 26480 | AJ10: =_xlfn.XLOOKUP(Table9[[#This Row],[Engine No.]],'[1]Dubai Islamic Consumer'!$Q$3:$Q$1176,'[1]Dubai Islamic Consumer'!$B$3:$B$1176,,,) -> KHI/HO/D/MO/PC COMP/C/102086/12/11/2024
A11: 10 | B11: ACTIVE | C11: 9976AD2212290009 | D11: T-PAK | E11: TASLEEM AKHTAR | F11: Lahore | G11: 38201-2575486-8 | H11: 03137357790 | I11: 03137357790 | J11: 03137357790 | K11: JAIL ROAD PUNJAB CARDIALOGY 3RD FLO OR OPPOSITE MECHDOLANDS LAHORE | L11: 1001250 | M11: 1335000 | N11: 2524/02742/0003/11/2021 | O11: 45598 | P11: 191149 | Q11: 1091170 | R11: NEW | T11: SUZUKI ALTO VXR EURO II | U11: 2021 | V11: 17-AUG-2021 | W11: 21-NOV-2021 | X11: 21-Nov-2025 | Y11: OLALHR300071995 | Z11: 4 | AA11: CTRK | AB11: DIB0032382 | AC11: 04-NOV-2021 | AD11: 2% | AE11: 1068000 | AF11: 21360 | AJ11: =_xlfn.XLOOKUP(Table9[[#This Row],[Engine No.]],'[1]Dubai Islamic Consumer'!$Q$3:$Q$1176,'[1]Dubai Islamic Consumer'!$B$3:$B$1176,,,) -> KHI/HO/D/MO/PC COMP/C/102086/13/11/2024
A12: 11 | B12: ACTIVE | C12: 9976AD1211810025 | D12: T-PAK | E12: AMEER ALI LUHUR | F12: LARKANA | G12: 43203-3056842-9 | I12: 03342243242 | K12: LUHUR DECORATION SERVICE NAUDERO ROAD BYPASS NEAR SINDH GREEN HOTEL LARKANA | L12: 999750 | M12: 1333000 | N12: DIB/T/34280/HYD/1121 | O12: 45598 | P12: 6R188933 | Q12: NF1AET306H1088889 | R12: NEW | T12: ALTO VXR EURO-II | U12: 2021 | V12: 30-JUN-2021 | W12: 11-NOV-2021 | X12: 11-Nov-2026 | Y12: OLALRK300070128 | Z12: 5 | AA12: CTRK | AB12: TDIDIB0029753 | AC12: 29-OCT-2021 | AD12: 2% | AE12: 1066400 | AF12: 21328 | AJ12: =_xlfn.XLOOKUP(Table9[[#This Row],[Engine No.]],'[1]Dubai Islamic Consumer'!$Q$3:$Q$1176,'[1]Dubai Islamic Consumer'!$B$3:$B$1176,,,) -> KHI/HO/D/MO/PC COMP/C/102086/14/11/2024
A13: 12 | B13: ACTIVE | C13: 997APD1203110006 | D13: T-PAK | E13: ASHFAQUE AHMED | F13: Lahore | G13: 35201-5806207-9 | H13: 03214228449 | I13: 03214228449 | J13: 04237191274 | K13: OFFICE NO 94 COMMERCIAL BROADWAY PA RGON CITY BARKI ROAD NEAR FUTURE NO W TECH LAHORE | L13: 1211000 | M13: 1730000 | N13: 53157/00004/11/2020 | O13: 45598 | P13: 207189 | Q13: 10107185 | R13: NEW | T13: WAGONR VXL | U13: 2020 | V13: 06-NOV-2020 | W13: 11-NOV-2020 | X13: 11-Nov-2026 | Y13: PODLHR300060261 | Z13: 6 | AA13: ITFM | AB13: 3474/11/2020/ITFM | AC13: 04-NOV-2020 | AD13: 2% | AE13: 1297500 | AF13: 25950 | AJ13: =_xlfn.XLOOKUP(Table9[[#This Row],[Engine No.]],'[1]Dubai Islamic Consumer'!$Q$3:$Q$1176,'[1]Dubai Islamic Consumer'!$B$3:$B$1176,,,) -> KHI/HO/D/MO/PC COMP/C/102086/15/11/2024
A14: 13 | B14: ACTIVE | C14: 9976AD2211800001 | D14: T-PAK | E14: MUHAMMAD IQBAL | F14: Gujrat | G14: 34201-0363899-5 | H14: 03036871894 | I14: 03036871894 | J14: 03036871894 | K14: OPPOSITE PUBLIC SCHOOL NO 2 MOHALLA H AZIZABAD RAILWAY ROAD GUJRAT PK | L14: 1066000 | M14: 1640000 | N14: 56607/00005/11/2021 | O14: 45598 | P14: 505771 | Q14: 1010057 | R14: NEW | T14: KARVAAN PLUS | U14: 2021 | V14: 29-JUN-2021 | W14: 03-DEC-2021 | X14: 03-Dec-2026 | Y14: OLAGJR300069996 | Z14: 5 | AA14: CTRK | AB14: DIB0032386 | AC14: 04-NOV-2021 | AD14: 2% | AE14: 1312000 | AF14: 26240 | AJ14: =_xlfn.XLOOKUP(Table9[[#This Row],[Engine No.]],'[1]Dubai Islamic Consumer'!$Q$3:$Q$1176,'[1]Dubai Islamic Consumer'!$B$3:$B$1176,,,) -> KHI/HO/D/MO/PC COMP/C/102086/16/11/2024
A15: 14 | B15: ACTIVE | C15: 997AAD2203020015 | D15: T-PAK | E15: AYEEN MUHAMMAD KHAN | F15: Islamabad | G15: 71501-0639654-5 | H15: 03327424312 | J15: 0518840517 | K15: H # 708 ST # 47 SECTOR # G-9/1 ISLAMABAD PK | L15: 1232500 | M15: 2465000 | N15: 2524/02150/00174/11/2020 | O15: 45598 | P15: 7541706 | Q15: LR-264824 | R15: NEW | T15: HONDA CITY IVTEC | U15: 2020 | V15: 28-OCT-2020 | W15: 11-NOV-2020 | X15: 11-Nov-2027 | Y15: POAISD300059172 | Z15: 7 | AA15: ITMM | AB15: 3463/11/2020/ITMM | AC15: 02-NOV-2020 | AD15: 2% | AE15: 1848750 | AF15: 36975 | AJ15: =_xlfn.XLOOKUP(Table9[[#This Row],[Engine No.]],'[1]Dubai Islamic Consumer'!$Q$3:$Q$1176,'[1]Dubai Islamic Consumer'!$B$3:$B$1176,,,) -> KHI/HO/D/MO/PC COMP/C/102086/17/11/2024
A16: 15 | B16: ACTIVE | C16: 997AAD1202960014 | D16: T-PAK | E16: MUHAMMAD YOUSAF ASLAM | F16: Faisalabad | G16: 33100-8463560-7 | H16: 03217821165 | I16: 03217821165, 03217821165 | J16: 0418728819 | K16: H NO 3-X BLOCK X UPPER FLOOR ST NO 12 MADINA TOWN FAISALABAD PK | L16: 2787050 | M16: 3981500 | N16: 2524/02150/00152/11/2020 | O16: 45598 | P16: 6914492 | Q16: LR066318 | R16: NEW | T16: CIVIC VTI ORIEL P/T | U16: 2020 | V16: 22-OCT-2020 | W16: 11-NOV-2020 | X16: 11-Nov-2025 | Y16: POAFSD300059003 | Z16: 5 | AA16: ITFM | AB16: 3476/11/2020/ITFM | AC16: 04-NOV-2020 | AD16: 2% | AE16: 2986125 | AF16: 59723 | AJ16: =_xlfn.XLOOKUP(Table9[[#This Row],[Engine No.]],'[1]Dubai Islamic Consumer'!$Q$3:$Q$1176,'[1]Dubai Islamic Consumer'!$B$3:$B$1176,,,) -> KHI/HO/D/MO/PC COMP/C/102086/20/11/2024
A17: 16 | B17: ACTIVE | C17: 9976AD1212380020 | D17: T-PAK | E17: RAJA ADIL SARFRAZ | F17: Faisalabad | G17: 41306-0723517-3 | H17: 03452932949 | I17: 03452932949, 03452932949 | J17: 0419200161 | K17: H NO P-391-C BLOCK-C MILLAT TOWN MI LLAT ROAD FAISALABAD PK | L17: 2549200 | M17: 3186500 | N17: 2021-10-205-V01501OP0002654 | O17: 45598 | P17: L15Z81001399 | Q17: NFBGN966XMR005542 | R17: NEW | T17: HONDA CITY ASPIRE | U17: 2021 | V17: 26-AUG-2021 | W17: 11-NOV-2021 | X17: 11-Nov-2026 | Y17: OLAFSD300072297 | Z17: 5 | AA17: CTRK | AB17: DIB0032299 | AC17: 03-NOV-2021 | AD17: 2% | AE17: 2549200 | AF17: 50984 | AJ17: =_xlfn.XLOOKUP(Table9[[#This Row],[Engine No.]],'[1]Dubai Islamic Consumer'!$Q$3:$Q$1176,'[1]Dubai Islamic Consumer'!$B$3:$B$1176,,,) -> KHI/HO/D/MO/PC COMP/C/102086/21/11/2024
A18: 17 | B18: ACTIVE | C18: 997AAD1202050020 | D18: T-PAK | E18: BILAL ZIA | F18: Gujranwala | G18: 34101-4056821-7 | H18: 03152227292 | I18: 03152227292 | J18: 03152227292 | K18: HOUSE NO 351 STREET NO 5 SECTOR 1 CANTT GUJRANWALA | L18: 3239400 | M18: 5399000 | N18: 53157/00003/11/2020 | O18: 45598 | P18: 327392 | Q18: KP506234 | R18: NEW | T18: KIA SPORTAGE AWD | U18: 2020 | V18: 23-JUL-2020 | W18: 11-NOV-2020 | X18: 11-Nov-2025 | Y18: POAGWL300055621 | Z18: 5 | AD18: 1.5% | AE18: 4049250 | AF18: 60739 | AJ18: =_xlfn.XLOOKUP(Table9[[#This Row],[Engine No.]],'[1]Dubai Islamic Consumer'!$Q$3:$Q$1176,'[1]Dubai Islamic Consumer'!$B$3:$B$1176,,,) -> KHI/HO/D/MO/PC COMP/C/102086/22/11/2024
A19: 18 | B19: ACTIVE | C19: 997AAD1201990002 | D19: T-PAK | E19: WASEEM EJAZ | F19: Lahore | G19: 35202-4832610-5 | H19: 0321-8807749 | I19: 0321-8807749 | J19: 35959594 | K19: H NO 11 MALIK STREET EJAZ CHOWK 18 KM FEROZPUR ROAD REHMAT COLONY NISHTER COLONY LAHORE | L19: 3798900 | M19: 5427000 | N19: DIB/T/29424/LHR/1120 | O19: 45598 | P19: 324054 | Q19: 506019 | R19: NEW | T19: KIA SPORATAGE AWD | U19: 2020 | V19: 17-JUL-2020 | W19: 11-NOV-2020 | X19: 11-Nov-2025 | Y19: POALHR300055319 | Z19: 5 | AD19: 1.5% | AE19: 4070250 | AF19: 61054 | AJ19: =_xlfn.XLOOKUP(Table9[[#This Row],[Engine No.]],'[1]Dubai Islamic Consumer'!$Q$3:$Q$1176,'[1]Dubai Islamic Consumer'!$B$3:$B$1176,,,) -> KHI/HO/D/MO/PC COMP/C/102086/23/11/2024
A20: 19 | B20: ACTIVE | C20: 9976AP1223080007 | D20: T-PAK | E20: MALIK MUHAMMAD BASHARAT | F20: Islamabad | G20: 42201-0256988-9 | H20: 03008232280 | J20: 0515709137 | K20: H # 7 ST # 8 FEDERATION HOUSING SOC IETY LOHI BAIR SECTOR A ISLAMABAD PK | L20: 1794800 | M20: 2564000 | N20: 64794/00003/11/2022 | O20: 45598 | P20: 10B239700 | Q20: 10139728 | R20: NEW | T20: SUZUKI WAGONR VXL | U20: 2022 | V20: 04-NOV-2022 | W20: 11-NOV-2022 | X20: 11-Nov-2027 | Y20: OLDISD300090725 | Z20: 5 | AA20: FLCN | AB20: 108809/11/2022 | AC20: 03-NOV-2022 | AD20: 1.75% | AE20: 2179400 | AF20: 38140 | AJ20: =_xlfn.XLOOKUP(Table9[[#This Row],[Engine No.]],'[1]Dubai Islamic Consumer'!$Q$3:$Q$1176,'[1]Dubai Islamic Consumer'!$B$3:$B$1176,,,) -> KHI/HO/D/MO/PC COMP/C/102086/24/11/2024
A21: 20 | B21: ACTIVE | C21: 9976AP2223110007 | D21: T-PAK | E21: MUHAMMAD KASHIF | F21: Karachi | G21: 42301-7784361-9 | H21: 03132213808 | I21: 03132213808 | J21: 0 | K21: C- 27 4 RTH FLOOR ZEESHAN BLESSING GULSHAN-E- IQBAL BOCK 16 OPP NOOR M KARACHI PK | L21: 1330000 | M21: 1900000 | N21: 64794/0004/11/2022 | O21: 45598 | P21: 122604 | Q21: 10022606 | R21: USD | S21: BKK-497 | T21: SUZUKI WAGONR VXL | U21: 2017 | V21: 07-NOV-2022 | W21: 11-NOV-2022 | X21: 11-Nov-2026 | Y21: OLUKHI300090714 | Z21: 4 | AA21: ITFT | AB21: 9298/11/2022/ITFM | AC21: 05-NOV-2022 | AD21: 1.75% | AE21: 1615000 | AF21: 28263 | AJ21: =_xlfn.XLOOKUP(Table9[[#This Row],[Engine No.]],'[1]Dubai Islamic Consumer'!$Q$3:$Q$1176,'[1]Dubai Islamic Consumer'!$B$3:$B$1176,,,) -> KHI/HO/D/MO/PC COMP/C/102086/26/11/2024
A22: 21 | B22: ACTIVE | C22: 9976AD2221710002 | D22: T-PAK | E22: USMAN JAVED BUTT | F22: Lahore | G22: 35202-3706453-7 | H22: 03004580882 | I22: 03004580882 | J22: 03004580882 | K22: H NO 829-A MUHALLAH CANAL VIEW BLOC K E LAHORE LAHORE PK | L22: 2733500 | M22: 3905000 | N22: 64794/00002/11/2022 | O22: 45598 | P22: 81012003 | Q22: 027765 | R22: NEW | T22: HONDA CITY ASPIRE A/T | U22: 2022 | V22: 20-JUN-2022 | W22: 11-NOV-2022 | X22: 11-Nov-2025 | Y22: OLALHR300088166 | Z22: 3 | AA22: ITFT | AB22: 9288/11/2022/ITFM | AC22: 03-NOV-2022 | AD22: 2% | AE22: 3319250 | AF22: 66385 | AJ22: =_xlfn.XLOOKUP(Table9[[#This Row],[Engine No.]],'[1]Dubai Islamic Consumer'!$Q$3:$Q$1176,'[1]Dubai Islamic Consumer'!$B$3:$B$1176,,,) -> KHI/HO/D/MO/PC COMP/C/102086/28/11/2024
A23: 22 | B23: ACTIVE | C23: 9976AD1213620032 | D23: T-PAK | E23: SALMAN IKRAM | F23: Sialkot | G23: 34603-5068241-5 | H23: 03008612564 | I23: 03008612564 | J23: 03008612564 | K23: MOH MODEL TOWN UGOKI PO KHAS GUJRANWALA PK | L23: 1524600 | M23: 2178000 | N23: 64794/00006/11/2022 | O23: 45598 | P23: 085661 | Q23: 711231 | R23: NEW | T23: KIA PICANTO 1.0 L A/T | U23: 2022 | V23: 28-DEC-2021 | W23: 11-NOV-2022 | X23: 11-Nov-2025 | Y23: OLASKT300082278 | Z23: 3 | AA23: ITECL | AB23: 9283/11/2022 | AC23: 01-NOV-2022 | AD23: 2% | AE23: 1851300 | AF23: 37026 | AJ23: =_xlfn.XLOOKUP(Table9[[#This Row],[Engine No.]],'[1]Dubai Islamic Consumer'!$Q$3:$Q$1176,'[1]Dubai Islamic Consumer'!$B$3:$B$1176,,,) -> KHI/HO/D/MO/PC COMP/C/102086/31/11/2024
A24: 23 | B24: ACTIVE | C24: 9976AP2223080004 | D24: T-PAK | E24: MUHAMMAD MOHSIN KHAIRI | F24: Karachi | G24: 42201-4373898-1 | H24: 03343236770 | I24: 03343236770 | J24: 03343236770 | K24: FLAT NO. 601 6TH FLOOR BURJ UL IMRA N APARTMENT SECTOR JINNAH AVENUE NE KARACHI PK | L24: 1267500 | M24: 1950000 | N24: 64794/00005/11/2022 | O24: 45598 | P24: 6R241226 | Q24: 1141200 | R24: USD | S24: BXF-240 | T24: SUZUKI ALTO VXR EURO-II | U24: 2022 | V24: 04-NOV-2022 | W24: 11-NOV-2022 | X24: 11-Nov-2027 | Y24: OLUKHI300090726 | Z24: 5 | AA24: ITFT | AB24: 9289/11/2022/ITFM | AC24: 03-NOV-2022 | AD24: 1.75% | AE24: 1657500 | AF24: 29006 | AJ24: =_xlfn.XLOOKUP(Table9[[#This Row],[Engine No.]],'[1]Dubai Islamic Consumer'!$Q$3:$Q$1176,'[1]Dubai Islamic Consumer'!$B$3:$B$1176,,,) -> KHI/HO/D/MO/PC COMP/C/102086/36/11/2024
A25: 24 | B25: ACTIVE | C25: 9976AD2232710003 | D25: T-PAK | E25: MUHAMMAD BILAL | F25: Lahore | G25: 34603-7401604-5 | H25: 03037015616 | I25: 03037015616 | J25: 04236400007 | K25: HOUSE NO 3-S-38 AZIM STREET CLIFTON COLONY NEAR GHATTI CHOWK WAHDAT CO LAHORE PK | L25: 1514960 | M25: 2612000 | N25: 77638/0001/11/2023 | O25: 02-NOV-2024 | P25: 6R286844 | Q25: 1187030 | R25: NEW | T25: SUZUKI ALTO VXR EURO II | U25: 2023 | V25: 45197 | W25: 27-NOV-2023 | X25: 27-Nov-2026 | Y25: OLALHR300097279 | Z25: 3 | AA25: CTRK | AB25: DIB0035410 | AC25: 06-NOV-2023 | AD25: 2% | AE25: 2350800 | AF25: 47016 | AJ25: =_xlfn.XLOOKUP(Table9[[#This Row],[Engine No.]],'[1]Dubai Islamic Consumer'!$Q$3:$Q$1176,'[1]Dubai Islamic Consumer'!$B$3:$B$1176,,,) -> KHI/HO/D/MO/PC COMP/C/102086/37/11/2024
A26: 25 | B26: ACTIVE | C26: 9976AD2212120031 | D26: T-PAK | E26: MUMTAZ AHMAD | F26: Lahore | G26: 35202-2733554-3 | H26: 03334634898 | I26: 03334634898 | J26: 099214240 | K26: DIO SAMAAJ ROAD NEAR MALL ROAD LAHORE | L26: 801000 | M26: 1335000 | N26: 2524/02742/00005/11/2021 | O26: 45599 | P26: 6R190275 | Q26: NF1AET306H1090242 | R26: NEW | T26: ALTO VXR EURO-II | U26: 2021 | V26: 31-JUL-2021 | W26: 21-NOV-2021 | X26: 21-Nov-2026 | Y26: OLALHR300071469 | Z26: 5 | AA26: ITECL | AB26: 5577/11/2021 | AC26: 04-NOV-2021 | AD26: 2% | AE26: 1068000 | AF26: 21360 | AJ26: =_xlfn.XLOOKUP(Table9[[#This Row],[Engine No.]],'[1]Dubai Islamic Consumer'!$Q$3:$Q$1176,'[1]Dubai Islamic Consumer'!$B$3:$B$1176,,,) -> KHI/HO/D/MO/PC COMP/C/102086/38/11/2024
A27: 26 | B27: ACTIVE | C27: 997AAD1202740084 | D27: T-PAK | E27: MAHER TAUSEEF AHMED | F27: Multan | G27: 36302-8413092-1 | I27: 03018510587 | J27: 6350987 | K27: AL JADEED ASSOCIATES PVT LTD HOUSE NO 16 CANTT COTTAGES SHER SHAH ROAD MULTAN CANTT | L27: 1198500 | M27: 1598000 | N27: 2020/11/CLFTTPCDP00682 | O27: 45599 | P27: 142804 | Q27: 1043351 | R27: NEW | T27: SUZUKI ALTO VXL EURO II AGS | U27: 2020 | V27: 30-SEP-2020 | W27: 21-NOV-2020 | X27: 21-Nov-2025 | Y27: POAMUX300058118 | Z27: 5 | AA27: CTRK | AB27: DIB0028999 | AC27: 04-NOV-2020 | AD27: 2% | AE27: 1198500 | AF27: 23970 | AJ27: =_xlfn.XLOOKUP(Table9[[#This Row],[Engine No.]],'[1]Dubai Islamic Consumer'!$Q$3:$Q$1176,'[1]Dubai Islamic Consumer'!$B$3:$B$1176,,,) -> KHI/HO/D/MO/PC COMP/C/102086/39/11/2024
A28: 27 | B28: ACTIVE | C28: 997APD2203140004 | D28: T-PAK | E28: DANYIAL ASIF | F28: Lahore | G28: 35202-2670690-5 | H28: 03349755036 | I28: 03349755036 | J28: 04235249651 | K28: PLAZA NO 50 SECTOR D BLOCK AA COMME RCIAL MARKET BAHRIA TOWN NEAR MCDON ALD LAHORE | L28: 1218000 | M28: 2030000 | N28: 53157/00009/11/2020 | O28: 45599 | P28: 13045447 | Q28: 10045452 | R28: NEW | T28: SUZUKI SWIFT DLX 1.3 MT | U28: 2020 | V28: 09-NOV-2020 | W28: 11-NOV-2020 | X28: 11-Nov-2025 | Y28: PODLHR300060201 | Z28: 5 | AA28: ITFM | AB28: 34921/11/2020/ITFM | AC28: 05-NOV-2020 | AD28: 2% | AE28: 1522500 | AF28: 30450 | AJ28: =_xlfn.XLOOKUP(Table9[[#This Row],[Engine No.]],'[1]Dubai Islamic Consumer'!$Q$3:$Q$1176,'[1]Dubai Islamic Consumer'!$B$3:$B$1176,,,) -> KHI/HO/D/MO/PC COMP/C/102086/40/11/2024
A29: 28 | B29: ACTIVE | C29: 9976AD2212230011 | D29: T-PAK | E29: SUHAIL AHMED | F29: Islamabad | G29: 43406-0374772-7 | H29: 2210817 | I29: 03322023689 | J29: 2210817 | K29: HOSE NO 181 SR NO 68 F 10/3 ISLAMABAD | L29: 1098000 | M29: 1830000 | N29: 01-2111-PO-MTR-PCCM-D-001510 | O29: 45599 | P29: 188067 | Q29: 10088066 | R29: NEW | T29: CULTUS VXL EURO II | U29: 2021 | V29: 11-AUG-2021 | W29: 21-NOV-2021 | X29: 21-Nov-2026 | Y29: OLAISD300071823 | Z29: 5 | AA29: CTRK | AB29: DIB0032403 | AC29: 05-NOV-2021 | AD29: 2% | AE29: 1464000 | AF29: 29280 | AJ29: =_xlfn.XLOOKUP(Table9[[#This Row],[Engine No.]],'[1]Dubai Islamic Consumer'!$Q$3:$Q$1176,'[1]Dubai Islamic Consumer'!$B$3:$B$1176,,,) -> KHI/HO/D/MO/PC COMP/C/102086/42/11/2024
A30: 29 | B30: ACTIVE | C30: 997AAD2202440025 | D30: T-PAK | E30: MUHAMMAD MANSHA | F30: Faisalabad | G30: 33100-2927708-3 | H30: 03008662363 | I30: 03008662363, 03008662363 | J30: 03008662363 | K30: P-21 MUSLIM PARK SARGODHA ROAD MUSL IM TOWN YOUSAF BLOCK FSD NEAR R.S B FAISALABAD PK | L30: 1657800 | M30: 2763000 | N30: 2524/02150/00185/11/2020 | O30: 45599 | P30: 2A11204 | Q30: 7006644 | R30: NEW | T30: TOYOTA COROLLA YARIS | U30: 2020 | V30: 31-AUG-2020 | W30: 27-NOV-2020 | X30: 27-Nov-2025 | Y30: POAFSD300057032 | Z30: 5 | AA30: ITFM | AB30: 3477/11/2020/ITFM | AC30: 04-NOV-2020 | AD30: 2% | AE30: 2072250 | AF30: 41445 | AJ30: =_xlfn.XLOOKUP(Table9[[#This Row],[Engine No.]],'[1]Dubai Islamic Consumer'!$Q$3:$Q$1176,'[1]Dubai Islamic Consumer'!$B$3:$B$1176,,,) -> KHI/HO/D/MO/PC COMP/C/102086/44/11/2024
A31: 30 | B31: ACTIVE | C31: 997APD2203110007 | D31: T-PAK | E31: MONIS ALI KHAN | F31: Karachi | G31: 42201-4151547-1 | H31: 03452250916 | I31: 03452250916 | J31: 03452250916 | K31: HOUSE # SDH # 108, NEW FALCON COMPLEX NEW MALIR OPP CHECK POST # 5 MALIR CANTT KARACHI | L31: 1692500 | M31: 3385000 | N31: 53157/00007/11/2020 | O31: 45599 | P31: 12917077 | Q31: 020450 | R31: USD | S31: BJV-518 | T31: CIVIC IVTEC P/T | U31: 2017 | V31: 06-NOV-2020 | W31: 11-NOV-2020 | X31: 11-Nov-2025 | Y31: POUKHI300060091 | Z31: 5 | AA31: ITFT | AB31: 3482/11/2020/ITFM | AC31: 04-NOV-2020 | AD31: 2% | AE31: 2538750 | AF31: 50775 | AJ31: =_xlfn.XLOOKUP(Table9[[#This Row],[Engine No.]],'[1]Dubai Islamic Consumer'!$Q$3:$Q$1176,'[1]Dubai Islamic Consumer'!$B$3:$B$1176,,,) -> KHI/HO/D/MO/PC COMP/C/102086/45/11/2024
A32: 31 | B32: ACTIVE | C32: 997AAD1202680015 | D32: T-PAK | E32: AFTAB AHMAD | F32: Lahore | G32: 35404-1596350-9 | H32: 03216460886 | I32: 03216460886 | J32: 03216460886 | K32: 50-U USMAN BLOCK NEAR TEDDI GALI NE W PAKISTAN CLOTH MARKET LAHORE | L32: 1851500 | M32: 2645000 | N32: DIB/T/BT/29430/LHR/1120 | O32: 45599 | P32: 7541647 | Q32: 264797 | R32: NEW | T32: CITY I-VTEC P/T | U32: 2020 | V32: 24-SEP-2020 | W32: 11-NOV-2020 | X32: 11-Nov-2025 | Y32: POALHR300057517 | Z32: 5 | AA32: CTRK | AB32: TDIDIB0028733 | AC32: 04-NOV-2020 | AD32: 2% | AE32: 1983750 | AF32: 39675 | AJ32: =_xlfn.XLOOKUP(Table9[[#This Row],[Engine No.]],'[1]Dubai Islamic Consumer'!$Q$3:$Q$1176,'[1]Dubai Islamic Consumer'!$B$3:$B$1176,,,) -> KHI/HO/D/MO/PC COMP/C/102086/47/11/2024
A33: 32 | B33: ACTIVE | C33: 9976AP1213090067 | D33: T-PAK | E33: RASHID MUNIR | F33: Faisalabad | G33: 33100-3524195-3 | H33: 041-8728868 | I33: 0300-9664972 0300-7632840 | J33: 041-2659191 | K33: H NO P-64 BLOCK-A PEOPLES COLONY # 2 NR PAK ELECTRIC STORE FAISALABAD | L33: 1715000 | M33: 2450000 | N33: DIB/T/34285/LHR/1121 | O33: 45599 | P33: L15A79789003 | Q33: R219402 | R33: USD | S33: AEW-076 | T33: HONDA CITY I-VTEC | U33: 2018 | V33: 05-NOV-2021 | W33: 11-NOV-2021 | X33: 11-Nov-2026 | Y33: OLUFSD300078032 | Z33: 5 | AA33: ITECL | AB33: 5578/11/2021 | AC33: 04-NOV-2021 | AD33: 2% | AE33: 1960000 | AF33: 39200 | AJ33: =_xlfn.XLOOKUP(Table9[[#This Row],[Engine No.]],'[1]Dubai Islamic Consumer'!$Q$3:$Q$1176,'[1]Dubai Islamic Consumer'!$B$3:$B$1176,,,) -> KHI/HO/D/MO/PC COMP/C/102086/48/11/2024
A34: 33 | B34: ACTIVE | C34: 9976AD1211200072 | D34: T-PAK | E34: ABDUL REHMAN | F34: Multan | G34: 36302-1281975-1 | H34: 03059638486 | I34: 03059638486 | J34: 03059638486 | K34: STREET NO 2 BOSAN ROAD AL QADIR STR EET MOHALLAH GHAFARIA CHUNGI NO 6 MULTAN PK | L34: 1847300 | M34: 2639000 | N34: 2021/11/CLFTTPCDP01216 | O34: 45599 | P34: CAD517751 | Q34: 1003750 | R34: NEW | T34: CHANGAN ALSVIN | U34: 2021 | V34: 30-APR-2021 | W34: 03-DEC-2021 | X34: 03-Dec-2026 | Y34: OLAMUX300068556 | Z34: 5 | AA34: ITFT | AB34: 5579/11/2021/ITFM | AC34: 05-NOV-2021 | AD34: 2% | AE34: 2243150 | AF34: 44863 | AJ34: =_xlfn.XLOOKUP(Table9[[#This Row],[Engine No.]],'[1]Dubai Islamic Consumer'!$Q$3:$Q$1176,'[1]Dubai Islamic Consumer'!$B$3:$B$1176,,,) -> KHI/HO/D/MO/PC COMP/C/102086/49/11/2024
A35: 34 | B35: ACTIVE | C35: 997AAD1202120020 | D35: T-PAK | E35: MUHAMMAD MUNEEB | F35: Gujranwala | G35: 34101-2584569-3 | H35: 03218112232 | I35: 03218112232 | J35: 0553844551 | K35: H# C 1 -576 WAPDA TOWM GUJRANWALA PK | L35: 2699500 | M35: 5399000 | N35: 2524/02150/00188/11/2020 | O35: 45599 | P35: G4NALH324032 | Q35: NNAQL51AZKP505918 | R35: NEW | T35: SPORTAGE AWD | U35: 2020 | V35: 30-JUL-2020 | W35: 27-NOV-2020 | X35: 27-Nov-2025 | Y35: POAGWL300056055 | Z35: 5 | AD35: 2% | AE35: 4049250 | AF35: 80985 | AJ35: =_xlfn.XLOOKUP(Table9[[#This Row],[Engine No.]],'[1]Dubai Islamic Consumer'!$Q$3:$Q$1176,'[1]Dubai Islamic Consumer'!$B$3:$B$1176,,,) -> KHI/HO/D/MO/PC COMP/C/102086/50/11/2024
A36: 35 | B36: ACTIVE | C36: 997AAD2202120012 | D36: T-PAK | E36: SANIA QAMAR | F36: Hyderabad | G36: 41304-8992077-0 | I36: 03338181234 | K36: HOUSE NO C/D-293 MOHALLA QAMAR HOUSE UNIT NO 06 LATIFABAD HYDERABAD PAKISTAN | L36: 2699500 | M36: 5399000 | N36: 2524/02150/00189/11/2020 | O36: 45599 | P36: 327106 | Q36: 506258 | R36: NEW | T36: KIA SPORTAGE AWD | U36: 2020 | V36: 30-JUL-2020 | W36: 03-DEC-2020 | X36: 03-Dec-2025 | Y36: POAHYD300056139 | Z36: 5 | AD36: 2% | AE36: 4049250 | AF36: 80985 | AJ36: =_xlfn.XLOOKUP(Table9[[#This Row],[Engine No.]],'[1]Dubai Islamic Consumer'!$Q$3:$Q$1176,'[1]Dubai Islamic Consumer'!$B$3:$B$1176,,,) -> KHI/HO/D/MO/PC COMP/C/102086/51/11/2024
A37: 36 | B37: ACTIVE | C37: 9976AP1213090072 | D37: T-PAK | E37: WAJEEHA YASMIN | F37: Lahore | G37: 35202-7676878-8 | H37: 03434678887 | I37: 03434678887 | J37: 03434678887 | K37: 49-E MAIN MOLANA SHAUKAT ALI ROAD K KT BUILDING MAZANINE FLOOR LAHORE | L37: 2416500 | M37: 5370000 | N37: DIB/T/34284/LHR/1121 | O37: 45599 | P37: G4NALH313952 | Q37: NNAQL51AZKP503950 | R37: USD | S37: AAC-234 | T37: SPORTAGE AWD | U37: 2020 | V37: 05-NOV-2021 | W37: 11-NOV-2021 | X37: 11-Nov-2026 | Y37: OLULHR300078002 | Z37: 5 | AA37: CTRK | AB37: TDIDIB0029794 | AC37: 04-NOV-2021 | AD37: 2% | AE37: 4296000 | AF37: 85920 | AJ37: =_xlfn.XLOOKUP(Table9[[#This Row],[Engine No.]],'[1]Dubai Islamic Consumer'!$Q$3:$Q$1176,'[1]Dubai Islamic Consumer'!$B$3:$B$1176,,,) -> KHI/HO/D/MO/PC COMP/C/102086/52/11/2024
A38: 37 | B38: ACTIVE | C38: 997AAD1203020044 | D38: T-PAK | E38: SULTAN MUHAMMAD KAIGOHAR KIANI | F38: Islamabad | G38: 61101-3717511-7 | H38: 03335524253 | J38: 0519220383 | K38: H # 14 ST # 3 ROAD-L BLOCK-E NAVAL ANCHORAGE ISLAMABAD PK | L38: 2986125 | M38: 3981500 | N38: 2524/02150/00187/11/2020 | O38: 45599 | P38: 16914508 | Q38: LR066375 | R38: NEW | T38: CIVIC VTI ORIEL P/T | U38: 2020 | V38: 28-OCT-2020 | W38: 21-NOV-2020 | X38: 21-Nov-2027 | Y38: POAISD300059175 | Z38: 7 | AA38: ITMM | AB38: 3480/11/2020/ITMM | AC38: 04-NOV-2020 | AD38: 2% | AE38: 2986125 | AF38: 59723 | AJ38: =_xlfn.XLOOKUP(Table9[[#This Row],[Engine No.]],'[1]Dubai Islamic Consumer'!$Q$3:$Q$1176,'[1]Dubai Islamic Consumer'!$B$3:$B$1176,,,) -> KHI/HO/D/MO/PC COMP/C/102086/53/11/2024
A39: 38 | B39: ACTIVE | C39: 997AAD1202050021 | D39: T-PAK | E39: MUHAMMAD ARSHAD | F39: Lahore | G39: 35202-9453292-9 | H39: 03219472731 | I39: 03219472731 | J39: 04235219011 | K39: 29-M , INTERNATIONAL MARKET MODEL T OWN (EXT) LAHORE | L39: 3527550 | M39: 5427000 | N39: 53157/00006/11/2020 | O39: 45599 | P39: 325988 | Q39: 506312 | R39: NEW | T39: KIA SPORAGE AWD | U39: 2020 | V39: 23-JUL-2020 | W39: 11-NOV-2020 | X39: 11-Nov-2025 | Y39: POALHR300055693 | Z39: 5 | AD39: 1.5% | AE39: 4070250 | AF39: 61054 | AJ39: =_xlfn.XLOOKUP(Table9[[#This Row],[Engine No.]],'[1]Dubai Islamic Consumer'!$Q$3:$Q$1176,'[1]Dubai Islamic Consumer'!$B$3:$B$1176,,,) -> KHI/HO/D/MO/PC COMP/C/102086/54/11/2024
A40: 39 | B40: ACTIVE | C40: 997APD2203100001 | D40: T-PAK | E40: SARDAR HASAN RAZA | F40: Islamabad | G40: 13101-4387845-3 | H40: 03018422202 | J40: 0519245702 | K40: H # 273 ST # 148/149 SECTOR # D-12/ 4 ISLAMABAD PK | L40: 3919300 | M40: 5599000 | N40: 53157/00008/11/2020 | O40: 45599 | P40: 576961 | Q40: 200411 | R40: NEW | T40: TUCSON AWD | U40: 2020 | V40: 05-NOV-2020 | W40: 11-NOV-2020 | X40: 11-Nov-2025 | Y40: PODISD300060131 | Z40: 5 | AA40: CTRK | AB40: DIB0029001 | AC40: 05-NOV-2020 | AD40: 1.5% | AE40: 4199250 | AF40: 62989 | AJ40: =_xlfn.XLOOKUP(Table9[[#This Row],[Engine No.]],'[1]Dubai Islamic Consumer'!$Q$3:$Q$1176,'[1]Dubai Islamic Consumer'!$B$3:$B$1176,,,) -> KHI/HO/D/MO/PC COMP/C/102086/55/11/2024
...

Sheet Active cases
A1: Sr. | B1: Status | C1: Contract No. | D1: Insurance Agency | E1: Customer Name | F1: City | G1: CNIC No. | H1: Home Phone# | I1: Mobile Number | J1: Business Phone# | K1: Mail Address | L1: Finance Amount | M1: Car Price | N1: Ins. Policy | O1: Ins. Expiry Date | P1: Engine No. | Q1: Chassis No. | R1: Car Category | S1: Reg. No. | T1: Car Name | U1: Model | V1: Contract Booking Date | W1: Contract Value Date | X1: Contract Maturity Date | Y1: Purchase Order No. | Z1: Tenor#2 | AA1: Tracker Company | AB1: Tracker Reference Number | AC1: Tracker Installation Date | AD1: Rate | AE1: Sum Insured | AF1: Premium | AG1: OLD Contract Ref | AH1: Remarks-I | AI1: Remarks-II | AJ1: Policy # | AK1: Tms prem | AL1: End. # | AM1: Difference | AN1: Tagging
A2: 1 | B2: ACTIVE | C2: 9976AD1211970001 | D2: T-PAK | E2: SOHAIL NASIR | F2: Faisalabad | G2: 33100-7633385-9 | H2: 03222227879 | I2: 03222227879, 03222227879 | J2: 03222227879 | K2: H NO 155 B-BLOCK GALIB CITY FAISALABAD PK | L2: 1001250 | M2: 1335000 | N2: 2021/10/CLFFTPCDP01207 | O2: 45597 | P2: 191006 | Q2: 1091022 | R2: NEW | T2: SUZUKI ALTO VXR EURO-II | U2: 2021 | V2: 16-JUL-2021 | W2: 11-NOV-2021 | X2: 11-Nov-2026 | Y2: OLAFSD300070753 | Z2: 5 | AA2: CTRK | AB2: DIB0032363 | AC2: 02-NOV-2021 | AD2: 2% | AE2: 1068000 | AF2: 21360 | AJ2: KHI/HO/D/MO/PC COMP/C/102086/2/11/2024 | AK2: 21360 | AM2: =AF2-AK2 -> 0 | AN2: REN
A3: 2 | B3: ACTIVE | C3: 9976AD1212090016 | D3: T-PAK | E3: IKHLAQ HUSSAIN | F3: Faisalabad | G3: 33100-0642718-5 | I3: 03006660309 | K3: SHOP NO 1891 AL MADINA COMMERCIAL MARKET NEAR MAIN CENTER GANESH MILLS FACTORY AREA FAISALABAD | L3: 1098000 | M3: 1830000 | N3: DIB/T/34267/LHR/1121 | O3: 45597 | P3: 187626 | Q3: 10087599 | R3: NEW | T3: CULTUS VXL | U3: 2021 | V3: 28-JUL-2021 | W3: 11-NOV-2021 | X3: 11-Nov-2026 | Y3: OLAFSD300071229 | Z3: 5 | AA3: CTRK | AB3: DIB0032361 | AC3: 02-NOV-2021 | AD3: 2% | AE3: 1464000 | AF3: 29280 | AJ3: KHI/HO/D/MO/PC COMP/C/102086/3/11/2024 | AK3: 29280 | AM3: =AF3-AK3 -> 0 | AN3: REN
A4: 3 | B4: ACTIVE | C4: 9976AD1212560009 | D4: T-PAK | E4: SELMAN RASHID IQBAL | F4: Sialkot | G4: 34603-2315200-3 | H4: 92524295927 | I4: 03018718899 | J4: 92523241923 | K4: HOUSE NO 127/24 HAIDAR ROAD SIALKOT CANTT TEHSIL AND DISTT SIALKOT | L4: 2027250 | M4: 2703000 | N4: UWT/D/T002/0000001124/1121/109-0 | O4: 45597 | P4: 2A39606 | Q4: 7024780 | R4: NEW | T4: COROLLA YARIS 1.3 AT | U4: 2021 | V4: 13-SEP-2021 | W4: 11-NOV-2021 | X4: 11-Nov-2026 | Y4: OLASKT300073113 | Z4: 5 | AA4: CTRK | AB4: DIB0032370 | AC4: 02-NOV-2021 | AD4: 1.75% | AE4: 2162400 | AF4: 37842 | AJ4: KHI/HO/D/MO/PC COMP/C/102086/5/11/2024 | AK4: 37842 | AM4: =AF4-AK4 -> 0 | AN4: REN
A5: 4 | B5: ACTIVE | C5: 997AAD1203050109 | D5: T-PAK | E5: ASAD MEHMOOD | F5: Rawalpindi | G5: 37405-0550285-5 | H5: 03345931343 | J5: 03005305187 | K5: KHASRA # 209 RAJA ASAD STREET ST # 37/8 MOHALLAH MILLATABAD BARAF KHAN RAWALPINDI PK | L5: 2986125 | M5: 3981500 | N5: 2524/02150/00177/11/2020 | O5: 45597 | P5: 914453 | Q5: 066325 | R5: NEW | T5: CIVIC VTI ORIEL P/T | U5: 2020 | V5: 31-OCT-2020 | W5: 11-NOV-2020 | X5: 11-Nov-2025 | Y5: POARWP300059795 | Z5: 5 | AA5: CTRK | AB5: DIB0028990 | AC5: 03-NOV-2020 | AD5: 2% | AE5: 2986125 | AF5: 59723 | AJ5: KHI/HO/D/MO/PC COMP/C/102086/6/11/2024 | AK5: 59723 | AM5: =AF5-AK5 -> 0 | AN5: REN
A6: 5 | B6: ACTIVE | C6: 9976AD1212120085 | D6: T-PAK | E6: ASIF MAHMOOD | F6: Lahore | G6: 35201-1571249-5 | H6: 03214765797 | I6: 03214765797 | J6: 04236520393 | K6: 5-A USMAN BLOCK CANAL BANK SCHEME H ARBANSPURA LAHORE | L6: 3952500 | M6: 5270000 | N6: DIB/T/34275/LHR/1121 | O6: 45597 | P6: 318580 | Q6: 513459 | R6: NEW | T6: KIA SPORTAGE AWD | U6: 2021 | V6: 31-JUL-2021 | W6: 11-NOV-2021 | X6: 11-Nov-2026 | Y6: OLALHR300071474 | Z6: 5 | AA6: ITECL | AB6: 5568/11/2021 | AC6: 02-NOV-2021 | AD6: 1.75% | AE6: 4216000 | AF6: 73780 | AJ6: KHI/HO/D/MO/PC COMP/C/102086/7/11/2024 | AK6: 73780 | AM6: =AF6-AK6 -> 0 | AN6: REN
A7: 6 | B7: ACTIVE | C7: 9976AD1211650002 | D7: T-PAK | E7: USAMA SHAFIQ | F7: Faisalabad | G7: 33102-6906523-3 | H7: 8777818 | I7: 03119999595, 03119999595 | J7: 03119999595 | K7: 46-A, TECH TOWN, NEAR SATYANA ROAD FAISALABAD PK | L7: 6516300 | M7: 9309000 | N7: 01-2110-PO-MTR-PCCM-D-001497 | O7: 45597 | P7: 1GD-5077748 | Q7: R-1097037 | R7: NEW | T7: FORTUNER A/T | U7: 2021 | V7: 14-JUN-2021 | W7: 03-DEC-2021 | X7: 03-Dec-2026 | Y7: OLAFSD300069468 | Z7: 5 | AA7: CTRK | AB7: DIB0032371 | AC7: 02-NOV-2021 | AD7: 1.75% | AE7: 7447200 | AF7: 130326 | AJ7: KHI/HO/D/MO/PC COMP/C/102086/8/11/2024 | AK7: 130326 | AM7: =AF7-AK7 -> 0 | AN7: REN
A8: 7 | B8: ACTIVE | C8: 9976AP1223080006 | D8: T-PAK | E8: MUHAMMAD SAMEER KAZI | F8: Karachi | G8: 42201-1431273-3 | H8: 03043615125 | I8: 03043615125 | J8: 0 | K8: H # R- 18 SUPARCO CO OPERATIVE HOUS ING SCOIETY SCHEEM 33 MAYMAR MORE KARACHI PK | L8: 922500 | M8: 2050000 | N8: 64794/00001/11/2022 | O8: 45597 | P8: 246433 | Q8: 1146470 | R8: USD | S8: BXP-407 | T8: SUZUKI ALTO VXR EURO-II | U8: 2022 | V8: 04-NOV-2022 | W8: 11-NOV-2022 | X8: 11-Nov-2025 | Y8: OLUKHI30009013 | Z8: 3 | AA8: ITFT | AB8: 9285/11/2022/ITFM | AC8: 02-NOV-2022 | AD8: 1.75% | AE8: 1742500 | AF8: 30494 | AJ8: KHI/HO/D/MO/PC COMP/C/102086/10/11/2024 | AK8: 30494 | AM8: =AF8-AK8 -> 0 | AN8: REN
A9: 8 | B9: ACTIVE | C9: 997AAD1201950001 | D9: T-PAK | E9: ZAHID SAMUEL | F9: JHELUM | G9: 37301-9691544-9 | H9: 03325922916 | J9: 0544275675 | K9: ROHTAS ROAD , MUHALLAH CHRISTAN COL ONY NEAR QASIR CHOWK JHELUM PK | L9: 1959750 | M9: 2613000 | N9: DIB/T/BT/29418/ISB/1120 | O9: 45597 | P9: 2A10639 | Q9: 7006139 | R9: NEW | T9: YARIS ATIV MT 1.3 | U9: 2020 | V9: 13-JUL-2020 | W9: 21-NOV-2020 | X9: 21-Nov-2027 | Y9: POAJHM300055111 | Z9: 7 | AA9: CTRK | AB9: DIB0028988 | AC9: 03-NOV-2020 | AD9: 2.5% | AE9: 1959750 | AF9: 48994 | AJ9: KHI/HO/D/MO/PC COMP/C/102086/11/11/2024 | AK9: 48994 | AM9: =AF9-AK9 -> 0 | AN9: REN
A10: 9 | B10: ACTIVE | C10: 9976AD1212350014 | D10: T-PAK | E10: MUHAMMAD ARIF | F10: Rawalpindi | G10: 37405-2017815-9 | H10: 03360573213 | J10: 0519268147 | K10: H # G-1 BLOCK C GHAZI COLONY TIPU R OAD NEAR GO CNG PUMP RAWALPINDI PK | L10: 744750 | M10: 1655000 | N10: DIB/T/34281/ISB/1121 | O10: 45598 | P10: 188029 | Q10: 10088024 | R10: NEW | T10: SUZUKI CULTUS VXR EURO II | U10: 2021 | V10: 23-AUG-2021 | W10: 11-NOV-2021 | X10: 11-Nov-2026 | Y10: OLARWP300072176 | Z10: 5 | AA10: CTRK | AB10: TDIDIB0029793 | AC10: 05-NOV-2021 | AD10: 2% | AE10: 1324000 | AF10: 26480 | AJ10: KHI/HO/D/MO/PC COMP/C/102086/12/11/2024 | AK10: 26480 | AM10: =AF10-AK10 -> 0 | AN10: REN
A11: 10 | B11: ACTIVE | C11: 9976AD2212290009 | D11: T-PAK | E11: TASLEEM AKHTAR | F11: Lahore | G11: 38201-2575486-8 | H11: 03137357790 | I11: 03137357790 | J11: 03137357790 | K11: JAIL ROAD PUNJAB CARDIALOGY 3RD FLO OR OPPOSITE MECHDOLANDS LAHORE | L11: 1001250 | M11: 1335000 | N11: 2524/02742/0003/11/2021 | O11: 45598 | P11: 191149 | Q11: 1091170 | R11: NEW | T11: SUZUKI ALTO VXR EURO II | U11: 2021 | V11: 17-AUG-2021 | W11: 21-NOV-2021 | X11: 21-Nov-2025 | Y11: OLALHR300071995 | Z11: 4 | AA11: CTRK | AB11: DIB0032382 | AC11: 04-NOV-2021 | AD11: 2% | AE11: 1068000 | AF11: 21360 | AJ11: KHI/HO/D/MO/PC COMP/C/102086/13/11/2024 | AK11: 21360 | AM11: =AF11-AK11 -> 0 | AN11: REN
A12: 11 | B12: ACTIVE | C12: 9976AD1211810025 | D12: T-PAK | E12: AMEER ALI LUHUR | F12: LARKANA | G12: 43203-3056842-9 | I12: 03342243242 | K12: LUHUR DECORATION SERVICE NAUDERO ROAD BYPASS NEAR SINDH GREEN HOTEL LARKANA | L12: 999750 | M12: 1333000 | N12: DIB/T/34280/HYD/1121 | O12: 45598 | P12: 6R188933 | Q12: NF1AET306H1088889 | R12: NEW | T12: ALTO VXR EURO-II | U12: 2021 | V12: 30-JUN-2021 | W12: 11-NOV-2021 | X12: 11-Nov-2026 | Y12: OLALRK300070128 | Z12: 5 | AA12: CTRK | AB12: TDIDIB0029753 | AC12: 29-OCT-2021 | AD12: 2% | AE12: 1066400 | AF12: 21328 | AJ12: KHI/HO/D/MO/PC COMP/C/102086/14/11/2024 | AK12: 21328 | AM12: =AF12-AK12 -> 0 | AN12: REN
A13: 12 | B13: ACTIVE | C13: 997APD1203110006 | D13: T-PAK | E13: ASHFAQUE AHMED | F13: Lahore | G13: 35201-5806207-9 | H13: 03214228449 | I13: 03214228449 | J13: 04237191274 | K13: OFFICE NO 94 COMMERCIAL BROADWAY PA RGON CITY BARKI ROAD NEAR FUTURE NO W TECH LAHORE | L13: 1211000 | M13: 1730000 | N13: 53157/00004/11/2020 | O13: 45598 | P13: 207189 | Q13: 10107185 | R13: NEW | T13: WAGONR VXL | U13: 2020 | V13: 06-NOV-2020 | W13: 11-NOV-2020 | X13: 11-Nov-2026 | Y13: PODLHR300060261 | Z13: 6 | AA13: ITFM | AB13: 3474/11/2020/ITFM | AC13: 04-NOV-2020 | AD13: 2% | AE13: 1297500 | AF13: 25950 | AJ13: KHI/HO/D/MO/PC COMP/C/102086/15/11/2024 | AK13: 27680 | AL13: KHI/HO/D/MO/PC COMP/E/49863/00015/12/2024 | AM13: =AF13-AK13 -> -1730 | AN13: REN
A14: 13 | B14: ACTIVE | C14: 9976AD2211800001 | D14: T-PAK | E14: MUHAMMAD IQBAL | F14: Gujrat | G14: 34201-0363899-5 | H14: 03036871894 | I14: 03036871894 | J14: 03036871894 | K14: OPPOSITE PUBLIC SCHOOL NO 2 MOHALLA H AZIZABAD RAILWAY ROAD GUJRAT PK | L14: 1066000 | M14: 1640000 | N14: 56607/00005/11/2021 | O14: 45598 | P14: 505771 | Q14: 1010057 | R14: NEW | T14: KARVAAN PLUS | U14: 2021 | V14: 29-JUN-2021 | W14: 03-DEC-2021 | X14: 03-Dec-2026 | Y14: OLAGJR300069996 | Z14: 5 | AA14: CTRK | AB14: DIB0032386 | AC14: 04-NOV-2021 | AD14: 2% | AE14: 1312000 | AF14: 26240 | AJ14: KHI/HO/D/MO/PC COMP/C/102086/16/11/2024 | AK14: 26240 | AM14: =AF14-AK14 -> 0 | AN14: REN
A15: 14 | B15: ACTIVE | C15: 997AAD2203020015 | D15: T-PAK | E15: AYEEN MUHAMMAD KHAN | F15: Islamabad | G15: 71501-0639654-5 | H15: 03327424312 | J15: 0518840517 | K15: H # 708 ST # 47 SECTOR # G-9/1 ISLAMABAD PK | L15: 1232500 | M15: 2465000 | N15: 2524/02150/00174/11/2020 | O15: 45598 | P15: 7541706 | Q15: LR-264824 | R15: NEW | T15: HONDA CITY IVTEC | U15: 2020 | V15: 28-OCT-2020 | W15: 11-NOV-2020 | X15: 11-Nov-2027 | Y15: POAISD300059172 | Z15: 7 | AA15: ITMM | AB15: 3463/11/2020/ITMM | AC15: 02-NOV-2020 | AD15: 2% | AE15: 1848750 | AF15: 36975 | AJ15: KHI/HO/D/MO/PC COMP/C/102086/17/11/2024 | AK15: 36975 | AM15: =AF15-AK15 -> 0 | AN15: REN
A16: 15 | B16: ACTIVE | C16: 997AAD1202960014 | D16: T-PAK | E16: MUHAMMAD YOUSAF ASLAM | F16: Faisalabad | G16: 33100-8463560-7 | H16: 03217821165 | I16: 03217821165, 03217821165 | J16: 0418728819 | K16: H NO 3-X BLOCK X UPPER FLOOR ST NO 12 MADINA TOWN FAISALABAD PK | L16: 2787050 | M16: 3981500 | N16: 2524/02150/00152/11/2020 | O16: 45598 | P16: 6914492 | Q16: LR066318 | R16: NEW | T16: CIVIC VTI ORIEL P/T | U16: 2020 | V16: 22-OCT-2020 | W16: 11-NOV-2020 | X16: 11-Nov-2025 | Y16: POAFSD300059003 | Z16: 5 | AA16: ITFM | AB16: 3476/11/2020/ITFM | AC16: 04-NOV-2020 | AD16: 2% | AE16: 2986125 | AF16: 59723 | AJ16: KHI/HO/D/MO/PC COMP/C/102086/20/11/2024 | AK16: 59723 | AM16: =AF16-AK16 -> 0 | AN16: REN
A17: 16 | B17: ACTIVE | C17: 9976AD1212380020 | D17: T-PAK | E17: RAJA ADIL SARFRAZ | F17: Faisalabad | G17: 41306-0723517-3 | H17: 03452932949 | I17: 03452932949, 03452932949 | J17: 0419200161 | K17: H NO P-391-C BLOCK-C MILLAT TOWN MI LLAT ROAD FAISALABAD PK | L17: 2549200 | M17: 3186500 | N17: 2021-10-205-V01501OP0002654 | O17: 45598 | P17: L15Z81001399 | Q17: NFBGN966XMR005542 | R17: NEW | T17: HONDA CITY ASPIRE | U17: 2021 | V17: 26-AUG-2021 | W17: 11-NOV-2021 | X17: 11-Nov-2026 | Y17: OLAFSD300072297 | Z17: 5 | AA17: CTRK | AB17: DIB0032299 | AC17: 03-NOV-2021 | AD17: 2% | AE17: 2549200 | AF17: 50984 | AJ17: KHI/HO/D/MO/PC COMP/C/102086/21/11/2024 | AK17: 50984 | AM17: =AF17-AK17 -> 0 | AN17: REN
A18: 17 | B18: ACTIVE | C18: 997AAD1202050020 | D18: T-PAK | E18: BILAL ZIA | F18: Gujranwala | G18: 34101-4056821-7 | H18: 03152227292 | I18: 03152227292 | J18: 03152227292 | K18: HOUSE NO 351 STREET NO 5 SECTOR 1 CANTT GUJRANWALA | L18: 3239400 | M18: 5399000 | N18: 53157/00003/11/2020 | O18: 45598 | P18: 327392 | Q18: KP506234 | R18: NEW | T18: KIA SPORTAGE AWD | U18: 2020 | V18: 23-JUL-2020 | W18: 11-NOV-2020 | X18: 11-Nov-2025 | Y18: POAGWL300055621 | Z18: 5 | AD18: 1.5% | AE18: 4049250 | AF18: 60739 | AJ18: KHI/HO/D/MO/PC COMP/C/102086/22/11/2024 | AK18: 60739 | AM18: =AF18-AK18 -> 0 | AN18: REN
A19: 18 | B19: ACTIVE | C19: 997AAD1201990002 | D19: T-PAK | E19: WASEEM EJAZ | F19: Lahore | G19: 35202-4832610-5 | H19: 0321-8807749 | I19: 0321-8807749 | J19: 35959594 | K19: H NO 11 MALIK STREET EJAZ CHOWK 18 KM FEROZPUR ROAD REHMAT COLONY NISHTER COLONY LAHORE | L19: 3798900 | M19: 5427000 | N19: DIB/T/29424/LHR/1120 | O19: 45598 | P19: 324054 | Q19: 506019 | R19: NEW | T19: KIA SPORATAGE AWD | U19: 2020 | V19: 17-JUL-2020 | W19: 11-NOV-2020 | X19: 11-Nov-2025 | Y19: POALHR300055319 | Z19: 5 | AD19: 1.5% | AE19: 4070250 | AF19: 61054 | AJ19: KHI/HO/D/MO/PC COMP/C/102086/23/11/2024 | AK19: 61054 | AM19: =AF19-AK19 -> 0 | AN19: REN
A20: 19 | B20: ACTIVE | C20: 9976AP1223080007 | D20: T-PAK | E20: MALIK MUHAMMAD BASHARAT | F20: Islamabad | G20: 42201-0256988-9 | H20: 03008232280 | J20: 0515709137 | K20: H # 7 ST # 8 FEDERATION HOUSING SOC IETY LOHI BAIR SECTOR A ISLAMABAD PK | L20: 1794800 | M20: 2564000 | N20: 64794/00003/11/2022 | O20: 45598 | P20: 10B239700 | Q20: 10139728 | R20: NEW | T20: SUZUKI WAGONR VXL | U20: 2022 | V20: 04-NOV-2022 | W20: 11-NOV-2022 | X20: 11-Nov-2027 | Y20: OLDISD300090725 | Z20: 5 | AA20: FLCN | AB20: 108809/11/2022 | AC20: 03-NOV-2022 | AD20: 1.75% | AE20: 2179400 | AF20: 38140 | AJ20: KHI/HO/D/MO/PC COMP/C/102086/24/11/2024 | AK20: 38140 | AM20: =AF20-AK20 -> 0 | AN20: REN
A21: 20 | B21: ACTIVE | C21: 9976AP2223110007 | D21: T-PAK | E21: MUHAMMAD KASHIF | F21: Karachi | G21: 42301-7784361-9 | H21: 03132213808 | I21: 03132213808 | J21: 0 | K21: C- 27 4 RTH FLOOR ZEESHAN BLESSING GULSHAN-E- IQBAL BOCK 16 OPP NOOR M KARACHI PK | L21: 1330000 | M21: 1900000 | N21: 64794/0004/11/2022 | O21: 45598 | P21: 122604 | Q21: 10022606 | R21: USD | S21: BKK-497 | T21: SUZUKI WAGONR VXL | U21: 2017 | V21: 07-NOV-2022 | W21: 11-NOV-2022 | X21: 11-Nov-2026 | Y21: OLUKHI300090714 | Z21: 4 | AA21: ITFT | AB21: 9298/11/2022/ITFM | AC21: 05-NOV-2022 | AD21: 1.75% | AE21: 1615000 | AF21: 28263 | AJ21: KHI/HO/D/MO/PC COMP/C/102086/26/11/2024 | AK21: 28263 | AM21: =AF21-AK21 -> 0 | AN21: REN
A22: 21 | B22: ACTIVE | C22: 9976AD2221710002 | D22: T-PAK | E22: USMAN JAVED BUTT | F22: Lahore | G22: 35202-3706453-7 | H22: 03004580882 | I22: 03004580882 | J22: 03004580882 | K22: H NO 829-A MUHALLAH CANAL VIEW BLOC K E LAHORE LAHORE PK | L22: 2733500 | M22: 3905000 | N22: 64794/00002/11/2022 | O22: 45598 | P22: 81012003 | Q22: 027765 | R22: NEW | T22: HONDA CITY ASPIRE A/T | U22: 2022 | V22: 20-JUN-2022 | W22: 11-NOV-2022 | X22: 11-Nov-2025 | Y22: OLALHR300088166 | Z22: 3 | AA22: ITFT | AB22: 9288/11/2022/ITFM | AC22: 03-NOV-2022 | AD22: 2% | AE22: 3319250 | AF22: 66385 | AJ22: KHI/HO/D/MO/PC COMP/C/102086/28/11/2024 | AK22: 66385 | AM22: =AF22-AK22 -> 0 | AN22: REN
A23: 22 | B23: ACTIVE | C23: 9976AD1213620032 | D23: T-PAK | E23: SALMAN IKRAM | F23: Sialkot | G23: 34603-5068241-5 | H23: 03008612564 | I23: 03008612564 | J23: 03008612564 | K23: MOH MODEL TOWN UGOKI PO KHAS GUJRANWALA PK | L23: 1524600 | M23: 2178000 | N23: 64794/00006/11/2022 | O23: 45598 | P23: 085661 | Q23: 711231 | R23: NEW | T23: KIA PICANTO 1.0 L A/T | U23: 2022 | V23: 28-DEC-2021 | W23: 11-NOV-2022 | X23: 11-Nov-2025 | Y23: OLASKT300082278 | Z23: 3 | AA23: ITECL | AB23: 9283/11/2022 | AC23: 01-NOV-2022 | AD23: 2% | AE23: 1851300 | AF23: 37026 | AJ23: KHI/HO/D/MO/PC COMP/C/102086/31/11/2024 | AK23: 37026 | AM23: =AF23-AK23 -> 0 | AN23: REN
A24: 23 | B24: ACTIVE | C24: 9976AP2223080004 | D24: T-PAK | E24: MUHAMMAD MOHSIN KHAIRI | F24: Karachi | G24: 42201-4373898-1 | H24: 03343236770 | I24: 03343236770 | J24: 03343236770 | K24: FLAT NO. 601 6TH FLOOR BURJ UL IMRA N APARTMENT SECTOR JINNAH AVENUE NE KARACHI PK | L24: 1267500 | M24: 1950000 | N24: 64794/00005/11/2022 | O24: 45598 | P24: 6R241226 | Q24: 1141200 | R24: USD | S24: BXF-240 | T24: SUZUKI ALTO VXR EURO-II | U24: 2022 | V24: 04-NOV-2022 | W24: 11-NOV-2022 | X24: 11-Nov-2027 | Y24: OLUKHI300090726 | Z24: 5 | AA24: ITFT | AB24: 9289/11/2022/ITFM | AC24: 03-NOV-2022 | AD24: 1.75% | AE24: 1657500 | AF24: 29006 | AJ24: KHI/HO/D/MO/PC COMP/C/102086/36/11/2024 | AK24: 29006 | AM24: =AF24-AK24 -> 0 | AN24: REN
A25: 24 | B25: ACTIVE | C25: 9976AD2232710003 | D25: T-PAK | E25: MUHAMMAD BILAL | F25: Lahore | G25: 34603-7401604-5 | H25: 03037015616 | I25: 03037015616 | J25: 04236400007 | K25: HOUSE NO 3-S-38 AZIM STREET CLIFTON COLONY NEAR GHATTI CHOWK WAHDAT CO LAHORE PK | L25: 1514960 | M25: 2612000 | N25: 77638/0001/11/2023 | O25: 02-NOV-2024 | P25: 6R286844 | Q25: 1187030 | R25: NEW | T25: SUZUKI ALTO VXR EURO II | U25: 2023 | V25: 45197 | W25: 27-NOV-2023 | X25: 27-Nov-2026 | Y25: OLALHR300097279 | Z25: 3 | AA25: CTRK | AB25: DIB0035410 | AC25: 06-NOV-2023 | AD25: 2% | AE25: 2350800 | AF25: 47016 | AJ25: KHI/HO/D/MO/PC COMP/C/102086/37/11/2024 | AK25: 47016 | AM25: =AF25-AK25 -> 0 | AN25: REN
A26: 25 | B26: ACTIVE | C26: 9976AD2212120031 | D26: T-PAK | E26: MUMTAZ AHMAD | F26: Lahore | G26: 35202-2733554-3 | H26: 03334634898 | I26: 03334634898 | J26: 099214240 | K26: DIO SAMAAJ ROAD NEAR MALL ROAD LAHORE | L26: 801000 | M26: 1335000 | N26: 2524/02742/00005/11/2021 | O26: 45599 | P26: 6R190275 | Q26: NF1AET306H1090242 | R26: NEW | T26: ALTO VXR EURO-II | U26: 2021 | V26: 31-JUL-2021 | W26: 21-NOV-2021 | X26: 21-Nov-2026 | Y26: OLALHR300071469 | Z26: 5 | AA26: ITECL | AB26: 5577/11/2021 | AC26: 04-NOV-2021 | AD26: 2% | AE26: 1068000 | AF26: 21360 | AJ26: KHI/HO/D/MO/PC COMP/C/102086/38/11/2024 | AK26: 21360 | AM26: =AF26-AK26 -> 0 | AN26: REN
A27: 26 | B27: ACTIVE | C27: 997AAD1202740084 | D27: T-PAK | E27: MAHER TAUSEEF AHMED | F27: Multan | G27: 36302-8413092-1 | I27: 03018510587 | J27: 6350987 | K27: AL JADEED ASSOCIATES PVT LTD HOUSE NO 16 CANTT COTTAGES SHER SHAH ROAD MULTAN CANTT | L27: 1198500 | M27: 1598000 | N27: 2020/11/CLFTTPCDP00682 | O27: 45599 | P27: 142804 | Q27: 1043351 | R27: NEW | T27: SUZUKI ALTO VXL EURO II AGS | U27: 2020 | V27: 30-SEP-2020 | W27: 21-NOV-2020 | X27: 21-Nov-2025 | Y27: POAMUX300058118 | Z27: 5 | AA27: CTRK | AB27: DIB0028999 | AC27: 04-NOV-2020 | AD27: 2% | AE27: 1198500 | AF27: 23970 | AJ27: KHI/HO/D/MO/PC COMP/C/102086/39/11/2024 | AK27: 23970 | AM27: =AF27-AK27 -> 0 | AN27: REN
A28: 27 | B28: ACTIVE | C28: 997APD2203140004 | D28: T-PAK | E28: DANYIAL ASIF | F28: Lahore | G28: 35202-2670690-5 | H28: 03349755036 | I28: 03349755036 | J28: 04235249651 | K28: PLAZA NO 50 SECTOR D BLOCK AA COMME RCIAL MARKET BAHRIA TOWN NEAR MCDON ALD LAHORE | L28: 1218000 | M28: 2030000 | N28: 53157/00009/11/2020 | O28: 45599 | P28: 13045447 | Q28: 10045452 | R28: NEW | T28: SUZUKI SWIFT DLX 1.3 MT | U28: 2020 | V28: 09-NOV-2020 | W28: 11-NOV-2020 | X28: 11-Nov-2025 | Y28: PODLHR300060201 | Z28: 5 | AA28: ITFM | AB28: 34921/11/2020/ITFM | AC28: 05-NOV-2020 | AD28: 2% | AE28: 1522500 | AF28: 30450 | AJ28: KHI/HO/D/MO/PC COMP/C/102086/40/11/2024 | AK28: 30450 | AM28: =AF28-AK28 -> 0 | AN28: REN
A29: 28 | B29: ACTIVE | C29: 9976AD2212230011 | D29: T-PAK | E29: SUHAIL AHMED | F29: Islamabad | G29: 43406-0374772-7 | H29: 2210817 | I29: 03322023689 | J29: 2210817 | K29: HOSE NO 181 SR NO 68 F 10/3 ISLAMABAD | L29: 1098000 | M29: 1830000 | N29: 01-2111-PO-MTR-PCCM-D-001510 | O29: 45599 | P29: 188067 | Q29: 10088066 | R29: NEW | T29: CULTUS VXL EURO II | U29: 2021 | V29: 11-AUG-2021 | W29: 21-NOV-2021 | X29: 21-Nov-2026 | Y29: OLAISD300071823 | Z29: 5 | AA29: CTRK | AB29: DIB0032403 | AC29: 05-NOV-2021 | AD29: 2% | AE29: 1464000 | AF29: 29280 | AJ29: KHI/HO/D/MO/PC COMP/C/102086/42/11/2024 | AK29: 29280 | AM29: =AF29-AK29 -> 0 | AN29: REN
A30: 29 | B30: ACTIVE | C30: 997AAD2202440025 | D30: T-PAK | E30: MUHAMMAD MANSHA | F30: Faisalabad | G30: 33100-2927708-3 | H30: 03008662363 | I30: 03008662363, 03008662363 | J30: 03008662363 | K30: P-21 MUSLIM PARK SARGODHA ROAD MUSL IM TOWN YOUSAF BLOCK FSD NEAR R.S B FAISALABAD PK | L30: 1657800 | M30: 2763000 | N30: 2524/02150/00185/11/2020 | O30: 45599 | P30: 2A11204 | Q30: 7006644 | R30: NEW | T30: TOYOTA COROLLA YARIS | U30: 2020 | V30: 31-AUG-2020 | W30: 27-NOV-2020 | X30: 27-Nov-2025 | Y30: POAFSD300057032 | Z30: 5 | AA30: ITFM | AB30: 3477/11/2020/ITFM | AC30: 04-NOV-2020 | AD30: 2% | AE30: 2072250 | AF30: 41445 | AJ30: KHI/HO/D/MO/PC COMP/C/102086/44/11/2024 | AK30: 41445 | AM30: =AF30-AK30 -> 0 | AN30: REN
A31: 30 | B31: ACTIVE | C31: 997APD2203110007 | D31: T-PAK | E31: MONIS ALI KHAN | F31: Karachi | G31: 42201-4151547-1 | H31: 03452250916 | I31: 03452250916 | J31: 03452250916 | K31: HOUSE # SDH # 108, NEW FALCON COMPLEX NEW MALIR OPP CHECK POST # 5 MALIR CANTT KARACHI | L31: 1692500 | M31: 3385000 | N31: 53157/00007/11/2020 | O31: 45599 | P31: 12917077 | Q31: 020450 | R31: USD | S31: BJV-518 | T31: CIVIC IVTEC P/T | U31: 2017 | V31: 06-NOV-2020 | W31: 11-NOV-2020 | X31: 11-Nov-2025 | Y31: POUKHI300060091 | Z31: 5 | AA31: ITFT | AB31: 3482/11/2020/ITFM | AC31: 04-NOV-2020 | AD31: 2% | AE31: 2538750 | AF31: 50775 | AJ31: KHI/HO/D/MO/PC COMP/C/102086/45/11/2024 | AK31: 50775 | AM31: =AF31-AK31 -> 0 | AN31: REN
A32: 31 | B32: ACTIVE | C32: 997AAD1202680015 | D32: T-PAK | E32: AFTAB AHMAD | F32: Lahore | G32: 35404-1596350-9 | H32: 03216460886 | I32: 03216460886 | J32: 03216460886 | K32: 50-U USMAN BLOCK NEAR TEDDI GALI NE W PAKISTAN CLOTH MARKET LAHORE | L32: 1851500 | M32: 2645000 | N32: DIB/T/BT/29430/LHR/1120 | O32: 45599 | P32: 7541647 | Q32: 264797 | R32: NEW | T32: CITY I-VTEC P/T | U32: 2020 | V32: 24-SEP-2020 | W32: 11-NOV-2020 | X32: 11-Nov-2025 | Y32: POALHR300057517 | Z32: 5 | AA32: CTRK | AB32: TDIDIB0028733 | AC32: 04-NOV-2020 | AD32: 2% | AE32: 1983750 | AF32: 39675 | AJ32: KHI/HO/D/MO/PC COMP/C/102086/47/11/2024 | AK32: 39675 | AM32: =AF32-AK32 -> 0 | AN32: REN
A33: 32 | B33: ACTIVE | C33: 9976AP1213090067 | D33: T-PAK | E33: RASHID MUNIR | F33: Faisalabad | G33: 33100-3524195-3 | H33: 041-8728868 | I33: 0300-9664972 0300-7632840 | J33: 041-2659191 | K33: H NO P-64 BLOCK-A PEOPLES COLONY # 2 NR PAK ELECTRIC STORE FAISALABAD | L33: 1715000 | M33: 2450000 | N33: DIB/T/34285/LHR/1121 | O33: 45599 | P33: L15A79789003 | Q33: R219402 | R33: USD | S33: AEW-076 | T33: HONDA CITY I-VTEC | U33: 2018 | V33: 05-NOV-2021 | W33: 11-NOV-2021 | X33: 11-Nov-2026 | Y33: OLUFSD300078032 | Z33: 5 | AA33: ITECL | AB33: 5578/11/2021 | AC33: 04-NOV-2021 | AD33: 2% | AE33: 1960000 | AF33: 39200 | AJ33: KHI/HO/D/MO/PC COMP/C/102086/48/11/2024 | AK33: 39200 | AM33: =AF33-AK33 -> 0 | AN33: REN
A34: 33 | B34: ACTIVE | C34: 9976AD1211200072 | D34: T-PAK | E34: ABDUL REHMAN | F34: Multan | G34: 36302-1281975-1 | H34: 03059638486 | I34: 03059638486 | J34: 03059638486 | K34: STREET NO 2 BOSAN ROAD AL QADIR STR EET MOHALLAH GHAFARIA CHUNGI NO 6 MULTAN PK | L34: 1847300 | M34: 2639000 | N34: 2021/11/CLFTTPCDP01216 | O34: 45599 | P34: CAD517751 | Q34: 1003750 | R34: NEW | T34: CHANGAN ALSVIN | U34: 2021 | V34: 30-APR-2021 | W34: 03-DEC-2021 | X34: 03-Dec-2026 | Y34: OLAMUX300068556 | Z34: 5 | AA34: ITFT | AB34: 5579/11/2021/ITFM | AC34: 05-NOV-2021 | AD34: 2% | AE34: 2243150 | AF34: 44863 | AJ34: KHI/HO/D/MO/PC COMP/C/102086/49/11/2024 | AK34: 44863 | AM34: =AF34-AK34 -> 0 | AN34: REN
A35: 34 | B35: ACTIVE | C35: 997AAD1202120020 | D35: T-PAK | E35: MUHAMMAD MUNEEB | F35: Gujranwala | G35: 34101-2584569-3 | H35: 03218112232 | I35: 03218112232 | J35: 0553844551 | K35: H# C 1 -576 WAPDA TOWM GUJRANWALA PK | L35: 2699500 | M35: 5399000 | N35: 2524/02150/00188/11/2020 | O35: 45599 | P35: G4NALH324032 | Q35: NNAQL51AZKP505918 | R35: NEW | T35: SPORTAGE AWD | U35: 2020 | V35: 30-JUL-2020 | W35: 27-NOV-2020 | X35: 27-Nov-2025 | Y35: POAGWL300056055 | Z35: 5 | AD35: 2% | AE35: 4049250 | AF35: 80985 | AJ35: KHI/HO/D/MO/PC COMP/C/102086/50/11/2024 | AK35: 80985 | AM35: =AF35-AK35 -> 0 | AN35: REN
A36: 35 | B36: ACTIVE | C36: 997AAD2202120012 | D36: T-PAK | E36: SANIA QAMAR | F36: Hyderabad | G36: 41304-8992077-0 | I36: 03338181234 | K36: HOUSE NO C/D-293 MOHALLA QAMAR HOUSE UNIT NO 06 LATIFABAD HYDERABAD PAKISTAN | L36: 2699500 | M36: 5399000 | N36: 2524/02150/00189/11/2020 | O36: 45599 | P36: 327106 | Q36: 506258 | R36: NEW | T36: KIA SPORTAGE AWD | U36: 2020 | V36: 30-JUL-2020 | W36: 03-DEC-2020 | X36: 03-Dec-2025 | Y36: POAHYD300056139 | Z36: 5 | AD36: 2% | AE36: 4049250 | AF36: 80985 | AJ36: KHI/HO/D/MO/PC COMP/C/102086/51/11/2024 | AK36: 80985 | AM36: =AF36-AK36 -> 0 | AN36: REN
A37: 36 | B37: ACTIVE | C37: 9976AP1213090072 | D37: T-PAK | E37: WAJEEHA YASMIN | F37: Lahore | G37: 35202-7676878-8 | H37: 03434678887 | I37: 03434678887 | J37: 03434678887 | K37: 49-E MAIN MOLANA SHAUKAT ALI ROAD K KT BUILDING MAZANINE FLOOR LAHORE | L37: 2416500 | M37: 5370000 | N37: DIB/T/34284/LHR/1121 | O37: 45599 | P37: G4NALH313952 | Q37: NNAQL51AZKP503950 | R37: USD | S37: AAC-234 | T37: SPORTAGE AWD | U37: 2020 | V37: 05-NOV-2021 | W37: 11-NOV-2021 | X37: 11-Nov-2026 | Y37: OLULHR300078002 | Z37: 5 | AA37: CTRK | AB37: TDIDIB0029794 | AC37: 04-NOV-2021 | AD37: 2% | AE37: 4296000 | AF37: 85920 | AJ37: KHI/HO/D/MO/PC COMP/C/102086/52/11/2024 | AK37: 85920 | AM37: =AF37-AK37 -> 0 | AN37: REN
A38: 37 | B38: ACTIVE | C38: 997AAD1203020044 | D38: T-PAK | E38: SULTAN MUHAMMAD KAIGOHAR KIANI | F38: Islamabad | G38: 61101-3717511-7 | H38: 03335524253 | J38: 0519220383 | K38: H # 14 ST # 3 ROAD-L BLOCK-E NAVAL ANCHORAGE ISLAMABAD PK | L38: 2986125 | M38: 3981500 | N38: 2524/02150/00187/11/2020 | O38: 45599 | P38: 16914508 | Q38: LR066375 | R38: NEW | T38: CIVIC VTI ORIEL P/T | U38: 2020 | V38: 28-OCT-2020 | W38: 21-NOV-2020 | X38: 21-Nov-2027 | Y38: POAISD300059175 | Z38: 7 | AA38: ITMM | AB38: 3480/11/2020/ITMM | AC38: 04-NOV-2020 | AD38: 2% | AE38: 2986125 | AF38: 59723 | AJ38: KHI/HO/D/MO/PC COMP/C/102086/53/11/2024 | AK38: 59723 | AM38: =AF38-AK38 -> 0 | AN38: REN
A39: 38 | B39: ACTIVE | C39: 997AAD1202050021 | D39: T-PAK | E39: MUHAMMAD ARSHAD | F39: Lahore | G39: 35202-9453292-9 | H39: 03219472731 | I39: 03219472731 | J39: 04235219011 | K39: 29-M , INTERNATIONAL MARKET MODEL T OWN (EXT) LAHORE | L39: 3527550 | M39: 5427000 | N39: 53157/00006/11/2020 | O39: 45599 | P39: 325988 | Q39: 506312 | R39: NEW | T39: KIA SPORAGE AWD | U39: 2020 | V39: 23-JUL-2020 | W39: 11-NOV-2020 | X39: 11-Nov-2025 | Y39: POALHR300055693 | Z39: 5 | AD39: 1.5% | AE39: 4070250 | AF39: 61054 | AJ39: KHI/HO/D/MO/PC COMP/C/102086/54/11/2024 | AK39: 61054 | AM39: =AF39-AK39 -> 0 | AN39: REN
A40: 39 | B40: ACTIVE | C40: 997APD2203100001 | D40: T-PAK | E40: SARDAR HASAN RAZA | F40: Islamabad | G40: 13101-4387845-3 | H40: 03018422202 | J40: 0519245702 | K40: H # 273 ST # 148/149 SECTOR # D-12/ 4 ISLAMABAD PK | L40: 3919300 | M40: 5599000 | N40: 53157/00008/11/2020 | O40: 45599 | P40: 576961 | Q40: 200411 | R40: NEW | T40: TUCSON AWD | U40: 2020 | V40: 05-NOV-2020 | W40: 11-NOV-2020 | X40: 11-Nov-2025 | Y40: PODISD300060131 | Z40: 5 | AA40: CTRK | AB40: DIB0029001 | AC40: 05-NOV-2020 | AD40: 1.5% | AE40: 4199250 | AF40: 62989 | AJ40: KHI/HO/D/MO/PC COMP/C/102086/55/11/2024 | AK40: 62989 | AM40: =AF40-AK40 -> 0 | AN40: REN
...

Sheet working
A1: POLICY NO. | B1: Assorted_code | D1: Premium | E1: 30Dec240042
A2: KHI/HO/D/MO/PC COMP/C/102086/2/11/2024 | B2: =VLOOKUP(A2,policy!B:C,2,0) -> 070000170565 | C2: 21360 | D2: =ROUND(C2,0) -> 21360 | E2: 30Dec240042 | F2: ="insert into ins_premium_det (premium_rcv_code,assorted_code, rec_amount,premium_rcv_detail_code,remaining_amt, payrec, mode_code,coinsurance_code,class_cd,it_remarks) values" -> insert into ins_premium_det (premium_rcv_code,assorted_code, rec_amount,premium_rcv_detail_code,remaining_amt, payrec, mode_code,coinsurance_code,class_cd,it_remarks) values | G2: ="('"&E2&"','"&B2&"','"&D2&"',(select max(to_number(i.premium_rcv_detail_code))+1 from ins_premium_det i),'"&D2&"','"&D2&"','02', '11000003','00','Request by Mr. Saqib Saleem 31-Dec-2024 Active');" -> ('30Dec240042','070000170565','21360',(select max(to_number(i.premium_rcv_detail_code))+1 from ins_premium_det i),'21360','21360','02', '11000003','00','Request by Mr. Saqib Saleem 31-Dec-2024 Active'); | H2: =F2&G2 -> insert into ins_premium_det (premium_rcv_code,assorted_code, rec_amount,premium_rcv_detail_code,remaining_amt, payrec, mode_code,coinsurance_code,class_cd,it_remarks) values('30Dec240042','070000170565','21360',(select max(to_number(i.premium_rcv_detail_code))+1 from ins_premium_det i),'21360','21360','02', '11000003','00','Request by Mr. Saqib Saleem 31-Dec-2024 Active');
A3: KHI/HO/D/MO/PC COMP/C/102086/3/11/2024 | B3: =VLOOKUP(A3,policy!B:C,2,0) -> 070000170566 | C3: 29280 | D3: =ROUND(C3,0) -> 29280 | E3: 30Dec240042 | F3: ="insert into ins_premium_det (premium_rcv_code,assorted_code, rec_amount,premium_rcv_detail_code,remaining_amt, payrec, mode_code,coinsurance_code,class_cd,it_remarks) values" -> insert into ins_premium_det (premium_rcv_code,assorted_code, rec_amount,premium_rcv_detail_code,remaining_amt, payrec, mode_code,coinsurance_code,class_cd,it_remarks) values | G3: ="('"&E3&"','"&B3&"','"&D3&"',(select max(to_number(i.premium_rcv_detail_code))+1 from ins_premium_det i),'"&D3&"','"&D3&"','02', '11000003','00','Request by Mr. Saqib Saleem 31-Dec-2024 Active');" -> ('30Dec240042','070000170566','29280',(select max(to_number(i.premium_rcv_detail_code))+1 from ins_premium_det i),'29280','29280','02', '11000003','00','Request by Mr. Saqib Saleem 31-Dec-2024 Active'); | H3: =F3&G3 -> insert into ins_premium_det (premium_rcv_code,assorted_code, rec_amount,premium_rcv_detail_code,remaining_amt, payrec, mode_code,coinsurance_code,class_cd,it_remarks) values('30Dec240042','070000170566','29280',(select max(to_number(i.premium_rcv_detail_code))+1 from ins_premium_det i),'29280','29280','02', '11000003','00','Request by Mr. Saqib Saleem 31-Dec-2024 Active');
