Workbook

Sheet Fresh
A1: S.No. | B1: Fresh | C1: Proposal No. | D1: Renewal Month | E1: Takaful Company | F1: PMD / Cert | G1: Takaful Start Date | H1: Takaful End Date | I1: Customer Name | J1: CNIC | K1: Vehicle Make | L1: Reg. No | M1: Engine No | N1: Chassis No | O1: Proposal No. | P1: Region | Q1: Unit ID | R1: BR # | S1: Financing Date | T1: Maturity Date | U1: Asset Value | V1: Dep. % | W1: Dep. Amount | X1: Sum Cover Amount | Y1: Takaful Rate | Z1: Premium Amount | AA1: For Takaful Company Rectifications | AB1: ALBARAKA Status | AC1: For COD Status | AD1: PO No. | AE1: PO Dates | AF1: Proposal Status | AG1: Overdue Days | AH1: Policy No. | AI1: Endorsement No. | AJ1: TMS Premium | AK1: Difference Amount
A2: 1 | B2: Fresh | C2: 79961/1 | D2: 45689 | E2: SALAAM TAKAFUL LTD | F2: KHI/HO/D/MO/PC COMP/C/106977/40/02/2025 | G2: 45715 | H2: 46079 | I2: UMER TAHIR | J2: 3410151526927 | K2: TOYOTA HILUX REVO ROCCO | L2: LED-17-567 | M2: U951480 | N2: R-0962306 | O2: 79961/1 | P2: Central | Q2: 0329 | R2: 390397 | S2: 45721 | T2: 46818 | U2: 8500000 | X2: 8500000 | Y2: 1.5 | Z2: 127500 | AC2: paid | AD2: 1141072987 | AE2: 45734 | AF2: DISBURSED | AG2: 0 | AH2: KHI/HO/D/MO/PC COMP/C/106977/40/02/2025 | AJ2: 127500 | AK2: 0
A3: 2 | B3: Fresh | C3: 79962/1 | D3: 45689 | E3: SALAAM TAKAFUL LTD | F3: KHI/HO/D/MO/PC COMP/C/106977/44/02/2025 | G3: 45716 | H3: 46080 | I3: YASIR . | J3: 4220162927733 | K3: HONDA BRV I-VTEC S STD | L3: BH-3721 | M3: 13516046 | N3: R016057 | O3: 79962/1 | P3: South | Q3: 0144 | R3: 672339 | S3: 45720 | T3: 46818 | U3: 3900000 | X3: 3900000 | Y3: 1.5 | Z3: 58500 | AC3: paid | AD3: 1141072987 | AE3: 45734 | AF3: DISBURSED | AG3: 0 | AH3: KHI/HO/D/MO/PC COMP/C/106977/44/02/2025 | AJ3: 58500 | AK3: 0
A4: 3 | B4: Fresh | C4: 78527/1 | D4: 45689 | E4: SALAAM TAKAFUL LTD | F4: KHI/HO/D/MO/PC COMP/C/106977/16/02/2025 | G4: 45701 | H4: 46065 | I4: DEEBA SHAHWAR | J4: 3630203898882 | K4: KIA PICANTO 1.0L A/T | M4: 220474 | N4: 714299 | O4: 78527/1 | P4: Central | Q4: 0431 | R4: 556616 | S4: 45723 | T4: 46818 | U4: 3904000 | X4: 3904000 | Y4: 1.5 | Z4: 58560 | AC4: paid | AD4: 1141072987 | AE4: 45734 | AF4: DISBURSED | AG4: 0 | AH4: KHI/HO/D/MO/PC COMP/C/106977/16/02/2025 | AJ4: 58560 | AK4: 0
A5: 4 | B5: Fresh | C5: 79848/1 | D5: 45689 | E5: SALAAM TAKAFUL LTD | F5: KHI/HO/D/MO/PC COMP/C/106977/29/02/2025 | G5: 45708 | H5: 46072 | I5: SAKHAWAT ALI | J5: 3540353957655 | K5: HONDA CIVIC VTI ORIEL PT | L5: ADD-317 | M5: R18Z16920969 | N5: NFBFC6665MR073246 | O5: 79848/1 | P5: Central | Q5: 0423 | R5: 669764 | S5: 45723 | T5: 46451 | U5: 6200000 | X5: 6200000 | Y5: 1.5 | Z5: 93000 | AC5: paid | AD5: 1141072987 | AE5: 45734 | AF5: DISBURSED | AG5: 0 | AH5: KHI/HO/D/MO/PC COMP/C/106977/29/02/2025 | AJ5: 93000 | AK5: 0
A6: 5 | B6: Fresh | C6: 79255/1 | D6: 45689 | E6: SALAAM TAKAFUL LTD | F6: KHI/HO/D/MO/PC COMP/C/106977/32/02/2025 | G6: 45712 | H6: 46076 | I6: JAMSHAID AKRAM | J6: 3310095613267 | K6: KIA STONIC EX+ | L6: AJF-270 | M6: G4LCMS814233 | N6: NNAYB54BZMT700069 | O6: 79255/1 | P6: Central | Q6: 0423 | R6: 671743 | S6: 45722 | T6: 46818 | U6: 4500000 | X6: 4500000 | Y6: 1.5 | Z6: 67500 | AC6: paid | AD6: 1141072987 | AE6: 45734 | AF6: DISBURSED | AG6: 0 | AH6: KHI/HO/D/MO/PC COMP/C/106977/32/02/2025 | AJ6: 67500 | AK6: 0
A7: 6 | B7: Fresh | C7: 79977/1 | D7: 45689 | E7: SALAAM TAKAFUL LTD | F7: KHI/HO/D/MO/PC COMP/C/106977/35/02/2025 | G7: 45714 | H7: 46078 | I7: MUHAMMAD ARSLAN | J7: 3520229418759 | K7: HONDA BRV I-VTEC S STD | L7: AAX-528 | M7: 14802471 | N7: 19156 | O7: 79977/1 | P7: Central | Q7: 0329 | R7: 672444 | S7: 45720 | T7: 47182 | U7: 4000000 | X7: 4000000 | Y7: 1.5 | Z7: 60000 | AC7: paid | AD7: 1141072987 | AE7: 45734 | AF7: DISBURSED | AG7: 0 | AH7: KHI/HO/D/MO/PC COMP/C/106977/35/02/2025 | AJ7: 60000 | AK7: 0
A8: 7 | B8: Fresh | C8: 77958/1 | D8: 45689 | E8: SALAAM TAKAFUL LTD | F8: KHI/HO/D/MO/PC COMP/C/106977/36/02/2025 | G8: 45715 | H8: 46079 | I8: MUHAMMAD IQBAL KHAN | J8: 4240190406687 | K8: KIA PICANTO 1.0L A/T | L8: BVK-520 | M8: 133143 | N8: 708858 | O8: 77958/1 | P8: South | Q8: 0144 | R8: 87728 | S8: 45722 | T8: 47547 | U8: 3000000 | X8: 3000000 | Y8: 2 | Z8: 60000 | AC8: paid | AD8: 1141072987 | AE8: 45734 | AF8: DISBURSED | AG8: 0 | AH8: KHI/HO/D/MO/PC COMP/C/106977/36/02/2025 | AJ8: 60000 | AK8: 0
A9: 8 | B9: Fresh | C9: 79285/1 | D9: 45689 | E9: SALAAM TAKAFUL LTD | F9: KHI/HO/D/MO/PC COMP/C/106977/43/02/2025 | G9: 45715 | H9: 46079 | I9: MUHAMMAD MEHBOOB | J9: 3520126687579 | K9: HONDA CITY 1.2 LS CVT | L9: ANK-907 | M9: B1017284 | N9: R030662 | O9: 79285/1 | P9: Central | Q9: 0329 | R9: 671763 | S9: 45722 | T9: 46818 | U9: 4500000 | X9: 4500000 | Y9: 1.5 | Z9: 67500 | AC9: paid | AD9: 1141072987 | AE9: 45734 | AF9: DISBURSED | AG9: 0 | AH9: KHI/HO/D/MO/PC COMP/C/106977/43/02/2025 | AJ9: 67500 | AK9: 0
A10: 9 | B10: Fresh | C10: 76402/1 | D10: 45689 | E10: SALAAM TAKAFUL LTD | F10: KHI/HO/D/MO/PC COMP/C/106977/48/02/2025 | G10: 45716 | H10: 46080 | I10: SYED ABDUL QADIR SHAH | J10: 3230350183367 | K10: TOYOTA COROLLA ALTIS CVT | L10: ABE-835 | M10: Q346587 | N10: R7045777 | O10: 76402/1 | P10: Central | Q10: 0329 | R10: 17826 | S10: 45722 | T10: 46818 | U10: 5000000 | X10: 5000000 | Y10: 1.5 | Z10: 75000 | AC10: paid | AD10: 1141072987 | AE10: 45734 | AF10: DISBURSED | AG10: 0 | AH10: KHI/HO/D/MO/PC COMP/C/106977/48/02/2025 | AJ10: 75000 | AK10: 0
A11: 10 | B11: Fresh | C11: 79725/1 | D11: 45689 | E11: SALAAM TAKAFUL LTD | F11: KHI/HO/D/MO/PC COMP/C/106977/49/02/2025 | G11: 45716 | H11: 46080 | I11: AYAZ AHMED | J11: 4210157438373 | K11: HONDA BRV - S | L11: BK-2488 | M11: 14808316 | N11: R025001 | O11: 79725/1 | P11: South | Q11: 0144 | R11: 518649 | S11: 45721 | T11: 46818 | U11: 5200000 | X11: 5200000 | Y11: 1.5 | Z11: 78000 | AC11: paid | AD11: 1141072987 | AE11: 45734 | AF11: DISBURSED | AG11: 0 | AH11: KHI/HO/D/MO/PC COMP/C/106977/49/02/2025 | AJ11: 78000 | AK11: 0
A12: 11 | B12: Fresh | C12: 78254/1 | D12: 45689 | E12: SALAAM TAKAFUL LTD | F12: KHI/HO/D/MO/PC COMP/C/106977/50/02/2025 | G12: 45716 | H12: 46080 | I12: FARHAN ALI | J12: 3220362614579 | K12: HONDA CIVIC VTI ORIEL U.G | L12: LEE-17-6506 | M12: Z12915376 | N12: HR018753 | O12: 78254/1 | P12: Central | Q12: 0329 | R12: 668734 | S12: 45722 | T12: 46818 | U12: 4900000 | X12: 4900000 | Y12: 1.5 | Z12: 73500 | AC12: paid | AD12: 1141072987 | AE12: 45734 | AF12: DISBURSED | AG12: 0 | AH12: KHI/HO/D/MO/PC COMP/C/106977/50/02/2025 | AJ12: 73500 | AK12: 0
A13: 12 | B13: Fresh | C13: 78827/1 | D13: 45689 | E13: SALAAM TAKAFUL LTD | F13: KHI/HO/D/MO/PC COMP/C/106977/51/02/2025 | G13: 45716 | H13: 46080 | I13: RANA MUHAMMAD SHAHZAD NAVEED | J13: 3520257939209 | K13: HONDA CITY 1.2 LS CVT | M13: 1032080 | N13: SR049609 | O13: 78827/1 | P13: Central | Q13: 0329 | R13: 670380 | S13: 45720 | T13: 46818 | U13: 4719000 | X13: 4719000 | Y13: 1.5 | Z13: 70785 | AC13: paid | AD13: 1141072987 | AE13: 45734 | AF13: DISBURSED | AG13: 0 | AH13: KHI/HO/D/MO/PC COMP/C/106977/51/02/2025 | AJ13: 70785 | AK13: 0
A14: 13 | B14: Fresh | C14: 79176/1 | D14: 45689 | E14: SALAAM TAKAFUL LTD | F14: KHI/HO/D/MO/PC COMP/C/106977/52/02/2025 | G14: 45716 | H14: 46080 | I14: KHALID FALAK SHER | J14: 3520186524535 | K14: TOYOTA Yaris ATIV 1.3 (CV | M14: 72954 | N14: 7050077 | O14: 79176/1 | P14: Central | Q14: 0329 | R14: 521809 | S14: 45723 | T14: 46818 | U14: 4760000 | X14: 4760000 | Y14: 1.5 | Z14: 71400 | AC14: paid | AD14: 1141072987 | AE14: 45734 | AF14: DISBURSED | AG14: 0 | AH14: KHI/HO/D/MO/PC COMP/C/106977/52/02/2025 | AJ14: 71400 | AK14: 0
A15: 14 | B15: Fresh | C15: 79419/1 | D15: 45689 | E15: SALAAM TAKAFUL LTD | F15: KHI/HO/D/MO/PC COMP/C/106977/47/02/2025 | G15: 45716 | H15: 46080 | I15: Arqam Javed Khan | J15: 4230173268933 | K15: KIA PICANTO 1.0L A/T | L15: BTZ-489 | M15: P050848 | N15: 706341 | O15: 79419/1 | P15: South | Q15: 0144 | R15: 672318 | S15: 45722 | T15: 46818 | U15: 2590000 | X15: 2590000 | Y15: 2 | Z15: 51800 | AC15: paid | AD15: 1141072987 | AE15: 45734 | AF15: DISBURSED | AG15: 0 | AH15: KHI/HO/D/MO/PC COMP/C/106977/47/02/2025 | AJ15: 51800 | AK15: 0
A16: 15 | B16: Fresh | C16: Not found | D16: 45689 | E16: SALAAM TAKAFUL LTD | F16: KHI/HO/D/MO/PC COMP/C/106977/54/02/2025 | G16: 45716 | H16: 46080 | I16: ADIL BOOTA | J16: 3520236916405 | K16: KIA PICANTO 1.0L M/T | L16: AEL-535 | M16: 131919 | N16: KP500158 | O16: 79538/1 | P16: Central | Q16: 0329 | R16: 672459 | S16: 45720 | T16: 46818 | U16: 2500000 | X16: 2500000 | Y16: 2 | Z16: 50000 | AC16: paid | AD16: 1141072987 | AE16: 45734 | AF16: DISBURSED | AG16: 0 | AH16: KHI/HO/D/MO/PC COMP/C/106977/54/02/2025 | AJ16: 50000 | AK16: 0
A17: 16 | B17: Fresh | C17: 76968/1 | D17: 45689 | E17: SALAAM TAKAFUL LTD | F17: KHI/HO/D/MO/PC COMP/C/106977/1/02/2025 | G17: 45691 | H17: 46055 | I17: SAIMA JAHANGIR | J17: 3520216589140 | K17: HONDA CITY 1.2 LS CVT | M17: 51030946 | N17: 048317 | O17: 76968/1 | P17: Central | Q17: 0329 | R17: 664913 | S17: 45694 | T17: 46788 | U17: 4719000 | X17: 4719000 | Y17: 1.5 | Z17: 70785 | AC17: paid | AD17: 1141072987 | AE17: 45734 | AF17: DISBURSED | AG17: 0 | AH17: KHI/HO/D/MO/PC COMP/C/106977/1/02/2025 | AJ17: 70785 | AK17: 0
A18: 17 | B18: Fresh | C18: 78059/1 | D18: 45689 | E18: SALAAM TAKAFUL LTD | F18: KHI/HO/D/MO/PC COMP/C/106977/10/02/2025 | G18: 45700 | H18: 46064 | I18: RIAZ AHMED | J18: 3540350484943 | K18: SUZUKI ALTO VXR E-2 | M18: 339116 | N18: 1239100 | O18: 78059/1 | P18: Central | Q18: 0804 | R18: 668202 | S18: 45692 | T18: 47519 | U18: 2707000 | X18: 2707000 | Y18: 2 | Z18: 54140 | AC18: paid | AD18: 1141072987 | AE18: 45734 | AF18: DISBURSED | AG18: 5 | AH18: KHI/HO/D/MO/PC COMP/C/106977/10/02/2025 | AJ18: 54140 | AK18: 0
A19: 18 | B19: Fresh | C19: 78559/1 | D19: 45689 | E19: SALAAM TAKAFUL LTD | F19: KHI/HO/D/MO/PC COMP/C/106977/11/02/2025 | G19: 45700 | H19: 46064 | I19: WASEEM ABBAS | J19: 3520250540159 | K19: CHANGAN ALSVIN | M19: 523382 | N19: 1000388 | O19: 78559/1 | P19: Central | Q19: 0329 | R19: 638507 | S19: 45702 | T19: 46788 | U19: 4574000 | X19: 4574000 | Y19: 1.5 | Z19: 68610 | AC19: paid | AD19: 1141072987 | AE19: 45734 | AF19: DISBURSED | AG19: 5 | AH19: KHI/HO/D/MO/PC COMP/C/106977/11/02/2025 | AJ19: 68610 | AK19: 0
A20: 19 | B20: Fresh | C20: 78610/1 | D20: 45689 | E20: SALAAM TAKAFUL LTD | F20: KHI/HO/D/MO/PC COMP/C/106977/12/02/2025 | G20: 45700 | H20: 46064 | I20: CHAUDHRY AAMIR HUSSAIN | J20: 3720347873091 | K20: SUZUKI WAGON-R VXL E2 | L20: AXW-144 | M20: 231605 | N20: 10131603 | O20: 78610/1 | P20: Central | Q20: 0841 | R20: 668708 | S20: 45716 | T20: 46818 | U20: 2850000 | X20: 2850000 | Y20: 2 | Z20: 57000 | AC20: paid | AD20: 1141072987 | AE20: 45734 | AF20: DISBURSED | AG20: 0 | AH20: KHI/HO/D/MO/PC COMP/C/106977/12/02/2025 | AJ20: 57000 | AK20: 0
A21: 20 | B21: Fresh | C21: 78502/1 | D21: 45689 | E21: SALAAM TAKAFUL LTD | F21: KHI/HO/D/MO/PC COMP/C/106977/13/02/2025 | G21: 45700 | H21: 46064 | I21: MUHAMMAD UZAIF | J21: 4210192923245 | K21: SUZUKI ALTO VXL AGS E-2 | L21: BXT-505 | M21: 6R246629 | N21: H1146623 | O21: 78502/1 | P21: South | Q21: 0144 | R21: 669479 | S21: 45705 | T21: 47547 | U21: 2700000 | X21: 2700000 | Y21: 2 | Z21: 54000 | AC21: paid | AD21: 1141072987 | AE21: 45734 | AF21: DISBURSED | AG21: 0 | AH21: KHI/HO/D/MO/PC COMP/C/106977/13/02/2025 | AJ21: 54000 | AK21: 0
A22: 21 | B22: Fresh | C22: 78676/1 | D22: 45689 | E22: SALAAM TAKAFUL LTD | F22: KHI/HO/D/MO/PC COMP/C/106977/14/02/2025 | G22: 45700 | H22: 46064 | I22: HUSSNAIN ALI NAQVI | J22: 3520207475449 | K22: HONDA CITY 1.2 LS CVT | M22: 51031354 | N22: 48730 | O22: 78676/1 | P22: Central | Q22: 0329 | R22: 670544 | S22: 45706 | T22: 46818 | U22: 4719000 | X22: 4719000 | Y22: 1.5 | Z22: 70785 | AC22: paid | AD22: 1141072987 | AE22: 45734 | AF22: DISBURSED | AG22: 0 | AH22: KHI/HO/D/MO/PC COMP/C/106977/14/02/2025 | AJ22: 70785 | AK22: 0
A23: 22 | B23: Fresh | C23: 78757/1 | D23: 45689 | E23: SALAAM TAKAFUL LTD | F23: KHI/HO/D/MO/PC COMP/C/106977/15/02/2025 | G23: 45701 | H23: 46065 | I23: MUHAMMAD AKRAM | J23: 3310299917639 | K23: HONDA CITY ASPIRE 1.5 I- | L23: ALC-285 | M23: L15A79793112 | N23: NFBGM1264JR238250 | O23: 78757/1 | P23: Central | Q23: 0423 | R23: 670642 | S23: 45706 | T23: 46818 | U23: 3700000 | X23: 3700000 | Y23: 1.5 | Z23: 55500 | AC23: paid | AD23: 1141072987 | AE23: 45734 | AF23: DISBURSED | AG23: 0 | AH23: KHI/HO/D/MO/PC COMP/C/106977/15/02/2025 | AJ23: 55500 | AK23: 0
A24: 23 | B24: Fresh | C24: 78506/1 | D24: 45689 | E24: SALAAM TAKAFUL LTD | F24: KHI/HO/D/MO/PC COMP/C/106977/17/02/2025 | G24: 45701 | H24: 46065 | I24: SIRAJ UDDIN | J24: 4240118951749 | K24: SUZUKI ALTO VXR E-2 | L24: BYU-798 | M24: 6R272083 | N24: 6H1172071 | O24: 78506/1 | P24: South | Q24: 0144 | R24: 441080 | S24: 45705 | T24: 46818 | U24: 2600000 | X24: 2600000 | Y24: 2 | Z24: 52000 | AC24: paid | AD24: 1141072987 | AE24: 45734 | AF24: DISBURSED | AG24: 0 | AH24: KHI/HO/D/MO/PC COMP/C/106977/17/02/2025 | AJ24: 52000 | AK24: 0
A25: 24 | B25: Fresh | C25: 79628/1 | D25: 45689 | E25: SALAAM TAKAFUL LTD | F25: KHI/HO/D/MO/PC COMP/C/106977/18/02/2025 | G25: 45702 | H25: 46066 | I25: ARSHAN ISMAIL | J25: 3630260508395 | K25: SUZUKI ALTO VXR E-2 | L25: ACY-572 | M25: 153036 | N25: 1053021 | O25: 79628/1 | P25: Central | Q25: 0431 | R25: 579068 | S25: 45709 | T25: 47182 | U25: 2400000 | X25: 2400000 | Y25: 2 | Z25: 48000 | AC25: paid | AD25: 1141072987 | AE25: 45734 | AF25: DISBURSED | AG25: 0 | AH25: KHI/HO/D/MO/PC COMP/C/106977/18/02/2025 | AJ25: 48000 | AK25: 0
A26: 25 | B26: Fresh | C26: 76383/1 | D26: 45689 | E26: SALAAM TAKAFUL LTD | F26: KHI/HO/D/MO/PC COMP/C/106977/19/02/2025 | G26: 45702 | H26: 46066 | I26: RIZWAN . | J26: 4220143043563 | K26: SUZUKI Swift GLX CVT | M26: 1025765 | N26: S00208450 | O26: 76383/1 | P26: South | Q26: 0144 | R26: 662887 | S26: 45706 | T26: 46818 | U26: 4719000 | X26: 4719000 | Y26: 1.5 | Z26: 70785 | AC26: paid | AD26: 1141072987 | AE26: 45734 | AF26: DISBURSED | AG26: 0 | AH26: KHI/HO/D/MO/PC COMP/C/106977/19/02/2025 | AJ26: 70785 | AK26: 0
A27: 26 | B27: Fresh | C27: 78609/1 | D27: 45689 | E27: SALAAM TAKAFUL LTD | F27: KHI/HO/D/MO/PC COMP/C/106977/20/02/2025 | G27: 45705 | H27: 46069 | I27: HAFIZ ABDUL RAZZAQ | J27: 3310029013595 | K27: SUZUKI ALTO VXL AGS E-2 | M27: 6R338217 | N27: NF1AET306H1238244 | O27: 78609/1 | P27: Central | Q27: 0423 | R27: 669775 | S27: 45707 | T27: 47547 | U27: 3045000 | X27: 3045000 | Y27: 2 | Z27: 60900 | AC27: paid | AD27: 1141072987 | AE27: 45734 | AF27: DISBURSED | AG27: 0 | AH27: KHI/HO/D/MO/PC COMP/C/106977/20/02/2025 | AJ27: 60900 | AK27: 0
A28: 27 | B28: Fresh | C28: 78596/1 | D28: 45689 | E28: SALAAM TAKAFUL LTD | F28: KHI/HO/D/MO/PC COMP/C/106977/22/02/2025 | G28: 45705 | H28: 46069 | I28: SAIRA ALI | J28: 3520123221974 | K28: HONDA CITY I-VTEC 1.2 | L28: ANJ-811 | M28: L12B51017958 | N28: R031762 | O28: 78596/1 | P28: Central | Q28: 0329 | R28: 669655 | S28: 45706 | T28: 46818 | U28: 4000000 | X28: 4000000 | Y28: 1.5 | Z28: 60000 | AC28: paid | AD28: 1141072987 | AE28: 45734 | AF28: DISBURSED | AG28: 0 | AH28: KHI/HO/D/MO/PC COMP/C/106977/22/02/2025 | AJ28: 60000 | AK28: 0
A29: 28 | B29: Fresh | C29: 79076/1 | D29: 45689 | E29: SALAAM TAKAFUL LTD | F29: KHI/HO/D/MO/PC COMP/C/106977/23/02/2025 | G29: 45706 | H29: 46070 | I29: ABUBAKAR AZHAR | J29: 3430294983403 | K29: SUZUKI ALTO VXR E-2 | L29: AZZ-289 | M29: 238861 | N29: 1138876 | O29: 79076/1 | P29: Central | Q29: 0804 | R29: 671223 | S29: 45709 | T29: 47547 | U29: 2350000 | X29: 2350000 | Y29: 2 | Z29: 47000 | AC29: paid | AD29: 1141072987 | AE29: 45734 | AF29: DISBURSED | AG29: 0 | AH29: KHI/HO/D/MO/PC COMP/C/106977/23/02/2025 | AJ29: 47000 | AK29: 0
A30: 29 | B30: Fresh | C30: 78035/1 | D30: 45689 | E30: SALAAM TAKAFUL LTD | F30: KHI/HO/D/MO/PC COMP/C/106977/24/02/2025 | G30: 45706 | H30: 46070 | I30: MUHAMMAD GOHAR | J30: 3520116452163 | K30: SUZUKI MEHRAN VXR EURO-II | L30: LEE-17-7453 | M30: PKB689219 | N30: SB308PK01227732 | O30: 78035/1 | P30: Central | Q30: 0329 | R30: 668063 | S30: 45708 | T30: 46818 | U30: 1000000 | X30: 1000000 | Y30: 2 | Z30: 20000 | AC30: paid | AD30: 1141072987 | AE30: 45734 | AF30: DISBURSED | AG30: 0 | AH30: KHI/HO/D/MO/PC COMP/C/106977/24/02/2025 | AJ30: 20000 | AK30: 0
A31: 30 | B31: Fresh | C31: 78462/1 | D31: 45689 | E31: SALAAM TAKAFUL LTD | F31: KHI/HO/D/MO/PC COMP/C/106977/25/02/2025 | G31: 45706 | H31: 46070 | I31: MUHAMMAD MUSA SHEIKH | J31: 3520273033169 | K31: TOYOTA COROLLA GLI M/T 1. | L31: LEB-18-4462 | M31: 534337 | N31: 4160461 | O31: 78462/1 | P31: Central | Q31: 0329 | R31: 669063 | S31: 45709 | T31: 46818 | U31: 4000000 | X31: 4000000 | Y31: 1.5 | Z31: 60000 | AC31: paid | AD31: 1141072987 | AE31: 45734 | AF31: DISBURSED | AG31: 0 | AH31: KHI/HO/D/MO/PC COMP/C/106977/25/02/2025 | AJ31: 60000 | AK31: 0
A32: 31 | B32: Fresh | C32: 78983/1 | D32: 45689 | E32: SALAAM TAKAFUL LTD | F32: KHI/HO/D/MO/PC COMP/C/106977/26/02/2025 | G32: 45706 | H32: 46070 | I32: ALI RAZA | J32: 3520168402605 | K32: SUZUKI ALTO VXL AGS E-2 | M32: R340852 | N32: H1240675 | O32: 78983/1 | P32: Central | Q32: 0329 | R32: 344022 | S32: 45708 | T32: 46086 | U32: 3045000 | X32: 3045000 | Y32: 2 | Z32: 60900 | AC32: paid | AD32: 1141072987 | AE32: 45734 | AF32: DISBURSED | AG32: 0 | AH32: KHI/HO/D/MO/PC COMP/C/106977/26/02/2025 | AJ32: 60900 | AK32: 0
A33: 32 | B33: Fresh | C33: 78821/1 | D33: 45689 | E33: SALAAM TAKAFUL LTD | F33: KHI/HO/D/MO/PC COMP/C/106977/27/02/2025 | G33: 45706 | H33: 46070 | I33: USMAN ALAM | J33: 3520181809805 | K33: HONDA CITY ASPIRE CVT PT | M33: 1017478 | N33: SR049269 | O33: 78821/1 | P33: Central | Q33: 0329 | R33: 670260 | S33: 45709 | T33: 46818 | U33: 5909000 | X33: 5909000 | Y33: 1.5 | Z33: 88635 | AC33: paid | AD33: 1141072987 | AE33: 45734 | AF33: DISBURSED | AG33: 0 | AH33: KHI/HO/D/MO/PC COMP/C/106977/27/02/2025 | AJ33: 88635 | AK33: 0
A34: 33 | B34: Fresh | C34: 77780/1 | D34: 45689 | E34: SALAAM TAKAFUL LTD | F34: KHI/HO/D/MO/PC COMP/C/106977/28/02/2025 | G34: 45707 | H34: 46071 | I34: NADEEM SAJJAD | J34: 3130297437981 | K34: HONDA CITY | L34: APK-375 | M34: 79797178 | N34: 255879 | O34: 77780/1 | P34: Central | Q34: 0804 | R34: 609404 | S34: 45712 | T34: 46818 | U34: 4200000 | X34: 4200000 | Y34: 1.5 | Z34: 63000 | AC34: paid | AD34: 1141072987 | AE34: 45734 | AF34: DISBURSED | AG34: 0 | AH34: KHI/HO/D/MO/PC COMP/C/106977/28/02/2025 | AJ34: 63000 | AK34: 0
A35: 34 | B35: Fresh | C35: 78317/1 | D35: 45689 | E35: SALAAM TAKAFUL LTD | F35: KHI/HO/D/MO/PC COMP/C/106977/3/02/2025 | G35: 45692 | H35: 46056 | I35: ZAHIDA PARVEEN | J35: 3520219524034 | K35: SUZUKI ALTO VXR E-2 | L35: AGM 269 | M35: 185137 | N35: 1085118 | O35: 78317/1 | P35: Central | Q35: 0329 | R35: 668849 | S35: 45699 | T35: 47519 | U35: 2300000 | X35: 2300000 | Y35: 2 | Z35: 46000 | AC35: paid | AD35: 1141072987 | AE35: 45734 | AF35: DISBURSED | AG35: 5 | AH35: KHI/HO/D/MO/PC COMP/C/106977/3/02/2025 | AJ35: 46000 | AK35: 0
A36: 35 | B36: Fresh | C36: 78595/1 | D36: 45689 | E36: SALAAM TAKAFUL LTD | F36: KHI/HO/D/MO/PC COMP/C/106977/30/02/2025 | G36: 45709 | H36: 46073 | I36: MUHAMMAD IRFAN | J36: 3460152811367 | K36: TOYOTA COROLLA XLI 1.3 | L36: LED-19-8931 | M36: Z549145 | N36: 4174440 | O36: 78595/1 | P36: Central | Q36: 0551 | R36: 216671 | S36: 45712 | T36: 46818 | U36: 3500000 | X36: 3500000 | Y36: 1.5 | Z36: 52500 | AC36: paid | AD36: 1141072987 | AE36: 45734 | AF36: DISBURSED | AG36: 0 | AH36: KHI/HO/D/MO/PC COMP/C/106977/30/02/2025 | AJ36: 52500 | AK36: 0
A37: 36 | B37: Fresh | C37: 79768/1 | D37: 45689 | E37: SALAAM TAKAFUL LTD | F37: KHI/HO/D/MO/PC COMP/C/106977/31/02/2025 | G37: 45709 | H37: 46073 | I37: ALI IMTIAZ | J37: 3520156141573 | K37: HONDA ACCORD CL9 | L37: LEH-15-2525 | M37: 1020306 | N37: CR61010293 | O37: 79768/1 | P37: Central | Q37: 0329 | R37: 468150 | S37: 45709 | T37: 47182 | U37: 7800000 | X37: 7800000 | Y37: 1.5 | Z37: 117000 | AC37: paid | AD37: 1141072987 | AE37: 45734 | AF37: DISBURSED | AG37: 0 | AH37: KHI/HO/D/MO/PC COMP/C/106977/31/02/2025 | AJ37: 117000 | AK37: 0
A38: 37 | B38: Fresh | C38: 79260/1 | D38: 45689 | E38: SALAAM TAKAFUL LTD | F38: KHI/HO/D/MO/PC COMP/C/106977/33/02/2025 | G38: 45713 | H38: 46077 | I38: TAUQEER HAIDER | J38: 3460390555085 | K38: HONDA CITY 1.2 LS CVT | M38: 51031961 | N38: SR049488 | O38: 79260/1 | P38: Central | Q38: 0431 | R38: 671939 | S38: 45716 | T38: 46818 | U38: 4719000 | X38: 4719000 | Y38: 1.5 | Z38: 70785 | AC38: paid | AD38: 1141072987 | AE38: 45734 | AF38: DISBURSED | AG38: 0 | AH38: KHI/HO/D/MO/PC COMP/C/106977/33/02/2025 | AJ38: 70785 | AK38: 0
A39: 38 | B39: Fresh | C39: 77788/1 | D39: 45689 | E39: SALAAM TAKAFUL LTD | F39: KHI/HO/D/MO/PC COMP/C/106977/34/02/2025 | G39: 45714 | H39: 46078 | I39: MUHAMMAD SHOUZAB RIAZ | J39: 3520290358317 | K39: SUZUKI ALTO VXL AGS E-2 | L39: LE-19A-6810 | M39: 6R105107 | N39: 1005078 | O39: 77788/1 | P39: Central | Q39: 0329 | R39: 636008 | S39: 45716 | T39: 47547 | U39: 2400000 | X39: 2400000 | Y39: 2 | Z39: 48000 | AC39: paid | AD39: 1141072987 | AE39: 45734 | AF39: DISBURSED | AG39: 0 | AH39: KHI/HO/D/MO/PC COMP/C/106977/34/02/2025 | AJ39: 48000 | AK39: 0
A40: 39 | B40: Fresh | C40: 78995/1 | D40: 45689 | E40: SALAAM TAKAFUL LTD | F40: KHI/HO/D/MO/PC COMP/C/106977/37/02/2025 | G40: 45715 | H40: 46079 | I40: REHAN AZIZ | J40: 3320212040041 | K40: SUZUKI ALTO VXR | M40: 337363 | N40: 1237301 | O40: 78995/1 | P40: Central | Q40: 0329 | R40: 670913 | S40: 45716 | T40: 47547 | U40: 2894000 | X40: 2894000 | Y40: 2 | Z40: 57880 | AC40: paid | AD40: 1141072987 | AE40: 45734 | AF40: DISBURSED | AG40: 0 | AH40: KHI/HO/D/MO/PC COMP/C/106977/37/02/2025 | AJ40: 57880 | AK40: 0
...

Sheet working
A1: POLICY NO. | B1: Assorted_code | D1: Premium | E1: 26Mar250058
A2: KHI/HO/D/MO/PC COMP/C/106977/40/02/2025 | B2: =VLOOKUP(A2,policy!B:C,2,0) -> 070000177695 | C2: 127500 | D2: =ROUND(C2,0) -> 127500 | E2: 26Mar250058 | F2: ="insert into ins_premium_det (premium_rcv_code,assorted_code, rec_amount,premium_rcv_detail_code,remaining_amt, payrec, mode_code,coinsurance_code,class_cd,it_remarks) values" -> insert into ins_premium_det (premium_rcv_code,assorted_code, rec_amount,premium_rcv_detail_code,remaining_amt, payrec, mode_code,coinsurance_code,class_cd,it_remarks) values | G2: ="('"&E2&"','"&B2&"','"&D2&"',(select max(to_number(i.premium_rcv_detail_code))+1 from ins_premium_det i),'"&D2&"','"&D2&"','02', '11000003','00','Request by Mr. Saqib Saleem 26-Mar-2025 Fresh');" -> ('26Mar250058','070000177695','127500',(select max(to_number(i.premium_rcv_detail_code))+1 from ins_premium_det i),'127500','127500','02', '11000003','00','Request by Mr. Saqib Saleem 26-Mar-2025 Fresh'); | H2: =F2&G2 -> insert into ins_premium_det (premium_rcv_code,assorted_code, rec_amount,premium_rcv_detail_code,remaining_amt, payrec, mode_code,coinsurance_code,class_cd,it_remarks) values('26Mar250058','070000177695','127500',(select max(to_number(i.premium_rcv_detail_code))+1 from ins_premium_det i),'127500','127500','02', '11000003','00','Request by Mr. Saqib Saleem 26-Mar-2025 Fresh');
A3: KHI/HO/D/MO/PC COMP/C/106977/44/02/2025 | B3: =VLOOKUP(A3,policy!B:C,2,0) -> 070000177706 | C3: 58500 | D3: =ROUND(C3,0) -> 58500 | E3: 26Mar250058 | F3: ="insert into ins_premium_det (premium_rcv_code,assorted_code, rec_amount,premium_rcv_detail_code,remaining_amt, payrec, mode_code,coinsurance_code,class_cd,it_remarks) values" -> insert into ins_premium_det (premium_rcv_code,assorted_code, rec_amount,premium_rcv_detail_code,remaining_amt, payrec, mode_code,coinsurance_code,class_cd,it_remarks) values | G3: ="('"&E3&"','"&B3&"','"&D3&"',(select max(to_number(i.premium_rcv_detail_code))+1 from ins_premium_det i),'"&D3&"','"&D3&"','02', '11000003','00','Request by Mr. Saqib Saleem 26-Mar-2025 Fresh');" -> ('26Mar250058','070000177706','58500',(select max(to_number(i.premium_rcv_detail_code))+1 from ins_premium_det i),'58500','58500','02', '11000003','00','Request by Mr. Saqib Saleem 26-Mar-2025 Fresh'); | H3: =F3&G3 -> insert into ins_premium_det (premium_rcv_code,assorted_code, rec_amount,premium_rcv_detail_code,remaining_amt, payrec, mode_code,coinsurance_code,class_cd,it_remarks) values('26Mar250058','070000177706','58500',(select max(to_number(i.premium_rcv_detail_code))+1 from ins_premium_det i),'58500','58500','02', '11000003','00','Request by Mr. Saqib Saleem 26-Mar-2025 Fresh');
A4: KHI/HO/D/MO/PC COMP/C/106977/16/02/2025 | B4: =VLOOKUP(A4,policy!B:C,2,0) -> 070000176617 | C4: 58560 | D4: =ROUND(C4,0) -> 58560 | E4: 26Mar250058 | F4: ="insert into ins_premium_det (premium_rcv_code,assorted_code, rec_amount,premium_rcv_detail_code,remaining_amt, payrec, mode_code,coinsurance_code,class_cd,it_remarks) values" -> insert into ins_premium_det (premium_rcv_code,assorted_code, rec_amount,premium_rcv_detail_code,remaining_amt, payrec, mode_code,coinsurance_code,class_cd,it_remarks) values | G4: ="('"&E4&"','"&B4&"','"&D4&"',(select max(to_number(i.premium_rcv_detail_code))+1 from ins_premium_det i),'"&D4&"','"&D4&"','02', '11000003','00','Request by Mr. Saqib Saleem 26-Mar-2025 Fresh');" -> ('26Mar250058','070000176617','58560',(select max(to_number(i.premium_rcv_detail_code))+1 from ins_premium_det i),'58560','58560','02', '11000003','00','Request by Mr. Saqib Saleem 26-Mar-2025 Fresh'); | H4: =F4&G4 -> insert into ins_premium_det (premium_rcv_code,assorted_code, rec_amount,premium_rcv_detail_code,remaining_amt, payrec, mode_code,coinsurance_code,class_cd,it_remarks) values('26Mar250058','070000176617','58560',(select max(to_number(i.premium_rcv_detail_code))+1 from ins_premium_det i),'58560','58560','02', '11000003','00','Request by Mr. Saqib Saleem 26-Mar-2025 Fresh');
A5: KHI/HO/D/MO/PC COMP/C/106977/29/02/2025 | B5: =VLOOKUP(A5,policy!B:C,2,0) -> 070000177180 | C5: 93000 | D5: =ROUND(C5,0) -> 93000 | E5: 26Mar250058 | F5: ="insert into ins_premium_det (premium_rcv_code,assorted_code, rec_amount,premium_rcv_detail_code,remaining_amt, payrec, mode_code,coinsurance_code,class_cd,it_remarks) values" -> insert into ins_premium_det (premium_rcv_code,assorted_code, rec_amount,premium_rcv_detail_code,remaining_amt, payrec, mode_code,coinsurance_code,class_cd,it_remarks) values | G5: ="('"&E5&"','"&B5&"','"&D5&"',(select max(to_number(i.premium_rcv_detail_code))+1 from ins_premium_det i),'"&D5&"','"&D5&"','02', '11000003','00','Request by Mr. Saqib Saleem 26-Mar-2025 Fresh');" -> ('26Mar250058','070000177180','93000',(select max(to_number(i.premium_rcv_detail_code))+1 from ins_premium_det i),'93000','93000','02', '11000003','00','Request by Mr. Saqib Saleem 26-Mar-2025 Fresh'); | H5: =F5&G5 -> insert into ins_premium_det (premium_rcv_code,assorted_code, rec_amount,premium_rcv_detail_code,remaining_amt, payrec, mode_code,coinsurance_code,class_cd,it_remarks) values('26Mar250058','070000177180','93000',(select max(to_number(i.premium_rcv_detail_code))+1 from ins_premium_det i),'93000','93000','02', '11000003','00','Request by Mr. Saqib Saleem 26-Mar-2025 Fresh');
A6: KHI/HO/D/MO/PC COMP/C/106977/32/02/2025 | B6: =VLOOKUP(A6,policy!B:C,2,0) -> 070000177320 | C6: 67500 | D6: =ROUND(C6,0) -> 67500 | E6: 26Mar250058 | F6: ="insert into ins_premium_det (premium_rcv_code,assorted_code, rec_amount,premium_rcv_detail_code,remaining_amt, payrec, mode_code,coinsurance_code,class_cd,it_remarks) values" -> insert into ins_premium_det (premium_rcv_code,assorted_code, rec_amount,premium_rcv_detail_code,remaining_amt, payrec, mode_code,coinsurance_code,class_cd,it_remarks) values | G6: ="('"&E6&"','"&B6&"','"&D6&"',(select max(to_number(i.premium_rcv_detail_code))+1 from ins_premium_det i),'"&D6&"','"&D6&"','02', '11000003','00','Request by Mr. Saqib Saleem 26-Mar-2025 Fresh');" -> ('26Mar250058','070000177320','67500',(select max(to_number(i.premium_rcv_detail_code))+1 from ins_premium_det i),'67500','67500','02', '11000003','00','Request by Mr. Saqib Saleem 26-Mar-2025 Fresh'); | H6: =F6&G6 -> insert into ins_premium_det (premium_rcv_code,assorted_code, rec_amount,premium_rcv_detail_code,remaining_amt, payrec, mode_code,coinsurance_code,class_cd,it_remarks) values('26Mar250058','070000177320','67500',(select max(to_number(i.premium_rcv_detail_code))+1 from ins_premium_det i),'67500','67500','02', '11000003','00','Request by Mr. Saqib Saleem 26-Mar-2025 Fresh');
A7: KHI/HO/D/MO/PC COMP/C/106977/35/02/2025 | B7: =VLOOKUP(A7,policy!B:C,2,0) -> 070000177654 | C7: 60000 | D7: =ROUND(C7,0) -> 60000 | E7: 26Mar250058 | F7: ="insert into ins_premium_det (premium_rcv_code,assorted_code, rec_amount,premium_rcv_detail_code,remaining_amt, payrec, mode_code,coinsurance_code,class_cd,it_remarks) values" -> insert into ins_premium_det (premium_rcv_code,assorted_code, rec_amount,premium_rcv_detail_code,remaining_amt, payrec, mode_code,coinsurance_code,class_cd,it_remarks) values | G7: ="('"&E7&"','"&B7&"','"&D7&"',(select max(to_number(i.premium_rcv_detail_code))+1 from ins_premium_det i),'"&D7&"','"&D7&"','02', '11000003','00','Request by Mr. Saqib Saleem 26-Mar-2025 Fresh');" -> ('26Mar250058','070000177654','60000',(select max(to_number(i.premium_rcv_detail_code))+1 from ins_premium_det i),'60000','60000','02', '11000003','00','Request by Mr. Saqib Saleem 26-Mar-2025 Fresh'); | H7: =F7&G7 -> insert into ins_premium_det (premium_rcv_code,assorted_code, rec_amount,premium_rcv_detail_code,remaining_amt, payrec, mode_code,coinsurance_code,class_cd,it_remarks) values('26Mar250058','070000177654','60000',(select max(to_number(i.premium_rcv_detail_code))+1 from ins_premium_det i),'60000','60000','02', '11000003','00','Request by Mr. Saqib Saleem 26-Mar-2025 Fresh');
A8: KHI/HO/D/MO/PC COMP/C/106977/36/02/2025 | B8: =VLOOKUP(A8,policy!B:C,2,0) -> 070000177659 | C8: 60000 | D8: =ROUND(C8,0) -> 60000 | E8: 26Mar250058 | F8: ="insert into ins_premium_det (premium_rcv_code,assorted_code, rec_amount,premium_rcv_detail_code,remaining_amt, payrec, mode_code,coinsurance_code,class_cd,it_remarks) values" -> insert into ins_premium_det (premium_rcv_code,assorted_code, rec_amount,premium_rcv_detail_code,remaining_amt, payrec, mode_code,coinsurance_code,class_cd,it_remarks) values | G8: ="('"&E8&"','"&B8&"','"&D8&"',(select max(to_number(i.premium_rcv_detail_code))+1 from ins_premium_det i),'"&D8&"','"&D8&"','02', '11000003','00','Request by Mr. Saqib Saleem 26-Mar-2025 Fresh');" -> ('26Mar250058','070000177659','60000',(select max(to_number(i.premium_rcv_detail_code))+1 from ins_premium_det i),'60000','60000','02', '11000003','00','Request by Mr. Saqib Saleem 26-Mar-2025 Fresh'); | H8: =F8&G8 -> insert into ins_premium_det (premium_rcv_code,assorted_code, rec_amount,premium_rcv_detail_code,remaining_amt, payrec, mode_code,coinsurance_code,class_cd,it_remarks) values('26Mar250058','070000177659','60000',(select max(to_number(i.premium_rcv_detail_code))+1 from ins_premium_det i),'60000','60000','02', '11000003','00','Request by Mr. Saqib Saleem 26-Mar-2025 Fresh');
A9: KHI/HO/D/MO/PC COMP/C/106977/43/02/2025 | B9: =VLOOKUP(A9,policy!B:C,2,0) -> 070000177703 | C9: 67500 | D9: =ROUND(C9,0) -> 67500 | E9: 26Mar250058 | F9: ="insert into ins_premium_det (premium_rcv_code,assorted_code, rec_amount,premium_rcv_detail_code,remaining_amt, payrec, mode_code,coinsurance_code,class_cd,it_remarks) values" -> insert into ins_premium_det (premium_rcv_code,assorted_code, rec_amount,premium_rcv_detail_code,remaining_amt, payrec, mode_code,coinsurance_code,class_cd,it_remarks) values | G9: ="('"&E9&"','"&B9&"','"&D9&"',(select max(to_number(i.premium_rcv_detail_code))+1 from ins_premium_det i),'"&D9&"','"&D9&"','02', '11000003','00','Request by Mr. Saqib Saleem 26-Mar-2025 Fresh');" -> ('26Mar250058','070000177703','67500',(select max(to_number(i.premium_rcv_detail_code))+1 from ins_premium_det i),'67500','67500','02', '11000003','00','Request by Mr. Saqib Saleem 26-Mar-2025 Fresh'); | H9: =F9&G9 -> insert into ins_premium_det (premium_rcv_code,assorted_code, rec_amount,premium_rcv_detail_code,remaining_amt, payrec, mode_code,coinsurance_code,class_cd,it_remarks) values('26Mar250058','070000177703','67500',(select max(to_number(i.premium_rcv_detail_code))+1 from ins_premium_det i),'67500','67500','02', '11000003','00','Request by Mr. Saqib Saleem 26-Mar-2025 Fresh');
A10: KHI/HO/D/MO/PC COMP/C/106977/48/02/2025 | B10: =VLOOKUP(A10,policy!B:C,2,0) -> 070000177713 | C10: 75000 | D10: =ROUND(C10,0) -> 75000 | E10: 26Mar250058 | F10: ="insert into ins_premium_det (premium_rcv_code,assorted_code, rec_amount,premium_rcv_detail_code,remaining_amt, payrec, mode_code,coinsurance_code,class_cd,it_remarks) values" -> insert into ins_premium_det (premium_rcv_code,assorted_code, rec_amount,premium_rcv_detail_code,remaining_amt, payrec, mode_code,coinsurance_code,class_cd,it_remarks) values | G10: ="('"&E10&"','"&B10&"','"&D10&"',(select max(to_number(i.premium_rcv_detail_code))+1 from ins_premium_det i),'"&D10&"','"&D10&"','02', '11000003','00','Request by Mr. Saqib Saleem 26-Mar-2025 Fresh');" -> ('26Mar250058','070000177713','75000',(select max(to_number(i.premium_rcv_detail_code))+1 from ins_premium_det i),'75000','75000','02', '11000003','00','Request by Mr. Saqib Saleem 26-Mar-2025 Fresh'); | H10: =F10&G10 -> insert into ins_premium_det (premium_rcv_code,assorted_code, rec_amount,premium_rcv_detail_code,remaining_amt, payrec, mode_code,coinsurance_code,class_cd,it_remarks) values('26Mar250058','070000177713','75000',(select max(to_number(i.premium_rcv_detail_code))+1 from ins_premium_det i),'75000','75000','02', '11000003','00','Request by Mr. Saqib Saleem 26-Mar-2025 Fresh');
A11: KHI/HO/D/MO/PC COMP/C/106977/49/02/2025 | B11: =VLOOKUP(A11,policy!B:C,2,0) -> 070000177715 | C11: 78000 | D11: =ROUND(C11,0) -> 78000 | E11: 26Mar250058 | F11: ="insert into ins_premium_det (premium_rcv_code,assorted_code, rec_amount,premium_rcv_detail_code,remaining_amt, payrec, mode_code,coinsurance_code,class_cd,it_remarks) values" -> insert into ins_premium_det (premium_rcv_code,assorted_code, rec_amount,premium_rcv_detail_code,remaining_amt, payrec, mode_code,coinsurance_code,class_cd,it_remarks) values | G11: ="('"&E11&"','"&B11&"','"&D11&"',(select max(to_number(i.premium_rcv_detail_code))+1 from ins_premium_det i),'"&D11&"','"&D11&"','02', '11000003','00','Request by Mr. Saqib Saleem 26-Mar-2025 Fresh');" -> ('26Mar250058','070000177715','78000',(select max(to_number(i.premium_rcv_detail_code))+1 from ins_premium_det i),'78000','78000','02', '11000003','00','Request by Mr. Saqib Saleem 26-Mar-2025 Fresh'); | H11: =F11&G11 -> insert into ins_premium_det (premium_rcv_code,assorted_code, rec_amount,premium_rcv_detail_code,remaining_amt, payrec, mode_code,coinsurance_code,class_cd,it_remarks) values('26Mar250058','070000177715','78000',(select max(to_number(i.premium_rcv_detail_code))+1 from ins_premium_det i),'78000','78000','02', '11000003','00','Request by Mr. Saqib Saleem 26-Mar-2025 Fresh');
A12: KHI/HO/D/MO/PC COMP/C/106977/50/02/2025 | B12: =VLOOKUP(A12,policy!B:C,2,0) -> 070000177736 | C12: 73500 | D12: =ROUND(C12,0) -> 73500 | E12: 26Mar250058 | F12: ="insert into ins_premium_det (premium_rcv_code,assorted_code, rec_amount,premium_rcv_detail_code,remaining_amt, payrec, mode_code,coinsurance_code,class_cd,it_remarks) values" -> insert into ins_premium_det (premium_rcv_code,assorted_code, rec_amount,premium_rcv_detail_code,remaining_amt, payrec, mode_code,coinsurance_code,class_cd,it_remarks) values | G12: ="('"&E12&"','"&B12&"','"&D12&"',(select max(to_number(i.premium_rcv_detail_code))+1 from ins_premium_det i),'"&D12&"','"&D12&"','02', '11000003','00','Request by Mr. Saqib Saleem 26-Mar-2025 Fresh');" -> ('26Mar250058','070000177736','73500',(select max(to_number(i.premium_rcv_detail_code))+1 from ins_premium_det i),'73500','73500','02', '11000003','00','Request by Mr. Saqib Saleem 26-Mar-2025 Fresh'); | H12: =F12&G12 -> insert into ins_premium_det (premium_rcv_code,assorted_code, rec_amount,premium_rcv_detail_code,remaining_amt, payrec, mode_code,coinsurance_code,class_cd,it_remarks) values('26Mar250058','070000177736','73500',(select max(to_number(i.premium_rcv_detail_code))+1 from ins_premium_det i),'73500','73500','02', '11000003','00','Request by Mr. Saqib Saleem 26-Mar-2025 Fresh');
A13: KHI/HO/D/MO/PC COMP/C/106977/51/02/2025 | B13: =VLOOKUP(A13,policy!B:C,2,0) -> 070000177739 | C13: 70785 | D13: =ROUND(C13,0) -> 70785 | E13: 26Mar250058 | F13: ="insert into ins_premium_det (premium_rcv_code,assorted_code, rec_amount,premium_rcv_detail_code,remaining_amt, payrec, mode_code,coinsurance_code,class_cd,it_remarks) values" -> insert into ins_premium_det (premium_rcv_code,assorted_code, rec_amount,premium_rcv_detail_code,remaining_amt, payrec, mode_code,coinsurance_code,class_cd,it_remarks) values | G13: ="('"&E13&"','"&B13&"','"&D13&"',(select max(to_number(i.premium_rcv_detail_code))+1 from ins_premium_det i),'"&D13&"','"&D13&"','02', '11000003','00','Request by Mr. Saqib Saleem 26-Mar-2025 Fresh');" -> ('26Mar250058','070000177739','70785',(select max(to_number(i.premium_rcv_detail_code))+1 from ins_premium_det i),'70785','70785','02', '11000003','00','Request by Mr. Saqib Saleem 26-Mar-2025 Fresh'); | H13: =F13&G13 -> insert into ins_premium_det (premium_rcv_code,assorted_code, rec_amount,premium_rcv_detail_code,remaining_amt, payrec, mode_code,coinsurance_code,class_cd,it_remarks) values('26Mar250058','070000177739','70785',(select max(to_number(i.premium_rcv_detail_code))+1 from ins_premium_det i),'70785','70785','02', '11000003','00','Request by Mr. Saqib Saleem 26-Mar-2025 Fresh');
... A77: KHI/HO/D/MO/PC COMP/C/105285/41/01/2025 | B77: =VLOOKUP(A77,policy!B:C,2,0) -> 070000175570 | C77: 54140 | D77: =ROUND(C77,0) -> 54140 | E77: 26Mar250058 | F77: ="insert into ins_premium_det (premium_rcv_code,assorted_code, rec_amount,premium_rcv_detail_code,remaining_amt, payrec, mode_code,coinsurance_code,class_cd,it_remarks) values" -> insert into ins_premium_det (premium_rcv_code,assorted_code, rec_amount,premium_rcv_detail_code,remaining_amt, payrec, mode_code,coinsurance_code,class_cd,it_remarks) values | G77: ="('"&E77&"','"&B77&"','"&D77&"',(select max(to_number(i.premium_rcv_detail_code))+1 from ins_premium_det i),'"&D77&"','"&D77&"','02', '11000003','00','Request by Mr. Saqib Saleem 26-Mar-2025 Fresh');" -> ('26Mar250058','070000175570','54140',(select max(to_number(i.premium_rcv_detail_code))+1 from ins_premium_det i),'54140','54140','02', '11000003','00','Request by Mr. Saqib Saleem 26-Mar-2025 Fresh'); | H77: =F77&G77 -> insert into ins_premium_det (premium_rcv_code,assorted_code, rec_amount,premium_rcv_detail_code,remaining_amt, payrec, mode_code,coinsurance_code,class_cd,it_remarks) values('26Mar250058','070000175570','54140',(select max(to_number(i.premium_rcv_detail_code))+1 from ins_premium_det i),'54140','54140','02', '11000003','00','Request by Mr. Saqib Saleem 26-Mar-2025 Fresh');
C79: =SUM(C2:C77) -> 4737068

Sheet Sheet2
A1: KHI/HO/D/MO/PC COMP/C/106977/40/02/2025 | B1: -02-2025 | H1: 106977 | I1: 00040 | J1: ="ia.assorted_string like '%"&H1&"-"&I1&B1&"%' or" -> ia.assorted_string like '%106977-00040-02-2025%' or
A2: KHI/HO/D/MO/PC COMP/C/106977/44/02/2025 | B2: -02-2025 | H2: 106977 | I2: 00044 | J2: ="ia.assorted_string like '%"&H2&"-"&I2&B2&"%' or" -> ia.assorted_string like '%106977-00044-02-2025%' or
A3: KHI/HO/D/MO/PC COMP/C/106977/16/02/2025 | B3: -02-2025 | H3: 106977 | I3: 00016 | J3: ="ia.assorted_string like '%"&H3&"-"&I3&B3&"%' or" -> ia.assorted_string like '%106977-00016-02-2025%' or
A4: KHI/HO/D/MO/PC COMP/C/106977/29/02/2025 | B4: -02-2025 | H4: 106977 | I4: 00029 | J4: ="ia.assorted_string like '%"&H4&"-"&I4&B4&"%' or" -> ia.assorted_string like '%106977-00029-02-2025%' or
A5: KHI/HO/D/MO/PC COMP/C/106977/32/02/2025 | B5: -02-2025 | H5: 106977 | I5: 00032 | J5: ="ia.assorted_string like '%"&H5&"-"&I5&B5&"%' or" -> ia.assorted_string like '%106977-00032-02-2025%' or
A6: KHI/HO/D/MO/PC COMP/C/106977/35/02/2025 | B6: -02-2025 | H6: 106977 | I6: 00035 | J6: ="ia.assorted_string like '%"&H6&"-"&I6&B6&"%' or" -> ia.assorted_string like '%106977-00035-02-2025%' or
A7: KHI/HO/D/MO/PC COMP/C/106977/36/02/2025 | B7: -02-2025 | H7: 106977 | I7: 00036 | J7: ="ia.assorted_string like '%"&H7&"-"&I7&B7&"%' or" -> ia.assorted_string like '%106977-00036-02-2025%' or
A8: KHI/HO/D/MO/PC COMP/C/106977/43/02/2025 | B8: -02-2025 | H8: 106977 | I8: 00043 | J8: ="ia.assorted_string like '%"&H8&"-"&I8&B8&"%' or" -> ia.assorted_string like '%106977-00043-02-2025%' or
A9: KHI/HO/D/MO/PC COMP/C/106977/48/02/2025 | B9: -02-2025 | H9: 106977 | I9: 00048 | J9: ="ia.assorted_string like '%"&H9&"-"&I9&B9&"%' or" -> ia.assorted_string like '%106977-00048-02-2025%' or
A10: KHI/HO/D/MO/PC COMP/C/106977/49/02/2025 | B10: -02-2025 | H10: 106977 | I10: 00049 | J10: ="ia.assorted_string like '%"&H10&"-"&I10&B10&"%' or" -> ia.assorted_string like '%106977-00049-02-2025%' or
A11: KHI/HO/D/MO/PC COMP/C/106977/50/02/2025 | B11: -02-2025 | H11: 106977 | I11: 00050 | J11: ="ia.assorted_string like '%"&H11&"-"&I11&B11&"%' or" -> ia.assorted_string like '%106977-00050-02-2025%' or
A12: KHI/HO/D/MO/PC COMP/C/106977/51/02/2025 | B12: -02-2025 | H12: 106977 | I12: 00051 | J12: ="ia.assorted_string like '%"&H12&"-"&I12&B12&"%' or" -> ia.assorted_string like '%106977-00051-02-2025%' or
... A76: KHI/HO/D/MO/PC COMP/C/105285/41/01/2025 | B76: -01-2025 | H76: 105285 | I76: 00041 | J76: ="ia.assorted_string like '%"&H76&"-"&I76&B76&"%' or" -> ia.assorted_string like '%105285-00041-01-2025%' or

Sheet policy
B1: FUNC_ASSORTED_STRING(IA.ASSORTED_CODE) | C1: ASSORTED_CODE
A2: 1 | B2: KHI/HO/D/MO/PC COMP/C/103201/54/12/2024 | C2: 070000173594
A3: 2 | B3: KHI/HO/D/MO/PC COMP/C/106977/40/02/2025 | C3: 070000177695
A4: 3 | B4: KHI/HO/D/MO/PC COMP/C/106977/41/02/2025 | C4: 070000177696
A5: 4 | B5: KHI/HO/D/MO/PC COMP/C/106977/43/02/2025 | C5: 070000177703
A6: 5 | B6: KHI/HO/D/MO/PC COMP/C/103201/46/12/2024 | C6: 070000173573
A7: 6 | B7: KHI/HO/D/MO/PC COMP/C/103201/47/12/2024 | C7: 070000173575
A8: 7 | B8: KHI/HO/D/MO/PC COMP/C/103201/52/12/2024 | C8: 070000173587
A9: 8 | B9: KHI/HO/D/MO/PC COMP/C/105285/41/01/2025 | C9: 070000175570
A10: 9 | B10: KHI/HO/D/MO/PC COMP/C/106977/13/02/2025 | C10: 070000176609
A11: 10 | B11: KHI/HO/D/MO/PC COMP/C/103201/48/12/2024 | C11: 070000173580
A12: 11 | B12: KHI/HO/D/MO/PC COMP/C/106977/12/02/2025 | C12: 070000176608
A13: 12 | B13: KHI/HO/D/MO/PC COMP/C/106977/36/02/2025 | C13: 070000177659
... A77: 76 | B77: KHI/HO/D/MO/PC COMP/C/106977/42/02/2025 | C77: 070000177701

Sheet Renewal
A1: S.No. | B1: Renewal | C1: Proposal No. | D1: Renewal Month | E1: Takaful Company | F1: PMD / Cert | G1: Old Takaful Start Date | H1: Old Takaful End Date | I1: Customer Name | J1: CNIC | K1: Vehicle Make | L1: Reg. No | M1: Engine No | N1: Chassis No | O1: Proposal No. | P1: Region | Q1: Unit ID | R1: BR # | S1: Financing Date | T1: Maturity Date | U1: Asset Value | V1: Dep. % | W1: Dep. Amount | X1: Sum Cover Amount | Y1: Takaful Rate | Z1: Premium Amount | AA1: For Takaful Company Rectifications | AB1: ALBARAKA Status | AC1: For COD Status | AD1: PO No. | AE1: PO Dates | AF1: Proposal Status | AG1: Overdue Days | AH1: Policy No. | AI1: Endorsement No. | AJ1: TMS Premium | AK1: Difference Amount
A2: 1 | B2: Renewal | C2: 69653/1 | D2: 45689 | E2: SALAAM TAKAFUL LTD | F2: KHI/HO/D/MO/PC COMP/C/107407/1/02/2025 | G2: 45694 | H2: 46058 | I2: MUHAMMAD ZEESHAN BHATTI | J2: 3540115636023 | K2: SUZUKI ALTO VXR E-2 | L2: AQZ-705 | M2: 293398 | N2: 1193364 | O2: 69653/1 | P2: Central | Q2: 0329 | R2: 525730 | S2: 45331 | T2: 47154 | U2: 2612000 | V2: 10 | W2: 261200 | X2: 2350800 | Y2: 2 | Z2: 47016 | AC2: paid | AD2: 1141073002 | AE2: 45735 | AF2: DISBURSED | AG2: 0 | AH2: KHI/HO/D/MO/PC COMP/C/107407/1/02/2025 | AJ2: =VLOOKUP(AH2,[1]Sheet1!$B$2:$AA$595,26,0) -> 47016 | AK2: =AJ2-Z2 -> 0
A3: 2 | B3: Renewal | C3: 68798/1 | D3: 45689 | E3: SALAAM TAKAFUL LTD | F3: KHI/HO/D/MO/PC COMP/C/107407/10/02/2025 | G3: 45709 | H3: 46073 | I3: IRFAN AAMIR | J3: 9140003638877 | K3: CHANGAN ALSVIN | L3: AQW-198 | M3: 537247 | N3: 1011419 | O3: 68798/1 | P3: Central | Q3: 0329 | R3: 302217 | S3: 45344 | T3: 46451 | U3: 4549000 | V3: 10 | W3: 454900 | X3: 4094100 | Y3: 1.5 | Z3: 61411.5 | AC3: paid | AD3: 1141073002 | AE3: 45735 | AF3: DISBURSED | AG3: 0 | AH3: KHI/HO/D/MO/PC COMP/C/107407/10/02/2025 | AJ3: =VLOOKUP(AH3,[1]Sheet1!$B$2:$AA$595,26,0) -> 61412 | AK3: =AJ3-Z3 -> 0.5
A4: 3 | B4: Renewal | C4: 54878/1 | D4: 45689 | E4: SALAAM TAKAFUL LTD | F4: KHI/HO/D/MO/PC COMP/C/107407/100/02/2025 | G4: 45704 | H4: 46068 | I4: MUHAMMAD TALHA ADEEL | J4: 3520221801947 | K4: SUZUKI WAGON-R VXR | L4: AJK-441 | M4: 212734 | N4: 1112701 | O4: 54878/1 | P4: Central | Q4: 0329 | R4: 565360 | S4: 44613 | T4: 46451 | U4: 1546000 | V4: 20 | W4: 309200 | X4: 1236800 | Y4: 2.5 | Z4: 30920 | AC4: paid | AD4: 1141073002 | AE4: 45735 | AF4: DISBURSED | AG4: 0 | AH4: KHI/HO/D/MO/PC COMP/C/107407/100/02/2025 | AJ4: =VLOOKUP(AH4,[1]Sheet1!$B$2:$AA$595,26,0) -> 30920 | AK4: =AJ4-Z4 -> 0
A5: 4 | B5: Renewal | C5: 54839/1 | D5: 45689 | E5: SALAAM TAKAFUL LTD | F5: KHI/HO/D/MO/PC COMP/C/107407/101/02/2025 | G5: 45704 | H5: 46068 | I5: MUHAMMAD ZEESHAN BHATTI | J5: 3540115636023 | K5: SUZUKI WAGON-R VXL E2 | L5: AJU-717 | M5: 229032 | N5: 10129024 | O5: 54839/1 | P5: Central | Q5: 0329 | R5: 525730 | S5: 44610 | T5: 46451 | U5: 1975000 | V5: 20 | W5: 395000 | X5: 1580000 | Y5: 1.75 | Z5: 27650 | AC5: paid | AD5: 1141073002 | AE5: 45735 | AF5: DISBURSED | AG5: 0 | AH5: KHI/HO/D/MO/PC COMP/C/107407/101/02/2025 | AJ5: =VLOOKUP(AH5,[1]Sheet1!$B$2:$AA$595,26,0) -> 27650 | AK5: =AJ5-Z5 -> 0
A6: 5 | B6: Renewal | C6: 54656/1 | D6: 45689 | E6: SALAAM TAKAFUL LTD | F6: KHI/HO/D/MO/PC COMP/C/107407/102/02/2025 | G6: 45704 | H6: 46068 | I6: ZARMEEN ZAHRA | J6: 3610230488400 | K6: SUZUKI ALTO VXR E-2 | L6: AGE-752 | M6: 212748 | N6: 1112720 | O6: 54656/1 | P6: Central | Q6: 0431 | R6: 561724 | S6: 44613 | T6: 46451 | U6: 1546000 | V6: 20 | W6: 309200 | X6: 1236800 | Y6: 1.75 | Z6: 21644 | AC6: paid | AD6: 1141073002 | AE6: 45735 | AF6: DISBURSED | AG6: 0 | AH6: KHI/HO/D/MO/PC COMP/C/107407/102/02/2025 | AJ6: =VLOOKUP(AH6,[1]Sheet1!$B$2:$AA$595,26,0) -> 21644 | AK6: =AJ6-Z6 -> 0
A7: 6 | B7: Renewal | C7: 54800/1 | D7: 45689 | E7: SALAAM TAKAFUL LTD | F7: KHI/HO/D/MO/PC COMP/C/107407/104/02/2025 | G7: 45704 | H7: 46068 | I7: UMER SABIR | J7: 3740505907221 | K7: SUZUKI CULTUS VXR | L7: ARU-623 | M7: 159983 | N7: 10060006 | O7: 54800/1 | P7: North | Q7: 0804 | R7: 566881 | S7: 44610 | T7: 46451 | U7: 1750000 | V7: 20 | W7: 350000 | X7: 1400000 | Y7: 1.75 | Z7: 24500 | AC7: paid | AD7: 1141073002 | AE7: 45735 | AF7: DISBURSED | AG7: 0 | AH7: KHI/HO/D/MO/PC COMP/C/107407/104/02/2025 | AJ7: =VLOOKUP(AH7,[1]Sheet1!$B$2:$AA$595,26,0) -> 24500 | AK7: =AJ7-Z7 -> 0
A8: 7 | B8: Renewal | C8: 54585/1 | D8: 45689 | E8: SALAAM TAKAFUL LTD | F8: KHI/HO/D/MO/PC COMP/C/107407/105/02/2025 | G8: 45691 | H8: 46055 | I8: MUHAMMAD MUSHTAQ | J8: 3520225860949 | K8: SUZUKI CULTUS VXL EURO II | L8: AHZ-924 | M8: 192131 | N8: 10092138 | O8: 54585/1 | P8: Central | Q8: 0329 | R8: 561212 | S8: 44601 | T8: 46058 | U8: 2244000 | V8: 20 | W8: 448800 | X8: 1795200 | Y8: 1.75 | Z8: 31416 | AC8: paid | AD8: 1141073002 | AE8: 45735 | AF8: DISBURSED | AG8: 0 | AH8: KHI/HO/D/MO/PC COMP/C/107407/105/02/2025 | AJ8: =VLOOKUP(AH8,[1]Sheet1!$B$2:$AA$595,26,0) -> 31416 | AK8: =AJ8-Z8 -> 0
A9: 8 | B9: Renewal | C9: 49944/1 | D9: 45689 | E9: SALAAM TAKAFUL LTD | F9: KHI/HO/D/MO/PC COMP/C/107407/106/02/2025 | G9: 45704 | H9: 46068 | I9: MUHAMMAD RAFIQ | J9: 5630215706883 | K9: KIA SPORTAGE AWD-CW | L9: AXT-168 | M9: H324816 | N9: P515480 | O9: 49944/1 | P9: Central | Q9: 0329 | R9: 542266 | S9: 44613 | T9: 46451 | U9: 5687000 | V9: 20 | W9: 1137400 | X9: 4549600 | Y9: 1.5 | Z9: 68244 | AC9: paid | AD9: 1141073002 | AE9: 45735 | AF9: DISBURSED | AG9: 0 | AH9: KHI/HO/D/MO/PC COMP/C/107407/106/02/2025 | AJ9: =VLOOKUP(AH9,[1]Sheet1!$B$2:$AA$595,26,0) -> 68244 | AK9: =AJ9-Z9 -> 0
A10: 9 | B10: Renewal | C10: 54857/1 | D10: 45689 | E10: SALAAM TAKAFUL LTD | F10: KHI/HO/D/MO/PC COMP/C/107407/107/02/2025 | G10: 45705 | H10: 46069 | I10: ABDUL AHAD KHAN | J10: 4250139859251 | K10: SUZUKI ALTO VXL AGS E-2 | L10: BUY-382 | M10: 189441 | N10: 1089440 | O10: 54857/1 | P10: South | Q10: 0150 | R10: 563321 | S10: 44614 | T10: 46451 | U10: 1500000 | V10: 20 | W10: 300000 | X10: 1200000 | Y10: 1.75 | Z10: 21000 | AC10: paid | AD10: 1141073002 | AE10: 45735 | AF10: DISBURSED | AG10: 0 | AH10: KHI/HO/D/MO/PC COMP/C/107407/107/02/2025 | AJ10: =VLOOKUP(AH10,[1]Sheet1!$B$2:$AA$595,26,0) -> 21000 | AK10: =AJ10-Z10 -> 0
A11: 10 | B11: Renewal | C11: 54939/1 | D11: 45689 | E11: SALAAM TAKAFUL LTD | F11: KHI/HO/D/MO/PC COMP/C/107407/108/02/2025 | G11: 45704 | H11: 46068 | I11: TAHIR MAHMOOD | J11: 3520283240485 | K11: SUZUKI ALTO VXR | L11: AHY-527 | M11: 6R212217 | N11: NF1AET306H1112180 | O11: 54939/1 | P11: Central | Q11: 0329 | R11: 529629 | S11: 44620 | T11: 46451 | U11: 1546000 | V11: 20 | W11: 309200 | X11: 1236800 | Y11: 2.5 | Z11: 30920 | AC11: paid | AD11: 1141073002 | AE11: 45735 | AF11: DISBURSED | AG11: 0 | AH11: KHI/HO/D/MO/PC COMP/C/107407/108/02/2025 | AJ11: =VLOOKUP(AH11,[1]Sheet1!$B$2:$AA$595,26,0) -> 30920 | AK11: =AJ11-Z11 -> 0
A12: 11 | B12: Renewal | C12: 52768/1 | D12: 45689 | E12: SALAAM TAKAFUL LTD | F12: KHI/HO/D/MO/PC COMP/C/107407/109/02/2025 | G12: 45705 | H12: 46069 | I12: ABID HUSSAIN | J12: 3630203878889 | K12: SUZUKI WAGON-R VXL E2 | L12: AHN-683 | M12: 228455 | N12: 10128415 | O12: 52768/1 | P12: Central | Q12: 0431 | R12: 555116 | S12: 44613 | T12: 46451 | U12: 1760000 | V12: 20 | W12: 352000 | X12: 1408000 | Y12: 1.75 | Z12: 24640 | AC12: paid | AD12: 1141073002 | AE12: 45735 | AF12: DISBURSED | AG12: 0 | AH12: KHI/HO/D/MO/PC COMP/C/107407/109/02/2025 | AJ12: =VLOOKUP(AH12,[1]Sheet1!$B$2:$AA$595,26,0) -> 24640 | AK12: =AJ12-Z12 -> 0
A13: 12 | B13: Renewal | C13: 67617/1 | D13: 45689 | E13: SALAAM TAKAFUL LTD | F13: KHI/HO/D/MO/PC COMP/C/107407/11/02/2025 | G13: 45709 | H13: 46073 | I13: HAFIZ MUHAMMAD GULFAM | J13: 3410365452477 | K13: HONDA CITY ASPIRE A/T | L13: LEB-20-6577 | M13: 17538667 | N13: LR260454 | O13: 67617/1 | P13: Central | Q13: 0329 | R13: 628337 | S13: 45345 | T13: 46451 | U13: 3800000 | V13: 10 | W13: 380000 | X13: 3420000 | Y13: 1.5 | Z13: 51300 | AC13: paid | AD13: 1141073002 | AE13: 45735 | AF13: DISBURSED | AG13: 0 | AH13: KHI/HO/D/MO/PC COMP/C/107407/11/02/2025 | AJ13: =VLOOKUP(AH13,[1]Sheet1!$B$2:$AA$595,26,0) -> 51300 | AK13: =AJ13-Z13 -> 0
... A189: 188 | B189: Renewal | C189: 46597/2 | D189: 45689 | E189: SALAAM TAKAFUL LTD | F189: KHI/HO/D/MO/CV/C/107453/1/02/2025 | G189: 45714 | H189: 46078 | I189: SAJJAD WASEEM RAJA | J189: 4220112377369 | K189: SUZUKI RAVI PICK UP | L189: TB-284 | M189: 367401 | N189: 472407 | O189: 46597/2 | P189: North | Q189: 0804 | R189: 523869 | S189: 44256 | T189: 46086 | U189: 1034000 | V189: 25 | W189: 258500 | X189: 775500 | Y189: 2 | Z189: 15510 | AC189: paid | AD189: 1141073002 | AE189: 45735 | AF189: DISBURSED | AG189: 0 | AH189: KHI/HO/D/MO/CV/C/107453/1/02/2025 | AJ189: =VLOOKUP(AH189,[1]Sheet1!$B$2:$AA$595,26,0) -> 15510 | AK189: =AJ189-Z189 -> 0
A190: 189 | B190: Renewal | C190: 54965/1 | D190: 45689 | E190: SALAAM TAKAFUL LTD | F190: KHI/HO/D/MO/CV/C/107453/2/02/2025 | G190: 45699 | H190: 46063 | I190: MUHAMMAD SHAHBAZ AHMAD | J190: 3820124857079 | K190: SUZUKI RAVI VX | M190: 381124 | N190: 485768 | O190: 54965/1 | P190: Central | Q190: 0413 | R190: 565081 | S190: 44617 | T190: 46451 | U190: 1117000 | V190: 20 | W190: 223400 | X190: 893600 | Y190: 2.5 | Z190: 22340 | AC190: paid | AD190: 1141073002 | AE190: 45735 | AF190: DISBURSED | AG190: 0 | AH190: KHI/HO/D/MO/CV/C/107453/2/02/2025 | AJ190: =VLOOKUP(AH190,[1]Sheet1!$B$2:$AA$595,26,0) -> 22340 | AK190: =AJ190-Z190 -> 0
A191: 190 | B191: Renewal | C191: 54867/1 | D191: 45689 | E191: SALAAM TAKAFUL LTD | F191: KHI/HO/D/MO/CV/C/107453/3/02/2025 | G191: 45704 | H191: 46068 | I191: MUHAMMAD WAQAS ALI | J191: 3310259243761 | K191: SUZUKI RAVI VX EURO II | L191: TD-409 | M191: 381381 | N191: 486038 | O191: 54867/1 | P191: North | Q191: 0804 | R191: 336255 | S191: 44613 | T191: 46451 | U191: 1117000 | V191: 20 | W191: 223400 | X191: 893600 | Y191: 2.5 | Z191: 22340 | AC191: paid | AD191: 1141073002 | AE191: 45735 | AF191: DISBURSED | AG191: 0 | AH191: KHI/HO/D/MO/CV/C/107453/3/02/2025 | AJ191: =VLOOKUP(AH191,[1]Sheet1!$B$2:$AA$595,26,0) -> 22340 | AK191: =AJ191-Z191 -> 0
A192: 191 | B192: Renewal | C192: 55033/1 | D192: 45689 | E192: SALAAM TAKAFUL LTD | F192: KHI/HO/D/MO/CV/C/107453/4/02/2025 | G192: 45709 | H192: 46073 | I192: MUHAMMAD HABIB | J192: 4240120985535 | K192: SUZUKI RAVI VX EURO II | L192: LB-1941 | M192: 377924 | N192: 482592 | O192: 55033/1 | P192: South | Q192: 0144 | R192: 565604 | S192: 44621 | T192: 46451 | U192: 1117000 | V192: 20 | W192: 223400 | X192: 893600 | Y192: 2.5 | Z192: 22340 | AC192: paid | AD192: 1141073002 | AE192: 45735 | AF192: DISBURSED | AG192: 0 | AH192: KHI/HO/D/MO/CV/C/107453/4/02/2025 | AJ192: =VLOOKUP(AH192,[1]Sheet1!$B$2:$AA$595,26,0) -> 22340 | AK192: =AJ192-Z192 -> 0
A193: 192 | B193: Renewal | C193: 54106/1 | D193: 45689 | E193: SALAAM TAKAFUL LTD | F193: KHI/HO/D/MO/CV/C/107453/5/02/2025 | G193: 45710 | H193: 46074 | I193: HUMAIR AHMED NASIR | J193: 4210145670965 | K193: MASTER FORLAND C-10 | L193: LB-2169 | M193: 09255767 | N193: 004117 | O193: 54106/1 | P193: South | Q193: 0150 | R193: 560270 | S193: 44623 | T193: 46451 | U193: 1365000 | V193: 20 | W193: 273000 | X193: 1092000 | Y193: 1.75 | Z193: 19110 | AC193: paid | AD193: 1141073002 | AE193: 45735 | AF193: DISBURSED | AG193: 0 | AH193: KHI/HO/D/MO/CV/C/107453/5/02/2025 | AJ193: =VLOOKUP(AH193,[1]Sheet1!$B$2:$AA$595,26,0) -> 19110 | AK193: =AJ193-Z193 -> 0
A194: 193 | B194: Renewal | C194: 55121/1 | D194: 45689 | E194: SALAAM TAKAFUL LTD | F194: KHI/HO/D/MO/CV/C/107453/6/02/2025 | G194: 45716 | H194: 46080 | I194: MUHAMMAD KAMIL RAZA | J194: 3630261315815 | K194: SUZUKI RAVI VX EURO II | L194: CAJ-2933 | M194: 381121 | N194: 485766 | O194: 55121/1 | P194: Central | Q194: 0431 | R194: 568320 | S194: 44621 | T194: 46451 | U194: 1117000 | V194: 20 | W194: 223400 | X194: 893600 | Y194: 2.5 | Z194: 22340 | AC194: paid | AD194: 1141073002 | AE194: 45735 | AF194: DISBURSED | AG194: 0 | AH194: KHI/HO/D/MO/CV/C/107453/6/02/2025 | AJ194: =VLOOKUP(AH194,[1]Sheet1!$B$2:$AA$595,26,0) -> 22340 | AK194: =AJ194-Z194 -> 0
A195: 194 | B195: Renewal | C195: 45592/1 | D195: 45689 | E195: SALAAM TAKAFUL LTD | F195: KHI/HO/D/MO/CV/C/107453/7/02/2025 | G195: 45717 | H195: 46081 | I195: SYED GHULAM MUSTAFA SHERAZI | J195: 3450125517999 | K195: SUZUKI RAVI VX EURO II | L195: TB-176 | M195: 368162 | N195: 472852 | O195: 45592/1 | P195: North | Q195: 0804 | R195: 516597 | S195: 44270 | T195: 46086 | U195: 1034000 | V195: 25 | W195: 258500 | X195: 775500 | Y195: 2.5 | Z195: 19387.5 | AC195: paid | AD195: 1141073002 | AE195: 45735 | AF195: DISBURSED | AG195: 0 | AH195: KHI/HO/D/MO/CV/C/107453/7/02/2025 | AJ195: =VLOOKUP(AH195,[1]Sheet1!$B$2:$AA$595,26,0) -> 19388 | AK195: =AJ195-Z195 -> 0.5
A196: 195 | B196: Renewal | C196: 46437/1 | D196: 45689 | E196: SALAAM TAKAFUL LTD | F196: KHI/HO/D/MO/CV/C/107454/1/02/2025 | G196: 45704 | H196: 46068 | I196: MUHAMMAD SHAFIQ | J196: 1350305533461 | K196: SUZUKI RAVI VX EURO II | L196: TB-313 | M196: 367410 | N196: 472075 | O196: 46437/1 | P196: North | Q196: 0804 | R196: 522621 | S196: 44249 | T196: 46086 | U196: 1034000 | V196: 25 | W196: 258500 | X196: 775500 | Y196: 2.5 | Z196: 19387.5 | AC196: paid | AD196: 1141073002 | AE196: 45735 | AF196: DISBURSED | AG196: 0 | AH196: KHI/HO/D/MO/CV/C/107454/1/02/2025 | AJ196: =VLOOKUP(AH196,[1]Sheet1!$B$2:$AA$595,26,0) -> 19388 | AK196: =AJ196-Z196 -> 0.5
A197: 196 | B197: Renewal | C197: 44627/1 | D197: 45689 | E197: SALAAM TAKAFUL LTD | F197: KHI/HO/D/MO/CV/C/107454/2/02/2025 | G197: 45709 | H197: 46073 | I197: SHERAZ SHARIF | J197: 6110152563201 | K197: SUZUKI RAVI VX EURO II | L197: TB-106 | M197: 367941 | N197: 472572 | O197: 44627/1 | P197: North | Q197: 0804 | R197: 509125 | S197: 44250 | T197: 46086 | U197: 1034000 | V197: 25 | W197: 258500 | X197: 775500 | Y197: 2.5 | Z197: 19387.5 | AC197: paid | AD197: 1141073002 | AE197: 45735 | AF197: DISBURSED | AG197: 0 | AH197: KHI/HO/D/MO/CV/C/107454/2/02/2025 | AJ197: =VLOOKUP(AH197,[1]Sheet1!$B$2:$AA$595,26,0) -> 19388 | AK197: =AJ197-Z197 -> 0.5
A198: 197 | B198: Renewal | C198: 46624/1 | D198: 45689 | E198: SALAAM TAKAFUL LTD | F198: KHI/HO/D/MO/CV/C/107454/3/02/2025 | G198: 45710 | H198: 46074 | I198: MUZAFAR KHAN | J198: 1120103131675 | K198: SUZUKI RAVI VX EURO II | L198: AB-297 | M198: 367394 | N198: 472057 | O198: 46624/1 | P198: North | Q198: 0804 | R198: 521895 | S198: 44256 | T198: 46086 | U198: 1034000 | V198: 25 | W198: 258500 | X198: 775500 | Y198: 2.5 | Z198: 19387.5 | AC198: paid | AD198: 1141073002 | AE198: 45735 | AF198: DISBURSED | AG198: 0 | AH198: KHI/HO/D/MO/CV/C/107454/3/02/2025 | AJ198: =VLOOKUP(AH198,[1]Sheet1!$B$2:$AA$595,26,0) -> 19388 | AK198: =AJ198-Z198 -> 0.5
A199: 198 | B199: Renewal | C199: 46842/1 | D199: 45689 | E199: SALAAM TAKAFUL LTD | F199: KHI/HO/D/MO/CV/C/107454/4/02/2025 | G199: 45713 | H199: 46077 | I199: MUHAMMAD HASSAN | J199: 3820107337191 | K199: SUZUKI RAVI VX EURO II | L199: TB-766 | M199: 367684 | N199: 472343 | O199: 46842/1 | P199: Central | Q199: 0413 | R199: 520215 | S199: 44264 | T199: 46086 | U199: 1034000 | V199: 25 | W199: 258500 | X199: 775500 | Y199: 2.5 | Z199: 19387.5 | AC199: paid | AD199: 1141073002 | AE199: 45735 | AF199: DISBURSED | AG199: 0 | AH199: KHI/HO/D/MO/CV/C/107454/4/02/2025 | AJ199: =VLOOKUP(AH199,[1]Sheet1!$B$2:$AA$595,26,0) -> 19388 | AK199: =AJ199-Z199 -> 0.5
A200: 199 | B200: Renewal | C200: 47379/2 | D200: 45597 | E200: SALAAM TAKAFUL LTD | F200: KHI/HO/D/MO/PC COMP/C/102208/16/11/2024 | G200: 45611 | H200: 45975 | I200: ABDUL SALAM | J200: 4240128673429 | K200: CHANGAN KARVAAN PLUS | M200: 503396 | N200: 1010660 | O200: 47379/2 | P200: South | Q200: 0150 | R200: 529803 | S200: 44601 | T200: 47154 | U200: 1640000 | V200: 20 | W200: 328000 | X200: 1312000 | Y200: 2.5 | Z200: 32800 | AC200: paid | AD200: 1141073002 | AE200: 45735 | AF200: DISBURSED | AG200: 5 | AH200: KHI/HO/D/MO/PC COMP/C/102208/16/11/2024 | AI200: KHI/HO/D/MO/PC COMP/E/58892/00016/03/2025 | AJ200: =VLOOKUP(AH200,[2]Sheet1!$B$2:$AA$1455,26,0) -> 34850 | AK200: =AJ200-Z200 -> 2050
A201: 200 | B201: Renewal | C201: 47828/1 | D201: 45597 | E201: SALAAM TAKAFUL LTD | F201: KHI/HO/D/MO/PC COMP/C/102208/28/11/2024 | G201: 45615 | H201: 45979 | I201: SOHAIL AKHTAR | J201: 4200043573107 | K201: TOYOTA COROLLA ALTIS A/T | L201: BVB-717 | M201: Q083847 | N201: 6061338 | O201: 47828/1 | P201: South | Q201: 0144 | R201: 532430 | S201: 44608 | T201: 46451 | U201: 3255000 | V201: 20 | W201: 651000 | X201: 2604000 | Y201: 1.25 | Z201: 32550 | AC201: paid | AD201: 1141073002 | AE201: 45735 | AF201: DISBURSED | AG201: 5 | AH201: KHI/HO/D/MO/PC COMP/C/102208/28/11/2024 | AI201: KHI/HO/D/MO/PC COMP/E/58892/00028/03/2025 | AJ201: =VLOOKUP(AH201,[2]Sheet1!$B$2:$AA$1455,26,0) -> 34584 | AK201: =AJ201-Z201 -> 2034
A202: 201 | B202: Renewal | C202: 52644/1 | D202: 45658 | E202: SALAAM TAKAFUL LTD | F202: KHI/HO/D/MO/PC COMP/C/105499/162/01/2025 | G202: 45685 | H202: 46049 | I202: IJAZ AHMAD | J202: 3650118236801 | K202: HONDA CITY 1.2 LS MT | L202: AHN-741 | M202: 1007385 | N202: NR011605 | O202: 52644/1 | P202: Central | Q202: 0329 | R202: 554221 | S202: 44613 | T202: 46451 | U202: 2955000 | V202: 20 | W202: 591000 | X202: 2364000 | Y202: 1.75 | Z202: 41370 | AC202: paid | AD202: 1141073002 | AE202: 45735 | AF202: DISBURSED | AG202: 5 | AH202: KHI/HO/D/MO/PC COMP/C/105499/162/01/2025 | AJ202: =VLOOKUP(AH202,[1]Sheet1!$B$2:$AA$595,26,0) -> 41370 | AK202: =AJ202-Z202 -> 0
