Workbook

Sheet Sheet1
A1: Loan ID | B1: Hub Code | C1: Name of Lessee | D1: Vehicle Description | E1: Engine | F1: Chasis | G1: Registration | H1: Start Date | I1: Expiry Date | J1: TENURE | K1: SUM COVERED | L1: Bank Ins Premium | M1: Bank Premium Rate | N1: New Takaful Company | O1: Policy No. | P1: Endorsement No. | Q1: TMS Premium | R1: Difference Amount | S1: Tagging
A2: CI-2021-0000-2853 | B2: PK0010002 | C2: Zohaib Shaikh | D2: Alto VXR | E2: R198370 | F2: H1098363 | G2: BVY-389 | H2: 45726 | I2: 46091 | J2: 12 MONTHS | K2: 1000917 | L2: 15014 | M2: 1.50 | N2: SALAM TAKAFUL Insurance Ltd-WTO | O2: KHI/HO/D/MO/PC COMP/C/107535/7/02/2025 | Q2: =VLOOKUP(O2,[1]Sheet1!$O$2:$P$91,2,0) -> 15014 | R2: =Q2-L2 -> 0 | S2: =VLOOKUP(E2,[1]Sheet1!$E$2:$R$91,14,0) -> REN
A3: CI-2021-0143-1264 | B3: PK0010002 | C3: AKHLAQ UR REHMAN | D3: Yaris 1.3 GLI MT | E3: 2A46684 | F3: R-7029280 | G3: BVU-937 | H3: 45708 | I3: 46073 | J3: 12 MONTHS | K3: 1909251 | L3: 28639 | M3: 1.50 | N3: SALAM TAKAFUL Insurance Ltd-WTO | O3: KHI/HO/D/MO/PC COMP/C/107437/1/02/2025 | Q3: =VLOOKUP(O3,[1]Sheet1!$O$2:$P$91,2,0) -> 28639 | R3: =Q3-L3 -> 0 | S3: =VLOOKUP(E3,[1]Sheet1!$E$2:$R$91,14,0) -> REN
A4: CI-2021-0174-2064 | B4: PK0010002 | C4: MUHAMMAD SAJJAD | D4: Alto VXL | E4: R205617 | F4: H1105599 | G4: BVV-239 | H4: 45721 | I4: 46086 | J4: 12 MONTHS | K4: 1108809 | L4: 16632 | M4: 1.50 | N4: SALAM TAKAFUL Insurance Ltd-WTO | O4: KHI/HO/D/MO/PC COMP/C/107437/2/02/2025 | Q4: =VLOOKUP(O4,[1]Sheet1!$O$2:$P$91,2,0) -> 16632 | R4: =Q4-L4 -> 0 | S4: =VLOOKUP(E4,[1]Sheet1!$E$2:$R$91,14,0) -> REN
A5: CI-2021-1602-2742 | B5: PK0010002 | C5: MUNWAR ALI ALMANI | D5: Alto VXR | E5: R215640 | F5: H1115626 | G5: BVY-385 | H5: 45726 | I5: 46091 | J5: 12 MONTHS | K5: 1000917 | L5: 15014 | M5: 1.50 | N5: SALAM TAKAFUL Insurance Ltd-WTO | O5: KHI/HO/D/MO/PC COMP/C/107535/6/02/2025 | Q5: =VLOOKUP(O5,[1]Sheet1!$O$2:$P$91,2,0) -> 15014 | R5: =Q5-L5 -> 0 | S5: =VLOOKUP(E5,[1]Sheet1!$E$2:$R$91,14,0) -> REN
A6: CI-2021-9938-2647 | B6: PK0010002 | C6: NABI BUX | D6: Cultus VXR | E6: 193350 | F6: 10093336 | G6: BVX-527 | H6: 45726 | I6: 46091 | J6: 12 MONTHS | K6: 1298349 | L6: 19475 | M6: 1.50 | N6: SALAM TAKAFUL Insurance Ltd-WTO | O6: KHI/HO/D/MO/PC COMP/C/107437/3/02/2025 | Q6: =VLOOKUP(O6,[1]Sheet1!$O$2:$P$91,2,0) -> 19475 | R6: =Q6-L6 -> 0 | S6: =VLOOKUP(E6,[1]Sheet1!$E$2:$R$91,14,0) -> REN
A7: CI-2021-9956-1079 | B7: PK0010002 | C7: ANUM ALTAF HUSSAIN | D7: SUZUKI ALTO VXR CNG METALLIC | E7: R215993 | F7: H1116006 | G7: BVY-533 | H7: 45731 | I7: 46096 | J7: 12 MONTHS | K7: 1140156 | L7: 17102 | M7: 1.50 | N7: SALAM TAKAFUL Insurance Ltd-WTO | O7: KHI/HO/D/MO/PC COMP/C/107535/4/02/2025 | Q7: =VLOOKUP(O7,[1]Sheet1!$O$2:$P$91,2,0) -> 17102 | R7: =Q7-L7 -> 0 | S7: =VLOOKUP(E7,[1]Sheet1!$E$2:$R$91,14,0) -> REN
A8: CI-2022-0135-0001 | B8: PK0010002 | C8: MUHAMMAD FAHAD | D8: Swift NAV MT | E8: S13038866 | F8: K10038850 | G8: - | H8: 45721 | I8: 46086 | J8: 12 MONTHS | K8: 1239300 | L8: 18590 | M8: 1.50 | N8: SALAM TAKAFUL Insurance Ltd-WTO | O8: KHI/HO/D/MO/PC COMP/C/107437/4/02/2025 | Q8: =VLOOKUP(O8,[1]Sheet1!$O$2:$P$91,2,0) -> 18590 | R8: =Q8-L8 -> 0 | S8: =VLOOKUP(E8,[1]Sheet1!$E$2:$R$91,14,0) -> REN
A9: CI-2023-0156-0003 | B9: PK0010002 | C9: ASHAR ASLAM | D9: Changan Karvaan Plus | E9: U501164 | F9: N1017507 | G9: SA-2081 | H9: 45721 | I9: 46086 | J9: 12 MONTHS | K9: 1939140 | L9: 29087 | M9: 1.50 | N9: SALAM TAKAFUL Insurance Ltd-WTO | O9: KHI/HO/D/MO/PC COMP/C/107533/3/02/2025 | Q9: =VLOOKUP(O9,[1]Sheet1!$O$2:$P$91,2,0) -> 29087 | R9: =Q9-L9 -> 0 | S9: =VLOOKUP(E9,[1]Sheet1!$E$2:$R$91,14,0) -> REN
A10: CI-2023-1038-0001 | B10: PK0010002 | C10: MUNIR KHAN | D10: Civic 1.8 i VTEC CVT Oriel | E10: Z16919352 | F10: R071483 | G10: BTP-563 | H10: 45721 | I10: 46086 | J10: 12 MONTHS | K10: 4455000 | L10: 66825 | M10: 1.50 | N10: SALAM TAKAFUL Insurance Ltd-WTO | O10: KHI/HO/D/MO/PC COMP/C/107533/1/02/2025 | Q10: =VLOOKUP(O10,[1]Sheet1!$O$2:$P$91,2,0) -> 66825 | R10: =Q10-L10 -> 0 | S10: =VLOOKUP(E10,[1]Sheet1!$E$2:$R$91,14,0) -> REN
A11: CI-2023-1241-0003 | B11: PK0010002 | C11: SYED ALI HUSSAIN SHAH | D11: Alto VXR | E11: 6R292366 | F11: NF1AET306H1192446 | G11: - | H11: 45703 | I11: 46068 | J11: 12 MONTHS | K11: 2350800 | L11: 35262 | M11: 1.50 | N11: SALAM TAKAFUL Insurance Ltd-WTO | O11: KHI/HO/D/MO/PC COMP/C/107127/2/02/2025 | Q11: =VLOOKUP(O11,[1]Sheet1!$O$2:$P$91,2,0) -> 35262 | R11: =Q11-L11 -> 0 | S11: =VLOOKUP(E11,[1]Sheet1!$E$2:$R$91,14,0) -> REN
A12: CI-2023-2671-0003 | B12: PK0010002 | C12: WAQAR AHMED | D12: Alto VXR | E12: 6R292976 | F12: NF1AET306H1193030 | G12: - | H12: 45698 | I12: 46063 | J12: 12 MONTHS | K12: 2350800 | L12: 35262 | M12: 1.50 | N12: SALAM TAKAFUL Insurance Ltd-WTO | O12: KHI/HO/D/MO/PC COMP/C/107127/1/02/2025 | Q12: =VLOOKUP(O12,[1]Sheet1!$O$2:$P$91,2,0) -> 35262 | R12: =Q12-L12 -> 0 | S12: =VLOOKUP(E12,[1]Sheet1!$E$2:$R$91,14,0) -> REN
A13: CI-2023-7501-0001 | B13: PK0010002 | C13: REHMAT ULLAH | D13: Corolla Altis Grande AT | E13: Q346782 | F13: R7046014 | G13: BSR-578 | H13: 45721 | I13: 46086 | J13: 12 MONTHS | K13: 3645000 | L13: 54675 | M13: 1.50 | N13: SALAM TAKAFUL Insurance Ltd-WTO | O13: KHI/HO/D/MO/PC COMP/C/107533/2/02/2025 | Q13: =VLOOKUP(O13,[1]Sheet1!$O$2:$P$91,2,0) -> 54675 | R13: =Q13-L13 -> 0 | S13: =VLOOKUP(E13,[1]Sheet1!$E$2:$R$91,14,0) -> REN
... A32: CI-2023-2646-0002 | B32: PK0010011 | C32: MUHAMMAD ASIF | D32: City PT 1.2 | E32: L12B51017639 | F32: NFBGN8622PR031015 | G32: ANL-849 | H32: 45736 | I32: 46101 | J32: 12 MONTHS | K32: 3166290 | L32: 47494 | M32: 1.50 | N32: SALAM TAKAFUL Insurance Ltd-WTO | O32: KHI/HO/D/MO/PC COMP/C/107550/5/02/2025 | Q32: =VLOOKUP(O32,[1]Sheet1!$O$2:$P$91,2,0) -> 47494 | R32: =Q32-L32 -> 0 | S32: =VLOOKUP(E32,[1]Sheet1!$E$2:$R$91,14,0) -> REN
A33: CI-2023-9813-0007 | B33: PK0010011 | C33: GHULAM DASTGEER | D33: Alto VXR | E33: 6R291434 | F33: NF1AET306H1191524 | H33: 45713 | I33: 46078 | J33: 12 MONTHS | K33: 2350800 | L33: 35262 | M33: 1.50 | N33: SALAM TAKAFUL Insurance Ltd-WTO | O33: KHI/HO/D/MO/PC COMP/C/107541/2/02/2025 | Q33: =VLOOKUP(O33,[1]Sheet1!$O$2:$P$91,2,0) -> 35262 | R33: =Q33-L33 -> 0 | S33: =VLOOKUP(E33,[1]Sheet1!$E$2:$R$91,14,0) -> REN
A34: CI-2024-1270-0002 | B34: PK0010011 | C34: MUHAMMAD WAQAS | D34: Alto VXR | E34: 6R147074 | F34: NF1AET306H1047056 | H34: 45721 | I34: 46086 | J34: 12 MONTHS | K34: 1800000 | L34: 27000 | M34: 1.50 | N34: SALAM TAKAFUL Insurance Ltd-WTO | O34: KHI/HO/D/MO/PC COMP/C/107541/3/02/2025 | Q34: =VLOOKUP(O34,[1]Sheet1!$O$2:$P$91,2,0) -> 27000 | R34: =Q34-L34 -> 0 | S34: =VLOOKUP(E34,[1]Sheet1!$E$2:$R$91,14,0) -> REN
A35: CI-2024-9501-0001 | B35: PK0010011 | C35: MUHAMMAD NAEEM | D35: City CVT 1.2L, CVT Transmission | E35: L12B51021424 | F35: NFBGN8620RR036569 | H35: 45713 | I35: 46078 | J35: 12 MONTHS | K35: 4386150 | L35: 65792 | M35: 1.50 | N35: SALAM TAKAFUL Insurance Ltd-WTO | O35: KHI/HO/D/MO/PC COMP/C/107541/1/02/2025 | Q35: =VLOOKUP(O35,[1]Sheet1!$O$2:$P$91,2,0) -> 65792 | R35: =Q35-L35 -> 0 | S35: =VLOOKUP(E35,[1]Sheet1!$E$2:$R$91,14,0) -> REN
A36: CM-2021-0011-1080 | B36: PK0010011 | C36: SADIA SALEEM | D36: KIA PICANTO 1.0 M/T | E36: G3LAMP193574 | F36: NNATA52AXKP503268 | G36: AHJ-838 | H36: 45721 | I36: 46086 | J36: 12 MONTHS | K36: 1614006 | L36: 24210 | M36: 1.50 | N36: SALAM TAKAFUL Insurance Ltd-WTO | O36: KHI/HO/D/MO/PC COMP/C/107554/1/02/2025 | Q36: =VLOOKUP(O36,[1]Sheet1!$O$2:$P$91,2,0) -> 24210 | R36: =Q36-L36 -> 0 | S36: =VLOOKUP(E36,[1]Sheet1!$E$2:$R$91,14,0) -> REN
A37: CM-2021-0011-1704 | B37: PK0010011 | C37: HUSNAIN YOUSAF | D37: SUZUKI WAGAN R VXL | E37: PK10B229082 | F37: A1J310PK10129072 | H37: 45721 | I37: 46086 | J37: 12 MONTHS | K37: 1439775 | L37: 21597 | M37: 1.50 | N37: SALAM TAKAFUL Insurance Ltd-WTO | O37: KHI/HO/D/MO/PC COMP/C/107554/2/02/2025 | Q37: =VLOOKUP(O37,[1]Sheet1!$O$2:$P$91,2,0) -> 21597 | R37: =Q37-L37 -> 0 | S37: =VLOOKUP(E37,[1]Sheet1!$E$2:$R$91,14,0) -> REN
A38: CM-2021-0508-1534 | B38: PK0010011 | C38: ANEEL MANZOOR | D38: HYUNDAI ELANTRA SEDAN | E38: G4NAMU962475 | F38: PMHD841FMNN302537 | G38: - | H38: 45721 | I38: 46086 | J38: 12 MONTHS | K38: 2996555 | L38: 44948 | M38: 1.50 | N38: SALAM TAKAFUL Insurance Ltd-WTO | O38: KHI/HO/D/MO/PC COMP/C/107554/3/02/2025 | P38: KHI/HO/D/MO/PC COMP/E/58973/00003/03/2025 | Q38: =VLOOKUP(O38,[1]Sheet1!$O$2:$P$91,2,0) -> 43841 | R38: =L38-Q38 -> 1107 | S38: =VLOOKUP(E38,[1]Sheet1!$E$2:$R$91,14,0) -> REN
A39: CM-2022-2104-0153 | B39: PK0010011 | C39: MUHAMMAD AMIR | D39: HONDA CITY 1.2 A/T | E39: L12B51006663 | F39: NFBGN8623NR010641 | G39: AHP-818 | H39: 45721 | I39: 46086 | J39: 12 MONTHS | K39: 2159663 | L39: 32395 | M39: 1.50 | N39: SALAM TAKAFUL Insurance Ltd-WTO | O39: KHI/HO/D/MO/PC COMP/C/107554/4/02/2025 | Q39: =VLOOKUP(O39,[1]Sheet1!$O$2:$P$91,2,0) -> 32395 | R39: =Q39-L39 -> 0 | S39: =VLOOKUP(E39,[1]Sheet1!$E$2:$R$91,14,0) -> REN
A40: CI-2022-5001-0013 | B40: PK0010014 | C40: HAJI MEHBOOB ELAHI | D40: City MT 1.5L | E40: L15Z81000141 | F40: NFBGN956XMR000441 | G40: AFE-015 | H40: 45713 | I40: 46078 | J40: 12 MONTHS | K40: 2835000 | L40: 42525 | M40: 1.50 | N40: SALAM TAKAFUL Insurance Ltd-WTO | O40: KHI/HO/D/MO/PC COMP/C/107470/1/02/2025 | Q40: =VLOOKUP(O40,[1]Sheet1!$O$2:$P$91,2,0) -> 42525 | R40: =Q40-L40 -> 0 | S40: =VLOOKUP(E40,[1]Sheet1!$E$2:$R$91,14,0) -> REN
A41: CI-2023-2201-0007 | B41: PK0010014 | C41: ABDUL MAJID | D41: City PT 1.2 | E41: L12B51017477 | F41: NFBGN8621PR030888 | G41: BBS-204 | H41: 45721 | I41: 46086 | J41: 12 MONTHS | K41: 3178035 | L41: 47671 | M41: 1.50 | N41: SALAM TAKAFUL Insurance Ltd-WTO | O41: KHI/HO/D/MO/PC COMP/C/107470/2/02/2025 | Q41: =VLOOKUP(O41,[1]Sheet1!$O$2:$P$91,2,0) -> 47671 | R41: =Q41-L41 -> 0 | S41: =VLOOKUP(E41,[1]Sheet1!$E$2:$R$91,14,0) -> REN
A42: CI-2024-2203-0001 | B42: PK0010014 | C42: HAFIZ SHAKIR MAHMOOD | D42: City PT Aspire 1.5L | E42: L15Z81015097 | F42: NFBGN9667RR036335 | G42: AQV-343 | H42: 45721 | I42: 46086 | J42: 12 MONTHS | K42: 5286150 | L42: 79292 | M42: 1.50 | N42: SALAM TAKAFUL Insurance Ltd-WTO | O42: KHI/HO/D/MO/PC COMP/C/107473/1/02/2025 | Q42: =VLOOKUP(O42,[1]Sheet1!$O$2:$P$91,2,0) -> 79292 | R42: =Q42-L42 -> 0 | S42: =VLOOKUP(E42,[1]Sheet1!$E$2:$R$91,14,0) -> REN
A43: CM-2020-0014-0010 | B43: PK0010014 | C43: MUHAMMAD ASGHAR | D43: SUZUKI WAGON R VXL | E43: PK10B210243 | F43: A1J310PK10110198 | G43: ASU-156 | H43: 45708 | I43: 46073 | J43: 12 MONTHS | K43: 1135053 | L43: 22701 | M43: 2 | N43: SALAM TAKAFUL Insurance Ltd-WTO | O43: KHI/HO/D/MO/PC COMP/C/107472/1/02/2025 | Q43: =VLOOKUP(O43,[1]Sheet1!$O$2:$P$91,2,0) -> 22701 | R43: =Q43-L43 -> 0 | S43: =VLOOKUP(E43,[1]Sheet1!$E$2:$R$91,14,0) -> REN
A44: CM-2021-1294-0469 | B44: PK0010014 | C44: MUJAHID IQBAL | D44: CULTUS VXR A/C | E44: PK10K192511 | F44: NF1AVK31H10092501 | G44: AHQ-390 | H44: 45721 | I44: 46086 | J44: 12 MONTHS | K44: 1298349 | L44: 19475 | M44: 1.50 | N44: SALAM TAKAFUL Insurance Ltd-WTO | O44: KHI/HO/D/MO/PC COMP/C/107468/8/02/2025 | Q44: =VLOOKUP(O44,[1]Sheet1!$O$2:$P$91,2,0) -> 19475 | R44: =Q44-L44 -> 0 | S44: =VLOOKUP(E44,[1]Sheet1!$E$2:$R$91,14,0) -> REN
A45: CM-2021-2201-0379 | B45: PK0010014 | C45: ASAD KHAN | D45: SUZUKI ALTO VXL AGS | E45: 6R210617 | F45: NF1AET306H1110673 | G45: AHJ-710 | H45: 45713 | I45: 46078 | J45: 12 MONTHS | K45: 1108809 | L45: 16632 | M45: 1.50 | N45: SALAM TAKAFUL Insurance Ltd-WTO | O45: KHI/HO/D/MO/PC COMP/C/107468/4/02/2025 | Q45: =VLOOKUP(O45,[1]Sheet1!$O$2:$P$91,2,0) -> 16632 | R45: =Q45-L45 -> 0 | S45: =VLOOKUP(E45,[1]Sheet1!$E$2:$R$91,14,0) -> REN
A46: CM-2021-4701-0457 | B46: PK0010014 | C46: KHAWAJA ABDUL REHMAN | D46: SUZUKI ALTO VXL AGS | E46: 6R212194 | F46: NF1AET306H1112138 | G46: AHT-167 | H46: 45721 | I46: 46086 | J46: 12 MONTHS | K46: 1108809 | L46: 16632 | M46: 1.50 | N46: SALAM TAKAFUL Insurance Ltd-WTO | O46: KHI/HO/D/MO/PC COMP/C/107468/5/02/2025 | Q46: =VLOOKUP(O46,[1]Sheet1!$O$2:$P$91,2,0) -> 16632 | R46: =Q46-L46 -> 0 | S46: =VLOOKUP(E46,[1]Sheet1!$E$2:$R$91,14,0) -> REN
A47: CM-2021-7401-0028 | B47: PK0010014 | C47: MUHAMMAD SAFDAR | D47: TOYOTA COROLLA ALTIS 1.6 AT | E47: Q089453 | F47: ZRE171R-6067319 | G47: AXD-653 | H47: 45713 | I47: 46078 | J47: 12 MONTHS | K47: 2598885 | L47: 38983 | M47: 1.50 | N47: SALAM TAKAFUL Insurance Ltd-WTO | O47: KHI/HO/D/MO/PC COMP/C/107468/3/02/2025 | Q47: =VLOOKUP(O47,[1]Sheet1!$O$2:$P$91,2,0) -> 38983 | R47: =Q47-L47 -> 0 | S47: =VLOOKUP(E47,[1]Sheet1!$E$2:$R$91,14,0) -> REN
A48: CM-2021-9812-0024 | B48: PK0010014 | C48: MUHAMMAD HASSAN | D48: SUZUKI CULTUS | E48: PK10K192951 | F48: NF1AVK31H10092943 | G48: AHM-925 | H48: 45721 | I48: 46086 | J48: 12 MONTHS | K48: 1298349 | L48: 19475 | M48: 1.50 | N48: SALAM TAKAFUL Insurance Ltd-WTO | O48: KHI/HO/D/MO/PC COMP/C/107468/7/02/2025 | Q48: =VLOOKUP(O48,[1]Sheet1!$O$2:$P$91,2,0) -> 19475 | R48: =Q48-L48 -> 0 | S48: =VLOOKUP(E48,[1]Sheet1!$E$2:$R$91,14,0) -> REN
A49: CM-2021-9812-0493 | B49: PK0010014 | C49: MUHAMAMD RAMZAN | D49: SUZUKI ALTO VXR | E49: 6R210521 | F49: NF1AET306H1110487 | G49: AHH-708 | H49: 45713 | I49: 46078 | J49: 12 MONTHS | K49: 973215 | L49: 14598 | M49: 1.50 | N49: SALAM TAKAFUL Insurance Ltd-WTO | O49: KHI/HO/D/MO/PC COMP/C/107468/2/02/2025 | Q49: =VLOOKUP(O49,[1]Sheet1!$O$2:$P$91,2,0) -> 14598 | R49: =Q49-L49 -> 0 | S49: =VLOOKUP(E49,[1]Sheet1!$E$2:$R$91,14,0) -> REN
A50: CM-2021-9838-0399 | B50: PK0010014 | C50: MUHAMMAD RAFIQUE | D50: SUZUKI ALTO VXR | E50: 6R209836 | F50: NF1AET306H1109708 | G50: AHE-628 | H50: 45708 | I50: 46073 | J50: 12 MONTHS | K50: 973215 | L50: 14598 | M50: 1.50 | N50: SALAM TAKAFUL Insurance Ltd-WTO | O50: KHI/HO/D/MO/PC COMP/C/107468/1/02/2025 | Q50: =VLOOKUP(O50,[1]Sheet1!$O$2:$P$91,2,0) -> 14598 | R50: =Q50-L50 -> 0 | S50: =VLOOKUP(E50,[1]Sheet1!$E$2:$R$91,14,0) -> REN
... A70: CI-2023-1161-0007 | B70: PK0010299 | C70: USMAN . | D70: Changan Alsvin Lumiere 1.5L DCT | E70: JL473QFM3CAD522159 | F70: NKMA2ASE5M1004341 | G70: AGJ 864 | H70: 45693 | I70: 46058 | J70: 12 MONTHS | K70: 3060000 | L70: 45900 | M70: 1.50 | N70: SALAM TAKAFUL Insurance Ltd-WTO | O70: KHI/HO/D/MO/PC COMP/C/107458/2/02/2025 | Q70: =VLOOKUP(O70,[1]Sheet1!$O$2:$P$91,2,0) -> 45900 | R70: =Q70-L70 -> 0 | S70: =VLOOKUP(E70,[1]Sheet1!$E$2:$R$91,14,0) -> REN
A71: CM-2021-1153-1101 | B71: PK0010299 | C71: MUHAMMAD WAQAR HAIDER | D71: TOYOTA COROLLA ALTIS 1.6 AT | E71: Q087226 | F71: ZRE171R-6064680 | H71: 45693 | I71: 46058 | J71: 12 MONTHS | K71: 2393307 | L71: 35900 | M71: 1.5 | N71: SALAM TAKAFUL Insurance Ltd-WTO | O71: KHI/HO/D/MO/PC COMP/C/107459/2/02/2025 | Q71: =VLOOKUP(O71,[1]Sheet1!$O$2:$P$91,2,0) -> 35900 | R71: =Q71-L71 -> 0 | S71: =VLOOKUP(E71,[1]Sheet1!$E$2:$R$91,14,0) -> REN
A72: CI-2023-0273-0001 | B72: PK0010299 | C72: RAFAY AHMAD ALVI | D72: Yaris 1.3ATIV MT | E72: 2A43583 | F72: NSP150R-7027317 | G72: AKG-301 | H72: 45698 | I72: 46063 | J72: 12 MONTHS | K72: 2697300 | L72: 40460 | M72: 1.50 | N72: SALAM TAKAFUL Insurance Ltd-WTO | O72: KHI/HO/D/MO/PC COMP/C/107459/3/02/2025 | Q72: =VLOOKUP(O72,[1]Sheet1!$O$2:$P$91,2,0) -> 40460 | R72: =Q72-L72 -> 0 | S72: =VLOOKUP(E72,[1]Sheet1!$E$2:$R$91,14,0) -> REN
A73: CI-2024-1145-0001 | B73: PK0010299 | C73: MUHAMMAD AHMAD | D73: Wagon R VXL | E73: PK10B225047 | F73: A1J310PK10125067 | G73: AGH 201 | H73: 45703 | I73: 46068 | J73: 12 MONTHS | K73: 2340000 | L73: 35100 | M73: 1.50 | N73: SALAM TAKAFUL Insurance Ltd-WTO | O73: KHI/HO/D/MO/PC COMP/C/107462/1/02/2025 | Q73: =VLOOKUP(O73,[1]Sheet1!$O$2:$P$91,2,0) -> 35100 | R73: =Q73-L73 -> 0 | S73: =VLOOKUP(E73,[1]Sheet1!$E$2:$R$91,14,0) -> REN
A74: CI-2024-0000-0007 | B74: PK0010299 | C74: SYED AWAIS MEHDI ZAIDI | D74: Elantra 1.6 | E74: G4FGPU105203 | F74: PMHD841CMPN307404 | G74: AQT 933 | H74: 45708 | I74: 46073 | J74: 12 MONTHS | K74: 5778900 | L74: 86684 | M74: 1.50 | N74: SALAM TAKAFUL Insurance Ltd-WTO | O74: KHI/HO/D/MO/PC COMP/C/107462/2/02/2025 | Q74: =VLOOKUP(O74,[1]Sheet1!$O$2:$P$91,2,0) -> 86684 | R74: =Q74-L74 -> 0 | S74: =VLOOKUP(E74,[1]Sheet1!$E$2:$R$91,14,0) -> REN
A75: CI-2023-0232-0012 | B75: PK0010300 | C75: MUHAMMAD SHAFIQUE | D75: Alto VXL AGS | E75: 6R290584 | F75: NF1AET306H1190790 | G75: AQQ 741 | H75: 45693 | I75: 46058 | J75: 12 MONTHS | K75: 2641500 | L75: 39623 | M75: 1.50 | N75: SALAM TAKAFUL Insurance Ltd-WTO | O75: KHI/HO/D/MO/PC COMP/C/107458/1/02/2025 | Q75: =VLOOKUP(O75,[1]Sheet1!$O$2:$P$91,2,0) -> 39623 | R75: =Q75-L75 -> 0 | S75: =VLOOKUP(E75,[1]Sheet1!$E$2:$R$91,14,0) -> REN
A76: CI-2023-0261-0002 | B76: PK0010300 | C76: MUHAMMAD ALI | D76: Alto VXR AGS | E76: 6R289545 | F76: NF1AET306H1189536 | G76: AQQ 504 | H76: 45693 | I76: 46058 | J76: 12 MONTHS | K76: 2519100 | L76: 37787 | M76: 1.50 | N76: SALAM TAKAFUL Insurance Ltd-WTO | O76: KHI/HO/D/MO/PC COMP/C/107458/4/02/2025 | Q76: =VLOOKUP(O76,[1]Sheet1!$O$2:$P$91,2,0) -> 37787 | R76: =Q76-L76 -> 0 | S76: =VLOOKUP(E76,[1]Sheet1!$E$2:$R$91,14,0) -> REN
A77: CI-2023-0282-0009 | B77: PK0010300 | C77: BILAWAL NAWAZ | D77: Alto VXL AGS | E77: 6R295023 | F77: NF1AET306H1195073 | G77: AQT 580 | H77: 45693 | I77: 46058 | J77: 12 MONTHS | K77: 2641500 | L77: 39623 | M77: 1.50 | N77: SALAM TAKAFUL Insurance Ltd-WTO | O77: KHI/HO/D/MO/PC COMP/C/107458/3/02/2025 | Q77: =VLOOKUP(O77,[1]Sheet1!$O$2:$P$91,2,0) -> 39623 | R77: =Q77-L77 -> 0 | S77: =VLOOKUP(E77,[1]Sheet1!$E$2:$R$91,14,0) -> REN
...

Sheet working
A1: POLICY NO. | B1: Assorted_code | D1: Premium | E1: 26Mar250052
A2: KHI/HO/D/MO/PC COMP/C/107535/7/02/2025 | B2: =VLOOKUP(A2,policy!B:C,2,0) -> 070000177205 | C2: =VLOOKUP(A2,[1]Sheet1!$O$2:$P$91,2,0) -> 15014 | D2: =ROUND(C2,0) -> 15014 | E2: 26Mar250052 | F2: ="insert into ins_premium_det (premium_rcv_code,assorted_code, rec_amount,premium_rcv_detail_code,remaining_amt, payrec, mode_code,coinsurance_code,class_cd,it_remarks) values" -> insert into ins_premium_det (premium_rcv_code,assorted_code, rec_amount,premium_rcv_detail_code,remaining_amt, payrec, mode_code,coinsurance_code,class_cd,it_remarks) values | G2: ="('"&E2&"','"&B2&"','"&D2&"',(select max(to_number(i.premium_rcv_detail_code))+1 from ins_premium_det i),'"&D2&"','"&D2&"','02', '11000003','00','Request by Mr. Saqib Saleem 26-Mar-2025');" -> ('26Mar250052','070000177205','15014',(select max(to_number(i.premium_rcv_detail_code))+1 from ins_premium_det i),'15014','15014','02', '11000003','00','Request by Mr. Saqib Saleem 26-Mar-2025'); | H2: =F2&G2 -> insert into ins_premium_det (premium_rcv_code,assorted_code, rec_amount,premium_rcv_detail_code,remaining_amt, payrec, mode_code,coinsurance_code,class_cd,it_remarks) values('26Mar250052','070000177205','15014',(select max(to_number(i.premium_rcv_detail_code))+1 from ins_premium_det i),'15014','15014','02', '11000003','00','Request by Mr. Saqib Saleem 26-Mar-2025');
A3: KHI/HO/D/MO/PC COMP/C/107437/1/02/2025 | B3: =VLOOKUP(A3,policy!B:C,2,0) -> 070000177054 | C3: =VLOOKUP(A3,[1]Sheet1!$O$2:$P$91,2,0) -> 28639 | D3: =ROUND(C3,0) -> 28639 | E3: 26Mar250052 | F3: ="insert into ins_premium_det (premium_rcv_code,assorted_code, rec_amount,premium_rcv_detail_code,remaining_amt, payrec, mode_code,coinsurance_code,class_cd,it_remarks) values" -> insert into ins_premium_det (premium_rcv_code,assorted_code, rec_amount,premium_rcv_detail_code,remaining_amt, payrec, mode_code,coinsurance_code,class_cd,it_remarks) values | G3: ="('"&E3&"','"&B3&"','"&D3&"',(select max(to_number(i.premium_rcv_detail_code))+1 from ins_premium_det i),'"&D3&"','"&D3&"','02', '11000003','00','Request by Mr. Saqib Saleem 26-Mar-2025');" -> ('26Mar250052','070000177054','28639',(select max(to_number(i.premium_rcv_detail_code))+1 from ins_premium_det i),'28639','28639','02', '11000003','00','Request by Mr. Saqib Saleem 26-Mar-2025'); | H3: =F3&G3 -> insert into ins_premium_det (premium_rcv_code,assorted_code, rec_amount,premium_rcv_detail_code,remaining_amt, payrec, mode_code,coinsurance_code,class_cd,it_remarks) values('26Mar250052','070000177054','28639',(select max(to_number(i.premium_rcv_detail_code))+1 from ins_premium_det i),'28639','28639','02', '11000003','00','Request by Mr. Saqib Saleem 26-Mar-2025');
A4: KHI/HO/D/MO/PC COMP/C/107437/2/02/2025 | B4: =VLOOKUP(A4,policy!B:C,2,0) -> 070000177055 | C4: =VLOOKUP(A4,[1]Sheet1!$O$2:$P$91,2,0) -> 16632 | D4: =ROUND(C4,0) -> 16632 | E4: 26Mar250052 | F4: ="insert into ins_premium_det (premium_rcv_code,assorted_code, rec_amount,premium_rcv_detail_code,remaining_amt, payrec, mode_code,coinsurance_code,class_cd,it_remarks) values" -> insert into ins_premium_det (premium_rcv_code,assorted_code, rec_amount,premium_rcv_detail_code,remaining_amt, payrec, mode_code,coinsurance_code,class_cd,it_remarks) values | G4: ="('"&E4&"','"&B4&"','"&D4&"',(select max(to_number(i.premium_rcv_detail_code))+1 from ins_premium_det i),'"&D4&"','"&D4&"','02', '11000003','00','Request by Mr. Saqib Saleem 26-Mar-2025');" -> ('26Mar250052','070000177055','16632',(select max(to_number(i.premium_rcv_detail_code))+1 from ins_premium_det i),'16632','16632','02', '11000003','00','Request by Mr. Saqib Saleem 26-Mar-2025'); | H4: =F4&G4 -> insert into ins_premium_det (premium_rcv_code,assorted_code, rec_amount,premium_rcv_detail_code,remaining_amt, payrec, mode_code,coinsurance_code,class_cd,it_remarks) values('26Mar250052','070000177055','16632',(select max(to_number(i.premium_rcv_detail_code))+1 from ins_premium_det i),'16632','16632','02', '11000003','00','Request by Mr. Saqib Saleem 26-Mar-2025');
A5: KHI/HO/D/MO/PC COMP/C/107535/6/02/2025 | B5: =VLOOKUP(A5,policy!B:C,2,0) -> 070000177204 | C5: =VLOOKUP(A5,[1]Sheet1!$O$2:$P$91,2,0) -> 15014 | D5: =ROUND(C5,0) -> 15014 | E5: 26Mar250052 | F5: ="insert into ins_premium_det (premium_rcv_code,assorted_code, rec_amount,premium_rcv_detail_code,remaining_amt, payrec, mode_code,coinsurance_code,class_cd,it_remarks) values" -> insert into ins_premium_det (premium_rcv_code,assorted_code, rec_amount,premium_rcv_detail_code,remaining_amt, payrec, mode_code,coinsurance_code,class_cd,it_remarks) values | G5: ="('"&E5&"','"&B5&"','"&D5&"',(select max(to_number(i.premium_rcv_detail_code))+1 from ins_premium_det i),'"&D5&"','"&D5&"','02', '11000003','00','Request by Mr. Saqib Saleem 26-Mar-2025');" -> ('26Mar250052','070000177204','15014',(select max(to_number(i.premium_rcv_detail_code))+1 from ins_premium_det i),'15014','15014','02', '11000003','00','Request by Mr. Saqib Saleem 26-Mar-2025'); | H5: =F5&G5 -> insert into ins_premium_det (premium_rcv_code,assorted_code, rec_amount,premium_rcv_detail_code,remaining_amt, payrec, mode_code,coinsurance_code,class_cd,it_remarks) values('26Mar250052','070000177204','15014',(select max(to_number(i.premium_rcv_detail_code))+1 from ins_premium_det i),'15014','15014','02', '11000003','00','Request by Mr. Saqib Saleem 26-Mar-2025');
A6: KHI/HO/D/MO/PC COMP/C/107437/3/02/2025 | B6: =VLOOKUP(A6,policy!B:C,2,0) -> 070000177057 | C6: =VLOOKUP(A6,[1]Sheet1!$O$2:$P$91,2,0) -> 19475 | D6: =ROUND(C6,0) -> 19475 | E6: 26Mar250052 | F6: ="insert into ins_premium_det (premium_rcv_code,assorted_code, rec_amount,premium_rcv_detail_code,remaining_amt, payrec, mode_code,coinsurance_code,class_cd,it_remarks) values" -> insert into ins_premium_det (premium_rcv_code,assorted_code, rec_amount,premium_rcv_detail_code,remaining_amt, payrec, mode_code,coinsurance_code,class_cd,it_remarks) values | G6: ="('"&E6&"','"&B6&"','"&D6&"',(select max(to_number(i.premium_rcv_detail_code))+1 from ins_premium_det i),'"&D6&"','"&D6&"','02', '11000003','00','Request by Mr. Saqib Saleem 26-Mar-2025');" -> ('26Mar250052','070000177057','19475',(select max(to_number(i.premium_rcv_detail_code))+1 from ins_premium_det i),'19475','19475','02', '11000003','00','Request by Mr. Saqib Saleem 26-Mar-2025'); | H6: =F6&G6 -> insert into ins_premium_det (premium_rcv_code,assorted_code, rec_amount,premium_rcv_detail_code,remaining_amt, payrec, mode_code,coinsurance_code,class_cd,it_remarks) values('26Mar250052','070000177057','19475',(select max(to_number(i.premium_rcv_detail_code))+1 from ins_premium_det i),'19475','19475','02', '11000003','00','Request by Mr. Saqib Saleem 26-Mar-2025');
A7: KHI/HO/D/MO/PC COMP/C/107535/4/02/2025 | B7: =VLOOKUP(A7,policy!B:C,2,0) -> 070000177202 | C7: =VLOOKUP(A7,[1]Sheet1!$O$2:$P$91,2,0) -> 17102 | D7: =ROUND(C7,0) -> 17102 | E7: 26Mar250052 | F7: ="insert into ins_premium_det (premium_rcv_code,assorted_code, rec_amount,premium_rcv_detail_code,remaining_amt, payrec, mode_code,coinsurance_code,class_cd,it_remarks) values" -> insert into ins_premium_det (premium_rcv_code,assorted_code, rec_amount,premium_rcv_detail_code,remaining_amt, payrec, mode_code,coinsurance_code,class_cd,it_remarks) values | G7: ="('"&E7&"','"&B7&"','"&D7&"',(select max(to_number(i.premium_rcv_detail_code))+1 from ins_premium_det i),'"&D7&"','"&D7&"','02', '11000003','00','Request by Mr. Saqib Saleem 26-Mar-2025');" -> ('26Mar250052','070000177202','17102',(select max(to_number(i.premium_rcv_detail_code))+1 from ins_premium_det i),'17102','17102','02', '11000003','00','Request by Mr. Saqib Saleem 26-Mar-2025'); | H7: =F7&G7 -> insert into ins_premium_det (premium_rcv_code,assorted_code, rec_amount,premium_rcv_detail_code,remaining_amt, payrec, mode_code,coinsurance_code,class_cd,it_remarks) values('26Mar250052','070000177202','17102',(select max(to_number(i.premium_rcv_detail_code))+1 from ins_premium_det i),'17102','17102','02', '11000003','00','Request by Mr. Saqib Saleem 26-Mar-2025');
A8: KHI/HO/D/MO/PC COMP/C/107437/4/02/2025 | B8: =VLOOKUP(A8,policy!B:C,2,0) -> 070000177058 | C8: =VLOOKUP(A8,[1]Sheet1!$O$2:$P$91,2,0) -> 18590 | D8: =ROUND(C8,0) -> 18590 | E8: 26Mar250052 | F8: ="insert into ins_premium_det (premium_rcv_code,assorted_code, rec_amount,premium_rcv_detail_code,remaining_amt, payrec, mode_code,coinsurance_code,class_cd,it_remarks) values" -> insert into ins_premium_det (premium_rcv_code,assorted_code, rec_amount,premium_rcv_detail_code,remaining_amt, payrec, mode_code,coinsurance_code,class_cd,it_remarks) values | G8: ="('"&E8&"','"&B8&"','"&D8&"',(select max(to_number(i.premium_rcv_detail_code))+1 from ins_premium_det i),'"&D8&"','"&D8&"','02', '11000003','00','Request by Mr. Saqib Saleem 26-Mar-2025');" -> ('26Mar250052','070000177058','18590',(select max(to_number(i.premium_rcv_detail_code))+1 from ins_premium_det i),'18590','18590','02', '11000003','00','Request by Mr. Saqib Saleem 26-Mar-2025'); | H8: =F8&G8 -> insert into ins_premium_det (premium_rcv_code,assorted_code, rec_amount,premium_rcv_detail_code,remaining_amt, payrec, mode_code,coinsurance_code,class_cd,it_remarks) values('26Mar250052','070000177058','18590',(select max(to_number(i.premium_rcv_detail_code))+1 from ins_premium_det i),'18590','18590','02', '11000003','00','Request by Mr. Saqib Saleem 26-Mar-2025');
A9: KHI/HO/D/MO/PC COMP/C/107533/3/02/2025 | B9: =VLOOKUP(A9,policy!B:C,2,0) -> 070000177195 | C9: =VLOOKUP(A9,[1]Sheet1!$O$2:$P$91,2,0) -> 29087 | D9: =ROUND(C9,0) -> 29087 | E9: 26Mar250052 | F9: ="insert into ins_premium_det (premium_rcv_code,assorted_code, rec_amount,premium_rcv_detail_code,remaining_amt, payrec, mode_code,coinsurance_code,class_cd,it_remarks) values" -> insert into ins_premium_det (premium_rcv_code,assorted_code, rec_amount,premium_rcv_detail_code,remaining_amt, payrec, mode_code,coinsurance_code,class_cd,it_remarks) values | G9: ="('"&E9&"','"&B9&"','"&D9&"',(select max(to_number(i.premium_rcv_detail_code))+1 from ins_premium_det i),'"&D9&"','"&D9&"','02', '11000003','00','Request by Mr. Saqib Saleem 26-Mar-2025');" -> ('26Mar250052','070000177195','29087',(select max(to_number(i.premium_rcv_detail_code))+1 from ins_premium_det i),'29087','29087','02', '11000003','00','Request by Mr. Saqib Saleem 26-Mar-2025'); | H9: =F9&G9 -> insert into ins_premium_det (premium_rcv_code,assorted_code, rec_amount,premium_rcv_detail_code,remaining_amt, payrec, mode_code,coinsurance_code,class_cd,it_remarks) values('26Mar250052','070000177195','29087',(select max(to_number(i.premium_rcv_detail_code))+1 from ins_premium_det i),'29087','29087','02', '11000003','00','Request by Mr. Saqib Saleem 26-Mar-2025');
A10: KHI/HO/D/MO/PC COMP/C/107533/1/02/2025 | B10: =VLOOKUP(A10,policy!B:C,2,0) -> 070000177192 | C10: =VLOOKUP(A10,[1]Sheet1!$O$2:$P$91,2,0) -> 66825 | D10: =ROUND(C10,0) -> 66825 | E10: 26Mar250052 | F10: ="insert into ins_premium_det (premium_rcv_code,assorted_code, rec_amount,premium_rcv_detail_code,remaining_amt, payrec, mode_code,coinsurance_code,class_cd,it_remarks) values" -> insert into ins_premium_det (premium_rcv_code,assorted_code, rec_amount,premium_rcv_detail_code,remaining_amt, payrec, mode_code,coinsurance_code,class_cd,it_remarks) values | G10: ="('"&E10&"','"&B10&"','"&D10&"',(select max(to_number(i.premium_rcv_detail_code))+1 from ins_premium_det i),'"&D10&"','"&D10&"','02', '11000003','00','Request by Mr. Saqib Saleem 26-Mar-2025');" -> ('26Mar250052','070000177192','66825',(select max(to_number(i.premium_rcv_detail_code))+1 from ins_premium_det i),'66825','66825','02', '11000003','00','Request by Mr. Saqib Saleem 26-Mar-2025'); | H10: =F10&G10 -> insert into ins_premium_det (premium_rcv_code,assorted_code, rec_amount,premium_rcv_detail_code,remaining_amt, payrec, mode_code,coinsurance_code,class_cd,it_remarks) values('26Mar250052','070000177192','66825',(select max(to_number(i.premium_rcv_detail_code))+1 from ins_premium_det i),'66825','66825','02', '11000003','00','Request by Mr. Saqib Saleem 26-Mar-2025');
A11: KHI/HO/D/MO/PC COMP/C/107127/2/02/2025 | B11: =VLOOKUP(A11,policy!B:C,2,0) -> 070000176442 | C11: =VLOOKUP(A11,[1]Sheet1!$O$2:$P$91,2,0) -> 35262 | D11: =ROUND(C11,0) -> 35262 | E11: 26Mar250052 | F11: ="insert into ins_premium_det (premium_rcv_code,assorted_code, rec_amount,premium_rcv_detail_code,remaining_amt, payrec, mode_code,coinsurance_code,class_cd,it_remarks) values" -> insert into ins_premium_det (premium_rcv_code,assorted_code, rec_amount,premium_rcv_detail_code,remaining_amt, payrec, mode_code,coinsurance_code,class_cd,it_remarks) values | G11: ="('"&E11&"','"&B11&"','"&D11&"',(select max(to_number(i.premium_rcv_detail_code))+1 from ins_premium_det i),'"&D11&"','"&D11&"','02', '11000003','00','Request by Mr. Saqib Saleem 26-Mar-2025');" -> ('26Mar250052','070000176442','35262',(select max(to_number(i.premium_rcv_detail_code))+1 from ins_premium_det i),'35262','35262','02', '11000003','00','Request by Mr. Saqib Saleem 26-Mar-2025'); | H11: =F11&G11 -> insert into ins_premium_det (premium_rcv_code,assorted_code, rec_amount,premium_rcv_detail_code,remaining_amt, payrec, mode_code,coinsurance_code,class_cd,it_remarks) values('26Mar250052','070000176442','35262',(select max(to_number(i.premium_rcv_detail_code))+1 from ins_premium_det i),'35262','35262','02', '11000003','00','Request by Mr. Saqib Saleem 26-Mar-2025');
A12: KHI/HO/D/MO/PC COMP/C/107127/1/02/2025 | B12: =VLOOKUP(A12,policy!B:C,2,0) -> 070000176441 | C12: =VLOOKUP(A12,[1]Sheet1!$O$2:$P$91,2,0) -> 35262 | D12: =ROUND(C12,0) -> 35262 | E12: 26Mar250052 | F12: ="insert into ins_premium_det (premium_rcv_code,assorted_code, rec_amount,premium_rcv_detail_code,remaining_amt, payrec, mode_code,coinsurance_code,class_cd,it_remarks) values" -> insert into ins_premium_det (premium_rcv_code,assorted_code, rec_amount,premium_rcv_detail_code,remaining_amt, payrec, mode_code,coinsurance_code,class_cd,it_remarks) values | G12: ="('"&E12&"','"&B12&"','"&D12&"',(select max(to_number(i.premium_rcv_detail_code))+1 from ins_premium_det i),'"&D12&"','"&D12&"','02', '11000003','00','Request by Mr. Saqib Saleem 26-Mar-2025');" -> ('26Mar250052','070000176441','35262',(select max(to_number(i.premium_rcv_detail_code))+1 from ins_premium_det i),'35262','35262','02', '11000003','00','Request by Mr. Saqib Saleem 26-Mar-2025'); | H12: =F12&G12 -> insert into ins_premium_det (premium_rcv_code,assorted_code, rec_amount,premium_rcv_detail_code,remaining_amt, payrec, mode_code,coinsurance_code,class_cd,it_remarks) values('26Mar250052','070000176441','35262',(select max(to_number(i.premium_rcv_detail_code))+1 from ins_premium_det i),'35262','35262','02', '11000003','00','Request by Mr. Saqib Saleem 26-Mar-2025');
A13: KHI/HO/D/MO/PC COMP/C/107533/2/02/2025 | B13: =VLOOKUP(A13,policy!B:C,2,0) -> 070000177193 | C13: =VLOOKUP(A13,[1]Sheet1!$O$2:$P$91,2,0) -> 54675 | D13: =ROUND(C13,0) -> 54675 | E13: 26Mar250052 | F13: ="insert into ins_premium_det (premium_rcv_code,assorted_code, rec_amount,premium_rcv_detail_code,remaining_amt, payrec, mode_code,coinsurance_code,class_cd,it_remarks) values" -> insert into ins_premium_det (premium_rcv_code,assorted_code, rec_amount,premium_rcv_detail_code,remaining_amt, payrec, mode_code,coinsurance_code,class_cd,it_remarks) values | G13: ="('"&E13&"','"&B13&"','"&D13&"',(select max(to_number(i.premium_rcv_detail_code))+1 from ins_premium_det i),'"&D13&"','"&D13&"','02', '11000003','00','Request by Mr. Saqib Saleem 26-Mar-2025');" -> ('26Mar250052','070000177193','54675',(select max(to_number(i.premium_rcv_detail_code))+1 from ins_premium_det i),'54675','54675','02', '11000003','00','Request by Mr. Saqib Saleem 26-Mar-2025'); | H13: =F13&G13 -> insert into ins_premium_det (premium_rcv_code,assorted_code, rec_amount,premium_rcv_detail_code,remaining_amt, payrec, mode_code,coinsurance_code,class_cd,it_remarks) values('26Mar250052','070000177193','54675',(select max(to_number(i.premium_rcv_detail_code))+1 from ins_premium_det i),'54675','54675','02', '11000003','00','Request by Mr. Saqib Saleem 26-Mar-2025');
... A91: KHI/HO/D/MO/PC COMP/C/107574/2/02/2025 | B91: =VLOOKUP(A91,policy!B:C,2,0) -> 070000177298 | C91: =VLOOKUP(A91,[1]Sheet1!$O$2:$P$91,2,0) -> 19475 | D91: =ROUND(C91,0) -> 19475 | E91: 26Mar250052 | F91: ="insert into ins_premium_det (premium_rcv_code,assorted_code, rec_amount,premium_rcv_detail_code,remaining_amt, payrec, mode_code,coinsurance_code,class_cd,it_remarks) values" -> insert into ins_premium_det (premium_rcv_code,assorted_code, rec_amount,premium_rcv_detail_code,remaining_amt, payrec, mode_code,coinsurance_code,class_cd,it_remarks) values | G91: ="('"&E91&"','"&B91&"','"&D91&"',(select max(to_number(i.premium_rcv_detail_code))+1 from ins_premium_det i),'"&D91&"','"&D91&"','02', '11000003','00','Request by Mr. Saqib Saleem 26-Mar-2025');" -> ('26Mar250052','070000177298','19475',(select max(to_number(i.premium_rcv_detail_code))+1 from ins_premium_det i),'19475','19475','02', '11000003','00','Request by Mr. Saqib Saleem 26-Mar-2025'); | H91: =F91&G91 -> insert into ins_premium_det (premium_rcv_code,assorted_code, rec_amount,premium_rcv_detail_code,remaining_amt, payrec, mode_code,coinsurance_code,class_cd,it_remarks) values('26Mar250052','070000177298','19475',(select max(to_number(i.premium_rcv_detail_code))+1 from ins_premium_det i),'19475','19475','02', '11000003','00','Request by Mr. Saqib Saleem 26-Mar-2025');
C93: =SUM(C2:C91) -> 3541514

Sheet Sheet3
A1: KHI/HO/D/MO/PC COMP/C/107535/7/02/2025 | B1: -02-2025 | H1: 107535 | I1: 00007 | J1: ="ia.assorted_string like '%"&H1&"-"&I1&B1&"%' or" -> ia.assorted_string like '%107535-00007-02-2025%' or
A2: KHI/HO/D/MO/PC COMP/C/107437/1/02/2025 | B2: -02-2025 | H2: 107437 | I2: 00001 | J2: ="ia.assorted_string like '%"&H2&"-"&I2&B2&"%' or" -> ia.assorted_string like '%107437-00001-02-2025%' or
A3: KHI/HO/D/MO/PC COMP/C/107437/2/02/2025 | B3: -02-2025 | H3: 107437 | I3: 00002 | J3: ="ia.assorted_string like '%"&H3&"-"&I3&B3&"%' or" -> ia.assorted_string like '%107437-00002-02-2025%' or
A4: KHI/HO/D/MO/PC COMP/C/107535/6/02/2025 | B4: -02-2025 | H4: 107535 | I4: 00006 | J4: ="ia.assorted_string like '%"&H4&"-"&I4&B4&"%' or" -> ia.assorted_string like '%107535-00006-02-2025%' or
A5: KHI/HO/D/MO/PC COMP/C/107437/3/02/2025 | B5: -02-2025 | H5: 107437 | I5: 00003 | J5: ="ia.assorted_string like '%"&H5&"-"&I5&B5&"%' or" -> ia.assorted_string like '%107437-00003-02-2025%' or
A6: KHI/HO/D/MO/PC COMP/C/107535/4/02/2025 | B6: -02-2025 | H6: 107535 | I6: 00004 | J6: ="ia.assorted_string like '%"&H6&"-"&I6&B6&"%' or" -> ia.assorted_string like '%107535-00004-02-2025%' or
A7: KHI/HO/D/MO/PC COMP/C/107437/4/02/2025 | B7: -02-2025 | H7: 107437 | I7: 00004 | J7: ="ia.assorted_string like '%"&H7&"-"&I7&B7&"%' or" -> ia.assorted_string like '%107437-00004-02-2025%' or
A8: KHI/HO/D/MO/PC COMP/C/107533/3/02/2025 | B8: -02-2025 | H8: 107533 | I8: 00003 | J8: ="ia.assorted_string like '%"&H8&"-"&I8&B8&"%' or" -> ia.assorted_string like '%107533-00003-02-2025%' or
A9: KHI/HO/D/MO/PC COMP/C/107533/1/02/2025 | B9: -02-2025 | H9: 107533 | I9: 00001 | J9: ="ia.assorted_string like '%"&H9&"-"&I9&B9&"%' or" -> ia.assorted_string like '%107533-00001-02-2025%' or
A10: KHI/HO/D/MO/PC COMP/C/107127/2/02/2025 | B10: -02-2025 | H10: 107127 | I10: 00002 | J10: ="ia.assorted_string like '%"&H10&"-"&I10&B10&"%' or" -> ia.assorted_string like '%107127-00002-02-2025%' or
A11: KHI/HO/D/MO/PC COMP/C/107127/1/02/2025 | B11: -02-2025 | H11: 107127 | I11: 00001 | J11: ="ia.assorted_string like '%"&H11&"-"&I11&B11&"%' or" -> ia.assorted_string like '%107127-00001-02-2025%' or
A12: KHI/HO/D/MO/PC COMP/C/107533/2/02/2025 | B12: -02-2025 | H12: 107533 | I12: 00002 | J12: ="ia.assorted_string like '%"&H12&"-"&I12&B12&"%' or" -> ia.assorted_string like '%107533-00002-02-2025%' or
... A90: KHI/HO/D/MO/PC COMP/C/107574/2/02/2025 | B90: -02-2025 | H90: 107574 | I90: 00002 | J90: ="ia.assorted_string like '%"&H90&"-"&I90&B90&"%' or" -> ia.assorted_string like '%107574-00002-02-2025%' or

Sheet policy
B1: FUNC_ASSORTED_STRING(IA.ASSORTED_CODE) | C1: ASSORTED_CODE
A2: 1 | B2: KHI/HO/D/MO/PC COMP/C/107127/1/02/2025 | C2: 070000176441
A3: 2 | B3: KHI/HO/D/MO/PC COMP/C/107127/2/02/2025 | C3: 070000176442
A4: 3 | B4: KHI/HO/D/MO/PC COMP/C/107127/3/02/2025 | C4: 070000176443
A5: 4 | B5: KHI/HO/D/MO/PC COMP/C/107127/4/02/2025 | C5: 070000176445
A6: 5 | B6: KHI/HO/D/MO/PC COMP/C/107127/5/02/2025 | C6: 070000176446
A7: 6 | B7: KHI/HO/D/MO/PC COMP/C/107127/6/02/2025 | C7: 070000176448
A8: 7 | B8: KHI/HO/D/MO/PC COMP/C/107127/8/02/2025 | C8: 070000176450
A9: 8 | B9: KHI/HO/D/MO/PC COMP/C/107437/1/02/2025 | C9: 070000177054
A10: 9 | B10: KHI/HO/D/MO/PC COMP/C/107437/2/02/2025 | C10: 070000177055
A11: 10 | B11: KHI/HO/D/MO/PC COMP/C/107437/3/02/2025 | C11: 070000177057
A12: 11 | B12: KHI/HO/D/MO/PC COMP/C/107437/4/02/2025 | C12: 070000177058
A13: 12 | B13: KHI/HO/D/MO/PC COMP/C/107127/7/02/2025 | C13: 070000176449
... A91: 90 | B91: KHI/HO/D/MO/PC COMP/C/107556/2/02/2025 | C91: 070000177252
