Workbook

Sheet Fresh
A1: Fresh / Renewal | B1: Proposal No. | C1: Billing Month | D1: Takaful Company | E1: PMD / Cert | F1: Takaful Start Date | G1: Takaful End Date | H1: Customer Name | I1: CNIC | J1: Vehicle Make | K1: Reg. No | L1: Engine No | M1: Chassis No | N1: Proposal No. | O1: Region | P1: Unit ID | Q1: BR # | R1: Financing Date | S1: Maturity Date | T1: Asset Value | U1: Dep. % | V1: Dep. Amount | W1: Sum Cover Amount | X1: Takaful Rate | Y1: Premium Amount | Z1: For Takaful Company Rectifications | AA1: For COD Status | AB1: PO No. | AC1: PO Dates | AD1: Proposal Status | AE1: Default Case (Overdue Days) | AF1: Policy # | AH1: Tms Prem | AI1: Difference
A2: Fresh | B2: 74064/1 | C2: 45627 | D2: SALAAM TAKAFUL LTD | E2: KHI/HO/D/MO/PC COMP/C/103201/1/12/2024 | F2: 45628 | G2: 45992 | H2: MUHAMMAD ASLAM | I2: 3530132608755 | J2: ALTO VX (NON-METALLIC) | K2: ATP-677 | L2: 6R328756 | M2: H1228748 | N2: 74064/1 | O2: Central | P2: 0329 | Q2: 614907 | R2: 45629 | S2: 46727 | T2: 2331000 | W2: =T2 -> 2331000 | X2: 2 | Y2: =W2*X2% -> 46620 | AA2: paid | AB2: 1141072451 | AC2: 45687 | AD2: DISBURSED | AE2: 0 | AF2: KHI/HO/D/MO/PC COMP/C/103201/1/12/2024 | AG2: KHI/HO/D/MO/PC COMP/E/52031/00001/02/2025 | AH2: 54140 | AI2: =Y2-AH2 -> -7520
A3: Fresh | B3: 76331/1 | C3: 45627 | D3: SALAAM TAKAFUL LTD | E3: KHI/HO/D/MO/PC COMP/C/103201/10/12/2024 | F3: 45628 | G3: 45992 | H3: MUHAMMAD ASIF MANZOOR | I3: 3650211536759 | J3: KIA STONIC | K3: - | L3: S375319 | M3: P703783 | N3: 76331/1 | O3: Central | P3: 0329 | Q3: 536317 | R3: 45638 | S3: 46727 | T3: 5564000 | W3: =T3 -> 5564000 | X3: 1.5 | Y3: =W3*X3% -> 83460 | AA3: paid | AB3: 1141072451 | AC3: 45687 | AD3: DISBURSED | AE3: 3 | AF3: KHI/HO/D/MO/PC COMP/C/103201/10/12/2024 | AH3: 83460 | AI3: =Y3-AH3 -> 0
A4: Fresh | B4: 76650/1 | C4: 45627 | D4: SALAAM TAKAFUL LTD | E4: KHI/HO/D/MO/PC COMP/C/103201/11/12/2024 | F4: 45628 | G4: 45992 | H4: ABU BAKAR ANEES | I4: 3310078878211 | J4: ALTO VXR (NON-METALLIC) | K4: - | L4: 6R329759 | M4: NF1AET306H1229781 | N4: 76650/1 | O4: Central | P4: 0423 | Q4: 663604 | R4: 45643 | S4: 47488 | T4: 2707000 | W4: =T4 -> 2707000 | X4: 2 | Y4: =W4*X4% -> 54140 | AA4: paid | AB4: 1141072451 | AC4: 45687 | AD4: DISBURSED | AE4: 0 | AF4: KHI/HO/D/MO/PC COMP/C/103201/11/12/2024 | AH4: 54140 | AI4: =Y4-AH4 -> 0
A5: Fresh | B5: 75496/1 | C5: 45627 | D5: SALAAM TAKAFUL LTD | E5: KHI/HO/D/MO/PC COMP/C/103201/12/12/2024 | F5: 45628 | G5: 45992 | H5: ADIL HUSSAIN | I5: 3630243369229 | J5: ALTO VXR (NON-METALLIC) | K5: - | L5: 328555 | M5: 1228589 | N5: 75496/1 | O5: Central | P5: 0431 | Q5: 659466 | R5: 45644 | S5: 47488 | T5: 2707000 | W5: =T5 -> 2707000 | X5: 2 | Y5: =W5*X5% -> 54140 | AA5: paid | AB5: 1141072451 | AC5: 45687 | AD5: DISBURSED | AE5: 0 | AF5: KHI/HO/D/MO/PC COMP/C/103201/12/12/2024 | AH5: 54140 | AI5: =Y5-AH5 -> 0
A6: Fresh | B6: 76603/1 | C6: 45627 | D6: SALAAM TAKAFUL LTD | E6: KHI/HO/D/MO/PC COMP/C/103201/13/12/2024 | F6: 45628 | G6: 45992 | H6: MALIK SHAFQAT ALI | I6: 3410104401293 | J6: WAGON R VXL | K6: AMG-097 | L6: 241136 | M6: 10141139 | N6: 76603/1 | O6: Central | P6: 0401 | Q6: 663341 | R6: 45639 | S6: 47457 | T6: 2600000 | W6: =T6 -> 2600000 | X6: 2 | Y6: =W6*X6% -> 52000 | AA6: paid | AB6: 1141072451 | AC6: 45687 | AD6: DISBURSED | AE6: 0 | AF6: KHI/HO/D/MO/PC COMP/C/103201/13/12/2024 | AH6: 52000 | AI6: =Y6-AH6 -> 0
A7: Fresh | B7: 77007/1 | C7: 45627 | D7: SALAAM TAKAFUL LTD | E7: KHI/HO/D/MO/PC COMP/C/103201/14/12/2024 | F7: 45628 | G7: 45992 | H7: MUHAMMAD WASEEM | I7: 3130324145195 | J7: ALTO VXR (NON-METALLIC) | K7: - | L7: 330668 | M7: 1230495 | N7: 77007/1 | O7: Central | P7: 0461 | Q7: 665129 | R7: 45642 | S7: 47488 | T7: 2707000 | W7: =T7 -> 2707000 | X7: 2 | Y7: =W7*X7% -> 54140 | AA7: paid | AB7: 1141072451 | AC7: 45687 | AD7: DISBURSED | AE7: 0 | AF7: KHI/HO/D/MO/PC COMP/C/103201/14/12/2024 | AH7: 54140 | AI7: =Y7-AH7 -> 0
A8: Fresh | B8: 76587/1 | C8: 45627 | D8: SALAAM TAKAFUL LTD | E8: KHI/HO/D/MO/PC COMP/C/103201/15/12/2024 | F8: 45628 | G8: 45992 | H8: SHAHRUKH TAHIR | I8: 3740518482643 | J8: EVERY VAN | K8: - | L8: 1001533 | M8: 00101534 | N8: 76587/1 | O8: North | P8: 0804 | Q8: 645044 | R8: 45646 | S8: 47488 | T8: 2799000 | W8: =T8 -> 2799000 | X8: 2 | Y8: =W8*X8% -> 55980 | AA8: paid | AB8: 1141072451 | AC8: 45687 | AD8: DISBURSED | AE8: 0 | AF8: KHI/HO/D/MO/PC COMP/C/103201/15/12/2024 | AH8: 55980 | AI8: =Y8-AH8 -> 0
A9: Fresh | B9: 76730/1 | C9: 45627 | D9: SALAAM TAKAFUL LTD | E9: KHI/HO/D/MO/PC COMP/C/103201/16/12/2024 | F9: 45628 | G9: 45992 | H9: MUHAMMAD UMAR | I9: 3520101465649 | J9: TOYOTA COROLLA ALTIS (AUTOMATIC) | K9: LEA-18A-8414 | L9: Q042220 | M9: 6019693 | N9: 76730/1 | O9: Central | P9: 0329 | Q9: 664004 | R9: 45645 | S9: 46757 | T9: 4000000 | W9: =T9 -> 4000000 | X9: 1.5 | Y9: =W9*X9% -> 60000 | AA9: paid | AB9: 1141072451 | AC9: 45687 | AD9: DISBURSED | AE9: 0 | AF9: KHI/HO/D/MO/PC COMP/C/103201/16/12/2024 | AH9: 60000 | AI9: =Y9-AH9 -> 0
A10: Fresh | B10: 76017/1 | C10: 45627 | D10: SALAAM TAKAFUL LTD | E10: KHI/HO/D/MO/PC COMP/C/103201/17/12/2024 | F10: 45628 | G10: 45992 | H10: MUHAMMAD RIAZ | I10: 3520115727377 | J10: CITY (AUTOMATIC) | K10: - | L10: 1029308 | M10: RR046238 | N10: 76017/1 | O10: Central | P10: 0329 | Q10: 661175 | R10: 45645 | S10: 46757 | T10: 4714000 | W10: =T10 -> 4714000 | X10: 1.5 | Y10: =W10*X10% -> 70710 | AA10: paid | AB10: 1141072451 | AC10: 45687 | AD10: DISBURSED | AE10: 0 | AF10: KHI/HO/D/MO/PC COMP/C/103201/17/12/2024 | AH10: 70710 | AI10: =Y10-AH10 -> 0
A11: Fresh | B11: 75974/1 | C11: 45627 | D11: SALAAM TAKAFUL LTD | E11: KHI/HO/D/MO/PC COMP/C/103201/18/12/2024 | F11: 45628 | G11: 45992 | H11: IRFAN ALI | I11: 3130399894557 | J11: ALTO VXR (NON-METALLIC) | K11: BQQ-549 | L11: 6R101579 | M11: 6H1001581 | N11: 75974/1 | O11: Central | P11: 0461 | Q11: 660696 | R11: 45644 | S11: 47488 | T11: 2100000 | W11: =T11 -> 2100000 | X11: 2 | Y11: =W11*X11% -> 42000 | AA11: paid | AB11: 1141072451 | AC11: 45687 | AD11: DISBURSED | AE11: 0 | AF11: KHI/HO/D/MO/PC COMP/C/103201/18/12/2024 | AH11: 42000 | AI11: =Y11-AH11 -> 0
A12: Fresh | B12: 75435/1 | C12: 45627 | D12: SALAAM TAKAFUL LTD | E12: KHI/HO/D/MO/PC COMP/C/103201/19/12/2024 | F12: 45628 | G12: 45992 | H12: MUHAMMAD ZESHAN | I12: 3630443739109 | J12: ALTO VXL AGS | K12: - | L12: 330929 | M12: 1230948 | N12: 75435/1 | O12: Central | P12: 0431 | Q12: 458892 | R12: 45649 | S12: 46757 | T12: 3045000 | W12: =T12 -> 3045000 | X12: 2 | Y12: =W12*X12% -> 60900 | AA12: paid | AB12: 1141072451 | AC12: 45687 | AD12: DISBURSED | AE12: 0 | AF12: KHI/HO/D/MO/PC COMP/C/103201/19/12/2024 | AH12: 60900 | AI12: =Y12-AH12 -> 0
A13: Fresh | B13: 76623/1 | C13: 45627 | D13: SALAAM TAKAFUL LTD | E13: KHI/HO/D/MO/PC COMP/C/103201/2/12/2024 | F13: 45628 | G13: 45992 | H13: ZARTASH BAIG | I13: 3310438483945 | J13: CITY (MANUAL) | K13: - | L13: L12B51028124 | M13: NFBGN8626RR044837 | N13: 76623/1 | O13: Central | P13: 0423 | Q13: 663549 | R13: 45632 | S13: 46727 | T13: 4719000 | W13: =T13 -> 4719000 | X13: 1.5 | Y13: =W13*X13% -> 70785 | AA13: paid | AB13: 1141072451 | AC13: 45687 | AD13: DISBURSED | AE13: 0 | AF13: KHI/HO/D/MO/PC COMP/C/103201/2/12/2024 | AH13: 70785 | AI13: =Y13-AH13 -> 0
A14: Fresh | B14: 77272/1 | C14: 45627 | D14: SALAAM TAKAFUL LTD | E14: KHI/HO/D/MO/PC COMP/C/103201/20/12/2024 | F14: 45628 | G14: 45992 | H14: TAHIR MUNIR | I14: 3520015623585 | J14: SWIFT GLX CVT | K14: AQD-385 | L14: 1014611 | M14: 114605 | N14: 77272/1 | O14: Central | P14: 0329 | Q14: 515375 | R14: 45645 | S14: 46392 | T14: 4500000 | W14: =T14 -> 4500000 | X14: 1.5 | Y14: =W14*X14% -> 67500 | AA14: paid | AB14: 1141072451 | AC14: 45687 | AD14: DISBURSED | AE14: 0 | AF14: KHI/HO/D/MO/PC COMP/C/103201/20/12/2024 | AH14: 67500 | AI14: =Y14-AH14 -> 0
A15: Fresh | B15: 76464/1 | C15: 45627 | D15: SALAAM TAKAFUL LTD | E15: KHI/HO/D/MO/PC COMP/C/103201/21/12/2024 | F15: 45628 | G15: 45992 | H15: MUHAMMAD ANAS | I15: 3410162869717 | J15: ALTO VXR (METALLIC) | K15: - | L15: 331808 | M15: 1231810 | N15: 76464/1 | O15: Central | P15: 0401 | Q15: 662662 | R15: 45644 | S15: 47488 | T15: 2707000 | W15: =T15 -> 2707000 | X15: 2 | Y15: =W15*X15% -> 54140 | AA15: paid | AB15: 1141072451 | AC15: 45687 | AD15: DISBURSED | AE15: 0 | AF15: KHI/HO/D/MO/PC COMP/C/103201/21/12/2024 | AH15: 54140 | AI15: =Y15-AH15 -> 0
A16: Fresh | B16: 77266/1 | C16: 45627 | D16: SALAAM TAKAFUL LTD | E16: KHI/HO/D/MO/PC COMP/C/103201/22/12/2024 | F16: 45628 | G16: 45992 | H16: MUHAMMAD SAJEEL ZAHOOR | I16: 3410132102521 | J16: ALTO VXL AGS | K16: - | L16: 328826 | M16: 1228774 | N16: 77266/1 | O16: Central | P16: 0423 | Q16: 622308 | R16: 45646 | S16: 47488 | T16: 3045000 | W16: =T16 -> 3045000 | X16: 2 | Y16: =W16*X16% -> 60900 | AA16: paid | AB16: 1141072451 | AC16: 45687 | AD16: DISBURSED | AE16: 0 | AF16: KHI/HO/D/MO/PC COMP/C/103201/22/12/2024 | AH16: 60900 | AI16: =Y16-AH16 -> 0
A17: Fresh | B17: 75925/1 | C17: 45627 | D17: SALAAM TAKAFUL LTD | E17: KHI/HO/D/MO/PC COMP/C/103201/23/12/2024 | F17: 45628 | G17: 45992 | H17: MUHAMMAD RAHEEL | I17: 4240126960557 | J17: CHANGAN KARVAAN | K17: CZ-7606 | L17: 90503312 | M17: 1011260 | N17: 75925/1 | O17: South | P17: 0144 | Q17: 661038 | R17: 45649 | S17: 47488 | T17: 2280000 | W17: =T17 -> 2280000 | X17: 2 | Y17: =W17*X17% -> 45600 | AA17: paid | AB17: 1141072451 | AC17: 45687 | AD17: DISBURSED | AE17: 0 | AF17: KHI/HO/D/MO/PC COMP/C/103201/23/12/2024 | AH17: 45600 | AI17: =Y17-AH17 -> 0
A18: Fresh | B18: 76653/1 | C18: 45627 | D18: SALAAM TAKAFUL LTD | E18: KHI/HO/D/MO/PC COMP/C/103201/24/12/2024 | F18: 45628 | G18: 45992 | H18: MUHAMMAD UMER NAEEM | I18: 3840301125149 | J18: BRV | K18: AJA-286 | L18: L15Z13509681 | M18: NFBDG1838JR009638 | N18: 76653/1 | O18: Central | P18: 0423 | Q18: 663603 | R18: 45646 | S18: 46757 | T18: 4000000 | W18: =T18 -> 4000000 | X18: 1.5 | Y18: =W18*X18% -> 60000 | AA18: paid | AB18: 1141072451 | AC18: 45687 | AD18: DISBURSED | AE18: 0 | AF18: KHI/HO/D/MO/PC COMP/C/103201/24/12/2024 | AH18: 60000 | AI18: =Y18-AH18 -> 0
A19: Fresh | B19: 76934/1 | C19: 45627 | D19: SALAAM TAKAFUL LTD | E19: KHI/HO/D/MO/PC COMP/C/103201/25/12/2024 | F19: 45644 | G19: 46008 | H19: MUHAMMAD SHOAIB | I19: 3520278654373 | J19: ALTO VXR (METALLIC) | K19: - | L19: 331314 | M19: 1231222 | N19: 76934/1 | O19: Central | P19: 0329 | Q19: 663008 | R19: 45646 | S19: 47488 | T19: 2707000 | W19: =T19 -> 2707000 | X19: 2 | Y19: =W19*X19% -> 54140 | AA19: paid | AB19: 1141072451 | AC19: 45687 | AD19: DISBURSED | AE19: 0 | AF19: KHI/HO/D/MO/PC COMP/C/103201/25/12/2024 | AH19: 54140 | AI19: =Y19-AH19 -> 0
A20: Fresh | B20: 76578/1 | C20: 45627 | D20: SALAAM TAKAFUL LTD | E20: KHI/HO/D/MO/PC COMP/C/103201/26/12/2024 | F20: 45644 | G20: 46008 | H20: KAMRAN NAHEED | I20: 1420286106303 | J20: ALTO VXR (METALLIC) | K20: ASK-798 | L20: 148996 | M20: 1049029 | N20: 76578/1 | O20: North | P20: 0804 | Q20: 565530 | R20: 45652 | S20: 47488 | T20: 2400000 | W20: =T20 -> 2400000 | X20: 2 | Y20: =W20*X20% -> 48000 | AA20: paid | AB20: 1141072451 | AC20: 45687 | AD20: DISBURSED | AE20: 0 | AF20: KHI/HO/D/MO/PC COMP/C/103201/26/12/2024 | AH20: 48000 | AI20: =Y20-AH20 -> 0
A21: Fresh | B21: 76461/1 | C21: 45627 | D21: SALAAM TAKAFUL LTD | E21: KHI/HO/D/MO/PC COMP/C/103201/27/12/2024 | F21: 45644 | G21: 46008 | H21: FAHAD ZULFIQAR | I21: 3520258048773 | J21: ALTO VXR (METALLIC) | K21: - | L21: 330848 | M21: 1230674 | N21: 76461/1 | O21: Central | P21: 0329 | Q21: 663018 | R21: 45649 | S21: 47488 | T21: 2707000 | W21: =T21 -> 2707000 | X21: 2 | Y21: =W21*X21% -> 54140 | AA21: paid | AB21: 1141072451 | AC21: 45687 | AD21: DISBURSED | AE21: 0 | AF21: KHI/HO/D/MO/PC COMP/C/103201/27/12/2024 | AH21: 54140 | AI21: =Y21-AH21 -> 0
A22: Fresh | B22: 76952/1 | C22: 45627 | D22: SALAAM TAKAFUL LTD | E22: KHI/HO/D/MO/PC COMP/C/103201/28/12/2024 | F22: 45644 | G22: 46008 | H22: AFSHAN IMRAN | I22: 4210116074962 | J22: CIVIC (AUTOMATIC) | K22: BPN-261 | L22: 12947345 | M22: R050773 | N22: 76952/1 | O22: South | P22: 0144 | Q22: 665061 | R22: 45646 | S22: 46757 | T22: 5025000 | W22: =T22 -> 5025000 | X22: 1.5 | Y22: =W22*X22% -> 75375 | AA22: paid | AB22: 1141072451 | AC22: 45687 | AD22: DISBURSED | AE22: 0 | AF22: KHI/HO/D/MO/PC COMP/C/103201/28/12/2024 | AH22: 75375 | AI22: =Y22-AH22 -> 0
A23: Fresh | B23: 76628/1 | C23: 45627 | D23: SALAAM TAKAFUL LTD | E23: KHI/HO/D/MO/PC COMP/C/103201/29/12/2024 | F23: 45645 | G23: 46009 | H23: QASIM MEHMOOD | I23: 3460322173787 | J23: ALTO VXL | K23: LEA-19A-7184 | L23: 6R108402 | M23: NF1AET306H1008409 | N23: 76628/1 | O23: Central | P23: 0443 | Q23: 664161 | R23: 45649 | S23: 47488 | T23: 2400000 | W23: =T23 -> 2400000 | X23: 2 | Y23: =W23*X23% -> 48000 | AA23: paid | AB23: 1141072451 | AC23: 45687 | AD23: DISBURSED | AE23: 0 | AF23: KHI/HO/D/MO/PC COMP/C/103201/29/12/2024 | AH23: 48000 | AI23: =Y23-AH23 -> 0
A24: Fresh | B24: 74234/1 | C24: 45627 | D24: SALAAM TAKAFUL LTD | E24: KHI/HO/D/MO/PC COMP/C/103201/3/12/2024 | F24: 45628 | G24: 45992 | H24: AJAZ FAREED | I24: 3210282566343 | J24: ALTO VXL | K24: - | L24: 328165 | M24: 1228010 | N24: 74234/1 | O24: Central | P24: 0567 | Q24: 654657 | R24: 45636 | S24: 47457 | T24: 3045000 | W24: =T24 -> 3045000 | X24: 2 | Y24: =W24*X24% -> 60900 | AA24: paid | AB24: 1141072451 | AC24: 45687 | AD24: DISBURSED | AE24: 0 | AF24: KHI/HO/D/MO/PC COMP/C/103201/3/12/2024 | AH24: 60900 | AI24: =Y24-AH24 -> 0
A25: Fresh | B25: 75505/1 | C25: 45627 | D25: SALAAM TAKAFUL LTD | E25: KHI/HO/D/MO/PC COMP/C/103201/30/12/2024 | F25: 45649 | G25: 46013 | H25: SYED SAAD UL HAQUE | I25: 4240195592221 | J25: CULTUS VXL (METALIC) | K25: BJL-995 | L25: PK10K100978 | M25: H10000982 | N25: 75505/1 | O25: South | P25: 0144 | Q25: 659473 | R25: 45650 | S25: 47123 | T25: 2150000 | W25: =T25 -> 2150000 | X25: 2 | Y25: =W25*X25% -> 43000 | AA25: paid | AB25: 1141072451 | AC25: 45687 | AD25: DISBURSED | AE25: 0 | AF25: KHI/HO/D/MO/PC COMP/C/103201/30/12/2024 | AH25: 43000 | AI25: =Y25-AH25 -> 0
A26: Fresh | B26: 74895/1 | C26: 45627 | D26: SALAAM TAKAFUL LTD | E26: KHI/HO/D/MO/PC COMP/C/103201/31/12/2024 | F26: 45649 | G26: 46013 | H26: SYED NAVEED HUSSAIN SHAH | I26: 3740552142033 | J26: ALTO VXL AGS | K26: - | L26: 332304 | M26: 1232332 | N26: 74895/1 | O26: North | P26: 0804 | Q26: 636707 | R26: 45659 | S26: 47123 | T26: 3045000 | W26: =T26 -> 3045000 | X26: 2 | Y26: =W26*X26% -> 60900 | AA26: paid | AB26: 1141072451 | AC26: 45687 | AD26: DISBURSED | AE26: 0 | AF26: KHI/HO/D/MO/PC COMP/C/103201/31/12/2024 | AH26: 60900 | AI26: =Y26-AH26 -> 0
A27: Fresh | B27: 77497/1 | C27: 45627 | D27: SALAAM TAKAFUL LTD | E27: KHI/HO/D/MO/PC COMP/C/103201/32/12/2024 | F27: 45650 | G27: 46014 | H27: FAISAL MUGHEES ALMAS | I27: 3630284301599 | J27: TOYOTA CROSS | K27: ATN-636 | L27: 7049 | M27: 905936 | N27: 77497/1 | O27: Central | P27: 0431 | Q27: 590393 | R27: 45656 | S27: 46392 | T27: 9000000 | W27: =T27 -> 9000000 | X27: 1.5 | Y27: =W27*X27% -> 135000 | AA27: paid | AB27: 1141072451 | AC27: 45687 | AD27: DISBURSED | AE27: 0 | AF27: KHI/HO/D/MO/PC COMP/C/103201/32/12/2024 | AH27: 135000 | AI27: =Y27-AH27 -> 0
A28: Fresh | B28: 77315/1 | C28: 45627 | D28: SALAAM TAKAFUL LTD | E28: KHI/HO/D/MO/PC COMP/C/103201/33/12/2024 | F28: 45650 | G28: 46014 | H28: MUHAMMAD NOSHERWAN ADIL RANA | I28: 3520223756863 | J28: COROLLA GLI A/T | K28: LEH-18-2954 | L28: 523836 | M28: 149745 | N28: 77315/1 | O28: Central | P28: 0329 | Q28: 666495 | R28: 45650 | S28: 46757 | T28: 4000000 | W28: =T28 -> 4000000 | X28: 1.5 | Y28: =W28*X28% -> 60000 | AA28: paid | AB28: 1141072451 | AC28: 45687 | AD28: DISBURSED | AE28: 0 | AF28: KHI/HO/D/MO/PC COMP/C/103201/33/12/2024 | AH28: 60000 | AI28: =Y28-AH28 -> 0
A29: Fresh | B29: 77018/1 | C29: 45627 | D29: SALAAM TAKAFUL LTD | E29: KHI/HO/D/MO/PC COMP/C/103201/34/12/2024 | F29: 45650 | G29: 46014 | H29: MUHAMMAD UMER | I29: 3520226156293 | J29: TOYOTA COROLLA ALTIS (AUTOMATIC) | K29: LEA-17A-2088 | L29: Q040210 | M29: 6017692 | N29: 77018/1 | O29: Central | P29: 0329 | Q29: 665137 | R29: 45653 | S29: 46757 | T29: 3200000 | W29: =T29 -> 3200000 | X29: 2 | Y29: =W29*X29% -> 64000 | AA29: paid | AB29: 1141072451 | AC29: 45687 | AD29: DISBURSED | AE29: 0 | AF29: KHI/HO/D/MO/PC COMP/C/103201/34/12/2024 | AH29: 64000 | AI29: =Y29-AH29 -> 0
A30: Fresh | B30: 77056/1 | C30: 45627 | D30: SALAAM TAKAFUL LTD | E30: KHI/HO/D/MO/PC COMP/C/103201/35/12/2024 | F30: 45650 | G30: 46014 | H30: ATIF SHAFIQUE SHAMI | I30: 3520173234079 | J30: ALTO VXL AGS | K30: - | L30: 6R331938 | M30: 1232014 | N30: 77056/1 | O30: Central | P30: 0306 | Q30: 230347 | R30: 45656 | S30: 47488 | T30: 3045000 | W30: =T30 -> 3045000 | X30: 2 | Y30: =W30*X30% -> 60900 | AA30: paid | AB30: 1141072451 | AC30: 45687 | AD30: DISBURSED | AE30: 0 | AF30: KHI/HO/D/MO/PC COMP/C/103201/35/12/2024 | AH30: 60900 | AI30: =Y30-AH30 -> 0
A31: Fresh | B31: 76234/1 | C31: 45627 | D31: SALAAM TAKAFUL LTD | E31: KHI/HO/D/MO/PC COMP/C/103201/4/12/2024 | F31: 45628 | G31: 45992 | H31: NAVEED HASSAN | I31: 3520261488379 | J31: YARIS | K31: APC-885 | L31: 2A42070 | M31: 9515574 | N31: 76234/1 | O31: Central | P31: 0329 | Q31: 661875 | R31: 45632 | S31: 46727 | T31: 4400000 | W31: =T31 -> 4400000 | X31: 1.5 | Y31: =W31*X31% -> 66000 | AA31: paid | AB31: 1141072451 | AC31: 45687 | AD31: DISBURSED | AE31: 3 | AF31: KHI/HO/D/MO/PC COMP/C/103201/4/12/2024 | AH31: 66000 | AI31: =Y31-AH31 -> 0
A32: Fresh | B32: 76747/1 | C32: 45627 | D32: SALAAM TAKAFUL LTD | E32: KHI/HO/D/MO/PC COMP/C/103201/5/12/2024 | F32: 45628 | G32: 45992 | H32: AZMAT ULLAH BAJWA | I32: 3520228131165 | J32: KIA SPORTAGE | K32: AJD-510 | L32: 329798 | M32: 309745 | N32: 76747/1 | O32: Central | P32: 0329 | Q32: 139479 | R32: 45632 | S32: 46727 | T32: 6600000 | W32: =T32 -> 6600000 | X32: 1.5 | Y32: =W32*X32% -> 99000 | AA32: paid | AB32: 1141072451 | AC32: 45687 | AD32: DISBURSED | AE32: 3 | AF32: KHI/HO/D/MO/PC COMP/C/103201/5/12/2024 | AH32: 99000 | AI32: =Y32-AH32 -> 0
A33: Fresh | B33: 75876/1 | C33: 45627 | D33: SALAAM TAKAFUL LTD | E33: KHI/HO/D/MO/PC COMP/C/103201/6/12/2024 | F33: 45631 | G33: 45995 | H33: MUHAMMAD AKBER | I33: 4240161836551 | J33: ALTO VXL AGS | K33: BVA-268 | L33: R185593 | M33: H1085501 | N33: 75876/1 | O33: South | P33: 0144 | Q33: 660828 | R33: 45636 | S33: 47457 | T33: 2200000 | W33: =T33 -> 2200000 | X33: 2 | Y33: =W33*X33% -> 44000 | AA33: paid | AB33: 1141072451 | AC33: 45687 | AD33: DISBURSED | AE33: 0 | AF33: KHI/HO/D/MO/PC COMP/C/103201/6/12/2024 | AH33: 44000 | AI33: =Y33-AH33 -> 0
A34: Fresh | B34: 76613/1 | C34: 45627 | D34: SALAAM TAKAFUL LTD | E34: KHI/HO/D/MO/PC COMP/C/103201/7/12/2024 | F34: 45628 | G34: 45992 | H34: SYED OMAR AHMED | I34: 4210139215135 | J34: CIVIC (AUTOMATIC) | K34: BMX-837 | L34: 12937022 | M34: R040448 | N34: 76613/1 | O34: South | P34: 0144 | Q34: 663443 | R34: 45636 | S34: 46727 | T34: 4750000 | W34: =T34 -> 4750000 | X34: 1.5 | Y34: =W34*X34% -> 71250 | AA34: paid | AB34: 1141072451 | AC34: 45687 | AD34: DISBURSED | AE34: 0 | AF34: KHI/HO/D/MO/PC COMP/C/103201/7/12/2024 | AH34: 71250 | AI34: =Y34-AH34 -> 0
A35: Fresh | B35: 76634/1 | C35: 45627 | D35: SALAAM TAKAFUL LTD | E35: KHI/HO/D/MO/PC COMP/C/103201/8/12/2024 | F35: 45628 | G35: 45992 | H35: KANEEZ FATIMA | I35: 4200030002210 | J35: KIA PICANTO | K35: BRG-587 | L35: 168846 | M35: 700615 | N35: 76634/1 | O35: South | P35: 0144 | Q35: 663574 | R35: 45642 | S35: 47488 | T35: 2600000 | W35: =T35 -> 2600000 | X35: 2 | Y35: =W35*X35% -> 52000 | AA35: paid | AB35: 1141072451 | AC35: 45687 | AD35: DISBURSED | AE35: 0 | AF35: KHI/HO/D/MO/PC COMP/C/103201/8/12/2024 | AH35: 52000 | AI35: =Y35-AH35 -> 0
A36: Fresh | B36: 77242/1 | C36: 45627 | D36: SALAAM TAKAFUL LTD | E36: KHI/HO/D/MO/PC COMP/C/103201/9/12/2024 | F36: 45628 | G36: 45992 | H36: MUHAMMAD KASHIF | I36: 3520273884939 | J36: TOYOTA COROLLA GLI | K36: BMC-060 | L36: 515834 | M36: 4141994 | N36: 77242/1 | O36: Central | P36: 0329 | Q36: 662881 | R36: 45643 | S36: 47123 | T36: 3550000 | W36: =T36 -> 3550000 | X36: 1.5 | Y36: =W36*X36% -> 53250 | AA36: paid | AB36: 1141072451 | AC36: 45687 | AD36: DISBURSED | AE36: 0 | AF36: KHI/HO/D/MO/PC COMP/C/103201/9/12/2024 | AH36: 53250 | AI36: =Y36-AH36 -> 0
A37: Fresh | B37: 76541/1 | C37: 45627 | D37: SALAAM TAKAFUL LTD | E37: KHI/HO/D/MO/CV/C/103846/1/12/2024 | F37: 45638 | G37: 46002 | H37: ALI . | I37: 3520244919747 | J37: RAVI | K37: - | L37: 394454 | M37: 499094 | N37: 76541/1 | O37: Central | P37: 0329 | Q37: 647832 | R37: 45643 | S37: 47488 | T37: 1856000 | W37: =T37 -> 1856000 | X37: 2 | Y37: =W37*X37% -> 37120 | AA37: paid | AB37: 1141072451 | AC37: 45687 | AD37: DISBURSED | AE37: 0 | AF37: KHI/HO/D/MO/CV/C/103846/1/12/2024 | AH37: 37120 | AI37: =Y37-AH37 -> 0
A38: Fresh | B38: 76943/1 | C38: 45627 | D38: SALAAM TAKAFUL LTD | E38: KHI/HO/D/MO/CV/C/103846/2/12/2024 | F38: 45644 | G38: 46008 | H38: GUL NAWAZ KHAN | I38: 2110502379687 | J38: RAVI | K38: - | L38: 394540 | M38: 499218 | N38: 76943/1 | O38: North | P38: 0823 | Q38: 665003 | R38: 45652 | S38: 46757 | T38: 1856000 | W38: =T38 -> 1856000 | X38: 2 | Y38: =W38*X38% -> 37120 | AA38: paid | AB38: 1141072451 | AC38: 45687 | AD38: DISBURSED | AE38: 0 | AF38: KHI/HO/D/MO/CV/C/103846/2/12/2024 | AH38: 37120 | AI38: =Y38-AH38 -> 0
A39: Fresh | B39: 76818/1 | C39: 45597 | D39: SALAAM TAKAFUL LTD | E39: KHI/HO/D/MO/PC COMP/C/101342/44/11/2024 | F39: 45625 | G39: 45989 | H39: MUHAMMAD MUSTAFA ZAIDI | I39: 3610102621529 | J39: YARIS | K39: AWU-417 | L39: 42433 | M39: 7026645 | N39: 76818/1 | O39: Central | P39: 0431 | Q39: 552825 | R39: 45636 | S39: 47092 | T39: 3700000 | W39: =T39 -> 3700000 | X39: 1.5 | Y39: =W39*X39% -> 55500 | AA39: paid | AB39: 1141072451 | AC39: 45687 | AD39: DISBURSED | AE39: 0 | AF39: KHI/HO/D/MO/PC COMP/C/101342/44/11/2024 | AH39: 55500 | AI39: =Y39-AH39 -> 0
Y41: =SUBTOTAL(9,Y2:Y39) -> 2272610 | AH41: =SUBTOTAL(9,AH2:AH39) -> 2280130

Sheet Renewal
A1: Fresh / Renewal | B1: Proposal No. | C1: Billing Month | D1: Takaful Company | E1: PMD / Cert | F1: Takaful Start Date | G1: Takaful End Date | H1: Customer Name | I1: CNIC | J1: Vehicle Make | K1: Reg. No | L1: Engine No | M1: Chassis No | N1: Proposal No. | O1: Region | P1: Unit ID | Q1: BR # | R1: Financing Date | S1: Maturity Date | T1: Asset Value | U1: Dep. % | V1: Dep. Amount | W1: Sum Cover Amount | X1: Takaful Rate | Y1: Premium Amount | Z1: For Takaful Company Rectifications | AA1: For COD Status | AB1: PO No. | AC1: PO Dates | AD1: Proposal Status | AE1: Default Case (Overdue Days) | AF1: Policy # | AG1: Tms Prem | AH1: Difference
A2: Renewal | B2: 68516/1 | C2: 45627 | D2: SALAAM TAKAFUL LTD | E2: KHI/HO/D/MO/PC COMP/C/103764/8/12/2024 | F2: 45645 | G2: 46009 | H2: MUHAMMAD KASHIF | I2: 3520197275909 | J2: SUZUKI MEHRAN VX | K2: LED-15-3088 | L2: 608606 | M2: 1147137 | N2: 68516/1 | O2: Central | P2: 0329 | Q2: 629773 | R2: 45287 | S2: 46392 | T2: 900000 | U2: 10 | V2: =T2*U2% -> 90000 | W2: =T2-V2 -> 810000 | X2: 2 | Y2: =W2*X2% -> 16200 | AA2: paid | AB2: 1141072474 | AC2: 45688 | AD2: DISBURSED | AE2: 0 | AF2: KHI/HO/D/MO/PC COMP/C/103764/8/12/2024 | AG2: 16200 | AH2: =Y2-AG2 -> 0
A3: Renewal | B3: 44871/2 | C3: 45627 | D3: SALAAM TAKAFUL LTD | E3: KHI/HO/D/MO/CV/C/104416/1/12/2024 | F3: 45629 | G3: 45993 | H3: AMJAD PERVAIZ | I3: 4220178497155 | J3: SUZUKI RAVI VX EURO II | K3: KZ-4320 | L3: 364707 | M3: 469365 | N3: 44871/2 | O3: South | P3: 0144 | Q3: 506978 | R3: 44175 | S3: 45996 | T3: 1034000 | U3: 25 | V3: =T3*U3% -> 258500 | W3: =T3-V3 -> 775500 | X3: 2.5 | Y3: =W3*X3% -> 19387.5 | AA3: paid | AB3: 1141072474 | AC3: 45688 | AD3: DISBURSED | AE3: 0 | AF3: KHI/HO/D/MO/CV/C/104416/1/12/2024 | AG3: 19388 | AH3: =Y3-AG3 -> -0.5
A4: Renewal | B4: 45079/1 | C4: 45627 | D4: SALAAM TAKAFUL LTD | E4: KHI/HO/D/MO/CV/C/104416/2/12/2024 | F4: 45637 | G4: 46001 | H4: DANISH ATTA | I4: 3740538789797 | J4: SUZUKI RAVI VX EURO II | K4: TAA-981 | L4: 364993 | M4: 469697 | N4: 45079/1 | O4: North | P4: 0804 | Q4: 501013 | R4: 44182 | S4: 46027 | T4: 1034000 | U4: 25 | V4: =T4*U4% -> 258500 | W4: =T4-V4 -> 775500 | X4: 2.5 | Y4: =W4*X4% -> 19387.5 | AA4: paid | AB4: 1141072474 | AC4: 45688 | AD4: DISBURSED | AE4: 0 | AF4: KHI/HO/D/MO/CV/C/104416/2/12/2024 | AG4: 19388 | AH4: =Y4-AG4 -> -0.5
A5: Renewal | B5: 51853/1 | C5: 45627 | D5: SALAAM TAKAFUL LTD | E5: KHI/HO/D/MO/PC COMP/C/103764/94/12/2024 | F5: 45641 | G5: 46005 | H5: USMAN SHAFQAT | I5: 3520183617665 | J5: PRINCE PEARL | K5: AGG-058 | L5: M05605717W | M5: M21K03228 | N5: 51853/1 | O5: Central | P5: 0329 | Q5: 553524 | R5: 44547 | S5: 46392 | T5: 1111000 | U5: 20 | V5: =T5*U5% -> 222200 | W5: =T5-V5 -> 888800 | X5: 1.75 | Y5: =W5*X5% -> 15554 | AA5: paid | AB5: 1141072474 | AC5: 45688 | AD5: DISBURSED | AE5: 0 | AF5: KHI/HO/D/MO/PC COMP/C/103764/94/12/2024 | AG5: 15554 | AH5: =Y5-AG5 -> 0
A6: Renewal | B6: 53000/1 | C6: 45627 | D6: SALAAM TAKAFUL LTD | E6: KHI/HO/D/MO/CV/C/104415/1/12/2024 | F6: 45634 | G6: 45998 | H6: SADAM HUSSAIN | I6: 3520132884715 | J6: SUZUKI RAVI VX EURO II | K6: CAH-2994 | L6: 377888 | M6: 482551 | N6: 53000/1 | O6: Central | P6: 0329 | Q6: 554395 | R6: 44544 | S6: 46361 | T6: 1117000 | U6: 20 | V6: =T6*U6% -> 223400 | W6: =T6-V6 -> 893600 | X6: 1.75 | Y6: =W6*X6% -> 15638 | AA6: paid | AB6: 1141072474 | AC6: 45688 | AD6: DISBURSED | AE6: 62 | AF6: KHI/HO/D/MO/CV/C/104415/1/12/2024 | AG6: 15638 | AH6: =Y6-AG6 -> 0
A7: Renewal | B7: 53115/1 | C7: 45627 | D7: SALAAM TAKAFUL LTD | E7: KHI/HO/D/MO/CV/C/104415/2/12/2024 | F7: 45641 | G7: 46005 | H7: MUHAMMAD SHAHZAD | I7: 3520117693435 | J7: SUZUKI RAVI VX EURO II | K7: CAH-2835 | L7: 378041 | M7: 482692 | N7: 53115/1 | O7: Central | P7: 0329 | Q7: 558104 | R7: 44552 | S7: 46392 | T7: 1117000 | U7: 20 | V7: =T7*U7% -> 223400 | W7: =T7-V7 -> 893600 | X7: 1.75 | Y7: =W7*X7% -> 15638 | AA7: paid | AB7: 1141072474 | AC7: 45688 | AD7: DISBURSED | AE7: 0 | AF7: KHI/HO/D/MO/CV/C/104415/2/12/2024 | AG7: 15638 | AH7: =Y7-AG7 -> 0
A8: Renewal | B8: 53151/1 | C8: 45627 | D8: SALAAM TAKAFUL LTD | E8: KHI/HO/D/MO/CV/C/104415/3/12/2024 | F8: 45643 | G8: 46007 | H8: MUHAMMAD MUBASHIR NAZAR AWAN | I8: 3740517536053 | J8: SUZUKI RAVI VX EURO II | K8: TC-13 | L8: 378815 | M8: 483469 | N8: 53151/1 | O8: North | P8: 0804 | Q8: 336775 | R8: 44551 | S8: 46392 | T8: 1117000 | U8: 20 | V8: =T8*U8% -> 223400 | W8: =T8-V8 -> 893600 | X8: 1.75 | Y8: =W8*X8% -> 15638 | AA8: paid | AB8: 1141072474 | AC8: 45688 | AD8: DISBURSED | AE8: 0 | AF8: KHI/HO/D/MO/CV/C/104415/3/12/2024 | AG8: 15638 | AH8: =Y8-AG8 -> 0
A9: Renewal | B9: 53246/1 | C9: 45627 | D9: SALAAM TAKAFUL LTD | E9: KHI/HO/D/MO/CV/C/104415/4/12/2024 | F9: 45646 | G9: 46010 | H9: NAVEED LATIF | I9: 3520115409715 | J9: SUZUKI RAVI VX EURO II | K9: CAH-2727 | L9: 378664 | M9: 483328 | N9: 53246/1 | O9: Central | P9: 0329 | Q9: 554600 | R9: 44553 | S9: 46392 | T9: 1117000 | U9: 20 | V9: =T9*U9% -> 223400 | W9: =T9-V9 -> 893600 | X9: 1.75 | Y9: =W9*X9% -> 15638 | AA9: paid | AB9: 1141072474 | AC9: 45688 | AD9: DISBURSED | AE9: 32 | AF9: KHI/HO/D/MO/CV/C/104415/4/12/2024 | AG9: 15638 | AH9: =Y9-AG9 -> 0
A10: Renewal | B10: 53365/1 | C10: 45627 | D10: SALAAM TAKAFUL LTD | E10: KHI/HO/D/MO/CV/C/104415/5/12/2024 | F10: 45649 | G10: 46013 | H10: KHAWAR ABBAS | I10: 3540112384833 | J10: SUZUKI RAVI VX EURO II | K10: CAH-6141 | L10: 378553 | M10: 483215 | N10: 53365/1 | O10: Central | P10: 0329 | Q10: 562324 | R10: 44559 | S10: 46392 | T10: 1117000 | U10: 20 | V10: =T10*U10% -> 223400 | W10: =T10-V10 -> 893600 | X10: 1.75 | Y10: =W10*X10% -> 15638 | AA10: paid | AB10: 1141072474 | AC10: 45688 | AD10: DISBURSED | AE10: 0 | AF10: KHI/HO/D/MO/CV/C/104415/5/12/2024 | AG10: 15638 | AH10: =Y10-AG10 -> 0
A11: Renewal | B11: 53088/1 | C11: 45627 | D11: SALAAM TAKAFUL LTD | E11: KHI/HO/D/MO/PC COMP/C/103764/87/12/2024 | F11: 45639 | G11: 46003 | H11: MUHAMMAD AKBAR | I11: 3310049530247 | J11: SUZUKI BOLAN VX | K11: AGH-723 | L11: 1017427 | M11: 1133917 | N11: 53088/1 | O11: Central | P11: 0423 | Q11: 553216 | R11: 44546 | S11: 46392 | T11: 1149000 | U11: 20 | V11: =T11*U11% -> 229800 | W11: =T11-V11 -> 919200 | X11: 1.75 | Y11: =W11*X11% -> 16086 | AA11: paid | AB11: 1141072474 | AC11: 45688 | AD11: DISBURSED | AE11: 0 | AF11: KHI/HO/D/MO/PC COMP/C/103764/87/12/2024 | AG11: 16086 | AH11: =Y11-AG11 -> 0
A12: Renewal | B12: 53598/1 | C12: 45627 | D12: SALAAM TAKAFUL LTD | E12: KHI/HO/D/MO/PC COMP/C/103764/132/12/2024 | F12: 45657 | G12: 46021 | H12: QAMAR ABBAS | I12: 3310498186457 | J12: SUZUKI BOLAN STD VX EURO | K12: AWY-904 | L12: 1017988 | M12: PK01134520 | N12: 53598/1 | O12: Central | P12: 0556 | Q12: 526529 | R12: 44561 | S12: 46392 | T12: 1149000 | U12: 20 | V12: =T12*U12% -> 229800 | W12: =T12-V12 -> 919200 | X12: 1.75 | Y12: =W12*X12% -> 16086 | AA12: paid | AB12: 1141072474 | AC12: 45688 | AD12: DISBURSED | AE12: 0 | AF12: KHI/HO/D/MO/PC COMP/C/103764/132/12/2024 | AG12: 16086 | AH12: =Y12-AG12 -> 0
A13: Renewal | B13: 61961/1 | C13: 45627 | D13: SALAAM TAKAFUL LTD | E13: KHI/HO/D/MO/PC COMP/C/103764/78/12/2024 | F13: 45656 | G13: 46020 | H13: MUHAMMAD ASIF | I13: 3520121313341 | J13: FAW FAW V2 M/T | K13: LEA-17-5464 | L13: HG300158 | M13: 5A10798 | N13: 61961/1 | O13: Central | P13: 0329 | Q13: 596062 | R13: 44926 | S13: 46027 | T13: 1200000 | U13: 15 | V13: =T13*U13% -> 180000 | W13: =T13-V13 -> 1020000 | X13: 2 | Y13: =W13*X13% -> 20400 | AA13: paid | AB13: 1141072474 | AC13: 45688 | AD13: DISBURSED | AE13: 0 | AF13: KHI/HO/D/MO/PC COMP/C/103764/78/12/2024 | AG13: 20400 | AH13: =Y13-AG13 -> 0
A14: Renewal | B14: 61867/1 | C14: 45627 | D14: SALAAM TAKAFUL LTD | E14: KHI/HO/D/MO/PC COMP/C/103764/59/12/2024 | F14: 45653 | G14: 46017 | H14: ASIM LATIF | I14: 3520115643635 | J14: SUZUKI BOLAN | K14: LEC-19-8158 | L14: PKT988475 | M14: PK01104951 | N14: 61867/1 | O14: Central | P14: 0329 | Q14: 535024 | R14: 44925 | S14: 46757 | T14: 1225000 | U14: 15 | V14: =T14*U14% -> 183750 | W14: =T14-V14 -> 1041250 | X14: 2 | Y14: =W14*X14% -> 20825 | AA14: paid | AB14: 1141072474 | AC14: 45688 | AD14: DISBURSED | AE14: 0 | AF14: KHI/HO/D/MO/PC COMP/C/103764/59/12/2024 | AG14: 20825 | AH14: =Y14-AG14 -> 0
A15: Renewal | B15: 61894/1 | C15: 45627 | D15: SALAAM TAKAFUL LTD | E15: KHI/HO/D/MO/PC COMP/C/103764/63/12/2024 | F15: 45654 | G15: 46018 | H15: ABID ALI | I15: 3520112667057 | J15: HONDA VAMOS HOBIO | K15: LE-17-6024 | L15: E07Z9106234 | M15: HM41500327 | N15: 61894/1 | O15: Central | P15: 0329 | Q15: 593337 | R15: 44925 | S15: 46392 | T15: 1300000 | U15: 15 | V15: =T15*U15% -> 195000 | W15: =T15-V15 -> 1105000 | X15: 2 | Y15: =W15*X15% -> 22100 | AA15: paid | AB15: 1141072474 | AC15: 45688 | AD15: DISBURSED | AE15: 0 | AF15: KHI/HO/D/MO/PC COMP/C/103764/63/12/2024 | AG15: 22100 | AH15: =Y15-AG15 -> 0
A16: Renewal | B16: 39728/1 | C16: 45627 | D16: SALAAM TAKAFUL LTD | E16: KHI/HO/D/MO/PC COMP/C/103764/157/12/2024 | F16: 45644 | G16: 46008 | H16: MUHAMMAD AZAM BHATTI | I16: 3410125794579 | J16: SUZUKI ALTO VXR | K16: LEA-19-2489- | L16: 125931 | M16: 1025947 | N16: 39728/1 | O16: Central | P16: 0401 | Q16: 461008 | R16: 43819 | S16: 46392 | T16: 1308000 | U16: 30 | V16: =T16*U16% -> 392400 | W16: =T16-V16 -> 915600 | X16: 3.75 | Y16: =W16*X16% -> 34335 | AA16: paid | AB16: 1141072474 | AC16: 45688 | AD16: DISBURSED | AE16: 0 | AF16: KHI/HO/D/MO/PC COMP/C/103764/157/12/2024 | AG16: 34335 | AH16: =Y16-AG16 -> 0
A17: Renewal | B17: 39845/1 | C17: 45627 | D17: SALAAM TAKAFUL LTD | E17: KHI/HO/D/MO/PC COMP/C/103764/156/12/2024 | F17: 45656 | G17: 46020 | H17: BUSHRA SHAAFI | I17: 3520221690708 | J17: SUZUKI ALTO VXR | K17: LE-20-2932 | L17: 124423 | M17: 1024400 | N17: 39845/1 | O17: Central | P17: 0329 | Q17: 474598 | R17: 43830 | S17: 46392 | T17: 1308000 | U17: 30 | V17: =T17*U17% -> 392400 | W17: =T17-V17 -> 915600 | X17: 3.75 | Y17: =W17*X17% -> 34335 | AA17: paid | AB17: 1141072474 | AC17: 45688 | AD17: DISBURSED | AE17: 0 | AF17: KHI/HO/D/MO/PC COMP/C/103764/156/12/2024 | AG17: 34335 | AH17: =Y17-AG17 -> 0
A18: Renewal | B18: 50031/1 | C18: 45627 | D18: SALAAM TAKAFUL LTD | E18: KHI/HO/D/MO/PC COMP/C/103764/99/12/2024 | F18: 45642 | G18: 46006 | H18: NASIR HUSSAIN | I18: 3520217476541 | J18: SUZUKI ALTO VXR E-2 | K18: AHB-571 | L18: 6R191978 | M18: NF1AET306H1091990 | N18: 50031/1 | O18: Central | P18: 0338 | Q18: 542413 | R18: 44552 | S18: 46392 | T18: 1335000 | U18: 20 | V18: =T18*U18% -> 267000 | W18: =T18-V18 -> 1068000 | X18: 2.5 | Y18: =W18*X18% -> 26700 | AA18: paid | AB18: 1141072474 | AC18: 45688 | AD18: DISBURSED | AE18: 0 | AF18: KHI/HO/D/MO/PC COMP/C/103764/99/12/2024 | AG18: 26700 | AH18: =Y18-AG18 -> 0
A19: Renewal | B19: 49988/1 | C19: 45627 | D19: SALAAM TAKAFUL LTD | E19: KHI/HO/D/MO/PC COMP/C/103764/109/12/2024 | F19: 45648 | G19: 46012 | H19: SARFARAZ AHMAD | I19: 3520228966025 | J19: SUZUKI ALTO VXR E-2 | K19: AGH-687 | L19: 6R200748 | M19: H1100763 | N19: 49988/1 | O19: Central | P19: 0329 | Q19: 540393 | R19: 44558 | S19: 46392 | T19: 1335000 | U19: 20 | V19: =T19*U19% -> 267000 | W19: =T19-V19 -> 1068000 | X19: 2.5 | Y19: =W19*X19% -> 26700 | AA19: paid | AB19: 1141072474 | AC19: 45688 | AD19: DISBURSED | AE19: 0 | AF19: KHI/HO/D/MO/PC COMP/C/103764/109/12/2024 | AG19: 26700 | AH19: =Y19-AG19 -> 0
A20: Renewal | B20: 50371/1 | C20: 45627 | D20: SALAAM TAKAFUL LTD | E20: KHI/HO/D/MO/PC COMP/C/103764/118/12/2024 | F20: 45655 | G20: 46019 | H20: GHULAM BAQIR | I20: 3840409410083 | J20: SUZUKI ALTO VXR | K20: AXC-535 | L20: 203259 | M20: 1103237 | N20: 50371/1 | O20: North | P20: 0804 | Q20: 336709 | R20: 44560 | S20: 46392 | T20: 1335000 | U20: 20 | V20: =T20*U20% -> 267000 | W20: =T20-V20 -> 1068000 | X20: 2.5 | Y20: =W20*X20% -> 26700 | AA20: paid | AB20: 1141072474 | AC20: 45688 | AD20: DISBURSED | AE20: 0 | AF20: KHI/HO/D/MO/PC COMP/C/103764/118/12/2024 | AG20: 26700 | AH20: =Y20-AG20 -> 0
A21: Renewal | B21: 50492/1 | C21: 45627 | D21: SALAAM TAKAFUL LTD | E21: KHI/HO/D/MO/PC COMP/C/103764/120/12/2024 | F21: 45655 | G21: 46019 | H21: NABI AHMED | I21: 6110118691361 | J21: SUZUKI ALTO VXR E-2 | K21: AWH-920 | L21: 203268 | M21: 1103168 | N21: 50492/1 | O21: North | P21: 0804 | Q21: 545709 | R21: 44561 | S21: 46392 | T21: 1335000 | U21: 20 | V21: =T21*U21% -> 267000 | W21: =T21-V21 -> 1068000 | X21: 2.5 | Y21: =W21*X21% -> 26700 | AA21: paid | AB21: 1141072474 | AC21: 45688 | AD21: DISBURSED | AE21: 0 | AF21: KHI/HO/D/MO/PC COMP/C/103764/120/12/2024 | AG21: 26700 | AH21: =Y21-AG21 -> 0
A22: Renewal | B22: 61581/1 | C22: 45627 | D22: SALAAM TAKAFUL LTD | E22: KHI/HO/D/MO/CV/C/104418/1/12/2024 | F22: 45641 | G22: 46005 | H22: ZEESHAN IDREES | I22: 3520283906469 | J22: SUZUKI RAVI VX EURO II | K22: CAM-3443 | L22: 387664 | M22: 492323 | N22: 61581/1 | O22: Central | P22: 0329 | Q22: 592814 | R22: 44914 | S22: 46027 | T22: 1424000 | U22: 15 | V22: =T22*U22% -> 213600 | W22: =T22-V22 -> 1210400 | X22: 2 | Y22: =W22*X22% -> 24208 | AA22: paid | AB22: 1141072474 | AC22: 45688 | AD22: DISBURSED | AE22: 0 | AF22: KHI/HO/D/MO/CV/C/104418/1/12/2024 | AG22: 24208 | AH22: =Y22-AG22 -> 0
A23: Renewal | B23: 61895/1 | C23: 45627 | D23: SALAAM TAKAFUL LTD | E23: KHI/HO/D/MO/CV/C/104418/2/12/2024 | F23: 45656 | G23: 46020 | H23: AHSAN REHMAN | I23: 1330256081477 | J23: SUZUKI RAVI VX EURO II | K23: TAB-766 | L23: 388133 | M23: 492793 | N23: 61895/1 | O23: North | P23: 0679 | Q23: 595193 | R23: 44925 | S23: 46757 | T23: 1424000 | U23: 15 | V23: =T23*U23% -> 213600 | W23: =T23-V23 -> 1210400 | X23: 2 | Y23: =W23*X23% -> 24208 | AA23: paid | AB23: 1141072474 | AC23: 45688 | AD23: DISBURSED | AE23: 0 | AF23: KHI/HO/D/MO/CV/C/104418/2/12/2024 | AG23: 24208 | AH23: =Y23-AG23 -> 0
A24: Renewal | B24: 45083/1 | C24: 45627 | D24: SALAAM TAKAFUL LTD | E24: KHI/HO/D/MO/PC COMP/C/103764/135/12/2024 | F24: 45636 | G24: 46000 | H24: MUHAMMAD ADNAN | I24: 6110176044205 | J24: SUZUKI ALTO VXR | K24: ASE-951 | L24: 146437 | M24: 1046411 | N24: 45083/1 | O24: North | P24: 0804 | Q24: 511544 | R24: 44176 | S24: 46361 | T24: 1433000 | U24: 25 | V24: =T24*U24% -> 358250 | W24: =T24-V24 -> 1074750 | X24: 2.5 | Y24: =W24*X24% -> 26868.75 | AA24: paid | AB24: 1141072474 | AC24: 45688 | AD24: DISBURSED | AE24: 0 | AF24: KHI/HO/D/MO/PC COMP/C/103764/135/12/2024 | AG24: 26869 | AH24: =Y24-AG24 -> -0.25
A25: Renewal | B25: 45113/1 | C25: 45627 | D25: SALAAM TAKAFUL LTD | E25: KHI/HO/D/MO/PC COMP/C/103764/146/12/2024 | F25: 45644 | G25: 46008 | H25: ALI NAWAZ | I25: 1730182223775 | J25: SUZUKI ALTO VXR | K25: ASH-432 | L25: 148245 | M25: 1048234 | N25: 45113/1 | O25: North | P25: 0822 | Q25: 510696 | R25: 44189 | S25: 46027 | T25: 1433000 | U25: 25 | V25: =T25*U25% -> 358250 | W25: =T25-V25 -> 1074750 | X25: 2.5 | Y25: =W25*X25% -> 26868.75 | AA25: paid | AB25: 1141072474 | AC25: 45688 | AD25: DISBURSED | AE25: 0 | AF25: KHI/HO/D/MO/PC COMP/C/103764/146/12/2024 | AG25: 26869 | AH25: =Y25-AG25 -> -0.25
A26: Renewal | B26: 45480/1 | C26: 45627 | D26: SALAAM TAKAFUL LTD | E26: KHI/HO/D/MO/PC COMP/C/103764/142/12/2024 | F26: 45657 | G26: 46021 | H26: ASAD ALI | I26: 3740525875351 | J26: SUZUKI ALTO VXR | K26: AMZ-064 | L26: 149313 | M26: 1049171 | N26: 45480/1 | O26: North | P26: 0804 | Q26: 442469 | R26: 44200 | S26: 46027 | T26: 1433000 | U26: 25 | V26: =T26*U26% -> 358250 | W26: =T26-V26 -> 1074750 | X26: 2.5 | Y26: =W26*X26% -> 26868.75 | AA26: paid | AB26: 1141072474 | AC26: 45688 | AD26: DISBURSED | AE26: 0 | AF26: KHI/HO/D/MO/PC COMP/C/103764/142/12/2024 | AG26: 26869 | AH26: =Y26-AG26 -> -0.25
A27: Renewal | B27: 58087/1 | C27: 45627 | D27: SALAAM TAKAFUL LTD | E27: KHI/HO/D/MO/PC COMP/C/103764/61/12/2024 | F27: 45653 | G27: 46017 | H27: MUHAMMAD ALI | I27: 3740599989567 | J27: SUZUKI ALTO VX | K27: BBC-732 | L27: 266053 | M27: 1166047 | N27: 58087/1 | O27: North | P27: 0804 | Q27: 578595 | R27: 44930 | S27: 46757 | T27: 1475000 | U27: 15 | V27: =T27*U27% -> 221250 | W27: =T27-V27 -> 1253750 | X27: 2 | Y27: =W27*X27% -> 25075 | AA27: paid | AB27: 1141072474 | AC27: 45688 | AD27: DISBURSED | AE27: 0 | AF27: KHI/HO/D/MO/PC COMP/C/103764/61/12/2024 | AG27: 25075 | AH27: =Y27-AG27 -> 0
A28: Renewal | B28: 53202/1 | C28: 45627 | D28: SALAAM TAKAFUL LTD | E28: KHI/HO/D/MO/PC COMP/C/103764/102/12/2024 | F28: 45646 | G28: 46010 | H28: RIZWAN YOUNAS | I28: 3520221879425 | J28: SUZUKI ALTO VXR E-2 | K28: AHF-137 | L28: 195246 | M28: 1095236 | N28: 53202/1 | O28: Central | P28: 0329 | Q28: 549667 | R28: 44558 | S28: 47123 | T28: 1508000 | U28: 20 | V28: =T28*U28% -> 301600 | W28: =T28-V28 -> 1206400 | X28: 1.75 | Y28: =W28*X28% -> 21112 | AA28: paid | AB28: 1141072474 | AC28: 45688 | AD28: DISBURSED | AE28: 0 | AF28: KHI/HO/D/MO/PC COMP/C/103764/102/12/2024 | AG28: 21112 | AH28: =Y28-AG28 -> 0
A29: Renewal | B29: 53403/1 | C29: 45627 | D29: SALAAM TAKAFUL LTD | E29: KHI/HO/D/MO/PC COMP/C/103764/114/12/2024 | F29: 45650 | G29: 46014 | H29: FAHAD YAQOOB BAJWA | I29: 3310216661929 | J29: SUZUKI ALTO | K29: AGD-695 | L29: 6R201944 | M29: NF1AET306H1101939 | N29: 53403/1 | O29: Central | P29: 0422 | Q29: 560255 | R29: 44560 | S29: 46392 | T29: 1508000 | U29: 20 | V29: =T29*U29% -> 301600 | W29: =T29-V29 -> 1206400 | X29: 1.75 | Y29: =W29*X29% -> 21112 | AA29: paid | AB29: 1141072474 | AC29: 45688 | AD29: DISBURSED | AE29: 0 | AF29: KHI/HO/D/MO/PC COMP/C/103764/114/12/2024 | AG29: 21112 | AH29: =Y29-AG29 -> 0
A30: Renewal | B30: 53482/1 | C30: 45627 | D30: SALAAM TAKAFUL LTD | E30: KHI/HO/D/MO/PC COMP/C/103764/123/12/2024 | F30: 45655 | G30: 46019 | H30: KHALID JAVED | I30: 3620120378495 | J30: SUZUKI ALTO VXR E-2 | K30: AGY-249 | L30: 195031 | M30: 1095013 | N30: 53482/1 | O30: Central | P30: 0471 | Q30: 558262 | R30: 44561 | S30: 46757 | T30: 1508000 | U30: 20 | V30: =T30*U30% -> 301600 | W30: =T30-V30 -> 1206400 | X30: 1.75 | Y30: =W30*X30% -> 21112 | AA30: paid | AB30: 1141072474 | AC30: 45688 | AD30: DISBURSED | AE30: 0 | AF30: KHI/HO/D/MO/PC COMP/C/103764/123/12/2024 | AG30: 21112 | AH30: =Y30-AG30 -> 0
A31: Renewal | B31: 53249/1 | C31: 45627 | D31: SALAAM TAKAFUL LTD | E31: KHI/HO/D/MO/PC COMP/C/103764/82/12/2024 | F31: 45635 | G31: 45999 | H31: FRANCIS BASHIR | I31: 3520228243895 | J31: CHANGAN KARVAAN PLUS | K31: AGE-389 | L31: 505976 | M31: 1010093 | N31: 53249/1 | O31: Central | P31: 0329 | Q31: 556753 | R31: 44553 | S31: 47123 | T31: 1539000 | U31: 20 | V31: =T31*U31% -> 307800 | W31: =T31-V31 -> 1231200 | X31: 1.75 | Y31: =W31*X31% -> 21546 | AA31: paid | AB31: 1141072474 | AC31: 45688 | AD31: DISBURSED | AE31: 0 | AF31: KHI/HO/D/MO/PC COMP/C/103764/82/12/2024 | AG31: 21546 | AH31: =Y31-AG31 -> 0
A32: Renewal | B32: 55736/1 | C32: 45627 | D32: SALAAM TAKAFUL LTD | E32: KHI/HO/D/MO/PC COMP/C/103764/41/12/2024 | F32: 45640 | G32: 46004 | H32: MIRZA MUHEET BAIG | I32: 4240108092267 | J32: SUZUKI ALTO VXR E-2 | K32: BXG-594 | L32: 254295 | M32: 1154290 | N32: 55736/1 | O32: South | P32: 0135 | Q32: 568402 | R32: 44915 | S32: 47123 | T32: 1546000 | U32: 15 | V32: =T32*U32% -> 231900 | W32: =T32-V32 -> 1314100 | X32: 2.5 | Y32: =W32*X32% -> 32852.5 | AA32: paid | AB32: 1141072474 | AC32: 45688 | AD32: DISBURSED | AE32: 0 | AF32: KHI/HO/D/MO/PC COMP/C/103764/41/12/2024 | AG32: 32853 | AH32: =Y32-AG32 -> -0.5
A33: Renewal | B33: 51249/1 | C33: 45627 | D33: SALAAM TAKAFUL LTD | E33: KHI/HO/D/MO/PC COMP/C/103764/119/12/2024 | F33: 45632 | G33: 45996 | H33: HAMID BIN RAIS | I33: 3310006886795 | J33: SUZUKI WAGON-R VXL E2 | K33: AGA-233 | L33: PK10B224670 | M33: A1J310PK10124683 | N33: 51249/1 | O33: Central | P33: 0423 | Q33: 543089 | R33: 44537 | S33: 47092 | T33: 1610000 | U33: 20 | V33: =T33*U33% -> 322000 | W33: =T33-V33 -> 1288000 | X33: 2.5 | Y33: =W33*X33% -> 32200 | AA33: paid | AB33: 1141072474 | AC33: 45688 | AD33: DISBURSED | AE33: 0 | AF33: KHI/HO/D/MO/PC COMP/C/103764/119/12/2024 | AG33: 32200 | AH33: =Y33-AG33 -> 0
A34: Renewal | B34: 50230/1 | C34: 45627 | D34: SALAAM TAKAFUL LTD | E34: KHI/HO/D/MO/PC COMP/C/103764/83/12/2024 | F34: 45635 | G34: 45999 | H34: MUHAMMAD ASIF RAZA | I34: 3520244469081 | J34: SUZUKI WAGON-R VXL E2 | K34: AGJ-413 | L34: 225285 | M34: 10125239 | N34: 50230/1 | O34: Central | P34: 0329 | Q34: 537464 | R34: 44544 | S34: 46361 | T34: 1610000 | U34: 20 | V34: =T34*U34% -> 322000 | W34: =T34-V34 -> 1288000 | X34: 2.5 | Y34: =W34*X34% -> 32200 | AA34: paid | AB34: 1141072474 | AC34: 45688 | AD34: DISBURSED | AE34: 0 | AF34: KHI/HO/D/MO/PC COMP/C/103764/83/12/2024 | AG34: 32200 | AH34: =Y34-AG34 -> 0
A35: Renewal | B35: 50251/1 | C35: 45627 | D35: SALAAM TAKAFUL LTD | E35: KHI/HO/D/MO/PC COMP/C/103764/104/12/2024 | F35: 45647 | G35: 46011 | H35: MUHAMMAD ABID SADIQ | I35: 3520270937527 | J35: SUZUKI WAGON R VXL | K35: AGD-524 | L35: PK10B225369 | M35: PK10125366 | N35: 50251/1 | O35: Central | P35: 0329 | Q35: 545261 | R35: 44568 | S35: 46392 | T35: 1610000 | U35: 20 | V35: =T35*U35% -> 322000 | W35: =T35-V35 -> 1288000 | X35: 2.5 | Y35: =W35*X35% -> 32200 | AA35: paid | AB35: 1141072474 | AC35: 45688 | AD35: DISBURSED | AE35: 0 | AF35: KHI/HO/D/MO/PC COMP/C/103764/104/12/2024 | AG35: 32200 | AH35: =Y35-AG35 -> 0
A36: Renewal | B36: 50703/1 | C36: 45627 | D36: SALAAM TAKAFUL LTD | E36: KHI/HO/D/MO/PC COMP/C/103764/129/12/2024 | F36: 45656 | G36: 46020 | H36: MUHAMMAD IFTIKHAR | I36: 3460161160157 | J36: SUZUKI WAGON-R VXL E2 | K36: AGQ-343 | L36: 226772 | M36: 10126782 | N36: 50703/1 | O36: Central | P36: 0329 | Q36: 542431 | R36: 44568 | S36: 46392 | T36: 1610000 | U36: 20 | V36: =T36*U36% -> 322000 | W36: =T36-V36 -> 1288000 | X36: 2.5 | Y36: =W36*X36% -> 32200 | AA36: paid | AB36: 1141072474 | AC36: 45688 | AD36: DISBURSED | AE36: 32 | AF36: KHI/HO/D/MO/PC COMP/C/103764/129/12/2024 | AG36: 32200 | AH36: =Y36-AG36 -> 0
A37: Renewal | B37: 45377/1 | C37: 45627 | D37: SALAAM TAKAFUL LTD | E37: KHI/HO/D/MO/PC COMP/C/103764/152/12/2024 | F37: 45649 | G37: 46013 | H37: MUKARRAM ZAIB | I37: 3520236597253 | J37: SUZUKI ALTO VXL AGS E-2 | K37: ABM-836 | L37: 147918 | M37: 1047908 | N37: 45377/1 | O37: Central | P37: 0329 | Q37: 515224 | R37: 44194 | S37: 46757 | T37: 1633000 | U37: 25 | V37: =T37*U37% -> 408250 | W37: =T37-V37 -> 1224750 | X37: 2.5 | Y37: =W37*X37% -> 30618.75 | AA37: paid | AB37: 1141072474 | AC37: 45688 | AD37: DISBURSED | AE37: 0 | AF37: KHI/HO/D/MO/PC COMP/C/103764/152/12/2024 | AG37: 30619 | AH37: =Y37-AG37 -> -0.25
A38: Renewal | B38: 45380/1 | C38: 45627 | D38: SALAAM TAKAFUL LTD | E38: KHI/HO/D/MO/PC COMP/C/103764/154/12/2024 | F38: 45650 | G38: 46014 | H38: AURANGZEB ABID | I38: 3520291006991 | J38: SUZUKI ALTO VXL AGS E-2 | K38: ABH-996 | L38: 147334 | M38: 1047245 | N38: 45380/1 | O38: Central | P38: 0329 | Q38: 513981 | R38: 44194 | S38: 46027 | T38: 1633000 | U38: 25 | V38: =T38*U38% -> 408250 | W38: =T38-V38 -> 1224750 | X38: 2.5 | Y38: =W38*X38% -> 30618.75 | AA38: paid | AB38: 1141072474 | AC38: 45688 | AD38: DISBURSED | AE38: 0 | AF38: KHI/HO/D/MO/PC COMP/C/103764/154/12/2024 | AG38: 30619 | AH38: =Y38-AG38 -> -0.25
A39: Renewal | B39: 45586/1 | C39: 45627 | D39: SALAAM TAKAFUL LTD | E39: KHI/HO/D/MO/PC COMP/C/103764/149/12/2024 | F39: 45657 | G39: 46021 | H39: MUHAMMAD WASIF | I39: 3520187823901 | J39: SUZUKI WAGON-R VXL E2 | K39: ABL-141 | L39: 206046 | M39: 10106049 | N39: 45586/1 | O39: Central | P39: 0329 | Q39: 515316 | R39: 44201 | S39: 46027 | T39: 1640000 | U39: 25 | V39: =T39*U39% -> 410000 | W39: =T39-V39 -> 1230000 | X39: 2.5 | Y39: =W39*X39% -> 30750 | AA39: paid | AB39: 1141072474 | AC39: 45688 | AD39: DISBURSED | AE39: 0 | AF39: KHI/HO/D/MO/PC COMP/C/103764/149/12/2024 | AG39: 30750 | AH39: =Y39-AG39 -> 0
A40: Renewal | B40: 53049/1 | C40: 45627 | D40: SALAAM TAKAFUL LTD | E40: KHI/HO/D/MO/PC COMP/C/103764/86/12/2024 | F40: 45636 | G40: 46000 | H40: MUHAMMAD SHAKEEL | I40: 3320330591451 | J40: SUZUKI WAGON-R VXL E2 | K40: LE-19-6108 | L40: 177771 | M40: 10077739 | N40: 53049/1 | O40: Central | P40: 0329 | Q40: 558096 | R40: 44544 | S40: 46361 | T40: 1650000 | U40: 20 | V40: =T40*U40% -> 330000 | W40: =T40-V40 -> 1320000 | X40: 1.75 | Y40: =W40*X40% -> 23100 | AA40: paid | AB40: 1141072474 | AC40: 45688 | AD40: DISBURSED | AE40: 0 | AF40: KHI/HO/D/MO/PC COMP/C/103764/86/12/2024 | AG40: 23100 | AH40: =Y40-AG40 -> 0
...

Sheet WORKING
A1: POLICY NO. | B1: Assorted_code | D1: Premium | E1: 04Feb250013
A2: KHI/HO/D/MO/PC COMP/C/103764/8/12/2024 | B2: =VLOOKUP(A2,policy!B:C,2,0) -> 070000172341 | C2: 16200 | D2: =ROUND(C2,0) -> 16200 | E2: 04Feb250013 | F2: ="insert into ins_premium_det (premium_rcv_code,assorted_code, rec_amount,premium_rcv_detail_code,remaining_amt, payrec, mode_code,coinsurance_code,class_cd,it_remarks) values" -> insert into ins_premium_det (premium_rcv_code,assorted_code, rec_amount,premium_rcv_detail_code,remaining_amt, payrec, mode_code,coinsurance_code,class_cd,it_remarks) values | G2: ="('"&E2&"','"&B2&"','"&D2&"',(select max(to_number(i.premium_rcv_detail_code))+1 from ins_premium_det i),'"&D2&"','"&D2&"','02', '11000003','00','Request by Mr. Saqib Saleem 04-Feb-2024');" -> ('04Feb250013','070000172341','16200',(select max(to_number(i.premium_rcv_detail_code))+1 from ins_premium_det i),'16200','16200','02', '11000003','00','Request by Mr. Saqib Saleem 04-Feb-2024'); | H2: =F2&G2 -> insert into ins_premium_det (premium_rcv_code,assorted_code, rec_amount,premium_rcv_detail_code,remaining_amt, payrec, mode_code,coinsurance_code,class_cd,it_remarks) values('04Feb250013','070000172341','16200',(select max(to_number(i.premium_rcv_detail_code))+1 from ins_premium_det i),'16200','16200','02', '11000003','00','Request by Mr. Saqib Saleem 04-Feb-2024');
A3: KHI/HO/D/MO/CV/C/104416/1/12/2024 | B3: =VLOOKUP(A3,policy!B:C,2,0) -> 070000172747 | C3: 19388 | D3: =ROUND(C3,0) -> 19388 | E3: 04Feb250013 | F3: ="insert into ins_premium_det (premium_rcv_code,assorted_code, rec_amount,premium_rcv_detail_code,remaining_amt, payrec, mode_code,coinsurance_code,class_cd,it_remarks) values" -> insert into ins_premium_det (premium_rcv_code,assorted_code, rec_amount,premium_rcv_detail_code,remaining_amt, payrec, mode_code,coinsurance_code,class_cd,it_remarks) values | G3: ="('"&E3&"','"&B3&"','"&D3&"',(select max(to_number(i.premium_rcv_detail_code))+1 from ins_premium_det i),'"&D3&"','"&D3&"','02', '11000003','00','Request by Mr. Saqib Saleem 04-Feb-2024');" -> ('04Feb250013','070000172747','19388',(select max(to_number(i.premium_rcv_detail_code))+1 from ins_premium_det i),'19388','19388','02', '11000003','00','Request by Mr. Saqib Saleem 04-Feb-2024'); | H3: =F3&G3 -> insert into ins_premium_det (premium_rcv_code,assorted_code, rec_amount,premium_rcv_detail_code,remaining_amt, payrec, mode_code,coinsurance_code,class_cd,it_remarks) values('04Feb250013','070000172747','19388',(select max(to_number(i.premium_rcv_detail_code))+1 from ins_premium_det i),'19388','19388','02', '11000003','00','Request by Mr. Saqib Saleem 04-Feb-2024');
A4: KHI/HO/D/MO/CV/C/104416/2/12/2024 | B4: =VLOOKUP(A4,policy!B:C,2,0) -> 070000172748 | C4: 19388 | D4: =ROUND(C4,0) -> 19388 | E4: 04Feb250013 | F4: ="insert into ins_premium_det (premium_rcv_code,assorted_code, rec_amount,premium_rcv_detail_code,remaining_amt, payrec, mode_code,coinsurance_code,class_cd,it_remarks) values" -> insert into ins_premium_det (premium_rcv_code,assorted_code, rec_amount,premium_rcv_detail_code,remaining_amt, payrec, mode_code,coinsurance_code,class_cd,it_remarks) values | G4: ="('"&E4&"','"&B4&"','"&D4&"',(select max(to_number(i.premium_rcv_detail_code))+1 from ins_premium_det i),'"&D4&"','"&D4&"','02', '11000003','00','Request by Mr. Saqib Saleem 04-Feb-2024');" -> ('04Feb250013','070000172748','19388',(select max(to_number(i.premium_rcv_detail_code))+1 from ins_premium_det i),'19388','19388','02', '11000003','00','Request by Mr. Saqib Saleem 04-Feb-2024'); | H4: =F4&G4 -> insert into ins_premium_det (premium_rcv_code,assorted_code, rec_amount,premium_rcv_detail_code,remaining_amt, payrec, mode_code,coinsurance_code,class_cd,it_remarks) values('04Feb250013','070000172748','19388',(select max(to_number(i.premium_rcv_detail_code))+1 from ins_premium_det i),'19388','19388','02', '11000003','00','Request by Mr. Saqib Saleem 04-Feb-2024');
A5: KHI/HO/D/MO/PC COMP/C/103764/94/12/2024 | B5: =VLOOKUP(A5,policy!B:C,2,0) -> 070000172427 | C5: 15554 | D5: =ROUND(C5,0) -> 15554 | E5: 04Feb250013 | F5: ="insert into ins_premium_det (premium_rcv_code,assorted_code, rec_amount,premium_rcv_detail_code,remaining_amt, payrec, mode_code,coinsurance_code,class_cd,it_remarks) values" -> insert into ins_premium_det (premium_rcv_code,assorted_code, rec_amount,premium_rcv_detail_code,remaining_amt, payrec, mode_code,coinsurance_code,class_cd,it_remarks) values | G5: ="('"&E5&"','"&B5&"','"&D5&"',(select max(to_number(i.premium_rcv_detail_code))+1 from ins_premium_det i),'"&D5&"','"&D5&"','02', '11000003','00','Request by Mr. Saqib Saleem 04-Feb-2024');" -> ('04Feb250013','070000172427','15554',(select max(to_number(i.premium_rcv_detail_code))+1 from ins_premium_det i),'15554','15554','02', '11000003','00','Request by Mr. Saqib Saleem 04-Feb-2024'); | H5: =F5&G5 -> insert into ins_premium_det (premium_rcv_code,assorted_code, rec_amount,premium_rcv_detail_code,remaining_amt, payrec, mode_code,coinsurance_code,class_cd,it_remarks) values('04Feb250013','070000172427','15554',(select max(to_number(i.premium_rcv_detail_code))+1 from ins_premium_det i),'15554','15554','02', '11000003','00','Request by Mr. Saqib Saleem 04-Feb-2024');
A6: KHI/HO/D/MO/CV/C/104415/1/12/2024 | B6: =VLOOKUP(A6,policy!B:C,2,0) -> 070000172749 | C6: 15638 | D6: =ROUND(C6,0) -> 15638 | E6: 04Feb250013 | F6: ="insert into ins_premium_det (premium_rcv_code,assorted_code, rec_amount,premium_rcv_detail_code,remaining_amt, payrec, mode_code,coinsurance_code,class_cd,it_remarks) values" -> insert into ins_premium_det (premium_rcv_code,assorted_code, rec_amount,premium_rcv_detail_code,remaining_amt, payrec, mode_code,coinsurance_code,class_cd,it_remarks) values | G6: ="('"&E6&"','"&B6&"','"&D6&"',(select max(to_number(i.premium_rcv_detail_code))+1 from ins_premium_det i),'"&D6&"','"&D6&"','02', '11000003','00','Request by Mr. Saqib Saleem 04-Feb-2024');" -> ('04Feb250013','070000172749','15638',(select max(to_number(i.premium_rcv_detail_code))+1 from ins_premium_det i),'15638','15638','02', '11000003','00','Request by Mr. Saqib Saleem 04-Feb-2024'); | H6: =F6&G6 -> insert into ins_premium_det (premium_rcv_code,assorted_code, rec_amount,premium_rcv_detail_code,remaining_amt, payrec, mode_code,coinsurance_code,class_cd,it_remarks) values('04Feb250013','070000172749','15638',(select max(to_number(i.premium_rcv_detail_code))+1 from ins_premium_det i),'15638','15638','02', '11000003','00','Request by Mr. Saqib Saleem 04-Feb-2024');
A7: KHI/HO/D/MO/CV/C/104415/2/12/2024 | B7: =VLOOKUP(A7,policy!B:C,2,0) -> 070000172750 | C7: 15638 | D7: =ROUND(C7,0) -> 15638 | E7: 04Feb250013 | F7: ="insert into ins_premium_det (premium_rcv_code,assorted_code, rec_amount,premium_rcv_detail_code,remaining_amt, payrec, mode_code,coinsurance_code,class_cd,it_remarks) values" -> insert into ins_premium_det (premium_rcv_code,assorted_code, rec_amount,premium_rcv_detail_code,remaining_amt, payrec, mode_code,coinsurance_code,class_cd,it_remarks) values | G7: ="('"&E7&"','"&B7&"','"&D7&"',(select max(to_number(i.premium_rcv_detail_code))+1 from ins_premium_det i),'"&D7&"','"&D7&"','02', '11000003','00','Request by Mr. Saqib Saleem 04-Feb-2024');" -> ('04Feb250013','070000172750','15638',(select max(to_number(i.premium_rcv_detail_code))+1 from ins_premium_det i),'15638','15638','02', '11000003','00','Request by Mr. Saqib Saleem 04-Feb-2024'); | H7: =F7&G7 -> insert into ins_premium_det (premium_rcv_code,assorted_code, rec_amount,premium_rcv_detail_code,remaining_amt, payrec, mode_code,coinsurance_code,class_cd,it_remarks) values('04Feb250013','070000172750','15638',(select max(to_number(i.premium_rcv_detail_code))+1 from ins_premium_det i),'15638','15638','02', '11000003','00','Request by Mr. Saqib Saleem 04-Feb-2024');
A8: KHI/HO/D/MO/CV/C/104415/3/12/2024 | B8: =VLOOKUP(A8,policy!B:C,2,0) -> 070000172751 | C8: 15638 | D8: =ROUND(C8,0) -> 15638 | E8: 04Feb250013 | F8: ="insert into ins_premium_det (premium_rcv_code,assorted_code, rec_amount,premium_rcv_detail_code,remaining_amt, payrec, mode_code,coinsurance_code,class_cd,it_remarks) values" -> insert into ins_premium_det (premium_rcv_code,assorted_code, rec_amount,premium_rcv_detail_code,remaining_amt, payrec, mode_code,coinsurance_code,class_cd,it_remarks) values | G8: ="('"&E8&"','"&B8&"','"&D8&"',(select max(to_number(i.premium_rcv_detail_code))+1 from ins_premium_det i),'"&D8&"','"&D8&"','02', '11000003','00','Request by Mr. Saqib Saleem 04-Feb-2024');" -> ('04Feb250013','070000172751','15638',(select max(to_number(i.premium_rcv_detail_code))+1 from ins_premium_det i),'15638','15638','02', '11000003','00','Request by Mr. Saqib Saleem 04-Feb-2024'); | H8: =F8&G8 -> insert into ins_premium_det (premium_rcv_code,assorted_code, rec_amount,premium_rcv_detail_code,remaining_amt, payrec, mode_code,coinsurance_code,class_cd,it_remarks) values('04Feb250013','070000172751','15638',(select max(to_number(i.premium_rcv_detail_code))+1 from ins_premium_det i),'15638','15638','02', '11000003','00','Request by Mr. Saqib Saleem 04-Feb-2024');
A9: KHI/HO/D/MO/CV/C/104415/4/12/2024 | B9: =VLOOKUP(A9,policy!B:C,2,0) -> 070000172752 | C9: 15638 | D9: =ROUND(C9,0) -> 15638 | E9: 04Feb250013 | F9: ="insert into ins_premium_det (premium_rcv_code,assorted_code, rec_amount,premium_rcv_detail_code,remaining_amt, payrec, mode_code,coinsurance_code,class_cd,it_remarks) values" -> insert into ins_premium_det (premium_rcv_code,assorted_code, rec_amount,premium_rcv_detail_code,remaining_amt, payrec, mode_code,coinsurance_code,class_cd,it_remarks) values | G9: ="('"&E9&"','"&B9&"','"&D9&"',(select max(to_number(i.premium_rcv_detail_code))+1 from ins_premium_det i),'"&D9&"','"&D9&"','02', '11000003','00','Request by Mr. Saqib Saleem 04-Feb-2024');" -> ('04Feb250013','070000172752','15638',(select max(to_number(i.premium_rcv_detail_code))+1 from ins_premium_det i),'15638','15638','02', '11000003','00','Request by Mr. Saqib Saleem 04-Feb-2024'); | H9: =F9&G9 -> insert into ins_premium_det (premium_rcv_code,assorted_code, rec_amount,premium_rcv_detail_code,remaining_amt, payrec, mode_code,coinsurance_code,class_cd,it_remarks) values('04Feb250013','070000172752','15638',(select max(to_number(i.premium_rcv_detail_code))+1 from ins_premium_det i),'15638','15638','02', '11000003','00','Request by Mr. Saqib Saleem 04-Feb-2024');
A10: KHI/HO/D/MO/CV/C/104415/5/12/2024 | B10: =VLOOKUP(A10,policy!B:C,2,0) -> 070000172753 | C10: 15638 | D10: =ROUND(C10,0) -> 15638 | E10: 04Feb250013 | F10: ="insert into ins_premium_det (premium_rcv_code,assorted_code, rec_amount,premium_rcv_detail_code,remaining_amt, payrec, mode_code,coinsurance_code,class_cd,it_remarks) values" -> insert into ins_premium_det (premium_rcv_code,assorted_code, rec_amount,premium_rcv_detail_code,remaining_amt, payrec, mode_code,coinsurance_code,class_cd,it_remarks) values | G10: ="('"&E10&"','"&B10&"','"&D10&"',(select max(to_number(i.premium_rcv_detail_code))+1 from ins_premium_det i),'"&D10&"','"&D10&"','02', '11000003','00','Request by Mr. Saqib Saleem 04-Feb-2024');" -> ('04Feb250013','070000172753','15638',(select max(to_number(i.premium_rcv_detail_code))+1 from ins_premium_det i),'15638','15638','02', '11000003','00','Request by Mr. Saqib Saleem 04-Feb-2024'); | H10: =F10&G10 -> insert into ins_premium_det (premium_rcv_code,assorted_code, rec_amount,premium_rcv_detail_code,remaining_amt, payrec, mode_code,coinsurance_code,class_cd,it_remarks) values('04Feb250013','070000172753','15638',(select max(to_number(i.premium_rcv_detail_code))+1 from ins_premium_det i),'15638','15638','02', '11000003','00','Request by Mr. Saqib Saleem 04-Feb-2024');
A11: KHI/HO/D/MO/PC COMP/C/103764/87/12/2024 | B11: =VLOOKUP(A11,policy!B:C,2,0) -> 070000172420 | C11: 16086 | D11: =ROUND(C11,0) -> 16086 | E11: 04Feb250013 | F11: ="insert into ins_premium_det (premium_rcv_code,assorted_code, rec_amount,premium_rcv_detail_code,remaining_amt, payrec, mode_code,coinsurance_code,class_cd,it_remarks) values" -> insert into ins_premium_det (premium_rcv_code,assorted_code, rec_amount,premium_rcv_detail_code,remaining_amt, payrec, mode_code,coinsurance_code,class_cd,it_remarks) values | G11: ="('"&E11&"','"&B11&"','"&D11&"',(select max(to_number(i.premium_rcv_detail_code))+1 from ins_premium_det i),'"&D11&"','"&D11&"','02', '11000003','00','Request by Mr. Saqib Saleem 04-Feb-2024');" -> ('04Feb250013','070000172420','16086',(select max(to_number(i.premium_rcv_detail_code))+1 from ins_premium_det i),'16086','16086','02', '11000003','00','Request by Mr. Saqib Saleem 04-Feb-2024'); | H11: =F11&G11 -> insert into ins_premium_det (premium_rcv_code,assorted_code, rec_amount,premium_rcv_detail_code,remaining_amt, payrec, mode_code,coinsurance_code,class_cd,it_remarks) values('04Feb250013','070000172420','16086',(select max(to_number(i.premium_rcv_detail_code))+1 from ins_premium_det i),'16086','16086','02', '11000003','00','Request by Mr. Saqib Saleem 04-Feb-2024');
