Workbook

Sheet Direct Agency Outstanding
B1: MUL/MUL/F/FR/D/P/12471/09/2021 | C1: -6
B2: KHI/HO/D/MO/PC COMP/P/73118/07/2023 | C2: -4
B3: MUL/MUL/F/FR/D/P/13574/12/2021 | C3: -3
B4: MUL/MUL/F/FR/ND/P/13059/11/2021 | C4: -3
B5: MUL/MUL/F/FR/ND/P/13084/11/2021 | C5: -3
B6: MUL/MUL/F/FR/ND/P/13122/11/2021 | C6: -3
B7: KHI/HO/D/MO/PC COMP/P/69597/04/2023 | C7: -2
B8: MUL/MUL/F/FR/ND/P/12988/11/2021 | C8: -2
B9: MUL/MUL/F/FR/ND/P/13081/11/2021 | C9: -2
B10: MUL/MUL/F/FR/ND/P/13116/11/2021 | C10: -2
B11: MUL/MUL/F/FR/ND/P/13567/12/2021 | C11: -2
B12: ISD/ISD/F/MR/IMPORTS/P/38010/11/2022 | C12: -1
... B2209: KHI/HO/D/MI/TRI/P/6533/11/2022 | C2209: 590
B2210: KHI/HO/D/MI/TRI/P/6534/11/2022 | C2210: 590 | E2210: =SUM(C1:C2210) -> 101021.82
B2211: KHI/HO/D/MI/TRI/P/6535/11/2022 | C2211: 590
B2212: MUL/MUL/F/FR/ND/P/12610/10/2021 | C2212: 592
B2213: KHI/HO/D/MI/MP/P/2514/01/2023 | C2213: 593
B2214: KHI/HO/D/MO/PD COMP/P/78292/11/2023 | C2214: 593
B2215: MUL/MUL/F/MI/FG/P/1797/09/2021 | C2215: 596
B2216: KHI/HO/D/MR/IMPORTS/C/18700/10/2023 | C2216: 598
B2217: KHI/HO/D/FR/ND/P/14909/06/2022 | C2217: 600
B2218: KHI/HO/D/MO/PC COMP/C/77027/346/10/2023 | C2218: 605
B2219: KHI/HO/D/MR/IMPORTS/C/18891/11/2023 | C2219: 605
B2220: KHI/HO/D/MO/PD COMP/P/75790/09/2023 | C2220: 606
B2221: MUL/MUL/F/EG/MBD/P/714/01/2022 | C2221: 613
B2222: KHI/HO/D/MO/PD COMP/P/58016/01/2022 | C2222: 614
... B2636: KHI/HO/D/MR/IMPORTS/P/41520/12/2023 | C2636: 1000
B2637: Policy No | C2637: Total
C2638: =SUM(C1:C2636) -> 410970.57

Sheet Advance Amount Knock Off Detail
A1: Type | B1: Vcher No. | C1: Cheque No. | D1: Date | E1: Rec From | F1: Amount
A2: RV | B2: 24-01-0436 | C2: 74824889 | D2: 45300 | E2: Zeeshan Ahmed | F2: 0.1
A3: RV | B3: 24-07-0171 | C3: 770736 | D3: 45478 | E3: Syed Muzafar Ali Shah | F3: 0.2
A4: RV | B4: 24-04-1377 | C4: 1519758 | D4: 45412 | E4: Imaan Hussain | F4: 0.3
A5: RV | B5: 24-05-0245 | C5: 416992 | D5: 45419 | E5: Jehangir Abbas Awan | F5: 0.3
A6: RV | B6: 24-04-0432 | C6: 2 on line transfer | D6: 45397 | E6: Mr. Syed Misbah Uddin CNIC: 4220116890503 Cell: 0301-3384728 | F6: 0.5
A7: RV | B7: 24-07-0398 | C7: 5758397 6460 | D7: 45484 | E7: Bank Of Punjab A/c. M/s. Security Organizing System Pakistan Pvt. Ltd. | F7: 0.71
A8: RV | B8: 24-05-1519 | C8: ON LINE | D8: 45442 | E8: M/s Bank Alfalah Limited Islamic A/c Various User | F8: 0.86
A9: RV | B9: 24-05-0153 | C9: 31930811 | D9: 45418 | E9: TAPAL TEX (PRIVATE) LIMITED | F9: 0.93
A10: RV | B10: 24-09-0594 | C10: 439373 | D10: 45547 | E10: Sabina Rana | F10: 0.95
A11: RV | B11: 24-02-0213 | C11: 71572932 | D11: 45331 | E11: Security General Insurance Co. Ltd. | F11: 1
A12: RV | B12: 24-03-1138 | C12: 59877482 | D12: 45378 | E12: EFU GENRAL INSURANCE LIMITED | F12: 1
A13: RV | B13: 24-01-1047 | C13: 928665 | D13: 45309 | E13: M/S. DUBAI ISLAMIC BANK PAKISTAN LIMITED A/C M/S. SAFA HEALTHCSARE | F13: 1
A14: RV | B14: 24-01-1071 | C14: 30299826 | D14: 45310 | E14: EFU GENRAL INSURANCE LIMITED (Soorthy Enterprises) | F14: 1
A15: RV | B15: 24-01-0190 | C15: 11 | D15: 45295 | E15: M/s Meezan Bank Limited A/c Various User | F15: 1
A16: RV | B16: 24-01-0304 | C16: 381289 | D16: 45296 | E16: PAID BY HAMMAD | F16: 1
A17: RV | B17: 24-01-0491 | C17: 356785 | D17: 45300 | E17: Imran Ali | F17: 1
A18: RV | B18: 24-01-0537 | C18: 146664 | D18: 45300 | E18: Nextbridge Private Limited. | F18: 1
A19: RV | B19: 24-01-0675 | C19: 295473 | D19: 45302 | E19: Muhammad Jawad Azam | F19: 1
A20: RV | B20: 24-01-0702 | C20: 241040 | D20: 45302 | E20: Naveed Iqbal | F20: 1
A21: RV | B21: 24-01-0775 | C21: 9976AFR2332 | D21: 45303 | E21: M/s. M/s. Nobel Cotton Waste HPA M/s Dubai Islamic Bank (Pakistan) Limited User Mr. Mr. Zeeshan Aziz Malik | F21: 1
A22: RV | B22: 24-01-0744 | C22: 107709 | D22: 45305 | E22: Aftab Iqbal Qureshi | F22: 1
A23: RV | B23: 24-01-0764 | C23: 102798 | D23: 45305 | E23: Muhammad Bashir | F23: 1
A24: RV | B24: 24-01-0872 | C24: 464975 | D24: 45306 | E24: Akhlas Ahmad | F24: 1
A25: RV | B25: 24-01-0979 | C25: 453244 | D25: 45308 | E25: Hafiz Asad Ali | F25: 1
A26: RV | B26: 24-01-1033 | C26: 578913 | D26: 45308 | E26: Farrkhanda Akhtar | F26: 1
A27: RV | B27: 24-01-1006 | C27: 534198 | D27: 45309 | E27: M/s Meezan Bank Limited A/c ARY Jewellers | F27: 1
A28: RV | B28: 24-01-1328 | C28: 2 Pay Orders | D28: 45315 | E28: M/s Al Baraka Bank A/c Various User (Fresh And Renewal) | F28: 1
A29: RV | B29: 24-01-1364 | C29: 209156 | D29: 45315 | E29: Abdul Basit Aziz | F29: 1
A30: RV | B30: 24-01-1419 | C30: 11 | D30: 45316 | E30: M/s Meezan Bank Limited Multan HubA/c Various User | F30: 1
A31: RV | B31: 24-01-1453 | D31: 45316 | E31: VARIOUS PAYD CUSTOMER | F31: 1
A32: RV | B32: 24-01-1865 | C32: 240310 | D32: 45322 | E32: Shah Rukh Shahid | F32: 1
A33: RV | B33: 24-02-0216 | C33: ON LINE | D33: 45329 | E33: M/S Dubai Islamic Bank Limited User A/c Various User | F33: 1
A34: RV | B34: 24-02-0294 | C34: 96045798 | D34: 45329 | E34: Mystic Tours Pvt Limited 1st Inst Plan | F34: 1
A35: RV | B35: 24-02-0716 | C35: 531498 | D35: 45329 | E35: M/S. Dubai Islamic Bank Pakistan Limited User: Saleem Ullah Butt | F35: 1
A36: RV | B36: 24-02-0330 | C36: 31162050973 | D36: 45331 | E36: M/s. Bank Alfalah Limited Islamic Banking Division (Dhoraji Branch Karachi ) as Lessor & Owner And Mr. Muhammad Pervaiz | F36: 1
A37: RV | B37: 24-02-0780 | C37: ON LINE | D37: 45341 | E37: M/S Dubai Islamic Bank Limited User A/c Various User | F37: 1
A38: RV | B38: 24-02-0943 | C38: 6502154 | D38: 45342 | E38: Sarfaraz Ali Shah | F38: 1
A39: RV | B39: 24-02-0986 | C39: 958801 | D39: 45344 | E39: M/S OCEAN NETWORK EXPRESS PAKISTAN PVT LTD | F39: 1
A40: RV | B40: 24-02-1395 | C40: 424463 | D40: 45350 | E40: Siraj Tanoli | F40: 1
...

Sheet working
A1: POLICY NO. | B1: Assorted_code | D1: Premium | E1: 13Nov240062
A2: MUL/MUL/F/FR/D/P/12471/09/2021 | B2: =VLOOKUP(A2,policy!B:C,2,0) -> 040000106339 | C2: -6 | D2: -6 | E2: 13Nov240062 | F2: ="insert into ins_premium_det (premium_rcv_code,assorted_code, rec_amount,premium_rcv_detail_code,remaining_amt, payrec, mode_code,coinsurance_code,class_cd,it_remarks) values" -> insert into ins_premium_det (premium_rcv_code,assorted_code, rec_amount,premium_rcv_detail_code,remaining_amt, payrec, mode_code,coinsurance_code,class_cd,it_remarks) values | G2: ="('"&E2&"','"&B2&"','"&D2&"',(select max(to_number(i.premium_rcv_detail_code))+1 from ins_premium_det i),'"&D2&"','"&D2&"','02', '11000003','00','Request by Mr. Raheel Malik 15-Nov-2024');" -> ('13Nov240062','040000106339','-6',(select max(to_number(i.premium_rcv_detail_code))+1 from ins_premium_det i),'-6','-6','02', '11000003','00','Request by Mr. Raheel Malik 15-Nov-2024'); | H2: =F2&G2 -> insert into ins_premium_det (premium_rcv_code,assorted_code, rec_amount,premium_rcv_detail_code,remaining_amt, payrec, mode_code,coinsurance_code,class_cd,it_remarks) values('13Nov240062','040000106339','-6',(select max(to_number(i.premium_rcv_detail_code))+1 from ins_premium_det i),'-6','-6','02', '11000003','00','Request by Mr. Raheel Malik 15-Nov-2024');
A3: KHI/HO/D/MO/PC COMP/P/73118/07/2023 | B3: =VLOOKUP(A3,policy!B:C,2,0) -> 040000149022 | C3: -4 | D3: -4 | E3: 13Nov240062 | F3: ="insert into ins_premium_det (premium_rcv_code,assorted_code, rec_amount,premium_rcv_detail_code,remaining_amt, payrec, mode_code,coinsurance_code,class_cd,it_remarks) values" -> insert into ins_premium_det (premium_rcv_code,assorted_code, rec_amount,premium_rcv_detail_code,remaining_amt, payrec, mode_code,coinsurance_code,class_cd,it_remarks) values | G3: ="('"&E3&"','"&B3&"','"&D3&"',(select max(to_number(i.premium_rcv_detail_code))+1 from ins_premium_det i),'"&D3&"','"&D3&"','02', '11000003','00','Request by Mr. Raheel Malik 15-Nov-2024');" -> ('13Nov240062','040000149022','-4',(select max(to_number(i.premium_rcv_detail_code))+1 from ins_premium_det i),'-4','-4','02', '11000003','00','Request by Mr. Raheel Malik 15-Nov-2024'); | H3: =F3&G3 -> insert into ins_premium_det (premium_rcv_code,assorted_code, rec_amount,premium_rcv_detail_code,remaining_amt, payrec, mode_code,coinsurance_code,class_cd,it_remarks) values('13Nov240062','040000149022','-4',(select max(to_number(i.premium_rcv_detail_code))+1 from ins_premium_det i),'-4','-4','02', '11000003','00','Request by Mr. Raheel Malik 15-Nov-2024');
A4: MUL/MUL/F/FR/D/P/13574/12/2021 | B4: =VLOOKUP(A4,policy!B:C,2,0) -> 040000110713 | C4: -3 | D4: -3 | E4: 13Nov240062 | F4: ="insert into ins_premium_det (premium_rcv_code,assorted_code, rec_amount,premium_rcv_detail_code,remaining_amt, payrec, mode_code,coinsurance_code,class_cd,it_remarks) values" -> insert into ins_premium_det (premium_rcv_code,assorted_code, rec_amount,premium_rcv_detail_code,remaining_amt, payrec, mode_code,coinsurance_code,class_cd,it_remarks) values | G4: ="('"&E4&"','"&B4&"','"&D4&"',(select max(to_number(i.premium_rcv_detail_code))+1 from ins_premium_det i),'"&D4&"','"&D4&"','02', '11000003','00','Request by Mr. Raheel Malik 15-Nov-2024');" -> ('13Nov240062','040000110713','-3',(select max(to_number(i.premium_rcv_detail_code))+1 from ins_premium_det i),'-3','-3','02', '11000003','00','Request by Mr. Raheel Malik 15-Nov-2024'); | H4: =F4&G4 -> insert into ins_premium_det (premium_rcv_code,assorted_code, rec_amount,premium_rcv_detail_code,remaining_amt, payrec, mode_code,coinsurance_code,class_cd,it_remarks) values('13Nov240062','040000110713','-3',(select max(to_number(i.premium_rcv_detail_code))+1 from ins_premium_det i),'-3','-3','02', '11000003','00','Request by Mr. Raheel Malik 15-Nov-2024');
A5: MUL/MUL/F/FR/ND/P/13059/11/2021 | B5: =VLOOKUP(A5,policy!B:C,2,0) -> 040000108658 | C5: -3 | D5: -3 | E5: 13Nov240062 | F5: ="insert into ins_premium_det (premium_rcv_code,assorted_code, rec_amount,premium_rcv_detail_code,remaining_amt, payrec, mode_code,coinsurance_code,class_cd,it_remarks) values" -> insert into ins_premium_det (premium_rcv_code,assorted_code, rec_amount,premium_rcv_detail_code,remaining_amt, payrec, mode_code,coinsurance_code,class_cd,it_remarks) values | G5: ="('"&E5&"','"&B5&"','"&D5&"',(select max(to_number(i.premium_rcv_detail_code))+1 from ins_premium_det i),'"&D5&"','"&D5&"','02', '11000003','00','Request by Mr. Raheel Malik 15-Nov-2024');" -> ('13Nov240062','040000108658','-3',(select max(to_number(i.premium_rcv_detail_code))+1 from ins_premium_det i),'-3','-3','02', '11000003','00','Request by Mr. Raheel Malik 15-Nov-2024'); | H5: =F5&G5 -> insert into ins_premium_det (premium_rcv_code,assorted_code, rec_amount,premium_rcv_detail_code,remaining_amt, payrec, mode_code,coinsurance_code,class_cd,it_remarks) values('13Nov240062','040000108658','-3',(select max(to_number(i.premium_rcv_detail_code))+1 from ins_premium_det i),'-3','-3','02', '11000003','00','Request by Mr. Raheel Malik 15-Nov-2024');
A6: MUL/MUL/F/FR/ND/P/13084/11/2021 | B6: =VLOOKUP(A6,policy!B:C,2,0) -> 040000108917 | C6: -3 | D6: -3 | E6: 13Nov240062 | F6: ="insert into ins_premium_det (premium_rcv_code,assorted_code, rec_amount,premium_rcv_detail_code,remaining_amt, payrec, mode_code,coinsurance_code,class_cd,it_remarks) values" -> insert into ins_premium_det (premium_rcv_code,assorted_code, rec_amount,premium_rcv_detail_code,remaining_amt, payrec, mode_code,coinsurance_code,class_cd,it_remarks) values | G6: ="('"&E6&"','"&B6&"','"&D6&"',(select max(to_number(i.premium_rcv_detail_code))+1 from ins_premium_det i),'"&D6&"','"&D6&"','02', '11000003','00','Request by Mr. Raheel Malik 15-Nov-2024');" -> ('13Nov240062','040000108917','-3',(select max(to_number(i.premium_rcv_detail_code))+1 from ins_premium_det i),'-3','-3','02', '11000003','00','Request by Mr. Raheel Malik 15-Nov-2024'); | H6: =F6&G6 -> insert into ins_premium_det (premium_rcv_code,assorted_code, rec_amount,premium_rcv_detail_code,remaining_amt, payrec, mode_code,coinsurance_code,class_cd,it_remarks) values('13Nov240062','040000108917','-3',(select max(to_number(i.premium_rcv_detail_code))+1 from ins_premium_det i),'-3','-3','02', '11000003','00','Request by Mr. Raheel Malik 15-Nov-2024');
A7: MUL/MUL/F/FR/ND/P/13122/11/2021 | B7: =VLOOKUP(A7,policy!B:C,2,0) -> 040000109079 | C7: -3 | D7: -3 | E7: 13Nov240062 | F7: ="insert into ins_premium_det (premium_rcv_code,assorted_code, rec_amount,premium_rcv_detail_code,remaining_amt, payrec, mode_code,coinsurance_code,class_cd,it_remarks) values" -> insert into ins_premium_det (premium_rcv_code,assorted_code, rec_amount,premium_rcv_detail_code,remaining_amt, payrec, mode_code,coinsurance_code,class_cd,it_remarks) values | G7: ="('"&E7&"','"&B7&"','"&D7&"',(select max(to_number(i.premium_rcv_detail_code))+1 from ins_premium_det i),'"&D7&"','"&D7&"','02', '11000003','00','Request by Mr. Raheel Malik 15-Nov-2024');" -> ('13Nov240062','040000109079','-3',(select max(to_number(i.premium_rcv_detail_code))+1 from ins_premium_det i),'-3','-3','02', '11000003','00','Request by Mr. Raheel Malik 15-Nov-2024'); | H7: =F7&G7 -> insert into ins_premium_det (premium_rcv_code,assorted_code, rec_amount,premium_rcv_detail_code,remaining_amt, payrec, mode_code,coinsurance_code,class_cd,it_remarks) values('13Nov240062','040000109079','-3',(select max(to_number(i.premium_rcv_detail_code))+1 from ins_premium_det i),'-3','-3','02', '11000003','00','Request by Mr. Raheel Malik 15-Nov-2024');
A8: KHI/HO/D/MO/PC COMP/P/69597/04/2023 | B8: =VLOOKUP(A8,policy!B:C,2,0) -> 040000143001 | C8: -2 | D8: -2 | E8: 13Nov240062 | F8: ="insert into ins_premium_det (premium_rcv_code,assorted_code, rec_amount,premium_rcv_detail_code,remaining_amt, payrec, mode_code,coinsurance_code,class_cd,it_remarks) values" -> insert into ins_premium_det (premium_rcv_code,assorted_code, rec_amount,premium_rcv_detail_code,remaining_amt, payrec, mode_code,coinsurance_code,class_cd,it_remarks) values | G8: ="('"&E8&"','"&B8&"','"&D8&"',(select max(to_number(i.premium_rcv_detail_code))+1 from ins_premium_det i),'"&D8&"','"&D8&"','02', '11000003','00','Request by Mr. Raheel Malik 15-Nov-2024');" -> ('13Nov240062','040000143001','-2',(select max(to_number(i.premium_rcv_detail_code))+1 from ins_premium_det i),'-2','-2','02', '11000003','00','Request by Mr. Raheel Malik 15-Nov-2024'); | H8: =F8&G8 -> insert into ins_premium_det (premium_rcv_code,assorted_code, rec_amount,premium_rcv_detail_code,remaining_amt, payrec, mode_code,coinsurance_code,class_cd,it_remarks) values('13Nov240062','040000143001','-2',(select max(to_number(i.premium_rcv_detail_code))+1 from ins_premium_det i),'-2','-2','02', '11000003','00','Request by Mr. Raheel Malik 15-Nov-2024');
A9: MUL/MUL/F/FR/ND/P/12988/11/2021 | B9: =VLOOKUP(A9,policy!B:C,2,0) -> 040000108330 | C9: -2 | D9: -2 | E9: 13Nov240062 | F9: ="insert into ins_premium_det (premium_rcv_code,assorted_code, rec_amount,premium_rcv_detail_code,remaining_amt, payrec, mode_code,coinsurance_code,class_cd,it_remarks) values" -> insert into ins_premium_det (premium_rcv_code,assorted_code, rec_amount,premium_rcv_detail_code,remaining_amt, payrec, mode_code,coinsurance_code,class_cd,it_remarks) values | G9: ="('"&E9&"','"&B9&"','"&D9&"',(select max(to_number(i.premium_rcv_detail_code))+1 from ins_premium_det i),'"&D9&"','"&D9&"','02', '11000003','00','Request by Mr. Raheel Malik 15-Nov-2024');" -> ('13Nov240062','040000108330','-2',(select max(to_number(i.premium_rcv_detail_code))+1 from ins_premium_det i),'-2','-2','02', '11000003','00','Request by Mr. Raheel Malik 15-Nov-2024'); | H9: =F9&G9 -> insert into ins_premium_det (premium_rcv_code,assorted_code, rec_amount,premium_rcv_detail_code,remaining_amt, payrec, mode_code,coinsurance_code,class_cd,it_remarks) values('13Nov240062','040000108330','-2',(select max(to_number(i.premium_rcv_detail_code))+1 from ins_premium_det i),'-2','-2','02', '11000003','00','Request by Mr. Raheel Malik 15-Nov-2024');
A10: MUL/MUL/F/FR/ND/P/13081/11/2021 | B10: =VLOOKUP(A10,policy!B:C,2,0) -> 040000108904 | C10: -2 | D10: -2 | E10: 13Nov240062 | F10: ="insert into ins_premium_det (premium_rcv_code,assorted_code, rec_amount,premium_rcv_detail_code,remaining_amt, payrec, mode_code,coinsurance_code,class_cd,it_remarks) values" -> insert into ins_premium_det (premium_rcv_code,assorted_code, rec_amount,premium_rcv_detail_code,remaining_amt, payrec, mode_code,coinsurance_code,class_cd,it_remarks) values | G10: ="('"&E10&"','"&B10&"','"&D10&"',(select max(to_number(i.premium_rcv_detail_code))+1 from ins_premium_det i),'"&D10&"','"&D10&"','02', '11000003','00','Request by Mr. Raheel Malik 15-Nov-2024');" -> ('13Nov240062','040000108904','-2',(select max(to_number(i.premium_rcv_detail_code))+1 from ins_premium_det i),'-2','-2','02', '11000003','00','Request by Mr. Raheel Malik 15-Nov-2024'); | H10: =F10&G10 -> insert into ins_premium_det (premium_rcv_code,assorted_code, rec_amount,premium_rcv_detail_code,remaining_amt, payrec, mode_code,coinsurance_code,class_cd,it_remarks) values('13Nov240062','040000108904','-2',(select max(to_number(i.premium_rcv_detail_code))+1 from ins_premium_det i),'-2','-2','02', '11000003','00','Request by Mr. Raheel Malik 15-Nov-2024');
A11: MUL/MUL/F/FR/ND/P/13116/11/2021 | B11: =VLOOKUP(A11,policy!B:C,2,0) -> 040000109068 | C11: -2 | D11: -2 | E11: 13Nov240062 | F11: ="insert into ins_premium_det (premium_rcv_code,assorted_code, rec_amount,premium_rcv_detail_code,remaining_amt, payrec, mode_code,coinsurance_code,class_cd,it_remarks) values" -> insert into ins_premium_det (premium_rcv_code,assorted_code, rec_amount,premium_rcv_detail_code,remaining_amt, payrec, mode_code,coinsurance_code,class_cd,it_remarks) values | G11: ="('"&E11&"','"&B11&"','"&D11&"',(select max(to_number(i.premium_rcv_detail_code))+1 from ins_premium_det i),'"&D11&"','"&D11&"','02', '11000003','00','Request by Mr. Raheel Malik 15-Nov-2024');" -> ('13Nov240062','040000109068','-2',(select max(to_number(i.premium_rcv_detail_code))+1 from ins_premium_det i),'-2','-2','02', '11000003','00','Request by Mr. Raheel Malik 15-Nov-2024'); | H11: =F11&G11 -> insert into ins_premium_det (premium_rcv_code,assorted_code, rec_amount,premium_rcv_detail_code,remaining_amt, payrec, mode_code,coinsurance_code,class_cd,it_remarks) values('13Nov240062','040000109068','-2',(select max(to_number(i.premium_rcv_detail_code))+1 from ins_premium_det i),'-2','-2','02', '11000003','00','Request by Mr. Raheel Malik 15-Nov-2024');
A12: MUL/MUL/F/FR/ND/P/13567/12/2021 | B12: =VLOOKUP(A12,policy!B:C,2,0) -> 040000110701 | C12: -2 | D12: -2 | E12: 13Nov240062 | F12: ="insert into ins_premium_det (premium_rcv_code,assorted_code, rec_amount,premium_rcv_detail_code,remaining_amt, payrec, mode_code,coinsurance_code,class_cd,it_remarks) values" -> insert into ins_premium_det (premium_rcv_code,assorted_code, rec_amount,premium_rcv_detail_code,remaining_amt, payrec, mode_code,coinsurance_code,class_cd,it_remarks) values | G12: ="('"&E12&"','"&B12&"','"&D12&"',(select max(to_number(i.premium_rcv_detail_code))+1 from ins_premium_det i),'"&D12&"','"&D12&"','02', '11000003','00','Request by Mr. Raheel Malik 15-Nov-2024');" -> ('13Nov240062','040000110701','-2',(select max(to_number(i.premium_rcv_detail_code))+1 from ins_premium_det i),'-2','-2','02', '11000003','00','Request by Mr. Raheel Malik 15-Nov-2024'); | H12: =F12&G12 -> insert into ins_premium_det (premium_rcv_code,assorted_code, rec_amount,premium_rcv_detail_code,remaining_amt, payrec, mode_code,coinsurance_code,class_cd,it_remarks) values('13Nov240062','040000110701','-2',(select max(to_number(i.premium_rcv_detail_code))+1 from ins_premium_det i),'-2','-2','02', '11000003','00','Request by Mr. Raheel Malik 15-Nov-2024');
A13: ISD/ISD/F/MR/IMPORTS/P/38010/11/2022 | B13: =VLOOKUP(A13,policy!B:C,2,0) -> 040000131738 | C13: -1 | D13: -1 | E13: 13Nov240062 | F13: ="insert into ins_premium_det (premium_rcv_code,assorted_code, rec_amount,premium_rcv_detail_code,remaining_amt, payrec, mode_code,coinsurance_code,class_cd,it_remarks) values" -> insert into ins_premium_det (premium_rcv_code,assorted_code, rec_amount,premium_rcv_detail_code,remaining_amt, payrec, mode_code,coinsurance_code,class_cd,it_remarks) values | G13: ="('"&E13&"','"&B13&"','"&D13&"',(select max(to_number(i.premium_rcv_detail_code))+1 from ins_premium_det i),'"&D13&"','"&D13&"','02', '11000003','00','Request by Mr. Raheel Malik 15-Nov-2024');" -> ('13Nov240062','040000131738','-1',(select max(to_number(i.premium_rcv_detail_code))+1 from ins_premium_det i),'-1','-1','02', '11000003','00','Request by Mr. Raheel Malik 15-Nov-2024'); | H13: =F13&G13 -> insert into ins_premium_det (premium_rcv_code,assorted_code, rec_amount,premium_rcv_detail_code,remaining_amt, payrec, mode_code,coinsurance_code,class_cd,it_remarks) values('13Nov240062','040000131738','-1',(select max(to_number(i.premium_rcv_detail_code))+1 from ins_premium_det i),'-1','-1','02', '11000003','00','Request by Mr. Raheel Malik 15-Nov-2024');
... A2211: KHI/HO/D/MI/TRI/P/6534/11/2022 | B2211: =VLOOKUP(A2211,policy!B:C,2,0) -> 040000130891 | C2211: 590 | D2211: 590 | E2211: 13Nov240062 | F2211: ="insert into ins_premium_det (premium_rcv_code,assorted_code, rec_amount,premium_rcv_detail_code,remaining_amt, payrec, mode_code,coinsurance_code,class_cd,it_remarks) values" -> insert into ins_premium_det (premium_rcv_code,assorted_code, rec_amount,premium_rcv_detail_code,remaining_amt, payrec, mode_code,coinsurance_code,class_cd,it_remarks) values | G2211: ="('"&E2211&"','"&B2211&"','"&D2211&"',(select max(to_number(i.premium_rcv_detail_code))+1 from ins_premium_det i),'"&D2211&"','"&D2211&"','02', '11000003','00','Request by Mr. Raheel Malik 15-Nov-2024');" -> ('13Nov240062','040000130891','590',(select max(to_number(i.premium_rcv_detail_code))+1 from ins_premium_det i),'590','590','02', '11000003','00','Request by Mr. Raheel Malik 15-Nov-2024'); | H2211: =F2211&G2211 -> insert into ins_premium_det (premium_rcv_code,assorted_code, rec_amount,premium_rcv_detail_code,remaining_amt, payrec, mode_code,coinsurance_code,class_cd,it_remarks) values('13Nov240062','040000130891','590',(select max(to_number(i.premium_rcv_detail_code))+1 from ins_premium_det i),'590','590','02', '11000003','00','Request by Mr. Raheel Malik 15-Nov-2024');
A2212: KHI/HO/D/MI/TRI/P/6535/11/2022 | B2212: 040000130892 | C2212: 590 | D2212: 590 | E2212: 13Nov240062 | F2212: ="insert into ins_premium_det (premium_rcv_code,assorted_code, rec_amount,premium_rcv_detail_code,remaining_amt, payrec, mode_code,coinsurance_code,class_cd,it_remarks) values" -> insert into ins_premium_det (premium_rcv_code,assorted_code, rec_amount,premium_rcv_detail_code,remaining_amt, payrec, mode_code,coinsurance_code,class_cd,it_remarks) values | G2212: ="('"&E2212&"','"&B2212&"','"&D2212&"',(select max(to_number(i.premium_rcv_detail_code))+1 from ins_premium_det i),'"&D2212&"','"&D2212&"','02', '11000003','00','Request by Mr. Raheel Malik 15-Nov-2024');" -> ('13Nov240062','040000130892','590',(select max(to_number(i.premium_rcv_detail_code))+1 from ins_premium_det i),'590','590','02', '11000003','00','Request by Mr. Raheel Malik 15-Nov-2024'); | H2212: =F2212&G2212 -> insert into ins_premium_det (premium_rcv_code,assorted_code, rec_amount,premium_rcv_detail_code,remaining_amt, payrec, mode_code,coinsurance_code,class_cd,it_remarks) values('13Nov240062','040000130892','590',(select max(to_number(i.premium_rcv_detail_code))+1 from ins_premium_det i),'590','590','02', '11000003','00','Request by Mr. Raheel Malik 15-Nov-2024');
A2213: MUL/MUL/F/FR/ND/P/12610/10/2021 | B2213: 040000107624 | C2213: 592 | D2213: 592 | E2213: 13Nov240062 | F2213: ="insert into ins_premium_det (premium_rcv_code,assorted_code, rec_amount,premium_rcv_detail_code,remaining_amt, payrec, mode_code,coinsurance_code,class_cd,it_remarks) values" -> insert into ins_premium_det (premium_rcv_code,assorted_code, rec_amount,premium_rcv_detail_code,remaining_amt, payrec, mode_code,coinsurance_code,class_cd,it_remarks) values | G2213: ="('"&E2213&"','"&B2213&"','"&D2213&"',(select max(to_number(i.premium_rcv_detail_code))+1 from ins_premium_det i),'"&D2213&"','"&D2213&"','02', '11000003','00','Request by Mr. Raheel Malik 15-Nov-2024');" -> ('13Nov240062','040000107624','592',(select max(to_number(i.premium_rcv_detail_code))+1 from ins_premium_det i),'592','592','02', '11000003','00','Request by Mr. Raheel Malik 15-Nov-2024'); | H2213: =F2213&G2213 -> insert into ins_premium_det (premium_rcv_code,assorted_code, rec_amount,premium_rcv_detail_code,remaining_amt, payrec, mode_code,coinsurance_code,class_cd,it_remarks) values('13Nov240062','040000107624','592',(select max(to_number(i.premium_rcv_detail_code))+1 from ins_premium_det i),'592','592','02', '11000003','00','Request by Mr. Raheel Malik 15-Nov-2024');
A2214: KHI/HO/D/MI/MP/P/2514/01/2023 | B2214: 040000138279 | C2214: 593 | D2214: 593 | E2214: 13Nov240062 | F2214: ="insert into ins_premium_det (premium_rcv_code,assorted_code, rec_amount,premium_rcv_detail_code,remaining_amt, payrec, mode_code,coinsurance_code,class_cd,it_remarks) values" -> insert into ins_premium_det (premium_rcv_code,assorted_code, rec_amount,premium_rcv_detail_code,remaining_amt, payrec, mode_code,coinsurance_code,class_cd,it_remarks) values | G2214: ="('"&E2214&"','"&B2214&"','"&D2214&"',(select max(to_number(i.premium_rcv_detail_code))+1 from ins_premium_det i),'"&D2214&"','"&D2214&"','02', '11000003','00','Request by Mr. Raheel Malik 15-Nov-2024');" -> ('13Nov240062','040000138279','593',(select max(to_number(i.premium_rcv_detail_code))+1 from ins_premium_det i),'593','593','02', '11000003','00','Request by Mr. Raheel Malik 15-Nov-2024'); | H2214: =F2214&G2214 -> insert into ins_premium_det (premium_rcv_code,assorted_code, rec_amount,premium_rcv_detail_code,remaining_amt, payrec, mode_code,coinsurance_code,class_cd,it_remarks) values('13Nov240062','040000138279','593',(select max(to_number(i.premium_rcv_detail_code))+1 from ins_premium_det i),'593','593','02', '11000003','00','Request by Mr. Raheel Malik 15-Nov-2024');
A2215: KHI/HO/D/MO/PD COMP/P/78292/11/2023 | B2215: 040000157961 | C2215: 593 | D2215: 593 | E2215: 13Nov240062 | F2215: ="insert into ins_premium_det (premium_rcv_code,assorted_code, rec_amount,premium_rcv_detail_code,remaining_amt, payrec, mode_code,coinsurance_code,class_cd,it_remarks) values" -> insert into ins_premium_det (premium_rcv_code,assorted_code, rec_amount,premium_rcv_detail_code,remaining_amt, payrec, mode_code,coinsurance_code,class_cd,it_remarks) values | G2215: ="('"&E2215&"','"&B2215&"','"&D2215&"',(select max(to_number(i.premium_rcv_detail_code))+1 from ins_premium_det i),'"&D2215&"','"&D2215&"','02', '11000003','00','Request by Mr. Raheel Malik 15-Nov-2024');" -> ('13Nov240062','040000157961','593',(select max(to_number(i.premium_rcv_detail_code))+1 from ins_premium_det i),'593','593','02', '11000003','00','Request by Mr. Raheel Malik 15-Nov-2024'); | H2215: =F2215&G2215 -> insert into ins_premium_det (premium_rcv_code,assorted_code, rec_amount,premium_rcv_detail_code,remaining_amt, payrec, mode_code,coinsurance_code,class_cd,it_remarks) values('13Nov240062','040000157961','593',(select max(to_number(i.premium_rcv_detail_code))+1 from ins_premium_det i),'593','593','02', '11000003','00','Request by Mr. Raheel Malik 15-Nov-2024');
A2216: MUL/MUL/F/MI/FG/P/1797/09/2021 | B2216: 040000106538 | C2216: 596 | D2216: 596 | E2216: 13Nov240062 | F2216: ="insert into ins_premium_det (premium_rcv_code,assorted_code, rec_amount,premium_rcv_detail_code,remaining_amt, payrec, mode_code,coinsurance_code,class_cd,it_remarks) values" -> insert into ins_premium_det (premium_rcv_code,assorted_code, rec_amount,premium_rcv_detail_code,remaining_amt, payrec, mode_code,coinsurance_code,class_cd,it_remarks) values | G2216: ="('"&E2216&"','"&B2216&"','"&D2216&"',(select max(to_number(i.premium_rcv_detail_code))+1 from ins_premium_det i),'"&D2216&"','"&D2216&"','02', '11000003','00','Request by Mr. Raheel Malik 15-Nov-2024');" -> ('13Nov240062','040000106538','596',(select max(to_number(i.premium_rcv_detail_code))+1 from ins_premium_det i),'596','596','02', '11000003','00','Request by Mr. Raheel Malik 15-Nov-2024'); | H2216: =F2216&G2216 -> insert into ins_premium_det (premium_rcv_code,assorted_code, rec_amount,premium_rcv_detail_code,remaining_amt, payrec, mode_code,coinsurance_code,class_cd,it_remarks) values('13Nov240062','040000106538','596',(select max(to_number(i.premium_rcv_detail_code))+1 from ins_premium_det i),'596','596','02', '11000003','00','Request by Mr. Raheel Malik 15-Nov-2024');
A2217: KHI/HO/D/MR/IMPORTS/C/18700/10/2023 | B2217: 070000140167 | C2217: 598 | D2217: 598 | E2217: 13Nov240062 | F2217: ="insert into ins_premium_det (premium_rcv_code,assorted_code, rec_amount,premium_rcv_detail_code,remaining_amt, payrec, mode_code,coinsurance_code,class_cd,it_remarks) values" -> insert into ins_premium_det (premium_rcv_code,assorted_code, rec_amount,premium_rcv_detail_code,remaining_amt, payrec, mode_code,coinsurance_code,class_cd,it_remarks) values | G2217: ="('"&E2217&"','"&B2217&"','"&D2217&"',(select max(to_number(i.premium_rcv_detail_code))+1 from ins_premium_det i),'"&D2217&"','"&D2217&"','02', '11000003','00','Request by Mr. Raheel Malik 15-Nov-2024');" -> ('13Nov240062','070000140167','598',(select max(to_number(i.premium_rcv_detail_code))+1 from ins_premium_det i),'598','598','02', '11000003','00','Request by Mr. Raheel Malik 15-Nov-2024'); | H2217: =F2217&G2217 -> insert into ins_premium_det (premium_rcv_code,assorted_code, rec_amount,premium_rcv_detail_code,remaining_amt, payrec, mode_code,coinsurance_code,class_cd,it_remarks) values('13Nov240062','070000140167','598',(select max(to_number(i.premium_rcv_detail_code))+1 from ins_premium_det i),'598','598','02', '11000003','00','Request by Mr. Raheel Malik 15-Nov-2024');
A2218: KHI/HO/D/FR/ND/P/14909/06/2022 | B2218: 040000120596 | C2218: 600 | D2218: 600 | E2218: 13Nov240062 | F2218: ="insert into ins_premium_det (premium_rcv_code,assorted_code, rec_amount,premium_rcv_detail_code,remaining_amt, payrec, mode_code,coinsurance_code,class_cd,it_remarks) values" -> insert into ins_premium_det (premium_rcv_code,assorted_code, rec_amount,premium_rcv_detail_code,remaining_amt, payrec, mode_code,coinsurance_code,class_cd,it_remarks) values | G2218: ="('"&E2218&"','"&B2218&"','"&D2218&"',(select max(to_number(i.premium_rcv_detail_code))+1 from ins_premium_det i),'"&D2218&"','"&D2218&"','02', '11000003','00','Request by Mr. Raheel Malik 15-Nov-2024');" -> ('13Nov240062','040000120596','600',(select max(to_number(i.premium_rcv_detail_code))+1 from ins_premium_det i),'600','600','02', '11000003','00','Request by Mr. Raheel Malik 15-Nov-2024'); | H2218: =F2218&G2218 -> insert into ins_premium_det (premium_rcv_code,assorted_code, rec_amount,premium_rcv_detail_code,remaining_amt, payrec, mode_code,coinsurance_code,class_cd,it_remarks) values('13Nov240062','040000120596','600',(select max(to_number(i.premium_rcv_detail_code))+1 from ins_premium_det i),'600','600','02', '11000003','00','Request by Mr. Raheel Malik 15-Nov-2024');
A2219: KHI/HO/D/MO/PC COMP/C/77027/346/10/2023 | B2219: 070000142596 | C2219: 605 | D2219: 605 | E2219: 13Nov240062 | F2219: ="insert into ins_premium_det (premium_rcv_code,assorted_code, rec_amount,premium_rcv_detail_code,remaining_amt, payrec, mode_code,coinsurance_code,class_cd,it_remarks) values" -> insert into ins_premium_det (premium_rcv_code,assorted_code, rec_amount,premium_rcv_detail_code,remaining_amt, payrec, mode_code,coinsurance_code,class_cd,it_remarks) values | G2219: ="('"&E2219&"','"&B2219&"','"&D2219&"',(select max(to_number(i.premium_rcv_detail_code))+1 from ins_premium_det i),'"&D2219&"','"&D2219&"','02', '11000003','00','Request by Mr. Raheel Malik 15-Nov-2024');" -> ('13Nov240062','070000142596','605',(select max(to_number(i.premium_rcv_detail_code))+1 from ins_premium_det i),'605','605','02', '11000003','00','Request by Mr. Raheel Malik 15-Nov-2024'); | H2219: =F2219&G2219 -> insert into ins_premium_det (premium_rcv_code,assorted_code, rec_amount,premium_rcv_detail_code,remaining_amt, payrec, mode_code,coinsurance_code,class_cd,it_remarks) values('13Nov240062','070000142596','605',(select max(to_number(i.premium_rcv_detail_code))+1 from ins_premium_det i),'605','605','02', '11000003','00','Request by Mr. Raheel Malik 15-Nov-2024');
A2220: KHI/HO/D/MR/IMPORTS/C/18891/11/2023 | B2220: 070000146417 | C2220: 605 | D2220: 605 | E2220: 13Nov240062 | F2220: ="insert into ins_premium_det (premium_rcv_code,assorted_code, rec_amount,premium_rcv_detail_code,remaining_amt, payrec, mode_code,coinsurance_code,class_cd,it_remarks) values" -> insert into ins_premium_det (premium_rcv_code,assorted_code, rec_amount,premium_rcv_detail_code,remaining_amt, payrec, mode_code,coinsurance_code,class_cd,it_remarks) values | G2220: ="('"&E2220&"','"&B2220&"','"&D2220&"',(select max(to_number(i.premium_rcv_detail_code))+1 from ins_premium_det i),'"&D2220&"','"&D2220&"','02', '11000003','00','Request by Mr. Raheel Malik 15-Nov-2024');" -> ('13Nov240062','070000146417','605',(select max(to_number(i.premium_rcv_detail_code))+1 from ins_premium_det i),'605','605','02', '11000003','00','Request by Mr. Raheel Malik 15-Nov-2024'); | H2220: =F2220&G2220 -> insert into ins_premium_det (premium_rcv_code,assorted_code, rec_amount,premium_rcv_detail_code,remaining_amt, payrec, mode_code,coinsurance_code,class_cd,it_remarks) values('13Nov240062','070000146417','605',(select max(to_number(i.premium_rcv_detail_code))+1 from ins_premium_det i),'605','605','02', '11000003','00','Request by Mr. Raheel Malik 15-Nov-2024');
A2221: KHI/HO/D/MO/PD COMP/P/75790/09/2023 | B2221: 040000153863 | C2221: 606 | D2221: 606 | E2221: 13Nov240062 | F2221: ="insert into ins_premium_det (premium_rcv_code,assorted_code, rec_amount,premium_rcv_detail_code,remaining_amt, payrec, mode_code,coinsurance_code,class_cd,it_remarks) values" -> insert into ins_premium_det (premium_rcv_code,assorted_code, rec_amount,premium_rcv_detail_code,remaining_amt, payrec, mode_code,coinsurance_code,class_cd,it_remarks) values | G2221: ="('"&E2221&"','"&B2221&"','"&D2221&"',(select max(to_number(i.premium_rcv_detail_code))+1 from ins_premium_det i),'"&D2221&"','"&D2221&"','02', '11000003','00','Request by Mr. Raheel Malik 15-Nov-2024');" -> ('13Nov240062','040000153863','606',(select max(to_number(i.premium_rcv_detail_code))+1 from ins_premium_det i),'606','606','02', '11000003','00','Request by Mr. Raheel Malik 15-Nov-2024'); | H2221: =F2221&G2221 -> insert into ins_premium_det (premium_rcv_code,assorted_code, rec_amount,premium_rcv_detail_code,remaining_amt, payrec, mode_code,coinsurance_code,class_cd,it_remarks) values('13Nov240062','040000153863','606',(select max(to_number(i.premium_rcv_detail_code))+1 from ins_premium_det i),'606','606','02', '11000003','00','Request by Mr. Raheel Malik 15-Nov-2024');
A2222: MUL/MUL/F/EG/MBD/P/714/01/2022 | B2222: 040000111316 | C2222: 613 | D2222: 613 | E2222: 13Nov240062 | F2222: ="insert into ins_premium_det (premium_rcv_code,assorted_code, rec_amount,premium_rcv_detail_code,remaining_amt, payrec, mode_code,coinsurance_code,class_cd,it_remarks) values" -> insert into ins_premium_det (premium_rcv_code,assorted_code, rec_amount,premium_rcv_detail_code,remaining_amt, payrec, mode_code,coinsurance_code,class_cd,it_remarks) values | G2222: ="('"&E2222&"','"&B2222&"','"&D2222&"',(select max(to_number(i.premium_rcv_detail_code))+1 from ins_premium_det i),'"&D2222&"','"&D2222&"','02', '11000003','00','Request by Mr. Raheel Malik 15-Nov-2024');" -> ('13Nov240062','040000111316','613',(select max(to_number(i.premium_rcv_detail_code))+1 from ins_premium_det i),'613','613','02', '11000003','00','Request by Mr. Raheel Malik 15-Nov-2024'); | H2222: =F2222&G2222 -> insert into ins_premium_det (premium_rcv_code,assorted_code, rec_amount,premium_rcv_detail_code,remaining_amt, payrec, mode_code,coinsurance_code,class_cd,it_remarks) values('13Nov240062','040000111316','613',(select max(to_number(i.premium_rcv_detail_code))+1 from ins_premium_det i),'613','613','02', '11000003','00','Request by Mr. Raheel Malik 15-Nov-2024');
A2223: KHI/HO/D/MO/PD COMP/P/58016/01/2022 | B2223: 040000111178 | C2223: 614 | D2223: 614 | E2223: 13Nov240062 | F2223: ="insert into ins_premium_det (premium_rcv_code,assorted_code, rec_amount,premium_rcv_detail_code,remaining_amt, payrec, mode_code,coinsurance_code,class_cd,it_remarks) values" -> insert into ins_premium_det (premium_rcv_code,assorted_code, rec_amount,premium_rcv_detail_code,remaining_amt, payrec, mode_code,coinsurance_code,class_cd,it_remarks) values | G2223: ="('"&E2223&"','"&B2223&"','"&D2223&"',(select max(to_number(i.premium_rcv_detail_code))+1 from ins_premium_det i),'"&D2223&"','"&D2223&"','02', '11000003','00','Request by Mr. Raheel Malik 15-Nov-2024');" -> ('13Nov240062','040000111178','614',(select max(to_number(i.premium_rcv_detail_code))+1 from ins_premium_det i),'614','614','02', '11000003','00','Request by Mr. Raheel Malik 15-Nov-2024'); | H2223: =F2223&G2223 -> insert into ins_premium_det (premium_rcv_code,assorted_code, rec_amount,premium_rcv_detail_code,remaining_amt, payrec, mode_code,coinsurance_code,class_cd,it_remarks) values('13Nov240062','040000111178','614',(select max(to_number(i.premium_rcv_detail_code))+1 from ins_premium_det i),'614','614','02', '11000003','00','Request by Mr. Raheel Malik 15-Nov-2024');
... A2637: KHI/HO/D/MR/IMPORTS/P/41520/12/2023 | B2637: 040000161493 | C2637: 1000 | D2637: 1000 | E2637: 13Nov240062 | F2637: ="insert into ins_premium_det (premium_rcv_code,assorted_code, rec_amount,premium_rcv_detail_code,remaining_amt, payrec, mode_code,coinsurance_code,class_cd,it_remarks) values" -> insert into ins_premium_det (premium_rcv_code,assorted_code, rec_amount,premium_rcv_detail_code,remaining_amt, payrec, mode_code,coinsurance_code,class_cd,it_remarks) values | G2637: ="('"&E2637&"','"&B2637&"','"&D2637&"',(select max(to_number(i.premium_rcv_detail_code))+1 from ins_premium_det i),'"&D2637&"','"&D2637&"','02', '11000003','00','Request by Mr. Raheel Malik 15-Nov-2024');" -> ('13Nov240062','040000161493','1000',(select max(to_number(i.premium_rcv_detail_code))+1 from ins_premium_det i),'1000','1000','02', '11000003','00','Request by Mr. Raheel Malik 15-Nov-2024'); | H2637: =F2637&G2637 -> insert into ins_premium_det (premium_rcv_code,assorted_code, rec_amount,premium_rcv_detail_code,remaining_amt, payrec, mode_code,coinsurance_code,class_cd,it_remarks) values('13Nov240062','040000161493','1000',(select max(to_number(i.premium_rcv_detail_code))+1 from ins_premium_det i),'1000','1000','02', '11000003','00','Request by Mr. Raheel Malik 15-Nov-2024');
C2639: =SUM(C2:C2637) -> 410970.57 | D2639: =SUM(D2:D2637) -> 410970.57

Sheet Remove
A1: 040000130892 | B1: '040000130892',
A2: 040000107624 | B2: '040000107624',
A3: 040000138279 | B3: '040000138279',
A4: 040000157961 | B4: '040000157961',
A5: 040000106538 | B5: '040000106538',
A6: 070000140167 | B6: '070000140167',
A7: 040000120596 | B7: '040000120596',
A8: 070000142596 | B8: '070000142596',
A9: 070000146417 | B9: '070000146417',
A10: 040000153863 | B10: '040000153863',
A11: 040000111316 | B11: '040000111316',
A12: 040000111178 | B12: '040000111178',
... A426: 040000161493 | B426: '040000161493',
D427: total | E427: remove
D428: 2636 | E428: 426 | F428: =D428-E428 -> 2210

Sheet Sheet3
C1: PC | E1: E
A2: MUL/MUL/F/FR/D/P/12471/09/2021 | B2: -09-2021 | C2: P | D2: 12471 | E2: ="ia.assorted_string like '%"&D2&B2&"%' or" -> ia.assorted_string like '%12471-09-2021%' or
A3: KHI/HO/D/MO/PC COMP/P/73118/07/2023 | B3: -07-2023 | C3: P | D3: 73118 | E3: ="ia.assorted_string like '%"&D3&B3&"%' or" -> ia.assorted_string like '%73118-07-2023%' or
A4: MUL/MUL/F/FR/D/P/13574/12/2021 | B4: -12-2021 | C4: P | D4: 13574 | E4: ="ia.assorted_string like '%"&D4&B4&"%' or" -> ia.assorted_string like '%13574-12-2021%' or
A5: MUL/MUL/F/FR/ND/P/13059/11/2021 | B5: -11-2021 | C5: P | D5: 13059 | E5: ="ia.assorted_string like '%"&D5&B5&"%' or" -> ia.assorted_string like '%13059-11-2021%' or
A6: MUL/MUL/F/FR/ND/P/13084/11/2021 | B6: -11-2021 | C6: P | D6: 13084 | E6: ="ia.assorted_string like '%"&D6&B6&"%' or" -> ia.assorted_string like '%13084-11-2021%' or
A7: MUL/MUL/F/FR/ND/P/13122/11/2021 | B7: -11-2021 | C7: P | D7: 13122 | E7: ="ia.assorted_string like '%"&D7&B7&"%' or" -> ia.assorted_string like '%13122-11-2021%' or
A8: KHI/HO/D/MO/PC COMP/P/69597/04/2023 | B8: -04-2023 | C8: P | D8: 69597 | E8: ="ia.assorted_string like '%"&D8&B8&"%' or" -> ia.assorted_string like '%69597-04-2023%' or
A9: MUL/MUL/F/FR/ND/P/12988/11/2021 | B9: -11-2021 | C9: P | D9: 12988 | E9: ="ia.assorted_string like '%"&D9&B9&"%' or" -> ia.assorted_string like '%12988-11-2021%' or
A10: MUL/MUL/F/FR/ND/P/13081/11/2021 | B10: -11-2021 | C10: P | D10: 13081 | E10: ="ia.assorted_string like '%"&D10&B10&"%' or" -> ia.assorted_string like '%13081-11-2021%' or
A11: MUL/MUL/F/FR/ND/P/13116/11/2021 | B11: -11-2021 | C11: P | D11: 13116 | E11: ="ia.assorted_string like '%"&D11&B11&"%' or" -> ia.assorted_string like '%13116-11-2021%' or
A12: MUL/MUL/F/FR/ND/P/13567/12/2021 | B12: -12-2021 | C12: P | D12: 13567 | E12: ="ia.assorted_string like '%"&D12&B12&"%' or" -> ia.assorted_string like '%13567-12-2021%' or
A13: ISD/ISD/F/MR/IMPORTS/P/38010/11/2022 | B13: -11-2022 | C13: P | D13: 38010 | E13: ="ia.assorted_string like '%"&D13&B13&"%' or" -> ia.assorted_string like '%38010-11-2022%' or
A14: ISD/ISD/F/MR/IMPORTS/P/38026/11/2022 | B14: -11-2022 | C14: P | D14: 38026 | E14: ="ia.assorted_string like '%"&D14&B14&"%' or" -> ia.assorted_string like '%38026-11-2022%' or
A15: KHI/HO/D/MO/PC COMP/C/63286/34/09/2022 | B15: -09-2022 | C15: C | D15: 63286 | E15: 00034 | F15: ="ia.assorted_string like '%"&D15&"-"&E15&B15&"%' or" -> ia.assorted_string like '%63286-00034-09-2022%' or
A16: KHI/HO/D/MO/PC COMP/C/64350/1/10/2022 | B16: -10-2022 | C16: C | D16: 64350 | E16: 00001 | F16: ="ia.assorted_string like '%"&D16&"-"&E16&B16&"%' or" -> ia.assorted_string like '%64350-00001-10-2022%' or
A17: KHI/HO/D/MO/PC COMP/C/64383/1/10/2022 | B17: -10-2022 | C17: C | D17: 64383 | E17: 00001 | F17: ="ia.assorted_string like '%"&D17&"-"&E17&B17&"%' or" -> ia.assorted_string like '%64383-00001-10-2022%' or
A18: KHI/HO/D/MO/PC COMP/C/64389/1/10/2022 | B18: -10-2022 | C18: C | D18: 64389 | E18: 00001 | F18: ="ia.assorted_string like '%"&D18&"-"&E18&B18&"%' or" -> ia.assorted_string like '%64389-00001-10-2022%' or
A19: KHI/HO/D/MO/PC COMP/C/64794/68/11/2022 | B19: -11-2022 | C19: C | D19: 64794 | E19: 00068 | F19: ="ia.assorted_string like '%"&D19&"-"&E19&B19&"%' or" -> ia.assorted_string like '%64794-00068-11-2022%' or
A20: KHI/HO/D/MO/PC COMP/C/65057/1/11/2022 | B20: -11-2022 | C20: C | D20: 65057 | E20: 00001 | F20: ="ia.assorted_string like '%"&D20&"-"&E20&B20&"%' or" -> ia.assorted_string like '%65057-00001-11-2022%' or
A21: KHI/HO/D/MO/PC COMP/C/65057/139/11/2022 | B21: -11-2022 | C21: C | D21: 65057 | E21: 00139 | F21: ="ia.assorted_string like '%"&D21&"-"&E21&B21&"%' or" -> ia.assorted_string like '%65057-00139-11-2022%' or
A22: KHI/HO/D/MO/PC COMP/C/65057/172/11/2022 | B22: -11-2022 | C22: C | D22: 65057 | E22: 00172 | F22: ="ia.assorted_string like '%"&D22&"-"&E22&B22&"%' or" -> ia.assorted_string like '%65057-00172-11-2022%' or
A23: KHI/HO/D/MO/PC COMP/C/65057/190/11/2022 | B23: -11-2022 | C23: C | D23: 65057 | E23: 00190 | F23: ="ia.assorted_string like '%"&D23&"-"&E23&B23&"%' or" -> ia.assorted_string like '%65057-00190-11-2022%' or
A24: KHI/HO/D/MO/PC COMP/C/65057/21/11/2022 | B24: -11-2022 | C24: C | D24: 65057 | E24: 00021 | F24: ="ia.assorted_string like '%"&D24&"-"&E24&B24&"%' or" -> ia.assorted_string like '%65057-00021-11-2022%' or
A25: KHI/HO/D/MO/PC COMP/C/65057/250/11/2022 | B25: -11-2022 | C25: C | D25: 65057 | E25: 00250 | F25: ="ia.assorted_string like '%"&D25&"-"&E25&B25&"%' or" -> ia.assorted_string like '%65057-00250-11-2022%' or
A26: KHI/HO/D/MO/PC COMP/C/65057/325/11/2022 | B26: -11-2022 | C26: C | D26: 65057 | E26: 00325 | F26: ="ia.assorted_string like '%"&D26&"-"&E26&B26&"%' or" -> ia.assorted_string like '%65057-00325-11-2022%' or
... A69: KHI/HO/D/MO/PC COMP/C/68699/99/03/2023 | B69: -03-2023 | C69: C | D69: 68699 | E69: 00099 | F69: ="ia.assorted_string like '%"&D69&"-"&E69&B69&"%' or" -> ia.assorted_string like '%68699-00099-03-2023%' or
A70: KHI/HO/D/MO/PC COMP/P/64394/10/2022 | B70: -10-2022 | C70: P | D70: 64394 | E70: ="ia.assorted_string like '%"&D70&B70&"%' or" -> ia.assorted_string like '%64394-10-2022%' or
A71: KHI/HO/D/MO/PC COMP/P/66872/01/2023 | B71: -01-2023 | C71: P | D71: 66872 | E71: ="ia.assorted_string like '%"&D71&B71&"%' or" -> ia.assorted_string like '%66872-01-2023%' or
A72: KHI/HO/D/MO/PC COMP/P/75915/09/2023 | B72: -09-2023 | C72: P | D72: 75915 | E72: ="ia.assorted_string like '%"&D72&B72&"%' or" -> ia.assorted_string like '%75915-09-2023%' or
A73: KHI/HO/D/MO/PC COMP/P/77977/11/2023 | B73: -11-2023 | C73: P | D73: 77977 | E73: ="ia.assorted_string like '%"&D73&B73&"%' or" -> ia.assorted_string like '%77977-11-2023%' or
A74: KHI/HO/F/FR/ND/P/13179/12/2021 | B74: -12-2021 | C74: P | D74: 13179 | E74: ="ia.assorted_string like '%"&D74&B74&"%' or" -> ia.assorted_string like '%13179-12-2021%' or
A75: LHR/LHR/D/MO/PC COMP/P/60625/05/2022 | B75: -05-2022 | C75: P | D75: 60625 | E75: ="ia.assorted_string like '%"&D75&B75&"%' or" -> ia.assorted_string like '%60625-05-2022%' or
A76: MUL/MUL/F/FR/D/P/13120/11/2021 | B76: -11-2021 | C76: P | D76: 13120 | E76: ="ia.assorted_string like '%"&D76&B76&"%' or" -> ia.assorted_string like '%13120-11-2021%' or
A77: MUL/MUL/F/FR/ND/P/12524/09/2021 | B77: -09-2021 | C77: P | D77: 12524 | E77: ="ia.assorted_string like '%"&D77&B77&"%' or" -> ia.assorted_string like '%12524-09-2021%' or
A78: MUL/MUL/F/FR/ND/P/12611/10/2021 | B78: -10-2021 | C78: P | D78: 12611 | E78: ="ia.assorted_string like '%"&D78&B78&"%' or" -> ia.assorted_string like '%12611-10-2021%' or
A79: MUL/MUL/F/FR/ND/P/12983/11/2021 | B79: -11-2021 | C79: P | D79: 12983 | E79: ="ia.assorted_string like '%"&D79&B79&"%' or" -> ia.assorted_string like '%12983-11-2021%' or
A80: MUL/MUL/F/FR/ND/P/13025/11/2021 | B80: -11-2021 | C80: P | D80: 13025 | E80: ="ia.assorted_string like '%"&D80&B80&"%' or" -> ia.assorted_string like '%13025-11-2021%' or
A81: MUL/MUL/F/FR/ND/P/13060/11/2021 | B81: -11-2021 | C81: P | D81: 13060 | E81: ="ia.assorted_string like '%"&D81&B81&"%' or" -> ia.assorted_string like '%13060-11-2021%' or
... A255: KHI/HO/D/MI/TRI/P/5801/10/2022 | B255: -10-2022 | C255: P | D255: 5801 | E255: ="ia.assorted_string like '%"&D255&B255&"%' or" -> ia.assorted_string like '%5801-10-2022%' or
...

Sheet policy
B1: FUNC_ASSORTED_STRING(IA.ASSORTED_CODE) | C1: ASSORTED_CODE
A2: 1 | B2: KHI/HO/D/MO/PC COMP/C/58470/167/02/2022 | C2: 070000094004
A3: =A2+1 -> 2 | B3: KHI/HO/D/MO/PC COMP/C/5192/02/2022 | C3: 020000024176
A4: =A3+1 -> 3 | B4: MUL/MUL/F/FR/ND/P/13084/11/2021 | C4: 040000108917
A5: =A4+1 -> 4 | B5: KHI/HO/D/MO/PC COMP/C/59294/284/03/2022 | C5: 070000097302
A6: =A5+1 -> 5 | B6: KHI/HO/D/MI/TRI/P/116/02/2022 | C6: 040000112435
A7: =A6+1 -> 6 | B7: KHI/HO/D/MI/TRI/P/130/02/2022 | C7: 040000112531
A8: =A7+1 -> 7 | B8: KHI/HO/D/MO/PC COMP/C/58470/221/02/2022 | C8: 070000094835
A9: =A8+1 -> 8 | B9: KHI/HO/D/MR/EXPORTS/P/36116/02/2022 | C9: 040000112349
A10: =A9+1 -> 9 | B10: MUL/MUL/F/FR/ND/P/12983/11/2021 | C10: 040000108321
A11: =A10+1 -> 10 | B11: MUL/MUL/F/FR/ND/P/12611/10/2021 | C11: 040000107626
A12: =A11+1 -> 11 | B12: KHI/HO/D/MR/IMPORTS/P/36167/02/2022 | C12: 040000112768
A13: =A12+1 -> 12 | B13: LHR/LHR/D/MO/PC COMP/P/59222/02/2022 | C13: 040000113309
A14: =A13+1 -> 13 | B14: KHI/HO/D/MO/PC COMP/C/58935/113/02/2022 | C14: 070000093846
... A5692: =A5691+1 -> 5691 | B5692: KHI/HO/D/MO/PC COMP/C/71203/73/05/2023 | C5692: 070000130331
