Workbook

Sheet STL 3 QTR
A2: CCR FLEET COMPREHENSIVELY INSURED FROM SALAAM TAKAFUL LTD
A3: FOR THE PERIOD 01 JAN 2024 - 31 DEC 2024 @1.65%
A4: CONVENTIONAL FLEET 3 QTR (JULY - SEPT 2024)
A5: Sr. | B5: Make | C5: Regn # | D5: Engine # | E5: Chassis # | F5: Colour | G5: Owner | H5: Model | I5: Sum Insu. | J5: Days | K5: Start Dt. | L5: End Dt | M5: Annual Premium | N5: 3rd Quartar 92 Days | O5: Policy #
A6: 1 | B6: HONDA CIVIC i-VTEC NAVIGATION | C6: BPX -211 | D6: R18Z12949760 | E6: NFBFC6661KR053248 | F6: White | G6: Capital Car Rental Pvt Ltd | H6: 2019 | I6: 3200000 | J6: 366 | K6: 45292 | L6: 45657 | M6: =I6*1.65% -> 52800 | N6: 13272.131 | O6: KHI/HO/D/MO/PC TPP/P/82548/01/2024
A7: 2 | B7: HONDA CIVIC i-VTEC NAVIGATION | C7: BPX-212 | D7: R18Z12949755 | E7: NFBFC666XKR053247 | F7: White | G7: Capital Car Rental Pvt Ltd | H7: 2019 | I7: 3200000 | J7: 366 | K7: 45292 | L7: 45657 | M7: =I7*1.65% -> 52800 | N7: 13272.131 | O7: KHI/HO/D/MO/PC TPP/P/82548/01/2024
A8: 3 | B8: HONDA CIVIC i-VTEC ORIEL | C8: ANC-962 | D8: R18Z12950285 | E8: NFBFC6665KR053754 | F8: White | G8: Capital Car Rental Pvt Ltd | H8: 2019 | I8: 3200000 | J8: 366 | K8: 45292 | L8: 45657 | M8: =I8*1.65% -> 52800 | N8: 13272.131 | O8: KHI/HO/D/MO/PC TPP/P/82548/01/2024
A9: 4 | B9: HONDA CIVIC i-VTEC ORIEL | C9: ANC-958 | D9: R18Z12950276 | E9: NFBFC6667KR053755 | F9: White | G9: Capital Car Rental Pvt Ltd | H9: 2019 | I9: 3200000 | J9: 366 | K9: 45292 | L9: 45657 | M9: =I9*1.65% -> 52800 | N9: 13272.131 | O9: KHI/HO/D/MO/PC TPP/P/82548/01/2024
A10: 5 | B10: HONDA CIVIC i-VTEC ORIEL | C10: ANX-651 | D10: R18Z12953579 | E10: NFBFC666XKR056990 | F10: White | G10: Capital Car Rental Pvt Ltd | H10: 2019 | I10: 3200000 | J10: 366 | K10: 45292 | L10: 45657 | M10: =I10*1.65% -> 52800 | N10: 13272.131 | O10: KHI/HO/D/MO/PC TPP/P/82548/01/2024
A11: 6 | B11: HONDA CIVIC i-VTEC ORIEL | C11: ANX-653 | D11: R18Z12953578 | E11: NFBFC6663KR056989 | F11: White | G11: Capital Car Rental Pvt Ltd | H11: 2019 | I11: 3200000 | J11: 366 | K11: 45292 | L11: 45657 | M11: =I11*1.65% -> 52800 | N11: 13272.131 | O11: KHI/HO/D/MO/PC TPP/P/82548/01/2024
A12: 7 | B12: HONDA CIVIC i-VTEC ORIEL | C12: APS-641 | D12: R18Z12953375 | E12: NFBFC6661KR056795 | F12: White | G12: Capital Car Rental Pvt Ltd | H12: 2019 | I12: 3200000 | J12: 366 | K12: 45292 | L12: 45657 | M12: =I12*1.65% -> 52800 | N12: 13272.131 | O12: KHI/HO/D/MO/PC TPP/P/82548/01/2024
A13: 8 | B13: HONDA CIVIC i-VTEC ORIEL | C13: APS-642 | D13: R18Z12953610 | E13: NFBFC6664KR057035 | F13: White | G13: Capital Car Rental Pvt Ltd | H13: 2019 | I13: 3200000 | J13: 366 | K13: 45292 | L13: 45657 | M13: =I13*1.65% -> 52800 | N13: 13272.131 | O13: KHI/HO/D/MO/PC TPP/P/82548/01/2024
A14: 9 | B14: HONDA CIVIC i-VTEC ORIEL | C14: APT-751 | D14: R18Z12953973 | E14: NFBFC6665KR057447 | F14: White | G14: Capital Car Rental Pvt Ltd | H14: 2019 | I14: 3200000 | J14: 366 | K14: 45292 | L14: 45657 | M14: =I14*1.65% -> 52800 | N14: 13272.131 | O14: KHI/HO/D/MO/PC TPP/P/82548/01/2024
A15: 10 | B15: HONDA CIVIC i-VTEC ORIEL | C15: APT-752 | D15: R18Z12954109 | E15: NFBFC6663KR057575 | F15: White | G15: Capital Car Rental Pvt Ltd | H15: 2019 | I15: 3200000 | J15: 366 | K15: 45292 | L15: 45657 | M15: =I15*1.65% -> 52800 | N15: 13272.131 | O15: KHI/HO/D/MO/PC TPP/P/82548/01/2024
A16: 11 | B16: HONDA CIVIC i-VTEC ORIEL | C16: APG-636 | D16: R18Z12954460 | E16: NFBFC6668KR057944 | F16: White | G16: Capital Car Rental Pvt Ltd | H16: 2019 | I16: 3200000 | J16: 366 | K16: 45292 | L16: 45657 | M16: =I16*1.65% -> 52800 | N16: 13272.131 | O16: KHI/HO/D/MO/PC TPP/P/82549/01/2024
A17: 12 | B17: HONDA CIVIC i-VTEC ORIEL | C17: APG-676 | D17: R18Z12953514 | E17: NFBFC6662KR056918 | F17: White | G17: Capital Car Rental Pvt Ltd | H17: 2019 | I17: 3200000 | J17: 366 | K17: 45292 | L17: 45657 | M17: =I17*1.65% -> 52800 | N17: 13272.131 | O17: KHI/HO/D/MO/PC TPP/P/82549/01/2024
... A91: 86 | B91: YARIS 662B 1.3 CVT | C91: BTG-225 | D91: 2A21954 | E91: NSP150R-7012966 | F91: White | G91: Capital Car Rental Pvt Ltd | H91: 2021 | I91: 2655000 | J91: 366 | K91: 45292 | L91: 45657 | M91: =I91*1.65% -> 43807.5 | N91: 11011.721 | O91: KHI/HO/D/MO/PC TPP/P/82546/01/2024
A92: 87 | B92: MOTOR CYCLE CD 70 | C92: ALX-6971 | D92: E321153 | E92: GH963691 | F92: RED | G92: Capital Car Rental Pvt Ltd | H92: 2022 | I92: 100000 | J92: 366 | K92: 45292 | L92: 45657 | M92: =I92*5% -> 5000 | N92: 1256.8306 | O92: KHI/HO/D/MO/PC TPP/P/82555/01/2024
A93: 88 | B93: REVO645B 4X4 G AT | C93: LB-0261 | D93: IGD5114315 | E93: GUN126R-5551343 | F93: White | G93: Habib Bank Ltd | H93: 2022 | I93: 7154500 | J93: 366 | K93: 45292 | L93: 45657 | M93: =I93*1.65% -> 118049.25 | N93: 29673.582 | O93: KHI/HO/D/MO/PC TPP/P/85556/03/2024
A94: 89 | B94: REVO645B 4X4 G AT | C94: LB-0262 | D94: IGD5114316 | E94: GUN126R-5551503 | F94: White | G94: Habib Bank Ltd | H94: 2022 | I94: 7154500 | J94: 366 | K94: 45292 | L94: 45657 | M94: =I94*1.65% -> 118049.25 | N94: 29673.582 | O94: KHI/HO/D/MO/PC TPP/P/85556/03/2024
A95: 90 | B95: REVO645B 4X4 G AT | C95: LB-0263 | D95: IGD5114308 | E95: GUN126R-5551517 | F95: White | G95: Habib Bank Ltd | H95: 2022 | I95: 7154500 | J95: 366 | K95: 45292 | L95: 45657 | M95: =I95*1.65% -> 118049.25 | N95: 29673.582 | O95: KHI/HO/D/MO/PC TPP/P/85556/03/2024
A96: 91 | B96: REVO645B 4X4 G AT | C96: LB-0327 | D96: IGD5114093 | E96: GUN126R-5551421 | F96: White | G96: Habib Bank Ltd | H96: 2022 | I96: 7154500 | J96: 366 | K96: 45292 | L96: 45657 | M96: =I96*1.65% -> 118049.25 | N96: 29673.582 | O96: KHI/HO/D/MO/PC TPP/P/85556/03/2024
A97: 92 | B97: REVO645B 4X4 G AT | C97: LD-0578 | D97: IGD5316814 | E97: GUN126R-5559951 | F97: White | G97: Capital Car Rental Pvt Ltd | H97: 2023 | I97: 14164200 | J97: 366 | K97: 45292 | L97: 45657 | M97: =I97*1.65% -> 233709.3 | N97: 58746.6 | O97: KHI/HO/D/MO/PC TPP/P/82550/01/2024
A98: 93 | B98: HONDA CIVIC i-VTEC ORIEL (NAV-SR) | C98: BVR-336 | D98: R18Z16931050 | E98: NFBFC6668NR083643 | F98: White | G98: Habib Bank Ltd | H98: 2022 | I98: 4275000 | J98: 366 | K98: 45292 | L98: 45657 | M98: =I98*1.65% -> 70537.5 | N98: 17730.738 | O98: KHI/HO/D/MO/PC TPP/P/85556/03/2024
A99: 94 | B99: HONDA CIVIC i-VTEC ORIEL (NAV-SR) | C99: BVR-337 | D99: R18Z16931222 | E99: NFBFC6666NR083804 | F99: White | G99: Habib Bank Ltd | H99: 2022 | I99: 4275000 | J99: 366 | K99: 45292 | L99: 45657 | M99: =I99*1.65% -> 70537.5 | N99: 17730.738 | O99: KHI/HO/D/MO/PC TPP/P/85556/03/2024
A100: 95 | B100: YARIS 662B 1.3 HCVT | C100: ANK-633 | D100: 2A58840 | E100: NSP150R-7037409 | F100: White | G100: Toyota Jhelum Motors Pvt Ltd | H100: 2023 | I100: 4052500 | J100: 366 | K100: 45292 | L100: 45657 | M100: =I100*1.65% -> 66866.25 | N100: 16807.91 | O100: KHI/HO/D/MO/PC TPP/P/82552/01/2024
A101: 96 | B101: YARIS 662B 1.3 HCVT | C101: ANK-668 | D101: 2A58843 | E101: NSP150R-7037410 | F101: White | G101: Toyota Jhelum Motors Pvt Ltd | H101: 2023 | I101: 4052500 | J101: 366 | K101: 45292 | L101: 45657 | M101: =I101*1.65% -> 66866.25 | N101: 16807.91 | O101: KHI/HO/D/MO/PC TPP/P/82552/01/2024
A102: 97 | B102: YARIS 662B ATIV X CVT (1.5) | C102: ANE-144 | D102: 2A57875 | E102: NSP151R-9521221 | F102: White | G102: Toyota Jhelum Motors Pvt Ltd | H102: 2022 | I102: 4382500 | J102: 366 | K102: 45292 | L102: 45657 | M102: =I102*1.65% -> 72311.25 | N102: 18176.598 | O102: KHI/HO/D/MO/PC TPP/P/82552/01/2024
A103: 98 | B103: YARIS 662B ATIV X CVT (1.5) | C103: ANE-574 | D103: 2A57874 | E103: NSP151R-9521219 | F103: White | G103: Toyota Jhelum Motors Pvt Ltd | H103: 2022 | I103: 4382500 | J103: 366 | K103: 45292 | L103: 45657 | M103: =I103*1.65% -> 72311.25 | N103: 18176.598 | O103: KHI/HO/D/MO/PC TPP/P/82552/01/2024
A104: 99 | B104: YARIS 662B ATIV X CVT (1.5) | C104: ANJ-877 | D104: 2A57849 | E104: NSP151R-9521209 | F104: White | G104: Toyota Jhelum Motors Pvt Ltd | H104: 2022 | I104: 4382500 | J104: 366 | K104: 45292 | L104: 45657 | M104: =I104*1.65% -> 72311.25 | N104: 18176.598 | O104: KHI/HO/D/MO/PC TPP/P/82552/01/2024
A105: 100 | B105: ALTIS 1.6 CVT M22 | C105: ARH-544 | D105: Q107370 | E105: ZRE171R-6084866 | F105: White | G105: Toyota Jhelum Motors Pvt Ltd | H105: 2024 | I105: 7324000 | J105: 272 | K105: 45385 | L105: 45657 | M105: =I105*1.65%/366*272 -> 89809.049 | N105: 30376.59 | O105: KHI/HO/D/MO/PC TPP/P/86642/04/2024
A106: 101 | B106: YARIS 662B 1.3 CVT | C106: ARA-309 | D106: 2A65365 | E106: NSP150R-7042982 | F106: White | G106: Capital Car Rental Pvt Ltd | H106: 2024 | I106: 4819500 | J106: =366-31-29-12 -> 294 | K106: 45364 | L106: 45657 | M106: =I106*1.65%/366*294 -> 63878.127 | N106: 19989.074 | O106: KHI/HO/D/MO/PC TPP/P/85423/03/2024
A107: 102 | B107: YARIS 662B 1.3 CVT | C107: ARA-361 | D107: 2A65297 | E107: NSP150R-7042922 | F107: White | G107: Capital Car Rental Pvt Ltd | H107: 2024 | I107: 4819500 | J107: =366-31-29-12 -> 294 | K107: 45364 | L107: 45657 | M107: =I107*1.65%/366*294 -> 63878.127 | N107: 19989.074 | O107: KHI/HO/D/MO/PC TPP/P/85423/03/2024
A108: 103 | B108: YARIS 662B 1.3 CVT | C108: ARA-723 | D108: 2A65294 | E108: NSP150R-7042938 | F108: White | G108: Capital Car Rental Pvt Ltd | H108: 2024 | I108: 4819500 | J108: =366-31-29-12 -> 294 | K108: 45364 | L108: 45657 | M108: =I108*1.65%/366*294 -> 63878.127 | N108: 19989.074 | O108: KHI/HO/D/MO/PC TPP/P/85423/03/2024
A109: 104 | B109: YARIS 662B 1.3 CVT | C109: ARA-731 | D109: 2A65305 | E109: NSP150R-7042926 | F109: White | G109: Capital Car Rental Pvt Ltd | H109: 2024 | I109: 4819500 | J109: =366-31-29-12 -> 294 | K109: 45364 | L109: 45657 | M109: =I109*1.65%/366*294 -> 63878.127 | N109: 19989.074 | O109: KHI/HO/D/MO/PC TPP/P/85423/03/2024
A110: 105 | B110: YARIS 662B 1.3 CVT | C110: ARA-790 | D110: 2A65298 | E110: NSP150R-7042924 | F110: White | G110: Capital Car Rental Pvt Ltd | H110: 2024 | I110: 4819500 | J110: =366-31-29-12 -> 294 | K110: 45364 | L110: 45657 | M110: =I110*1.65%/366*294 -> 63878.127 | N110: 19989.074 | O110: KHI/HO/D/MO/PC TPP/P/85423/03/2024
A111: 106 | B111: Corolla Cross 164/D/942W HV 1.8X 1799cc | C111: ASA-854 | D111: 9Z04472 | E111: ZVG10R-0903387 | F111: White | G111: Capital Car Rental Pvt Ltd | H111: 2024 | I111: 10084000 | J111: =366-31-29-31-30-31-7 -> 207 | K111: 45450 | L111: 45657 | M111: =I111*1.65%/366*207 -> 94103.557 | N111: 41823.803 | O111: KHI/HO/D/MO/PC TPP/P/82546/01/2024
B112: Corolla Cross 164/D/942W HV 1.8X 1799cc | C112: ASA-854 | D112: 9Z04472 | E112: ZVG10R-0903387 | F112: White | G112: Capital Car Rental Pvt Ltd | H112: 2024 | I112: 10084000 | J112: =366-31-29-31-30-31-7 -> 207 | K112: 45450 | L112: 45657 | M112: 2 Qtr payment | N112: 10456 | O112: KHI/HO/D/MO/PC TPP/P/82546/01/2024
M113: =SUM(M6:M112) -> 5574293.3 | N113: =SUM(N6:N112) -> 1457276.9
A116: SOLD OUT VEHICLES DETAIL
...

Sheet working
A1: POLICY NO. | B1: Assorted_code | D1: Premium | E1: 14Nov240007
A2: KHI/HO/D/MO/PC TPP/P/82548/01/2024 | B2: =VLOOKUP(A2,policy!B:C,2,0) -> 040000164225 | C2: 13272.131 | D2: =ROUND(C2,0) -> 13272 | E2: 14Nov240007 | F2: ="insert into ins_premium_det (premium_rcv_code,assorted_code, rec_amount,premium_rcv_detail_code,remaining_amt, payrec, mode_code,coinsurance_code,class_cd,it_remarks) values" -> insert into ins_premium_det (premium_rcv_code,assorted_code, rec_amount,premium_rcv_detail_code,remaining_amt, payrec, mode_code,coinsurance_code,class_cd,it_remarks) values | G2: ="('"&E2&"','"&B2&"','"&D2&"',(select max(to_number(i.premium_rcv_detail_code))+1 from ins_premium_det i),'"&D2&"','"&D2&"','02', '11000003','00','Request by Mr. Saqib Saleem 15-Nov-2024');" -> ('14Nov240007','040000164225','13272',(select max(to_number(i.premium_rcv_detail_code))+1 from ins_premium_det i),'13272','13272','02', '11000003','00','Request by Mr. Saqib Saleem 15-Nov-2024'); | H2: =F2&G2 -> insert into ins_premium_det (premium_rcv_code,assorted_code, rec_amount,premium_rcv_detail_code,remaining_amt, payrec, mode_code,coinsurance_code,class_cd,it_remarks) values('14Nov240007','040000164225','13272',(select max(to_number(i.premium_rcv_detail_code))+1 from ins_premium_det i),'13272','13272','02', '11000003','00','Request by Mr. Saqib Saleem 15-Nov-2024');
A3: KHI/HO/D/MO/PC TPP/P/82548/01/2024 | B3: =VLOOKUP(A3,policy!B:C,2,0) -> 040000164225 | C3: 13272.131 | D3: =ROUND(C3,0) -> 13272 | E3: 14Nov240007 | F3: ="insert into ins_premium_det (premium_rcv_code,assorted_code, rec_amount,premium_rcv_detail_code,remaining_amt, payrec, mode_code,coinsurance_code,class_cd,it_remarks) values" -> insert into ins_premium_det (premium_rcv_code,assorted_code, rec_amount,premium_rcv_detail_code,remaining_amt, payrec, mode_code,coinsurance_code,class_cd,it_remarks) values | G3: ="('"&E3&"','"&B3&"','"&D3&"',(select max(to_number(i.premium_rcv_detail_code))+1 from ins_premium_det i),'"&D3&"','"&D3&"','02', '11000003','00','Request by Mr. Saqib Saleem 15-Nov-2024');" -> ('14Nov240007','040000164225','13272',(select max(to_number(i.premium_rcv_detail_code))+1 from ins_premium_det i),'13272','13272','02', '11000003','00','Request by Mr. Saqib Saleem 15-Nov-2024'); | H3: =F3&G3 -> insert into ins_premium_det (premium_rcv_code,assorted_code, rec_amount,premium_rcv_detail_code,remaining_amt, payrec, mode_code,coinsurance_code,class_cd,it_remarks) values('14Nov240007','040000164225','13272',(select max(to_number(i.premium_rcv_detail_code))+1 from ins_premium_det i),'13272','13272','02', '11000003','00','Request by Mr. Saqib Saleem 15-Nov-2024');
A4: KHI/HO/D/MO/PC TPP/P/82548/01/2024 | B4: =VLOOKUP(A4,policy!B:C,2,0) -> 040000164225 | C4: 13272.131 | D4: =ROUND(C4,0) -> 13272 | E4: 14Nov240007 | F4: ="insert into ins_premium_det (premium_rcv_code,assorted_code, rec_amount,premium_rcv_detail_code,remaining_amt, payrec, mode_code,coinsurance_code,class_cd,it_remarks) values" -> insert into ins_premium_det (premium_rcv_code,assorted_code, rec_amount,premium_rcv_detail_code,remaining_amt, payrec, mode_code,coinsurance_code,class_cd,it_remarks) values | G4: ="('"&E4&"','"&B4&"','"&D4&"',(select max(to_number(i.premium_rcv_detail_code))+1 from ins_premium_det i),'"&D4&"','"&D4&"','02', '11000003','00','Request by Mr. Saqib Saleem 15-Nov-2024');" -> ('14Nov240007','040000164225','13272',(select max(to_number(i.premium_rcv_detail_code))+1 from ins_premium_det i),'13272','13272','02', '11000003','00','Request by Mr. Saqib Saleem 15-Nov-2024'); | H4: =F4&G4 -> insert into ins_premium_det (premium_rcv_code,assorted_code, rec_amount,premium_rcv_detail_code,remaining_amt, payrec, mode_code,coinsurance_code,class_cd,it_remarks) values('14Nov240007','040000164225','13272',(select max(to_number(i.premium_rcv_detail_code))+1 from ins_premium_det i),'13272','13272','02', '11000003','00','Request by Mr. Saqib Saleem 15-Nov-2024');
A5: KHI/HO/D/MO/PC TPP/P/82548/01/2024 | B5: =VLOOKUP(A5,policy!B:C,2,0) -> 040000164225 | C5: 13272.131 | D5: =ROUND(C5,0) -> 13272 | E5: 14Nov240007 | F5: ="insert into ins_premium_det (premium_rcv_code,assorted_code, rec_amount,premium_rcv_detail_code,remaining_amt, payrec, mode_code,coinsurance_code,class_cd,it_remarks) values" -> insert into ins_premium_det (premium_rcv_code,assorted_code, rec_amount,premium_rcv_detail_code,remaining_amt, payrec, mode_code,coinsurance_code,class_cd,it_remarks) values | G5: ="('"&E5&"','"&B5&"','"&D5&"',(select max(to_number(i.premium_rcv_detail_code))+1 from ins_premium_det i),'"&D5&"','"&D5&"','02', '11000003','00','Request by Mr. Saqib Saleem 15-Nov-2024');" -> ('14Nov240007','040000164225','13272',(select max(to_number(i.premium_rcv_detail_code))+1 from ins_premium_det i),'13272','13272','02', '11000003','00','Request by Mr. Saqib Saleem 15-Nov-2024'); | H5: =F5&G5 -> insert into ins_premium_det (premium_rcv_code,assorted_code, rec_amount,premium_rcv_detail_code,remaining_amt, payrec, mode_code,coinsurance_code,class_cd,it_remarks) values('14Nov240007','040000164225','13272',(select max(to_number(i.premium_rcv_detail_code))+1 from ins_premium_det i),'13272','13272','02', '11000003','00','Request by Mr. Saqib Saleem 15-Nov-2024');
A6: KHI/HO/D/MO/PC TPP/P/82548/01/2024 | B6: =VLOOKUP(A6,policy!B:C,2,0) -> 040000164225 | C6: 13272.131 | D6: =ROUND(C6,0) -> 13272 | E6: 14Nov240007 | F6: ="insert into ins_premium_det (premium_rcv_code,assorted_code, rec_amount,premium_rcv_detail_code,remaining_amt, payrec, mode_code,coinsurance_code,class_cd,it_remarks) values" -> insert into ins_premium_det (premium_rcv_code,assorted_code, rec_amount,premium_rcv_detail_code,remaining_amt, payrec, mode_code,coinsurance_code,class_cd,it_remarks) values | G6: ="('"&E6&"','"&B6&"','"&D6&"',(select max(to_number(i.premium_rcv_detail_code))+1 from ins_premium_det i),'"&D6&"','"&D6&"','02', '11000003','00','Request by Mr. Saqib Saleem 15-Nov-2024');" -> ('14Nov240007','040000164225','13272',(select max(to_number(i.premium_rcv_detail_code))+1 from ins_premium_det i),'13272','13272','02', '11000003','00','Request by Mr. Saqib Saleem 15-Nov-2024'); | H6: =F6&G6 -> insert into ins_premium_det (premium_rcv_code,assorted_code, rec_amount,premium_rcv_detail_code,remaining_amt, payrec, mode_code,coinsurance_code,class_cd,it_remarks) values('14Nov240007','040000164225','13272',(select max(to_number(i.premium_rcv_detail_code))+1 from ins_premium_det i),'13272','13272','02', '11000003','00','Request by Mr. Saqib Saleem 15-Nov-2024');
A7: KHI/HO/D/MO/PC TPP/P/82548/01/2024 | B7: =VLOOKUP(A7,policy!B:C,2,0) -> 040000164225 | C7: 13272.131 | D7: =ROUND(C7,0) -> 13272 | E7: 14Nov240007 | F7: ="insert into ins_premium_det (premium_rcv_code,assorted_code, rec_amount,premium_rcv_detail_code,remaining_amt, payrec, mode_code,coinsurance_code,class_cd,it_remarks) values" -> insert into ins_premium_det (premium_rcv_code,assorted_code, rec_amount,premium_rcv_detail_code,remaining_amt, payrec, mode_code,coinsurance_code,class_cd,it_remarks) values | G7: ="('"&E7&"','"&B7&"','"&D7&"',(select max(to_number(i.premium_rcv_detail_code))+1 from ins_premium_det i),'"&D7&"','"&D7&"','02', '11000003','00','Request by Mr. Saqib Saleem 15-Nov-2024');" -> ('14Nov240007','040000164225','13272',(select max(to_number(i.premium_rcv_detail_code))+1 from ins_premium_det i),'13272','13272','02', '11000003','00','Request by Mr. Saqib Saleem 15-Nov-2024'); | H7: =F7&G7 -> insert into ins_premium_det (premium_rcv_code,assorted_code, rec_amount,premium_rcv_detail_code,remaining_amt, payrec, mode_code,coinsurance_code,class_cd,it_remarks) values('14Nov240007','040000164225','13272',(select max(to_number(i.premium_rcv_detail_code))+1 from ins_premium_det i),'13272','13272','02', '11000003','00','Request by Mr. Saqib Saleem 15-Nov-2024');
A8: KHI/HO/D/MO/PC TPP/P/82548/01/2024 | B8: =VLOOKUP(A8,policy!B:C,2,0) -> 040000164225 | C8: 13272.131 | D8: =ROUND(C8,0) -> 13272 | E8: 14Nov240007 | F8: ="insert into ins_premium_det (premium_rcv_code,assorted_code, rec_amount,premium_rcv_detail_code,remaining_amt, payrec, mode_code,coinsurance_code,class_cd,it_remarks) values" -> insert into ins_premium_det (premium_rcv_code,assorted_code, rec_amount,premium_rcv_detail_code,remaining_amt, payrec, mode_code,coinsurance_code,class_cd,it_remarks) values | G8: ="('"&E8&"','"&B8&"','"&D8&"',(select max(to_number(i.premium_rcv_detail_code))+1 from ins_premium_det i),'"&D8&"','"&D8&"','02', '11000003','00','Request by Mr. Saqib Saleem 15-Nov-2024');" -> ('14Nov240007','040000164225','13272',(select max(to_number(i.premium_rcv_detail_code))+1 from ins_premium_det i),'13272','13272','02', '11000003','00','Request by Mr. Saqib Saleem 15-Nov-2024'); | H8: =F8&G8 -> insert into ins_premium_det (premium_rcv_code,assorted_code, rec_amount,premium_rcv_detail_code,remaining_amt, payrec, mode_code,coinsurance_code,class_cd,it_remarks) values('14Nov240007','040000164225','13272',(select max(to_number(i.premium_rcv_detail_code))+1 from ins_premium_det i),'13272','13272','02', '11000003','00','Request by Mr. Saqib Saleem 15-Nov-2024');
A9: KHI/HO/D/MO/PC TPP/P/82548/01/2024 | B9: =VLOOKUP(A9,policy!B:C,2,0) -> 040000164225 | C9: 13272.131 | D9: =ROUND(C9,0) -> 13272 | E9: 14Nov240007 | F9: ="insert into ins_premium_det (premium_rcv_code,assorted_code, rec_amount,premium_rcv_detail_code,remaining_amt, payrec, mode_code,coinsurance_code,class_cd,it_remarks) values" -> insert into ins_premium_det (premium_rcv_code,assorted_code, rec_amount,premium_rcv_detail_code,remaining_amt, payrec, mode_code,coinsurance_code,class_cd,it_remarks) values | G9: ="('"&E9&"','"&B9&"','"&D9&"',(select max(to_number(i.premium_rcv_detail_code))+1 from ins_premium_det i),'"&D9&"','"&D9&"','02', '11000003','00','Request by Mr. Saqib Saleem 15-Nov-2024');" -> ('14Nov240007','040000164225','13272',(select max(to_number(i.premium_rcv_detail_code))+1 from ins_premium_det i),'13272','13272','02', '11000003','00','Request by Mr. Saqib Saleem 15-Nov-2024'); | H9: =F9&G9 -> insert into ins_premium_det (premium_rcv_code,assorted_code, rec_amount,premium_rcv_detail_code,remaining_amt, payrec, mode_code,coinsurance_code,class_cd,it_remarks) values('14Nov240007','040000164225','13272',(select max(to_number(i.premium_rcv_detail_code))+1 from ins_premium_det i),'13272','13272','02', '11000003','00','Request by Mr. Saqib Saleem 15-Nov-2024');
A10: KHI/HO/D/MO/PC TPP/P/82548/01/2024 | B10: =VLOOKUP(A10,policy!B:C,2,0) -> 040000164225 | C10: 13272.131 | D10: =ROUND(C10,0) -> 13272 | E10: 14Nov240007 | F10: ="insert into ins_premium_det (premium_rcv_code,assorted_code, rec_amount,premium_rcv_detail_code,remaining_amt, payrec, mode_code,coinsurance_code,class_cd,it_remarks) values" -> insert into ins_premium_det (premium_rcv_code,assorted_code, rec_amount,premium_rcv_detail_code,remaining_amt, payrec, mode_code,coinsurance_code,class_cd,it_remarks) values | G10: ="('"&E10&"','"&B10&"','"&D10&"',(select max(to_number(i.premium_rcv_detail_code))+1 from ins_premium_det i),'"&D10&"','"&D10&"','02', '11000003','00','Request by Mr. Saqib Saleem 15-Nov-2024');" -> ('14Nov240007','040000164225','13272',(select max(to_number(i.premium_rcv_detail_code))+1 from ins_premium_det i),'13272','13272','02', '11000003','00','Request by Mr. Saqib Saleem 15-Nov-2024'); | H10: =F10&G10 -> insert into ins_premium_det (premium_rcv_code,assorted_code, rec_amount,premium_rcv_detail_code,remaining_amt, payrec, mode_code,coinsurance_code,class_cd,it_remarks) values('14Nov240007','040000164225','13272',(select max(to_number(i.premium_rcv_detail_code))+1 from ins_premium_det i),'13272','13272','02', '11000003','00','Request by Mr. Saqib Saleem 15-Nov-2024');
A11: KHI/HO/D/MO/PC TPP/P/82548/01/2024 | B11: =VLOOKUP(A11,policy!B:C,2,0) -> 040000164225 | C11: 13272.131 | D11: =ROUND(C11,0) -> 13272 | E11: 14Nov240007 | F11: ="insert into ins_premium_det (premium_rcv_code,assorted_code, rec_amount,premium_rcv_detail_code,remaining_amt, payrec, mode_code,coinsurance_code,class_cd,it_remarks) values" -> insert into ins_premium_det (premium_rcv_code,assorted_code, rec_amount,premium_rcv_detail_code,remaining_amt, payrec, mode_code,coinsurance_code,class_cd,it_remarks) values | G11: ="('"&E11&"','"&B11&"','"&D11&"',(select max(to_number(i.premium_rcv_detail_code))+1 from ins_premium_det i),'"&D11&"','"&D11&"','02', '11000003','00','Request by Mr. Saqib Saleem 15-Nov-2024');" -> ('14Nov240007','040000164225','13272',(select max(to_number(i.premium_rcv_detail_code))+1 from ins_premium_det i),'13272','13272','02', '11000003','00','Request by Mr. Saqib Saleem 15-Nov-2024'); | H11: =F11&G11 -> insert into ins_premium_det (premium_rcv_code,assorted_code, rec_amount,premium_rcv_detail_code,remaining_amt, payrec, mode_code,coinsurance_code,class_cd,it_remarks) values('14Nov240007','040000164225','13272',(select max(to_number(i.premium_rcv_detail_code))+1 from ins_premium_det i),'13272','13272','02', '11000003','00','Request by Mr. Saqib Saleem 15-Nov-2024');
A12: KHI/HO/D/MO/PC TPP/P/82549/01/2024 | B12: =VLOOKUP(A12,policy!B:C,2,0) -> 040000164226 | C12: 13272.131 | D12: =ROUND(C12,0) -> 13272 | E12: 14Nov240007 | F12: ="insert into ins_premium_det (premium_rcv_code,assorted_code, rec_amount,premium_rcv_detail_code,remaining_amt, payrec, mode_code,coinsurance_code,class_cd,it_remarks) values" -> insert into ins_premium_det (premium_rcv_code,assorted_code, rec_amount,premium_rcv_detail_code,remaining_amt, payrec, mode_code,coinsurance_code,class_cd,it_remarks) values | G12: ="('"&E12&"','"&B12&"','"&D12&"',(select max(to_number(i.premium_rcv_detail_code))+1 from ins_premium_det i),'"&D12&"','"&D12&"','02', '11000003','00','Request by Mr. Saqib Saleem 15-Nov-2024');" -> ('14Nov240007','040000164226','13272',(select max(to_number(i.premium_rcv_detail_code))+1 from ins_premium_det i),'13272','13272','02', '11000003','00','Request by Mr. Saqib Saleem 15-Nov-2024'); | H12: =F12&G12 -> insert into ins_premium_det (premium_rcv_code,assorted_code, rec_amount,premium_rcv_detail_code,remaining_amt, payrec, mode_code,coinsurance_code,class_cd,it_remarks) values('14Nov240007','040000164226','13272',(select max(to_number(i.premium_rcv_detail_code))+1 from ins_premium_det i),'13272','13272','02', '11000003','00','Request by Mr. Saqib Saleem 15-Nov-2024');
A13: KHI/HO/D/MO/PC TPP/P/82549/01/2024 | B13: =VLOOKUP(A13,policy!B:C,2,0) -> 040000164226 | C13: 13272.131 | D13: =ROUND(C13,0) -> 13272 | E13: 14Nov240007 | F13: ="insert into ins_premium_det (premium_rcv_code,assorted_code, rec_amount,premium_rcv_detail_code,remaining_amt, payrec, mode_code,coinsurance_code,class_cd,it_remarks) values" -> insert into ins_premium_det (premium_rcv_code,assorted_code, rec_amount,premium_rcv_detail_code,remaining_amt, payrec, mode_code,coinsurance_code,class_cd,it_remarks) values | G13: ="('"&E13&"','"&B13&"','"&D13&"',(select max(to_number(i.premium_rcv_detail_code))+1 from ins_premium_det i),'"&D13&"','"&D13&"','02', '11000003','00','Request by Mr. Saqib Saleem 15-Nov-2024');" -> ('14Nov240007','040000164226','13272',(select max(to_number(i.premium_rcv_detail_code))+1 from ins_premium_det i),'13272','13272','02', '11000003','00','Request by Mr. Saqib Saleem 15-Nov-2024'); | H13: =F13&G13 -> insert into ins_premium_det (premium_rcv_code,assorted_code, rec_amount,premium_rcv_detail_code,remaining_amt, payrec, mode_code,coinsurance_code,class_cd,it_remarks) values('14Nov240007','040000164226','13272',(select max(to_number(i.premium_rcv_detail_code))+1 from ins_premium_det i),'13272','13272','02', '11000003','00','Request by Mr. Saqib Saleem 15-Nov-2024');
... A87: KHI/HO/D/MO/PC TPP/P/82546/01/2024 | B87: =VLOOKUP(A87,policy!B:C,2,0) -> 040000164223 | C87: 11011.721 | D87: =ROUND(C87,0) -> 11012 | E87: 14Nov240007 | F87: ="insert into ins_premium_det (premium_rcv_code,assorted_code, rec_amount,premium_rcv_detail_code,remaining_amt, payrec, mode_code,coinsurance_code,class_cd,it_remarks) values" -> insert into ins_premium_det (premium_rcv_code,assorted_code, rec_amount,premium_rcv_detail_code,remaining_amt, payrec, mode_code,coinsurance_code,class_cd,it_remarks) values | G87: ="('"&E87&"','"&B87&"','"&D87&"',(select max(to_number(i.premium_rcv_detail_code))+1 from ins_premium_det i),'"&D87&"','"&D87&"','02', '11000003','00','Request by Mr. Saqib Saleem 15-Nov-2024');" -> ('14Nov240007','040000164223','11012',(select max(to_number(i.premium_rcv_detail_code))+1 from ins_premium_det i),'11012','11012','02', '11000003','00','Request by Mr. Saqib Saleem 15-Nov-2024'); | H87: =F87&G87 -> insert into ins_premium_det (premium_rcv_code,assorted_code, rec_amount,premium_rcv_detail_code,remaining_amt, payrec, mode_code,coinsurance_code,class_cd,it_remarks) values('14Nov240007','040000164223','11012',(select max(to_number(i.premium_rcv_detail_code))+1 from ins_premium_det i),'11012','11012','02', '11000003','00','Request by Mr. Saqib Saleem 15-Nov-2024');
A88: KHI/HO/D/MO/PC TPP/P/82555/01/2024 | B88: 040000164240 | C88: 1256.8306 | D88: =ROUND(C88,0) -> 1257 | E88: 14Nov240007 | F88: ="insert into ins_premium_det (premium_rcv_code,assorted_code, rec_amount,premium_rcv_detail_code,remaining_amt, payrec, mode_code,coinsurance_code,class_cd,it_remarks) values" -> insert into ins_premium_det (premium_rcv_code,assorted_code, rec_amount,premium_rcv_detail_code,remaining_amt, payrec, mode_code,coinsurance_code,class_cd,it_remarks) values | G88: ="('"&E88&"','"&B88&"','"&D88&"',(select max(to_number(i.premium_rcv_detail_code))+1 from ins_premium_det i),'"&D88&"','"&D88&"','02', '11000003','00','Request by Mr. Saqib Saleem 15-Nov-2024');" -> ('14Nov240007','040000164240','1257',(select max(to_number(i.premium_rcv_detail_code))+1 from ins_premium_det i),'1257','1257','02', '11000003','00','Request by Mr. Saqib Saleem 15-Nov-2024'); | H88: =F88&G88 -> insert into ins_premium_det (premium_rcv_code,assorted_code, rec_amount,premium_rcv_detail_code,remaining_amt, payrec, mode_code,coinsurance_code,class_cd,it_remarks) values('14Nov240007','040000164240','1257',(select max(to_number(i.premium_rcv_detail_code))+1 from ins_premium_det i),'1257','1257','02', '11000003','00','Request by Mr. Saqib Saleem 15-Nov-2024');
A89: KHI/HO/D/MO/PC TPP/P/85556/03/2024 | B89: =VLOOKUP(A89,policy!B:C,2,0) -> 040000168665 | C89: 29673.582 | D89: =ROUND(C89,0) -> 29674 | E89: 14Nov240007 | F89: ="insert into ins_premium_det (premium_rcv_code,assorted_code, rec_amount,premium_rcv_detail_code,remaining_amt, payrec, mode_code,coinsurance_code,class_cd,it_remarks) values" -> insert into ins_premium_det (premium_rcv_code,assorted_code, rec_amount,premium_rcv_detail_code,remaining_amt, payrec, mode_code,coinsurance_code,class_cd,it_remarks) values | G89: ="('"&E89&"','"&B89&"','"&D89&"',(select max(to_number(i.premium_rcv_detail_code))+1 from ins_premium_det i),'"&D89&"','"&D89&"','02', '11000003','00','Request by Mr. Saqib Saleem 15-Nov-2024');" -> ('14Nov240007','040000168665','29674',(select max(to_number(i.premium_rcv_detail_code))+1 from ins_premium_det i),'29674','29674','02', '11000003','00','Request by Mr. Saqib Saleem 15-Nov-2024'); | H89: =F89&G89 -> insert into ins_premium_det (premium_rcv_code,assorted_code, rec_amount,premium_rcv_detail_code,remaining_amt, payrec, mode_code,coinsurance_code,class_cd,it_remarks) values('14Nov240007','040000168665','29674',(select max(to_number(i.premium_rcv_detail_code))+1 from ins_premium_det i),'29674','29674','02', '11000003','00','Request by Mr. Saqib Saleem 15-Nov-2024');
A90: KHI/HO/D/MO/PC TPP/P/85556/03/2024 | B90: =VLOOKUP(A90,policy!B:C,2,0) -> 040000168665 | C90: 29673.582 | D90: =ROUND(C90,0) -> 29674 | E90: 14Nov240007 | F90: ="insert into ins_premium_det (premium_rcv_code,assorted_code, rec_amount,premium_rcv_detail_code,remaining_amt, payrec, mode_code,coinsurance_code,class_cd,it_remarks) values" -> insert into ins_premium_det (premium_rcv_code,assorted_code, rec_amount,premium_rcv_detail_code,remaining_amt, payrec, mode_code,coinsurance_code,class_cd,it_remarks) values | G90: ="('"&E90&"','"&B90&"','"&D90&"',(select max(to_number(i.premium_rcv_detail_code))+1 from ins_premium_det i),'"&D90&"','"&D90&"','02', '11000003','00','Request by Mr. Saqib Saleem 15-Nov-2024');" -> ('14Nov240007','040000168665','29674',(select max(to_number(i.premium_rcv_detail_code))+1 from ins_premium_det i),'29674','29674','02', '11000003','00','Request by Mr. Saqib Saleem 15-Nov-2024'); | H90: =F90&G90 -> insert into ins_premium_det (premium_rcv_code,assorted_code, rec_amount,premium_rcv_detail_code,remaining_amt, payrec, mode_code,coinsurance_code,class_cd,it_remarks) values('14Nov240007','040000168665','29674',(select max(to_number(i.premium_rcv_detail_code))+1 from ins_premium_det i),'29674','29674','02', '11000003','00','Request by Mr. Saqib Saleem 15-Nov-2024');
A91: KHI/HO/D/MO/PC TPP/P/85556/03/2024 | B91: =VLOOKUP(A91,policy!B:C,2,0) -> 040000168665 | C91: 29673.582 | D91: =ROUND(C91,0) -> 29674 | E91: 14Nov240007 | F91: ="insert into ins_premium_det (premium_rcv_code,assorted_code, rec_amount,premium_rcv_detail_code,remaining_amt, payrec, mode_code,coinsurance_code,class_cd,it_remarks) values" -> insert into ins_premium_det (premium_rcv_code,assorted_code, rec_amount,premium_rcv_detail_code,remaining_amt, payrec, mode_code,coinsurance_code,class_cd,it_remarks) values | G91: ="('"&E91&"','"&B91&"','"&D91&"',(select max(to_number(i.premium_rcv_detail_code))+1 from ins_premium_det i),'"&D91&"','"&D91&"','02', '11000003','00','Request by Mr. Saqib Saleem 15-Nov-2024');" -> ('14Nov240007','040000168665','29674',(select max(to_number(i.premium_rcv_detail_code))+1 from ins_premium_det i),'29674','29674','02', '11000003','00','Request by Mr. Saqib Saleem 15-Nov-2024'); | H91: =F91&G91 -> insert into ins_premium_det (premium_rcv_code,assorted_code, rec_amount,premium_rcv_detail_code,remaining_amt, payrec, mode_code,coinsurance_code,class_cd,it_remarks) values('14Nov240007','040000168665','29674',(select max(to_number(i.premium_rcv_detail_code))+1 from ins_premium_det i),'29674','29674','02', '11000003','00','Request by Mr. Saqib Saleem 15-Nov-2024');
A92: KHI/HO/D/MO/PC TPP/P/85556/03/2024 | B92: =VLOOKUP(A92,policy!B:C,2,0) -> 040000168665 | C92: 29673.582 | D92: =ROUND(C92,0) -> 29674 | E92: 14Nov240007 | F92: ="insert into ins_premium_det (premium_rcv_code,assorted_code, rec_amount,premium_rcv_detail_code,remaining_amt, payrec, mode_code,coinsurance_code,class_cd,it_remarks) values" -> insert into ins_premium_det (premium_rcv_code,assorted_code, rec_amount,premium_rcv_detail_code,remaining_amt, payrec, mode_code,coinsurance_code,class_cd,it_remarks) values | G92: ="('"&E92&"','"&B92&"','"&D92&"',(select max(to_number(i.premium_rcv_detail_code))+1 from ins_premium_det i),'"&D92&"','"&D92&"','02', '11000003','00','Request by Mr. Saqib Saleem 15-Nov-2024');" -> ('14Nov240007','040000168665','29674',(select max(to_number(i.premium_rcv_detail_code))+1 from ins_premium_det i),'29674','29674','02', '11000003','00','Request by Mr. Saqib Saleem 15-Nov-2024'); | H92: =F92&G92 -> insert into ins_premium_det (premium_rcv_code,assorted_code, rec_amount,premium_rcv_detail_code,remaining_amt, payrec, mode_code,coinsurance_code,class_cd,it_remarks) values('14Nov240007','040000168665','29674',(select max(to_number(i.premium_rcv_detail_code))+1 from ins_premium_det i),'29674','29674','02', '11000003','00','Request by Mr. Saqib Saleem 15-Nov-2024');
A93: KHI/HO/D/MO/PC TPP/P/82550/01/2024 | B93: =VLOOKUP(A93,policy!B:C,2,0) -> 040000164227 | C93: 58746.6 | D93: =ROUND(C93,0) -> 58747 | E93: 14Nov240007 | F93: ="insert into ins_premium_det (premium_rcv_code,assorted_code, rec_amount,premium_rcv_detail_code,remaining_amt, payrec, mode_code,coinsurance_code,class_cd,it_remarks) values" -> insert into ins_premium_det (premium_rcv_code,assorted_code, rec_amount,premium_rcv_detail_code,remaining_amt, payrec, mode_code,coinsurance_code,class_cd,it_remarks) values | G93: ="('"&E93&"','"&B93&"','"&D93&"',(select max(to_number(i.premium_rcv_detail_code))+1 from ins_premium_det i),'"&D93&"','"&D93&"','02', '11000003','00','Request by Mr. Saqib Saleem 15-Nov-2024');" -> ('14Nov240007','040000164227','58747',(select max(to_number(i.premium_rcv_detail_code))+1 from ins_premium_det i),'58747','58747','02', '11000003','00','Request by Mr. Saqib Saleem 15-Nov-2024'); | H93: =F93&G93 -> insert into ins_premium_det (premium_rcv_code,assorted_code, rec_amount,premium_rcv_detail_code,remaining_amt, payrec, mode_code,coinsurance_code,class_cd,it_remarks) values('14Nov240007','040000164227','58747',(select max(to_number(i.premium_rcv_detail_code))+1 from ins_premium_det i),'58747','58747','02', '11000003','00','Request by Mr. Saqib Saleem 15-Nov-2024');
A94: KHI/HO/D/MO/PC TPP/P/85556/03/2024 | B94: =VLOOKUP(A94,policy!B:C,2,0) -> 040000168665 | C94: 17730.738 | D94: =ROUND(C94,0) -> 17731 | E94: 14Nov240007 | F94: ="insert into ins_premium_det (premium_rcv_code,assorted_code, rec_amount,premium_rcv_detail_code,remaining_amt, payrec, mode_code,coinsurance_code,class_cd,it_remarks) values" -> insert into ins_premium_det (premium_rcv_code,assorted_code, rec_amount,premium_rcv_detail_code,remaining_amt, payrec, mode_code,coinsurance_code,class_cd,it_remarks) values | G94: ="('"&E94&"','"&B94&"','"&D94&"',(select max(to_number(i.premium_rcv_detail_code))+1 from ins_premium_det i),'"&D94&"','"&D94&"','02', '11000003','00','Request by Mr. Saqib Saleem 15-Nov-2024');" -> ('14Nov240007','040000168665','17731',(select max(to_number(i.premium_rcv_detail_code))+1 from ins_premium_det i),'17731','17731','02', '11000003','00','Request by Mr. Saqib Saleem 15-Nov-2024'); | H94: =F94&G94 -> insert into ins_premium_det (premium_rcv_code,assorted_code, rec_amount,premium_rcv_detail_code,remaining_amt, payrec, mode_code,coinsurance_code,class_cd,it_remarks) values('14Nov240007','040000168665','17731',(select max(to_number(i.premium_rcv_detail_code))+1 from ins_premium_det i),'17731','17731','02', '11000003','00','Request by Mr. Saqib Saleem 15-Nov-2024');
A95: KHI/HO/D/MO/PC TPP/P/85556/03/2024 | B95: =VLOOKUP(A95,policy!B:C,2,0) -> 040000168665 | C95: 17730.738 | D95: =ROUND(C95,0) -> 17731 | E95: 14Nov240007 | F95: ="insert into ins_premium_det (premium_rcv_code,assorted_code, rec_amount,premium_rcv_detail_code,remaining_amt, payrec, mode_code,coinsurance_code,class_cd,it_remarks) values" -> insert into ins_premium_det (premium_rcv_code,assorted_code, rec_amount,premium_rcv_detail_code,remaining_amt, payrec, mode_code,coinsurance_code,class_cd,it_remarks) values | G95: ="('"&E95&"','"&B95&"','"&D95&"',(select max(to_number(i.premium_rcv_detail_code))+1 from ins_premium_det i),'"&D95&"','"&D95&"','02', '11000003','00','Request by Mr. Saqib Saleem 15-Nov-2024');" -> ('14Nov240007','040000168665','17731',(select max(to_number(i.premium_rcv_detail_code))+1 from ins_premium_det i),'17731','17731','02', '11000003','00','Request by Mr. Saqib Saleem 15-Nov-2024'); | H95: =F95&G95 -> insert into ins_premium_det (premium_rcv_code,assorted_code, rec_amount,premium_rcv_detail_code,remaining_amt, payrec, mode_code,coinsurance_code,class_cd,it_remarks) values('14Nov240007','040000168665','17731',(select max(to_number(i.premium_rcv_detail_code))+1 from ins_premium_det i),'17731','17731','02', '11000003','00','Request by Mr. Saqib Saleem 15-Nov-2024');
A96: KHI/HO/D/MO/PC TPP/P/82552/01/2024 | B96: =VLOOKUP(A96,policy!B:C,2,0) -> 040000164229 | C96: 16807.91 | D96: =ROUND(C96,0) -> 16808 | E96: 14Nov240007 | F96: ="insert into ins_premium_det (premium_rcv_code,assorted_code, rec_amount,premium_rcv_detail_code,remaining_amt, payrec, mode_code,coinsurance_code,class_cd,it_remarks) values" -> insert into ins_premium_det (premium_rcv_code,assorted_code, rec_amount,premium_rcv_detail_code,remaining_amt, payrec, mode_code,coinsurance_code,class_cd,it_remarks) values | G96: ="('"&E96&"','"&B96&"','"&D96&"',(select max(to_number(i.premium_rcv_detail_code))+1 from ins_premium_det i),'"&D96&"','"&D96&"','02', '11000003','00','Request by Mr. Saqib Saleem 15-Nov-2024');" -> ('14Nov240007','040000164229','16808',(select max(to_number(i.premium_rcv_detail_code))+1 from ins_premium_det i),'16808','16808','02', '11000003','00','Request by Mr. Saqib Saleem 15-Nov-2024'); | H96: =F96&G96 -> insert into ins_premium_det (premium_rcv_code,assorted_code, rec_amount,premium_rcv_detail_code,remaining_amt, payrec, mode_code,coinsurance_code,class_cd,it_remarks) values('14Nov240007','040000164229','16808',(select max(to_number(i.premium_rcv_detail_code))+1 from ins_premium_det i),'16808','16808','02', '11000003','00','Request by Mr. Saqib Saleem 15-Nov-2024');
A97: KHI/HO/D/MO/PC TPP/P/82552/01/2024 | B97: =VLOOKUP(A97,policy!B:C,2,0) -> 040000164229 | C97: 16807.91 | D97: =ROUND(C97,0) -> 16808 | E97: 14Nov240007 | F97: ="insert into ins_premium_det (premium_rcv_code,assorted_code, rec_amount,premium_rcv_detail_code,remaining_amt, payrec, mode_code,coinsurance_code,class_cd,it_remarks) values" -> insert into ins_premium_det (premium_rcv_code,assorted_code, rec_amount,premium_rcv_detail_code,remaining_amt, payrec, mode_code,coinsurance_code,class_cd,it_remarks) values | G97: ="('"&E97&"','"&B97&"','"&D97&"',(select max(to_number(i.premium_rcv_detail_code))+1 from ins_premium_det i),'"&D97&"','"&D97&"','02', '11000003','00','Request by Mr. Saqib Saleem 15-Nov-2024');" -> ('14Nov240007','040000164229','16808',(select max(to_number(i.premium_rcv_detail_code))+1 from ins_premium_det i),'16808','16808','02', '11000003','00','Request by Mr. Saqib Saleem 15-Nov-2024'); | H97: =F97&G97 -> insert into ins_premium_det (premium_rcv_code,assorted_code, rec_amount,premium_rcv_detail_code,remaining_amt, payrec, mode_code,coinsurance_code,class_cd,it_remarks) values('14Nov240007','040000164229','16808',(select max(to_number(i.premium_rcv_detail_code))+1 from ins_premium_det i),'16808','16808','02', '11000003','00','Request by Mr. Saqib Saleem 15-Nov-2024');
A98: KHI/HO/D/MO/PC TPP/P/82552/01/2024 | B98: =VLOOKUP(A98,policy!B:C,2,0) -> 040000164229 | C98: 18176.598 | D98: =ROUND(C98,0) -> 18177 | E98: 14Nov240007 | F98: ="insert into ins_premium_det (premium_rcv_code,assorted_code, rec_amount,premium_rcv_detail_code,remaining_amt, payrec, mode_code,coinsurance_code,class_cd,it_remarks) values" -> insert into ins_premium_det (premium_rcv_code,assorted_code, rec_amount,premium_rcv_detail_code,remaining_amt, payrec, mode_code,coinsurance_code,class_cd,it_remarks) values | G98: ="('"&E98&"','"&B98&"','"&D98&"',(select max(to_number(i.premium_rcv_detail_code))+1 from ins_premium_det i),'"&D98&"','"&D98&"','02', '11000003','00','Request by Mr. Saqib Saleem 15-Nov-2024');" -> ('14Nov240007','040000164229','18177',(select max(to_number(i.premium_rcv_detail_code))+1 from ins_premium_det i),'18177','18177','02', '11000003','00','Request by Mr. Saqib Saleem 15-Nov-2024'); | H98: =F98&G98 -> insert into ins_premium_det (premium_rcv_code,assorted_code, rec_amount,premium_rcv_detail_code,remaining_amt, payrec, mode_code,coinsurance_code,class_cd,it_remarks) values('14Nov240007','040000164229','18177',(select max(to_number(i.premium_rcv_detail_code))+1 from ins_premium_det i),'18177','18177','02', '11000003','00','Request by Mr. Saqib Saleem 15-Nov-2024');
A99: KHI/HO/D/MO/PC TPP/P/82552/01/2024 | B99: =VLOOKUP(A99,policy!B:C,2,0) -> 040000164229 | C99: 18176.598 | D99: =ROUND(C99,0) -> 18177 | E99: 14Nov240007 | F99: ="insert into ins_premium_det (premium_rcv_code,assorted_code, rec_amount,premium_rcv_detail_code,remaining_amt, payrec, mode_code,coinsurance_code,class_cd,it_remarks) values" -> insert into ins_premium_det (premium_rcv_code,assorted_code, rec_amount,premium_rcv_detail_code,remaining_amt, payrec, mode_code,coinsurance_code,class_cd,it_remarks) values | G99: ="('"&E99&"','"&B99&"','"&D99&"',(select max(to_number(i.premium_rcv_detail_code))+1 from ins_premium_det i),'"&D99&"','"&D99&"','02', '11000003','00','Request by Mr. Saqib Saleem 15-Nov-2024');" -> ('14Nov240007','040000164229','18177',(select max(to_number(i.premium_rcv_detail_code))+1 from ins_premium_det i),'18177','18177','02', '11000003','00','Request by Mr. Saqib Saleem 15-Nov-2024'); | H99: =F99&G99 -> insert into ins_premium_det (premium_rcv_code,assorted_code, rec_amount,premium_rcv_detail_code,remaining_amt, payrec, mode_code,coinsurance_code,class_cd,it_remarks) values('14Nov240007','040000164229','18177',(select max(to_number(i.premium_rcv_detail_code))+1 from ins_premium_det i),'18177','18177','02', '11000003','00','Request by Mr. Saqib Saleem 15-Nov-2024');
A100: KHI/HO/D/MO/PC TPP/P/82552/01/2024 | B100: =VLOOKUP(A100,policy!B:C,2,0) -> 040000164229 | C100: 18176.598 | D100: =ROUND(C100,0) -> 18177 | E100: 14Nov240007 | F100: ="insert into ins_premium_det (premium_rcv_code,assorted_code, rec_amount,premium_rcv_detail_code,remaining_amt, payrec, mode_code,coinsurance_code,class_cd,it_remarks) values" -> insert into ins_premium_det (premium_rcv_code,assorted_code, rec_amount,premium_rcv_detail_code,remaining_amt, payrec, mode_code,coinsurance_code,class_cd,it_remarks) values | G100: ="('"&E100&"','"&B100&"','"&D100&"',(select max(to_number(i.premium_rcv_detail_code))+1 from ins_premium_det i),'"&D100&"','"&D100&"','02', '11000003','00','Request by Mr. Saqib Saleem 15-Nov-2024');" -> ('14Nov240007','040000164229','18177',(select max(to_number(i.premium_rcv_detail_code))+1 from ins_premium_det i),'18177','18177','02', '11000003','00','Request by Mr. Saqib Saleem 15-Nov-2024'); | H100: =F100&G100 -> insert into ins_premium_det (premium_rcv_code,assorted_code, rec_amount,premium_rcv_detail_code,remaining_amt, payrec, mode_code,coinsurance_code,class_cd,it_remarks) values('14Nov240007','040000164229','18177',(select max(to_number(i.premium_rcv_detail_code))+1 from ins_premium_det i),'18177','18177','02', '11000003','00','Request by Mr. Saqib Saleem 15-Nov-2024');
... A108: KHI/HO/D/MO/PC TPP/P/82546/01/2024 | B108: =VLOOKUP(A108,policy!B:C,2,0) -> 040000164223 | C108: 10456 | D108: =ROUND(C108,0) -> 10456 | E108: 14Nov240007 | F108: ="insert into ins_premium_det (premium_rcv_code,assorted_code, rec_amount,premium_rcv_detail_code,remaining_amt, payrec, mode_code,coinsurance_code,class_cd,it_remarks) values" -> insert into ins_premium_det (premium_rcv_code,assorted_code, rec_amount,premium_rcv_detail_code,remaining_amt, payrec, mode_code,coinsurance_code,class_cd,it_remarks) values | G108: ="('"&E108&"','"&B108&"','"&D108&"',(select max(to_number(i.premium_rcv_detail_code))+1 from ins_premium_det i),'"&D108&"','"&D108&"','02', '11000003','00','Request by Mr. Saqib Saleem 15-Nov-2024');" -> ('14Nov240007','040000164223','10456',(select max(to_number(i.premium_rcv_detail_code))+1 from ins_premium_det i),'10456','10456','02', '11000003','00','Request by Mr. Saqib Saleem 15-Nov-2024'); | H108: =F108&G108 -> insert into ins_premium_det (premium_rcv_code,assorted_code, rec_amount,premium_rcv_detail_code,remaining_amt, payrec, mode_code,coinsurance_code,class_cd,it_remarks) values('14Nov240007','040000164223','10456',(select max(to_number(i.premium_rcv_detail_code))+1 from ins_premium_det i),'10456','10456','02', '11000003','00','Request by Mr. Saqib Saleem 15-Nov-2024');

Sheet Sheet2
A1: KHI/HO/D/MO/PC TPP/P/82548/01/2024 | B1: -01-2024 | D1: 82548 | E1: ="ia.assorted_string like '%"&D1&B1&"%' or" -> ia.assorted_string like '%82548-01-2024%' or
A2: KHI/HO/D/MO/PC TPP/P/82548/01/2024 | B2: -01-2024 | D2: 82548 | E2: ="ia.assorted_string like '%"&D2&B2&"%' or" -> ia.assorted_string like '%82548-01-2024%' or
A3: KHI/HO/D/MO/PC TPP/P/82548/01/2024 | B3: -01-2024 | D3: 82548 | E3: ="ia.assorted_string like '%"&D3&B3&"%' or" -> ia.assorted_string like '%82548-01-2024%' or
A4: KHI/HO/D/MO/PC TPP/P/82548/01/2024 | B4: -01-2024 | D4: 82548 | E4: ="ia.assorted_string like '%"&D4&B4&"%' or" -> ia.assorted_string like '%82548-01-2024%' or
A5: KHI/HO/D/MO/PC TPP/P/82548/01/2024 | B5: -01-2024 | D5: 82548 | E5: ="ia.assorted_string like '%"&D5&B5&"%' or" -> ia.assorted_string like '%82548-01-2024%' or
A6: KHI/HO/D/MO/PC TPP/P/82548/01/2024 | B6: -01-2024 | D6: 82548 | E6: ="ia.assorted_string like '%"&D6&B6&"%' or" -> ia.assorted_string like '%82548-01-2024%' or
A7: KHI/HO/D/MO/PC TPP/P/82548/01/2024 | B7: -01-2024 | D7: 82548 | E7: ="ia.assorted_string like '%"&D7&B7&"%' or" -> ia.assorted_string like '%82548-01-2024%' or
A8: KHI/HO/D/MO/PC TPP/P/82548/01/2024 | B8: -01-2024 | D8: 82548 | E8: ="ia.assorted_string like '%"&D8&B8&"%' or" -> ia.assorted_string like '%82548-01-2024%' or
A9: KHI/HO/D/MO/PC TPP/P/82548/01/2024 | B9: -01-2024 | D9: 82548 | E9: ="ia.assorted_string like '%"&D9&B9&"%' or" -> ia.assorted_string like '%82548-01-2024%' or
A10: KHI/HO/D/MO/PC TPP/P/82548/01/2024 | B10: -01-2024 | D10: 82548 | E10: ="ia.assorted_string like '%"&D10&B10&"%' or" -> ia.assorted_string like '%82548-01-2024%' or
A11: KHI/HO/D/MO/PC TPP/P/82549/01/2024 | B11: -01-2024 | D11: 82549 | E11: ="ia.assorted_string like '%"&D11&B11&"%' or" -> ia.assorted_string like '%82549-01-2024%' or
A12: KHI/HO/D/MO/PC TPP/P/82549/01/2024 | B12: -01-2024 | D12: 82549 | E12: ="ia.assorted_string like '%"&D12&B12&"%' or" -> ia.assorted_string like '%82549-01-2024%' or
... A107: KHI/HO/D/MO/PC TPP/P/82546/01/2024 | B107: -01-2024 | D107: 82546 | E107: ="ia.assorted_string like '%"&D107&B107&"%' or" -> ia.assorted_string like '%82546-01-2024%' or

Sheet policy
B1: FUNC_ASSORTED_STRING(IA.ASSORTED_CODE) | C1: ASSORTED_CODE
A2: 1 | B2: KHI/HO/D/MO/MC COMP/P/82555/01/2024 | C2: 040000164240
A3: 2 | B3: KHI/HO/D/MO/PC TPP/P/85423/03/2024 | C3: 040000168478
A4: 3 | B4: KHI/HO/D/MO/PC TPP/P/82546/01/2024 | C4: 040000164223
A5: 4 | B5: KHI/HO/D/MO/PC TPP/P/82550/01/2024 | C5: 040000164227
A6: 5 | B6: KHI/HO/D/MO/PC TPP/P/82552/01/2024 | C6: 040000164229
A7: 6 | B7: KHI/HO/D/MO/PC TPP/P/82549/01/2024 | C7: 040000164226
A8: 7 | B8: KHI/HO/D/MO/PC TPP/P/82548/01/2024 | C8: 040000164225
A9: 8 | B9: KHI/HO/D/MO/PC TPP/P/86642/04/2024 | C9: 040000170253
A10: 9 | B10: KHI/HO/D/MO/PC TPP/P/85556/03/2024 | C10: 040000168665
A11: 1 | B11: KHI/HO/D/MO/MC COMP/P/82555/01/2024 | C11: 040000164240
