Workbook

Sheet Invoice
C9: FOR THE MONTH OF Aug-24
C11: INVOICE # 0018
C13: Policy | E13: As Per Schedule | G13: Risk Covered | I13: MOTORCYCLE COMPREHENSIVE
C15: Participant Name | E15: PAK SUZUKI MOTOR COMPANY LIMITED.
C17: Address | E17: DSU-13 PAKISTAN STEEL INDUSTRIAL ESTATE, BIN QASIM, KARACHI -75000.
C20: Expiry Date : | E20: To be advised | H20: Make: | J20: Suzuki Motorcycle
C21: Effective Date: | E21: To be advised | H21: No of Bikes | J21: =Detail!A1 -> 1016
C22: Date Of Issue: | E22: To be advised
C25: Computation
C27: Gross Contribution | K27: =Detail!I1 -> 11666621
C28: SST 15% | K28: =Detail!R1 -> 1026218.5
C29: F.I.F 1% | K29: =Detail!S1 -> 68414.567
C30: Stamp Duty | K30: =Detail!T1 -> 297000
C31: Net Contribution | K31: =Detail!H1 -> 14053879
C34: =CONCATENATE(C36,F36,C37) -> Payment Of PKR. Rs. 14,053,879/- be cheque in favour of M/s. Salaam Takaful Limited.
C36: Payment Of PKR. Rs. | F36: =TEXT(K31,"##,###,###") -> 14,053,879
C37: /- be cheque in favour of M/s. Salaam Takaful Limited.

Sheet Summary
A3: Showroom | B3: No. Of Policies | C3: Net Premium
A4: Suzuki Defence Motors | B4: 35 | C4: 587352.5
A5: A R Suzuki | B5: 54 | C5: 862030
A6: FSD Suzuki | B6: 70 | C6: 670750
A7: GT Suzuki | B7: 33 | C7: 354225
A8: Khalil Motor | B8: 73 | C8: 1192062
A9: South | B9: 48 | C9: 797770.5
A10: Suzuki Mandviwalla Motors | B10: 36 | C10: 612259
A11: TR Suzuki | B11: 89 | C11: 1458051.5
A12: UP Suzuki | B12: 65 | C12: 1146064
A13: UR Suzuki | B13: 154 | C13: 2699250.8
A14: KR Suzuki | B14: 13 | C14: 132100
A15: GR Suzuki | B15: 14 | C15: 144800
... A32: Grand Total | B32: 1016 | C32: 14053879

Sheet Detail
A1: =COUNTIFS(T3:T1048576,">=0") -> 1016 | H1: =SUBTOTAL(9,H3:H1018) -> 14053879 | I1: =SUBTOTAL(9,I3:I1018) -> 11666621 | R1: =SUBTOTAL(9,R3:R596) -> 1026218.5 | S1: =SUBTOTAL(9,S3:S596) -> 68414.567 | T1: =SUBTOTAL(9,T3:T596) -> 297000
A2: Policy # | B2: Endorsement | C2: Dealer | D2: Period From | E2: Period To | F2: Insured Name | G2: Vehicle Info | H2: Net | I2: Gross | J2: Net Rate | K2: Net | L2: Gross | M2: Difference | N2: Engine | O2: Issue date | P2: Policy Name | Q2: SumCovered | R2: SST 15% | S2: F.I.F 1% | T2: Stamp Duty
A3: KHI/HO/D/MO/MC COMP/P/94363/08/2024 | C3: UR Suzuki | D3: 45505 | E3: 45870 | F3: FARHAN KHAN | G3: SUZUKI-GR150 EURO II | H3: =K3 -> 23247.5 | I3: =L3 -> 19540.948 | J3: 0.0425 | K3: =Q3*J3 -> 23247.5 | L3: =K3/116%-T3 -> 19540.948 | M3: =K3-H3 -> 0 | N3: 113462 | O3: 45505 | P3: MOTORCYCLE COMPREHENSIVE | Q3: 547000 | R3: =I3*15/100 -> 2931.1422 | S3: =I3*1/100 -> 195.40948 | T3: 500
A4: KHI/HO/D/MO/MC COMP/P/94364/08/2024 | C4: UR Suzuki | D4: 45871 | E4: 46236 | F4: FARHAN KHAN | G4: SUZUKI-GR150 EURO II | H4: =K4 -> 23247.5 | I4: =L4 -> 19540.948 | J4: 0.0425 | K4: =Q4*J4 -> 23247.5 | L4: =K4/116%-T4 -> 19540.948 | M4: =K4-H4 -> 0 | N4: 113462 | O4: 45505 | P4: MOTORCYCLE COMPREHENSIVE | Q4: 547000 | R4: =I4*15/100 -> 2931.1422 | S4: =I4*1/100 -> 195.40948 | T4: 500
A5: KHI/HO/D/MO/MC COMP/P/94373/08/2024 | C5: UR Suzuki | D5: 45505 | E5: 45870 | F5: ZUNAIR RAZA | G5: SUZUKI-GR150 EURO II | H5: =K5 -> 23247.5 | I5: =L5 -> 19540.948 | J5: 0.0425 | K5: =Q5*J5 -> 23247.5 | L5: =K5/116%-T5 -> 19540.948 | M5: =K5-H5 -> 0 | N5: 113392 | O5: 45505 | P5: MOTORCYCLE COMPREHENSIVE | Q5: 547000 | R5: =I5*15/100 -> 2931.1422 | S5: =I5*1/100 -> 195.40948 | T5: 500
A6: KHI/HO/D/MO/MC COMP/P/94374/08/2024 | C6: UR Suzuki | D6: 45871 | E6: 46236 | F6: ZUNAIR RAZA | G6: SUZUKI-GR150 EURO II | H6: =K6 -> 23247.5 | I6: =L6 -> 19540.948 | J6: 0.0425 | K6: =Q6*J6 -> 23247.5 | L6: =K6/116%-T6 -> 19540.948 | M6: =K6-H6 -> 0 | N6: 113392 | O6: 45505 | P6: MOTORCYCLE COMPREHENSIVE | Q6: 547000 | R6: =I6*15/100 -> 2931.1422 | S6: =I6*1/100 -> 195.40948 | T6: 500
A7: KHI/HO/D/MO/MC COMP/P/94375/08/2024 | C7: TR Suzuki | D7: 45505 | E7: 45870 | F7: IMRAN HUSSAIN | G7: SUZUKI-GR150 EURO II | H7: =K7 -> 23247.5 | I7: =L7 -> 19540.948 | J7: 0.0425 | K7: =Q7*J7 -> 23247.5 | L7: =K7/116%-T7 -> 19540.948 | M7: =K7-H7 -> 0 | N7: 113385 | O7: 45505 | P7: MOTORCYCLE COMPREHENSIVE | Q7: 547000 | R7: =I7*15/100 -> 2931.1422 | S7: =I7*1/100 -> 195.40948 | T7: 500
A8: KHI/HO/D/MO/MC COMP/P/94379/08/2024 | C8: UR Suzuki | D8: 45505 | E8: 45870 | F8: MUHAMMAD TAHIR AMAN | G8: SUZUKI-GSX 125 | H8: =K8 -> 21207.5 | I8: =L8 -> 17782.328 | J8: 0.0425 | K8: =Q8*J8 -> 21207.5 | L8: =K8/116%-T8 -> 17782.328 | M8: =K8-H8 -> 0 | N8: 23100411 | O8: 45505 | P8: MOTORCYCLE COMPREHENSIVE | Q8: 499000 | R8: =I8*15/100 -> 2667.3491 | S8: =I8*1/100 -> 177.82328 | T8: 500
A9: KHI/HO/D/MO/MC COMP/P/94380/08/2024 | C9: UR Suzuki | D9: 45871 | E9: 46236 | F9: MUHAMMAD TAHIR AMAN | G9: SUZUKI-GSX 125 | H9: =K9 -> 21207.5 | I9: =L9 -> 17782.328 | J9: 0.0425 | K9: =Q9*J9 -> 21207.5 | L9: =K9/116%-T9 -> 17782.328 | M9: =K9-H9 -> 0 | N9: 23100411 | O9: 45505 | P9: MOTORCYCLE COMPREHENSIVE | Q9: 499000 | R9: =I9*15/100 -> 2667.3491 | S9: =I9*1/100 -> 177.82328 | T9: 500
A10: KHI/HO/D/MO/MC COMP/P/94382/08/2024 | C10: TR Suzuki | D10: 45505 | E10: 45870 | F10: MUHAMMAD FAIZAN QASIM | G10: SUZUKI-GS 150 | H10: =K10 -> 16235 | I10: =L10 -> 13495.69 | J10: 0.0425 | K10: =Q10*J10 -> 16235 | L10: =K10/116%-T10 -> 13495.69 | M10: =K10-H10 -> 0 | N10: 30092358 | O10: 45505 | P10: MOTORCYCLE COMPREHENSIVE | Q10: 382000 | R10: =I10*15/100 -> 2024.3534 | S10: =I10*1/100 -> 134.9569 | T10: 500
A11: KHI/HO/D/MO/MC COMP/P/94383/08/2024 | C11: TR Suzuki | D11: 45871 | E11: 46236 | F11: MUHAMMAD FAIZAN QASIM | G11: SUZUKI-GS 150 | H11: =K11 -> 16235 | I11: =L11 -> 13495.69 | J11: 0.0425 | K11: =Q11*J11 -> 16235 | L11: =K11/116%-T11 -> 13495.69 | M11: =K11-H11 -> 0 | N11: 30092358 | O11: 45505 | P11: MOTORCYCLE COMPREHENSIVE | Q11: 382000 | R11: =I11*15/100 -> 2024.3534 | S11: =I11*1/100 -> 134.9569 | T11: 500
A12: KHI/HO/D/MO/MC COMP/P/94385/08/2024 | C12: UR Suzuki | D12: 45505 | E12: 45870 | F12: SYED FARHAN BADAR | G12: SUZUKI-GS 150 | H12: =K12 -> 16235 | I12: =L12 -> 13495.69 | J12: 0.0425 | K12: =Q12*J12 -> 16235 | L12: =K12/116%-T12 -> 13495.69 | M12: =K12-H12 -> 0 | N12: 30092320 | O12: 45505 | P12: MOTORCYCLE COMPREHENSIVE | Q12: 382000 | R12: =I12*15/100 -> 2024.3534 | S12: =I12*1/100 -> 134.9569 | T12: 500
A13: KHI/HO/D/MO/MC COMP/P/94386/08/2024 | C13: UR Suzuki | D13: 45871 | E13: 46236 | F13: SYED FARHAN BADAR | G13: SUZUKI-GS 150 | H13: =K13 -> 16235 | I13: =L13 -> 13495.69 | J13: 0.0425 | K13: =Q13*J13 -> 16235 | L13: =K13/116%-T13 -> 13495.69 | M13: =K13-H13 -> 0 | N13: 30092320 | O13: 45505 | P13: MOTORCYCLE COMPREHENSIVE | Q13: 382000 | R13: =I13*15/100 -> 2024.3534 | S13: =I13*1/100 -> 134.9569 | T13: 500
A14: KHI/HO/D/MO/MC COMP/P/94388/08/2024 | C14: TR Suzuki | D14: 45505 | E14: 45870 | F14: FAWAD AHMED | G14: SUZUKI-GS-150 | H14: =K14 -> 16235 | I14: =L14 -> 13495.69 | J14: 0.0425 | K14: =Q14*J14 -> 16235 | L14: =K14/116%-T14 -> 13495.69 | M14: =K14-H14 -> 0 | N14: 30092355 | O14: 45505 | P14: MOTORCYCLE COMPREHENSIVE | Q14: 382000 | R14: =I14*15/100 -> 2024.3534 | S14: =I14*1/100 -> 134.9569 | T14: 500
... A31: KHI/HO/D/MO/MC COMP/P/94438/08/2024 | C31: UR Suzuki | D31: 45871 | E31: 46236 | F31: ATIF UZ ZAMAN KHAN | G31: SUZUKI-GS 150 | H31: =K31 -> 16235 | I31: =L31 -> 13495.69 | J31: 0.0425 | K31: =Q31*J31 -> 16235 | L31: =K31/116%-T31 -> 13495.69 | M31: =K31-H31 -> 0 | N31: 30092328 | O31: 45505 | P31: MOTORCYCLE COMPREHENSIVE | Q31: 382000 | R31: =I31*15/100 -> 2024.3534 | S31: =I31*1/100 -> 134.9569 | T31: 500
A32: KHI/HO/D/MO/MC COMP/P/94439/08/2024 | C32: Suzuki R.Y.Khan | D32: 45505 | E32: 45870 | F32: MUHAMMAD MANSOOR SADIQ | G32: SUZUKI-GSX 125 | H32: =K32 -> 12475 | I32: =L32 -> 10254.31 | J32: 0.025 | K32: =Q32*J32 -> 12475 | L32: =K32/116%-T32 -> 10254.31 | N32: 23100231 | O32: 45505 | P32: MOTORCYCLE COMPREHENSIVE | Q32: 499000 | R32: =I32*15/100 -> 1538.1466 | S32: =I32*1/100 -> 102.5431 | T32: 500
A33: KHI/HO/D/MO/MC COMP/P/94461/08/2024 | C33: TR Suzuki | D33: 45506 | E33: 45871 | F33: IMTIAZ KHAN ABBASI | G33: SUZUKI-GS-150 | H33: =K33 -> 16235 | I33: =L33 -> 13495.69 | J33: 0.0425 | K33: =Q33*J33 -> 16235 | L33: =K33/116%-T33 -> 13495.69 | M33: =K33-H33 -> 0 | N33: 30092357 | O33: 45506 | P33: MOTORCYCLE COMPREHENSIVE | Q33: 382000 | R33: =I33*15/100 -> 2024.3534 | S33: =I33*1/100 -> 134.9569 | T33: 500
A34: KHI/HO/D/MO/MC COMP/P/94462/08/2024 | C34: TR Suzuki | D34: 45872 | E34: 46237 | F34: IMTIAZ KHAN ABBASI | G34: SUZUKI-GS-150 | H34: =K34 -> 16235 | I34: =L34 -> 13495.69 | J34: 0.0425 | K34: =Q34*J34 -> 16235 | L34: =K34/116%-T34 -> 13495.69 | M34: =K34-H34 -> 0 | N34: 30092357 | O34: 45506 | P34: MOTORCYCLE COMPREHENSIVE | Q34: 382000 | R34: =I34*15/100 -> 2024.3534 | S34: =I34*1/100 -> 134.9569 | T34: 500
A35: KHI/HO/D/MO/MC COMP/P/94463/08/2024 | C35: UR Suzuki | D35: 45506 | E35: 45871 | F35: SALMAN ALI KHAN | G35: SUZUKI-GD-110S | H35: =K35 -> 14960 | I35: =L35 -> 12396.552 | J35: 0.0425 | K35: =Q35*J35 -> 14960 | L35: =K35/116%-T35 -> 12396.552 | M35: =K35-H35 -> 0 | N35: 146289 | O35: 45506 | P35: MOTORCYCLE COMPREHENSIVE | Q35: 352000 | R35: =I35*15/100 -> 1859.4828 | S35: =I35*1/100 -> 123.96552 | T35: 500
A36: KHI/HO/D/MO/MC COMP/P/94464/08/2024 | C36: Suzuki Canal Motors Faisalabad Branch | D36: 45506 | E36: 45871 | F36: M. AHMAD NADEEM | G36: SUZUKI-GD-110S | H36: =K36 -> 8800 | I36: =L36 -> 7086.2069 | J36: 0.025 | K36: =Q36*J36 -> 8800 | L36: =K36/116%-T36 -> 7086.2069 | N36: 145860 | O36: 45506 | P36: MOTORCYCLE COMPREHENSIVE | Q36: 352000 | R36: =I36*15/100 -> 1062.931 | S36: =I36*1/100 -> 70.862069 | T36: 500
A37: KHI/HO/D/MO/MC COMP/P/94465/08/2024 | C37: UR Suzuki | D37: 45506 | E37: 45871 | F37: KANWER REHAN ALI KHAN | G37: SUZUKI-GSX 125 | H37: =K37 -> 20378.75 | I37: =L37 -> 17067.888 | J37: 0.0425 | K37: =Q37*J37 -> 20378.75 | L37: =K37/116%-T37 -> 17067.888 | M37: =K37-H37 -> 0 | N37: 23102531 | O37: 45506 | P37: MOTORCYCLE COMPREHENSIVE | Q37: 479500 | R37: =I37*15/100 -> 2560.1832 | S37: =I37*1/100 -> 170.67888 | T37: 500
A38: KHI/HO/D/MO/MC COMP/P/94467/08/2024 | C38: UR Suzuki | D38: 45506 | E38: 45871 | F38: NOMAN AHMED | G38: SUZUKI-GD-110S | H38: =K38 -> 14960 | I38: =L38 -> 12396.552 | J38: 0.0425 | K38: =Q38*J38 -> 14960 | L38: =K38/116%-T38 -> 12396.552 | M38: =K38-H38 -> 0 | N38: 145906 | O38: 45506 | P38: MOTORCYCLE COMPREHENSIVE | Q38: 352000 | R38: =I38*15/100 -> 1859.4828 | S38: =I38*1/100 -> 123.96552 | T38: 500
A39: KHI/HO/D/MO/MC COMP/P/94468/08/2024 | C39: UR Suzuki | D39: 45872 | E39: 46237 | F39: NOMAN AHMED | G39: SUZUKI-GD-110S | H39: =K39 -> 14960 | I39: =L39 -> 12396.552 | J39: 0.0425 | K39: =Q39*J39 -> 14960 | L39: =K39/116%-T39 -> 12396.552 | M39: =K39-H39 -> 0 | N39: 145906 | O39: 45506 | P39: MOTORCYCLE COMPREHENSIVE | Q39: 352000 | R39: =I39*15/100 -> 1859.4828 | S39: =I39*1/100 -> 123.96552 | T39: 500
A40: KHI/HO/D/MO/MC COMP/P/94469/08/2024 | C40: UR Suzuki | D40: 45506 | E40: 45871 | F40: MUHAMMAD UMER AKRAM | G40: SUZUKI-GS 150 | H40: =K40 -> 16235 | I40: =L40 -> 13495.69 | J40: 0.0425 | K40: =Q40*J40 -> 16235 | L40: =K40/116%-T40 -> 13495.69 | M40: =K40-H40 -> 0 | N40: 30092349 | O40: 45506 | P40: MOTORCYCLE COMPREHENSIVE | Q40: 382000 | R40: =I40*15/100 -> 2024.3534 | S40: =I40*1/100 -> 134.9569 | T40: 500
A41: KHI/HO/D/MO/MC COMP/P/94470/08/2024 | C41: UR Suzuki | D41: 45872 | E41: 46237 | F41: MUHAMMAD UMER AKRAM | G41: SUZUKI-GS 150 | H41: =K41 -> 16235 | I41: =L41 -> 13495.69 | J41: 0.0425 | K41: =Q41*J41 -> 16235 | L41: =K41/116%-T41 -> 13495.69 | M41: =K41-H41 -> 0 | N41: 30092349 | O41: 45506 | P41: MOTORCYCLE COMPREHENSIVE | Q41: 382000 | R41: =I41*15/100 -> 2024.3534 | S41: =I41*1/100 -> 134.9569 | T41: 500
A42: KHI/HO/D/MO/MC COMP/P/94472/08/2024 | C42: GR Suzuki | D42: 45506 | E42: 45871 | F42: MUHAMMAD NADEEM | G42: SUZUKI-GS 150 | H42: =K42 -> 9550 | I42: =L42 -> 7732.7586 | J42: 0.025 | K42: =Q42*J42 -> 9550 | L42: =K42/116%-T42 -> 7732.7586 | N42: 30092058 | O42: 45506 | P42: MOTORCYCLE COMPREHENSIVE | Q42: 382000 | R42: =I42*15/100 -> 1159.9138 | S42: =I42*1/100 -> 77.327586 | T42: 500
A43: KHI/HO/D/MO/MC COMP/P/94473/08/2024 | C43: UR Suzuki | D43: 45506 | E43: 45871 | F43: AWAIS JAMAL | G43: SUZUKI-GD-110S | H43: =K43 -> 14960 | I43: =L43 -> 12396.552 | J43: 0.0425 | K43: =Q43*J43 -> 14960 | L43: =K43/116%-T43 -> 12396.552 | M43: =K43-H43 -> 0 | N43: 145896 | O43: 45506 | P43: MOTORCYCLE COMPREHENSIVE | Q43: 352000 | R43: =I43*15/100 -> 1859.4828 | S43: =I43*1/100 -> 123.96552 | T43: 500
A44: KHI/HO/D/MO/MC COMP/P/94474/08/2024 | C44: UR Suzuki | D44: 45872 | E44: 46237 | F44: AWAIS JAMAL | G44: SUZUKI-GD-110S | H44: =K44 -> 14960 | I44: =L44 -> 12396.552 | J44: 0.0425 | K44: =Q44*J44 -> 14960 | L44: =K44/116%-T44 -> 12396.552 | M44: =K44-H44 -> 0 | N44: 145896 | O44: 45506 | P44: MOTORCYCLE COMPREHENSIVE | Q44: 352000 | R44: =I44*15/100 -> 1859.4828 | S44: =I44*1/100 -> 123.96552 | T44: 500
A45: KHI/HO/D/MO/MC COMP/P/94475/08/2024 | C45: UR Suzuki | D45: 45506 | E45: 45871 | F45: ZUBAIR ADIL | G45: SUZUKI-GR150 EURO II | H45: =K45 -> 23247.5 | I45: =L45 -> 19540.948 | J45: 0.0425 | K45: =Q45*J45 -> 23247.5 | L45: =K45/116%-T45 -> 19540.948 | M45: =K45-H45 -> 0 | N45: 113485 | O45: 45506 | P45: MOTORCYCLE COMPREHENSIVE | Q45: 547000 | R45: =I45*15/100 -> 2931.1422 | S45: =I45*1/100 -> 195.40948 | T45: 500
A46: KHI/HO/D/MO/MC COMP/P/94476/08/2024 | C46: UR Suzuki | D46: 45872 | E46: 46237 | F46: ZUBAIR ADIL | G46: SUZUKI-GR150 EURO II | H46: =K46 -> 23247.5 | I46: =L46 -> 19540.948 | J46: 0.0425 | K46: =Q46*J46 -> 23247.5 | L46: =K46/116%-T46 -> 19540.948 | M46: =K46-H46 -> 0 | N46: 113485 | O46: 45506 | P46: MOTORCYCLE COMPREHENSIVE | Q46: 547000 | R46: =I46*15/100 -> 2931.1422 | S46: =I46*1/100 -> 195.40948 | T46: 500
A47: KHI/HO/D/MO/MC COMP/P/94486/08/2024 | C47: South | D47: 45506 | E47: 45871 | F47: MAHRUKH PACKAGES (Pvt) Ltd. | G47: SUZUKI-GS 150 | H47: =K47 -> 16235 | I47: =L47 -> 13495.69 | J47: 0.0425 | K47: =Q47*J47 -> 16235 | L47: =K47/116%-T47 -> 13495.69 | M47: =K47-H47 -> 0 | N47: 30092414 | O47: 45506 | P47: MOTORCYCLE COMPREHENSIVE | Q47: 382000 | R47: =I47*15/100 -> 2024.3534 | S47: =I47*1/100 -> 134.9569 | T47: 500
A48: KHI/HO/D/MO/MC COMP/P/94492/08/2024 | C48: Khalil Motor | D48: 45506 | E48: 45871 | F48: ABDUL HAMEED | G48: SUZUKI-GS 150 | H48: =K48 -> 16235 | I48: =L48 -> 13495.69 | J48: 0.0425 | K48: =Q48*J48 -> 16235 | L48: =K48/116%-T48 -> 13495.69 | M48: =K48-H48 -> 0 | N48: 30092360 | O48: 45506 | P48: MOTORCYCLE COMPREHENSIVE | Q48: 382000 | R48: =I48*15/100 -> 2024.3534 | S48: =I48*1/100 -> 134.9569 | T48: 500
A49: KHI/HO/D/MO/MC COMP/P/94493/08/2024 | C49: Khalil Motor | D49: 45872 | E49: 46237 | F49: ABDUL HAMEED | G49: SUZUKI-GS 150 | H49: =K49 -> 16235 | I49: =L49 -> 13495.69 | J49: 0.0425 | K49: =Q49*J49 -> 16235 | L49: =K49/116%-T49 -> 13495.69 | M49: =K49-H49 -> 0 | N49: 30092360 | O49: 45506 | P49: MOTORCYCLE COMPREHENSIVE | Q49: 382000 | R49: =I49*15/100 -> 2024.3534 | S49: =I49*1/100 -> 134.9569 | T49: 500
A50: KHI/HO/D/MO/MC COMP/P/94497/08/2024 | C50: Suzuki Defence Motors | D50: 45506 | E50: 45871 | F50: AFTIKHAR HUSSAIN | G50: SUZUKI-GD-110S | H50: =K50 -> 14960 | I50: =L50 -> 12396.552 | J50: 0.0425 | K50: =Q50*J50 -> 14960 | L50: =K50/116%-T50 -> 12396.552 | M50: =K50-H50 -> 0 | N50: 145953 | O50: 45506 | P50: MOTORCYCLE COMPREHENSIVE | Q50: 352000 | R50: =I50*15/100 -> 1859.4828 | S50: =I50*1/100 -> 123.96552 | T50: 500
A51: KHI/HO/D/MO/MC COMP/P/94498/08/2024 | C51: Suzuki Defence Motors | D51: 45872 | E51: 46237 | F51: AFTIKHAR HUSSAIN | G51: SUZUKI-GD-110S | H51: =K51 -> 14960 | I51: =L51 -> 12396.552 | J51: 0.0425 | K51: =Q51*J51 -> 14960 | L51: =K51/116%-T51 -> 12396.552 | M51: =K51-H51 -> 0 | N51: 145953 | O51: 45506 | P51: MOTORCYCLE COMPREHENSIVE | Q51: 352000 | R51: =I51*15/100 -> 1859.4828 | S51: =I51*1/100 -> 123.96552 | T51: 500
A52: KHI/HO/D/MO/MC COMP/P/94510/08/2024 | C52: UR Suzuki | D52: 45506 | E52: 45871 | F52: MUHAMMAD USMAN KHAN | G52: SUZUKI-GR150 EURO II | H52: =K52 -> 23247.5 | I52: =L52 -> 19540.948 | J52: 0.0425 | K52: =Q52*J52 -> 23247.5 | L52: =K52/116%-T52 -> 19540.948 | M52: =K52-H52 -> 0 | N52: 113481 | O52: 45506 | P52: MOTORCYCLE COMPREHENSIVE | Q52: 547000 | R52: =I52*15/100 -> 2931.1422 | S52: =I52*1/100 -> 195.40948 | T52: 500
A53: KHI/HO/D/MO/MC COMP/P/94511/08/2024 | C53: UR Suzuki | D53: 45872 | E53: 46237 | F53: MUHAMMAD USMAN KHAN | G53: SUZUKI-GR150 EURO II | H53: =K53 -> 23247.5 | I53: =L53 -> 19540.948 | J53: 0.0425 | K53: =Q53*J53 -> 23247.5 | L53: =K53/116%-T53 -> 19540.948 | M53: =K53-H53 -> 0 | N53: 113481 | O53: 45506 | P53: MOTORCYCLE COMPREHENSIVE | Q53: 547000 | R53: =I53*15/100 -> 2931.1422 | S53: =I53*1/100 -> 195.40948 | T53: 500
A54: KHI/HO/D/MO/MC COMP/P/94515/08/2024 | C54: TS Suzuki | D54: 45506 | E54: 45871 | F54: Muhammad Numan Khan | G54: SUZUKI-GR150 EURO II | H54: =K54 -> 13675 | I54: =L54 -> 11288.793 | J54: 0.025 | K54: =Q54*J54 -> 13675 | L54: =K54/116%-T54 -> 11288.793 | N54: 113256 | O54: 45506 | P54: MOTORCYCLE COMPREHENSIVE | Q54: 547000 | R54: =I54*15/100 -> 1693.319 | S54: =I54*1/100 -> 112.88793 | T54: 500
A55: KHI/HO/D/MO/MC COMP/P/94516/08/2024 | C55: UR Suzuki | D55: 45506 | E55: 45871 | F55: WAQAR AHMED SIDDIQUI | G55: SUZUKI-GR150 EURO II | H55: =K55 -> 23247.5 | I55: =L55 -> 19540.948 | J55: 0.0425 | K55: =Q55*J55 -> 23247.5 | L55: =K55/116%-T55 -> 19540.948 | M55: =K55-H55 -> 0 | N55: 113496 | O55: 45506 | P55: MOTORCYCLE COMPREHENSIVE | Q55: 547000 | R55: =I55*15/100 -> 2931.1422 | S55: =I55*1/100 -> 195.40948 | T55: 500
A56: KHI/HO/D/MO/MC COMP/P/94517/08/2024 | C56: UR Suzuki | D56: 45872 | E56: 46237 | F56: WAQAR AHMED SIDDIQUI | G56: SUZUKI-GR150 EURO II | H56: =K56 -> 23247.5 | I56: =L56 -> 19540.948 | J56: 0.0425 | K56: =Q56*J56 -> 23247.5 | L56: =K56/116%-T56 -> 19540.948 | M56: =K56-H56 -> 0 | N56: 113496 | O56: 45506 | P56: MOTORCYCLE COMPREHENSIVE | Q56: 547000 | R56: =I56*15/100 -> 2931.1422 | S56: =I56*1/100 -> 195.40948 | T56: 500
...

Sheet Sheet2
A1: Policy # | B1: PREM
A2: KHI/HO/D/MO/MC COMP/P/94363/08/2024 | B2: 23247.5
A3: KHI/HO/D/MO/MC COMP/P/94364/08/2024 | B3: 23247.5
A4: KHI/HO/D/MO/MC COMP/P/94373/08/2024 | B4: 23247.5
A5: KHI/HO/D/MO/MC COMP/P/94374/08/2024 | B5: 23247.5
A6: KHI/HO/D/MO/MC COMP/P/94375/08/2024 | B6: 23247.5
A7: KHI/HO/D/MO/MC COMP/P/94379/08/2024 | B7: 21207.5
A8: KHI/HO/D/MO/MC COMP/P/94380/08/2024 | B8: 21207.5
A9: KHI/HO/D/MO/MC COMP/P/94382/08/2024 | B9: 16235
A10: KHI/HO/D/MO/MC COMP/P/94383/08/2024 | B10: 16235
A11: KHI/HO/D/MO/MC COMP/P/94385/08/2024 | B11: 16235
A12: KHI/HO/D/MO/MC COMP/P/94386/08/2024 | B12: 16235
A13: KHI/HO/D/MO/MC COMP/P/94388/08/2024 | B13: 16235
... A1017: KHI/HO/D/MO/MC COMP/P/96533/08/2024 | B1017: 16235
B1018: =SUM(B2:B1017) -> 14053879

Sheet working
A1: POLICY NO. | B1: Assorted_code | D1: Premium | E1: 22Oct240201
A2: KHI/HO/D/MO/MC COMP/P/94363/08/2024 | B2: =VLOOKUP(A2,policy!B:C,2,0) -> 040000180429 | C2: 23247.5 | D2: 23247.5 | E2: 22Oct240201 | F2: ="insert into ins_premium_det (premium_rcv_code,assorted_code, rec_amount,premium_rcv_detail_code,remaining_amt, payrec, mode_code,coinsurance_code,class_cd,it_remarks) values" -> insert into ins_premium_det (premium_rcv_code,assorted_code, rec_amount,premium_rcv_detail_code,remaining_amt, payrec, mode_code,coinsurance_code,class_cd,it_remarks) values | G2: ="('"&E2&"','"&B2&"','"&D2&"',(select max(to_number(i.premium_rcv_detail_code))+1 from ins_premium_det i),'"&D2&"','"&D2&"','02', '11000003','00','Request by Mr. Omair Ali 22-Oct-2024 allocation 22Oct240201');" -> ('22Oct240201','040000180429','23247.5',(select max(to_number(i.premium_rcv_detail_code))+1 from ins_premium_det i),'23247.5','23247.5','02', '11000003','00','Request by Mr. Omair Ali 22-Oct-2024 allocation 22Oct240201'); | H2: =F2&G2 -> insert into ins_premium_det (premium_rcv_code,assorted_code, rec_amount,premium_rcv_detail_code,remaining_amt, payrec, mode_code,coinsurance_code,class_cd,it_remarks) values('22Oct240201','040000180429','23247.5',(select max(to_number(i.premium_rcv_detail_code))+1 from ins_premium_det i),'23247.5','23247.5','02', '11000003','00','Request by Mr. Omair Ali 22-Oct-2024 allocation 22Oct240201');
A3: KHI/HO/D/MO/MC COMP/P/94364/08/2024 | B3: =VLOOKUP(A3,policy!B:C,2,0) -> 040000180430 | C3: 23247.5 | D3: 23247.5 | E3: 22Oct240201 | F3: ="insert into ins_premium_det (premium_rcv_code,assorted_code, rec_amount,premium_rcv_detail_code,remaining_amt, payrec, mode_code,coinsurance_code,class_cd,it_remarks) values" -> insert into ins_premium_det (premium_rcv_code,assorted_code, rec_amount,premium_rcv_detail_code,remaining_amt, payrec, mode_code,coinsurance_code,class_cd,it_remarks) values | G3: ="('"&E3&"','"&B3&"','"&D3&"',(select max(to_number(i.premium_rcv_detail_code))+1 from ins_premium_det i),'"&D3&"','"&D3&"','02', '11000003','00','Request by Mr. Omair Ali 22-Oct-2024 allocation 22Oct240201');" -> ('22Oct240201','040000180430','23247.5',(select max(to_number(i.premium_rcv_detail_code))+1 from ins_premium_det i),'23247.5','23247.5','02', '11000003','00','Request by Mr. Omair Ali 22-Oct-2024 allocation 22Oct240201'); | H3: =F3&G3 -> insert into ins_premium_det (premium_rcv_code,assorted_code, rec_amount,premium_rcv_detail_code,remaining_amt, payrec, mode_code,coinsurance_code,class_cd,it_remarks) values('22Oct240201','040000180430','23247.5',(select max(to_number(i.premium_rcv_detail_code))+1 from ins_premium_det i),'23247.5','23247.5','02', '11000003','00','Request by Mr. Omair Ali 22-Oct-2024 allocation 22Oct240201');
A4: KHI/HO/D/MO/MC COMP/P/94373/08/2024 | B4: =VLOOKUP(A4,policy!B:C,2,0) -> 040000180441 | C4: 23247.5 | D4: 23247.5 | E4: 22Oct240201 | F4: ="insert into ins_premium_det (premium_rcv_code,assorted_code, rec_amount,premium_rcv_detail_code,remaining_amt, payrec, mode_code,coinsurance_code,class_cd,it_remarks) values" -> insert into ins_premium_det (premium_rcv_code,assorted_code, rec_amount,premium_rcv_detail_code,remaining_amt, payrec, mode_code,coinsurance_code,class_cd,it_remarks) values | G4: ="('"&E4&"','"&B4&"','"&D4&"',(select max(to_number(i.premium_rcv_detail_code))+1 from ins_premium_det i),'"&D4&"','"&D4&"','02', '11000003','00','Request by Mr. Omair Ali 22-Oct-2024 allocation 22Oct240201');" -> ('22Oct240201','040000180441','23247.5',(select max(to_number(i.premium_rcv_detail_code))+1 from ins_premium_det i),'23247.5','23247.5','02', '11000003','00','Request by Mr. Omair Ali 22-Oct-2024 allocation 22Oct240201'); | H4: =F4&G4 -> insert into ins_premium_det (premium_rcv_code,assorted_code, rec_amount,premium_rcv_detail_code,remaining_amt, payrec, mode_code,coinsurance_code,class_cd,it_remarks) values('22Oct240201','040000180441','23247.5',(select max(to_number(i.premium_rcv_detail_code))+1 from ins_premium_det i),'23247.5','23247.5','02', '11000003','00','Request by Mr. Omair Ali 22-Oct-2024 allocation 22Oct240201');
A5: KHI/HO/D/MO/MC COMP/P/94374/08/2024 | B5: =VLOOKUP(A5,policy!B:C,2,0) -> 040000180443 | C5: 23247.5 | D5: 23247.5 | E5: 22Oct240201 | F5: ="insert into ins_premium_det (premium_rcv_code,assorted_code, rec_amount,premium_rcv_detail_code,remaining_amt, payrec, mode_code,coinsurance_code,class_cd,it_remarks) values" -> insert into ins_premium_det (premium_rcv_code,assorted_code, rec_amount,premium_rcv_detail_code,remaining_amt, payrec, mode_code,coinsurance_code,class_cd,it_remarks) values | G5: ="('"&E5&"','"&B5&"','"&D5&"',(select max(to_number(i.premium_rcv_detail_code))+1 from ins_premium_det i),'"&D5&"','"&D5&"','02', '11000003','00','Request by Mr. Omair Ali 22-Oct-2024 allocation 22Oct240201');" -> ('22Oct240201','040000180443','23247.5',(select max(to_number(i.premium_rcv_detail_code))+1 from ins_premium_det i),'23247.5','23247.5','02', '11000003','00','Request by Mr. Omair Ali 22-Oct-2024 allocation 22Oct240201'); | H5: =F5&G5 -> insert into ins_premium_det (premium_rcv_code,assorted_code, rec_amount,premium_rcv_detail_code,remaining_amt, payrec, mode_code,coinsurance_code,class_cd,it_remarks) values('22Oct240201','040000180443','23247.5',(select max(to_number(i.premium_rcv_detail_code))+1 from ins_premium_det i),'23247.5','23247.5','02', '11000003','00','Request by Mr. Omair Ali 22-Oct-2024 allocation 22Oct240201');
A6: KHI/HO/D/MO/MC COMP/P/94375/08/2024 | B6: =VLOOKUP(A6,policy!B:C,2,0) -> 040000180444 | C6: 23247.5 | D6: 23247.5 | E6: 22Oct240201 | F6: ="insert into ins_premium_det (premium_rcv_code,assorted_code, rec_amount,premium_rcv_detail_code,remaining_amt, payrec, mode_code,coinsurance_code,class_cd,it_remarks) values" -> insert into ins_premium_det (premium_rcv_code,assorted_code, rec_amount,premium_rcv_detail_code,remaining_amt, payrec, mode_code,coinsurance_code,class_cd,it_remarks) values | G6: ="('"&E6&"','"&B6&"','"&D6&"',(select max(to_number(i.premium_rcv_detail_code))+1 from ins_premium_det i),'"&D6&"','"&D6&"','02', '11000003','00','Request by Mr. Omair Ali 22-Oct-2024 allocation 22Oct240201');" -> ('22Oct240201','040000180444','23247.5',(select max(to_number(i.premium_rcv_detail_code))+1 from ins_premium_det i),'23247.5','23247.5','02', '11000003','00','Request by Mr. Omair Ali 22-Oct-2024 allocation 22Oct240201'); | H6: =F6&G6 -> insert into ins_premium_det (premium_rcv_code,assorted_code, rec_amount,premium_rcv_detail_code,remaining_amt, payrec, mode_code,coinsurance_code,class_cd,it_remarks) values('22Oct240201','040000180444','23247.5',(select max(to_number(i.premium_rcv_detail_code))+1 from ins_premium_det i),'23247.5','23247.5','02', '11000003','00','Request by Mr. Omair Ali 22-Oct-2024 allocation 22Oct240201');
A7: KHI/HO/D/MO/MC COMP/P/94379/08/2024 | B7: =VLOOKUP(A7,policy!B:C,2,0) -> 040000180448 | C7: 21207.5 | D7: 21207.5 | E7: 22Oct240201 | F7: ="insert into ins_premium_det (premium_rcv_code,assorted_code, rec_amount,premium_rcv_detail_code,remaining_amt, payrec, mode_code,coinsurance_code,class_cd,it_remarks) values" -> insert into ins_premium_det (premium_rcv_code,assorted_code, rec_amount,premium_rcv_detail_code,remaining_amt, payrec, mode_code,coinsurance_code,class_cd,it_remarks) values | G7: ="('"&E7&"','"&B7&"','"&D7&"',(select max(to_number(i.premium_rcv_detail_code))+1 from ins_premium_det i),'"&D7&"','"&D7&"','02', '11000003','00','Request by Mr. Omair Ali 22-Oct-2024 allocation 22Oct240201');" -> ('22Oct240201','040000180448','21207.5',(select max(to_number(i.premium_rcv_detail_code))+1 from ins_premium_det i),'21207.5','21207.5','02', '11000003','00','Request by Mr. Omair Ali 22-Oct-2024 allocation 22Oct240201'); | H7: =F7&G7 -> insert into ins_premium_det (premium_rcv_code,assorted_code, rec_amount,premium_rcv_detail_code,remaining_amt, payrec, mode_code,coinsurance_code,class_cd,it_remarks) values('22Oct240201','040000180448','21207.5',(select max(to_number(i.premium_rcv_detail_code))+1 from ins_premium_det i),'21207.5','21207.5','02', '11000003','00','Request by Mr. Omair Ali 22-Oct-2024 allocation 22Oct240201');
A8: KHI/HO/D/MO/MC COMP/P/94380/08/2024 | B8: =VLOOKUP(A8,policy!B:C,2,0) -> 040000180449 | C8: 21207.5 | D8: 21207.5 | E8: 22Oct240201 | F8: ="insert into ins_premium_det (premium_rcv_code,assorted_code, rec_amount,premium_rcv_detail_code,remaining_amt, payrec, mode_code,coinsurance_code,class_cd,it_remarks) values" -> insert into ins_premium_det (premium_rcv_code,assorted_code, rec_amount,premium_rcv_detail_code,remaining_amt, payrec, mode_code,coinsurance_code,class_cd,it_remarks) values | G8: ="('"&E8&"','"&B8&"','"&D8&"',(select max(to_number(i.premium_rcv_detail_code))+1 from ins_premium_det i),'"&D8&"','"&D8&"','02', '11000003','00','Request by Mr. Omair Ali 22-Oct-2024 allocation 22Oct240201');" -> ('22Oct240201','040000180449','21207.5',(select max(to_number(i.premium_rcv_detail_code))+1 from ins_premium_det i),'21207.5','21207.5','02', '11000003','00','Request by Mr. Omair Ali 22-Oct-2024 allocation 22Oct240201'); | H8: =F8&G8 -> insert into ins_premium_det (premium_rcv_code,assorted_code, rec_amount,premium_rcv_detail_code,remaining_amt, payrec, mode_code,coinsurance_code,class_cd,it_remarks) values('22Oct240201','040000180449','21207.5',(select max(to_number(i.premium_rcv_detail_code))+1 from ins_premium_det i),'21207.5','21207.5','02', '11000003','00','Request by Mr. Omair Ali 22-Oct-2024 allocation 22Oct240201');
A9: KHI/HO/D/MO/MC COMP/P/94382/08/2024 | B9: =VLOOKUP(A9,policy!B:C,2,0) -> 040000180451 | C9: 16235 | D9: 16235 | E9: 22Oct240201 | F9: ="insert into ins_premium_det (premium_rcv_code,assorted_code, rec_amount,premium_rcv_detail_code,remaining_amt, payrec, mode_code,coinsurance_code,class_cd,it_remarks) values" -> insert into ins_premium_det (premium_rcv_code,assorted_code, rec_amount,premium_rcv_detail_code,remaining_amt, payrec, mode_code,coinsurance_code,class_cd,it_remarks) values | G9: ="('"&E9&"','"&B9&"','"&D9&"',(select max(to_number(i.premium_rcv_detail_code))+1 from ins_premium_det i),'"&D9&"','"&D9&"','02', '11000003','00','Request by Mr. Omair Ali 22-Oct-2024 allocation 22Oct240201');" -> ('22Oct240201','040000180451','16235',(select max(to_number(i.premium_rcv_detail_code))+1 from ins_premium_det i),'16235','16235','02', '11000003','00','Request by Mr. Omair Ali 22-Oct-2024 allocation 22Oct240201'); | H9: =F9&G9 -> insert into ins_premium_det (premium_rcv_code,assorted_code, rec_amount,premium_rcv_detail_code,remaining_amt, payrec, mode_code,coinsurance_code,class_cd,it_remarks) values('22Oct240201','040000180451','16235',(select max(to_number(i.premium_rcv_detail_code))+1 from ins_premium_det i),'16235','16235','02', '11000003','00','Request by Mr. Omair Ali 22-Oct-2024 allocation 22Oct240201');
A10: KHI/HO/D/MO/MC COMP/P/94383/08/2024 | B10: =VLOOKUP(A10,policy!B:C,2,0) -> 040000180452 | C10: 16235 | D10: 16235 | E10: 22Oct240201 | F10: ="insert into ins_premium_det (premium_rcv_code,assorted_code, rec_amount,premium_rcv_detail_code,remaining_amt, payrec, mode_code,coinsurance_code,class_cd,it_remarks) values" -> insert into ins_premium_det (premium_rcv_code,assorted_code, rec_amount,premium_rcv_detail_code,remaining_amt, payrec, mode_code,coinsurance_code,class_cd,it_remarks) values | G10: ="('"&E10&"','"&B10&"','"&D10&"',(select max(to_number(i.premium_rcv_detail_code))+1 from ins_premium_det i),'"&D10&"','"&D10&"','02', '11000003','00','Request by Mr. Omair Ali 22-Oct-2024 allocation 22Oct240201');" -> ('22Oct240201','040000180452','16235',(select max(to_number(i.premium_rcv_detail_code))+1 from ins_premium_det i),'16235','16235','02', '11000003','00','Request by Mr. Omair Ali 22-Oct-2024 allocation 22Oct240201'); | H10: =F10&G10 -> insert into ins_premium_det (premium_rcv_code,assorted_code, rec_amount,premium_rcv_detail_code,remaining_amt, payrec, mode_code,coinsurance_code,class_cd,it_remarks) values('22Oct240201','040000180452','16235',(select max(to_number(i.premium_rcv_detail_code))+1 from ins_premium_det i),'16235','16235','02', '11000003','00','Request by Mr. Omair Ali 22-Oct-2024 allocation 22Oct240201');
A11: KHI/HO/D/MO/MC COMP/P/94385/08/2024 | B11: =VLOOKUP(A11,policy!B:C,2,0) -> 040000180454 | C11: 16235 | D11: 16235 | E11: 22Oct240201 | F11: ="insert into ins_premium_det (premium_rcv_code,assorted_code, rec_amount,premium_rcv_detail_code,remaining_amt, payrec, mode_code,coinsurance_code,class_cd,it_remarks) values" -> insert into ins_premium_det (premium_rcv_code,assorted_code, rec_amount,premium_rcv_detail_code,remaining_amt, payrec, mode_code,coinsurance_code,class_cd,it_remarks) values | G11: ="('"&E11&"','"&B11&"','"&D11&"',(select max(to_number(i.premium_rcv_detail_code))+1 from ins_premium_det i),'"&D11&"','"&D11&"','02', '11000003','00','Request by Mr. Omair Ali 22-Oct-2024 allocation 22Oct240201');" -> ('22Oct240201','040000180454','16235',(select max(to_number(i.premium_rcv_detail_code))+1 from ins_premium_det i),'16235','16235','02', '11000003','00','Request by Mr. Omair Ali 22-Oct-2024 allocation 22Oct240201'); | H11: =F11&G11 -> insert into ins_premium_det (premium_rcv_code,assorted_code, rec_amount,premium_rcv_detail_code,remaining_amt, payrec, mode_code,coinsurance_code,class_cd,it_remarks) values('22Oct240201','040000180454','16235',(select max(to_number(i.premium_rcv_detail_code))+1 from ins_premium_det i),'16235','16235','02', '11000003','00','Request by Mr. Omair Ali 22-Oct-2024 allocation 22Oct240201');
A12: KHI/HO/D/MO/MC COMP/P/94386/08/2024 | B12: =VLOOKUP(A12,policy!B:C,2,0) -> 040000180455 | C12: 16235 | D12: 16235 | E12: 22Oct240201 | F12: ="insert into ins_premium_det (premium_rcv_code,assorted_code, rec_amount,premium_rcv_detail_code,remaining_amt, payrec, mode_code,coinsurance_code,class_cd,it_remarks) values" -> insert into ins_premium_det (premium_rcv_code,assorted_code, rec_amount,premium_rcv_detail_code,remaining_amt, payrec, mode_code,coinsurance_code,class_cd,it_remarks) values | G12: ="('"&E12&"','"&B12&"','"&D12&"',(select max(to_number(i.premium_rcv_detail_code))+1 from ins_premium_det i),'"&D12&"','"&D12&"','02', '11000003','00','Request by Mr. Omair Ali 22-Oct-2024 allocation 22Oct240201');" -> ('22Oct240201','040000180455','16235',(select max(to_number(i.premium_rcv_detail_code))+1 from ins_premium_det i),'16235','16235','02', '11000003','00','Request by Mr. Omair Ali 22-Oct-2024 allocation 22Oct240201'); | H12: =F12&G12 -> insert into ins_premium_det (premium_rcv_code,assorted_code, rec_amount,premium_rcv_detail_code,remaining_amt, payrec, mode_code,coinsurance_code,class_cd,it_remarks) values('22Oct240201','040000180455','16235',(select max(to_number(i.premium_rcv_detail_code))+1 from ins_premium_det i),'16235','16235','02', '11000003','00','Request by Mr. Omair Ali 22-Oct-2024 allocation 22Oct240201');
A13: KHI/HO/D/MO/MC COMP/P/94388/08/2024 | B13: =VLOOKUP(A13,policy!B:C,2,0) -> 040000180457 | C13: 16235 | D13: 16235 | E13: 22Oct240201 | F13: ="insert into ins_premium_det (premium_rcv_code,assorted_code, rec_amount,premium_rcv_detail_code,remaining_amt, payrec, mode_code,coinsurance_code,class_cd,it_remarks) values" -> insert into ins_premium_det (premium_rcv_code,assorted_code, rec_amount,premium_rcv_detail_code,remaining_amt, payrec, mode_code,coinsurance_code,class_cd,it_remarks) values | G13: ="('"&E13&"','"&B13&"','"&D13&"',(select max(to_number(i.premium_rcv_detail_code))+1 from ins_premium_det i),'"&D13&"','"&D13&"','02', '11000003','00','Request by Mr. Omair Ali 22-Oct-2024 allocation 22Oct240201');" -> ('22Oct240201','040000180457','16235',(select max(to_number(i.premium_rcv_detail_code))+1 from ins_premium_det i),'16235','16235','02', '11000003','00','Request by Mr. Omair Ali 22-Oct-2024 allocation 22Oct240201'); | H13: =F13&G13 -> insert into ins_premium_det (premium_rcv_code,assorted_code, rec_amount,premium_rcv_detail_code,remaining_amt, payrec, mode_code,coinsurance_code,class_cd,it_remarks) values('22Oct240201','040000180457','16235',(select max(to_number(i.premium_rcv_detail_code))+1 from ins_premium_det i),'16235','16235','02', '11000003','00','Request by Mr. Omair Ali 22-Oct-2024 allocation 22Oct240201');
... A1017: KHI/HO/D/MO/MC COMP/P/96533/08/2024 | B1017: =VLOOKUP(A1017,policy!B:C,2,0) -> 040000183070 | C1017: 16235 | D1017: 16235 | E1017: 22Oct240201 | F1017: ="insert into ins_premium_det (premium_rcv_code,assorted_code, rec_amount,premium_rcv_detail_code,remaining_amt, payrec, mode_code,coinsurance_code,class_cd,it_remarks) values" -> insert into ins_premium_det (premium_rcv_code,assorted_code, rec_amount,premium_rcv_detail_code,remaining_amt, payrec, mode_code,coinsurance_code,class_cd,it_remarks) values | G1017: ="('"&E1017&"','"&B1017&"','"&D1017&"',(select max(to_number(i.premium_rcv_detail_code))+1 from ins_premium_det i),'"&D1017&"','"&D1017&"','02', '11000003','00','Request by Mr. Omair Ali 22-Oct-2024 allocation 22Oct240201');" -> ('22Oct240201','040000183070','16235',(select max(to_number(i.premium_rcv_detail_code))+1 from ins_premium_det i),'16235','16235','02', '11000003','00','Request by Mr. Omair Ali 22-Oct-2024 allocation 22Oct240201'); | H1017: =F1017&G1017 -> insert into ins_premium_det (premium_rcv_code,assorted_code, rec_amount,premium_rcv_detail_code,remaining_amt, payrec, mode_code,coinsurance_code,class_cd,it_remarks) values('22Oct240201','040000183070','16235',(select max(to_number(i.premium_rcv_detail_code))+1 from ins_premium_det i),'16235','16235','02', '11000003','00','Request by Mr. Omair Ali 22-Oct-2024 allocation 22Oct240201');
C1019: =SUM(C2:C1017) -> 14053879 | D1019: =SUM(D2:D1017) -> 14053879 | E1019: =D1019-C1019 -> 0

Sheet Sheet4
A1: KHI/HO/D/MO/MC COMP/P/94363/08/2024 | B1: -08-2024 | D1: 94363 | E1: ="ia.assorted_string like '%"&D1&B1&"%' or" -> ia.assorted_string like '%94363-08-2024%' or
A2: KHI/HO/D/MO/MC COMP/P/94364/08/2024 | B2: -08-2024 | D2: 94364 | E2: ="ia.assorted_string like '%"&D2&B2&"%' or" -> ia.assorted_string like '%94364-08-2024%' or
A3: KHI/HO/D/MO/MC COMP/P/94373/08/2024 | B3: -08-2024 | D3: 94373 | E3: ="ia.assorted_string like '%"&D3&B3&"%' or" -> ia.assorted_string like '%94373-08-2024%' or
A4: KHI/HO/D/MO/MC COMP/P/94374/08/2024 | B4: -08-2024 | D4: 94374 | E4: ="ia.assorted_string like '%"&D4&B4&"%' or" -> ia.assorted_string like '%94374-08-2024%' or
A5: KHI/HO/D/MO/MC COMP/P/94375/08/2024 | B5: -08-2024 | D5: 94375 | E5: ="ia.assorted_string like '%"&D5&B5&"%' or" -> ia.assorted_string like '%94375-08-2024%' or
A6: KHI/HO/D/MO/MC COMP/P/94379/08/2024 | B6: -08-2024 | D6: 94379 | E6: ="ia.assorted_string like '%"&D6&B6&"%' or" -> ia.assorted_string like '%94379-08-2024%' or
A7: KHI/HO/D/MO/MC COMP/P/94380/08/2024 | B7: -08-2024 | D7: 94380 | E7: ="ia.assorted_string like '%"&D7&B7&"%' or" -> ia.assorted_string like '%94380-08-2024%' or
A8: KHI/HO/D/MO/MC COMP/P/94382/08/2024 | B8: -08-2024 | D8: 94382 | E8: ="ia.assorted_string like '%"&D8&B8&"%' or" -> ia.assorted_string like '%94382-08-2024%' or
A9: KHI/HO/D/MO/MC COMP/P/94383/08/2024 | B9: -08-2024 | D9: 94383 | E9: ="ia.assorted_string like '%"&D9&B9&"%' or" -> ia.assorted_string like '%94383-08-2024%' or
A10: KHI/HO/D/MO/MC COMP/P/94385/08/2024 | B10: -08-2024 | D10: 94385 | E10: ="ia.assorted_string like '%"&D10&B10&"%' or" -> ia.assorted_string like '%94385-08-2024%' or
A11: KHI/HO/D/MO/MC COMP/P/94386/08/2024 | B11: -08-2024 | D11: 94386 | E11: ="ia.assorted_string like '%"&D11&B11&"%' or" -> ia.assorted_string like '%94386-08-2024%' or
A12: KHI/HO/D/MO/MC COMP/P/94388/08/2024 | B12: -08-2024 | D12: 94388 | E12: ="ia.assorted_string like '%"&D12&B12&"%' or" -> ia.assorted_string like '%94388-08-2024%' or
... A1016: KHI/HO/D/MO/MC COMP/P/96533/08/2024 | B1016: -08-2024 | D1016: 96533 | E1016: ="ia.assorted_string like '%"&D1016&B1016&"%' or" -> ia.assorted_string like '%96533-08-2024%' or

Sheet policy
B1: FUNC_ASSORTED_STRING(IA.ASSORTED_CODE) | C1: ASSORTED_CODE
A2: 1 | B2: KHI/HO/D/MO/MC COMP/P/95109/08/2024 | C2: 040000181347
A3: 2 | B3: KHI/HO/D/MO/MC COMP/P/95110/08/2024 | C3: 040000181348
A4: 3 | B4: KHI/HO/D/MO/MC COMP/P/95117/08/2024 | C4: 040000181356
A5: 4 | B5: KHI/HO/D/MO/MC COMP/P/95118/08/2024 | C5: 040000181357
A6: 5 | B6: KHI/HO/D/MO/MC COMP/P/95120/08/2024 | C6: 040000181359
A7: 6 | B7: KHI/HO/D/MO/MC COMP/P/95121/08/2024 | C7: 040000181360
A8: 7 | B8: KHI/HO/D/MO/MC COMP/P/95122/08/2024 | C8: 040000181361
A9: 8 | B9: KHI/HO/D/MO/MC COMP/P/95123/08/2024 | C9: 040000181362
A10: 9 | B10: KHI/HO/D/MO/MC COMP/P/95128/08/2024 | C10: 040000181368
A11: 10 | B11: KHI/HO/D/MO/MC COMP/P/95130/08/2024 | C11: 040000181371
A12: 11 | B12: KHI/HO/D/MO/MC COMP/P/95124/08/2024 | C12: 040000181363
A13: 12 | B13: KHI/HO/D/MO/MC COMP/P/95125/08/2024 | C13: 040000181364
... A1022: 1021 | B1022: KHI/HO/D/MO/MC COMP/P/94861/08/2024 | C1022: 040000181031

Sheet Sheet1
F3: 0331-0365301
