Workbook

Sheet Sheet1
A1: S.No | B1: Loan ID | C1: Hub Code | D1: Name of Lessee | E1: Vehicle Description | F1: Engine | G1: Chasis | H1: Registration | I1: Start Date | J1: Expiry Date | K1: TENURE | L1: SUM COVERED | M1: Bank Ins Premium | N1: Bank Premium Rate | O1: New Takaful Company | P1: Policy No. | Q1: TMS Premium | R1: Endorsement No. | S1: Difference Amount
A2: 1 | B2: CI-2021-0171-7005 | C2: PK0010002 | D2: USAMA TAJ KHAN | E2: Alto VXL | F2: R155412 | G2: H1055399 | H2: - | I2: 45667 | J2: 46032 | K2: 12 MONTHS | L2: 1190457 | M2: 17857 | N2: 1.50 | O2: SALAM TAKAFUL Insurance Ltd-WTO | P2: KHI/HO/D/MO/PC COMP/C/105699/1/01/2025 | Q2: 17857 | S2: =Q2-M2 -> 0
A3: 2 | B3: CI-2021-0172-3102 | C3: PK0010002 | D3: ZAFAR ALI | E3: Yaris 1.3 GLI AT | F3: 2A43772 | G3: R-7027668 | H3: - | I3: 45693 | J3: 46058 | K3: 12 MONTHS | L3: 1891755 | M3: 28376 | N3: 1.50 | O3: SALAM TAKAFUL Insurance Ltd-WTO | P3: KHI/HO/D/MO/PC COMP/C/105699/5/01/2025 | Q3: 28376 | S3: =Q3-M3 -> 0
A4: 3 | B4: CI-2021-1273-7470 | C4: PK0010002 | D4: SHARAF U DDIN KALHORO | E4: Mehran VXR | F4: B757956 | G4: PK01306484 | H4: - | I4: 45672 | J4: 46037 | K4: 12 MONTHS | L4: 626940 | M4: 9404 | N4: 1.50 | O4: SALAM TAKAFUL Insurance Ltd-WTO | P4: KHI/HO/D/MO/PC COMP/C/105699/4/01/2025 | Q4: 9404 | S4: =Q4-M4 -> 0
A5: 4 | B5: CI-2021-1601-1846 | C5: PK0010002 | D5: Majid Hussain Hussain | E5: CULTUS VXR | F5: K191635 | G5: H10091601 | H5: - | I5: 45682 | J5: 46047 | K5: 12 MONTHS | L5: 1206495 | M5: 18097 | N5: 1.50 | O5: SALAM TAKAFUL Insurance Ltd-WTO | P5: KHI/HO/D/MO/PC COMP/C/105699/7/01/2025 | Q5: 18097 | S5: =Q5-M5 -> 0
A6: 5 | B6: CI-2021-2481-2544 | C6: PK0010002 | D6: MUHAMMAD NAWAZ | E6: Alto VXR | F6: R201717 | G6: H1101716 | H6: - | I6: 45672 | J6: 46037 | K6: 12 MONTHS | L6: 1099332 | M6: 16490 | N6: 1.50 | O6: SALAM TAKAFUL Insurance Ltd-WTO | P6: KHI/HO/D/MO/PC COMP/C/105699/3/01/2025 | Q6: 16490 | S6: =Q6-M6 -> 0
A7: 6 | B7: CI-2021-9945-2298 | C7: PK0010002 | D7: MUHAMMAD IRFAN | E7: City PT Aspire 1.5L | F7: Z81002837 | G7: MR008424 | H7: - | I7: 45682 | J7: 46047 | K7: 12 MONTHS | L7: 2326968 | M7: 34905 | N7: 1.50 | O7: SALAM TAKAFUL Insurance Ltd-WTO | P7: KHI/HO/D/MO/PC COMP/C/105699/6/01/2025 | Q7: 34905 | S7: =Q7-M7 -> 0
A8: 7 | B8: CI-2022-0101-0019 | C8: PK0010002 | D8: Muhammmad Zahoor Uz Zama | E8: Swift GLX CVT | F8: 1012726 | G8: 112724 | H8: BYG-064 | I8: 45682 | J8: 46047 | K8: 12 MONTHS | L8: 3045600 | M8: 45684 | N8: 1.50 | O8: SALAM TAKAFUL Insurance Ltd-WTO | P8: KHI/HO/D/MO/PC COMP/C/106617/3/01/2025 | Q8: 45684 | S8: =Q8-M8 -> 0
A9: 8 | B9: CI-2022-8601-0017 | C9: PK0010002 | D9: YAMEEN KHAN JAMALI | E9: Cultus AGS | F9: K204738 | G9: H10104731 | H9: BYF-392 | I9: 45677 | J9: 46042 | K9: 12 MONTHS | L9: 2619540 | M9: 39293 | N9: 1.50 | O9: SALAM TAKAFUL Insurance Ltd-WTO | P9: KHI/HO/D/MO/PC COMP/C/106617/1/01/2025 | Q9: 39293 | S9: =Q9-M9 -> 0
A10: 9 | B10: CI-2022-9910-0005 | C10: PK0010002 | D10: MANSOOR GHAFFAR | E10: Sportage AWD | F10: H310401 | G10: P502907 | H10: BK-0212 | I10: 45672 | J10: 46037 | K10: 12 MONTHS | L10: 3321000 | M10: 49815 | N10: 1.50 | O10: SALAM TAKAFUL Insurance Ltd-WTO | P10: KHI/HO/D/MO/PC COMP/C/106617/2/01/2025 | Q10: 49815 | S10: =Q10-M10 -> 0
A11: 10 | B11: CI-2022-9949-0016 | C11: PK0010002 | D11: ABDUL RAUF | E11: Picanto AT | F11: P131172 | G11: P708289 | H11: BVH-590 | I11: 45698 | J11: 46063 | K11: 12 MONTHS | L11: 2106000 | M11: 31590 | N11: 1.50 | O11: SALAM TAKAFUL Insurance Ltd-WTO | P11: KHI/HO/D/MO/PC COMP/C/106617/5/01/2025 | Q11: 31590 | S11: =Q11-M11 -> 0
A12: 11 | B12: CI-2022-9955-0012 | C12: PK0010002 | D12: AMREEN YASIR | E12: Honda City i VTEC CVT Aspire 1.5 | F12: Z81013282 | G12: R030271 | H12: BYG-688 | I12: 45698 | J12: 46063 | K12: 12 MONTHS | L12: 3651480 | M12: 54772 | N12: 1.50 | O12: SALAM TAKAFUL Insurance Ltd-WTO | P12: KHI/HO/D/MO/PC COMP/C/106617/4/01/2025 | Q12: 54772 | S12: =Q12-M12 -> 0
A13: 12 | B13: CI-2023-0000-0317 | C13: PK0010002 | D13: MUHAMMAD NAFAY MAHMOOD | E13: Alto VXR AGS | F13: 6R285857 | G13: NF1AET306H1185854 | H13: - | I13: 45667 | J13: 46032 | K13: 12 MONTHS | L13: 2519100 | M13: 37787 | N13: 1.50 | O13: SALAM TAKAFUL Insurance Ltd-WTO | P13: KHI/HO/D/MO/PC COMP/C/106616/2/01/2025 | Q13: 37787 | S13: =Q13-M13 -> 0
... A23: 22 | B23: CM-2019-3601-0392 | C23: PK0010002 | D23: ABDUL SATTAR | E23: SUZUKI ALTO VXR | F23: 6R128500 | G23: NF1AET306H1028471 | H23: BRG-376 | I23: 45667 | J23: 46032 | K23: 12 MONTHS | L23: 772361 | M23: 15447 | N23: 2 | O23: SALAM TAKAFUL Insurance Ltd-WTO | P23: KHI/HO/D/MO/PC COMP/C/106621/2/01/2025 | Q23: 15447 | S23: =Q23-M23 -> 0
A24: 23 | B24: CM-2020-8301-0781 | C24: PK0010002 | D24: MUHAMMAD ASIF | E24: TOYOTA COROLLA ALTIS 1.6 | F24: Q070745 | G24: ZRE171R-6048259 | I24: 45677 | J24: 46042 | K24: 12 MONTHS | L24: 2178252 | M24: 43565 | N24: 2 | O24: SALAM TAKAFUL Insurance Ltd-WTO | P24: KHI/HO/D/MO/PC COMP/C/105699/9/01/2025 | Q24: 43565 | S24: =Q24-M24 -> 0
A25: 24 | B25: CI-2021-0135-5645 | C25: PK0010002 | D25: SADAQAT KHAN | E25: Corolla Altis 1.6 AT | F25: Q045586 | G25: R-6023073 | H25: BMK-157 | I25: 45662 | J25: 46027 | K25: 12 MONTHS | L25: 1822500 | M25: 27338 | N25: 1.50 | O25: SALAM TAKAFUL Insurance Ltd-WTO | P25: KHI/HO/D/MO/PC COMP/C/104220/10/12/2024 | Q25: 27338 | S25: =Q25-M25 -> 0
A26: 25 | B26: CI-2021-9801-6822 | C26: PK0010002 | D26: AHSAN SHAFIQ | E26: Alto VXR | F26: R200858 | G26: H1100854 | H26: - | I26: 45662 | J26: 46027 | K26: 12 MONTHS | L26: 1099332 | M26: 16490 | N26: 1.50 | O26: SALAM TAKAFUL Insurance Ltd-WTO | P26: KHI/HO/D/MO/PC COMP/C/104220/9/12/2024 | Q26: 16490 | S26: =Q26-M26 -> 0
A27: 26 | B27: CI-2022-0139-0022 | C27: PK0010002 | D27: TARIQ NISHAN | E27: Corolla Altis 1.6 AT | F27: Q052681 | G27: R6030146 | H27: BPB-372 | I27: 45662 | J27: 46027 | K27: 12 MONTHS | L27: 2632500 | M27: 39488 | N27: 1.50 | O27: SALAM TAKAFUL Insurance Ltd-WTO | P27: KHI/HO/D/MO/PC COMP/C/104213/3/12/2024 | Q27: 39488 | S27: =Q27-M27 -> 0
A28: 27 | B28: CI-2022-9916-0011 | C28: PK0010002 | D28: SANA ULLAH KHAN | E28: Chery Tiggo 4 Pro | F28: H01804 | G28: 1900867 | H28: BL-0627 | I28: 45662 | J28: 46027 | K28: 12 MONTHS | L28: 4502353 | M28: 67535 | N28: 1.50 | O28: SALAM TAKAFUL Insurance Ltd-WTO | P28: KHI/HO/D/MO/PC COMP/C/104213/4/12/2024 | Q28: 67535 | S28: =Q28-M28 -> 0
A29: 28 | B29: CI-2022-9930-0016 | C29: PK0010002 | D29: MUHAMMAD TAHA KHAN | E29: Alto VXR AGS | F29: R260966 | G29: 1160968 | H29: BYC-461 | I29: 45662 | J29: 46027 | K29: 12 MONTHS | L29: 1717200 | M29: 25758 | N29: 1.50 | O29: SALAM TAKAFUL Insurance Ltd-WTO | P29: KHI/HO/D/MO/PC COMP/C/104213/5/12/2024 | Q29: 25758 | S29: =Q29-M29 -> 0
A30: 29 | B30: CI-2021-0703-6504 | C30: PK0010007 | D30: SALMA NAZ | E30: City MT 1.5L | F30: L15A90017978 | G30: NFBGM2646JR219450 | H30: AHF-581 | I30: 45689 | J30: 46054 | K30: 12 MONTHS | L30: 1856763 | M30: 27851 | N30: 1.50 | O30: SALAM TAKAFUL Insurance Ltd-WTO | P30: KHI/HO/D/MO/PC COMP/C/106715/2/01/2025 | Q30: 27851 | S30: =Q30-M30 -> 0
A31: 30 | B31: CI-2023-0701-0019 | C31: PK0010007 | D31: SALAR ISLAM TARIQ | E31: Corolla XLI Auto | F31: NZE170R-4121575 | G31: Z494244 | H31: AES-858 | I31: 45667 | J31: 46032 | K31: 12 MONTHS | L31: 2340000 | M31: 35100 | N31: 1.50 | O31: SALAM TAKAFUL Insurance Ltd-WTO | P31: KHI/HO/D/MO/PC COMP/C/106715/1/01/2025 | Q31: 35100 | S31: =Q31-M31 -> 0
A32: 31 | B32: CI-2022-0705-0010 | C32: PK0010007 | D32: FAWAD AZIZ AWAN | E32: Alto VXL | F32: 6R236953 | G32: NF1AET306H1136966 | H32: AZT-943 | I32: 45667 | J32: 46032 | K32: 12 MONTHS | L32: 2025000 | M32: 30375 | N32: 1.50 | O32: SALAM TAKAFUL Insurance Ltd-WTO | P32: KHI/HO/D/MO/PC COMP/C/104273/2/12/2024 | Q32: 30375 | S32: =Q32-M32 -> 0
A33: 32 | B33: CM-2021-2601-0282 | C33: PK0010007 | D33: MUHAMMAD AKHLAQ | E33: HONDA CITY 1339 CC | F33: L13Z17462469 | G33: NFBGM1547HR205658 | H33: LEF-19-6753 | I33: 45667 | J33: 46032 | K33: 12 MONTHS | L33: 1120473 | M33: 16807 | N33: 1.50 | O33: SALAM TAKAFUL Insurance Ltd-WTO | P33: KHI/HO/D/MO/PC COMP/C/104273/1/12/2024 | Q33: 16807 | S33: =Q33-M33 -> 0
A34: 33 | B34: CI-2022-1408-0041 | C34: PK0010008 | D34: MUHAMMAD IMRAN YAQOOB | E34: Cultus VXL | F34: PK10K193704 | G34: NF1AVK31H10093715 | H34: AKE-706 | I34: 45698 | J34: 46063 | K34: 12 MONTHS | L34: 2430000 | M34: 36450 | N34: 1.50 | O34: SALAM TAKAFUL Insurance Ltd-WTO | P34: KHI/HO/D/MO/PC COMP/C/106692/1/01/2025 | Q34: 36450 | S34: =Q34-M34 -> 0
A35: 34 | B35: CI-2023-9853-0005 | C35: PK0010008 | D35: AMIR MEHMOOD | E35: Alto VXR | F35: 6R178124 | G35: NF1AET306H1078100 | H35: AVJ-299-ICT | I35: 45682 | J35: 46047 | K35: 12 MONTHS | L35: 2025000 | M35: 30375 | N35: 1.50 | O35: SALAM TAKAFUL Insurance Ltd-WTO | P35: KHI/HO/D/MO/PC COMP/C/106690/1/01/2025 | Q35: 30375 | S35: =Q35-M35 -> 0
A36: 35 | B36: CI-2023-9853-0006 | C36: PK0010008 | D36: SAMINA SHAHEEN | E36: Wagon R VXL | F36: PK10B189522 | G36: A1J310PK10089506 | H36: LE-20-9531 | I36: 45662 | J36: 46027 | K36: 12 MONTHS | L36: 2115000 | M36: 31725 | N36: 1.50 | O36: SALAM TAKAFUL Insurance Ltd-WTO | P36: KHI/HO/D/MO/PC COMP/C/104307/1/12/2024 | Q36: 31725 | S36: =Q36-M36 -> 0
... A87: 86 | B87: CI-2022-0607-0005 | C87: PK0010015 | D87: TAYYAB RIAZ | E87: Alto VXR | F87: 6R263492 | G87: NF1AET306H1163477 | H87: AMW-354 (PUNJAB) | I87: 45662 | J87: 46027 | K87: 12 MONTHS | L87: 1403730 | M87: 21056 | N87: 1.50 | O87: SALAM TAKAFUL Insurance Ltd-WTO | P87: KHI/HO/D/MO/PC COMP/C/104265/5/12/2024 | Q87: 21056 | S87: =Q87-M87 -> 0
A88: 87 | B88: CI-2022-0902-0004 | C88: PK0010015 | D88: IMTIAZ HAMEED | E88: Corolla X Altis Grande CVTI 1.8 | F88: Q364391 | G88: ZRE172R7063572 | H88: APL | I88: 45667 | J88: 46032 | K88: 12 MONTHS | L88: 3692336 | M88: 55385 | N88: 1.50 | O88: SALAM TAKAFUL Insurance Ltd-WTO | P88: KHI/HO/D/MO/PC COMP/P/104265/12/2024 | Q88: 61539 | R88: KHI/HO/D/MO/PC COMP/E/51649/00004/01/2025 | S88: =Q88-M88 -> 6154
A89: 88 | B89: CI-2022-0810-0018 | C89: PK0010016 | D89: SYED SHABBIR HASSAN RIZVI | E89: Cultus AGS | F89: PK10K204991 | G89: NF1AVK31H10104999 | H89: BBE-725 | I89: 45672 | J89: 46037 | K89: 12 MONTHS | L89: 2619540 | M89: 39293 | N89: 1.50 | O89: SALAM TAKAFUL Insurance Ltd-WTO | P89: KHI/HO/D/MO/PC COMP/C/106719/3/01/2025 | Q89: 39293 | S89: =Q89-M89 -> 0
A90: 89 | B90: CI-2022-0829-0005 | C90: PK0010016 | D90: RAJA KHURRAM FIDA | E90: Alto VX | F90: 6R266395 | G90: NF1AET306H1166372 | H90: BBC-671 | I90: 45667 | J90: 46032 | K90: 12 MONTHS | L90: 1194750 | M90: 17921 | N90: 1.50 | O90: SALAM TAKAFUL Insurance Ltd-WTO | P90: KHI/HO/D/MO/PC COMP/C/106719/1/01/2025 | Q90: 17921 | S90: =Q90-M90 -> 0
A91: 90 | B91: CI-2022-9829-0022 | C91: PK0010016 | D91: MUHAMMAD AFZAL | E91: Alto VX | F91: 6R238841 | G91: NF1AET306H1138668 | H91: AZS-483 | I91: 45667 | J91: 46032 | K91: 12 MONTHS | L91: 1458000 | M91: 21870 | N91: 1.50 | O91: SALAM TAKAFUL Insurance Ltd-WTO | P91: KHI/HO/D/MO/PC COMP/C/106719/2/01/2025 | Q91: 21870 | S91: =Q91-M91 -> 0
A92: 91 | B92: CI-2023-0000-0304 | C92: PK0010016 | D92: SHEIKH MUHAMMAD WAQAR | E92: Alto VXL AGS | F92: 6R292638 | G92: NF1AET306H1192623 | H92: BCZ-297 | I92: 45672 | J92: 46037 | K92: 12 MONTHS | L92: 2641500 | M92: 39623 | N92: 1.50 | O92: SALAM TAKAFUL Insurance Ltd-WTO | P92: KHI/HO/D/MO/PC COMP/C/106720/1/01/2025 | Q92: 39623 | S92: =Q92-M92 -> 0
A93: 92 | B93: CI-2023-0812-0009 | C93: PK0010016 | D93: RAJA ABDUL BASIT MISKEEN | E93: Corolla Altis Grande AT | F93: Q337718 | G93: ZRE172R-7036867 | H93: ALI-244 | I93: 45682 | J93: 46047 | K93: 12 MONTHS | L93: 4500000 | M93: 67500 | N93: 1.50 | O93: SALAM TAKAFUL Insurance Ltd-WTO | P93: KHI/HO/D/MO/PC COMP/C/106720/3/01/2025 | Q93: 67500 | S93: =Q93-M93 -> 0
A94: 93 | B94: CI-2023-0819-0009 | C94: PK0010016 | D94: ZAHEER AHMED AWAN | E94: Alto VXL AGS | F94: 6R293932 | G94: NF1AET306H1193970 | H94: BDB-347 | I94: 45682 | J94: 46047 | K94: 12 MONTHS | L94: 2641500 | M94: 39623 | N94: 1.50 | O94: SALAM TAKAFUL Insurance Ltd-WTO | P94: KHI/HO/D/MO/PC COMP/C/106720/2/01/2025 | Q94: 39623 | S94: =Q94-M94 -> 0
A95: 94 | B95: CI-2022-0813-0013 | C95: PK0010016 | D95: CHOUDHARY ZULFIQAR HUSSAIN | E95: Alto VXL | F95: 6R263398 | G95: NF1AET306H1163370 | H95: BBC-458 | I95: 45662 | J95: 46027 | K95: 12 MONTHS | L95: 1800630 | M95: 27009 | N95: 1.50 | O95: SALAM TAKAFUL Insurance Ltd-WTO | P95: KHI/HO/D/MO/PC COMP/C/104283/7/12/2024 | Q95: 27009 | S95: =Q95-M95 -> 0
A96: 95 | B96: CI-2022-0827-0009 | C96: PK0010016 | D96: NADEEM AHMED | E96: Alto VXL | F96: 6R264348 | G96: NF1AET306H1164374 | H96: BBE-257 | I96: 45672 | J96: 46037 | K96: 12 MONTHS | L96: 1580310 | M96: 23705 | N96: 1.50 | O96: SALAM TAKAFUL Insurance Ltd-WTO | P96: KHI/HO/D/MO/PC COMP/C/104283/9/12/2024 | Q96: 23705 | S96: =Q96-M96 -> 0
A97: 96 | B97: CI-2022-3401-0012 | C97: PK0010016 | D97: KHAWAJA DANISH NAZIR QADRI | E97: Alto VXR | F97: 6R263140. | G97: NF1AET306H1163124 | H97: BBB-672 | I97: 45662 | J97: 46027 | K97: 12 MONTHS | L97: 1403730 | M97: 21056 | N97: 1.50 | O97: SALAM TAKAFUL Insurance Ltd-WTO | P97: KHI/HO/D/MO/PC COMP/C/104283/6/12/2024 | Q97: 21056 | S97: =Q97-M97 -> 0
A98: 97 | B98: CI-2022-9829-0011 | C98: PK0010016 | D98: RIZWAN NAZIR | E98: Alto VXR | F98: 6R262284 | G98: NF1AET306H1162237 | H98: BBC-976 | I98: 45667 | J98: 46032 | K98: 12 MONTHS | L98: 1403730 | M98: 21056 | N98: 1.50 | O98: SALAM TAKAFUL Insurance Ltd-WTO | P98: KHI/HO/D/MO/PC COMP/C/104283/8/12/2024 | Q98: 21056 | S98: =Q98-M98 -> 0
A99: 98 | B99: CI-2023-0818-0016 | C99: PK0010016 | D99: YASIR NAZIR | E99: Civic 1.8 i VTEC CVT Oriel | F99: R18Z12934990 | G99: NFBFC6664JR038418 | H99: AJK-344 | I99: 45667 | J99: 46032 | K99: 12 MONTHS | L99: 3839400 | M99: 57591 | N99: 1.50 | O99: SALAM TAKAFUL Insurance Ltd-WTO | P99: KHI/HO/D/MO/PC COMP/C/104281/3/12/2024 | Q99: 57591 | S99: =Q99-M99 -> 0
...

Sheet working
A1: POLICY NO. | B1: Assorted_code | D1: Premium | E1: 21Feb250007
A2: KHI/HO/D/MO/PC COMP/C/105699/1/01/2025 | B2: =VLOOKUP(A2,Sheet3!B:C,2,0) -> 070000173855 | C2: 17857 | D2: =ROUND(C2,0) -> 17857 | E2: 21Feb250007 | F2: ="insert into ins_premium_det (premium_rcv_code,assorted_code, rec_amount,premium_rcv_detail_code,remaining_amt, payrec, mode_code,coinsurance_code,class_cd,it_remarks) values" -> insert into ins_premium_det (premium_rcv_code,assorted_code, rec_amount,premium_rcv_detail_code,remaining_amt, payrec, mode_code,coinsurance_code,class_cd,it_remarks) values | G2: ="('"&E2&"','"&B2&"','"&D2&"',(select max(to_number(i.premium_rcv_detail_code))+1 from ins_premium_det i),'"&D2&"','"&D2&"','02', '11000003','00','Request by Mr.Saqib Saleem 24-Feb-2025');" -> ('21Feb250007','070000173855','17857',(select max(to_number(i.premium_rcv_detail_code))+1 from ins_premium_det i),'17857','17857','02', '11000003','00','Request by Mr.Saqib Saleem 24-Feb-2025'); | H2: =F2&G2 -> insert into ins_premium_det (premium_rcv_code,assorted_code, rec_amount,premium_rcv_detail_code,remaining_amt, payrec, mode_code,coinsurance_code,class_cd,it_remarks) values('21Feb250007','070000173855','17857',(select max(to_number(i.premium_rcv_detail_code))+1 from ins_premium_det i),'17857','17857','02', '11000003','00','Request by Mr.Saqib Saleem 24-Feb-2025');
A3: KHI/HO/D/MO/PC COMP/C/105699/5/01/2025 | B3: =VLOOKUP(A3,Sheet3!B:C,2,0) -> 070000173867 | C3: 28376 | D3: =ROUND(C3,0) -> 28376 | E3: 21Feb250007 | F3: ="insert into ins_premium_det (premium_rcv_code,assorted_code, rec_amount,premium_rcv_detail_code,remaining_amt, payrec, mode_code,coinsurance_code,class_cd,it_remarks) values" -> insert into ins_premium_det (premium_rcv_code,assorted_code, rec_amount,premium_rcv_detail_code,remaining_amt, payrec, mode_code,coinsurance_code,class_cd,it_remarks) values | G3: ="('"&E3&"','"&B3&"','"&D3&"',(select max(to_number(i.premium_rcv_detail_code))+1 from ins_premium_det i),'"&D3&"','"&D3&"','02', '11000003','00','Request by Mr.Saqib Saleem 24-Feb-2025');" -> ('21Feb250007','070000173867','28376',(select max(to_number(i.premium_rcv_detail_code))+1 from ins_premium_det i),'28376','28376','02', '11000003','00','Request by Mr.Saqib Saleem 24-Feb-2025'); | H3: =F3&G3 -> insert into ins_premium_det (premium_rcv_code,assorted_code, rec_amount,premium_rcv_detail_code,remaining_amt, payrec, mode_code,coinsurance_code,class_cd,it_remarks) values('21Feb250007','070000173867','28376',(select max(to_number(i.premium_rcv_detail_code))+1 from ins_premium_det i),'28376','28376','02', '11000003','00','Request by Mr.Saqib Saleem 24-Feb-2025');
A4: KHI/HO/D/MO/PC COMP/C/105699/4/01/2025 | B4: =VLOOKUP(A4,Sheet3!B:C,2,0) -> 070000173862 | C4: 9404 | D4: =ROUND(C4,0) -> 9404 | E4: 21Feb250007 | F4: ="insert into ins_premium_det (premium_rcv_code,assorted_code, rec_amount,premium_rcv_detail_code,remaining_amt, payrec, mode_code,coinsurance_code,class_cd,it_remarks) values" -> insert into ins_premium_det (premium_rcv_code,assorted_code, rec_amount,premium_rcv_detail_code,remaining_amt, payrec, mode_code,coinsurance_code,class_cd,it_remarks) values | G4: ="('"&E4&"','"&B4&"','"&D4&"',(select max(to_number(i.premium_rcv_detail_code))+1 from ins_premium_det i),'"&D4&"','"&D4&"','02', '11000003','00','Request by Mr.Saqib Saleem 24-Feb-2025');" -> ('21Feb250007','070000173862','9404',(select max(to_number(i.premium_rcv_detail_code))+1 from ins_premium_det i),'9404','9404','02', '11000003','00','Request by Mr.Saqib Saleem 24-Feb-2025'); | H4: =F4&G4 -> insert into ins_premium_det (premium_rcv_code,assorted_code, rec_amount,premium_rcv_detail_code,remaining_amt, payrec, mode_code,coinsurance_code,class_cd,it_remarks) values('21Feb250007','070000173862','9404',(select max(to_number(i.premium_rcv_detail_code))+1 from ins_premium_det i),'9404','9404','02', '11000003','00','Request by Mr.Saqib Saleem 24-Feb-2025');
A5: KHI/HO/D/MO/PC COMP/C/105699/7/01/2025 | B5: =VLOOKUP(A5,Sheet3!B:C,2,0) -> 070000173869 | C5: 18097 | D5: =ROUND(C5,0) -> 18097 | E5: 21Feb250007 | F5: ="insert into ins_premium_det (premium_rcv_code,assorted_code, rec_amount,premium_rcv_detail_code,remaining_amt, payrec, mode_code,coinsurance_code,class_cd,it_remarks) values" -> insert into ins_premium_det (premium_rcv_code,assorted_code, rec_amount,premium_rcv_detail_code,remaining_amt, payrec, mode_code,coinsurance_code,class_cd,it_remarks) values | G5: ="('"&E5&"','"&B5&"','"&D5&"',(select max(to_number(i.premium_rcv_detail_code))+1 from ins_premium_det i),'"&D5&"','"&D5&"','02', '11000003','00','Request by Mr.Saqib Saleem 24-Feb-2025');" -> ('21Feb250007','070000173869','18097',(select max(to_number(i.premium_rcv_detail_code))+1 from ins_premium_det i),'18097','18097','02', '11000003','00','Request by Mr.Saqib Saleem 24-Feb-2025'); | H5: =F5&G5 -> insert into ins_premium_det (premium_rcv_code,assorted_code, rec_amount,premium_rcv_detail_code,remaining_amt, payrec, mode_code,coinsurance_code,class_cd,it_remarks) values('21Feb250007','070000173869','18097',(select max(to_number(i.premium_rcv_detail_code))+1 from ins_premium_det i),'18097','18097','02', '11000003','00','Request by Mr.Saqib Saleem 24-Feb-2025');
A6: KHI/HO/D/MO/PC COMP/C/105699/3/01/2025 | B6: =VLOOKUP(A6,Sheet3!B:C,2,0) -> 070000173860 | C6: 16490 | D6: =ROUND(C6,0) -> 16490 | E6: 21Feb250007 | F6: ="insert into ins_premium_det (premium_rcv_code,assorted_code, rec_amount,premium_rcv_detail_code,remaining_amt, payrec, mode_code,coinsurance_code,class_cd,it_remarks) values" -> insert into ins_premium_det (premium_rcv_code,assorted_code, rec_amount,premium_rcv_detail_code,remaining_amt, payrec, mode_code,coinsurance_code,class_cd,it_remarks) values | G6: ="('"&E6&"','"&B6&"','"&D6&"',(select max(to_number(i.premium_rcv_detail_code))+1 from ins_premium_det i),'"&D6&"','"&D6&"','02', '11000003','00','Request by Mr.Saqib Saleem 24-Feb-2025');" -> ('21Feb250007','070000173860','16490',(select max(to_number(i.premium_rcv_detail_code))+1 from ins_premium_det i),'16490','16490','02', '11000003','00','Request by Mr.Saqib Saleem 24-Feb-2025'); | H6: =F6&G6 -> insert into ins_premium_det (premium_rcv_code,assorted_code, rec_amount,premium_rcv_detail_code,remaining_amt, payrec, mode_code,coinsurance_code,class_cd,it_remarks) values('21Feb250007','070000173860','16490',(select max(to_number(i.premium_rcv_detail_code))+1 from ins_premium_det i),'16490','16490','02', '11000003','00','Request by Mr.Saqib Saleem 24-Feb-2025');
A7: KHI/HO/D/MO/PC COMP/C/105699/6/01/2025 | B7: =VLOOKUP(A7,Sheet3!B:C,2,0) -> 070000173868 | C7: 34905 | D7: =ROUND(C7,0) -> 34905 | E7: 21Feb250007 | F7: ="insert into ins_premium_det (premium_rcv_code,assorted_code, rec_amount,premium_rcv_detail_code,remaining_amt, payrec, mode_code,coinsurance_code,class_cd,it_remarks) values" -> insert into ins_premium_det (premium_rcv_code,assorted_code, rec_amount,premium_rcv_detail_code,remaining_amt, payrec, mode_code,coinsurance_code,class_cd,it_remarks) values | G7: ="('"&E7&"','"&B7&"','"&D7&"',(select max(to_number(i.premium_rcv_detail_code))+1 from ins_premium_det i),'"&D7&"','"&D7&"','02', '11000003','00','Request by Mr.Saqib Saleem 24-Feb-2025');" -> ('21Feb250007','070000173868','34905',(select max(to_number(i.premium_rcv_detail_code))+1 from ins_premium_det i),'34905','34905','02', '11000003','00','Request by Mr.Saqib Saleem 24-Feb-2025'); | H7: =F7&G7 -> insert into ins_premium_det (premium_rcv_code,assorted_code, rec_amount,premium_rcv_detail_code,remaining_amt, payrec, mode_code,coinsurance_code,class_cd,it_remarks) values('21Feb250007','070000173868','34905',(select max(to_number(i.premium_rcv_detail_code))+1 from ins_premium_det i),'34905','34905','02', '11000003','00','Request by Mr.Saqib Saleem 24-Feb-2025');
A8: KHI/HO/D/MO/PC COMP/C/106617/3/01/2025 | B8: =VLOOKUP(A8,Sheet3!B:C,2,0) -> 070000174467 | C8: 45684 | D8: =ROUND(C8,0) -> 45684 | E8: 21Feb250007 | F8: ="insert into ins_premium_det (premium_rcv_code,assorted_code, rec_amount,premium_rcv_detail_code,remaining_amt, payrec, mode_code,coinsurance_code,class_cd,it_remarks) values" -> insert into ins_premium_det (premium_rcv_code,assorted_code, rec_amount,premium_rcv_detail_code,remaining_amt, payrec, mode_code,coinsurance_code,class_cd,it_remarks) values | G8: ="('"&E8&"','"&B8&"','"&D8&"',(select max(to_number(i.premium_rcv_detail_code))+1 from ins_premium_det i),'"&D8&"','"&D8&"','02', '11000003','00','Request by Mr.Saqib Saleem 24-Feb-2025');" -> ('21Feb250007','070000174467','45684',(select max(to_number(i.premium_rcv_detail_code))+1 from ins_premium_det i),'45684','45684','02', '11000003','00','Request by Mr.Saqib Saleem 24-Feb-2025'); | H8: =F8&G8 -> insert into ins_premium_det (premium_rcv_code,assorted_code, rec_amount,premium_rcv_detail_code,remaining_amt, payrec, mode_code,coinsurance_code,class_cd,it_remarks) values('21Feb250007','070000174467','45684',(select max(to_number(i.premium_rcv_detail_code))+1 from ins_premium_det i),'45684','45684','02', '11000003','00','Request by Mr.Saqib Saleem 24-Feb-2025');
A9: KHI/HO/D/MO/PC COMP/C/106617/1/01/2025 | B9: =VLOOKUP(A9,Sheet3!B:C,2,0) -> 070000174465 | C9: 39293 | D9: =ROUND(C9,0) -> 39293 | E9: 21Feb250007 | F9: ="insert into ins_premium_det (premium_rcv_code,assorted_code, rec_amount,premium_rcv_detail_code,remaining_amt, payrec, mode_code,coinsurance_code,class_cd,it_remarks) values" -> insert into ins_premium_det (premium_rcv_code,assorted_code, rec_amount,premium_rcv_detail_code,remaining_amt, payrec, mode_code,coinsurance_code,class_cd,it_remarks) values | G9: ="('"&E9&"','"&B9&"','"&D9&"',(select max(to_number(i.premium_rcv_detail_code))+1 from ins_premium_det i),'"&D9&"','"&D9&"','02', '11000003','00','Request by Mr.Saqib Saleem 24-Feb-2025');" -> ('21Feb250007','070000174465','39293',(select max(to_number(i.premium_rcv_detail_code))+1 from ins_premium_det i),'39293','39293','02', '11000003','00','Request by Mr.Saqib Saleem 24-Feb-2025'); | H9: =F9&G9 -> insert into ins_premium_det (premium_rcv_code,assorted_code, rec_amount,premium_rcv_detail_code,remaining_amt, payrec, mode_code,coinsurance_code,class_cd,it_remarks) values('21Feb250007','070000174465','39293',(select max(to_number(i.premium_rcv_detail_code))+1 from ins_premium_det i),'39293','39293','02', '11000003','00','Request by Mr.Saqib Saleem 24-Feb-2025');
A10: KHI/HO/D/MO/PC COMP/C/106617/2/01/2025 | B10: =VLOOKUP(A10,Sheet3!B:C,2,0) -> 070000174466 | C10: 49815 | D10: =ROUND(C10,0) -> 49815 | E10: 21Feb250007 | F10: ="insert into ins_premium_det (premium_rcv_code,assorted_code, rec_amount,premium_rcv_detail_code,remaining_amt, payrec, mode_code,coinsurance_code,class_cd,it_remarks) values" -> insert into ins_premium_det (premium_rcv_code,assorted_code, rec_amount,premium_rcv_detail_code,remaining_amt, payrec, mode_code,coinsurance_code,class_cd,it_remarks) values | G10: ="('"&E10&"','"&B10&"','"&D10&"',(select max(to_number(i.premium_rcv_detail_code))+1 from ins_premium_det i),'"&D10&"','"&D10&"','02', '11000003','00','Request by Mr.Saqib Saleem 24-Feb-2025');" -> ('21Feb250007','070000174466','49815',(select max(to_number(i.premium_rcv_detail_code))+1 from ins_premium_det i),'49815','49815','02', '11000003','00','Request by Mr.Saqib Saleem 24-Feb-2025'); | H10: =F10&G10 -> insert into ins_premium_det (premium_rcv_code,assorted_code, rec_amount,premium_rcv_detail_code,remaining_amt, payrec, mode_code,coinsurance_code,class_cd,it_remarks) values('21Feb250007','070000174466','49815',(select max(to_number(i.premium_rcv_detail_code))+1 from ins_premium_det i),'49815','49815','02', '11000003','00','Request by Mr.Saqib Saleem 24-Feb-2025');
A11: KHI/HO/D/MO/PC COMP/C/106617/5/01/2025 | B11: =VLOOKUP(A11,Sheet3!B:C,2,0) -> 070000174469 | C11: 31590 | D11: =ROUND(C11,0) -> 31590 | E11: 21Feb250007 | F11: ="insert into ins_premium_det (premium_rcv_code,assorted_code, rec_amount,premium_rcv_detail_code,remaining_amt, payrec, mode_code,coinsurance_code,class_cd,it_remarks) values" -> insert into ins_premium_det (premium_rcv_code,assorted_code, rec_amount,premium_rcv_detail_code,remaining_amt, payrec, mode_code,coinsurance_code,class_cd,it_remarks) values | G11: ="('"&E11&"','"&B11&"','"&D11&"',(select max(to_number(i.premium_rcv_detail_code))+1 from ins_premium_det i),'"&D11&"','"&D11&"','02', '11000003','00','Request by Mr.Saqib Saleem 24-Feb-2025');" -> ('21Feb250007','070000174469','31590',(select max(to_number(i.premium_rcv_detail_code))+1 from ins_premium_det i),'31590','31590','02', '11000003','00','Request by Mr.Saqib Saleem 24-Feb-2025'); | H11: =F11&G11 -> insert into ins_premium_det (premium_rcv_code,assorted_code, rec_amount,premium_rcv_detail_code,remaining_amt, payrec, mode_code,coinsurance_code,class_cd,it_remarks) values('21Feb250007','070000174469','31590',(select max(to_number(i.premium_rcv_detail_code))+1 from ins_premium_det i),'31590','31590','02', '11000003','00','Request by Mr.Saqib Saleem 24-Feb-2025');
A12: KHI/HO/D/MO/PC COMP/C/106617/4/01/2025 | B12: =VLOOKUP(A12,Sheet3!B:C,2,0) -> 070000174468 | C12: 54772 | D12: =ROUND(C12,0) -> 54772 | E12: 21Feb250007 | F12: ="insert into ins_premium_det (premium_rcv_code,assorted_code, rec_amount,premium_rcv_detail_code,remaining_amt, payrec, mode_code,coinsurance_code,class_cd,it_remarks) values" -> insert into ins_premium_det (premium_rcv_code,assorted_code, rec_amount,premium_rcv_detail_code,remaining_amt, payrec, mode_code,coinsurance_code,class_cd,it_remarks) values | G12: ="('"&E12&"','"&B12&"','"&D12&"',(select max(to_number(i.premium_rcv_detail_code))+1 from ins_premium_det i),'"&D12&"','"&D12&"','02', '11000003','00','Request by Mr.Saqib Saleem 24-Feb-2025');" -> ('21Feb250007','070000174468','54772',(select max(to_number(i.premium_rcv_detail_code))+1 from ins_premium_det i),'54772','54772','02', '11000003','00','Request by Mr.Saqib Saleem 24-Feb-2025'); | H12: =F12&G12 -> insert into ins_premium_det (premium_rcv_code,assorted_code, rec_amount,premium_rcv_detail_code,remaining_amt, payrec, mode_code,coinsurance_code,class_cd,it_remarks) values('21Feb250007','070000174468','54772',(select max(to_number(i.premium_rcv_detail_code))+1 from ins_premium_det i),'54772','54772','02', '11000003','00','Request by Mr.Saqib Saleem 24-Feb-2025');
A13: KHI/HO/D/MO/PC COMP/C/106616/2/01/2025 | B13: =VLOOKUP(A13,Sheet3!B:C,2,0) -> 070000174457 | C13: 37787 | D13: =ROUND(C13,0) -> 37787 | E13: 21Feb250007 | F13: ="insert into ins_premium_det (premium_rcv_code,assorted_code, rec_amount,premium_rcv_detail_code,remaining_amt, payrec, mode_code,coinsurance_code,class_cd,it_remarks) values" -> insert into ins_premium_det (premium_rcv_code,assorted_code, rec_amount,premium_rcv_detail_code,remaining_amt, payrec, mode_code,coinsurance_code,class_cd,it_remarks) values | G13: ="('"&E13&"','"&B13&"','"&D13&"',(select max(to_number(i.premium_rcv_detail_code))+1 from ins_premium_det i),'"&D13&"','"&D13&"','02', '11000003','00','Request by Mr.Saqib Saleem 24-Feb-2025');" -> ('21Feb250007','070000174457','37787',(select max(to_number(i.premium_rcv_detail_code))+1 from ins_premium_det i),'37787','37787','02', '11000003','00','Request by Mr.Saqib Saleem 24-Feb-2025'); | H13: =F13&G13 -> insert into ins_premium_det (premium_rcv_code,assorted_code, rec_amount,premium_rcv_detail_code,remaining_amt, payrec, mode_code,coinsurance_code,class_cd,it_remarks) values('21Feb250007','070000174457','37787',(select max(to_number(i.premium_rcv_detail_code))+1 from ins_premium_det i),'37787','37787','02', '11000003','00','Request by Mr.Saqib Saleem 24-Feb-2025');
... A70: KHI/HO/D/MO/PC COMP/C/106707/10/01/2025 | B70: =VLOOKUP(A70,Sheet3!B:C,2,0) -> 070000174920 | C70: 14598 | D70: =ROUND(C70,0) -> 14598 | E70: 21Feb250007 | F70: ="insert into ins_premium_det (premium_rcv_code,assorted_code, rec_amount,premium_rcv_detail_code,remaining_amt, payrec, mode_code,coinsurance_code,class_cd,it_remarks) values" -> insert into ins_premium_det (premium_rcv_code,assorted_code, rec_amount,premium_rcv_detail_code,remaining_amt, payrec, mode_code,coinsurance_code,class_cd,it_remarks) values | G70: ="('"&E70&"','"&B70&"','"&D70&"',(select max(to_number(i.premium_rcv_detail_code))+1 from ins_premium_det i),'"&D70&"','"&D70&"','02', '11000003','00','Request by Mr.Saqib Saleem 24-Feb-2025');" -> ('21Feb250007','070000174920','14598',(select max(to_number(i.premium_rcv_detail_code))+1 from ins_premium_det i),'14598','14598','02', '11000003','00','Request by Mr.Saqib Saleem 24-Feb-2025'); | H70: =F70&G70 -> insert into ins_premium_det (premium_rcv_code,assorted_code, rec_amount,premium_rcv_detail_code,remaining_amt, payrec, mode_code,coinsurance_code,class_cd,it_remarks) values('21Feb250007','070000174920','14598',(select max(to_number(i.premium_rcv_detail_code))+1 from ins_premium_det i),'14598','14598','02', '11000003','00','Request by Mr.Saqib Saleem 24-Feb-2025');
A71: KHI/HO/D/MO/PC COMP/P/104253/12/2024 | B71: 040000192126 | C71: 16490 | D71: =ROUND(C71,0) -> 16490 | E71: 21Feb250007 | F71: ="insert into ins_premium_det (premium_rcv_code,assorted_code, rec_amount,premium_rcv_detail_code,remaining_amt, payrec, mode_code,coinsurance_code,class_cd,it_remarks) values" -> insert into ins_premium_det (premium_rcv_code,assorted_code, rec_amount,premium_rcv_detail_code,remaining_amt, payrec, mode_code,coinsurance_code,class_cd,it_remarks) values | G71: ="('"&E71&"','"&B71&"','"&D71&"',(select max(to_number(i.premium_rcv_detail_code))+1 from ins_premium_det i),'"&D71&"','"&D71&"','02', '11000003','00','Request by Mr.Saqib Saleem 24-Feb-2025');" -> ('21Feb250007','040000192126','16490',(select max(to_number(i.premium_rcv_detail_code))+1 from ins_premium_det i),'16490','16490','02', '11000003','00','Request by Mr.Saqib Saleem 24-Feb-2025'); | H71: =F71&G71 -> insert into ins_premium_det (premium_rcv_code,assorted_code, rec_amount,premium_rcv_detail_code,remaining_amt, payrec, mode_code,coinsurance_code,class_cd,it_remarks) values('21Feb250007','040000192126','16490',(select max(to_number(i.premium_rcv_detail_code))+1 from ins_premium_det i),'16490','16490','02', '11000003','00','Request by Mr.Saqib Saleem 24-Feb-2025');
A72: KHI/HO/D/MO/PC COMP/C/104257/1/12/2024 | B72: =VLOOKUP(A72,Sheet3!B:C,2,0) -> 070000172591 | C72: 67072 | D72: =ROUND(C72,0) -> 67072 | E72: 21Feb250007 | F72: ="insert into ins_premium_det (premium_rcv_code,assorted_code, rec_amount,premium_rcv_detail_code,remaining_amt, payrec, mode_code,coinsurance_code,class_cd,it_remarks) values" -> insert into ins_premium_det (premium_rcv_code,assorted_code, rec_amount,premium_rcv_detail_code,remaining_amt, payrec, mode_code,coinsurance_code,class_cd,it_remarks) values | G72: ="('"&E72&"','"&B72&"','"&D72&"',(select max(to_number(i.premium_rcv_detail_code))+1 from ins_premium_det i),'"&D72&"','"&D72&"','02', '11000003','00','Request by Mr.Saqib Saleem 24-Feb-2025');" -> ('21Feb250007','070000172591','67072',(select max(to_number(i.premium_rcv_detail_code))+1 from ins_premium_det i),'67072','67072','02', '11000003','00','Request by Mr.Saqib Saleem 24-Feb-2025'); | H72: =F72&G72 -> insert into ins_premium_det (premium_rcv_code,assorted_code, rec_amount,premium_rcv_detail_code,remaining_amt, payrec, mode_code,coinsurance_code,class_cd,it_remarks) values('21Feb250007','070000172591','67072',(select max(to_number(i.premium_rcv_detail_code))+1 from ins_premium_det i),'67072','67072','02', '11000003','00','Request by Mr.Saqib Saleem 24-Feb-2025');
A73: KHI/HO/D/MO/PC COMP/C/104257/2/12/2024 | B73: =VLOOKUP(A73,Sheet3!B:C,2,0) -> 070000172593 | C73: 39182 | D73: =ROUND(C73,0) -> 39182 | E73: 21Feb250007 | F73: ="insert into ins_premium_det (premium_rcv_code,assorted_code, rec_amount,premium_rcv_detail_code,remaining_amt, payrec, mode_code,coinsurance_code,class_cd,it_remarks) values" -> insert into ins_premium_det (premium_rcv_code,assorted_code, rec_amount,premium_rcv_detail_code,remaining_amt, payrec, mode_code,coinsurance_code,class_cd,it_remarks) values | G73: ="('"&E73&"','"&B73&"','"&D73&"',(select max(to_number(i.premium_rcv_detail_code))+1 from ins_premium_det i),'"&D73&"','"&D73&"','02', '11000003','00','Request by Mr.Saqib Saleem 24-Feb-2025');" -> ('21Feb250007','070000172593','39182',(select max(to_number(i.premium_rcv_detail_code))+1 from ins_premium_det i),'39182','39182','02', '11000003','00','Request by Mr.Saqib Saleem 24-Feb-2025'); | H73: =F73&G73 -> insert into ins_premium_det (premium_rcv_code,assorted_code, rec_amount,premium_rcv_detail_code,remaining_amt, payrec, mode_code,coinsurance_code,class_cd,it_remarks) values('21Feb250007','070000172593','39182',(select max(to_number(i.premium_rcv_detail_code))+1 from ins_premium_det i),'39182','39182','02', '11000003','00','Request by Mr.Saqib Saleem 24-Feb-2025');
A74: KHI/HO/D/MO/PC COMP/C/104257/3/12/2024 | B74: =VLOOKUP(A74,Sheet3!B:C,2,0) -> 070000172595 | C74: 16731 | D74: =ROUND(C74,0) -> 16731 | E74: 21Feb250007 | F74: ="insert into ins_premium_det (premium_rcv_code,assorted_code, rec_amount,premium_rcv_detail_code,remaining_amt, payrec, mode_code,coinsurance_code,class_cd,it_remarks) values" -> insert into ins_premium_det (premium_rcv_code,assorted_code, rec_amount,premium_rcv_detail_code,remaining_amt, payrec, mode_code,coinsurance_code,class_cd,it_remarks) values | G74: ="('"&E74&"','"&B74&"','"&D74&"',(select max(to_number(i.premium_rcv_detail_code))+1 from ins_premium_det i),'"&D74&"','"&D74&"','02', '11000003','00','Request by Mr.Saqib Saleem 24-Feb-2025');" -> ('21Feb250007','070000172595','16731',(select max(to_number(i.premium_rcv_detail_code))+1 from ins_premium_det i),'16731','16731','02', '11000003','00','Request by Mr.Saqib Saleem 24-Feb-2025'); | H74: =F74&G74 -> insert into ins_premium_det (premium_rcv_code,assorted_code, rec_amount,premium_rcv_detail_code,remaining_amt, payrec, mode_code,coinsurance_code,class_cd,it_remarks) values('21Feb250007','070000172595','16731',(select max(to_number(i.premium_rcv_detail_code))+1 from ins_premium_det i),'16731','16731','02', '11000003','00','Request by Mr.Saqib Saleem 24-Feb-2025');
A75: KHI/HO/D/MO/PC COMP/C/104253/2/12/2024 | B75: =VLOOKUP(A75,Sheet3!B:C,2,0) -> 070000172585 | C75: 14598 | D75: =ROUND(C75,0) -> 14598 | E75: 21Feb250007 | F75: ="insert into ins_premium_det (premium_rcv_code,assorted_code, rec_amount,premium_rcv_detail_code,remaining_amt, payrec, mode_code,coinsurance_code,class_cd,it_remarks) values" -> insert into ins_premium_det (premium_rcv_code,assorted_code, rec_amount,premium_rcv_detail_code,remaining_amt, payrec, mode_code,coinsurance_code,class_cd,it_remarks) values | G75: ="('"&E75&"','"&B75&"','"&D75&"',(select max(to_number(i.premium_rcv_detail_code))+1 from ins_premium_det i),'"&D75&"','"&D75&"','02', '11000003','00','Request by Mr.Saqib Saleem 24-Feb-2025');" -> ('21Feb250007','070000172585','14598',(select max(to_number(i.premium_rcv_detail_code))+1 from ins_premium_det i),'14598','14598','02', '11000003','00','Request by Mr.Saqib Saleem 24-Feb-2025'); | H75: =F75&G75 -> insert into ins_premium_det (premium_rcv_code,assorted_code, rec_amount,premium_rcv_detail_code,remaining_amt, payrec, mode_code,coinsurance_code,class_cd,it_remarks) values('21Feb250007','070000172585','14598',(select max(to_number(i.premium_rcv_detail_code))+1 from ins_premium_det i),'14598','14598','02', '11000003','00','Request by Mr.Saqib Saleem 24-Feb-2025');
A76: KHI/HO/D/MO/PC COMP/C/104253/4/12/2024 | B76: =VLOOKUP(A76,Sheet3!B:C,2,0) -> 070000172589 | C76: 28311 | D76: =ROUND(C76,0) -> 28311 | E76: 21Feb250007 | F76: ="insert into ins_premium_det (premium_rcv_code,assorted_code, rec_amount,premium_rcv_detail_code,remaining_amt, payrec, mode_code,coinsurance_code,class_cd,it_remarks) values" -> insert into ins_premium_det (premium_rcv_code,assorted_code, rec_amount,premium_rcv_detail_code,remaining_amt, payrec, mode_code,coinsurance_code,class_cd,it_remarks) values | G76: ="('"&E76&"','"&B76&"','"&D76&"',(select max(to_number(i.premium_rcv_detail_code))+1 from ins_premium_det i),'"&D76&"','"&D76&"','02', '11000003','00','Request by Mr.Saqib Saleem 24-Feb-2025');" -> ('21Feb250007','070000172589','28311',(select max(to_number(i.premium_rcv_detail_code))+1 from ins_premium_det i),'28311','28311','02', '11000003','00','Request by Mr.Saqib Saleem 24-Feb-2025'); | H76: =F76&G76 -> insert into ins_premium_det (premium_rcv_code,assorted_code, rec_amount,premium_rcv_detail_code,remaining_amt, payrec, mode_code,coinsurance_code,class_cd,it_remarks) values('21Feb250007','070000172589','28311',(select max(to_number(i.premium_rcv_detail_code))+1 from ins_premium_det i),'28311','28311','02', '11000003','00','Request by Mr.Saqib Saleem 24-Feb-2025');
A77: KHI/HO/D/MO/PC COMP/C/104253/3/12/2024 | B77: =VLOOKUP(A77,Sheet3!B:C,2,0) -> 070000172586 | C77: 22712 | D77: =ROUND(C77,0) -> 22712 | E77: 21Feb250007 | F77: ="insert into ins_premium_det (premium_rcv_code,assorted_code, rec_amount,premium_rcv_detail_code,remaining_amt, payrec, mode_code,coinsurance_code,class_cd,it_remarks) values" -> insert into ins_premium_det (premium_rcv_code,assorted_code, rec_amount,premium_rcv_detail_code,remaining_amt, payrec, mode_code,coinsurance_code,class_cd,it_remarks) values | G77: ="('"&E77&"','"&B77&"','"&D77&"',(select max(to_number(i.premium_rcv_detail_code))+1 from ins_premium_det i),'"&D77&"','"&D77&"','02', '11000003','00','Request by Mr.Saqib Saleem 24-Feb-2025');" -> ('21Feb250007','070000172586','22712',(select max(to_number(i.premium_rcv_detail_code))+1 from ins_premium_det i),'22712','22712','02', '11000003','00','Request by Mr.Saqib Saleem 24-Feb-2025'); | H77: =F77&G77 -> insert into ins_premium_det (premium_rcv_code,assorted_code, rec_amount,premium_rcv_detail_code,remaining_amt, payrec, mode_code,coinsurance_code,class_cd,it_remarks) values('21Feb250007','070000172586','22712',(select max(to_number(i.premium_rcv_detail_code))+1 from ins_premium_det i),'22712','22712','02', '11000003','00','Request by Mr.Saqib Saleem 24-Feb-2025');
A78: KHI/HO/D/MO/PC COMP/C/106712/5/01/2025 | B78: =VLOOKUP(A78,Sheet3!B:C,2,0) -> 070000174936 | C78: 25758 | D78: =ROUND(C78,0) -> 25758 | E78: 21Feb250007 | F78: ="insert into ins_premium_det (premium_rcv_code,assorted_code, rec_amount,premium_rcv_detail_code,remaining_amt, payrec, mode_code,coinsurance_code,class_cd,it_remarks) values" -> insert into ins_premium_det (premium_rcv_code,assorted_code, rec_amount,premium_rcv_detail_code,remaining_amt, payrec, mode_code,coinsurance_code,class_cd,it_remarks) values | G78: ="('"&E78&"','"&B78&"','"&D78&"',(select max(to_number(i.premium_rcv_detail_code))+1 from ins_premium_det i),'"&D78&"','"&D78&"','02', '11000003','00','Request by Mr.Saqib Saleem 24-Feb-2025');" -> ('21Feb250007','070000174936','25758',(select max(to_number(i.premium_rcv_detail_code))+1 from ins_premium_det i),'25758','25758','02', '11000003','00','Request by Mr.Saqib Saleem 24-Feb-2025'); | H78: =F78&G78 -> insert into ins_premium_det (premium_rcv_code,assorted_code, rec_amount,premium_rcv_detail_code,remaining_amt, payrec, mode_code,coinsurance_code,class_cd,it_remarks) values('21Feb250007','070000174936','25758',(select max(to_number(i.premium_rcv_detail_code))+1 from ins_premium_det i),'25758','25758','02', '11000003','00','Request by Mr.Saqib Saleem 24-Feb-2025');
A79: KHI/HO/D/MO/PC COMP/C/106712/1/01/2025 | B79: =VLOOKUP(A79,Sheet3!B:C,2,0) -> 070000174932 | C79: 17921 | D79: =ROUND(C79,0) -> 17921 | E79: 21Feb250007 | F79: ="insert into ins_premium_det (premium_rcv_code,assorted_code, rec_amount,premium_rcv_detail_code,remaining_amt, payrec, mode_code,coinsurance_code,class_cd,it_remarks) values" -> insert into ins_premium_det (premium_rcv_code,assorted_code, rec_amount,premium_rcv_detail_code,remaining_amt, payrec, mode_code,coinsurance_code,class_cd,it_remarks) values | G79: ="('"&E79&"','"&B79&"','"&D79&"',(select max(to_number(i.premium_rcv_detail_code))+1 from ins_premium_det i),'"&D79&"','"&D79&"','02', '11000003','00','Request by Mr.Saqib Saleem 24-Feb-2025');" -> ('21Feb250007','070000174932','17921',(select max(to_number(i.premium_rcv_detail_code))+1 from ins_premium_det i),'17921','17921','02', '11000003','00','Request by Mr.Saqib Saleem 24-Feb-2025'); | H79: =F79&G79 -> insert into ins_premium_det (premium_rcv_code,assorted_code, rec_amount,premium_rcv_detail_code,remaining_amt, payrec, mode_code,coinsurance_code,class_cd,it_remarks) values('21Feb250007','070000174932','17921',(select max(to_number(i.premium_rcv_detail_code))+1 from ins_premium_det i),'17921','17921','02', '11000003','00','Request by Mr.Saqib Saleem 24-Feb-2025');
A80: KHI/HO/D/MO/PC COMP/C/106712/3/01/2025 | B80: =VLOOKUP(A80,Sheet3!B:C,2,0) -> 070000174934 | C80: 31153 | D80: =ROUND(C80,0) -> 31153 | E80: 21Feb250007 | F80: ="insert into ins_premium_det (premium_rcv_code,assorted_code, rec_amount,premium_rcv_detail_code,remaining_amt, payrec, mode_code,coinsurance_code,class_cd,it_remarks) values" -> insert into ins_premium_det (premium_rcv_code,assorted_code, rec_amount,premium_rcv_detail_code,remaining_amt, payrec, mode_code,coinsurance_code,class_cd,it_remarks) values | G80: ="('"&E80&"','"&B80&"','"&D80&"',(select max(to_number(i.premium_rcv_detail_code))+1 from ins_premium_det i),'"&D80&"','"&D80&"','02', '11000003','00','Request by Mr.Saqib Saleem 24-Feb-2025');" -> ('21Feb250007','070000174934','31153',(select max(to_number(i.premium_rcv_detail_code))+1 from ins_premium_det i),'31153','31153','02', '11000003','00','Request by Mr.Saqib Saleem 24-Feb-2025'); | H80: =F80&G80 -> insert into ins_premium_det (premium_rcv_code,assorted_code, rec_amount,premium_rcv_detail_code,remaining_amt, payrec, mode_code,coinsurance_code,class_cd,it_remarks) values('21Feb250007','070000174934','31153',(select max(to_number(i.premium_rcv_detail_code))+1 from ins_premium_det i),'31153','31153','02', '11000003','00','Request by Mr.Saqib Saleem 24-Feb-2025');
A81: KHI/HO/D/MO/PC COMP/C/106712/7/01/2025 | B81: =VLOOKUP(A81,Sheet3!B:C,2,0) -> 070000174938 | C81: 42525 | D81: =ROUND(C81,0) -> 42525 | E81: 21Feb250007 | F81: ="insert into ins_premium_det (premium_rcv_code,assorted_code, rec_amount,premium_rcv_detail_code,remaining_amt, payrec, mode_code,coinsurance_code,class_cd,it_remarks) values" -> insert into ins_premium_det (premium_rcv_code,assorted_code, rec_amount,premium_rcv_detail_code,remaining_amt, payrec, mode_code,coinsurance_code,class_cd,it_remarks) values | G81: ="('"&E81&"','"&B81&"','"&D81&"',(select max(to_number(i.premium_rcv_detail_code))+1 from ins_premium_det i),'"&D81&"','"&D81&"','02', '11000003','00','Request by Mr.Saqib Saleem 24-Feb-2025');" -> ('21Feb250007','070000174938','42525',(select max(to_number(i.premium_rcv_detail_code))+1 from ins_premium_det i),'42525','42525','02', '11000003','00','Request by Mr.Saqib Saleem 24-Feb-2025'); | H81: =F81&G81 -> insert into ins_premium_det (premium_rcv_code,assorted_code, rec_amount,premium_rcv_detail_code,remaining_amt, payrec, mode_code,coinsurance_code,class_cd,it_remarks) values('21Feb250007','070000174938','42525',(select max(to_number(i.premium_rcv_detail_code))+1 from ins_premium_det i),'42525','42525','02', '11000003','00','Request by Mr.Saqib Saleem 24-Feb-2025');
A82: KHI/HO/D/MO/PC COMP/C/106712/6/01/2025 | B82: =VLOOKUP(A82,Sheet3!B:C,2,0) -> 070000174937 | C82: 61345 | D82: =ROUND(C82,0) -> 61345 | E82: 21Feb250007 | F82: ="insert into ins_premium_det (premium_rcv_code,assorted_code, rec_amount,premium_rcv_detail_code,remaining_amt, payrec, mode_code,coinsurance_code,class_cd,it_remarks) values" -> insert into ins_premium_det (premium_rcv_code,assorted_code, rec_amount,premium_rcv_detail_code,remaining_amt, payrec, mode_code,coinsurance_code,class_cd,it_remarks) values | G82: ="('"&E82&"','"&B82&"','"&D82&"',(select max(to_number(i.premium_rcv_detail_code))+1 from ins_premium_det i),'"&D82&"','"&D82&"','02', '11000003','00','Request by Mr.Saqib Saleem 24-Feb-2025');" -> ('21Feb250007','070000174937','61345',(select max(to_number(i.premium_rcv_detail_code))+1 from ins_premium_det i),'61345','61345','02', '11000003','00','Request by Mr.Saqib Saleem 24-Feb-2025'); | H82: =F82&G82 -> insert into ins_premium_det (premium_rcv_code,assorted_code, rec_amount,premium_rcv_detail_code,remaining_amt, payrec, mode_code,coinsurance_code,class_cd,it_remarks) values('21Feb250007','070000174937','61345',(select max(to_number(i.premium_rcv_detail_code))+1 from ins_premium_det i),'61345','61345','02', '11000003','00','Request by Mr.Saqib Saleem 24-Feb-2025');
A83: KHI/HO/D/MO/PC COMP/C/106712/2/01/2025 | B83: =VLOOKUP(A83,Sheet3!B:C,2,0) -> 070000174933 | C83: 39293 | D83: =ROUND(C83,0) -> 39293 | E83: 21Feb250007 | F83: ="insert into ins_premium_det (premium_rcv_code,assorted_code, rec_amount,premium_rcv_detail_code,remaining_amt, payrec, mode_code,coinsurance_code,class_cd,it_remarks) values" -> insert into ins_premium_det (premium_rcv_code,assorted_code, rec_amount,premium_rcv_detail_code,remaining_amt, payrec, mode_code,coinsurance_code,class_cd,it_remarks) values | G83: ="('"&E83&"','"&B83&"','"&D83&"',(select max(to_number(i.premium_rcv_detail_code))+1 from ins_premium_det i),'"&D83&"','"&D83&"','02', '11000003','00','Request by Mr.Saqib Saleem 24-Feb-2025');" -> ('21Feb250007','070000174933','39293',(select max(to_number(i.premium_rcv_detail_code))+1 from ins_premium_det i),'39293','39293','02', '11000003','00','Request by Mr.Saqib Saleem 24-Feb-2025'); | H83: =F83&G83 -> insert into ins_premium_det (premium_rcv_code,assorted_code, rec_amount,premium_rcv_detail_code,remaining_amt, payrec, mode_code,coinsurance_code,class_cd,it_remarks) values('21Feb250007','070000174933','39293',(select max(to_number(i.premium_rcv_detail_code))+1 from ins_premium_det i),'39293','39293','02', '11000003','00','Request by Mr.Saqib Saleem 24-Feb-2025');
... A87: KHI/HO/D/MO/PC COMP/C/104265/5/12/2024 | B87: =VLOOKUP(A87,Sheet3!B:C,2,0) -> 070000172605 | C87: 21056 | D87: =ROUND(C87,0) -> 21056 | E87: 21Feb250007 | F87: ="insert into ins_premium_det (premium_rcv_code,assorted_code, rec_amount,premium_rcv_detail_code,remaining_amt, payrec, mode_code,coinsurance_code,class_cd,it_remarks) values" -> insert into ins_premium_det (premium_rcv_code,assorted_code, rec_amount,premium_rcv_detail_code,remaining_amt, payrec, mode_code,coinsurance_code,class_cd,it_remarks) values | G87: ="('"&E87&"','"&B87&"','"&D87&"',(select max(to_number(i.premium_rcv_detail_code))+1 from ins_premium_det i),'"&D87&"','"&D87&"','02', '11000003','00','Request by Mr.Saqib Saleem 24-Feb-2025');" -> ('21Feb250007','070000172605','21056',(select max(to_number(i.premium_rcv_detail_code))+1 from ins_premium_det i),'21056','21056','02', '11000003','00','Request by Mr.Saqib Saleem 24-Feb-2025'); | H87: =F87&G87 -> insert into ins_premium_det (premium_rcv_code,assorted_code, rec_amount,premium_rcv_detail_code,remaining_amt, payrec, mode_code,coinsurance_code,class_cd,it_remarks) values('21Feb250007','070000172605','21056',(select max(to_number(i.premium_rcv_detail_code))+1 from ins_premium_det i),'21056','21056','02', '11000003','00','Request by Mr.Saqib Saleem 24-Feb-2025');
A88: KHI/HO/D/MO/PC COMP/P/104265/12/2024 | B88: 040000192139 | C88: 61539 | D88: =ROUND(C88,0) -> 61539 | E88: 21Feb250007 | F88: ="insert into ins_premium_det (premium_rcv_code,assorted_code, rec_amount,premium_rcv_detail_code,remaining_amt, payrec, mode_code,coinsurance_code,class_cd,it_remarks) values" -> insert into ins_premium_det (premium_rcv_code,assorted_code, rec_amount,premium_rcv_detail_code,remaining_amt, payrec, mode_code,coinsurance_code,class_cd,it_remarks) values | G88: ="('"&E88&"','"&B88&"','"&D88&"',(select max(to_number(i.premium_rcv_detail_code))+1 from ins_premium_det i),'"&D88&"','"&D88&"','02', '11000003','00','Request by Mr.Saqib Saleem 24-Feb-2025');" -> ('21Feb250007','040000192139','61539',(select max(to_number(i.premium_rcv_detail_code))+1 from ins_premium_det i),'61539','61539','02', '11000003','00','Request by Mr.Saqib Saleem 24-Feb-2025'); | H88: =F88&G88 -> insert into ins_premium_det (premium_rcv_code,assorted_code, rec_amount,premium_rcv_detail_code,remaining_amt, payrec, mode_code,coinsurance_code,class_cd,it_remarks) values('21Feb250007','040000192139','61539',(select max(to_number(i.premium_rcv_detail_code))+1 from ins_premium_det i),'61539','61539','02', '11000003','00','Request by Mr.Saqib Saleem 24-Feb-2025');
A89: KHI/HO/D/MO/PC COMP/C/106719/3/01/2025 | B89: =VLOOKUP(A89,Sheet3!B:C,2,0) -> 070000174951 | C89: 39293 | D89: =ROUND(C89,0) -> 39293 | E89: 21Feb250007 | F89: ="insert into ins_premium_det (premium_rcv_code,assorted_code, rec_amount,premium_rcv_detail_code,remaining_amt, payrec, mode_code,coinsurance_code,class_cd,it_remarks) values" -> insert into ins_premium_det (premium_rcv_code,assorted_code, rec_amount,premium_rcv_detail_code,remaining_amt, payrec, mode_code,coinsurance_code,class_cd,it_remarks) values | G89: ="('"&E89&"','"&B89&"','"&D89&"',(select max(to_number(i.premium_rcv_detail_code))+1 from ins_premium_det i),'"&D89&"','"&D89&"','02', '11000003','00','Request by Mr.Saqib Saleem 24-Feb-2025');" -> ('21Feb250007','070000174951','39293',(select max(to_number(i.premium_rcv_detail_code))+1 from ins_premium_det i),'39293','39293','02', '11000003','00','Request by Mr.Saqib Saleem 24-Feb-2025'); | H89: =F89&G89 -> insert into ins_premium_det (premium_rcv_code,assorted_code, rec_amount,premium_rcv_detail_code,remaining_amt, payrec, mode_code,coinsurance_code,class_cd,it_remarks) values('21Feb250007','070000174951','39293',(select max(to_number(i.premium_rcv_detail_code))+1 from ins_premium_det i),'39293','39293','02', '11000003','00','Request by Mr.Saqib Saleem 24-Feb-2025');
A90: KHI/HO/D/MO/PC COMP/C/106719/1/01/2025 | B90: =VLOOKUP(A90,Sheet3!B:C,2,0) -> 070000174949 | C90: 17921 | D90: =ROUND(C90,0) -> 17921 | E90: 21Feb250007 | F90: ="insert into ins_premium_det (premium_rcv_code,assorted_code, rec_amount,premium_rcv_detail_code,remaining_amt, payrec, mode_code,coinsurance_code,class_cd,it_remarks) values" -> insert into ins_premium_det (premium_rcv_code,assorted_code, rec_amount,premium_rcv_detail_code,remaining_amt, payrec, mode_code,coinsurance_code,class_cd,it_remarks) values | G90: ="('"&E90&"','"&B90&"','"&D90&"',(select max(to_number(i.premium_rcv_detail_code))+1 from ins_premium_det i),'"&D90&"','"&D90&"','02', '11000003','00','Request by Mr.Saqib Saleem 24-Feb-2025');" -> ('21Feb250007','070000174949','17921',(select max(to_number(i.premium_rcv_detail_code))+1 from ins_premium_det i),'17921','17921','02', '11000003','00','Request by Mr.Saqib Saleem 24-Feb-2025'); | H90: =F90&G90 -> insert into ins_premium_det (premium_rcv_code,assorted_code, rec_amount,premium_rcv_detail_code,remaining_amt, payrec, mode_code,coinsurance_code,class_cd,it_remarks) values('21Feb250007','070000174949','17921',(select max(to_number(i.premium_rcv_detail_code))+1 from ins_premium_det i),'17921','17921','02', '11000003','00','Request by Mr.Saqib Saleem 24-Feb-2025');
A91: KHI/HO/D/MO/PC COMP/C/106719/2/01/2025 | B91: =VLOOKUP(A91,Sheet3!B:C,2,0) -> 070000174950 | C91: 21870 | D91: =ROUND(C91,0) -> 21870 | E91: 21Feb250007 | F91: ="insert into ins_premium_det (premium_rcv_code,assorted_code, rec_amount,premium_rcv_detail_code,remaining_amt, payrec, mode_code,coinsurance_code,class_cd,it_remarks) values" -> insert into ins_premium_det (premium_rcv_code,assorted_code, rec_amount,premium_rcv_detail_code,remaining_amt, payrec, mode_code,coinsurance_code,class_cd,it_remarks) values | G91: ="('"&E91&"','"&B91&"','"&D91&"',(select max(to_number(i.premium_rcv_detail_code))+1 from ins_premium_det i),'"&D91&"','"&D91&"','02', '11000003','00','Request by Mr.Saqib Saleem 24-Feb-2025');" -> ('21Feb250007','070000174950','21870',(select max(to_number(i.premium_rcv_detail_code))+1 from ins_premium_det i),'21870','21870','02', '11000003','00','Request by Mr.Saqib Saleem 24-Feb-2025'); | H91: =F91&G91 -> insert into ins_premium_det (premium_rcv_code,assorted_code, rec_amount,premium_rcv_detail_code,remaining_amt, payrec, mode_code,coinsurance_code,class_cd,it_remarks) values('21Feb250007','070000174950','21870',(select max(to_number(i.premium_rcv_detail_code))+1 from ins_premium_det i),'21870','21870','02', '11000003','00','Request by Mr.Saqib Saleem 24-Feb-2025');
A92: KHI/HO/D/MO/PC COMP/C/106720/1/01/2025 | B92: =VLOOKUP(A92,Sheet3!B:C,2,0) -> 070000174946 | C92: 39623 | D92: =ROUND(C92,0) -> 39623 | E92: 21Feb250007 | F92: ="insert into ins_premium_det (premium_rcv_code,assorted_code, rec_amount,premium_rcv_detail_code,remaining_amt, payrec, mode_code,coinsurance_code,class_cd,it_remarks) values" -> insert into ins_premium_det (premium_rcv_code,assorted_code, rec_amount,premium_rcv_detail_code,remaining_amt, payrec, mode_code,coinsurance_code,class_cd,it_remarks) values | G92: ="('"&E92&"','"&B92&"','"&D92&"',(select max(to_number(i.premium_rcv_detail_code))+1 from ins_premium_det i),'"&D92&"','"&D92&"','02', '11000003','00','Request by Mr.Saqib Saleem 24-Feb-2025');" -> ('21Feb250007','070000174946','39623',(select max(to_number(i.premium_rcv_detail_code))+1 from ins_premium_det i),'39623','39623','02', '11000003','00','Request by Mr.Saqib Saleem 24-Feb-2025'); | H92: =F92&G92 -> insert into ins_premium_det (premium_rcv_code,assorted_code, rec_amount,premium_rcv_detail_code,remaining_amt, payrec, mode_code,coinsurance_code,class_cd,it_remarks) values('21Feb250007','070000174946','39623',(select max(to_number(i.premium_rcv_detail_code))+1 from ins_premium_det i),'39623','39623','02', '11000003','00','Request by Mr.Saqib Saleem 24-Feb-2025');
A93: KHI/HO/D/MO/PC COMP/C/106720/3/01/2025 | B93: =VLOOKUP(A93,Sheet3!B:C,2,0) -> 070000174948 | C93: 67500 | D93: =ROUND(C93,0) -> 67500 | E93: 21Feb250007 | F93: ="insert into ins_premium_det (premium_rcv_code,assorted_code, rec_amount,premium_rcv_detail_code,remaining_amt, payrec, mode_code,coinsurance_code,class_cd,it_remarks) values" -> insert into ins_premium_det (premium_rcv_code,assorted_code, rec_amount,premium_rcv_detail_code,remaining_amt, payrec, mode_code,coinsurance_code,class_cd,it_remarks) values | G93: ="('"&E93&"','"&B93&"','"&D93&"',(select max(to_number(i.premium_rcv_detail_code))+1 from ins_premium_det i),'"&D93&"','"&D93&"','02', '11000003','00','Request by Mr.Saqib Saleem 24-Feb-2025');" -> ('21Feb250007','070000174948','67500',(select max(to_number(i.premium_rcv_detail_code))+1 from ins_premium_det i),'67500','67500','02', '11000003','00','Request by Mr.Saqib Saleem 24-Feb-2025'); | H93: =F93&G93 -> insert into ins_premium_det (premium_rcv_code,assorted_code, rec_amount,premium_rcv_detail_code,remaining_amt, payrec, mode_code,coinsurance_code,class_cd,it_remarks) values('21Feb250007','070000174948','67500',(select max(to_number(i.premium_rcv_detail_code))+1 from ins_premium_det i),'67500','67500','02', '11000003','00','Request by Mr.Saqib Saleem 24-Feb-2025');
A94: KHI/HO/D/MO/PC COMP/C/106720/2/01/2025 | B94: =VLOOKUP(A94,Sheet3!B:C,2,0) -> 070000174947 | C94: 39623 | D94: =ROUND(C94,0) -> 39623 | E94: 21Feb250007 | F94: ="insert into ins_premium_det (premium_rcv_code,assorted_code, rec_amount,premium_rcv_detail_code,remaining_amt, payrec, mode_code,coinsurance_code,class_cd,it_remarks) values" -> insert into ins_premium_det (premium_rcv_code,assorted_code, rec_amount,premium_rcv_detail_code,remaining_amt, payrec, mode_code,coinsurance_code,class_cd,it_remarks) values | G94: ="('"&E94&"','"&B94&"','"&D94&"',(select max(to_number(i.premium_rcv_detail_code))+1 from ins_premium_det i),'"&D94&"','"&D94&"','02', '11000003','00','Request by Mr.Saqib Saleem 24-Feb-2025');" -> ('21Feb250007','070000174947','39623',(select max(to_number(i.premium_rcv_detail_code))+1 from ins_premium_det i),'39623','39623','02', '11000003','00','Request by Mr.Saqib Saleem 24-Feb-2025'); | H94: =F94&G94 -> insert into ins_premium_det (premium_rcv_code,assorted_code, rec_amount,premium_rcv_detail_code,remaining_amt, payrec, mode_code,coinsurance_code,class_cd,it_remarks) values('21Feb250007','070000174947','39623',(select max(to_number(i.premium_rcv_detail_code))+1 from ins_premium_det i),'39623','39623','02', '11000003','00','Request by Mr.Saqib Saleem 24-Feb-2025');
A95: KHI/HO/D/MO/PC COMP/C/104283/7/12/2024 | B95: =VLOOKUP(A95,Sheet3!B:C,2,0) -> 070000172641 | C95: 27009 | D95: =ROUND(C95,0) -> 27009 | E95: 21Feb250007 | F95: ="insert into ins_premium_det (premium_rcv_code,assorted_code, rec_amount,premium_rcv_detail_code,remaining_amt, payrec, mode_code,coinsurance_code,class_cd,it_remarks) values" -> insert into ins_premium_det (premium_rcv_code,assorted_code, rec_amount,premium_rcv_detail_code,remaining_amt, payrec, mode_code,coinsurance_code,class_cd,it_remarks) values | G95: ="('"&E95&"','"&B95&"','"&D95&"',(select max(to_number(i.premium_rcv_detail_code))+1 from ins_premium_det i),'"&D95&"','"&D95&"','02', '11000003','00','Request by Mr.Saqib Saleem 24-Feb-2025');" -> ('21Feb250007','070000172641','27009',(select max(to_number(i.premium_rcv_detail_code))+1 from ins_premium_det i),'27009','27009','02', '11000003','00','Request by Mr.Saqib Saleem 24-Feb-2025'); | H95: =F95&G95 -> insert into ins_premium_det (premium_rcv_code,assorted_code, rec_amount,premium_rcv_detail_code,remaining_amt, payrec, mode_code,coinsurance_code,class_cd,it_remarks) values('21Feb250007','070000172641','27009',(select max(to_number(i.premium_rcv_detail_code))+1 from ins_premium_det i),'27009','27009','02', '11000003','00','Request by Mr.Saqib Saleem 24-Feb-2025');
