Workbook

Sheet Fresh
A3: Fresh / Renewal | B3: Billing Month | C3: Takaful Company | D3: PMD # | E3: TRACKER_TYPE | F3: Start Date | G3: Expiry Date | H3: Make | I3: Model | J3: REGISTRATION_NUMBER | K3: ENGINE_NUMBER | L3: CHASIS_NUMBER | M3: Customer Name | N3: CNIC | O3: CIF+Deal+BR | P3: BRANCH_CODE | Q3: CLASS | R3: DEAL_DATE | S3: MATURITY_DATE | T3: New Sum cover | U3: Rate | V3: Gross Amount | W3: Tracker Amount | X3: Net Premium Amount | Y3: Remarks | Z3: DEAL_STATUS | AA3: Product_Detail | AB3: Payment Date | AC3: Policy # | AD3: Tms prem | AE3: Difference
A4: Fresh | B4: 45620 | C4: Salaam Takaful | D4: KHI/HO/D/MO/PC COMP/C/101132/1/11/2024 | E4: ResQ | F4: 45597 | G4: 45962 | H4: SUZUKI ALTO VXR | I4: 2024 | J4: BEV-599 | K4: 6R322766 | L4: NF1AET306H1222862 | M4: Mr. Sajjad Ahmed | N4: 1310134315439 | O4: 298847-385-3054 | P4: 3054 | Q4: 464 | R4: 45601 | S4: 47416 | T4: 2707000 | U4: 0.0199 | V4: 53869.3 | W4: 0 | X4: 53869 | Y4: Ready to pay | Z4: APPROVED | AA4: Consumer | AB4: 45625 | AC4: KHI/HO/D/MO/PC COMP/C/101132/1/11/2024 | AD4: 53869 | AE4: =X4-AD4 -> 0
A5: Fresh | B5: 45620 | C5: Salaam Takaful | D5: KHI/HO/D/MO/PC COMP/C/101132/2/11/2024 | E5: - | F5: 45600 | G5: 45965 | H5: TOYOTA COROLLA | I5: 2020 | J5: BTE-753 | K5: Q065312 | L5: ZRE171R-6042820 | M5: Mr. Syed Perwaiz Asdaque | N5: 4210101987831 | O5: 5671463-264-1024 | P5: 1024 | Q5: 464 | R5: 45608 | S5: 46696 | T5: 4760000 | U5: 0.0199 | V5: 94724 | W5: 0 | X5: 94724 | Y5: Ready to pay | Z5: APPROVED | AA5: Consumer | AB5: 45625 | AC5: KHI/HO/D/MO/PC COMP/C/101132/2/11/2024 | AD5: 94724 | AE5: =X5-AD5 -> 0
A6: Fresh | B6: 45620 | C6: Salaam Takaful | D6: KHI/HO/D/MO/PC COMP/C/101132/3/11/2024 | E6: Falcon-I | F6: 45600 | G6: 45965 | H6: SUZUKI CULTUS | I6: 2021 | J6: BUF-405 | K6: PK10K180948 | L6: NF1AVK31H10080975 | M6: Mr. Farzeen Rizvi | N6: 4210182245268 | O6: 5652470-4-1195 | P6: 1195 | Q6: 450 | R6: 45602 | S6: 47427 | T6: 3200000 | U6: 0.0199 | V6: 63680 | W6: 0 | X6: 63680 | Y6: Ready to pay | Z6: APPROVED | AA6: Consumer | AB6: 45625 | AC6: KHI/HO/D/MO/PC COMP/C/101132/3/11/2024 | AD6: 63680 | AE6: =X6-AD6 -> 0
A7: Fresh | B7: 45620 | C7: Salaam Takaful | D7: KHI/HO/D/MO/PC COMP/C/101132/4/11/2024 | E7: - | F7: 45601 | G7: 45966 | H7: TOYOTA CROSS HYBRID CVT | I7: 2024 | J7: BM-7081 | K7: 9Z06130 | L7: ZVG10R-0905068 | M7: M/s Noorani Commission Agent | N7: 5440133393709 | O7: 95324-34-1070 | P7: 1070 | Q7: 572 | R7: 45607 | S7: 46696 | T7: 9862000 | U7: 0.015 | V7: 147930 | W7: 0 | X7: 147930 | Y7: Ready to pay | Z7: APPROVED | AA7: Consumer | AB7: 45625 | AC7: KHI/HO/D/MO/PC COMP/C/101132/4/11/2024 | AD7: 147930 | AE7: =X7-AD7 -> 0
A8: Fresh | B8: 45620 | C8: Salaam Takaful | D8: KHI/HO/D/MO/PC COMP/C/101132/5/11/2024 | E8: - | F8: 45617 | G8: 45982 | H8: CHANGAN OSHAN X7 COMFORT | I8: 2024 | J8: FW-62 | K8: JL473ZQ7RN8AT258387 | L8: NKMASE2E9R1000928 | M8: M/s. MUGHAL COMPUTERS & WOOFER CENTER | N8: 3120319798807 | O8: 1850220-3-2166 | P8: 2166 | Q8: 572 | R8: 45617 | S8: 47437 | T8: 8899000 | U8: 0.015 | V8: 133485 | W8: 0 | X8: 133485 | Y8: Ready to pay | Z8: APPROVED | AA8: Consumer | AB8: 45625 | AC8: KHI/HO/D/MO/PC COMP/C/101132/5/11/2024 | AD8: 133485 | AE8: =X8-AD8 -> 0
A9: Fresh | B9: 45620 | C9: Salaam Takaful | D9: KHI/HO/D/MO/PC COMP/C/101132/6/11/2024 | E9: - | F9: 45617 | G9: 45982 | H9: SUZUKI ALTO AGS A/T | I9: 2024 | J9: BEX-290 | K9: 6R327254 | L9: NF1AET306H1227207 | M9: Mrs. Sadia Ijaz | N9: 3740629336546 | O9: 5553152-96-3008 | P9: 3008 | Q9: 464 | R9: 45618 | S9: 47082 | T9: 3045000 | U9: 0.0199 | V9: 60595.5 | W9: 0 | X9: 60596 | Y9: Ready to pay | Z9: APPROVED | AA9: Consumer | AB9: 45625 | AC9: KHI/HO/D/MO/PC COMP/C/101132/6/11/2024 | AD9: 60596 | AE9: =X9-AD9 -> 0
A10: Fresh | B10: 45595 | C10: Salaam Takaful | D10: KHI/HO/D/MO/PC COMP/C/100345/8/10/2024 | E10: - | F10: 45594 | G10: 45959 | H10: SUZUKI ALTO VXR | I10: 2024 | J10: BEU-205 | K10: 6R324185 | L10: NF1AET306H1224032 | M10: ABDUL RAZZAQ | N10: 3740551859283 | O10: 5500309-384-3054 | P10: 3054 | Q10: 464 | R10: 45595 | S10: 47416 | T10: 2707000 | U10: 0.0199 | V10: 53869.3 | W10: 0 | X10: 53869 | Y10: Ready to pay | Z10: APPROVED | AA10: Consumer | AB10: 45625 | AC10: KHI/HO/D/MO/PC COMP/C/100345/8/10/2024 | AD10: =VLOOKUP(AC10,'[1]Master Sheet'!$B$3:$Y$11580,24,0) -> 53869 | AE10: =X10-AD10 -> 0
A11: Fresh | B11: 45595 | C11: Salaam Takaful | D11: KHI/HO/D/MO/PC COMP/C/100345/4/10/2024 | E11: - | F11: 45590 | G11: 45955 | H11: HONDA CITY | I11: 2020 | J11: BSA-132 | K11: L15A79799136 | L11: NFBGM2669LR261874 | M11: CURE 9 PHARMA | N11: 4220174910147 | O11: 1292938-175-1068 | P11: 1068 | Q11: 573 | R11: 45595 | S11: 47416 | T11: 3900000 | U11: 0.015 | V11: 58500 | W11: 0 | X11: 58500 | Y11: Ready to pay | Z11: APPROVED | AA11: Consumer | AB11: 45625 | AC11: KHI/HO/D/MO/PC COMP/C/100345/4/10/2024 | AD11: =VLOOKUP(AC11,'[1]Master Sheet'!$B$3:$Y$11580,24,0) -> 58500 | AE11: =X11-AD11 -> 0
A12: Fresh | B12: 45595 | C12: Salaam Takaful | D12: KHI/HO/D/MO/PC COMP/C/100345/5/10/2024 | E12: - | F12: 45590 | G12: 45955 | H12: TOYOTA COROLLA | I12: 2021 | J12: AEV-365 | K12: Q352524 | L12: ZRE172R7051792 | M12: MUHAMMAD UMAIR MAHMO | N12: 3650228635515 | O12: 1610694-66-2097 | P12: 2097 | Q12: 464 | R12: 45594 | S12: 46685 | T12: 4835000 | U12: 0.0199 | V12: 96216.5 | W12: 0 | X12: 96217 | Y12: Ready to pay | Z12: APPROVED | AA12: Consumer | AB12: 45625 | AC12: KHI/HO/D/MO/PC COMP/C/100345/5/10/2024 | AD12: =VLOOKUP(AC12,'[1]Master Sheet'!$B$3:$Y$11580,24,0) -> 96217 | AE12: =X12-AD12 -> 0
A13: Fresh | B13: 45595 | C13: Salaam Takaful | D13: KHI/HO/D/MO/PC COMP/C/100345/6/10/2024 | E13: - | F13: 45593 | G13: 45958 | H13: HAVAL H6 TURBO SUV | I13: 2024 | J13: BEU-219 | K13: 24431516181 | L13: NF9EFUA56R2010034 | M13: JIMI TECHNOLOGIES | N13: 120107 | O13: 64854-286-2072 | P13: 2072 | Q13: 572 | R13: 45594 | S13: 46696 | T13: 11907490 | U13: 0.015 | V13: 178612.35 | W13: 0 | X13: 178612 | Y13: Ready to pay | Z13: APPROVED | AA13: Consumer | AB13: 45625 | AC13: KHI/HO/D/MO/PC COMP/C/100345/6/10/2024 | AD13: =VLOOKUP(AC13,'[1]Master Sheet'!$B$3:$Y$11580,24,0) -> 178612 | AE13: =X13-AD13 -> 0
A14: Fresh | B14: 45595 | C14: Salaam Takaful | D14: KHI/HO/D/MO/PC COMP/C/100345/2/10/2024 | E14: - | F14: 45589 | G14: 45954 | H14: TOYOTA HILUX REVO GR S | I14: 2024 | J14: WX-48 | K14: 1GD1648799 | L14: GUN126R5566124 | M14: ALPA EGGS(PRIVATE) L | N14: 129858 | O14: 6500573-123-2098 | P14: 2098 | Q14: 573 | R14: 45593 | S14: 45955 | T14: 15451000 | U14: 0.015 | V14: 231765 | W14: 0 | X14: 231765 | Y14: Ready to pay | Z14: APPROVED | AA14: Consumer | AB14: 45625 | AC14: KHI/HO/D/MO/PC COMP/C/100345/2/10/2024 | AD14: =VLOOKUP(AC14,'[1]Master Sheet'!$B$3:$Y$11580,24,0) -> 231765 | AE14: =X14-AD14 -> 0
A15: Fresh | B15: 45595 | C15: Salaam Takaful | D15: KHI/HO/D/MO/PC COMP/P/98111/09/2024 | E15: - | F15: 45566 | G15: 45931 | H15: TOYOTA COROLLA ALTIS | I15: 2021 | J15: BTM-083 | K15: Q071344 | L15: ZRE171R-6048869 | M15: SYED AYAZ ALI | N15: 4210170171077 | O15: 211625-11808-1003 | P15: 1003 | Q15: 528 | R15: 45572 | S15: 47387 | T15: 4900000 | U15: 0.0175 | V15: 85750 | W15: 0 | X15: 85750 | Y15: Ready to pay | Z15: APPROVED | AA15: Staff | AB15: 45625 | AC15: KHI/HO/D/MO/PC COMP/C/98111/5/10/2024 | AD15: =VLOOKUP(AC15,'[1]Master Sheet'!$B$3:$Y$11580,24,0) -> 85750 | AE15: =X15-AD15 -> 0
X17: =SUBTOTAL(9,X4:X15) -> 1258997

Sheet working
A1: POLICY NO. | B1: Assorted_code | D1: Premium | E1: 29Nov240037
A2: KHI/HO/D/MO/PC COMP/C/101132/1/11/2024 | B2: =VLOOKUP(A2,policy!B:C,2,0) -> 070000169457 | C2: 53869 | D2: =ROUND(C2,0) -> 53869 | E2: 29Nov240037 | F2: ="insert into ins_premium_det (premium_rcv_code,assorted_code, rec_amount,premium_rcv_detail_code,remaining_amt, payrec, mode_code,coinsurance_code,class_cd,it_remarks) values" -> insert into ins_premium_det (premium_rcv_code,assorted_code, rec_amount,premium_rcv_detail_code,remaining_amt, payrec, mode_code,coinsurance_code,class_cd,it_remarks) values | G2: ="('"&E2&"','"&B2&"','"&D2&"',(select max(to_number(i.premium_rcv_detail_code))+1 from ins_premium_det i),'"&D2&"','"&D2&"','02', '11000003','00','Request by Mr. Raheel Malik 04-Dec-2024 For Fresh ');" -> ('29Nov240037','070000169457','53869',(select max(to_number(i.premium_rcv_detail_code))+1 from ins_premium_det i),'53869','53869','02', '11000003','00','Request by Mr. Raheel Malik 04-Dec-2024 For Fresh '); | H2: =F2&G2 -> insert into ins_premium_det (premium_rcv_code,assorted_code, rec_amount,premium_rcv_detail_code,remaining_amt, payrec, mode_code,coinsurance_code,class_cd,it_remarks) values('29Nov240037','070000169457','53869',(select max(to_number(i.premium_rcv_detail_code))+1 from ins_premium_det i),'53869','53869','02', '11000003','00','Request by Mr. Raheel Malik 04-Dec-2024 For Fresh ');
A3: KHI/HO/D/MO/PC COMP/C/101132/2/11/2024 | B3: =VLOOKUP(A3,policy!B:C,2,0) -> 070000169481 | C3: 94724 | D3: =ROUND(C3,0) -> 94724 | E3: 29Nov240037 | F3: ="insert into ins_premium_det (premium_rcv_code,assorted_code, rec_amount,premium_rcv_detail_code,remaining_amt, payrec, mode_code,coinsurance_code,class_cd,it_remarks) values" -> insert into ins_premium_det (premium_rcv_code,assorted_code, rec_amount,premium_rcv_detail_code,remaining_amt, payrec, mode_code,coinsurance_code,class_cd,it_remarks) values | G3: ="('"&E3&"','"&B3&"','"&D3&"',(select max(to_number(i.premium_rcv_detail_code))+1 from ins_premium_det i),'"&D3&"','"&D3&"','02', '11000003','00','Request by Mr. Raheel Malik 04-Dec-2024 For Fresh ');" -> ('29Nov240037','070000169481','94724',(select max(to_number(i.premium_rcv_detail_code))+1 from ins_premium_det i),'94724','94724','02', '11000003','00','Request by Mr. Raheel Malik 04-Dec-2024 For Fresh '); | H3: =F3&G3 -> insert into ins_premium_det (premium_rcv_code,assorted_code, rec_amount,premium_rcv_detail_code,remaining_amt, payrec, mode_code,coinsurance_code,class_cd,it_remarks) values('29Nov240037','070000169481','94724',(select max(to_number(i.premium_rcv_detail_code))+1 from ins_premium_det i),'94724','94724','02', '11000003','00','Request by Mr. Raheel Malik 04-Dec-2024 For Fresh ');
A4: KHI/HO/D/MO/PC COMP/C/101132/3/11/2024 | B4: =VLOOKUP(A4,policy!B:C,2,0) -> 070000169482 | C4: 63680 | D4: =ROUND(C4,0) -> 63680 | E4: 29Nov240037 | F4: ="insert into ins_premium_det (premium_rcv_code,assorted_code, rec_amount,premium_rcv_detail_code,remaining_amt, payrec, mode_code,coinsurance_code,class_cd,it_remarks) values" -> insert into ins_premium_det (premium_rcv_code,assorted_code, rec_amount,premium_rcv_detail_code,remaining_amt, payrec, mode_code,coinsurance_code,class_cd,it_remarks) values | G4: ="('"&E4&"','"&B4&"','"&D4&"',(select max(to_number(i.premium_rcv_detail_code))+1 from ins_premium_det i),'"&D4&"','"&D4&"','02', '11000003','00','Request by Mr. Raheel Malik 04-Dec-2024 For Fresh ');" -> ('29Nov240037','070000169482','63680',(select max(to_number(i.premium_rcv_detail_code))+1 from ins_premium_det i),'63680','63680','02', '11000003','00','Request by Mr. Raheel Malik 04-Dec-2024 For Fresh '); | H4: =F4&G4 -> insert into ins_premium_det (premium_rcv_code,assorted_code, rec_amount,premium_rcv_detail_code,remaining_amt, payrec, mode_code,coinsurance_code,class_cd,it_remarks) values('29Nov240037','070000169482','63680',(select max(to_number(i.premium_rcv_detail_code))+1 from ins_premium_det i),'63680','63680','02', '11000003','00','Request by Mr. Raheel Malik 04-Dec-2024 For Fresh ');
A5: KHI/HO/D/MO/PC COMP/C/101132/4/11/2024 | B5: =VLOOKUP(A5,policy!B:C,2,0) -> 070000169491 | C5: 147930 | D5: =ROUND(C5,0) -> 147930 | E5: 29Nov240037 | F5: ="insert into ins_premium_det (premium_rcv_code,assorted_code, rec_amount,premium_rcv_detail_code,remaining_amt, payrec, mode_code,coinsurance_code,class_cd,it_remarks) values" -> insert into ins_premium_det (premium_rcv_code,assorted_code, rec_amount,premium_rcv_detail_code,remaining_amt, payrec, mode_code,coinsurance_code,class_cd,it_remarks) values | G5: ="('"&E5&"','"&B5&"','"&D5&"',(select max(to_number(i.premium_rcv_detail_code))+1 from ins_premium_det i),'"&D5&"','"&D5&"','02', '11000003','00','Request by Mr. Raheel Malik 04-Dec-2024 For Fresh ');" -> ('29Nov240037','070000169491','147930',(select max(to_number(i.premium_rcv_detail_code))+1 from ins_premium_det i),'147930','147930','02', '11000003','00','Request by Mr. Raheel Malik 04-Dec-2024 For Fresh '); | H5: =F5&G5 -> insert into ins_premium_det (premium_rcv_code,assorted_code, rec_amount,premium_rcv_detail_code,remaining_amt, payrec, mode_code,coinsurance_code,class_cd,it_remarks) values('29Nov240037','070000169491','147930',(select max(to_number(i.premium_rcv_detail_code))+1 from ins_premium_det i),'147930','147930','02', '11000003','00','Request by Mr. Raheel Malik 04-Dec-2024 For Fresh ');
A6: KHI/HO/D/MO/PC COMP/C/101132/5/11/2024 | B6: =VLOOKUP(A6,policy!B:C,2,0) -> 070000170973 | C6: 133485 | D6: =ROUND(C6,0) -> 133485 | E6: 29Nov240037 | F6: ="insert into ins_premium_det (premium_rcv_code,assorted_code, rec_amount,premium_rcv_detail_code,remaining_amt, payrec, mode_code,coinsurance_code,class_cd,it_remarks) values" -> insert into ins_premium_det (premium_rcv_code,assorted_code, rec_amount,premium_rcv_detail_code,remaining_amt, payrec, mode_code,coinsurance_code,class_cd,it_remarks) values | G6: ="('"&E6&"','"&B6&"','"&D6&"',(select max(to_number(i.premium_rcv_detail_code))+1 from ins_premium_det i),'"&D6&"','"&D6&"','02', '11000003','00','Request by Mr. Raheel Malik 04-Dec-2024 For Fresh ');" -> ('29Nov240037','070000170973','133485',(select max(to_number(i.premium_rcv_detail_code))+1 from ins_premium_det i),'133485','133485','02', '11000003','00','Request by Mr. Raheel Malik 04-Dec-2024 For Fresh '); | H6: =F6&G6 -> insert into ins_premium_det (premium_rcv_code,assorted_code, rec_amount,premium_rcv_detail_code,remaining_amt, payrec, mode_code,coinsurance_code,class_cd,it_remarks) values('29Nov240037','070000170973','133485',(select max(to_number(i.premium_rcv_detail_code))+1 from ins_premium_det i),'133485','133485','02', '11000003','00','Request by Mr. Raheel Malik 04-Dec-2024 For Fresh ');
A7: KHI/HO/D/MO/PC COMP/C/101132/6/11/2024 | B7: =VLOOKUP(A7,policy!B:C,2,0) -> 070000171251 | C7: 60596 | D7: =ROUND(C7,0) -> 60596 | E7: 29Nov240037 | F7: ="insert into ins_premium_det (premium_rcv_code,assorted_code, rec_amount,premium_rcv_detail_code,remaining_amt, payrec, mode_code,coinsurance_code,class_cd,it_remarks) values" -> insert into ins_premium_det (premium_rcv_code,assorted_code, rec_amount,premium_rcv_detail_code,remaining_amt, payrec, mode_code,coinsurance_code,class_cd,it_remarks) values | G7: ="('"&E7&"','"&B7&"','"&D7&"',(select max(to_number(i.premium_rcv_detail_code))+1 from ins_premium_det i),'"&D7&"','"&D7&"','02', '11000003','00','Request by Mr. Raheel Malik 04-Dec-2024 For Fresh ');" -> ('29Nov240037','070000171251','60596',(select max(to_number(i.premium_rcv_detail_code))+1 from ins_premium_det i),'60596','60596','02', '11000003','00','Request by Mr. Raheel Malik 04-Dec-2024 For Fresh '); | H7: =F7&G7 -> insert into ins_premium_det (premium_rcv_code,assorted_code, rec_amount,premium_rcv_detail_code,remaining_amt, payrec, mode_code,coinsurance_code,class_cd,it_remarks) values('29Nov240037','070000171251','60596',(select max(to_number(i.premium_rcv_detail_code))+1 from ins_premium_det i),'60596','60596','02', '11000003','00','Request by Mr. Raheel Malik 04-Dec-2024 For Fresh ');
A8: KHI/HO/D/MO/PC COMP/C/100345/8/10/2024 | B8: =VLOOKUP(A8,policy!B:C,2,0) -> 070000169339 | C8: 53869 | D8: =ROUND(C8,0) -> 53869 | E8: 29Nov240037 | F8: ="insert into ins_premium_det (premium_rcv_code,assorted_code, rec_amount,premium_rcv_detail_code,remaining_amt, payrec, mode_code,coinsurance_code,class_cd,it_remarks) values" -> insert into ins_premium_det (premium_rcv_code,assorted_code, rec_amount,premium_rcv_detail_code,remaining_amt, payrec, mode_code,coinsurance_code,class_cd,it_remarks) values | G8: ="('"&E8&"','"&B8&"','"&D8&"',(select max(to_number(i.premium_rcv_detail_code))+1 from ins_premium_det i),'"&D8&"','"&D8&"','02', '11000003','00','Request by Mr. Raheel Malik 04-Dec-2024 For Fresh ');" -> ('29Nov240037','070000169339','53869',(select max(to_number(i.premium_rcv_detail_code))+1 from ins_premium_det i),'53869','53869','02', '11000003','00','Request by Mr. Raheel Malik 04-Dec-2024 For Fresh '); | H8: =F8&G8 -> insert into ins_premium_det (premium_rcv_code,assorted_code, rec_amount,premium_rcv_detail_code,remaining_amt, payrec, mode_code,coinsurance_code,class_cd,it_remarks) values('29Nov240037','070000169339','53869',(select max(to_number(i.premium_rcv_detail_code))+1 from ins_premium_det i),'53869','53869','02', '11000003','00','Request by Mr. Raheel Malik 04-Dec-2024 For Fresh ');
A9: KHI/HO/D/MO/PC COMP/C/100345/4/10/2024 | B9: =VLOOKUP(A9,policy!B:C,2,0) -> 070000169018 | C9: 58500 | D9: =ROUND(C9,0) -> 58500 | E9: 29Nov240037 | F9: ="insert into ins_premium_det (premium_rcv_code,assorted_code, rec_amount,premium_rcv_detail_code,remaining_amt, payrec, mode_code,coinsurance_code,class_cd,it_remarks) values" -> insert into ins_premium_det (premium_rcv_code,assorted_code, rec_amount,premium_rcv_detail_code,remaining_amt, payrec, mode_code,coinsurance_code,class_cd,it_remarks) values | G9: ="('"&E9&"','"&B9&"','"&D9&"',(select max(to_number(i.premium_rcv_detail_code))+1 from ins_premium_det i),'"&D9&"','"&D9&"','02', '11000003','00','Request by Mr. Raheel Malik 04-Dec-2024 For Fresh ');" -> ('29Nov240037','070000169018','58500',(select max(to_number(i.premium_rcv_detail_code))+1 from ins_premium_det i),'58500','58500','02', '11000003','00','Request by Mr. Raheel Malik 04-Dec-2024 For Fresh '); | H9: =F9&G9 -> insert into ins_premium_det (premium_rcv_code,assorted_code, rec_amount,premium_rcv_detail_code,remaining_amt, payrec, mode_code,coinsurance_code,class_cd,it_remarks) values('29Nov240037','070000169018','58500',(select max(to_number(i.premium_rcv_detail_code))+1 from ins_premium_det i),'58500','58500','02', '11000003','00','Request by Mr. Raheel Malik 04-Dec-2024 For Fresh ');
A10: KHI/HO/D/MO/PC COMP/C/100345/5/10/2024 | B10: =VLOOKUP(A10,policy!B:C,2,0) -> 070000169038 | C10: 96217 | D10: =ROUND(C10,0) -> 96217 | E10: 29Nov240037 | F10: ="insert into ins_premium_det (premium_rcv_code,assorted_code, rec_amount,premium_rcv_detail_code,remaining_amt, payrec, mode_code,coinsurance_code,class_cd,it_remarks) values" -> insert into ins_premium_det (premium_rcv_code,assorted_code, rec_amount,premium_rcv_detail_code,remaining_amt, payrec, mode_code,coinsurance_code,class_cd,it_remarks) values | G10: ="('"&E10&"','"&B10&"','"&D10&"',(select max(to_number(i.premium_rcv_detail_code))+1 from ins_premium_det i),'"&D10&"','"&D10&"','02', '11000003','00','Request by Mr. Raheel Malik 04-Dec-2024 For Fresh ');" -> ('29Nov240037','070000169038','96217',(select max(to_number(i.premium_rcv_detail_code))+1 from ins_premium_det i),'96217','96217','02', '11000003','00','Request by Mr. Raheel Malik 04-Dec-2024 For Fresh '); | H10: =F10&G10 -> insert into ins_premium_det (premium_rcv_code,assorted_code, rec_amount,premium_rcv_detail_code,remaining_amt, payrec, mode_code,coinsurance_code,class_cd,it_remarks) values('29Nov240037','070000169038','96217',(select max(to_number(i.premium_rcv_detail_code))+1 from ins_premium_det i),'96217','96217','02', '11000003','00','Request by Mr. Raheel Malik 04-Dec-2024 For Fresh ');
A11: KHI/HO/D/MO/PC COMP/C/100345/6/10/2024 | B11: =VLOOKUP(A11,policy!B:C,2,0) -> 070000169075 | C11: 178612 | D11: =ROUND(C11,0) -> 178612 | E11: 29Nov240037 | F11: ="insert into ins_premium_det (premium_rcv_code,assorted_code, rec_amount,premium_rcv_detail_code,remaining_amt, payrec, mode_code,coinsurance_code,class_cd,it_remarks) values" -> insert into ins_premium_det (premium_rcv_code,assorted_code, rec_amount,premium_rcv_detail_code,remaining_amt, payrec, mode_code,coinsurance_code,class_cd,it_remarks) values | G11: ="('"&E11&"','"&B11&"','"&D11&"',(select max(to_number(i.premium_rcv_detail_code))+1 from ins_premium_det i),'"&D11&"','"&D11&"','02', '11000003','00','Request by Mr. Raheel Malik 04-Dec-2024 For Fresh ');" -> ('29Nov240037','070000169075','178612',(select max(to_number(i.premium_rcv_detail_code))+1 from ins_premium_det i),'178612','178612','02', '11000003','00','Request by Mr. Raheel Malik 04-Dec-2024 For Fresh '); | H11: =F11&G11 -> insert into ins_premium_det (premium_rcv_code,assorted_code, rec_amount,premium_rcv_detail_code,remaining_amt, payrec, mode_code,coinsurance_code,class_cd,it_remarks) values('29Nov240037','070000169075','178612',(select max(to_number(i.premium_rcv_detail_code))+1 from ins_premium_det i),'178612','178612','02', '11000003','00','Request by Mr. Raheel Malik 04-Dec-2024 For Fresh ');
A12: KHI/HO/D/MO/PC COMP/C/100345/2/10/2024 | B12: =VLOOKUP(A12,policy!B:C,2,0) -> 070000169002 | C12: 231765 | D12: =ROUND(C12,0) -> 231765 | E12: 29Nov240037 | F12: ="insert into ins_premium_det (premium_rcv_code,assorted_code, rec_amount,premium_rcv_detail_code,remaining_amt, payrec, mode_code,coinsurance_code,class_cd,it_remarks) values" -> insert into ins_premium_det (premium_rcv_code,assorted_code, rec_amount,premium_rcv_detail_code,remaining_amt, payrec, mode_code,coinsurance_code,class_cd,it_remarks) values | G12: ="('"&E12&"','"&B12&"','"&D12&"',(select max(to_number(i.premium_rcv_detail_code))+1 from ins_premium_det i),'"&D12&"','"&D12&"','02', '11000003','00','Request by Mr. Raheel Malik 04-Dec-2024 For Fresh ');" -> ('29Nov240037','070000169002','231765',(select max(to_number(i.premium_rcv_detail_code))+1 from ins_premium_det i),'231765','231765','02', '11000003','00','Request by Mr. Raheel Malik 04-Dec-2024 For Fresh '); | H12: =F12&G12 -> insert into ins_premium_det (premium_rcv_code,assorted_code, rec_amount,premium_rcv_detail_code,remaining_amt, payrec, mode_code,coinsurance_code,class_cd,it_remarks) values('29Nov240037','070000169002','231765',(select max(to_number(i.premium_rcv_detail_code))+1 from ins_premium_det i),'231765','231765','02', '11000003','00','Request by Mr. Raheel Malik 04-Dec-2024 For Fresh ');
A13: KHI/HO/D/MO/PC COMP/C/98111/5/10/2024 | B13: =VLOOKUP(A13,policy!B:C,2,0) -> 070000166919 | C13: 85750 | D13: =ROUND(C13,0) -> 85750 | E13: 29Nov240037 | F13: ="insert into ins_premium_det (premium_rcv_code,assorted_code, rec_amount,premium_rcv_detail_code,remaining_amt, payrec, mode_code,coinsurance_code,class_cd,it_remarks) values" -> insert into ins_premium_det (premium_rcv_code,assorted_code, rec_amount,premium_rcv_detail_code,remaining_amt, payrec, mode_code,coinsurance_code,class_cd,it_remarks) values | G13: ="('"&E13&"','"&B13&"','"&D13&"',(select max(to_number(i.premium_rcv_detail_code))+1 from ins_premium_det i),'"&D13&"','"&D13&"','02', '11000003','00','Request by Mr. Raheel Malik 04-Dec-2024 For Fresh ');" -> ('29Nov240037','070000166919','85750',(select max(to_number(i.premium_rcv_detail_code))+1 from ins_premium_det i),'85750','85750','02', '11000003','00','Request by Mr. Raheel Malik 04-Dec-2024 For Fresh '); | H13: =F13&G13 -> insert into ins_premium_det (premium_rcv_code,assorted_code, rec_amount,premium_rcv_detail_code,remaining_amt, payrec, mode_code,coinsurance_code,class_cd,it_remarks) values('29Nov240037','070000166919','85750',(select max(to_number(i.premium_rcv_detail_code))+1 from ins_premium_det i),'85750','85750','02', '11000003','00','Request by Mr. Raheel Malik 04-Dec-2024 For Fresh ');
C14: =SUM(C2:C13) -> 1258997 | D14: =SUM(D2:D13) -> 1258997

Sheet Sheet2
A1: KHI/HO/D/MO/PC COMP/C/101132/1/11/2024 | B1: -11-2024 | H1: 101132 | I1: 00001 | J1: ="ia.assorted_string like '%"&H1&"-"&I1&B1&"%' or" -> ia.assorted_string like '%101132-00001-11-2024%' or
A2: KHI/HO/D/MO/PC COMP/C/101132/2/11/2024 | B2: -11-2024 | H2: 101132 | I2: 00002 | J2: ="ia.assorted_string like '%"&H2&"-"&I2&B2&"%' or" -> ia.assorted_string like '%101132-00002-11-2024%' or
A3: KHI/HO/D/MO/PC COMP/C/101132/3/11/2024 | B3: -11-2024 | H3: 101132 | I3: 00003 | J3: ="ia.assorted_string like '%"&H3&"-"&I3&B3&"%' or" -> ia.assorted_string like '%101132-00003-11-2024%' or
A4: KHI/HO/D/MO/PC COMP/C/101132/4/11/2024 | B4: -11-2024 | H4: 101132 | I4: 00004 | J4: ="ia.assorted_string like '%"&H4&"-"&I4&B4&"%' or" -> ia.assorted_string like '%101132-00004-11-2024%' or
A5: KHI/HO/D/MO/PC COMP/C/101132/5/11/2024 | B5: -11-2024 | H5: 101132 | I5: 00005 | J5: ="ia.assorted_string like '%"&H5&"-"&I5&B5&"%' or" -> ia.assorted_string like '%101132-00005-11-2024%' or
A6: KHI/HO/D/MO/PC COMP/C/101132/6/11/2024 | B6: -11-2024 | H6: 101132 | I6: 00006 | J6: ="ia.assorted_string like '%"&H6&"-"&I6&B6&"%' or" -> ia.assorted_string like '%101132-00006-11-2024%' or
A7: KHI/HO/D/MO/PC COMP/C/100345/8/10/2024 | B7: -10-2024 | H7: 100345 | I7: 00008 | J7: ="ia.assorted_string like '%"&H7&"-"&I7&B7&"%' or" -> ia.assorted_string like '%100345-00008-10-2024%' or
A8: KHI/HO/D/MO/PC COMP/C/100345/4/10/2024 | B8: -10-2024 | H8: 100345 | I8: 00004 | J8: ="ia.assorted_string like '%"&H8&"-"&I8&B8&"%' or" -> ia.assorted_string like '%100345-00004-10-2024%' or
A9: KHI/HO/D/MO/PC COMP/C/100345/5/10/2024 | B9: -10-2024 | H9: 100345 | I9: 00005 | J9: ="ia.assorted_string like '%"&H9&"-"&I9&B9&"%' or" -> ia.assorted_string like '%100345-00005-10-2024%' or
A10: KHI/HO/D/MO/PC COMP/C/100345/6/10/2024 | B10: -10-2024 | H10: 100345 | I10: 00006 | J10: ="ia.assorted_string like '%"&H10&"-"&I10&B10&"%' or" -> ia.assorted_string like '%100345-00006-10-2024%' or
A11: KHI/HO/D/MO/PC COMP/C/100345/2/10/2024 | B11: -10-2024 | H11: 100345 | I11: 00002 | J11: ="ia.assorted_string like '%"&H11&"-"&I11&B11&"%' or" -> ia.assorted_string like '%100345-00002-10-2024%' or
A12: KHI/HO/D/MO/PC COMP/C/98111/5/10/2024 | B12: -10-2024 | H12: 98111 | I12: 00005 | J12: ="ia.assorted_string like '%"&H12&"-"&I12&B12&"%' or" -> ia.assorted_string like '%98111-00005-10-2024%' or

Sheet policy
B1: FUNC_ASSORTED_STRING(IA.ASSORTED_CODE) | C1: ASSORTED_CODE
A2: 1 | B2: KHI/HO/D/MO/PC COMP/C/100345/5/10/2024 | C2: 070000169038
A3: 2 | B3: KHI/HO/D/MO/PC COMP/C/100345/8/10/2024 | C3: 070000169339
A4: 3 | B4: KHI/HO/D/MO/PC COMP/C/101132/3/11/2024 | C4: 070000169482
A5: 4 | B5: KHI/HO/D/MO/PC COMP/C/101132/2/11/2024 | C5: 070000169481
A6: 5 | B6: KHI/HO/D/MO/PC COMP/C/100345/4/10/2024 | C6: 070000169018
A7: 6 | B7: KHI/HO/D/MO/PC COMP/C/98111/5/10/2024 | C7: 070000166919
A8: 7 | B8: KHI/HO/D/MO/PC COMP/C/101132/1/11/2024 | C8: 070000169457
A9: 8 | B9: KHI/HO/D/MO/PC COMP/C/100345/6/10/2024 | C9: 070000169075
A10: 9 | B10: KHI/HO/D/MO/PC COMP/C/100345/2/10/2024 | C10: 070000169002
A11: 10 | B11: KHI/HO/D/MO/PC COMP/C/101132/4/11/2024 | C11: 070000169491
A12: 11 | B12: KHI/HO/D/MO/PC COMP/C/101132/5/11/2024 | C12: 070000170973
A13: 12 | B13: KHI/HO/D/MO/PC COMP/C/101132/6/11/2024 | C13: 070000171251

Sheet Renewal
A3: Fresh / Renewal | B3: Renewal Month | C3: Takaful Company | D3: Policy # | E3: TRACKER_TYPE | F3: Takaful start Date | G3: Takaful End End | H3: Make | I3: Model | J3: Registration_Number | K3: Engine_Number | L3: Chassis_Number | M3: Customer Name | N3: CNIC | O3: CIF+Deal+Branch | P3: BRANCH_CODE | Q3: CLASS | R3: DEAL_DATE | S3: MATURITY_DATE | T3: Old Sum Covered | U3: Rate | V3: New Sum Covered | W3: Gross Premium | X3: Tracker Amount | Y3: Net Premium | Z3: Remarks | AA3: DEAL_STATUS | AB3: Category | AC3: Prepaid Date | AD3: Payment Date | AE3: Policy # | AF3: Tms prem | AG3: Difference
A4: Renewal | B4: Nov-24 | C4: Salaam Takaful | D4: KHI/HO/D/MO/PC COMP/C/78152/342/11/2023 | E4: By Bank | F4: 45597 | G4: 45962 | H4: KIA SPORTAGE AWD-CW | I4: 2021 | J4: AFM-658 | K4: G4NALH342077 | L4: NNAQL51AZKP508547 | M4: M/S.Bankislami(Pakistan)Limited User:Mr.MianMuhayminAzamManeka | N4: 3520191578637 | O4: 3630342-2780-2002 | P4: 2002 | Q4: 477 | R4: 44503 | S4: 46331 | T4: 4398300 | U4: 0.0175 | V4: 3958470 | W4: 69273.225 | X4: 0 | Y4: 69273 | Z4: Ok for Renewal | AA4: APPROVED | AB4: Consumer | AC4: Before_24-Dec-2021 | AD4: 45623 | AE4: KHI/HO/D/MO/PC COMP/C/101820/2/11/2024 | AF4: 69273 | AG4: =Y4-AF4 -> 0
A5: Renewal | B5: Nov-24 | C5: Salaam Takaful | D5: KHI/HO/D/MO/PC COMP/C/78152/192/11/2023 | E5: By Bank | F5: 45600 | G5: 45965 | H5: HYUNDAI SONATA 6A/T SR DELUXE | I5: 2021 | J5: AFN-594 | K5: G4NAMU124566 | L5: PMHL3416MMN400480 | M5: M/S.Bankislami(Pakistan)Limited User:MrMuhammadQaisarIqbalKhan | N5: 3520238214541 | O5: 743675-802-2053 | P5: 2053 | Q5: 450 | R5: 44505 | S5: 46331 | T5: 5194125 | U5: 0.0175 | V5: 4674712.5 | W5: 81807.469 | X5: 0 | Y5: 81807 | Z5: Ok for Renewal | AA5: APPROVED | AB5: Consumer | AC5: Before_24-Dec-2021 | AD5: 45623 | AE5: KHI/HO/D/MO/PC COMP/C/101820/3/11/2024 | AF5: 81807 | AG5: =Y5-AF5 -> 0
A6: Renewal | B6: Nov-24 | C6: Salaam Takaful | D6: KHI/HO/D/MO/PC COMP/C/78152/226/11/2023 | E6: By Bank | F6: 45617 | G6: 45982 | H6: SUZUKI ALTO VXL AGS E-2 | I6: 2021 | J6: AFV-847 | K6: 6R193101 | L6: NF1AET306H1093081 | M6: M/S.Bankislami(Pakistan)Limited User:Mr.MairaAmjad | N6: 3520275280074 | O6: 864373-666-2029 | P6: 2029 | Q6: 450 | R6: 44530 | S6: 46351 | T6: 1232010 | U6: 0.018 | V6: 1108809 | W6: 19958.562 | X6: 0 | Y6: 19959 | Z6: Ok for Renewal | AA6: APPROVED | AB6: Consumer | AC6: Before_24-Dec-2021 | AD6: 45623 | AE6: KHI/HO/D/MO/PC COMP/C/101820/4/11/2024 | AF6: 19959 | AG6: =Y6-AF6 -> 0
A7: Renewal | B7: Nov-24 | C7: Salaam Takaful | D7: KHI/HO/D/MO/PC COMP/C/78152/248/11/2023 | E7: By Bank | F7: 45620 | G7: 45985 | H7: SUZUKI ALTO AGS A/T | I7: 2021 | J7: AFW-479 | K7: 6R193315 | L7: NF1AET306H1093227 | M7: M/S.Bankislami(Pakistan)Limited User:Mr.MuhammadKhyzerBinDost | N7: 3520282688765 | O7: 894012-665-2029 | P7: 2029 | Q7: 450 | R7: 44525 | S7: 47082 | T7: 1232010 | U7: 0.018 | V7: 1108809 | W7: 19958.562 | X7: 0 | Y7: 19959 | Z7: Ok for Renewal | AA7: APPROVED | AB7: Consumer | AC7: Before_24-Dec-2021 | AD7: 45623 | AE7: KHI/HO/D/MO/PC COMP/C/101820/5/11/2024 | AF7: 19959 | AG7: =Y7-AF7 -> 0
A8: Renewal | B8: Nov-24 | C8: Salaam Takaful | D8: KHI/HO/D/MO/PC COMP/C/78152/225/11/2023 | E8: By Bank | F8: 45605 | G8: 45970 | H8: KIA SPORTAGE AWD-CW | I8: 2020 | J8: ARW-138 | K8: G4NALH326134 | L8: NNAQL51AZKP506308 | M8: M/S.Bankislami(Pakistan)Limited User:Mr.AmmarWaheed | N8: 3120222404265 | O8: 861406-226-2009 | P8: 2009 | Q8: 450 | R8: 44146 | S8: 45966 | T8: 3952638 | U8: 0.019 | V8: 3557374.2 | W8: 67590.11 | X8: 0 | Y8: 67590 | Z8: Ok for Renewal | AA8: APPROVED | AB8: Consumer | AC8: Before_24-Dec-2021 | AD8: 45623 | AE8: KHI/HO/D/MO/PC COMP/C/101820/6/11/2024 | AF8: 67590 | AG8: =Y8-AF8 -> 0
A9: Renewal | B9: Nov-24 | C9: Salaam Takaful | D9: KHI/HO/D/MO/PC COMP/C/78152/223/11/2023 | E9: By Bank | F9: 45618 | G9: 45983 | H9: SUZUKI ALTO VX | I9: 2021 | J9: AFW-653 | K9: 6R192879 | L9: NF1AET306H1092876 | M9: M/S.Bankislami(Pakistan)Limited User:Mr.NadeemShakir | N9: 3520178201837 | O9: 857975-2821-2002 | P9: 2002 | Q9: 477 | R9: 44546 | S9: 46351 | T9: 901530 | U9: 0.0199 | V9: 811377 | W9: 16146.402 | X9: 0 | Y9: 16146 | Z9: Ok for Renewal | AA9: APPROVED | AB9: Consumer | AC9: Before_24-Dec-2021 | AD9: 45623 | AE9: KHI/HO/D/MO/PC COMP/C/101820/7/11/2024 | AF9: 16146 | AG9: =Y9-AF9 -> 0
A10: Renewal | B10: Nov-24 | C10: Salaam Takaful | D10: KHI/HO/D/MO/PC COMP/C/78152/19/11/2023 | E10: By Bank | F10: 45618 | G10: 45983 | H10: SUZUKI BOLAN VX | I10: 2022 | J10: AMJ-489 | K10: PKT1023482 | L10: SV308PK01139998 | M10: M/s.BankislamiPakistanLimited UserMr.GhulamMustafa | N10: 3520121047647 | O10: 3700663-252-2046 | P10: 2046 | Q10: 477 | R10: 44888 | S10: 46716 | T10: 1195200 | U10: 0.0199 | V10: 1075680 | W10: 21406.032 | X10: 0 | Y10: 21406 | Z10: Ok for Renewal | AA10: APPROVED | AB10: Consumer | AC10: After_24-Dec-2021 | AD10: 45623 | AE10: KHI/HO/D/MO/PC COMP/C/101820/8/11/2024 | AF10: 21406 | AG10: =Y10-AF10 -> 0
A11: Renewal | B11: Nov-24 | C11: Salaam Takaful | D11: KHI/HO/D/MO/PC COMP/C/78152/108/11/2023 | E11: By Bank | F11: 45610 | G11: 45975 | H11: SUZUKI ALTO VX EURO II | I11: 2022 | J11: AMF-467 | K11: 6R252242 | L11: NF1AET306H1152254 | M11: M/s.BankislamiPakistanLimited UserMs.SanaChudhry | N11: 3520188325842 | O11: 3692544-250-2046 | P11: 2046 | Q11: 477 | R11: 44873 | S11: 46696 | T11: 1175400 | U11: 0.0199 | V11: 1057860 | W11: 21051.414 | X11: 0 | Y11: 21051 | Z11: Ok for Renewal | AA11: APPROVED | AB11: Consumer | AC11: After_24-Dec-2021 | AD11: 45623 | AE11: KHI/HO/D/MO/PC COMP/C/101820/9/11/2024 | AF11: 21051 | AG11: =Y11-AF11 -> 0
A12: Renewal | B12: Nov-24 | C12: Salaam Takaful | D12: KHI/HO/D/MO/PC COMP/C/78152/27/11/2023 | E12: By Bank | F12: 45619 | G12: 45984 | H12: SUZUKI ALTO VX | I12: 2022 | J12: AMK-647 | K12: 6R256253 | L12: NF1AET306H1156311 | M12: M/s.BankIslamiPakistanLimited UserMr.RanaMaqsoodAhmad | N12: 3410126382061 | O12: 3695383-128-3082 | P12: 3082 | Q12: 450 | R12: 44893 | S12: 46351 | T12: 1175400 | U12: 0.0199 | V12: 1057860 | W12: 21051.414 | X12: 0 | Y12: 21051 | Z12: Ok for Renewal | AA12: APPROVED | AB12: Consumer | AC12: After_24-Dec-2021 | AD12: 45623 | AE12: KHI/HO/D/MO/PC COMP/C/101820/10/11/2024 | AF12: 21051 | AG12: =Y12-AF12 -> 0
A13: Renewal | B13: Nov-24 | C13: Salaam Takaful | D13: KHI/HO/D/MO/PC COMP/C/78152/86/11/2023 | E13: By Bank | F13: 45603 | G13: 45968 | H13: SUZUKI ALTO VX EURO II | I13: 2022 | J13: AMF-579 | K13: 6R252232 | L13: NF1AET306H1152237 | M13: M/s.BankIslamiPakistanLimited UserMr.RizwanAli | N13: 3520107444767 | O13: 852774-359-2031 | P13: 2031 | Q13: 450 | R13: 44875 | S13: 47437 | T13: 1175400 | U13: 0.0199 | V13: 1057860 | W13: 21051.414 | X13: 0 | Y13: 21051 | Z13: Ok for Renewal | AA13: APPROVED | AB13: Consumer | AC13: After_24-Dec-2021 | AD13: 45623 | AE13: KHI/HO/D/MO/PC COMP/C/101820/11/11/2024 | AF13: 21051 | AG13: =Y13-AF13 -> 0
A14: Renewal | B14: Nov-24 | C14: Salaam Takaful | D14: KHI/HO/D/MO/PC COMP/C/78152/39/11/2023 | E14: By Bank | F14: 45623 | G14: 45988 | H14: SUZUKI ALTO | I14: 2022 | J14: BAW-863 | K14: 6R256741 | L14: NF1AET306H1156723 | M14: M/s.BankislamiPakistanLimited UserMr.PakeezaFarooqi | N14: 3740504874296 | O14: 3715055-226-3004 | P14: 3004 | Q14: 450 | R14: 44893 | S14: 46726 | T14: 1755900 | U14: 0.0199 | V14: 1580310 | W14: 31448.169 | X14: 0 | Y14: 31448 | Z14: Ok for Renewal | AA14: APPROVED | AB14: Consumer | AC14: After_24-Dec-2021 | AD14: 45623 | AE14: KHI/HO/D/MO/PC COMP/C/101820/12/11/2024 | AF14: 31448 | AG14: =Y14-AF14 -> 0
A15: Renewal | B15: Nov-24 | C15: Salaam Takaful | D15: KHI/HO/D/MO/PC COMP/C/78152/44/11/2023 | E15: By Bank | F15: 45623 | G15: 45988 | H15: SUZUKI ALTO | I15: 2022 | J15: ARU-572 | K15: 6R258561 | L15: NF1AET306H1158556 | M15: M/s.BankislamiPakistanLimited UserMr.AsadAliKiyani | N15: 3740510454007 | O15: 1313618-67-3085 | P15: 3085 | Q15: 450 | R15: 44896 | S15: 46726 | T15: 1755900 | U15: 0.0199 | V15: 1580310 | W15: 31448.169 | X15: 0 | Y15: 31448 | Z15: Ok for Renewal | AA15: APPROVED | AB15: Consumer | AC15: After_24-Dec-2021 | AD15: 45623 | AE15: KHI/HO/D/MO/PC COMP/C/101820/13/11/2024 | AF15: 31448 | AG15: =Y15-AF15 -> 0
A16: Renewal | B16: Nov-24 | C16: Salaam Takaful | D16: KHI/HO/D/MO/PC COMP/C/78152/54/11/2023 | E16: By Bank | F16: 45625 | G16: 45990 | H16: SUZUKI ALTO | I16: 2022 | J16: AML-641 | K16: 6R257799 | L16: NF1AET306H1157774 | M16: M/s.BankIslamiPakistanLimited UserMr.ZaidRiaz | N16: 3410194796469 | O16: 3717500-228-2005 | P16: 2005 | Q16: 450 | R16: 44897 | S16: 46726 | T16: 1755900 | U16: 0.0199 | V16: 1580310 | W16: 31448.169 | X16: 0 | Y16: 31448 | Z16: Ok for Renewal | AA16: APPROVED | AB16: Consumer | AC16: After_24-Dec-2021 | AD16: 45623 | AE16: KHI/HO/D/MO/PC COMP/C/101820/14/11/2024 | AF16: 31448 | AG16: =Y16-AF16 -> 0
A17: Renewal | B17: Nov-24 | C17: Salaam Takaful | D17: KHI/HO/D/MO/PC COMP/C/78152/56/11/2023 | E17: By Bank | F17: 45625 | G17: 45990 | H17: SUZUKI ALTO | I17: 2022 | J17: AML-965 | K17: 6R259088 | L17: NF1AET306H1159118 | M17: M/s.BankIslamiPakistanLimited UserMr.KhadijaNauman | N17: 3310045118926 | O17: 3705088-32-2117 | P17: 2117 | Q17: 450 | R17: 44901 | S17: 46726 | T17: 1755900 | U17: 0.0199 | V17: 1580310 | W17: 31448.169 | X17: 0 | Y17: 31448 | Z17: Ok for Renewal | AA17: APPROVED | AB17: Consumer | AC17: After_24-Dec-2021 | AD17: 45623 | AE17: KHI/HO/D/MO/PC COMP/C/101820/15/11/2024 | AF17: 31448 | AG17: =Y17-AF17 -> 0
A18: Renewal | B18: Nov-24 | C18: Salaam Takaful | D18: KHI/HO/D/MO/PC COMP/C/78152/376/11/2023 | E18: By Bank | F18: 45626 | G18: 45991 | H18: CHANGAN KARVAAN VAN | I18: 2022 | J18: BAX-738 | K18: JL466Q9N69U501077 | L18: NKMAAB3D1N1014067 | M18: M/s.Bankislami(Pakistan)Limited UserMr.HafizMuhammadAfzaal | N18: 3740270734491 | O18: 3638057-31-3095 | P18: 3095 | Q18: 450 | R18: 44900 | S18: 46726 | T18: 1506600 | U18: 0.0199 | V18: 1355940 | W18: 26983.206 | X18: 0 | Y18: 26983 | Z18: Ok for Renewal | AA18: APPROVED | AB18: Consumer | AC18: After_24-Dec-2021 | AD18: 45623 | AE18: KHI/HO/D/MO/PC COMP/C/101820/16/11/2024 | AF18: 26983 | AG18: =Y18-AF18 -> 0
A19: Renewal | B19: Nov-24 | C19: Salaam Takaful | D19: KHI/HO/D/MO/PC COMP/C/78152/83/11/2023 | E19: By Bank | F19: 45603 | G19: 45968 | H19: SUZUKI CULTUS VXL EURO II | I19: 2022 | J19: BAU-768 | K19: PK10K202681 | L19: NF1AVK31H10102658 | M19: M/s.BankIslamiPakistanLimited UserMr.RizwanAli | N19: 3640162562631 | O19: 673290-81-2056 | P19: 2056 | Q19: 450 | R19: 44882 | S19: 46331 | T19: 2485800 | U19: 0.0199 | V19: 2237220 | W19: 44520.678 | X19: 0 | Y19: 44521 | Z19: Ok for Renewal | AA19: APPROVED | AB19: Consumer | AC19: After_24-Dec-2021 | AD19: 45623 | AE19: KHI/HO/D/MO/PC COMP/C/101820/17/11/2024 | AF19: 44521 | AG19: =Y19-AF19 -> 0
A20: Renewal | B20: Nov-24 | C20: Salaam Takaful | D20: KHI/HO/D/MO/PC COMP/C/78152/116/11/2023 | E20: By Bank | F20: 45612 | G20: 45977 | H20: SUZUKI ALTO VXR | I20: 2022 | J20: AMH-775 | K20: 6R254360 | L20: NF1AET306H1154352 | M20: M/s.BankislamiPakistanLimited UserMr.MuhammadAzeemSubhani | N20: 3520151772725 | O20: 3707095-80-2112 | P20: 2112 | Q20: 450 | R20: 44883 | S20: 46716 | T20: 1507500 | U20: 0.0199 | V20: 1356750 | W20: 26999.325 | X20: 0 | Y20: 26999 | Z20: Ok for Renewal | AA20: APPROVED | AB20: Consumer | AC20: After_24-Dec-2021 | AD20: 45623 | AE20: KHI/HO/D/MO/PC COMP/C/101820/18/11/2024 | AF20: 26999 | AG20: =Y20-AF20 -> 0
A21: Renewal | B21: Nov-24 | C21: Salaam Takaful | D21: KHI/HO/D/MO/PC COMP/C/78152/63/11/2023 | E21: By Bank | F21: 45597 | G21: 45962 | H21: SUZUKI ALTO VXR E-2 | I21: 2022 | J21: BXU-597 | K21: 6R251960 | L21: NF1AET306H1151951 | M21: M/s.BankislamiPakistanLimited UserMr.AbdulSalamShaikh | N21: 4520308180741 | O21: 496888-174-1101 | P21: 1101 | Q21: 450 | R21: 44867 | S21: 46696 | T21: 1507500 | U21: 0.0199 | V21: 1356750 | W21: 26999.325 | X21: 0 | Y21: 26999 | Z21: Ok for Renewal | AA21: APPROVED | AB21: Consumer | AC21: After_24-Dec-2021 | AD21: 45623 | AE21: KHI/HO/D/MO/PC COMP/C/101820/19/11/2024 | AF21: 26999 | AG21: =Y21-AF21 -> 0
A22: Renewal | B22: Nov-24 | C22: Salaam Takaful | D22: KHI/HO/D/MO/PC COMP/C/78152/42/11/2023 | E22: By Bank | F22: 45597 | G22: 45962 | H22: SUZUKI ALTO | I22: 2022 | J22: BAT-857 | K22: 6R252246 | L22: NF1AET306H1152193 | M22: M/s.BankislamiPakistanLimited UserMr.MuhammadTariq | N22: 3630211666467 | O22: 3713943-236-2028 | P22: 2028 | Q22: 450 | R22: 44872 | S22: 45966 | T22: 1697400 | U22: 0.0199 | V22: 1527660 | W22: 30400.434 | X22: 0 | Y22: 30400 | Z22: Ok for Renewal | AA22: APPROVED | AB22: Consumer | AC22: After_24-Dec-2021 | AD22: 45623 | AE22: KHI/HO/D/MO/PC COMP/C/101820/20/11/2024 | AF22: 30400 | AG22: =Y22-AF22 -> 0
A23: Renewal | B23: Nov-24 | C23: Salaam Takaful | D23: KHI/HO/D/MO/PC COMP/C/78152/61/11/2023 | E23: By Bank | F23: 45597 | G23: 45962 | H23: SUZUKI ALTO | I23: 2022 | J23: AMH-744 | K23: 6R253794 | L23: NF1AET306H1153795 | M23: M/s.BankislamiPakistanLimited UserMr.USMANAYUBKHAN | N23: 3410204433707 | O23: 1437133-126-2033 | P23: 2033 | Q23: 450 | R23: 44869 | S23: 46696 | T23: 1697400 | U23: 0.0199 | V23: 1527660 | W23: 30400.434 | X23: 0 | Y23: 30400 | Z23: Ok for Renewal | AA23: APPROVED | AB23: Consumer | AC23: After_24-Dec-2021 | AD23: 45623 | AE23: KHI/HO/D/MO/PC COMP/C/101820/21/11/2024 | AF23: 30400 | AG23: =Y23-AF23 -> 0
A24: Renewal | B24: Nov-24 | C24: Salaam Takaful | D24: KHI/HO/D/MO/PC COMP/C/78152/90/11/2023 | E24: By Bank | F24: 45605 | G24: 45970 | H24: SUZUKI ALTO | I24: 2022 | J24: AMF-667 | K24: 6R253894 | L24: NF1AET306H1153903 | M24: M/s.BankIslamiPakistanLimited UserMs.NasiraSarkar | N24: 3520210798636 | O24: 3708536-444-2096 | P24: 2096 | Q24: 450 | R24: 44876 | S24: 45976 | T24: 1697400 | U24: 0.0199 | V24: 1527660 | W24: 30400.434 | X24: 0 | Y24: 30400 | Z24: Ok for Renewal | AA24: APPROVED | AB24: Consumer | AC24: After_24-Dec-2021 | AD24: 45623 | AE24: KHI/HO/D/MO/PC COMP/C/101820/22/11/2024 | AF24: 30400 | AG24: =Y24-AF24 -> 0
... A105: Renewal | B105: Nov-24 | C105: Salaam Takaful | D105: KHI/HO/D/MO/PC COMP/C/78152/99/11/2023 | E105: By Bank | F105: 45609 | G105: 45974 | H105: SUZUKI ALTO | I105: 2022 | J105: BXG-324 | K105: 6R242448 | L105: NF1AET306H1142479 | M105: M/sBankislamiPakistanLimited UserMr.MuhammadAkram | N105: 3510142368399 | O105: 327520-169-1028 | P105: 1028 | Q105: 450 | R105: 44876 | S105: 46706 | T105: 1890000 | U105: 0.0199 | V105: 1701000 | W105: 33849.9 | X105: 0 | Y105: 33850 | Z105: Ok for Renewal | AA105: APPROVED | AB105: Consumer | AC105: After_24-Dec-2021 | AD105: 45623 | AE105: KHI/HO/D/MO/PC COMP/C/101820/104/11/2024 | AF105: 33850 | AG105: =Y105-AF105 -> 0
A106: Renewal | B106: Nov-24 | C106: Salaam Takaful | D106: KHI/HO/D/MO/PC COMP/P/78212/11/2023 | E106: By Bank | F106: 45609 | G106: 45974 | H106: MERCEDES MERCEDEZ BENZ | I106: 2017 | J106: BHS-646 | K106: 27491030720790 | L106: WDD2050402R20969 | M106: M/s Bankislami Pakistan Limited User Mr. Zeeshan Qazi M/S Jauhar Autos CNIC # 42201-4711152-3 CELL # 0331-2138186 P.O # 1186/4711152 | N106: 8268550 | O106: 1520714-17-1186 | P106: 1186 | Q106: 565 | R106: 44873 | S106: 45955 | T106: 11250000 | U106: 0.0199 | V106: 10125000 | W106: 201487.5 | X106: 0 | Y106: 201488 | Z106: Ok for Renewal | AA106: APPROVED | AB106: Consumer | AC106: After_24-Dec-2021 | AD106: 45623 | AE106: KHI/HO/D/MO/PC COMP/C/101820/105/11/2024 | AF106: 201488 | AG106: =Y106-AF106 -> 0
A107: Renewal | B107: Nov-24 | C107: Salaam Takaful | D107: KHI/HO/D/MO/PC COMP/C/78152/136/11/2023 | E107: By Bank | F107: 45605 | G107: 45970 | H107: SUZUKI ALTO AGS A/T | I107: 2021 | J107: AFP-766 | K107: 6R191063 | L107: NF1AET306H1091088 | M107: M/S.Bankislami(Pakistan)Limited User:MrAsherRehmanButt | N107: 3520290027825 | O107: 500860-658-2029 | P107: 2029 | Q107: 450 | R107: 44510 | S107: 46331 | T107: 1232010 | U107: 0.0199 | V107: 1108809 | W107: 22065.299 | X107: 0 | Y107: 22065 | Z107: Ok for Renewal | AA107: APPROVED | AB107: Consumer | AC107: Before_24-Dec-2021 | AD107: 45623 | AE107: KHI/HO/D/MO/PC COMP/C/101820/106/11/2024 | AF107: 22065 | AG107: =Y107-AF107 -> 0
A108: Renewal | B108: Nov-24 | C108: Salaam Takaful | D108: KHI/HO/D/MO/PC COMP/C/78152/151/11/2023 | E108: By Bank | F108: 45604 | G108: 45969 | H108: SUZUKI ALTO AGS A/T | I108: 2021 | J108: AVU-799 | K108: 6R190953 | L108: NF1AET306H1090975 | M108: M/S.Bankislami(Pakistan)Limited User:MrNisarAhmadCheema | N108: 3410126347649 | O108: 579055-2899-2002 | P108: 2002 | Q108: 450 | R108: 44571 | S108: 47072 | T108: 1232010 | U108: 0.0199 | V108: 1108809 | W108: 22065.299 | X108: 0 | Y108: 22065 | Z108: Ok for Renewal | AA108: APPROVED | AB108: Consumer | AC108: After_24-Dec-2021 | AD108: 45623 | AE108: KHI/HO/D/MO/PC COMP/C/101820/107/11/2024 | AF108: 22065 | AG108: =Y108-AF108 -> 0
A109: Renewal | B109: Nov-24 | C109: Salaam Takaful | D109: KHI/HO/D/MO/PC COMP/C/78152/276/11/2023 | E109: By Bank | F109: 45600 | G109: 45965 | H109: SUZUKI ALTO | I109: 2021 | J109: BUY-697 | K109: 6R191529 | L109: NF1AET306H1091531 | M109: M/S.Bankislami(Pakistan)Limited User:SyedAdnanAli | N109: 4210105740475 | O109: 971861-179-1050 | P109: 1050 | Q109: 450 | R109: 44505 | S109: 47062 | T109: 1232010 | U109: 0.0199 | V109: 1108809 | W109: 22065.299 | X109: 0 | Y109: 22065 | Z109: Ok for Renewal | AA109: APPROVED | AB109: Consumer | AC109: Before_24-Dec-2021 | AD109: 45623 | AE109: KHI/HO/D/MO/PC COMP/C/101820/108/11/2024 | AF109: 22065 | AG109: =Y109-AF109 -> 0
A110: Renewal | B110: Nov-24 | C110: Salaam Takaful | D110: KHI/HO/D/MO/PC COMP/C/78152/278/11/2023 | E110: By Bank | F110: 45603 | G110: 45968 | H110: SUZUKI ALTO AGS A/T | I110: 2021 | J110: AVU-610 | K110: 6R191420 | L110: NF1AET306H1091432 | M110: M/S.Bankislami(Pakistan)Limited User:Ms.AmbreenZia | N110: 4230102918524 | O110: 976822-308-2031 | P110: 2031 | Q110: 450 | R110: 44511 | S110: 47062 | T110: 1232010 | U110: 0.0199 | V110: 1108809 | W110: 22065.299 | X110: 0 | Y110: 22065 | Z110: Ok for Renewal | AA110: APPROVED | AB110: Consumer | AC110: Before_24-Dec-2021 | AD110: 45623 | AE110: KHI/HO/D/MO/PC COMP/C/101820/109/11/2024 | AF110: 22065 | AG110: =Y110-AF110 -> 0
A111: Renewal | B111: Nov-24 | C111: Salaam Takaful | D111: KHI/HO/D/MO/PC COMP/C/78152/295/11/2023 | E111: By Bank | F111: 45612 | G111: 45977 | H111: SUZUKI ALTO VXL AGS E-2 | I111: 2021 | J111: AVW-260 | K111: 191121 | L111: 91124 | M111: M/S.Bankislami(Pakistan)Limited User:MrWaleedBinZahid | N111: 4210135313113 | O111: 966866-177-3087 | P111: 3087 | Q111: 450 | R111: 44518 | S111: 47072 | T111: 1232010 | U111: 0.0199 | V111: 1108809 | W111: 22065.299 | X111: 0 | Y111: 22065 | Z111: Ok for Renewal | AA111: APPROVED | AB111: Consumer | AC111: Before_24-Dec-2021 | AD111: 45623 | AE111: KHI/HO/D/MO/PC COMP/C/101820/110/11/2024 | AF111: 22065 | AG111: =Y111-AF111 -> 0
A112: Renewal | B112: Nov-24 | C112: Salaam Takaful | D112: KHI/HO/D/MO/PC COMP/C/78152/277/11/2023 | E112: By Bank | F112: 45621 | G112: 45986 | H112: HONDA CIVIC | I112: 2021 | J112: BVC-676 | K112: R18Z16927724 | L112: NFBFC6669MR080300 | M112: M/S.Bankislami(Pakistan)Limited User:ZarqaBano | N112: 4520307768036 | O112: 972393-163-1149 | P112: 1149 | Q112: 477 | R112: 44530 | S112: 46341 | T112: 3144420 | U112: 0.0199 | V112: 2829978 | W112: 56316.562 | X112: 0 | Y112: 56317 | Z112: Ok for Renewal | AA112: APPROVED | AB112: Consumer | AC112: Before_24-Dec-2021 | AD112: 45623 | AE112: KHI/HO/D/MO/PC COMP/C/101820/111/11/2024 | AF112: 56317 | AG112: =Y112-AF112 -> 0
A113: Renewal | B113: Nov-24 | C113: Salaam Takaful | D113: KHI/HO/D/MO/PC COMP/C/78152/35/11/2023 | E113: By Bank | F113: 45620 | G113: 45985 | H113: CHANGAN OSHAN X7 COMFORT | I113: 2022 | J113: AML-793 | K113: JL473ZQ7NN8AH227862 | L113: NKMASE2E6N1001972 | M113: M/s.BankislamiPakistanLimited UserMr.NoumanFarrukh | N113: 3520109355625 | O113: 3698246-72-2047 | P113: 2047 | Q113: 450 | R113: 44896 | S113: 45986 | T113: 6681150 | U113: 0.0199 | V113: 6013035 | W113: 119659.4 | X113: 0 | Y113: 119659 | Z113: Ok for Renewal | AA113: APPROVED | AB113: Consumer | AC113: After_24-Dec-2021 | AD113: 45623 | AE113: KHI/HO/D/MO/PC COMP/C/101820/112/11/2024 | AF113: 119659 | AG113: =Y113-AF113 -> 0
A114: Renewal | B114: Nov-24 | C114: Salaam Takaful | D114: KHI/HO/D/MO/PC COMP/C/78152/48/11/2023 | E114: By Bank | F114: 45623 | G114: 45988 | H114: TOYOTA HILUX REVO | I114: 2022 | J114: BAS-77 | K114: 1GD5290723 | L114: GUN126R5559016 | M114: M/s.BankislamiPakistanLimited UserMr.ShafayTex | N114: 3330386983690 | O114: 1280682-688-2011 | P114: 2011 | Q114: 565 | R114: 44902 | S114: 46716 | T114: 10132200 | U114: 0.0199 | V114: 9118980 | W114: 181467.7 | X114: 0 | Y114: 181468 | Z114: Ok for Renewal | AA114: APPROVED | AB114: Consumer | AC114: After_24-Dec-2021 | AD114: 45623 | AE114: KHI/HO/D/MO/PC COMP/C/101820/113/11/2024 | AF114: 181468 | AG114: =Y114-AF114 -> 0
A115: Renewal | B115: Nov-24 | C115: Salaam Takaful | D115: KHI/HO/D/MO/PC COMP/C/78152/96/11/2023 | E115: By Bank | F115: 45626 | G115: 45991 | H115: TOYOTA HILUX REVO | I115: 2022 | J115: BAT-67 | K115: 1GD5290020 | L115: GUN126R-5558654 | M115: M/s.Bankislami(Pakistan)Limited UserM/S.NjsAssociates | N115: 3730211728091 | O115: 1284635-172-3062 | P115: 3062 | Q115: 565 | R115: 44897 | S115: 46726 | T115: 10143000 | U115: 0.0199 | V115: 9128700 | W115: 181661.13 | X115: 0 | Y115: 181661 | Z115: Ok for Renewal | AA115: APPROVED | AB115: Consumer | AC115: After_24-Dec-2021 | AD115: 45623 | AE115: KHI/HO/D/MO/PC COMP/C/101820/114/11/2024 | AF115: 181661 | AG115: =Y115-AF115 -> 0
A116: Renewal | B116: Nov-24 | C116: Salaam Takaful | D116: KHI/HO/D/MO/PC COMP/C/78152/382/11/2023 | E116: By Bank | F116: 45626 | G116: 45991 | H116: KIA SPORTAGE AWD | I116: 2022 | J116: BK-3125 | K116: G4NANH303113 | L116: NNAQ51AZKP518597 | M116: M/s.Bankislami(Pakistan)Limited UserMr.DeenMuhammad | N116: 4120263216473 | O116: 981667-1-1182 | P116: 1182 | Q116: 450 | R116: 44900 | S116: 46716 | T116: 6532200 | U116: 0.0199 | V116: 5878980 | W116: 116991.7 | X116: 0 | Y116: 116992 | Z116: Ok for Renewal | AA116: APPROVED | AB116: Consumer | AC116: After_24-Dec-2021 | AD116: 45623 | AE116: KHI/HO/D/MO/PC COMP/C/101820/115/11/2024 | AF116: 116992 | AG116: =Y116-AF116 -> 0
A117: Renewal | B117: Nov-24 | C117: Salaam Takaful | D117: KHI/HO/D/MO/PC COMP/C/78152/296/11/2023 | E117: By Bank | F117: 45604 | G117: 45969 | H117: TOYOTA FORTUNER A/T 2.7 L VVTI | I117: 2021 | J117: AVV-916 | K117: 907039 | L117: 44442 | M117: M/S.Bankislami(Pakistan)Limited User:MrWaseemAbbas | N117: 3740244096527 | O117: 964203-12-3095 | P117: 3095 | Q117: 450 | R117: 44544 | S117: 46341 | T117: 7240590 | U117: 0.0199 | V117: 6516531 | W117: 129678.97 | X117: 0 | Y117: 129679 | Z117: Ok for Renewal | AA117: APPROVED | AB117: Consumer | AC117: Before_24-Dec-2021 | AD117: 45623 | AE117: KHI/HO/D/MO/PC COMP/C/101820/116/11/2024 | AF117: 129679 | AG117: =Y117-AF117 -> 0
A118: Renewal | B118: Nov-24 | C118: Salaam Takaful | D118: KHI/HO/D/MO/PC COMP/C/78152/224/11/2023 | E118: By Bank | F118: 45604 | G118: 45969 | H118: KIA SPORTAGE AWT | I118: 2021 | J118: BJ-8078 | K118: G4NAMH314137 | L118: NNAQL51AZKP513754 | M118: M/S.Bankislami(Pakistan)Limited User:MrAghaAbdulWasay | N118: 4230176403039 | O118: 262429-2477-1106 | P118: 1106 | Q118: 550 | R118: 44516 | S118: 46341 | T118: 4273560 | U118: 0.0199 | V118: 3846204 | W118: 76539.46 | X118: 0 | Y118: 76539 | Z118: Ok for Renewal | AA118: APPROVED | AB118: Consumer | AC118: Before_24-Dec-2021 | AD118: 45623 | AE118: KHI/HO/D/MO/PC COMP/C/101820/117/11/2024 | AF118: 76539 | AG118: =Y118-AF118 -> 0
... A276: Renewal | B276: Nov-24 | C276: Salaam Takaful | D276: KHI/HO/D/MO/PC COMP/C/78152/123/11/2023 | E276: By Bank | F276: 45625 | G276: 45990 | H276: TOYOTA REVO VIGO A/T | I276: 2020 | J276: ASA-661 | K276: 881656 | L276: 5541304 | M276: M/S.Bankislami(Pakistan)Limited User:Mr.MuhammadFaisalKiani | N276: 3740591806343 | O276: 449662-61-3049 | P276: 3049 | Q276: 450 | R276: 44173 | S276: 45996 | T276: 5154759 | U276: 0.028 | V276: 4639283.1 | W276: 129899.93 | X276: 0 | Y276: 129900 | Z276: Ok for Renewal | AA276: APPROVED | AB276: Consumer | AC276: Before_24-Dec-2021 | AD276: 45623 | AE276: KHI/HO/D/MO/PC COMP/C/101820/274/11/2024 | AF276: 129900 | AG276: =Y276-AF276 -> 0
A277: Renewal | B277: 45597 | C277: Salaam Takaful | D277: KHI/HO/D/MO/PC COMP/C/80040/23/12/2023 | E277: Waiver | F277: 45602 | G277: 45967 | H277: DAIHATSU MIRA | I277: 2019 | J277: BVT-725 | K277: KF-J842961 | L277: LA350S-0183068 | M277: RIZWAN MEHMOOD MARWAT (Staff) | N277: 4230194569983 | O277: 103838-9900-1003 | P277: 1003 | Q277: 528 | R277: 44875 | S277: 47417 | T277: 2340000 | U277: 0.018 | V277: 2106000 | W277: 37908 | X277: 0 | Y277: 37908 | Z277: Ok for Renewal | AA277: APPROVED | AB277: Staff | AC277: After_24-Dec-2021 | AD277: 45623 | AE277: KHI/HO/D/MO/PC COMP/C/102243/11/11/2024 | AF277: 37908 | AG277: =Y277-AF277 -> 0
A278: Renewal | B278: 45597 | C278: Salaam Takaful | D278: KHI/HO/D/MO/PC COMP/C/80040/39/12/2023 | E278: Waiver | F278: 45617 | G278: 45982 | H278: HONDA CITY | I278: 2022 | J278: BXX-296 | K278: L15Z81012009 | L278: NFBGN9661NR027723 | M278: TABINDA (Staff) | N278: 4210117571696 | O278: 10571-9938-1003 | P278: 1003 | Q278: 459 | R278: 44888 | S278: 47448 | T278: 3940200 | U278: 0.018 | V278: 3546180 | W278: 63831.24 | X278: 0 | Y278: 63831 | Z278: Ok for Renewal | AA278: APPROVED | AB278: Staff | AC278: After_24-Dec-2021 | AD278: 45623 | AE278: KHI/HO/D/MO/PC COMP/C/102243/24/11/2024 | AF278: 63831 | AG278: =Y278-AF278 -> 0
A279: Renewal | B279: 45597 | C279: Salaam Takaful | D279: KHI/HO/D/MO/PC COMP/C/80040/28/12/2023 | E279: Waiver | F279: 45609 | G279: 45974 | H279: KIA SPORTAGE | I279: 2020 | J279: AQD-016 | K279: G4NAKH029992 | L279: NNAQL51AZKP300555 | M279: IMRAN KHAN (Staff) | N279: 3520136594739 | O279: 11034-9918-1003 | P279: 1003 | Q279: 459 | R279: 44879 | S279: 47417 | T279: 4770000 | U279: 0.018 | V279: 4293000 | W279: 77274 | X279: 0 | Y279: 77274 | Z279: Ok for Renewal | AA279: APPROVED | AB279: Staff | AC279: After_24-Dec-2021 | AD279: 45623 | AE279: KHI/HO/D/MO/PC COMP/C/102243/14/11/2024 | AF279: 77274 | AG279: =Y279-AF279 -> 0
...

Sheet working1
A1: POLICY NO. | B1: Assorted_code | D1: Premium | E1: 29Nov240037
A2: KHI/HO/D/MO/PC COMP/C/101820/2/11/2024 | B2: =VLOOKUP(A2,policy1!B:C,2,0) -> 070000170975 | C2: 69273 | D2: =ROUND(C2,0) -> 69273 | E2: 29Nov240037 | F2: ="insert into ins_premium_det (premium_rcv_code,assorted_code, rec_amount,premium_rcv_detail_code,remaining_amt, payrec, mode_code,coinsurance_code,class_cd,it_remarks) values" -> insert into ins_premium_det (premium_rcv_code,assorted_code, rec_amount,premium_rcv_detail_code,remaining_amt, payrec, mode_code,coinsurance_code,class_cd,it_remarks) values | G2: ="('"&E2&"','"&B2&"','"&D2&"',(select max(to_number(i.premium_rcv_detail_code))+1 from ins_premium_det i),'"&D2&"','"&D2&"','02', '11000003','00','Request by Mr. Raheel Malik 04-Dec-2024 for premium');" -> ('29Nov240037','070000170975','69273',(select max(to_number(i.premium_rcv_detail_code))+1 from ins_premium_det i),'69273','69273','02', '11000003','00','Request by Mr. Raheel Malik 04-Dec-2024 for premium'); | H2: =F2&G2 -> insert into ins_premium_det (premium_rcv_code,assorted_code, rec_amount,premium_rcv_detail_code,remaining_amt, payrec, mode_code,coinsurance_code,class_cd,it_remarks) values('29Nov240037','070000170975','69273',(select max(to_number(i.premium_rcv_detail_code))+1 from ins_premium_det i),'69273','69273','02', '11000003','00','Request by Mr. Raheel Malik 04-Dec-2024 for premium');
A3: KHI/HO/D/MO/PC COMP/C/101820/3/11/2024 | B3: =VLOOKUP(A3,policy1!B:C,2,0) -> 070000170976 | C3: 81807 | D3: =ROUND(C3,0) -> 81807 | E3: 29Nov240037 | F3: ="insert into ins_premium_det (premium_rcv_code,assorted_code, rec_amount,premium_rcv_detail_code,remaining_amt, payrec, mode_code,coinsurance_code,class_cd,it_remarks) values" -> insert into ins_premium_det (premium_rcv_code,assorted_code, rec_amount,premium_rcv_detail_code,remaining_amt, payrec, mode_code,coinsurance_code,class_cd,it_remarks) values | G3: ="('"&E3&"','"&B3&"','"&D3&"',(select max(to_number(i.premium_rcv_detail_code))+1 from ins_premium_det i),'"&D3&"','"&D3&"','02', '11000003','00','Request by Mr. Raheel Malik 04-Dec-2024 for premium');" -> ('29Nov240037','070000170976','81807',(select max(to_number(i.premium_rcv_detail_code))+1 from ins_premium_det i),'81807','81807','02', '11000003','00','Request by Mr. Raheel Malik 04-Dec-2024 for premium'); | H3: =F3&G3 -> insert into ins_premium_det (premium_rcv_code,assorted_code, rec_amount,premium_rcv_detail_code,remaining_amt, payrec, mode_code,coinsurance_code,class_cd,it_remarks) values('29Nov240037','070000170976','81807',(select max(to_number(i.premium_rcv_detail_code))+1 from ins_premium_det i),'81807','81807','02', '11000003','00','Request by Mr. Raheel Malik 04-Dec-2024 for premium');
A4: KHI/HO/D/MO/PC COMP/C/101820/4/11/2024 | B4: =VLOOKUP(A4,policy1!B:C,2,0) -> 070000170977 | C4: 19959 | D4: =ROUND(C4,0) -> 19959 | E4: 29Nov240037 | F4: ="insert into ins_premium_det (premium_rcv_code,assorted_code, rec_amount,premium_rcv_detail_code,remaining_amt, payrec, mode_code,coinsurance_code,class_cd,it_remarks) values" -> insert into ins_premium_det (premium_rcv_code,assorted_code, rec_amount,premium_rcv_detail_code,remaining_amt, payrec, mode_code,coinsurance_code,class_cd,it_remarks) values | G4: ="('"&E4&"','"&B4&"','"&D4&"',(select max(to_number(i.premium_rcv_detail_code))+1 from ins_premium_det i),'"&D4&"','"&D4&"','02', '11000003','00','Request by Mr. Raheel Malik 04-Dec-2024 for premium');" -> ('29Nov240037','070000170977','19959',(select max(to_number(i.premium_rcv_detail_code))+1 from ins_premium_det i),'19959','19959','02', '11000003','00','Request by Mr. Raheel Malik 04-Dec-2024 for premium'); | H4: =F4&G4 -> insert into ins_premium_det (premium_rcv_code,assorted_code, rec_amount,premium_rcv_detail_code,remaining_amt, payrec, mode_code,coinsurance_code,class_cd,it_remarks) values('29Nov240037','070000170977','19959',(select max(to_number(i.premium_rcv_detail_code))+1 from ins_premium_det i),'19959','19959','02', '11000003','00','Request by Mr. Raheel Malik 04-Dec-2024 for premium');
A5: KHI/HO/D/MO/PC COMP/C/101820/5/11/2024 | B5: =VLOOKUP(A5,policy1!B:C,2,0) -> 070000170978 | C5: 19959 | D5: =ROUND(C5,0) -> 19959 | E5: 29Nov240037 | F5: ="insert into ins_premium_det (premium_rcv_code,assorted_code, rec_amount,premium_rcv_detail_code,remaining_amt, payrec, mode_code,coinsurance_code,class_cd,it_remarks) values" -> insert into ins_premium_det (premium_rcv_code,assorted_code, rec_amount,premium_rcv_detail_code,remaining_amt, payrec, mode_code,coinsurance_code,class_cd,it_remarks) values | G5: ="('"&E5&"','"&B5&"','"&D5&"',(select max(to_number(i.premium_rcv_detail_code))+1 from ins_premium_det i),'"&D5&"','"&D5&"','02', '11000003','00','Request by Mr. Raheel Malik 04-Dec-2024 for premium');" -> ('29Nov240037','070000170978','19959',(select max(to_number(i.premium_rcv_detail_code))+1 from ins_premium_det i),'19959','19959','02', '11000003','00','Request by Mr. Raheel Malik 04-Dec-2024 for premium'); | H5: =F5&G5 -> insert into ins_premium_det (premium_rcv_code,assorted_code, rec_amount,premium_rcv_detail_code,remaining_amt, payrec, mode_code,coinsurance_code,class_cd,it_remarks) values('29Nov240037','070000170978','19959',(select max(to_number(i.premium_rcv_detail_code))+1 from ins_premium_det i),'19959','19959','02', '11000003','00','Request by Mr. Raheel Malik 04-Dec-2024 for premium');
A6: KHI/HO/D/MO/PC COMP/C/101820/6/11/2024 | B6: =VLOOKUP(A6,policy1!B:C,2,0) -> 070000170979 | C6: 67590 | D6: =ROUND(C6,0) -> 67590 | E6: 29Nov240037 | F6: ="insert into ins_premium_det (premium_rcv_code,assorted_code, rec_amount,premium_rcv_detail_code,remaining_amt, payrec, mode_code,coinsurance_code,class_cd,it_remarks) values" -> insert into ins_premium_det (premium_rcv_code,assorted_code, rec_amount,premium_rcv_detail_code,remaining_amt, payrec, mode_code,coinsurance_code,class_cd,it_remarks) values | G6: ="('"&E6&"','"&B6&"','"&D6&"',(select max(to_number(i.premium_rcv_detail_code))+1 from ins_premium_det i),'"&D6&"','"&D6&"','02', '11000003','00','Request by Mr. Raheel Malik 04-Dec-2024 for premium');" -> ('29Nov240037','070000170979','67590',(select max(to_number(i.premium_rcv_detail_code))+1 from ins_premium_det i),'67590','67590','02', '11000003','00','Request by Mr. Raheel Malik 04-Dec-2024 for premium'); | H6: =F6&G6 -> insert into ins_premium_det (premium_rcv_code,assorted_code, rec_amount,premium_rcv_detail_code,remaining_amt, payrec, mode_code,coinsurance_code,class_cd,it_remarks) values('29Nov240037','070000170979','67590',(select max(to_number(i.premium_rcv_detail_code))+1 from ins_premium_det i),'67590','67590','02', '11000003','00','Request by Mr. Raheel Malik 04-Dec-2024 for premium');
